{"ts": 1785164107.47, "kind": "price_change", "data": {"market": "0x18b1c135d0a40c5894da9412e77311827d9caf16cf4cd6591b247a34730af919", "price_changes": [{"asset_id": "78633590736077251574794513664747155551297291244492840448622550955320930591622", "price": "0.532", "size": "74115.71", "side": "BUY", "hash": "8442b497bb6888fafb6cf9053f35e9bddf5fab8b", "best_bid": "0.571", "best_ask": "0.572"}, {"asset_id": "40081275558852222228080198821361202017557872256707631666334039001378518619916", "price": "0.468", "size": "74115.71", "side": "SELL", "hash": "356c25ae9a4d6777599e26b3ae4754293f6c7575", "best_bid": "0.428", "best_ask": "0.429"}], "timestamp": "1785164107470", "event_type": "price_change"}}
{"ts": 1785164107.927, "kind": "price_change", "data": {"market": "0x18b1c135d0a40c5894da9412e77311827d9caf16cf4cd6591b247a34730af919", "price_changes": [{"asset_id": "40081275558852222228080198821361202017557872256707631666334039001378518619916", "price": "0.505", "size": "0", "side": "SELL", "hash": "7cd60d93a7867dd6a9982811c2f4a5f91f441877", "best_bid": "0.428", "best_ask": "0.429"}, {"asset_id": "78633590736077251574794513664747155551297291244492840448622550955320930591622", "price": "0.495", "size": "0", "side": "BUY", "hash": "931bd198265c9f1338b2c34baa650ae6fd5c8239", "best_bid": "0.571", "best_ask": "0.572"}], "timestamp": "1785164107927", "event_type": "price_change"}}
{"ts": 1785164108.933, "kind": "price_change", "data": {"market": "0x18b1c135d0a40c5894da9412e77311827d9caf16cf4cd6591b247a34730af919", "price_changes": [{"asset_id": "40081275558852222228080198821361202017557872256707631666334039001378518619916", "price": "0.505", "size": "36.7", "side": "SELL", "hash": "cb6b7b233b583cea6dcf5c9afdf3eeb85a15be72", "best_bid": "0.428", "best_ask": "0.429"}, {"asset_id": "78633590736077251574794513664747155551297291244492840448622550955320930591622", "price": "0.495", "size": "36.7", "side": "BUY", "hash": "3a1f7c144bb53eef73fea88e178022d7ec5a5724", "best_bid": "0.571", "best_ask": "0.572"}], "timestamp": "1785164108933", "event_type": "price_change"}}
{"ts": 1785164109.657, "kind": "price_change", "data": {"market": "0x18b1c135d0a40c5894da9412e77311827d9caf16cf4cd6591b247a34730af919", "price_changes": [{"asset_id": "40081275558852222228080198821361202017557872256707631666334039001378518619916", "price": "0.505", "size": "0", "side": "SELL", "hash": "7371982ecba81a518f333a0a8950475afe75341c", "best_bid": "0.428", "best_ask": "0.429"}, {"asset_id": "78633590736077251574794513664747155551297291244492840448622550955320930591622", "price": "0.495", "size": "0", "side": "BUY", "hash": "204ede40c365ed23df911c430c70f4aea86074d3", "best_bid": "0.571", "best_ask": "0.572"}], "timestamp": "1785164109657", "event_type": "price_change"}}
{"ts": 1785164109.934, "kind": "price_change", "data": {"market": "0x18b1c135d0a40c5894da9412e77311827d9caf16cf4cd6591b247a34730af919", "price_changes": [{"asset_id": "40081275558852222228080198821361202017557872256707631666334039001378518619916", "price": "0.506", "size": "36.7", "side": "SELL", "hash": "e904ba9075ff6d69788c53d6ff5a6887d2b08b00", "best_bid": "0.428", "best_ask": "0.429"}, {"asset_id": "78633590736077251574794513664747155551297291244492840448622550955320930591622", "price": "0.494", "size": "36.7", "side": "BUY", "hash": "6a93c7920cb0ac07e95e48059e4389085f7cd844", "best_bid": "0.571", "best_ask": "0.572"}], "timestamp": "1785164109934", "event_type": "price_change"}}
{"ts": 1785164112.521, "kind": "price_change", "data": {"market": "0x18b1c135d0a40c5894da9412e77311827d9caf16cf4cd6591b247a34730af919", "price_changes": [{"asset_id": "40081275558852222228080198821361202017557872256707631666334039001378518619916", "price": "0.03", "size": "158750", "side": "BUY", "hash": "fd2c8e4f7ba0aa1ca39a8f900386b0fe200a00b3", "best_bid": "0.428", "best_ask": "0.429"}, {"asset_id": "78633590736077251574794513664747155551297291244492840448622550955320930591622", "price": "0.97", "size": "158750", "side": "SELL", "hash": "3516a322dcce78b6d9b7766dce242ea101e1f96e", "best_bid": "0.571", "best_ask": "0.572"}], "timestamp": "1785164112521", "event_type": "price_change"}}
{"ts": 1785164112.523, "kind": "price_change", "data": {"market": "0x18b1c135d0a40c5894da9412e77311827d9caf16cf4cd6591b247a34730af919", "price_changes": [{"asset_id": "78633590736077251574794513664747155551297291244492840448622550955320930591622", "price": "0.08", "size": "20000", "side": "BUY", "hash": "e707e85b3e479f58b28c474b62d512a10a19171e", "best_bid": "0.571", "best_ask": "0.572"}, {"asset_id": "40081275558852222228080198821361202017557872256707631666334039001378518619916", "price": "0.92", "size": "20000", "side": "SELL", "hash": "c54bad7ccbd2c957cdbebc47b7f2939aa678e5c0", "best_bid": "0.428", "best_ask": "0.429"}], "timestamp": "1785164112523", "event_type": "price_change"}}
{"ts": 1785164113.485, "kind": "price_change", "data": {"market": "0x0f49db97f71c68b1e42a6d16e3de93d85dbf7d4148e3f018eb79e88554be9f75", "price_changes": [{"asset_id": "87854174148074652060467921081181402357467303721471806610111179101805869578687", "price": "0.37", "size": "2702", "side": "BUY", "hash": "4ff8d8ecc8b30642c7a66c37cd9100b2da454a49", "best_bid": "0.805", "best_ask": "0.806"}, {"asset_id": "54533043819946592547517511176940999955633860128497669742211153063842200957669", "price": "0.63", "size": "2702", "side": "SELL", "hash": "944fb267c78651e0d31e577c3e3bb0d5e289fcbd", "best_bid": "0.194", "best_ask": "0.195"}], "timestamp": "1785164113485", "event_type": "price_change"}}
{"ts": 1785164113.784019, "kind": "orders_out", "data": [{"token_id": "54533043819946592547517511176940999955633860128497669742211153063842200957669", "side": "BUY", "price": 0.153, "size": 19.61}]}
{"ts": 1785164113.87, "kind": "price_change", "data": {"market": "0x18b1c135d0a40c5894da9412e77311827d9caf16cf4cd6591b247a34730af919", "price_changes": [{"asset_id": "40081275558852222228080198821361202017557872256707631666334039001378518619916", "price": "0.41", "size": "2931.23", "side": "BUY", "hash": "4a062a2b539cf4d206d4760e68c091852d241e41", "best_bid": "0.428", "best_ask": "0.429"}, {"asset_id": "78633590736077251574794513664747155551297291244492840448622550955320930591622", "price": "0.59", "size": "2931.23", "side": "SELL", "hash": "af60756a60043d3b4ed1bdd2a5c1e715d2e3e1a9", "best_bid": "0.571", "best_ask": "0.572"}], "timestamp": "1785164113870", "event_type": "price_change"}}
{"ts": 1785164114.342, "kind": "price_change", "data": {"market": "0x18b1c135d0a40c5894da9412e77311827d9caf16cf4cd6591b247a34730af919", "price_changes": [{"asset_id": "40081275558852222228080198821361202017557872256707631666334039001378518619916", "price": "0.41", "size": "2947.28", "side": "BUY", "hash": "2503b6b7b7697a9f57b85502eb43fe0fa5422854", "best_bid": "0.428", "best_ask": "0.429"}, {"asset_id": "78633590736077251574794513664747155551297291244492840448622550955320930591622", "price": "0.59", "size": "2947.28", "side": "SELL", "hash": "c0d6c1d8127ede7e5af8d61bd87553d2a37c427a", "best_bid": "0.571", "best_ask": "0.572"}], "timestamp": "1785164114342", "event_type": "price_change"}}
{"ts": 1785164114.367, "kind": "price_change", "data": {"market": "0x18b1c135d0a40c5894da9412e77311827d9caf16cf4cd6591b247a34730af919", "price_changes": [{"asset_id": "78633590736077251574794513664747155551297291244492840448622550955320930591622", "price": "0.371", "size": "0", "side": "BUY", "hash": "73959db9d5032c98b48d9a59cef8307faa18dc14", "best_bid": "0.571", "best_ask": "0.572"}, {"asset_id": "40081275558852222228080198821361202017557872256707631666334039001378518619916", "price": "0.629", "size": "0", "side": "SELL", "hash": "fc7a925238ceaae4842c6ef2f923a2ac6b6e9f39", "best_bid": "0.428", "best_ask": "0.429"}], "timestamp": "1785164114367", "event_type": "price_change"}}
{"ts": 1785164114.394, "kind": "price_change", "data": {"market": "0x18b1c135d0a40c5894da9412e77311827d9caf16cf4cd6591b247a34730af919", "price_changes": [{"asset_id": "78633590736077251574794513664747155551297291244492840448622550955320930591622", "price": "0.373", "size": "400", "side": "BUY", "hash": "b64f49c20bf4052c8028d9da26417c8b6e05a2fb", "best_bid": "0.571", "best_ask": "0.572"}, {"asset_id": "40081275558852222228080198821361202017557872256707631666334039001378518619916", "price": "0.627", "size": "400", "side": "SELL", "hash": "f4f1e3a84cce4e06a7ab6d630ff27624f94410b5", "best_bid": "0.428", "best_ask": "0.429"}], "timestamp": "1785164114394", "event_type": "price_change"}}
{"ts": 1785164115.38, "kind": "price_change", "data": {"market": "0x0f49db97f71c68b1e42a6d16e3de93d85dbf7d4148e3f018eb79e88554be9f75", "price_changes": [{"asset_id": "54533043819946592547517511176940999955633860128497669742211153063842200957669", "price": "0.009", "size": "13888.88", "side": "BUY", "hash": "01bd9b5ca6941948f5340e1dfc0e3e197ac68b2e", "best_bid": "0.194", "best_ask": "0.195"}, {"asset_id": "87854174148074652060467921081181402357467303721471806610111179101805869578687", "price": "0.991", "size": "13888.88", "side": "SELL", "hash": "7872d1c7387495264dff6da3f732bb3f90419594", "best_bid": "0.805", "best_ask": "0.806"}], "timestamp": "1785164115380", "event_type": "price_change"}}
{"ts": 1785164115.381, "kind": "price_change", "data": {"market": "0x0f49db97f71c68b1e42a6d16e3de93d85dbf7d4148e3f018eb79e88554be9f75", "price_changes": [{"asset_id": "54533043819946592547517511176940999955633860128497669742211153063842200957669", "price": "0.007", "size": "53571.42", "side": "BUY", "hash": "2187a21751f20416353b7a6b4adf0441f0f33246", "best_bid": "0.194", "best_ask": "0.195"}, {"asset_id": "87854174148074652060467921081181402357467303721471806610111179101805869578687", "price": "0.993", "size": "53571.42", "side": "SELL", "hash": "b3c7d266272ca35110357b2dc39b94395e14e8e5", "best_bid": "0.805", "best_ask": "0.806"}], "timestamp": "1785164115381", "event_type": "price_change"}}
{"ts": 1785164116.001, "kind": "price_change", "data": {"market": "0x0f49db97f71c68b1e42a6d16e3de93d85dbf7d4148e3f018eb79e88554be9f75", "price_changes": [{"asset_id": "54533043819946592547517511176940999955633860128497669742211153063842200957669", "price": "0.17", "size": "5889.88", "side": "BUY", "hash": "8775c1f5d94a9e1761fea20c109b6d2166d554e7", "best_bid": "0.194", "best_ask": "0.195"}, {"asset_id": "87854174148074652060467921081181402357467303721471806610111179101805869578687", "price": "0.83", "size": "5889.88", "side": "SELL", "hash": "01c448ae597eaf9f76546c9c1614ecf9650e8af4", "best_bid": "0.805", "best_ask": "0.806"}], "timestamp": "1785164116001", "event_type": "price_change"}}
{"ts": 1785164116.001, "kind": "price_change", "data": {"market": "0x0f49db97f71c68b1e42a6d16e3de93d85dbf7d4148e3f018eb79e88554be9f75", "price_changes": [{"asset_id": "54533043819946592547517511176940999955633860128497669742211153063842200957669", "price": "0.16", "size": "2750", "side": "BUY", "hash": "8775c1f5d94a9e1761fea20c109b6d2166d554e7", "best_bid": "0.194", "best_ask": "0.195"}, {"asset_id": "87854174148074652060467921081181402357467303721471806610111179101805869578687", "price": "0.84", "size": "2750", "side": "SELL", "hash": "01c448ae597eaf9f76546c9c1614ecf9650e8af4", "best_bid": "0.805", "best_ask": "0.806"}], "timestamp": "1785164116001", "event_type": "price_change"}}
{"ts": 1785164116.915, "kind": "price_change", "data": {"market": "0x18b1c135d0a40c5894da9412e77311827d9caf16cf4cd6591b247a34730af919", "price_changes": [{"asset_id": "40081275558852222228080198821361202017557872256707631666334039001378518619916", "price": "0.506", "size": "0", "side": "SELL", "hash": "9561ed8d649af151a0bde8d213682ac92c93db7b", "best_bid": "0.428", "best_ask": "0.429"}, {"asset_id": "78633590736077251574794513664747155551297291244492840448622550955320930591622", "price": "0.494", "size": "0", "side": "BUY", "hash": "bf122ce334399f6ef3deaeec28af9cbe13699c3b", "best_bid": "0.571", "best_ask": "0.572"}], "timestamp": "1785164116915", "event_type": "price_change"}}
{"ts": 1785164117.872, "kind": "price_change", "data": {"market": "0x18b1c135d0a40c5894da9412e77311827d9caf16cf4cd6591b247a34730af919", "price_changes": [{"asset_id": "40081275558852222228080198821361202017557872256707631666334039001378518619916", "price": "0.505", "size": "36.7", "side": "SELL", "hash": "8dc5797cf13b8b4c4e026f0cde048926ad94d0c4", "best_bid": "0.428", "best_ask": "0.429"}, {"asset_id": "78633590736077251574794513664747155551297291244492840448622550955320930591622", "price": "0.495", "size": "36.7", "side": "BUY", "hash": "47ac7a79aa901f7123657ab9679e1a214b7d54df", "best_bid": "0.571", "best_ask": "0.572"}], "timestamp": "1785164117872", "event_type": "price_change"}}
{"ts": 1785164118.683, "kind": "price_change", "data": {"market": "0x0f49db97f71c68b1e42a6d16e3de93d85dbf7d4148e3f018eb79e88554be9f75", "price_changes": [{"asset_id": "54533043819946592547517511176940999955633860128497669742211153063842200957669", "price": "0.007", "size": "0", "side": "BUY", "hash": "316914dbfb60b7f8b609b962179eabe8e8b409b1", "best_bid": "0.194", "best_ask": "0.195"}, {"asset_id": "87854174148074652060467921081181402357467303721471806610111179101805869578687", "price": "0.993", "size": "0", "side": "SELL", "hash": "988d33a5cb34d1d999087b6e13c618862c4109b1", "best_bid": "0.805", "best_ask": "0.806"}], "timestamp": "1785164118683", "event_type": "price_change"}}
{"ts": 1785164118.683, "kind": "price_change", "data": {"market": "0x0f49db97f71c68b1e42a6d16e3de93d85dbf7d4148e3f018eb79e88554be9f75", "price_changes": [{"asset_id": "54533043819946592547517511176940999955633860128497669742211153063842200957669", "price": "0.009", "size": "0", "side": "BUY", "hash": "316914dbfb60b7f8b609b962179eabe8e8b409b1", "best_bid": "0.194", "best_ask": "0.195"}, {"asset_id": "87854174148074652060467921081181402357467303721471806610111179101805869578687", "price": "0.991", "size": "0", "side": "SELL", "hash": "988d33a5cb34d1d999087b6e13c618862c4109b1", "best_bid": "0.805", "best_ask": "0.806"}], "timestamp": "1785164118683", "event_type": "price_change"}}
{"ts": 1785164118.837, "kind": "price_change", "data": {"market": "0x18b1c135d0a40c5894da9412e77311827d9caf16cf4cd6591b247a34730af919", "price_changes": [{"asset_id": "40081275558852222228080198821361202017557872256707631666334039001378518619916", "price": "0.505", "size": "0", "side": "SELL", "hash": "a03000a35880b3294a14f4901dbee7793c914685", "best_bid": "0.428", "best_ask": "0.429"}, {"asset_id": "78633590736077251574794513664747155551297291244492840448622550955320930591622", "price": "0.495", "size": "0", "side": "BUY", "hash": "3a687b9b4315c51950f768bbcf98375813ae3591", "best_bid": "0.571", "best_ask": "0.572"}], "timestamp": "1785164118837", "event_type": "price_change"}}
{"ts": 1785164119.181, "kind": "price_change", "data": {"market": "0x18b1c135d0a40c5894da9412e77311827d9caf16cf4cd6591b247a34730af919", "price_changes": [{"asset_id": "40081275558852222228080198821361202017557872256707631666334039001378518619916", "price": "0.506", "size": "36.7", "side": "SELL", "hash": "539df418106985a49cf842e8e5e1ce3c135d427a", "best_bid": "0.428", "best_ask": "0.429"}, {"asset_id": "78633590736077251574794513664747155551297291244492840448622550955320930591622", "price": "0.494", "size": "36.7", "side": "BUY", "hash": "6782f1c372c1a906997036b63465d2dc5d67e3d1", "best_bid": "0.571", "best_ask": "0.572"}], "timestamp": "1785164119181", "event_type": "price_change"}}
{"ts": 1785164120.609, "kind": "price_change", "data": {"market": "0x0f49db97f71c68b1e42a6d16e3de93d85dbf7d4148e3f018eb79e88554be9f75", "price_changes": [{"asset_id": "87854174148074652060467921081181402357467303721471806610111179101805869578687", "price": "0.795", "size": "2648.98", "side": "BUY", "hash": "7735ed960253166cc2a7ad07bd77c7579bb6d567", "best_bid": "0.805", "best_ask": "0.806"}, {"asset_id": "54533043819946592547517511176940999955633860128497669742211153063842200957669", "price": "0.205", "size": "2648.98", "side": "SELL", "hash": "90d6e2508db88fc763ffa2034e51bc898f72c7cb", "best_bid": "0.194", "best_ask": "0.195"}], "timestamp": "1785164120609", "event_type": "price_change"}}
{"ts": 1785164120.679, "kind": "price_change", "data": {"market": "0x0f49db97f71c68b1e42a6d16e3de93d85dbf7d4148e3f018eb79e88554be9f75", "price_changes": [{"asset_id": "87854174148074652060467921081181402357467303721471806610111179101805869578687", "price": "0.795", "size": "3215.98", "side": "BUY", "hash": "2b261cb5cf8ae8f725003ec9ce301f96cbd5fb43", "best_bid": "0.805", "best_ask": "0.806"}, {"asset_id": "54533043819946592547517511176940999955633860128497669742211153063842200957669", "price": "0.205", "size": "3215.98", "side": "SELL", "hash": "ac1b41bb67f679ecd36b7f6fdcf9e70bb8eac437", "best_bid": "0.194", "best_ask": "0.195"}], "timestamp": "1785164120679", "event_type": "price_change"}}
{"ts": 1785164121.002, "kind": "price_change", "data": {"market": "0x0f49db97f71c68b1e42a6d16e3de93d85dbf7d4148e3f018eb79e88554be9f75", "price_changes": [{"asset_id": "87854174148074652060467921081181402357467303721471806610111179101805869578687", "price": "0.02", "size": "13000", "side": "BUY", "hash": "766a0f6a8322227f25962e221ea2c3ab3ce24844", "best_bid": "0.805", "best_ask": "0.806"}, {"asset_id": "54533043819946592547517511176940999955633860128497669742211153063842200957669", "price": "0.98", "size": "13000", "side": "SELL", "hash": "8009f0aa0394370b4716573e3f34ef0409641d7a", "best_bid": "0.194", "best_ask": "0.195"}], "timestamp": "1785164121002", "event_type": "price_change"}}
{"ts": 1785164121.002, "kind": "price_change", "data": {"market": "0x0f49db97f71c68b1e42a6d16e3de93d85dbf7d4148e3f018eb79e88554be9f75", "price_changes": [{"asset_id": "87854174148074652060467921081181402357467303721471806610111179101805869578687", "price": "0.02", "size": "13000", "side": "BUY", "hash": "766a0f6a8322227f25962e221ea2c3ab3ce24844", "best_bid": "0.805", "best_ask": "0.806"}, {"asset_id": "54533043819946592547517511176940999955633860128497669742211153063842200957669", "price": "0.98", "size": "13000", "side": "SELL", "hash": "8009f0aa0394370b4716573e3f34ef0409641d7a", "best_bid": "0.194", "best_ask": "0.195"}], "timestamp": "1785164121002", "event_type": "price_change"}}
{"ts": 1785164121.003, "kind": "price_change", "data": {"market": "0x0f49db97f71c68b1e42a6d16e3de93d85dbf7d4148e3f018eb79e88554be9f75", "price_changes": [{"asset_id": "87854174148074652060467921081181402357467303721471806610111179101805869578687", "price": "0.02", "size": "13000", "side": "BUY", "hash": "03386bfd0394764ed79a7e2590f39100ab3fcb91", "best_bid": "0.805", "best_ask": "0.806"}, {"asset_id": "54533043819946592547517511176940999955633860128497669742211153063842200957669", "price": "0.98", "size": "13000", "side": "SELL", "hash": "0e6ca15a28707204ffa2348bacde4ec582250e22", "best_bid": "0.194", "best_ask": "0.195"}], "timestamp": "1785164121003", "event_type": "price_change"}}
{"ts": 1785164121.242, "kind": "price_change", "data": {"market": "0x18b1c135d0a40c5894da9412e77311827d9caf16cf4cd6591b247a34730af919", "price_changes": [{"asset_id": "40081275558852222228080198821361202017557872256707631666334039001378518619916", "price": "0.418", "size": "6353.25", "side": "BUY", "hash": "f62445170950a36c3540363f6e043e45773c6538", "best_bid": "0.428", "best_ask": "0.429"}, {"asset_id": "78633590736077251574794513664747155551297291244492840448622550955320930591622", "price": "0.582", "size": "6353.25", "side": "SELL", "hash": "a60200e3f641c275bbeba8bd97399b313c7c4107", "best_bid": "0.571", "best_ask": "0.572"}], "timestamp": "1785164121242", "event_type": "price_change"}}
{"ts": 1785164121.318, "kind": "price_change", "data": {"market": "0x18b1c135d0a40c5894da9412e77311827d9caf16cf4cd6591b247a34730af919", "price_changes": [{"asset_id": "40081275558852222228080198821361202017557872256707631666334039001378518619916", "price": "0.418", "size": "7431.25", "side": "BUY", "hash": "60979cc9f3b8557d23c17fb701bd676d624deb73", "best_bid": "0.428", "best_ask": "0.429"}, {"asset_id": "78633590736077251574794513664747155551297291244492840448622550955320930591622", "price": "0.582", "size": "7431.25", "side": "SELL", "hash": "19c00b6e41502c458fd541798436d0746057c3aa", "best_bid": "0.571", "best_ask": "0.572"}], "timestamp": "1785164121318", "event_type": "price_change"}}
{"ts": 1785164127.69, "kind": "price_change", "data": {"market": "0x0f49db97f71c68b1e42a6d16e3de93d85dbf7d4148e3f018eb79e88554be9f75", "price_changes": [{"asset_id": "87854174148074652060467921081181402357467303721471806610111179101805869578687", "price": "0.02", "size": "73000", "side": "BUY", "hash": "876a0aa6efe991a73380ec9525cb0ec0b98d7564", "best_bid": "0.805", "best_ask": "0.806"}, {"asset_id": "54533043819946592547517511176940999955633860128497669742211153063842200957669", "price": "0.98", "size": "73000", "side": "SELL", "hash": "acdca6c649586f47434a24702b92d33dbc440eb8", "best_bid": "0.194", "best_ask": "0.195"}], "timestamp": "1785164127690", "event_type": "price_change"}}
{"ts": 1785164127.691, "kind": "price_change", "data": {"market": "0x0f49db97f71c68b1e42a6d16e3de93d85dbf7d4148e3f018eb79e88554be9f75", "price_changes": [{"asset_id": "87854174148074652060467921081181402357467303721471806610111179101805869578687", "price": "0.02", "size": "158000", "side": "BUY", "hash": "8d0e99ceac0b96019b0697374d50c23a9d82b72c", "best_bid": "0.805", "best_ask": "0.806"}, {"asset_id": "54533043819946592547517511176940999955633860128497669742211153063842200957669", "price": "0.98", "size": "158000", "side": "SELL", "hash": "6344b5c1a4a3bf4b2d1586513bd7d6f3f5c80aa1", "best_bid": "0.194", "best_ask": "0.195"}], "timestamp": "1785164127691", "event_type": "price_change"}}
{"ts": 1785164127.692, "kind": "price_change", "data": {"market": "0x0f49db97f71c68b1e42a6d16e3de93d85dbf7d4148e3f018eb79e88554be9f75", "price_changes": [{"asset_id": "87854174148074652060467921081181402357467303721471806610111179101805869578687", "price": "0.02", "size": "233000", "side": "BUY", "hash": "6bbb080c83217002893903cf808e448e589cef92", "best_bid": "0.805", "best_ask": "0.806"}, {"asset_id": "54533043819946592547517511176940999955633860128497669742211153063842200957669", "price": "0.98", "size": "233000", "side": "SELL", "hash": "eb5a839ec540cc4b5407c25cb986ba4dca1f6353", "best_bid": "0.194", "best_ask": "0.195"}], "timestamp": "1785164127692", "event_type": "price_change"}}
{"ts": 1785164128.395, "kind": "price_change", "data": {"market": "0x18b1c135d0a40c5894da9412e77311827d9caf16cf4cd6591b247a34730af919", "price_changes": [{"asset_id": "40081275558852222228080198821361202017557872256707631666334039001378518619916", "price": "0.506", "size": "0", "side": "SELL", "hash": "61b51be35dda305bd2fc6040aaad0f521f43d295", "best_bid": "0.428", "best_ask": "0.429"}, {"asset_id": "78633590736077251574794513664747155551297291244492840448622550955320930591622", "price": "0.494", "size": "0", "side": "BUY", "hash": "1b1dd5991a0123a701df12972882a1bb4e8af105", "best_bid": "0.571", "best_ask": "0.572"}], "timestamp": "1785164128395", "event_type": "price_change"}}
{"ts": 1785164129.049, "kind": "price_change", "data": {"market": "0x0f49db97f71c68b1e42a6d16e3de93d85dbf7d4148e3f018eb79e88554be9f75", "price_changes": [{"asset_id": "87854174148074652060467921081181402357467303721471806610111179101805869578687", "price": "0.795", "size": "2649.98", "side": "BUY", "hash": "f5b38ca5a61a26e72e2fd398e104461127d1cc25", "best_bid": "0.805", "best_ask": "0.806"}, {"asset_id": "54533043819946592547517511176940999955633860128497669742211153063842200957669", "price": "0.205", "size": "2649.98", "side": "SELL", "hash": "514d639d780e28c7c8909f20393e2459465a7aaa", "best_bid": "0.194", "best_ask": "0.195"}], "timestamp": "1785164129049", "event_type": "price_change"}}
{"ts": 1785164129.131, "kind": "price_change", "data": {"market": "0x0f49db97f71c68b1e42a6d16e3de93d85dbf7d4148e3f018eb79e88554be9f75", "price_changes": [{"asset_id": "87854174148074652060467921081181402357467303721471806610111179101805869578687", "price": "0.795", "size": "3215.98", "side": "BUY", "hash": "57f79e267508bea0833d31d74457a3e1b52d6c54", "best_bid": "0.805", "best_ask": "0.806"}, {"asset_id": "54533043819946592547517511176940999955633860128497669742211153063842200957669", "price": "0.205", "size": "3215.98", "side": "SELL", "hash": "3111742100b1dd5ab4add89546f734ff84660d34", "best_bid": "0.194", "best_ask": "0.195"}], "timestamp": "1785164129131", "event_type": "price_change"}}
{"ts": 1785164129.381, "kind": "price_change", "data": {"market": "0x18b1c135d0a40c5894da9412e77311827d9caf16cf4cd6591b247a34730af919", "price_changes": [{"asset_id": "40081275558852222228080198821361202017557872256707631666334039001378518619916", "price": "0.505", "size": "36.7", "side": "SELL", "hash": "a6708aa61322d6b8701245be0fe658d27d25e6d4", "best_bid": "0.428", "best_ask": "0.429"}, {"asset_id": "78633590736077251574794513664747155551297291244492840448622550955320930591622", "price": "0.495", "size": "36.7", "side": "BUY", "hash": "17f82924982b6849d5ccea2c730d24e23ba907ff", "best_bid": "0.571", "best_ask": "0.572"}], "timestamp": "1785164129381", "event_type": "price_change"}}
{"ts": 1785164129.708, "kind": "price_change", "data": {"market": "0x18b1c135d0a40c5894da9412e77311827d9caf16cf4cd6591b247a34730af919", "price_changes": [{"asset_id": "40081275558852222228080198821361202017557872256707631666334039001378518619916", "price": "0.418", "size": "6355.25", "side": "BUY", "hash": "ed1809dc4bcdc9d6d335d7c143ace79bb3c5a0c8", "best_bid": "0.428", "best_ask": "0.429"}, {"asset_id": "78633590736077251574794513664747155551297291244492840448622550955320930591622", "price": "0.582", "size": "6355.25", "side": "SELL", "hash": "1827d7ba9b5f493eabd1bc2a684df556414ece0b", "best_bid": "0.571", "best_ask": "0.572"}], "timestamp": "1785164129708", "event_type": "price_change"}}
{"ts": 1785164129.804, "kind": "price_change", "data": {"market": "0x18b1c135d0a40c5894da9412e77311827d9caf16cf4cd6591b247a34730af919", "price_changes": [{"asset_id": "40081275558852222228080198821361202017557872256707631666334039001378518619916", "price": "0.418", "size": "7431.25", "side": "BUY", "hash": "53dc716f2c7e9786e1a7d5bac946a7489b93677c", "best_bid": "0.428", "best_ask": "0.429"}, {"asset_id": "78633590736077251574794513664747155551297291244492840448622550955320930591622", "price": "0.582", "size": "7431.25", "side": "SELL", "hash": "8a5704f7ef7347e2781a8402b60970265a2d825f", "best_bid": "0.571", "best_ask": "0.572"}], "timestamp": "1785164129804", "event_type": "price_change"}}
{"ts": 1785164129.885, "kind": "price_change", "data": {"market": "0x18b1c135d0a40c5894da9412e77311827d9caf16cf4cd6591b247a34730af919", "price_changes": [{"asset_id": "78633590736077251574794513664747155551297291244492840448622550955320930591622", "price": "0.549", "size": "9.99", "side": "BUY", "hash": "6dc6885fc20097adf1b0a2ca76e4dbec64876c93", "best_bid": "0.571", "best_ask": "0.572"}, {"asset_id": "40081275558852222228080198821361202017557872256707631666334039001378518619916", "price": "0.451", "size": "9.99", "side": "SELL", "hash": "4afd6ac1215f207aef8e6dd918828ca6a4932334", "best_bid": "0.428", "best_ask": "0.429"}], "timestamp": "1785164129885", "event_type": "price_change"}}
{"ts": 1785164129.944, "kind": "price_change", "data": {"market": "0x18b1c135d0a40c5894da9412e77311827d9caf16cf4cd6591b247a34730af919", "price_changes": [{"asset_id": "40081275558852222228080198821361202017557872256707631666334039001378518619916", "price": "0.505", "size": "0", "side": "SELL", "hash": "d11a49f307ed9f09f343dee698ad920b3fc8a3a3", "best_bid": "0.428", "best_ask": "0.429"}, {"asset_id": "78633590736077251574794513664747155551297291244492840448622550955320930591622", "price": "0.495", "size": "0", "side": "BUY", "hash": "2dbeb6502f0844ee53dd88962aa4fc43ac3a5a5f", "best_bid": "0.571", "best_ask": "0.572"}], "timestamp": "1785164129944", "event_type": "price_change"}}
{"ts": 1785164130.007, "kind": "price_change", "data": {"market": "0x18b1c135d0a40c5894da9412e77311827d9caf16cf4cd6591b247a34730af919", "price_changes": [{"asset_id": "78633590736077251574794513664747155551297291244492840448622550955320930591622", "price": "0.549", "size": "0", "side": "BUY", "hash": "69806814851f3a78632c8c350862ab104d6a767f", "best_bid": "0.571", "best_ask": "0.572"}, {"asset_id": "40081275558852222228080198821361202017557872256707631666334039001378518619916", "price": "0.451", "size": "0", "side": "SELL", "hash": "0e4f81584ea8b51b48c40b153dca1e0170f4b685", "best_bid": "0.428", "best_ask": "0.429"}], "timestamp": "1785164130007", "event_type": "price_change"}}
{"ts": 1785164130.271, "kind": "price_change", "data": {"market": "0x18b1c135d0a40c5894da9412e77311827d9caf16cf4cd6591b247a34730af919", "price_changes": [{"asset_id": "40081275558852222228080198821361202017557872256707631666334039001378518619916", "price": "0.506", "size": "36.7", "side": "SELL", "hash": "77f1002911b24dbe918d84fb2d3c1d83dfd91bcb", "best_bid": "0.428", "best_ask": "0.429"}, {"asset_id": "78633590736077251574794513664747155551297291244492840448622550955320930591622", "price": "0.494", "size": "36.7", "side": "BUY", "hash": "5522f7b4cc39327d5ff8736473c8966c2c57e170", "best_bid": "0.571", "best_ask": "0.572"}], "timestamp": "1785164130271", "event_type": "price_change"}}
{"ts": 1785164130.85, "kind": "price_change", "data": {"market": "0x18b1c135d0a40c5894da9412e77311827d9caf16cf4cd6591b247a34730af919", "price_changes": [{"asset_id": "78633590736077251574794513664747155551297291244492840448622550955320930591622", "price": "0.482", "size": "161.09", "side": "BUY", "hash": "693eba57767b4a6e894df09b7f6640f974307294", "best_bid": "0.571", "best_ask": "0.572"}, {"asset_id": "40081275558852222228080198821361202017557872256707631666334039001378518619916", "price": "0.518", "size": "161.09", "side": "SELL", "hash": "017230e1255db2ee828ed35aeb48884149524fb5", "best_bid": "0.428", "best_ask": "0.429"}], "timestamp": "1785164130850", "event_type": "price_change"}}
{"ts": 1785164130.888, "kind": "price_change", "data": {"market": "0x18b1c135d0a40c5894da9412e77311827d9caf16cf4cd6591b247a34730af919", "price_changes": [{"asset_id": "78633590736077251574794513664747155551297291244492840448622550955320930591622", "price": "0.485", "size": "0", "side": "BUY", "hash": "ecce28f3a9777df6854ad57813aa175a6fd9129c", "best_bid": "0.571", "best_ask": "0.572"}, {"asset_id": "40081275558852222228080198821361202017557872256707631666334039001378518619916", "price": "0.515", "size": "0", "side": "SELL", "hash": "65a1bd09e152d0ed2ad17684bca10dc701a96777", "best_bid": "0.428", "best_ask": "0.429"}], "timestamp": "1785164130888", "event_type": "price_change"}}
{"ts": 1785164130.888, "kind": "price_change", "data": {"market": "0x18b1c135d0a40c5894da9412e77311827d9caf16cf4cd6591b247a34730af919", "price_changes": [{"asset_id": "78633590736077251574794513664747155551297291244492840448622550955320930591622", "price": "0.482", "size": "0", "side": "BUY", "hash": "ecce28f3a9777df6854ad57813aa175a6fd9129c", "best_bid": "0.571", "best_ask": "0.572"}, {"asset_id": "40081275558852222228080198821361202017557872256707631666334039001378518619916", "price": "0.518", "size": "0", "side": "SELL", "hash": "65a1bd09e152d0ed2ad17684bca10dc701a96777", "best_bid": "0.428", "best_ask": "0.429"}], "timestamp": "1785164130888", "event_type": "price_change"}}
{"ts": 1785164130.894, "kind": "price_change", "data": {"market": "0x18b1c135d0a40c5894da9412e77311827d9caf16cf4cd6591b247a34730af919", "price_changes": [{"asset_id": "78633590736077251574794513664747155551297291244492840448622550955320930591622", "price": "0.486", "size": "10", "side": "BUY", "hash": "2dede15cdc2ad96355591701b75f1de70b9683ba", "best_bid": "0.571", "best_ask": "0.572"}, {"asset_id": "40081275558852222228080198821361202017557872256707631666334039001378518619916", "price": "0.514", "size": "10", "side": "SELL", "hash": "a718d2985eb15167b2789ff5224220edfeaf622b", "best_bid": "0.428", "best_ask": "0.429"}], "timestamp": "1785164130894", "event_type": "price_change"}}
{"ts": 1785164130.896, "kind": "price_change", "data": {"market": "0x18b1c135d0a40c5894da9412e77311827d9caf16cf4cd6591b247a34730af919", "price_changes": [{"asset_id": "78633590736077251574794513664747155551297291244492840448622550955320930591622", "price": "0.479", "size": "238.09", "side": "BUY", "hash": "7c667fb002805b53c03793012fd82ec0d2faa6c5", "best_bid": "0.571", "best_ask": "0.572"}, {"asset_id": "40081275558852222228080198821361202017557872256707631666334039001378518619916", "price": "0.521", "size": "238.09", "side": "SELL", "hash": "85c33ee6f05d1576f7f7fa7331534245b89f1495", "best_bid": "0.428", "best_ask": "0.429"}], "timestamp": "1785164130896", "event_type": "price_change"}}
{"ts": 1785164130.897, "kind": "price_change", "data": {"market": "0x18b1c135d0a40c5894da9412e77311827d9caf16cf4cd6591b247a34730af919", "price_changes": [{"asset_id": "78633590736077251574794513664747155551297291244492840448622550955320930591622", "price": "0.485", "size": "30", "side": "BUY", "hash": "13cc61940e5dae01da140db181373678c993dd53", "best_bid": "0.571", "best_ask": "0.572"}, {"asset_id": "40081275558852222228080198821361202017557872256707631666334039001378518619916", "price": "0.515", "size": "30", "side": "SELL", "hash": "4a6cb55013aecd07fd92ccd7624d2db744e6e64b", "best_bid": "0.428", "best_ask": "0.429"}], "timestamp": "1785164130897", "event_type": "price_change"}}
{"ts": 1785164130.917, "kind": "price_change", "data": {"market": "0x18b1c135d0a40c5894da9412e77311827d9caf16cf4cd6591b247a34730af919", "price_changes": [{"asset_id": "78633590736077251574794513664747155551297291244492840448622550955320930591622", "price": "0.549", "size": "9.99", "side": "BUY", "hash": "ab99da6c5c1a5bb0fbdf9db7a3eb6ef0cf856f83", "best_bid": "0.571", "best_ask": "0.572"}, {"asset_id": "40081275558852222228080198821361202017557872256707631666334039001378518619916", "price": "0.451", "size": "9.99", "side": "SELL", "hash": "5796ec1c27e437e88bb595f9d9f0145947f25cb4", "best_bid": "0.428", "best_ask": "0.429"}], "timestamp": "1785164130917", "event_type": "price_change"}}
{"ts": 1785164130.929, "kind": "price_change", "data": {"market": "0x18b1c135d0a40c5894da9412e77311827d9caf16cf4cd6591b247a34730af919", "price_changes": [{"asset_id": "78633590736077251574794513664747155551297291244492840448622550955320930591622", "price": "0.486", "size": "0", "side": "BUY", "hash": "17655fc9bc0f8d39d3ccf7bf267a9d24648407d4", "best_bid": "0.571", "best_ask": "0.572"}, {"asset_id": "40081275558852222228080198821361202017557872256707631666334039001378518619916", "price": "0.514", "size": "0", "side": "SELL", "hash": "6183fb2a1a16725a7a67cd9a874671ef71a40462", "best_bid": "0.428", "best_ask": "0.429"}], "timestamp": "1785164130929", "event_type": "price_change"}}
{"ts": 1785164130.929, "kind": "price_change", "data": {"market": "0x18b1c135d0a40c5894da9412e77311827d9caf16cf4cd6591b247a34730af919", "price_changes": [{"asset_id": "78633590736077251574794513664747155551297291244492840448622550955320930591622", "price": "0.485", "size": "0", "side": "BUY", "hash": "17655fc9bc0f8d39d3ccf7bf267a9d24648407d4", "best_bid": "0.571", "best_ask": "0.572"}, {"asset_id": "40081275558852222228080198821361202017557872256707631666334039001378518619916", "price": "0.515", "size": "0", "side": "SELL", "hash": "6183fb2a1a16725a7a67cd9a874671ef71a40462", "best_bid": "0.428", "best_ask": "0.429"}], "timestamp": "1785164130929", "event_type": "price_change"}}
{"ts": 1785164130.951, "kind": "price_change", "data": {"market": "0x18b1c135d0a40c5894da9412e77311827d9caf16cf4cd6591b247a34730af919", "price_changes": [{"asset_id": "78633590736077251574794513664747155551297291244492840448622550955320930591622", "price": "0.479", "size": "0", "side": "BUY", "hash": "fdbe3551ef03b8d65a944adb8c58d5a8c3ce5148", "best_bid": "0.571", "best_ask": "0.572"}, {"asset_id": "40081275558852222228080198821361202017557872256707631666334039001378518619916", "price": "0.521", "size": "0", "side": "SELL", "hash": "8f47c35b9f9a681bbd83dadee50bcaea3c43ae08", "best_bid": "0.428", "best_ask": "0.429"}], "timestamp": "1785164130951", "event_type": "price_change"}}
{"ts": 1785164130.955, "kind": "price_change", "data": {"market": "0x18b1c135d0a40c5894da9412e77311827d9caf16cf4cd6591b247a34730af919", "price_changes": [{"asset_id": "78633590736077251574794513664747155551297291244492840448622550955320930591622", "price": "0.482", "size": "10", "side": "BUY", "hash": "913f5d2d420246bbd986ee69802b407397677ed9", "best_bid": "0.571", "best_ask": "0.572"}, {"asset_id": "40081275558852222228080198821361202017557872256707631666334039001378518619916", "price": "0.518", "size": "10", "side": "SELL", "hash": "0ae2dc2ab04bd389aac269c5e341f8923b5d7e1c", "best_bid": "0.428", "best_ask": "0.429"}], "timestamp": "1785164130955", "event_type": "price_change"}}
{"ts": 1785164130.956, "kind": "price_change", "data": {"market": "0x18b1c135d0a40c5894da9412e77311827d9caf16cf4cd6591b247a34730af919", "price_changes": [{"asset_id": "78633590736077251574794513664747155551297291244492840448622550955320930591622", "price": "0.482", "size": "40", "side": "BUY", "hash": "b8ef9aca2b3b136fe2cdc2be694cf936046efd13", "best_bid": "0.571", "best_ask": "0.572"}, {"asset_id": "40081275558852222228080198821361202017557872256707631666334039001378518619916", "price": "0.518", "size": "40", "side": "SELL", "hash": "ef2a73b16486d3daf271c2702fae31f4c5e18027", "best_bid": "0.428", "best_ask": "0.429"}], "timestamp": "1785164130956", "event_type": "price_change"}}
{"ts": 1785164130.982, "kind": "price_change", "data": {"market": "0x18b1c135d0a40c5894da9412e77311827d9caf16cf4cd6591b247a34730af919", "price_changes": [{"asset_id": "78633590736077251574794513664747155551297291244492840448622550955320930591622", "price": "0.549", "size": "0", "side": "BUY", "hash": "2a60ab36f53f8ab227cabf5f39121b872bfb4e43", "best_bid": "0.571", "best_ask": "0.572"}, {"asset_id": "40081275558852222228080198821361202017557872256707631666334039001378518619916", "price": "0.451", "size": "0", "side": "SELL", "hash": "8f7b539b837c2ac08a864c72b974900376e37b36", "best_bid": "0.428", "best_ask": "0.429"}], "timestamp": "1785164130982", "event_type": "price_change"}}
{"ts": 1785164131.378, "kind": "price_change", "data": {"market": "0x18b1c135d0a40c5894da9412e77311827d9caf16cf4cd6591b247a34730af919", "price_changes": [{"asset_id": "40081275558852222228080198821361202017557872256707631666334039001378518619916", "price": "0.412", "size": "11323.8", "side": "BUY", "hash": "f54c61f470dee4a8947fa46ddb2078c9d0fdf280", "best_bid": "0.428", "best_ask": "0.429"}, {"asset_id": "78633590736077251574794513664747155551297291244492840448622550955320930591622", "price": "0.588", "size": "11323.8", "side": "SELL", "hash": "b7c6464838526b4f87f13ef5fd7ac8037241fa8f", "best_bid": "0.571", "best_ask": "0.572"}], "timestamp": "1785164131378", "event_type": "price_change"}}
{"ts": 1785164131.383, "kind": "price_change", "data": {"market": "0x18b1c135d0a40c5894da9412e77311827d9caf16cf4cd6591b247a34730af919", "price_changes": [{"asset_id": "40081275558852222228080198821361202017557872256707631666334039001378518619916", "price": "0.411", "size": "37109.4", "side": "BUY", "hash": "ef57b9d4ab0bde6f48c263fd21d479712c46f897", "best_bid": "0.428", "best_ask": "0.429"}, {"asset_id": "78633590736077251574794513664747155551297291244492840448622550955320930591622", "price": "0.589", "size": "37109.4", "side": "SELL", "hash": "3a9bf2ac376ce229e49778c8040cf4f6b3cc4bdd", "best_bid": "0.571", "best_ask": "0.572"}], "timestamp": "1785164131383", "event_type": "price_change"}}
{"ts": 1785164131.405, "kind": "price_change", "data": {"market": "0x18b1c135d0a40c5894da9412e77311827d9caf16cf4cd6591b247a34730af919", "price_changes": [{"asset_id": "78633590736077251574794513664747155551297291244492840448622550955320930591622", "price": "0.561", "size": "12582.6", "side": "BUY", "hash": "6316c3474659a21c580edd664c0a1b250fdc74fe", "best_bid": "0.571", "best_ask": "0.572"}, {"asset_id": "40081275558852222228080198821361202017557872256707631666334039001378518619916", "price": "0.439", "size": "12582.6", "side": "SELL", "hash": "9469a4620acf2124c88b43345d0d94948162f53e", "best_bid": "0.428", "best_ask": "0.429"}], "timestamp": "1785164131405", "event_type": "price_change"}}
{"ts": 1785164131.411, "kind": "price_change", "data": {"market": "0x18b1c135d0a40c5894da9412e77311827d9caf16cf4cd6591b247a34730af919", "price_changes": [{"asset_id": "78633590736077251574794513664747155551297291244492840448622550955320930591622", "price": "0.532", "size": "74856.91", "side": "BUY", "hash": "ff1b545163fc9bf3d82908dae00fe4faf2c2e018", "best_bid": "0.571", "best_ask": "0.572"}, {"asset_id": "40081275558852222228080198821361202017557872256707631666334039001378518619916", "price": "0.468", "size": "74856.91", "side": "SELL", "hash": "8bd593041304058f08d87e18553ab0fa0fe08e9f", "best_bid": "0.428", "best_ask": "0.429"}], "timestamp": "1785164131411", "event_type": "price_change"}}
{"ts": 1785164131.42, "kind": "price_change", "data": {"market": "0x18b1c135d0a40c5894da9412e77311827d9caf16cf4cd6591b247a34730af919", "price_changes": [{"asset_id": "40081275558852222228080198821361202017557872256707631666334039001378518619916", "price": "0.398", "size": "14592.5", "side": "BUY", "hash": "2afb6e7798fbc7245b1b346d3c0722bf505e1aaf", "best_bid": "0.428", "best_ask": "0.429"}, {"asset_id": "78633590736077251574794513664747155551297291244492840448622550955320930591622", "price": "0.602", "size": "14592.5", "side": "SELL", "hash": "041838a405bc43951ea40fdd7a300c13640c229f", "best_bid": "0.571", "best_ask": "0.572"}], "timestamp": "1785164131420", "event_type": "price_change"}}
{"ts": 1785164131.433, "kind": "price_change", "data": {"market": "0x18b1c135d0a40c5894da9412e77311827d9caf16cf4cd6591b247a34730af919", "price_changes": [{"asset_id": "78633590736077251574794513664747155551297291244492840448622550955320930591622", "price": "0.555", "size": "12364.59", "side": "BUY", "hash": "22dc986b45089958213dd046c671de7d087f8aec", "best_bid": "0.571", "best_ask": "0.572"}, {"asset_id": "40081275558852222228080198821361202017557872256707631666334039001378518619916", "price": "0.445", "size": "12364.59", "side": "SELL", "hash": "b0a7bd0ecd135070014af3eb497ba2f956f2c0e4", "best_bid": "0.428", "best_ask": "0.429"}], "timestamp": "1785164131433", "event_type": "price_change"}}
{"ts": 1785164131.444, "kind": "price_change", "data": {"market": "0x18b1c135d0a40c5894da9412e77311827d9caf16cf4cd6591b247a34730af919", "price_changes": [{"asset_id": "40081275558852222228080198821361202017557872256707631666334039001378518619916", "price": "0.397", "size": "50704", "side": "BUY", "hash": "f23f4742804c625072f260aff2af9edde28ef067", "best_bid": "0.428", "best_ask": "0.429"}, {"asset_id": "78633590736077251574794513664747155551297291244492840448622550955320930591622", "price": "0.603", "size": "50704", "side": "SELL", "hash": "179ef3299d7c6e87109986d021f168e5f30b9d05", "best_bid": "0.571", "best_ask": "0.572"}], "timestamp": "1785164131444", "event_type": "price_change"}}
{"ts": 1785164131.449, "kind": "price_change", "data": {"market": "0x18b1c135d0a40c5894da9412e77311827d9caf16cf4cd6591b247a34730af919", "price_changes": [{"asset_id": "78633590736077251574794513664747155551297291244492840448622550955320930591622", "price": "0.56", "size": "5894.39", "side": "BUY", "hash": "564c3a1086fd762548429c700aad18ca266ed7e1", "best_bid": "0.571", "best_ask": "0.572"}, {"asset_id": "40081275558852222228080198821361202017557872256707631666334039001378518619916", "price": "0.44", "size": "5894.39", "side": "SELL", "hash": "5636be8212c5e6251f41ebf99e6c74f34c9e2c09", "best_bid": "0.428", "best_ask": "0.429"}], "timestamp": "1785164131449", "event_type": "price_change"}}
{"ts": 1785164131.451, "kind": "price_change", "data": {"market": "0x18b1c135d0a40c5894da9412e77311827d9caf16cf4cd6591b247a34730af919", "price_changes": [{"asset_id": "78633590736077251574794513664747155551297291244492840448622550955320930591622", "price": "0.551", "size": "28708.16", "side": "BUY", "hash": "d4ea65462957e5b67d6b6e8764f73018b947a11e", "best_bid": "0.571", "best_ask": "0.572"}, {"asset_id": "40081275558852222228080198821361202017557872256707631666334039001378518619916", "price": "0.449", "size": "28708.16", "side": "SELL", "hash": "5005e99bb2a294a34088388508a9f683bdbda2de", "best_bid": "0.428", "best_ask": "0.429"}], "timestamp": "1785164131451", "event_type": "price_change"}}
{"ts": 1785164131.452, "kind": "price_change", "data": {"market": "0x18b1c135d0a40c5894da9412e77311827d9caf16cf4cd6591b247a34730af919", "price_changes": [{"asset_id": "40081275558852222228080198821361202017557872256707631666334039001378518619916", "price": "0.399", "size": "10218.2", "side": "BUY", "hash": "0f4591d3c2c4eb8acc1a52af5217251a63c10a8a", "best_bid": "0.428", "best_ask": "0.429"}, {"asset_id": "78633590736077251574794513664747155551297291244492840448622550955320930591622", "price": "0.601", "size": "10218.2", "side": "SELL", "hash": "4335ff96dc50793e7100e19e3ce7add96fcae367", "best_bid": "0.571", "best_ask": "0.572"}], "timestamp": "1785164131452", "event_type": "price_change"}}
{"ts": 1785164131.458, "kind": "price_change", "data": {"market": "0x18b1c135d0a40c5894da9412e77311827d9caf16cf4cd6591b247a34730af919", "price_changes": [{"asset_id": "40081275558852222228080198821361202017557872256707631666334039001378518619916", "price": "0.418", "size": "7505.55", "side": "BUY", "hash": "45de2837db293240ad1b106a1e9c2a671f000cba", "best_bid": "0.428", "best_ask": "0.429"}, {"asset_id": "78633590736077251574794513664747155551297291244492840448622550955320930591622", "price": "0.582", "size": "7505.55", "side": "SELL", "hash": "9260ec1b012b64a582f08089cff9bd5133ecf3df", "best_bid": "0.571", "best_ask": "0.572"}], "timestamp": "1785164131458", "event_type": "price_change"}}
{"ts": 1785164131.462, "kind": "price_change", "data": {"market": "0x18b1c135d0a40c5894da9412e77311827d9caf16cf4cd6591b247a34730af919", "price_changes": [{"asset_id": "78633590736077251574794513664747155551297291244492840448622550955320930591622", "price": "0.55", "size": "30581.18", "side": "BUY", "hash": "c219a8a5ce56f1637da38bec577da28e8f1682f8", "best_bid": "0.571", "best_ask": "0.572"}, {"asset_id": "40081275558852222228080198821361202017557872256707631666334039001378518619916", "price": "0.45", "size": "30581.18", "side": "SELL", "hash": "e1226ee5711c7498c69404be6d16a1eb6e2e4865", "best_bid": "0.428", "best_ask": "0.429"}], "timestamp": "1785164131462", "event_type": "price_change"}}
{"ts": 1785164131.486, "kind": "price_change", "data": {"market": "0x18b1c135d0a40c5894da9412e77311827d9caf16cf4cd6591b247a34730af919", "price_changes": [{"asset_id": "40081275558852222228080198821361202017557872256707631666334039001378518619916", "price": "0.412", "size": "11123.8", "side": "BUY", "hash": "eab3584e1d8e8120383ce727cfe29f5461536c02", "best_bid": "0.428", "best_ask": "0.429"}, {"asset_id": "78633590736077251574794513664747155551297291244492840448622550955320930591622", "price": "0.588", "size": "11123.8", "side": "SELL", "hash": "bab975b84f868a210e28527dd01b0aaf1b81eb30", "best_bid": "0.571", "best_ask": "0.572"}], "timestamp": "1785164131486", "event_type": "price_change"}}
{"ts": 1785164131.517, "kind": "price_change", "data": {"market": "0x18b1c135d0a40c5894da9412e77311827d9caf16cf4cd6591b247a34730af919", "price_changes": [{"asset_id": "40081275558852222228080198821361202017557872256707631666334039001378518619916", "price": "0.414", "size": "500", "side": "BUY", "hash": "d7e1e8ce02440907349ffb8e48d2a55fa600ee5e", "best_bid": "0.428", "best_ask": "0.429"}, {"asset_id": "78633590736077251574794513664747155551297291244492840448622550955320930591622", "price": "0.586", "size": "500", "side": "SELL", "hash": "2f4f014ea07ca2edcbe5474656853fc7f4d216c0", "best_bid": "0.571", "best_ask": "0.572"}], "timestamp": "1785164131517", "event_type": "price_change"}}
{"ts": 1785164131.534, "kind": "price_change", "data": {"market": "0x18b1c135d0a40c5894da9412e77311827d9caf16cf4cd6591b247a34730af919", "price_changes": [{"asset_id": "78633590736077251574794513664747155551297291244492840448622550955320930591622", "price": "0.549", "size": "9.99", "side": "BUY", "hash": "01f10ebe1393d3745b2429a65035969233247b3e", "best_bid": "0.571", "best_ask": "0.572"}, {"asset_id": "40081275558852222228080198821361202017557872256707631666334039001378518619916", "price": "0.451", "size": "9.99", "side": "SELL", "hash": "99a20d219666d85884bbabd8e923d5da4a0e9226", "best_bid": "0.428", "best_ask": "0.429"}], "timestamp": "1785164131534", "event_type": "price_change"}}
{"ts": 1785164131.746, "kind": "price_change", "data": {"market": "0x0f49db97f71c68b1e42a6d16e3de93d85dbf7d4148e3f018eb79e88554be9f75", "price_changes": [{"asset_id": "87854174148074652060467921081181402357467303721471806610111179101805869578687", "price": "0.02", "size": "220500", "side": "BUY", "hash": "693ade54989424d9deb22570134faab5adf2cc64", "best_bid": "0.805", "best_ask": "0.806"}, {"asset_id": "54533043819946592547517511176940999955633860128497669742211153063842200957669", "price": "0.98", "size": "220500", "side": "SELL", "hash": "f1d5865dbc21cbb34da9a560c78fac767afeb83a", "best_bid": "0.194", "best_ask": "0.195"}], "timestamp": "1785164131746", "event_type": "price_change"}}
{"ts": 1785164131.755, "kind": "price_change", "data": {"market": "0x0f49db97f71c68b1e42a6d16e3de93d85dbf7d4148e3f018eb79e88554be9f75", "price_changes": [{"asset_id": "87854174148074652060467921081181402357467303721471806610111179101805869578687", "price": "0.64", "size": "234", "side": "BUY", "hash": "aae2fc9bec5d09a801bd09f7f05f430537128579", "best_bid": "0.805", "best_ask": "0.806"}, {"asset_id": "54533043819946592547517511176940999955633860128497669742211153063842200957669", "price": "0.36", "size": "234", "side": "SELL", "hash": "6837805075c8c7a2564b81dfac9026bc855d7810", "best_bid": "0.194", "best_ask": "0.195"}], "timestamp": "1785164131755", "event_type": "price_change"}}
{"ts": 1785164132.043808, "kind": "orders_out", "data": [{"token_id": "54533043819946592547517511176940999955633860128497669742211153063842200957669", "side": "BUY", "price": 0.153, "size": 19.61}]}
{"ts": 1785164132.003, "kind": "price_change", "data": {"market": "0x18b1c135d0a40c5894da9412e77311827d9caf16cf4cd6591b247a34730af919", "price_changes": [{"asset_id": "40081275558852222228080198821361202017557872256707631666334039001378518619916", "price": "0.171", "size": "0", "side": "BUY", "hash": "0ce909ecc465f94a670ae3cf67e086a51a937944", "best_bid": "0.428", "best_ask": "0.429"}, {"asset_id": "78633590736077251574794513664747155551297291244492840448622550955320930591622", "price": "0.829", "size": "0", "side": "SELL", "hash": "40da3eb8d3cdad513bb9cae07fb6370bb33be788", "best_bid": "0.571", "best_ask": "0.572"}], "timestamp": "1785164132003", "event_type": "price_change"}}
{"ts": 1785164132.003, "kind": "price_change", "data": {"market": "0x18b1c135d0a40c5894da9412e77311827d9caf16cf4cd6591b247a34730af919", "price_changes": [{"asset_id": "40081275558852222228080198821361202017557872256707631666334039001378518619916", "price": "0.171", "size": "0", "side": "BUY", "hash": "0ce909ecc465f94a670ae3cf67e086a51a937944", "best_bid": "0.428", "best_ask": "0.429"}, {"asset_id": "78633590736077251574794513664747155551297291244492840448622550955320930591622", "price": "0.829", "size": "0", "side": "SELL", "hash": "40da3eb8d3cdad513bb9cae07fb6370bb33be788", "best_bid": "0.571", "best_ask": "0.572"}], "timestamp": "1785164132003", "event_type": "price_change"}}
{"ts": 1785164133.777, "kind": "price_change", "data": {"market": "0x18b1c135d0a40c5894da9412e77311827d9caf16cf4cd6591b247a34730af919", "price_changes": [{"asset_id": "40081275558852222228080198821361202017557872256707631666334039001378518619916", "price": "0.41", "size": "2931.23", "side": "BUY", "hash": "1d2dab7f87d14a178ce7c3b5f3a06772e53ead86", "best_bid": "0.428", "best_ask": "0.429"}, {"asset_id": "78633590736077251574794513664747155551297291244492840448622550955320930591622", "price": "0.59", "size": "2931.23", "side": "SELL", "hash": "ca13abe546a0a3003d770d9f3cea91416e99c1bd", "best_bid": "0.571", "best_ask": "0.572"}], "timestamp": "1785164133777", "event_type": "price_change"}}
{"ts": 1785164134.631, "kind": "price_change", "data": {"market": "0x18b1c135d0a40c5894da9412e77311827d9caf16cf4cd6591b247a34730af919", "price_changes": [{"asset_id": "40081275558852222228080198821361202017557872256707631666334039001378518619916", "price": "0.41", "size": "2947.28", "side": "BUY", "hash": "abfd6b0e3883f3f1726c3e1386bf3718fb66e639", "best_bid": "0.428", "best_ask": "0.429"}, {"asset_id": "78633590736077251574794513664747155551297291244492840448622550955320930591622", "price": "0.59", "size": "2947.28", "side": "SELL", "hash": "bb7e5e0a97fa3f501cf6da410dc353251fa7cea6", "best_bid": "0.571", "best_ask": "0.572"}], "timestamp": "1785164134631", "event_type": "price_change"}}
{"ts": 1785164137.359, "kind": "price_change", "data": {"market": "0x18b1c135d0a40c5894da9412e77311827d9caf16cf4cd6591b247a34730af919", "price_changes": [{"asset_id": "40081275558852222228080198821361202017557872256707631666334039001378518619916", "price": "0.231", "size": "0", "side": "BUY", "hash": "1a6c38bb6e625f807303494b462428f606358e03", "best_bid": "0.428", "best_ask": "0.429"}, {"asset_id": "78633590736077251574794513664747155551297291244492840448622550955320930591622", "price": "0.769", "size": "0", "side": "SELL", "hash": "90d8f821ad9d088aff17e2393b7bf96f5dd21952", "best_bid": "0.571", "best_ask": "0.572"}], "timestamp": "1785164137359", "event_type": "price_change"}}
{"ts": 1785164137.359, "kind": "price_change", "data": {"market": "0x18b1c135d0a40c5894da9412e77311827d9caf16cf4cd6591b247a34730af919", "price_changes": [{"asset_id": "78633590736077251574794513664747155551297291244492840448622550955320930591622", "price": "0.372", "size": "0", "side": "BUY", "hash": "90d8f821ad9d088aff17e2393b7bf96f5dd21952", "best_bid": "0.571", "best_ask": "0.572"}, {"asset_id": "40081275558852222228080198821361202017557872256707631666334039001378518619916", "price": "0.628", "size": "0", "side": "SELL", "hash": "1a6c38bb6e625f807303494b462428f606358e03", "best_bid": "0.428", "best_ask": "0.429"}], "timestamp": "1785164137359", "event_type": "price_change"}}
{"ts": 1785164137.383, "kind": "price_change", "data": {"market": "0x0f49db97f71c68b1e42a6d16e3de93d85dbf7d4148e3f018eb79e88554be9f75", "price_changes": [{"asset_id": "87854174148074652060467921081181402357467303721471806610111179101805869578687", "price": "0.001", "size": "6146756.01", "side": "BUY", "hash": "05f89a44d25a95a3c579c2174cb3f2ce26fe4fca", "best_bid": "0.805", "best_ask": "0.806"}, {"asset_id": "54533043819946592547517511176940999955633860128497669742211153063842200957669", "price": "0.999", "size": "6146756.01", "side": "SELL", "hash": "96fb76859c5bf4097728ed9fb38183b60275152a", "best_bid": "0.194", "best_ask": "0.195"}], "timestamp": "1785164137383", "event_type": "price_change"}}
{"ts": 1785164137.386, "kind": "price_change", "data": {"market": "0x18b1c135d0a40c5894da9412e77311827d9caf16cf4cd6591b247a34730af919", "price_changes": [{"asset_id": "78633590736077251574794513664747155551297291244492840448622550955320930591622", "price": "0.373", "size": "0", "side": "BUY", "hash": "678158ff196b7249a0cf09cfbaea2562578fd1cd", "best_bid": "0.571", "best_ask": "0.572"}, {"asset_id": "40081275558852222228080198821361202017557872256707631666334039001378518619916", "price": "0.627", "size": "0", "side": "SELL", "hash": "bb4b38a83d144219089e80bc266f86e082437ab2", "best_bid": "0.428", "best_ask": "0.429"}], "timestamp": "1785164137386", "event_type": "price_change"}}
{"ts": 1785164137.396, "kind": "price_change", "data": {"market": "0x0f49db97f71c68b1e42a6d16e3de93d85dbf7d4148e3f018eb79e88554be9f75", "price_changes": [{"asset_id": "87854174148074652060467921081181402357467303721471806610111179101805869578687", "price": "0.001", "size": "6147766.01", "side": "BUY", "hash": "013e7dd0f654520ae46e0b26ccce8fa94326469d", "best_bid": "0.805", "best_ask": "0.806"}, {"asset_id": "54533043819946592547517511176940999955633860128497669742211153063842200957669", "price": "0.999", "size": "6147766.01", "side": "SELL", "hash": "dc1324be8bfe7300dd1a173643ebaa2ec58b5733", "best_bid": "0.194", "best_ask": "0.195"}], "timestamp": "1785164137396", "event_type": "price_change"}}
{"ts": 1785164137.412, "kind": "price_change", "data": {"market": "0x18b1c135d0a40c5894da9412e77311827d9caf16cf4cd6591b247a34730af919", "price_changes": [{"asset_id": "78633590736077251574794513664747155551297291244492840448622550955320930591622", "price": "0.371", "size": "400", "side": "BUY", "hash": "842c4a529a6eaff9f89d9ae4351c749fcd9158ee", "best_bid": "0.571", "best_ask": "0.572"}, {"asset_id": "40081275558852222228080198821361202017557872256707631666334039001378518619916", "price": "0.629", "size": "400", "side": "SELL", "hash": "5e74dd5c0a62d3435ea24bfcf71a4f58b7ad23f1", "best_bid": "0.428", "best_ask": "0.429"}], "timestamp": "1785164137412", "event_type": "price_change"}}
{"ts": 1785164138.204, "kind": "price_change", "data": {"market": "0x18b1c135d0a40c5894da9412e77311827d9caf16cf4cd6591b247a34730af919", "price_changes": [{"asset_id": "40081275558852222228080198821361202017557872256707631666334039001378518619916", "price": "0.221", "size": "48.28", "side": "BUY", "hash": "d470875b484a73103d2262e725d4cd501e265f5d", "best_bid": "0.428", "best_ask": "0.429"}, {"asset_id": "78633590736077251574794513664747155551297291244492840448622550955320930591622", "price": "0.779", "size": "48.28", "side": "SELL", "hash": "439c4d295f0f072fc7ad888f4e7660327fc48e11", "best_bid": "0.571", "best_ask": "0.572"}], "timestamp": "1785164138204", "event_type": "price_change"}}
{"ts": 1785164138.209, "kind": "price_change", "data": {"market": "0x18b1c135d0a40c5894da9412e77311827d9caf16cf4cd6591b247a34730af919", "price_changes": [{"asset_id": "78633590736077251574794513664747155551297291244492840448622550955320930591622", "price": "0.374", "size": "48.28", "side": "BUY", "hash": "ba634e306c06273eb084ccaf9d4d8e46397af4ba", "best_bid": "0.571", "best_ask": "0.572"}, {"asset_id": "40081275558852222228080198821361202017557872256707631666334039001378518619916", "price": "0.626", "size": "48.28", "side": "SELL", "hash": "05a4264b7c77553ffd590d0a6f5238886d5a0c3d", "best_bid": "0.428", "best_ask": "0.429"}], "timestamp": "1785164138209", "event_type": "price_change"}}
{"ts": 1785164144.001, "kind": "price_change", "data": {"market": "0x18b1c135d0a40c5894da9412e77311827d9caf16cf4cd6591b247a34730af919", "price_changes": [{"asset_id": "78633590736077251574794513664747155551297291244492840448622550955320930591622", "price": "0.004", "size": "5000", "side": "BUY", "hash": "d75cbf5a53e343ac6de4b22ded6ef484429ff77f", "best_bid": "0.571", "best_ask": "0.572"}, {"asset_id": "40081275558852222228080198821361202017557872256707631666334039001378518619916", "price": "0.996", "size": "5000", "side": "SELL", "hash": "bb0f2101364e61c3695b9a7fc45d5b6105a0cba3", "best_bid": "0.428", "best_ask": "0.429"}], "timestamp": "1785164144001", "event_type": "price_change"}}
{"ts": 1785164146.847, "kind": "price_change", "data": {"market": "0x18b1c135d0a40c5894da9412e77311827d9caf16cf4cd6591b247a34730af919", "price_changes": [{"asset_id": "40081275558852222228080198821361202017557872256707631666334039001378518619916", "price": "0.506", "size": "0", "side": "SELL", "hash": "dbb829fd9b98a5910b82fc6b958187dd0dd29048", "best_bid": "0.428", "best_ask": "0.429"}, {"asset_id": "78633590736077251574794513664747155551297291244492840448622550955320930591622", "price": "0.494", "size": "0", "side": "BUY", "hash": "16fb9d61895da58dedcd139257d359e7cfe205a7", "best_bid": "0.571", "best_ask": "0.572"}], "timestamp": "1785164146847", "event_type": "price_change"}}
{"ts": 1785164147.833, "kind": "price_change", "data": {"market": "0x18b1c135d0a40c5894da9412e77311827d9caf16cf4cd6591b247a34730af919", "price_changes": [{"asset_id": "78633590736077251574794513664747155551297291244492840448622550955320930591622", "price": "0.004", "size": "15016.91", "side": "BUY", "hash": "5cfd2e45fabf552092e51b2fa02f3cd383291561", "best_bid": "0.571", "best_ask": "0.572"}, {"asset_id": "40081275558852222228080198821361202017557872256707631666334039001378518619916", "price": "0.996", "size": "15016.91", "side": "SELL", "hash": "e682945de853dd290c62dd46a6d127896e1c69c2", "best_bid": "0.428", "best_ask": "0.429"}], "timestamp": "1785164147833", "event_type": "price_change"}}
{"ts": 1785164147.997, "kind": "price_change", "data": {"market": "0x18b1c135d0a40c5894da9412e77311827d9caf16cf4cd6591b247a34730af919", "price_changes": [{"asset_id": "40081275558852222228080198821361202017557872256707631666334039001378518619916", "price": "0.505", "size": "36.7", "side": "SELL", "hash": "c41c00ccfe6a92780306257b1c19e602fd4a1812", "best_bid": "0.428", "best_ask": "0.429"}, {"asset_id": "78633590736077251574794513664747155551297291244492840448622550955320930591622", "price": "0.495", "size": "36.7", "side": "BUY", "hash": "2879dc77b5b2de0a34b5d17ed2085bc71081b1c9", "best_bid": "0.571", "best_ask": "0.572"}], "timestamp": "1785164147997", "event_type": "price_change"}}
{"ts": 1785164148.683, "kind": "price_change", "data": {"market": "0x18b1c135d0a40c5894da9412e77311827d9caf16cf4cd6591b247a34730af919", "price_changes": [{"asset_id": "40081275558852222228080198821361202017557872256707631666334039001378518619916", "price": "0.505", "size": "0", "side": "SELL", "hash": "ed0006d69d97a273fb05e009e4852080841bf88e", "best_bid": "0.428", "best_ask": "0.429"}, {"asset_id": "78633590736077251574794513664747155551297291244492840448622550955320930591622", "price": "0.495", "size": "0", "side": "BUY", "hash": "b8d46054fdbcd82d7a3ddcee9e80fa8449ac9f40", "best_bid": "0.571", "best_ask": "0.572"}], "timestamp": "1785164148683", "event_type": "price_change"}}
{"ts": 1785164149.016, "kind": "price_change", "data": {"market": "0x18b1c135d0a40c5894da9412e77311827d9caf16cf4cd6591b247a34730af919", "price_changes": [{"asset_id": "40081275558852222228080198821361202017557872256707631666334039001378518619916", "price": "0.506", "size": "36.7", "side": "SELL", "hash": "55444f4d4874dd833c8f837b3a297ea0e37a93f2", "best_bid": "0.428", "best_ask": "0.429"}, {"asset_id": "78633590736077251574794513664747155551297291244492840448622550955320930591622", "price": "0.494", "size": "36.7", "side": "BUY", "hash": "f1477eac0c16c1073a4d632c7fe3cf22a5c7ec34", "best_bid": "0.571", "best_ask": "0.572"}], "timestamp": "1785164149016", "event_type": "price_change"}}
{"ts": 1785164150.903, "kind": "price_change", "data": {"market": "0x18b1c135d0a40c5894da9412e77311827d9caf16cf4cd6591b247a34730af919", "price_changes": [{"asset_id": "78633590736077251574794513664747155551297291244492840448622550955320930591622", "price": "0.482", "size": "201.09", "side": "BUY", "hash": "f8e86e8781e7452c3d21d36d164da847fd099ae7", "best_bid": "0.571", "best_ask": "0.572"}, {"asset_id": "40081275558852222228080198821361202017557872256707631666334039001378518619916", "price": "0.518", "size": "201.09", "side": "SELL", "hash": "c65ae465490dbcc6570646979b886f479ff86b6c", "best_bid": "0.428", "best_ask": "0.429"}], "timestamp": "1785164150903", "event_type": "price_change"}}
{"ts": 1785164150.904, "kind": "price_change", "data": {"market": "0x18b1c135d0a40c5894da9412e77311827d9caf16cf4cd6591b247a34730af919", "price_changes": [{"asset_id": "78633590736077251574794513664747155551297291244492840448622550955320930591622", "price": "0.485", "size": "77", "side": "BUY", "hash": "63e515c7cb6f8cf890da1ea122c1681ec2352f5e", "best_bid": "0.571", "best_ask": "0.572"}, {"asset_id": "40081275558852222228080198821361202017557872256707631666334039001378518619916", "price": "0.515", "size": "77", "side": "SELL", "hash": "07494047b9c40dd69577f149f0ef18401709ad44", "best_bid": "0.428", "best_ask": "0.429"}], "timestamp": "1785164150904", "event_type": "price_change"}}
{"ts": 1785164151.417, "kind": "price_change", "data": {"market": "0x18b1c135d0a40c5894da9412e77311827d9caf16cf4cd6591b247a34730af919", "price_changes": [{"asset_id": "40081275558852222228080198821361202017557872256707631666334039001378518619916", "price": "0.41", "size": "2931.23", "side": "BUY", "hash": "b40dd734ec266512c3fd27ee338f7763af0d5f09", "best_bid": "0.428", "best_ask": "0.429"}, {"asset_id": "78633590736077251574794513664747155551297291244492840448622550955320930591622", "price": "0.59", "size": "2931.23", "side": "SELL", "hash": "18da2c4c189fb3a2b5e0182e103ed9adc0a6399c", "best_bid": "0.571", "best_ask": "0.572"}], "timestamp": "1785164151417", "event_type": "price_change"}}
{"ts": 1785164152.05, "kind": "price_change", "data": {"market": "0x18b1c135d0a40c5894da9412e77311827d9caf16cf4cd6591b247a34730af919", "price_changes": [{"asset_id": "40081275558852222228080198821361202017557872256707631666334039001378518619916", "price": "0.41", "size": "2947.28", "side": "BUY", "hash": "6200577fcca0389ef6abd7a09bdb67d6b502c3d3", "best_bid": "0.428", "best_ask": "0.429"}, {"asset_id": "78633590736077251574794513664747155551297291244492840448622550955320930591622", "price": "0.59", "size": "2947.28", "side": "SELL", "hash": "29c5546be3d89382760a13b92a6cca4b41107d4b", "best_bid": "0.571", "best_ask": "0.572"}], "timestamp": "1785164152050", "event_type": "price_change"}}
{"ts": 1785164154.228, "kind": "price_change", "data": {"market": "0x18b1c135d0a40c5894da9412e77311827d9caf16cf4cd6591b247a34730af919", "price_changes": [{"asset_id": "78633590736077251574794513664747155551297291244492840448622550955320930591622", "price": "0.445", "size": "0", "side": "BUY", "hash": "dcba9c2ab8e996bed65997de76ce533e4861851f", "best_bid": "0.571", "best_ask": "0.572"}, {"asset_id": "40081275558852222228080198821361202017557872256707631666334039001378518619916", "price": "0.555", "size": "0", "side": "SELL", "hash": "a16a55ecc9bc2c6a8340a84a2568a8c562662ba2", "best_bid": "0.428", "best_ask": "0.429"}], "timestamp": "1785164154228", "event_type": "price_change"}}
{"ts": 1785164154.388, "kind": "price_change", "data": {"market": "0x18b1c135d0a40c5894da9412e77311827d9caf16cf4cd6591b247a34730af919", "price_changes": [{"asset_id": "78633590736077251574794513664747155551297291244492840448622550955320930591622", "price": "0.445", "size": "100", "side": "BUY", "hash": "f84d639052b961917eef2c04a2e574e5efb510ac", "best_bid": "0.571", "best_ask": "0.572"}, {"asset_id": "40081275558852222228080198821361202017557872256707631666334039001378518619916", "price": "0.555", "size": "100", "side": "SELL", "hash": "6e13dba792cb7720e7dfc7f1b75bbfddcd47f48e", "best_bid": "0.428", "best_ask": "0.429"}], "timestamp": "1785164154388", "event_type": "price_change"}}
{"ts": 1785164158.91, "kind": "price_change", "data": {"market": "0x18b1c135d0a40c5894da9412e77311827d9caf16cf4cd6591b247a34730af919", "price_changes": [{"asset_id": "78633590736077251574794513664747155551297291244492840448622550955320930591622", "price": "0.481", "size": "0", "side": "BUY", "hash": "14bc0fd08ae678f713f6eec7d63f84f7a20c0d2c", "best_bid": "0.571", "best_ask": "0.572"}, {"asset_id": "40081275558852222228080198821361202017557872256707631666334039001378518619916", "price": "0.519", "size": "0", "side": "SELL", "hash": "c8759c54f708ef03b6c430734b3df857a7983f87", "best_bid": "0.428", "best_ask": "0.429"}], "timestamp": "1785164158910", "event_type": "price_change"}}
{"ts": 1785164159.082, "kind": "price_change", "data": {"market": "0x18b1c135d0a40c5894da9412e77311827d9caf16cf4cd6591b247a34730af919", "price_changes": [{"asset_id": "78633590736077251574794513664747155551297291244492840448622550955320930591622", "price": "0.483", "size": "25", "side": "BUY", "hash": "9b982beaaf064b8f936fdc8cf4b903960f2e103f", "best_bid": "0.571", "best_ask": "0.572"}, {"asset_id": "40081275558852222228080198821361202017557872256707631666334039001378518619916", "price": "0.517", "size": "25", "side": "SELL", "hash": "4da4b023ceaab8f98d8e5a69072263d45abb6fb7", "best_bid": "0.428", "best_ask": "0.429"}], "timestamp": "1785164159082", "event_type": "price_change"}}
{"ts": 1785164159.907, "kind": "price_change", "data": {"market": "0x18b1c135d0a40c5894da9412e77311827d9caf16cf4cd6591b247a34730af919", "price_changes": [{"asset_id": "40081275558852222228080198821361202017557872256707631666334039001378518619916", "price": "0.506", "size": "0", "side": "SELL", "hash": "2d3cfb58797a8902ef1204b88c09125c263c8bfe", "best_bid": "0.428", "best_ask": "0.429"}, {"asset_id": "78633590736077251574794513664747155551297291244492840448622550955320930591622", "price": "0.494", "size": "0", "side": "BUY", "hash": "6cb7d3abc04ce2361736eb782e1eecee45b155ec", "best_bid": "0.571", "best_ask": "0.572"}], "timestamp": "1785164159907", "event_type": "price_change"}}
{"ts": 1785164160.896, "kind": "price_change", "data": {"market": "0x18b1c135d0a40c5894da9412e77311827d9caf16cf4cd6591b247a34730af919", "price_changes": [{"asset_id": "40081275558852222228080198821361202017557872256707631666334039001378518619916", "price": "0.505", "size": "36.7", "side": "SELL", "hash": "8ecd830c3572dd00b02f43b17c284675f48e50f7", "best_bid": "0.428", "best_ask": "0.429"}, {"asset_id": "78633590736077251574794513664747155551297291244492840448622550955320930591622", "price": "0.495", "size": "36.7", "side": "BUY", "hash": "2b40f92aa980f05855fabb91cdf396e78b932e95", "best_bid": "0.571", "best_ask": "0.572"}], "timestamp": "1785164160896", "event_type": "price_change"}}
{"ts": 1785164161.002, "kind": "price_change", "data": {"market": "0x18b1c135d0a40c5894da9412e77311827d9caf16cf4cd6591b247a34730af919", "price_changes": [{"asset_id": "40081275558852222228080198821361202017557872256707631666334039001378518619916", "price": "0.05", "size": "0", "side": "BUY", "hash": "c230da50b8b97f214a988251634d5f608b4b923f", "best_bid": "0.428", "best_ask": "0.429"}, {"asset_id": "78633590736077251574794513664747155551297291244492840448622550955320930591622", "price": "0.95", "size": "0", "side": "SELL", "hash": "a27d7c472c1d16c99b7f9f35301d0e69fa53675f", "best_bid": "0.571", "best_ask": "0.572"}], "timestamp": "1785164161002", "event_type": "price_change"}}
{"ts": 1785164161.416, "kind": "price_change", "data": {"market": "0x18b1c135d0a40c5894da9412e77311827d9caf16cf4cd6591b247a34730af919", "price_changes": [{"asset_id": "40081275558852222228080198821361202017557872256707631666334039001378518619916", "price": "0.505", "size": "0", "side": "SELL", "hash": "53e5845983067c7a150246b313517271e840f8a2", "best_bid": "0.428", "best_ask": "0.429"}, {"asset_id": "78633590736077251574794513664747155551297291244492840448622550955320930591622", "price": "0.495", "size": "0", "side": "BUY", "hash": "84d8ce9986f6bcb8d93998b259c3a99e54850522", "best_bid": "0.571", "best_ask": "0.572"}], "timestamp": "1785164161416", "event_type": "price_change"}}
{"ts": 1785164161.753, "kind": "price_change", "data": {"market": "0x18b1c135d0a40c5894da9412e77311827d9caf16cf4cd6591b247a34730af919", "price_changes": [{"asset_id": "40081275558852222228080198821361202017557872256707631666334039001378518619916", "price": "0.506", "size": "36.7", "side": "SELL", "hash": "dbdb6beeda43ed6a4e53a4357d7848622f05efa4", "best_bid": "0.428", "best_ask": "0.429"}, {"asset_id": "78633590736077251574794513664747155551297291244492840448622550955320930591622", "price": "0.494", "size": "36.7", "side": "BUY", "hash": "53da927aecaa9c170913d259eef6cc1c47f6cf67", "best_bid": "0.571", "best_ask": "0.572"}], "timestamp": "1785164161753", "event_type": "price_change"}}
{"ts": 1785164164.156, "kind": "price_change", "data": {"market": "0x18b1c135d0a40c5894da9412e77311827d9caf16cf4cd6591b247a34730af919", "price_changes": [{"asset_id": "78633590736077251574794513664747155551297291244492840448622550955320930591622", "price": "0.08", "size": "32500", "side": "BUY", "hash": "ff4e2a223d51e63ebf15bf6b79f43869acb0acf0", "best_bid": "0.571", "best_ask": "0.572"}, {"asset_id": "40081275558852222228080198821361202017557872256707631666334039001378518619916", "price": "0.92", "size": "32500", "side": "SELL", "hash": "758226428a162289f40003dd0fa23c0e93426448", "best_bid": "0.428", "best_ask": "0.429"}], "timestamp": "1785164164156", "event_type": "price_change"}}
{"ts": 1785164166.001, "kind": "price_change", "data": {"market": "0x18b1c135d0a40c5894da9412e77311827d9caf16cf4cd6591b247a34730af919", "price_changes": [{"asset_id": "78633590736077251574794513664747155551297291244492840448622550955320930591622", "price": "0.02", "size": "750", "side": "BUY", "hash": "b6da2fdbaeb8fdc1db365bf3bc31ff30348bd691", "best_bid": "0.571", "best_ask": "0.572"}, {"asset_id": "40081275558852222228080198821361202017557872256707631666334039001378518619916", "price": "0.98", "size": "750", "side": "SELL", "hash": "d64ae82e41b3211996ddb071e11341f11540ff6e", "best_bid": "0.428", "best_ask": "0.429"}], "timestamp": "1785164166001", "event_type": "price_change"}}
{"ts": 1785164168.001, "kind": "price_change", "data": {"market": "0x0f49db97f71c68b1e42a6d16e3de93d85dbf7d4148e3f018eb79e88554be9f75", "price_changes": [{"asset_id": "54533043819946592547517511176940999955633860128497669742211153063842200957669", "price": "0.193", "size": "10894", "side": "BUY", "hash": "79b6d3c2f51c1c708d9efa4d48d4059c73c36fa6", "best_bid": "0.194", "best_ask": "0.195"}, {"asset_id": "87854174148074652060467921081181402357467303721471806610111179101805869578687", "price": "0.807", "size": "10894", "side": "SELL", "hash": "1859fc3673933000689743667c3d5eaf6da6da81", "best_bid": "0.805", "best_ask": "0.806"}], "timestamp": "1785164168001", "event_type": "price_change"}}
{"ts": 1785164168.001, "kind": "price_change", "data": {"market": "0x0f49db97f71c68b1e42a6d16e3de93d85dbf7d4148e3f018eb79e88554be9f75", "price_changes": [{"asset_id": "54533043819946592547517511176940999955633860128497669742211153063842200957669", "price": "0.193", "size": "10894", "side": "BUY", "hash": "79b6d3c2f51c1c708d9efa4d48d4059c73c36fa6", "best_bid": "0.194", "best_ask": "0.195"}, {"asset_id": "87854174148074652060467921081181402357467303721471806610111179101805869578687", "price": "0.807", "size": "10894", "side": "SELL", "hash": "1859fc3673933000689743667c3d5eaf6da6da81", "best_bid": "0.805", "best_ask": "0.806"}], "timestamp": "1785164168001", "event_type": "price_change"}}
{"ts": 1785164168.006, "kind": "price_change", "data": {"market": "0x0f49db97f71c68b1e42a6d16e3de93d85dbf7d4148e3f018eb79e88554be9f75", "price_changes": [{"asset_id": "87854174148074652060467921081181402357467303721471806610111179101805869578687", "price": "0.803", "size": "12234.97", "side": "BUY", "hash": "972b65dfabc378c136868706f2d4e26c366987f5", "best_bid": "0.805", "best_ask": "0.806"}, {"asset_id": "54533043819946592547517511176940999955633860128497669742211153063842200957669", "price": "0.197", "size": "12234.97", "side": "SELL", "hash": "b788d000f15d9304685b614b6b2f67575dbf6844", "best_bid": "0.194", "best_ask": "0.195"}], "timestamp": "1785164168006", "event_type": "price_change"}}
{"ts": 1785164168.006, "kind": "price_change", "data": {"market": "0x0f49db97f71c68b1e42a6d16e3de93d85dbf7d4148e3f018eb79e88554be9f75", "price_changes": [{"asset_id": "87854174148074652060467921081181402357467303721471806610111179101805869578687", "price": "0.803", "size": "12234.97", "side": "BUY", "hash": "972b65dfabc378c136868706f2d4e26c366987f5", "best_bid": "0.805", "best_ask": "0.806"}, {"asset_id": "54533043819946592547517511176940999955633860128497669742211153063842200957669", "price": "0.197", "size": "12234.97", "side": "SELL", "hash": "b788d000f15d9304685b614b6b2f67575dbf6844", "best_bid": "0.194", "best_ask": "0.195"}], "timestamp": "1785164168006", "event_type": "price_change"}}
{"ts": 1785164168.037, "kind": "price_change", "data": {"market": "0x0f49db97f71c68b1e42a6d16e3de93d85dbf7d4148e3f018eb79e88554be9f75", "price_changes": [{"asset_id": "54533043819946592547517511176940999955633860128497669742211153063842200957669", "price": "0.193", "size": "10994", "side": "BUY", "hash": "196d4f09adcc4d0ffccf72dac3a43fa2bbebc792", "best_bid": "0.194", "best_ask": "0.195"}, {"asset_id": "87854174148074652060467921081181402357467303721471806610111179101805869578687", "price": "0.807", "size": "10994", "side": "SELL", "hash": "1e14e76249422fa9c4384bae2b87e405744d05fa", "best_bid": "0.805", "best_ask": "0.806"}], "timestamp": "1785164168037", "event_type": "price_change"}}
{"ts": 1785164168.043, "kind": "price_change", "data": {"market": "0x0f49db97f71c68b1e42a6d16e3de93d85dbf7d4148e3f018eb79e88554be9f75", "price_changes": [{"asset_id": "87854174148074652060467921081181402357467303721471806610111179101805869578687", "price": "0.803", "size": "12334.97", "side": "BUY", "hash": "74c3e6a06d40875ef8b0eed90a30f97dfeed8104", "best_bid": "0.805", "best_ask": "0.806"}, {"asset_id": "54533043819946592547517511176940999955633860128497669742211153063842200957669", "price": "0.197", "size": "12334.97", "side": "SELL", "hash": "62b2b2ae0f1b879b0b435c61fdf023f16fc7dc2f", "best_bid": "0.194", "best_ask": "0.195"}], "timestamp": "1785164168043", "event_type": "price_change"}}
{"ts": 1785164168.046, "kind": "price_change", "data": {"market": "0x0f49db97f71c68b1e42a6d16e3de93d85dbf7d4148e3f018eb79e88554be9f75", "price_changes": [{"asset_id": "54533043819946592547517511176940999955633860128497669742211153063842200957669", "price": "0.193", "size": "11094", "side": "BUY", "hash": "7f45a8d4257e71621a71f10de5d0851dc4629587", "best_bid": "0.194", "best_ask": "0.195"}, {"asset_id": "87854174148074652060467921081181402357467303721471806610111179101805869578687", "price": "0.807", "size": "11094", "side": "SELL", "hash": "f5f0b43fc57c4f53752bfed12cb519483b46d68e", "best_bid": "0.805", "best_ask": "0.806"}], "timestamp": "1785164168046", "event_type": "price_change"}}
{"ts": 1785164168.048, "kind": "price_change", "data": {"market": "0x0f49db97f71c68b1e42a6d16e3de93d85dbf7d4148e3f018eb79e88554be9f75", "price_changes": [{"asset_id": "87854174148074652060467921081181402357467303721471806610111179101805869578687", "price": "0.803", "size": "12434.97", "side": "BUY", "hash": "cdef43511eae6cf2e662a10eea28128adb39124b", "best_bid": "0.805", "best_ask": "0.806"}, {"asset_id": "54533043819946592547517511176940999955633860128497669742211153063842200957669", "price": "0.197", "size": "12434.97", "side": "SELL", "hash": "ff74df636f6e18a6c64bf78f052a7d6405eba9a9", "best_bid": "0.194", "best_ask": "0.195"}], "timestamp": "1785164168048", "event_type": "price_change"}}
{"ts": 1785164168.298933, "kind": "orders_out", "data": [{"token_id": "54533043819946592547517511176940999955633860128497669742211153063842200957669", "side": "BUY", "price": 0.153, "size": 19.61}]}
{"ts": 1785164169.558, "kind": "price_change", "data": {"market": "0x0f49db97f71c68b1e42a6d16e3de93d85dbf7d4148e3f018eb79e88554be9f75", "price_changes": [{"asset_id": "54533043819946592547517511176940999955633860128497669742211153063842200957669", "price": "0.009", "size": "13888.88", "side": "BUY", "hash": "4eda01ab92ad19f517d4ec39260476dab51516d4", "best_bid": "0.194", "best_ask": "0.195"}, {"asset_id": "87854174148074652060467921081181402357467303721471806610111179101805869578687", "price": "0.991", "size": "13888.88", "side": "SELL", "hash": "8e5b39e957ddb289404390ded27b0b5dda06ef09", "best_bid": "0.805", "best_ask": "0.806"}], "timestamp": "1785164169558", "event_type": "price_change"}}
{"ts": 1785164169.671, "kind": "price_change", "data": {"market": "0x0f49db97f71c68b1e42a6d16e3de93d85dbf7d4148e3f018eb79e88554be9f75", "price_changes": [{"asset_id": "54533043819946592547517511176940999955633860128497669742211153063842200957669", "price": "0.007", "size": "53571.42", "side": "BUY", "hash": "e98d335d32e76c71ee089f005a4fafa42ff2d28c", "best_bid": "0.194", "best_ask": "0.195"}, {"asset_id": "87854174148074652060467921081181402357467303721471806610111179101805869578687", "price": "0.993", "size": "53571.42", "side": "SELL", "hash": "b17373b07f1b566dde0023301d6b2099f03eedce", "best_bid": "0.805", "best_ask": "0.806"}], "timestamp": "1785164169671", "event_type": "price_change"}}
{"ts": 1785164169.858, "kind": "price_change", "data": {"market": "0x18b1c135d0a40c5894da9412e77311827d9caf16cf4cd6591b247a34730af919", "price_changes": [{"asset_id": "40081275558852222228080198821361202017557872256707631666334039001378518619916", "price": "0.171", "size": "1947.36", "side": "BUY", "hash": "dada6c329399497629608991da644ca71a9ec547", "best_bid": "0.428", "best_ask": "0.429"}, {"asset_id": "78633590736077251574794513664747155551297291244492840448622550955320930591622", "price": "0.829", "size": "1947.36", "side": "SELL", "hash": "3bbd7086fbbee0e1c269bd32595914596e17d26b", "best_bid": "0.571", "best_ask": "0.572"}], "timestamp": "1785164169858", "event_type": "price_change"}}
{"ts": 1785164169.864, "kind": "price_change", "data": {"market": "0x18b1c135d0a40c5894da9412e77311827d9caf16cf4cd6591b247a34730af919", "price_changes": [{"asset_id": "40081275558852222228080198821361202017557872256707631666334039001378518619916", "price": "0.171", "size": "2970.75", "side": "BUY", "hash": "1cb8cefec9ffa9f474030db2a5c6cec7d77bdf28", "best_bid": "0.428", "best_ask": "0.429"}, {"asset_id": "78633590736077251574794513664747155551297291244492840448622550955320930591622", "price": "0.829", "size": "2970.75", "side": "SELL", "hash": "1d3a029f6e1091b0ccc30e7f458b81fcce79836a", "best_bid": "0.571", "best_ask": "0.572"}], "timestamp": "1785164169864", "event_type": "price_change"}}
{"ts": 1785164170.679, "kind": "price_change", "data": {"market": "0x18b1c135d0a40c5894da9412e77311827d9caf16cf4cd6591b247a34730af919", "price_changes": [{"asset_id": "40081275558852222228080198821361202017557872256707631666334039001378518619916", "price": "0.41", "size": "2931.23", "side": "BUY", "hash": "20979c71bbd9a751381157afdcfbbb90ac55b225", "best_bid": "0.428", "best_ask": "0.429"}, {"asset_id": "78633590736077251574794513664747155551297291244492840448622550955320930591622", "price": "0.59", "size": "2931.23", "side": "SELL", "hash": "249d566f569acb93d0fd99032d0ecf9ae597a107", "best_bid": "0.571", "best_ask": "0.572"}], "timestamp": "1785164170679", "event_type": "price_change"}}
{"ts": 1785164170.702, "kind": "price_change", "data": {"market": "0x0f49db97f71c68b1e42a6d16e3de93d85dbf7d4148e3f018eb79e88554be9f75", "price_changes": [{"asset_id": "54533043819946592547517511176940999955633860128497669742211153063842200957669", "price": "0.04", "size": "300", "side": "BUY", "hash": "7809797c2308d9aa33db2485e5024ddcf7ff88fa", "best_bid": "0.194", "best_ask": "0.195"}, {"asset_id": "87854174148074652060467921081181402357467303721471806610111179101805869578687", "price": "0.96", "size": "300", "side": "SELL", "hash": "92268c8d59fa851fbc8fd52dff1a66330fdb8912", "best_bid": "0.805", "best_ask": "0.806"}], "timestamp": "1785164170702", "event_type": "price_change"}}
{"ts": 1785164170.708, "kind": "price_change", "data": {"market": "0x0f49db97f71c68b1e42a6d16e3de93d85dbf7d4148e3f018eb79e88554be9f75", "price_changes": [{"asset_id": "54533043819946592547517511176940999955633860128497669742211153063842200957669", "price": "0.02", "size": "8000", "side": "BUY", "hash": "aff6f1e34b9d75b5bd1407c3f8ef4f12f926b544", "best_bid": "0.194", "best_ask": "0.195"}, {"asset_id": "87854174148074652060467921081181402357467303721471806610111179101805869578687", "price": "0.98", "size": "8000", "side": "SELL", "hash": "8d55f609d2322d2d06bae35512f08f06f7a15092", "best_bid": "0.805", "best_ask": "0.806"}], "timestamp": "1785164170708", "event_type": "price_change"}}
{"ts": 1785164171.155, "kind": "price_change", "data": {"market": "0x18b1c135d0a40c5894da9412e77311827d9caf16cf4cd6591b247a34730af919", "price_changes": [{"asset_id": "40081275558852222228080198821361202017557872256707631666334039001378518619916", "price": "0.41", "size": "2947.28", "side": "BUY", "hash": "3b6a354d8fbac3d1f94cb134a8d8deb65a213cec", "best_bid": "0.428", "best_ask": "0.429"}, {"asset_id": "78633590736077251574794513664747155551297291244492840448622550955320930591622", "price": "0.59", "size": "2947.28", "side": "SELL", "hash": "ba34282e1b326a86f1a129c4398a0c0713347604", "best_bid": "0.571", "best_ask": "0.572"}], "timestamp": "1785164171155", "event_type": "price_change"}}
{"ts": 1785164173.002, "kind": "price_change", "data": {"market": "0x18b1c135d0a40c5894da9412e77311827d9caf16cf4cd6591b247a34730af919", "price_changes": [{"asset_id": "78633590736077251574794513664747155551297291244492840448622550955320930591622", "price": "0.551", "size": "28508.16", "side": "BUY", "hash": "359f33466bc86d393b72e242a45ff584df1b77e1", "best_bid": "0.571", "best_ask": "0.572"}, {"asset_id": "40081275558852222228080198821361202017557872256707631666334039001378518619916", "price": "0.449", "size": "28508.16", "side": "SELL", "hash": "1dd75bee783f519721007526f625dc7bd7993054", "best_bid": "0.428", "best_ask": "0.429"}], "timestamp": "1785164173002", "event_type": "price_change"}}
{"ts": 1785164173.002, "kind": "price_change", "data": {"market": "0x18b1c135d0a40c5894da9412e77311827d9caf16cf4cd6591b247a34730af919", "price_changes": [{"asset_id": "78633590736077251574794513664747155551297291244492840448622550955320930591622", "price": "0.55", "size": "30381.18", "side": "BUY", "hash": "359f33466bc86d393b72e242a45ff584df1b77e1", "best_bid": "0.571", "best_ask": "0.572"}, {"asset_id": "40081275558852222228080198821361202017557872256707631666334039001378518619916", "price": "0.45", "size": "30381.18", "side": "SELL", "hash": "1dd75bee783f519721007526f625dc7bd7993054", "best_bid": "0.428", "best_ask": "0.429"}], "timestamp": "1785164173002", "event_type": "price_change"}}
{"ts": 1785164173.036, "kind": "price_change", "data": {"market": "0x18b1c135d0a40c5894da9412e77311827d9caf16cf4cd6591b247a34730af919", "price_changes": [{"asset_id": "78633590736077251574794513664747155551297291244492840448622550955320930591622", "price": "0.551", "size": "28708.16", "side": "BUY", "hash": "9eb42261f89a18ee8af3c16b51c3aba9aa12a4b4", "best_bid": "0.571", "best_ask": "0.572"}, {"asset_id": "40081275558852222228080198821361202017557872256707631666334039001378518619916", "price": "0.449", "size": "28708.16", "side": "SELL", "hash": "c9dcce44e27df77f51d32e7b026d9d2f70b7d580", "best_bid": "0.428", "best_ask": "0.429"}], "timestamp": "1785164173036", "event_type": "price_change"}}
{"ts": 1785164173.047, "kind": "price_change", "data": {"market": "0x18b1c135d0a40c5894da9412e77311827d9caf16cf4cd6591b247a34730af919", "price_changes": [{"asset_id": "78633590736077251574794513664747155551297291244492840448622550955320930591622", "price": "0.55", "size": "30581.18", "side": "BUY", "hash": "3901fe9a89febcb73dc0ff747ab6ad2df11433b4", "best_bid": "0.571", "best_ask": "0.572"}, {"asset_id": "40081275558852222228080198821361202017557872256707631666334039001378518619916", "price": "0.45", "size": "30581.18", "side": "SELL", "hash": "25a70dab48a4f93f853eb2772d75a7ddbeac70a9", "best_bid": "0.428", "best_ask": "0.429"}], "timestamp": "1785164173047", "event_type": "price_change"}}
{"ts": 1785164176.925, "kind": "price_change", "data": {"market": "0x18b1c135d0a40c5894da9412e77311827d9caf16cf4cd6591b247a34730af919", "price_changes": [{"asset_id": "40081275558852222228080198821361202017557872256707631666334039001378518619916", "price": "0.506", "size": "0", "side": "SELL", "hash": "8ab1d615804fb91158b4c84a8ccdc8db5eed9edb", "best_bid": "0.428", "best_ask": "0.429"}, {"asset_id": "78633590736077251574794513664747155551297291244492840448622550955320930591622", "price": "0.494", "size": "0", "side": "BUY", "hash": "77e4ae4ff4a1235cb59c36db68069f9d26ca566b", "best_bid": "0.571", "best_ask": "0.572"}], "timestamp": "1785164176925", "event_type": "price_change"}}
{"ts": 1785164177.85, "kind": "price_change", "data": {"market": "0x18b1c135d0a40c5894da9412e77311827d9caf16cf4cd6591b247a34730af919", "price_changes": [{"asset_id": "40081275558852222228080198821361202017557872256707631666334039001378518619916", "price": "0.505", "size": "36.7", "side": "SELL", "hash": "f9efa4f47e02a699c4241ef92018d8d40529d336", "best_bid": "0.428", "best_ask": "0.429"}, {"asset_id": "78633590736077251574794513664747155551297291244492840448622550955320930591622", "price": "0.495", "size": "36.7", "side": "BUY", "hash": "eaf451ddfb820072f2ffe952edaeec95f9472bd4", "best_bid": "0.571", "best_ask": "0.572"}], "timestamp": "1785164177850", "event_type": "price_change"}}
{"ts": 1785164179.605, "kind": "price_change", "data": {"market": "0x18b1c135d0a40c5894da9412e77311827d9caf16cf4cd6591b247a34730af919", "price_changes": [{"asset_id": "78633590736077251574794513664747155551297291244492840448622550955320930591622", "price": "0.02", "size": "75750", "side": "BUY", "hash": "eb3fd9c05685f8e3675fa74ff352a511c805c205", "best_bid": "0.571", "best_ask": "0.572"}, {"asset_id": "40081275558852222228080198821361202017557872256707631666334039001378518619916", "price": "0.98", "size": "75750", "side": "SELL", "hash": "aae43c907fe4c63433d23be9f0f73b0b09bf0880", "best_bid": "0.428", "best_ask": "0.429"}], "timestamp": "1785164179605", "event_type": "price_change"}}
{"ts": 1785164180.385, "kind": "price_change", "data": {"market": "0x0f49db97f71c68b1e42a6d16e3de93d85dbf7d4148e3f018eb79e88554be9f75", "price_changes": [{"asset_id": "87854174148074652060467921081181402357467303721471806610111179101805869578687", "price": "0.795", "size": "2648.98", "side": "BUY", "hash": "40c2dc4c763ea70656acc7d0bcee97a379e8afdc", "best_bid": "0.805", "best_ask": "0.806"}, {"asset_id": "54533043819946592547517511176940999955633860128497669742211153063842200957669", "price": "0.205", "size": "2648.98", "side": "SELL", "hash": "82de2147b60ac4d5ab7e8c6a61a3f5302803a439", "best_bid": "0.194", "best_ask": "0.195"}], "timestamp": "1785164180385", "event_type": "price_change"}}
{"ts": 1785164180.451, "kind": "price_change", "data": {"market": "0x0f49db97f71c68b1e42a6d16e3de93d85dbf7d4148e3f018eb79e88554be9f75", "price_changes": [{"asset_id": "87854174148074652060467921081181402357467303721471806610111179101805869578687", "price": "0.795", "size": "3215.98", "side": "BUY", "hash": "d2c59c9f884a10c2fca37b922374cb8616a54d5c", "best_bid": "0.805", "best_ask": "0.806"}, {"asset_id": "54533043819946592547517511176940999955633860128497669742211153063842200957669", "price": "0.205", "size": "3215.98", "side": "SELL", "hash": "14d391649f43aa10eeac9913cb2d5398dea9f3b3", "best_bid": "0.194", "best_ask": "0.195"}], "timestamp": "1785164180451", "event_type": "price_change"}}
{"ts": 1785164180.917, "kind": "price_change", "data": {"market": "0x18b1c135d0a40c5894da9412e77311827d9caf16cf4cd6591b247a34730af919", "price_changes": [{"asset_id": "40081275558852222228080198821361202017557872256707631666334039001378518619916", "price": "0.418", "size": "6427.55", "side": "BUY", "hash": "569e0189b4d1ce082482ff5e256dc16e245324f2", "best_bid": "0.428", "best_ask": "0.429"}, {"asset_id": "78633590736077251574794513664747155551297291244492840448622550955320930591622", "price": "0.582", "size": "6427.55", "side": "SELL", "hash": "df4f1e542bda6d961a265c09f1baaec000641be8", "best_bid": "0.571", "best_ask": "0.572"}], "timestamp": "1785164180917", "event_type": "price_change"}}
{"ts": 1785164180.952, "kind": "price_change", "data": {"market": "0x18b1c135d0a40c5894da9412e77311827d9caf16cf4cd6591b247a34730af919", "price_changes": [{"asset_id": "40081275558852222228080198821361202017557872256707631666334039001378518619916", "price": "0.414", "size": "300", "side": "BUY", "hash": "059bc406ef2ad0063689f0534a757fd4f50a7373", "best_bid": "0.428", "best_ask": "0.429"}, {"asset_id": "78633590736077251574794513664747155551297291244492840448622550955320930591622", "price": "0.586", "size": "300", "side": "SELL", "hash": "c6e5ef1ededea0276232f28d6a934c17d87f6a22", "best_bid": "0.571", "best_ask": "0.572"}], "timestamp": "1785164180952", "event_type": "price_change"}}
{"ts": 1785164180.983, "kind": "price_change", "data": {"market": "0x18b1c135d0a40c5894da9412e77311827d9caf16cf4cd6591b247a34730af919", "price_changes": [{"asset_id": "40081275558852222228080198821361202017557872256707631666334039001378518619916", "price": "0.412", "size": "11323.8", "side": "BUY", "hash": "9e686a32227260546936a46797abcd6757ec784c", "best_bid": "0.428", "best_ask": "0.429"}, {"asset_id": "78633590736077251574794513664747155551297291244492840448622550955320930591622", "price": "0.588", "size": "11323.8", "side": "SELL", "hash": "21f803dfedbaad74e660d14fce395cbbb74d5ad0", "best_bid": "0.571", "best_ask": "0.572"}], "timestamp": "1785164180983", "event_type": "price_change"}}
{"ts": 1785164180.988, "kind": "price_change", "data": {"market": "0x18b1c135d0a40c5894da9412e77311827d9caf16cf4cd6591b247a34730af919", "price_changes": [{"asset_id": "40081275558852222228080198821361202017557872256707631666334039001378518619916", "price": "0.418", "size": "7505.55", "side": "BUY", "hash": "053e60f352df141641a31b8197e643caed70e78d", "best_bid": "0.428", "best_ask": "0.429"}, {"asset_id": "78633590736077251574794513664747155551297291244492840448622550955320930591622", "price": "0.582", "size": "7505.55", "side": "SELL", "hash": "a9e273b3b874823b7bec3ed5b1be20f720226687", "best_bid": "0.571", "best_ask": "0.572"}], "timestamp": "1785164180988", "event_type": "price_change"}}
{"ts": 1785164181.027, "kind": "price_change", "data": {"market": "0x18b1c135d0a40c5894da9412e77311827d9caf16cf4cd6591b247a34730af919", "price_changes": [{"asset_id": "40081275558852222228080198821361202017557872256707631666334039001378518619916", "price": "0.412", "size": "11123.8", "side": "BUY", "hash": "861e884bb297daa287579330bcc72973816722ef", "best_bid": "0.428", "best_ask": "0.429"}, {"asset_id": "78633590736077251574794513664747155551297291244492840448622550955320930591622", "price": "0.588", "size": "11123.8", "side": "SELL", "hash": "3602203b436f643c37a391f5ce169c0421aef862", "best_bid": "0.571", "best_ask": "0.572"}], "timestamp": "1785164181027", "event_type": "price_change"}}
{"ts": 1785164181.063, "kind": "price_change", "data": {"market": "0x18b1c135d0a40c5894da9412e77311827d9caf16cf4cd6591b247a34730af919", "price_changes": [{"asset_id": "40081275558852222228080198821361202017557872256707631666334039001378518619916", "price": "0.414", "size": "500", "side": "BUY", "hash": "91f1dcdd8e1c38ee0e8cb70a6301068637dbb220", "best_bid": "0.428", "best_ask": "0.429"}, {"asset_id": "78633590736077251574794513664747155551297291244492840448622550955320930591622", "price": "0.586", "size": "500", "side": "SELL", "hash": "854b7d3fd8fdd2412b604e3bb939bbefe7a03699", "best_bid": "0.571", "best_ask": "0.572"}], "timestamp": "1785164181063", "event_type": "price_change"}}
{"ts": 1785164181.493, "kind": "price_change", "data": {"market": "0x0f49db97f71c68b1e42a6d16e3de93d85dbf7d4148e3f018eb79e88554be9f75", "price_changes": [{"asset_id": "54533043819946592547517511176940999955633860128497669742211153063842200957669", "price": "0.007", "size": "0", "side": "BUY", "hash": "b4ffce239a2b2c614110bc3c1c751a47689b794e", "best_bid": "0.194", "best_ask": "0.195"}, {"asset_id": "87854174148074652060467921081181402357467303721471806610111179101805869578687", "price": "0.993", "size": "0", "side": "SELL", "hash": "152ba2521eadab3b1154b8e44efdceb054d6b738", "best_bid": "0.805", "best_ask": "0.806"}], "timestamp": "1785164181493", "event_type": "price_change"}}
{"ts": 1785164181.493, "kind": "price_change", "data": {"market": "0x0f49db97f71c68b1e42a6d16e3de93d85dbf7d4148e3f018eb79e88554be9f75", "price_changes": [{"asset_id": "54533043819946592547517511176940999955633860128497669742211153063842200957669", "price": "0.009", "size": "0", "side": "BUY", "hash": "b4ffce239a2b2c614110bc3c1c751a47689b794e", "best_bid": "0.194", "best_ask": "0.195"}, {"asset_id": "87854174148074652060467921081181402357467303721471806610111179101805869578687", "price": "0.991", "size": "0", "side": "SELL", "hash": "152ba2521eadab3b1154b8e44efdceb054d6b738", "best_bid": "0.805", "best_ask": "0.806"}], "timestamp": "1785164181493", "event_type": "price_change"}}
{"ts": 1785164184.988, "kind": "price_change", "data": {"market": "0x0f49db97f71c68b1e42a6d16e3de93d85dbf7d4148e3f018eb79e88554be9f75", "price_changes": [{"asset_id": "54533043819946592547517511176940999955633860128497669742211153063842200957669", "price": "0.02", "size": "500", "side": "BUY", "hash": "84872f116207d748a2b84650e3d62e3b4b45922b", "best_bid": "0.194", "best_ask": "0.195"}, {"asset_id": "87854174148074652060467921081181402357467303721471806610111179101805869578687", "price": "0.98", "size": "500", "side": "SELL", "hash": "5cbf371735c522f2fdd44d383d5af5330ea6a88b", "best_bid": "0.805", "best_ask": "0.806"}], "timestamp": "1785164184988", "event_type": "price_change"}}
{"ts": 1785164184.996, "kind": "price_change", "data": {"market": "0x0f49db97f71c68b1e42a6d16e3de93d85dbf7d4148e3f018eb79e88554be9f75", "price_changes": [{"asset_id": "54533043819946592547517511176940999955633860128497669742211153063842200957669", "price": "0.04", "size": "4050", "side": "BUY", "hash": "fcae76c5af836deff7ec65e53e24f6faeb3119ad", "best_bid": "0.194", "best_ask": "0.195"}, {"asset_id": "87854174148074652060467921081181402357467303721471806610111179101805869578687", "price": "0.96", "size": "4050", "side": "SELL", "hash": "2435257fc652e3e5d20d0294515ad9f93136dd18", "best_bid": "0.805", "best_ask": "0.806"}], "timestamp": "1785164184996", "event_type": "price_change"}}
{"ts": 1785164188.948, "kind": "price_change", "data": {"market": "0x18b1c135d0a40c5894da9412e77311827d9caf16cf4cd6591b247a34730af919", "price_changes": [{"asset_id": "40081275558852222228080198821361202017557872256707631666334039001378518619916", "price": "0.41", "size": "2931.23", "side": "BUY", "hash": "dd2fc561595ad4d98a85e81c7c8fbfc5f359d39c", "best_bid": "0.428", "best_ask": "0.429"}, {"asset_id": "78633590736077251574794513664747155551297291244492840448622550955320930591622", "price": "0.59", "size": "2931.23", "side": "SELL", "hash": "650678ce315227ffb9bad864d965b6e41af0c035", "best_bid": "0.571", "best_ask": "0.572"}], "timestamp": "1785164188948", "event_type": "price_change"}}
{"ts": 1785164189.242, "kind": "price_change", "data": {"market": "0x18b1c135d0a40c5894da9412e77311827d9caf16cf4cd6591b247a34730af919", "price_changes": [{"asset_id": "40081275558852222228080198821361202017557872256707631666334039001378518619916", "price": "0.505", "size": "0", "side": "SELL", "hash": "23eb0f816bc46c36ebe9aa00e49d1c160be6cfe3", "best_bid": "0.428", "best_ask": "0.429"}, {"asset_id": "78633590736077251574794513664747155551297291244492840448622550955320930591622", "price": "0.495", "size": "0", "side": "BUY", "hash": "c7cffbc96b56cd006594160eab0947344c60f37c", "best_bid": "0.571", "best_ask": "0.572"}], "timestamp": "1785164189242", "event_type": "price_change"}}
{"ts": 1785164189.313, "kind": "price_change", "data": {"market": "0x0f49db97f71c68b1e42a6d16e3de93d85dbf7d4148e3f018eb79e88554be9f75", "price_changes": [{"asset_id": "87854174148074652060467921081181402357467303721471806610111179101805869578687", "price": "0.795", "size": "2649.98", "side": "BUY", "hash": "aa76c804ade77c76c5b73d29dbd6fdec4e2cded6", "best_bid": "0.805", "best_ask": "0.806"}, {"asset_id": "54533043819946592547517511176940999955633860128497669742211153063842200957669", "price": "0.205", "size": "2649.98", "side": "SELL", "hash": "150cfa50472b2534977d772138f60c951209e199", "best_bid": "0.194", "best_ask": "0.195"}], "timestamp": "1785164189313", "event_type": "price_change"}}
{"ts": 1785164189.39, "kind": "price_change", "data": {"market": "0x0f49db97f71c68b1e42a6d16e3de93d85dbf7d4148e3f018eb79e88554be9f75", "price_changes": [{"asset_id": "87854174148074652060467921081181402357467303721471806610111179101805869578687", "price": "0.795", "size": "3215.98", "side": "BUY", "hash": "cb7654c630c57100fdfc24656858f79468025765", "best_bid": "0.805", "best_ask": "0.806"}, {"asset_id": "54533043819946592547517511176940999955633860128497669742211153063842200957669", "price": "0.205", "size": "3215.98", "side": "SELL", "hash": "b69fc04f08218f1a54be2589eb8b5126c55bcafe", "best_bid": "0.194", "best_ask": "0.195"}], "timestamp": "1785164189390", "event_type": "price_change"}}
{"ts": 1785164189.638, "kind": "price_change", "data": {"market": "0x18b1c135d0a40c5894da9412e77311827d9caf16cf4cd6591b247a34730af919", "price_changes": [{"asset_id": "40081275558852222228080198821361202017557872256707631666334039001378518619916", "price": "0.41", "size": "2947.28", "side": "BUY", "hash": "881a1fd5d62f5a9279c22399fc038418acd89bdf", "best_bid": "0.428", "best_ask": "0.429"}, {"asset_id": "78633590736077251574794513664747155551297291244492840448622550955320930591622", "price": "0.59", "size": "2947.28", "side": "SELL", "hash": "3ca8bc172d723837c6870c7ba8004ced4c379bf0", "best_bid": "0.571", "best_ask": "0.572"}], "timestamp": "1785164189638", "event_type": "price_change"}}
{"ts": 1785164189.912, "kind": "price_change", "data": {"market": "0x18b1c135d0a40c5894da9412e77311827d9caf16cf4cd6591b247a34730af919", "price_changes": [{"asset_id": "40081275558852222228080198821361202017557872256707631666334039001378518619916", "price": "0.418", "size": "6429.55", "side": "BUY", "hash": "7edf66c436c5fa9d9b20f4c07d4945f7a3bfc7a7", "best_bid": "0.428", "best_ask": "0.429"}, {"asset_id": "78633590736077251574794513664747155551297291244492840448622550955320930591622", "price": "0.582", "size": "6429.55", "side": "SELL", "hash": "ccfc12aaa33441b24865e0f96cef6fb61e43e57a", "best_bid": "0.571", "best_ask": "0.572"}], "timestamp": "1785164189912", "event_type": "price_change"}}
{"ts": 1785164189.947, "kind": "price_change", "data": {"market": "0x18b1c135d0a40c5894da9412e77311827d9caf16cf4cd6591b247a34730af919", "price_changes": [{"asset_id": "40081275558852222228080198821361202017557872256707631666334039001378518619916", "price": "0.414", "size": "300", "side": "BUY", "hash": "2c13a8d6ce8ddd7824ad8fef832376d9c0c37318", "best_bid": "0.428", "best_ask": "0.429"}, {"asset_id": "78633590736077251574794513664747155551297291244492840448622550955320930591622", "price": "0.586", "size": "300", "side": "SELL", "hash": "3236a595f790c42ff543afb4d279a667e3e6bd25", "best_bid": "0.571", "best_ask": "0.572"}], "timestamp": "1785164189947", "event_type": "price_change"}}
{"ts": 1785164189.977, "kind": "price_change", "data": {"market": "0x18b1c135d0a40c5894da9412e77311827d9caf16cf4cd6591b247a34730af919", "price_changes": [{"asset_id": "40081275558852222228080198821361202017557872256707631666334039001378518619916", "price": "0.412", "size": "11323.8", "side": "BUY", "hash": "c13ad713c748e416da08dd782066a5013eb2f3ca", "best_bid": "0.428", "best_ask": "0.429"}, {"asset_id": "78633590736077251574794513664747155551297291244492840448622550955320930591622", "price": "0.588", "size": "11323.8", "side": "SELL", "hash": "456f9196696d2e63107bcf944b17c126880bbf08", "best_bid": "0.571", "best_ask": "0.572"}], "timestamp": "1785164189977", "event_type": "price_change"}}
{"ts": 1785164190.007, "kind": "price_change", "data": {"market": "0x18b1c135d0a40c5894da9412e77311827d9caf16cf4cd6591b247a34730af919", "price_changes": [{"asset_id": "40081275558852222228080198821361202017557872256707631666334039001378518619916", "price": "0.418", "size": "7505.55", "side": "BUY", "hash": "e40cc7db0453bf7574ae0481e1ccddb8dffd285c", "best_bid": "0.428", "best_ask": "0.429"}, {"asset_id": "78633590736077251574794513664747155551297291244492840448622550955320930591622", "price": "0.582", "size": "7505.55", "side": "SELL", "hash": "5499d1a4a5eee7e7412d6b96deca5088936fe8d7", "best_bid": "0.571", "best_ask": "0.572"}], "timestamp": "1785164190007", "event_type": "price_change"}}
{"ts": 1785164190.043, "kind": "price_change", "data": {"market": "0x18b1c135d0a40c5894da9412e77311827d9caf16cf4cd6591b247a34730af919", "price_changes": [{"asset_id": "40081275558852222228080198821361202017557872256707631666334039001378518619916", "price": "0.412", "size": "11123.8", "side": "BUY", "hash": "bea9c8da3970270ecc01476c0f9b8b785f9cdae0", "best_bid": "0.428", "best_ask": "0.429"}, {"asset_id": "78633590736077251574794513664747155551297291244492840448622550955320930591622", "price": "0.588", "size": "11123.8", "side": "SELL", "hash": "9e4f688808ab41beae495889c5be747a150e8803", "best_bid": "0.571", "best_ask": "0.572"}], "timestamp": "1785164190043", "event_type": "price_change"}}
{"ts": 1785164190.074, "kind": "price_change", "data": {"market": "0x18b1c135d0a40c5894da9412e77311827d9caf16cf4cd6591b247a34730af919", "price_changes": [{"asset_id": "40081275558852222228080198821361202017557872256707631666334039001378518619916", "price": "0.414", "size": "500", "side": "BUY", "hash": "5df4c109ca68dfae3e1464cc5e56803fb9a4e540", "best_bid": "0.428", "best_ask": "0.429"}, {"asset_id": "78633590736077251574794513664747155551297291244492840448622550955320930591622", "price": "0.586", "size": "500", "side": "SELL", "hash": "4cfbb25f77425aed196bc5db270c3220333ba78f", "best_bid": "0.571", "best_ask": "0.572"}], "timestamp": "1785164190074", "event_type": "price_change"}}
{"ts": 1785164197.379, "kind": "price_change", "data": {"market": "0x0f49db97f71c68b1e42a6d16e3de93d85dbf7d4148e3f018eb79e88554be9f75", "price_changes": [{"asset_id": "87854174148074652060467921081181402357467303721471806610111179101805869578687", "price": "0.001", "size": "6146756.01", "side": "BUY", "hash": "b3a0c5a70c0e11a6a13c55ec4c870b73b7f4edba", "best_bid": "0.805", "best_ask": "0.806"}, {"asset_id": "54533043819946592547517511176940999955633860128497669742211153063842200957669", "price": "0.999", "size": "6146756.01", "side": "SELL", "hash": "0e854f2cd01af385ddbaf91bf8dc3ddc2fad692a", "best_bid": "0.194", "best_ask": "0.195"}], "timestamp": "1785164197379", "event_type": "price_change"}}
{"ts": 1785164197.38, "kind": "price_change", "data": {"market": "0x0f49db97f71c68b1e42a6d16e3de93d85dbf7d4148e3f018eb79e88554be9f75", "price_changes": [{"asset_id": "87854174148074652060467921081181402357467303721471806610111179101805869578687", "price": "0.001", "size": "6147766.01", "side": "BUY", "hash": "24bebd3f69895cef5ae93c8c9b32ea2fb6d2c36f", "best_bid": "0.805", "best_ask": "0.806"}, {"asset_id": "54533043819946592547517511176940999955633860128497669742211153063842200957669", "price": "0.999", "size": "6147766.01", "side": "SELL", "hash": "71b5c08511f3687ac2f7f04d449fd379c73e64c4", "best_bid": "0.194", "best_ask": "0.195"}], "timestamp": "1785164197380", "event_type": "price_change"}}
{"ts": 1785164197.679415, "kind": "orders_out", "data": [{"token_id": "54533043819946592547517511176940999955633860128497669742211153063842200957669", "side": "BUY", "price": 0.153, "size": 19.61}]}
{"ts": 1785164198.848, "kind": "price_change", "data": {"market": "0x18b1c135d0a40c5894da9412e77311827d9caf16cf4cd6591b247a34730af919", "price_changes": [{"asset_id": "78633590736077251574794513664747155551297291244492840448622550955320930591622", "price": "0.371", "size": "0", "side": "BUY", "hash": "7fb5d01378ad5f6c0949de83db52eb5d56aed0d1", "best_bid": "0.571", "best_ask": "0.572"}, {"asset_id": "40081275558852222228080198821361202017557872256707631666334039001378518619916", "price": "0.629", "size": "0", "side": "SELL", "hash": "fb33c0b5c2b3155007f2ddb203edc4b7321a2d3f", "best_bid": "0.428", "best_ask": "0.429"}], "timestamp": "1785164198848", "event_type": "price_change"}}
{"ts": 1785164198.87, "kind": "price_change", "data": {"market": "0x18b1c135d0a40c5894da9412e77311827d9caf16cf4cd6591b247a34730af919", "price_changes": [{"asset_id": "78633590736077251574794513664747155551297291244492840448622550955320930591622", "price": "0.375", "size": "400", "side": "BUY", "hash": "9a5505bed8b6dcc0de28695e277c48b2254195d9", "best_bid": "0.571", "best_ask": "0.572"}, {"asset_id": "40081275558852222228080198821361202017557872256707631666334039001378518619916", "price": "0.625", "size": "400", "side": "SELL", "hash": "fbdbc48d84b9de662f1b9f62971fdcf5b56e76fc", "best_bid": "0.428", "best_ask": "0.429"}], "timestamp": "1785164198870", "event_type": "price_change"}}
{"ts": 1785164202.0, "kind": "price_change", "data": {"market": "0x18b1c135d0a40c5894da9412e77311827d9caf16cf4cd6591b247a34730af919", "price_changes": [{"asset_id": "78633590736077251574794513664747155551297291244492840448622550955320930591622", "price": "0.08", "size": "30625", "side": "BUY", "hash": "f8fa2332180ad82094160fd73d9cf57ea44a356c", "best_bid": "0.571", "best_ask": "0.572"}, {"asset_id": "40081275558852222228080198821361202017557872256707631666334039001378518619916", "price": "0.92", "size": "30625", "side": "SELL", "hash": "128df3ac414233d8629b90c0d8e31dda7fce4ba6", "best_bid": "0.428", "best_ask": "0.429"}], "timestamp": "1785164202000", "event_type": "price_change"}}
{"ts": 1785164208.424, "kind": "price_change", "data": {"market": "0x18b1c135d0a40c5894da9412e77311827d9caf16cf4cd6591b247a34730af919", "price_changes": [{"asset_id": "40081275558852222228080198821361202017557872256707631666334039001378518619916", "price": "0.41", "size": "2931.23", "side": "BUY", "hash": "f7214f3a75d360c12685bf5f2fdc11eb38191f9c", "best_bid": "0.428", "best_ask": "0.429"}, {"asset_id": "78633590736077251574794513664747155551297291244492840448622550955320930591622", "price": "0.59", "size": "2931.23", "side": "SELL", "hash": "d3ba8d88c088e82ab02a20e0411ead868d711c85", "best_bid": "0.571", "best_ask": "0.572"}], "timestamp": "1785164208424", "event_type": "price_change"}}
{"ts": 1785164208.775, "kind": "price_change", "data": {"market": "0x18b1c135d0a40c5894da9412e77311827d9caf16cf4cd6591b247a34730af919", "price_changes": [{"asset_id": "40081275558852222228080198821361202017557872256707631666334039001378518619916", "price": "0.506", "size": "36.7", "side": "SELL", "hash": "368bced32f3e9e4e9ab618dcd8520cdbb5af459c", "best_bid": "0.428", "best_ask": "0.429"}, {"asset_id": "78633590736077251574794513664747155551297291244492840448622550955320930591622", "price": "0.494", "size": "36.7", "side": "BUY", "hash": "d0f6021cf385764d0373ad7963ca22e8b33e444a", "best_bid": "0.571", "best_ask": "0.572"}], "timestamp": "1785164208775", "event_type": "price_change"}}
