{"ts": 1785163724.007, "kind": "price_change", "data": {"market": "0x0f49db97f71c68b1e42a6d16e3de93d85dbf7d4148e3f018eb79e88554be9f75", "price_changes": [{"asset_id": "87854174148074652060467921081181402357467303721471806610111179101805869578687", "price": "0.02", "size": "173000", "side": "BUY", "hash": "1fbd7de1d7386d42ca25a12be0cce020a273424f", "best_bid": "0.805", "best_ask": "0.806"}, {"asset_id": "54533043819946592547517511176940999955633860128497669742211153063842200957669", "price": "0.98", "size": "173000", "side": "SELL", "hash": "bc16ded1ffd39c2992951d584d4a0c74a85ecef5", "best_bid": "0.194", "best_ask": "0.195"}], "timestamp": "1785163724007", "event_type": "price_change"}}
{"ts": 1785163724.008, "kind": "price_change", "data": {"market": "0x0f49db97f71c68b1e42a6d16e3de93d85dbf7d4148e3f018eb79e88554be9f75", "price_changes": [{"asset_id": "87854174148074652060467921081181402357467303721471806610111179101805869578687", "price": "0.02", "size": "233000", "side": "BUY", "hash": "6f7cc4d2d21c3c7ee6b603b11c56bc6fcd2531f2", "best_bid": "0.805", "best_ask": "0.806"}, {"asset_id": "54533043819946592547517511176940999955633860128497669742211153063842200957669", "price": "0.98", "size": "233000", "side": "SELL", "hash": "d47aadf25fa72a6fa4b5ad3c008b34d37585c94b", "best_bid": "0.194", "best_ask": "0.195"}], "timestamp": "1785163724008", "event_type": "price_change"}}
{"ts": 1785163724.08, "kind": "price_change", "data": {"market": "0x0f49db97f71c68b1e42a6d16e3de93d85dbf7d4148e3f018eb79e88554be9f75", "price_changes": [{"asset_id": "54533043819946592547517511176940999955633860128497669742211153063842200957669", "price": "0.04", "size": "300", "side": "BUY", "hash": "ce40af44d12a9a777709e15fbfd53be03fd3899b", "best_bid": "0.194", "best_ask": "0.195"}, {"asset_id": "87854174148074652060467921081181402357467303721471806610111179101805869578687", "price": "0.96", "size": "300", "side": "SELL", "hash": "2d349c4472fe5fd6bf0face06af2b3b4d76b018a", "best_bid": "0.805", "best_ask": "0.806"}], "timestamp": "1785163724080", "event_type": "price_change"}}
{"ts": 1785163724.086, "kind": "price_change", "data": {"market": "0x0f49db97f71c68b1e42a6d16e3de93d85dbf7d4148e3f018eb79e88554be9f75", "price_changes": [{"asset_id": "54533043819946592547517511176940999955633860128497669742211153063842200957669", "price": "0.02", "size": "8000", "side": "BUY", "hash": "3e3d132a0f0653dba9e0e0339f85eaf9b7ffed4c", "best_bid": "0.194", "best_ask": "0.195"}, {"asset_id": "87854174148074652060467921081181402357467303721471806610111179101805869578687", "price": "0.98", "size": "8000", "side": "SELL", "hash": "5b775f61bc04cd28f705468427f936f7189411f9", "best_bid": "0.805", "best_ask": "0.806"}], "timestamp": "1785163724086", "event_type": "price_change"}}
{"ts": 1785163724.133, "kind": "price_change", "data": {"market": "0x18b1c135d0a40c5894da9412e77311827d9caf16cf4cd6591b247a34730af919", "price_changes": [{"asset_id": "40081275558852222228080198821361202017557872256707631666334039001378518619916", "price": "0.399", "size": "10117", "side": "BUY", "hash": "73dbdbf6704800781b0f4fc51d225da471804596", "best_bid": "0.428", "best_ask": "0.429"}, {"asset_id": "78633590736077251574794513664747155551297291244492840448622550955320930591622", "price": "0.601", "size": "10117", "side": "SELL", "hash": "7de4f81d5ec3bba121a76422b6decc2e5e1a06d9", "best_bid": "0.571", "best_ask": "0.572"}], "timestamp": "1785163724133", "event_type": "price_change"}}
{"ts": 1785163727.787, "kind": "price_change", "data": {"market": "0x0f49db97f71c68b1e42a6d16e3de93d85dbf7d4148e3f018eb79e88554be9f75", "price_changes": [{"asset_id": "54533043819946592547517511176940999955633860128497669742211153063842200957669", "price": "0.009", "size": "0", "side": "BUY", "hash": "71eccdb4426629ef374cd279bd8353fa296cbb81", "best_bid": "0.194", "best_ask": "0.195"}, {"asset_id": "87854174148074652060467921081181402357467303721471806610111179101805869578687", "price": "0.991", "size": "0", "side": "SELL", "hash": "ccd965f21fb64dd3d88ad87dc5bca3cdb8c97bab", "best_bid": "0.805", "best_ask": "0.806"}], "timestamp": "1785163727787", "event_type": "price_change"}}
{"ts": 1785163727.787, "kind": "price_change", "data": {"market": "0x0f49db97f71c68b1e42a6d16e3de93d85dbf7d4148e3f018eb79e88554be9f75", "price_changes": [{"asset_id": "54533043819946592547517511176940999955633860128497669742211153063842200957669", "price": "0.007", "size": "0", "side": "BUY", "hash": "71eccdb4426629ef374cd279bd8353fa296cbb81", "best_bid": "0.194", "best_ask": "0.195"}, {"asset_id": "87854174148074652060467921081181402357467303721471806610111179101805869578687", "price": "0.993", "size": "0", "side": "SELL", "hash": "ccd965f21fb64dd3d88ad87dc5bca3cdb8c97bab", "best_bid": "0.805", "best_ask": "0.806"}], "timestamp": "1785163727787", "event_type": "price_change"}}
{"ts": 1785163730.34, "kind": "price_change", "data": {"market": "0x18b1c135d0a40c5894da9412e77311827d9caf16cf4cd6591b247a34730af919", "price_changes": [{"asset_id": "40081275558852222228080198821361202017557872256707631666334039001378518619916", "price": "0.398", "size": "14448", "side": "BUY", "hash": "dca8efef03f1fcd282777feb76ecdf9d7210df72", "best_bid": "0.428", "best_ask": "0.429"}, {"asset_id": "78633590736077251574794513664747155551297291244492840448622550955320930591622", "price": "0.602", "size": "14448", "side": "SELL", "hash": "16a4e05f3f4c40a0c40bd1f87ccba336e409f06a", "best_bid": "0.571", "best_ask": "0.572"}], "timestamp": "1785163730340", "event_type": "price_change"}}
{"ts": 1785163731.0, "kind": "price_change", "data": {"market": "0x18b1c135d0a40c5894da9412e77311827d9caf16cf4cd6591b247a34730af919", "price_changes": [{"asset_id": "40081275558852222228080198821361202017557872256707631666334039001378518619916", "price": "0.003", "size": "11000", "side": "BUY", "hash": "4f8656689fb923546d8b8a4530a91a591100199e", "best_bid": "0.428", "best_ask": "0.429"}, {"asset_id": "78633590736077251574794513664747155551297291244492840448622550955320930591622", "price": "0.997", "size": "11000", "side": "SELL", "hash": "309c30b25db1dd68b46f658df449f49d7f1350f5", "best_bid": "0.571", "best_ask": "0.572"}], "timestamp": "1785163731000", "event_type": "price_change"}}
{"ts": 1785163734.969, "kind": "price_change", "data": {"market": "0x0f49db97f71c68b1e42a6d16e3de93d85dbf7d4148e3f018eb79e88554be9f75", "price_changes": [{"asset_id": "87854174148074652060467921081181402357467303721471806610111179101805869578687", "price": "0.02", "size": "220500", "side": "BUY", "hash": "ebaecca8ffa7a049322bb586f85affd96af16f0a", "best_bid": "0.805", "best_ask": "0.806"}, {"asset_id": "54533043819946592547517511176940999955633860128497669742211153063842200957669", "price": "0.98", "size": "220500", "side": "SELL", "hash": "e529877259db0f3137ae149f99e26c137fcb642d", "best_bid": "0.194", "best_ask": "0.195"}], "timestamp": "1785163734969", "event_type": "price_change"}}
{"ts": 1785163735.012, "kind": "price_change", "data": {"market": "0x0f49db97f71c68b1e42a6d16e3de93d85dbf7d4148e3f018eb79e88554be9f75", "price_changes": [{"asset_id": "87854174148074652060467921081181402357467303721471806610111179101805869578687", "price": "0.03", "size": "8333", "side": "BUY", "hash": "ca423af86ff8f755eb389428d4ecdee68e8638c5", "best_bid": "0.805", "best_ask": "0.806"}, {"asset_id": "54533043819946592547517511176940999955633860128497669742211153063842200957669", "price": "0.97", "size": "8333", "side": "SELL", "hash": "3244ceb3aa5762ae86f8bdf652718573352459c1", "best_bid": "0.194", "best_ask": "0.195"}], "timestamp": "1785163735012", "event_type": "price_change"}}
{"ts": 1785163735.012, "kind": "price_change", "data": {"market": "0x0f49db97f71c68b1e42a6d16e3de93d85dbf7d4148e3f018eb79e88554be9f75", "price_changes": [{"asset_id": "54533043819946592547517511176940999955633860128497669742211153063842200957669", "price": "0.04", "size": "4050", "side": "BUY", "hash": "ef63e3b047cd91a3599036f09bafb5dddefe7fd2", "best_bid": "0.194", "best_ask": "0.195"}, {"asset_id": "87854174148074652060467921081181402357467303721471806610111179101805869578687", "price": "0.96", "size": "4050", "side": "SELL", "hash": "b4f5ba4b80a554ffdc6dc267eceba133fbdbb3f0", "best_bid": "0.805", "best_ask": "0.806"}], "timestamp": "1785163735012", "event_type": "price_change"}}
{"ts": 1785163735.2764611, "kind": "orders_out", "data": [{"token_id": "54533043819946592547517511176940999955633860128497669742211153063842200957669", "side": "BUY", "price": 0.153, "size": 19.61}]}
{"ts": 1785163735.797, "kind": "price_change", "data": {"market": "0x18b1c135d0a40c5894da9412e77311827d9caf16cf4cd6591b247a34730af919", "price_changes": [{"asset_id": "40081275558852222228080198821361202017557872256707631666334039001378518619916", "price": "0.397", "size": "50202", "side": "BUY", "hash": "e541c3b8ba3db03d570277c898c7d07aaddc1bcd", "best_bid": "0.428", "best_ask": "0.429"}, {"asset_id": "78633590736077251574794513664747155551297291244492840448622550955320930591622", "price": "0.603", "size": "50202", "side": "SELL", "hash": "65c746327ba7c890dc404f315c4950149d535192", "best_bid": "0.571", "best_ask": "0.572"}], "timestamp": "1785163735797", "event_type": "price_change"}}
{"ts": 1785163736.104776, "kind": "orders_out", "data": [{"token_id": "40081275558852222228080198821361202017557872256707631666334039001378518619916", "side": "BUY", "price": 0.387, "size": 7.75}, {"token_id": "78633590736077251574794513664747155551297291244492840448622550955320930591622", "side": "BUY", "price": 0.529, "size": 5.67}]}
{"ts": 1785163736.708, "kind": "price_change", "data": {"market": "0x18b1c135d0a40c5894da9412e77311827d9caf16cf4cd6591b247a34730af919", "price_changes": [{"asset_id": "40081275558852222228080198821361202017557872256707631666334039001378518619916", "price": "0.003", "size": "19333.33", "side": "BUY", "hash": "7555d16c846559f0eb7472bbe3557c4ea91ad545", "best_bid": "0.428", "best_ask": "0.429"}, {"asset_id": "78633590736077251574794513664747155551297291244492840448622550955320930591622", "price": "0.997", "size": "19333.33", "side": "SELL", "hash": "1cd4a3ef08bd26bee056612852b604f2b640792f", "best_bid": "0.571", "best_ask": "0.572"}], "timestamp": "1785163736708", "event_type": "price_change"}}
{"ts": 1785163737.814, "kind": "price_change", "data": {"market": "0x0f49db97f71c68b1e42a6d16e3de93d85dbf7d4148e3f018eb79e88554be9f75", "price_changes": [{"asset_id": "87854174148074652060467921081181402357467303721471806610111179101805869578687", "price": "0.77", "size": "489.97", "side": "BUY", "hash": "af2b0693a2d40c77249554428b299c9b7c755b96", "best_bid": "0.805", "best_ask": "0.806"}, {"asset_id": "54533043819946592547517511176940999955633860128497669742211153063842200957669", "price": "0.23", "size": "489.97", "side": "SELL", "hash": "96536d6693f410bfec213bbdf7449adbdbaf9118", "best_bid": "0.194", "best_ask": "0.195"}], "timestamp": "1785163737814", "event_type": "price_change"}}
{"ts": 1785163737.828, "kind": "price_change", "data": {"market": "0x0f49db97f71c68b1e42a6d16e3de93d85dbf7d4148e3f018eb79e88554be9f75", "price_changes": [{"asset_id": "54533043819946592547517511176940999955633860128497669742211153063842200957669", "price": "0.174", "size": "11362", "side": "BUY", "hash": "b5b9d1bf51bc559bf2fa89beac337318052643c3", "best_bid": "0.194", "best_ask": "0.195"}, {"asset_id": "87854174148074652060467921081181402357467303721471806610111179101805869578687", "price": "0.826", "size": "11362", "side": "SELL", "hash": "1107a4393c6c2b71020126ec32c301237b980ac3", "best_bid": "0.805", "best_ask": "0.806"}], "timestamp": "1785163737828", "event_type": "price_change"}}
{"ts": 1785163738.671, "kind": "price_change", "data": {"market": "0x18b1c135d0a40c5894da9412e77311827d9caf16cf4cd6591b247a34730af919", "price_changes": [{"asset_id": "78633590736077251574794513664747155551297291244492840448622550955320930591622", "price": "0.485", "size": "77", "side": "BUY", "hash": "7a4a2d8a497748c30579d4d1578848ab06ed53fb", "best_bid": "0.571", "best_ask": "0.572"}, {"asset_id": "40081275558852222228080198821361202017557872256707631666334039001378518619916", "price": "0.515", "size": "77", "side": "SELL", "hash": "a134260d9d140b4ecdeb99cd58af529d5a3feee1", "best_bid": "0.428", "best_ask": "0.429"}], "timestamp": "1785163738671", "event_type": "price_change"}}
{"ts": 1785163738.675, "kind": "price_change", "data": {"market": "0x18b1c135d0a40c5894da9412e77311827d9caf16cf4cd6591b247a34730af919", "price_changes": [{"asset_id": "78633590736077251574794513664747155551297291244492840448622550955320930591622", "price": "0.482", "size": "201.09", "side": "BUY", "hash": "97f6fda7f8518af4e5cdfb0f1b91ef2a44360c5f", "best_bid": "0.571", "best_ask": "0.572"}, {"asset_id": "40081275558852222228080198821361202017557872256707631666334039001378518619916", "price": "0.518", "size": "201.09", "side": "SELL", "hash": "2749782d5f5a4a3404d1e58dc6523f65706f4d22", "best_bid": "0.428", "best_ask": "0.429"}], "timestamp": "1785163738675", "event_type": "price_change"}}
{"ts": 1785163739.094, "kind": "price_change", "data": {"market": "0x18b1c135d0a40c5894da9412e77311827d9caf16cf4cd6591b247a34730af919", "price_changes": [{"asset_id": "78633590736077251574794513664747155551297291244492840448622550955320930591622", "price": "0.561", "size": "11777", "side": "BUY", "hash": "b56bdecd2c81ee89fb291043696345f05fc889bd", "best_bid": "0.571", "best_ask": "0.572"}, {"asset_id": "40081275558852222228080198821361202017557872256707631666334039001378518619916", "price": "0.439", "size": "11777", "side": "SELL", "hash": "b0ca6adff8b2bbfe3e16720c3f8a6d67acfcf343", "best_bid": "0.428", "best_ask": "0.429"}], "timestamp": "1785163739094", "event_type": "price_change"}}
{"ts": 1785163739.266, "kind": "price_change", "data": {"market": "0x18b1c135d0a40c5894da9412e77311827d9caf16cf4cd6591b247a34730af919", "price_changes": [{"asset_id": "40081275558852222228080198821361202017557872256707631666334039001378518619916", "price": "0.41", "size": "2931.23", "side": "BUY", "hash": "059931d56bc215f02783254ac4b1fbf156058c39", "best_bid": "0.428", "best_ask": "0.429"}, {"asset_id": "78633590736077251574794513664747155551297291244492840448622550955320930591622", "price": "0.59", "size": "2931.23", "side": "SELL", "hash": "fbd4cafbb3eb127d878ba9b8b2b9b8c14fbb0b28", "best_bid": "0.571", "best_ask": "0.572"}], "timestamp": "1785163739266", "event_type": "price_change"}}
{"ts": 1785163739.849, "kind": "price_change", "data": {"market": "0x18b1c135d0a40c5894da9412e77311827d9caf16cf4cd6591b247a34730af919", "price_changes": [{"asset_id": "40081275558852222228080198821361202017557872256707631666334039001378518619916", "price": "0.41", "size": "2947.28", "side": "BUY", "hash": "d1c0c6bf568c531ac904041026bbac3983387603", "best_bid": "0.428", "best_ask": "0.429"}, {"asset_id": "78633590736077251574794513664747155551297291244492840448622550955320930591622", "price": "0.59", "size": "2947.28", "side": "SELL", "hash": "5646693a44d80482fdb93ea8865242bd56486dea", "best_bid": "0.571", "best_ask": "0.572"}], "timestamp": "1785163739849", "event_type": "price_change"}}
{"ts": 1785163742.966, "kind": "price_change", "data": {"market": "0x0f49db97f71c68b1e42a6d16e3de93d85dbf7d4148e3f018eb79e88554be9f75", "price_changes": [{"asset_id": "87854174148074652060467921081181402357467303721471806610111179101805869578687", "price": "0.03", "size": "0", "side": "BUY", "hash": "3c91797bfa278679237fa541100127283314d90c", "best_bid": "0.805", "best_ask": "0.806"}, {"asset_id": "54533043819946592547517511176940999955633860128497669742211153063842200957669", "price": "0.97", "size": "0", "side": "SELL", "hash": "98ced92309ae1d892737db5e3ec9a84d6bb63753", "best_bid": "0.194", "best_ask": "0.195"}], "timestamp": "1785163742966", "event_type": "price_change"}}
{"ts": 1785163743.042, "kind": "price_change", "data": {"market": "0x0f49db97f71c68b1e42a6d16e3de93d85dbf7d4148e3f018eb79e88554be9f75", "price_changes": [{"asset_id": "87854174148074652060467921081181402357467303721471806610111179101805869578687", "price": "0.788", "size": "178", "side": "BUY", "hash": "ee75e474fe8f01043106d4fb51c65ab0e7e5aaeb", "best_bid": "0.805", "best_ask": "0.806"}, {"asset_id": "54533043819946592547517511176940999955633860128497669742211153063842200957669", "price": "0.212", "size": "178", "side": "SELL", "hash": "4be86dbf5b8892c8e81d7c7245982e8c8ea9a0d1", "best_bid": "0.194", "best_ask": "0.195"}], "timestamp": "1785163743042", "event_type": "price_change"}}
{"ts": 1785163743.134, "kind": "price_change", "data": {"market": "0x0f49db97f71c68b1e42a6d16e3de93d85dbf7d4148e3f018eb79e88554be9f75", "price_changes": [{"asset_id": "87854174148074652060467921081181402357467303721471806610111179101805869578687", "price": "0.788", "size": "188", "side": "BUY", "hash": "e7635bb4e7a593b9940fcf385e3b5ab406e34190", "best_bid": "0.805", "best_ask": "0.806"}, {"asset_id": "54533043819946592547517511176940999955633860128497669742211153063842200957669", "price": "0.212", "size": "188", "side": "SELL", "hash": "f899c721377d13f14a8efd224a9054fb152dff69", "best_bid": "0.194", "best_ask": "0.195"}], "timestamp": "1785163743134", "event_type": "price_change"}}
{"ts": 1785163743.208, "kind": "price_change", "data": {"market": "0x0f49db97f71c68b1e42a6d16e3de93d85dbf7d4148e3f018eb79e88554be9f75", "price_changes": [{"asset_id": "87854174148074652060467921081181402357467303721471806610111179101805869578687", "price": "0.788", "size": "178", "side": "BUY", "hash": "23cc0256fbd5f7834e8d07c623086be3fc28bc28", "best_bid": "0.805", "best_ask": "0.806"}, {"asset_id": "54533043819946592547517511176940999955633860128497669742211153063842200957669", "price": "0.212", "size": "178", "side": "SELL", "hash": "f05f7d603c7edb2b7146edfbae8a66cab88cf7de", "best_bid": "0.194", "best_ask": "0.195"}], "timestamp": "1785163743208", "event_type": "price_change"}}
{"ts": 1785163744.224, "kind": "price_change", "data": {"market": "0x18b1c135d0a40c5894da9412e77311827d9caf16cf4cd6591b247a34730af919", "price_changes": [{"asset_id": "78633590736077251574794513664747155551297291244492840448622550955320930591622", "price": "0.56", "size": "5835.99", "side": "BUY", "hash": "3c1bb50052389cfae7fc83c6fec68221ee0bd45b", "best_bid": "0.571", "best_ask": "0.572"}, {"asset_id": "40081275558852222228080198821361202017557872256707631666334039001378518619916", "price": "0.44", "size": "5835.99", "side": "SELL", "hash": "8d3b97379462af4b282cb76744e16b45b38d0f37", "best_bid": "0.428", "best_ask": "0.429"}], "timestamp": "1785163744224", "event_type": "price_change"}}
{"ts": 1785163744.501, "kind": "price_change", "data": {"market": "0x18b1c135d0a40c5894da9412e77311827d9caf16cf4cd6591b247a34730af919", "price_changes": [{"asset_id": "40081275558852222228080198821361202017557872256707631666334039001378518619916", "price": "0.399", "size": "5", "side": "BUY", "hash": "7b822ad3435d0d3ea51996014d2dd11a7b2728d8", "best_bid": "0.428", "best_ask": "0.429"}, {"asset_id": "78633590736077251574794513664747155551297291244492840448622550955320930591622", "price": "0.601", "size": "5", "side": "SELL", "hash": "0ef107490976319ac06b5bbbced60b93fccfe35f", "best_bid": "0.571", "best_ask": "0.572"}], "timestamp": "1785163744501", "event_type": "price_change"}}
{"ts": 1785163746.302, "kind": "price_change", "data": {"market": "0x18b1c135d0a40c5894da9412e77311827d9caf16cf4cd6591b247a34730af919", "price_changes": [{"asset_id": "78633590736077251574794513664747155551297291244492840448622550955320930591622", "price": "0.555", "size": "12242.19", "side": "BUY", "hash": "6261a4237f162714df6e0a1c6cac150f01f4bf06", "best_bid": "0.571", "best_ask": "0.572"}, {"asset_id": "40081275558852222228080198821361202017557872256707631666334039001378518619916", "price": "0.445", "size": "12242.19", "side": "SELL", "hash": "83b73c2458f255b2dd2306a5e4b99cf9521489b1", "best_bid": "0.428", "best_ask": "0.429"}], "timestamp": "1785163746302", "event_type": "price_change"}}
{"ts": 1785163746.776, "kind": "price_change", "data": {"market": "0x18b1c135d0a40c5894da9412e77311827d9caf16cf4cd6591b247a34730af919", "price_changes": [{"asset_id": "40081275558852222228080198821361202017557872256707631666334039001378518619916", "price": "0.507", "size": "0", "side": "SELL", "hash": "7bac91a2fdc4e6578d130e9aa70cac8325c93992", "best_bid": "0.428", "best_ask": "0.429"}, {"asset_id": "78633590736077251574794513664747155551297291244492840448622550955320930591622", "price": "0.493", "size": "0", "side": "BUY", "hash": "5a87ce495a36916b9138ffd0430f3e1a056d65f2", "best_bid": "0.571", "best_ask": "0.572"}], "timestamp": "1785163746776", "event_type": "price_change"}}
{"ts": 1785163747.789, "kind": "price_change", "data": {"market": "0x18b1c135d0a40c5894da9412e77311827d9caf16cf4cd6591b247a34730af919", "price_changes": [{"asset_id": "40081275558852222228080198821361202017557872256707631666334039001378518619916", "price": "0.506", "size": "36.7", "side": "SELL", "hash": "92be0247730061427ec343c8eb9317bebc92abfd", "best_bid": "0.428", "best_ask": "0.429"}, {"asset_id": "78633590736077251574794513664747155551297291244492840448622550955320930591622", "price": "0.494", "size": "36.7", "side": "BUY", "hash": "2ba0c7cfd1233c74344a45518553038784822fa5", "best_bid": "0.571", "best_ask": "0.572"}], "timestamp": "1785163747789", "event_type": "price_change"}}
{"ts": 1785163748.332, "kind": "price_change", "data": {"market": "0x18b1c135d0a40c5894da9412e77311827d9caf16cf4cd6591b247a34730af919", "price_changes": [{"asset_id": "40081275558852222228080198821361202017557872256707631666334039001378518619916", "price": "0.506", "size": "0", "side": "SELL", "hash": "d4648ae653c0eb2d0837464b74db74872b0cb8d0", "best_bid": "0.428", "best_ask": "0.429"}, {"asset_id": "78633590736077251574794513664747155551297291244492840448622550955320930591622", "price": "0.494", "size": "0", "side": "BUY", "hash": "571770d92004878e9c92c075e5691124fbebb5c6", "best_bid": "0.571", "best_ask": "0.572"}], "timestamp": "1785163748332", "event_type": "price_change"}}
{"ts": 1785163748.661, "kind": "price_change", "data": {"market": "0x18b1c135d0a40c5894da9412e77311827d9caf16cf4cd6591b247a34730af919", "price_changes": [{"asset_id": "40081275558852222228080198821361202017557872256707631666334039001378518619916", "price": "0.507", "size": "36.7", "side": "SELL", "hash": "86ce9109b60bfc85b1ba46534a9f7ddf0b65416e", "best_bid": "0.428", "best_ask": "0.429"}, {"asset_id": "78633590736077251574794513664747155551297291244492840448622550955320930591622", "price": "0.493", "size": "36.7", "side": "BUY", "hash": "5415ea4c1c179ba3e78e93fa9eb969929d234e66", "best_bid": "0.571", "best_ask": "0.572"}], "timestamp": "1785163748661", "event_type": "price_change"}}
{"ts": 1785163749.233, "kind": "price_change", "data": {"market": "0x18b1c135d0a40c5894da9412e77311827d9caf16cf4cd6591b247a34730af919", "price_changes": [{"asset_id": "78633590736077251574794513664747155551297291244492840448622550955320930591622", "price": "0.551", "size": "28421.96", "side": "BUY", "hash": "5aa6429e83757f4b823908501b6dc9dbb26522d1", "best_bid": "0.571", "best_ask": "0.572"}, {"asset_id": "40081275558852222228080198821361202017557872256707631666334039001378518619916", "price": "0.449", "size": "28421.96", "side": "SELL", "hash": "9d988fececd0e86cb8b729316cd0f35d1d8a8df3", "best_bid": "0.428", "best_ask": "0.429"}], "timestamp": "1785163749233", "event_type": "price_change"}}
{"ts": 1785163749.621, "kind": "price_change", "data": {"market": "0x18b1c135d0a40c5894da9412e77311827d9caf16cf4cd6591b247a34730af919", "price_changes": [{"asset_id": "40081275558852222228080198821361202017557872256707631666334039001378518619916", "price": "0.399", "size": "10117", "side": "BUY", "hash": "c81ebac63afe84ab445e2f300ebfe5b7fa598c2a", "best_bid": "0.428", "best_ask": "0.429"}, {"asset_id": "78633590736077251574794513664747155551297291244492840448622550955320930591622", "price": "0.601", "size": "10117", "side": "SELL", "hash": "a43add492fb608febfc4cc04cf3baa787723b938", "best_bid": "0.571", "best_ask": "0.572"}], "timestamp": "1785163749621", "event_type": "price_change"}}
{"ts": 1785163750.002, "kind": "price_change", "data": {"market": "0x18b1c135d0a40c5894da9412e77311827d9caf16cf4cd6591b247a34730af919", "price_changes": [{"asset_id": "78633590736077251574794513664747155551297291244492840448622550955320930591622", "price": "0.551", "size": "28221.96", "side": "BUY", "hash": "3b63d9367e75d12d3715b5d51924cd63b3476e54", "best_bid": "0.571", "best_ask": "0.572"}, {"asset_id": "40081275558852222228080198821361202017557872256707631666334039001378518619916", "price": "0.449", "size": "28221.96", "side": "SELL", "hash": "8f0d003b8e7dd76375c7b98addd88df43af78016", "best_bid": "0.428", "best_ask": "0.429"}], "timestamp": "1785163750002", "event_type": "price_change"}}
{"ts": 1785163750.143, "kind": "price_change", "data": {"market": "0x18b1c135d0a40c5894da9412e77311827d9caf16cf4cd6591b247a34730af919", "price_changes": [{"asset_id": "78633590736077251574794513664747155551297291244492840448622550955320930591622", "price": "0.551", "size": "28421.96", "side": "BUY", "hash": "8e43ba43c7617d068fe43e8a87be56189ef30a0f", "best_bid": "0.571", "best_ask": "0.572"}, {"asset_id": "40081275558852222228080198821361202017557872256707631666334039001378518619916", "price": "0.449", "size": "28421.96", "side": "SELL", "hash": "a3bc5b1c765bc25de6b476ca4546a1d0129f2a54", "best_bid": "0.428", "best_ask": "0.429"}], "timestamp": "1785163750143", "event_type": "price_change"}}
{"ts": 1785163751.325, "kind": "price_change", "data": {"market": "0x0f49db97f71c68b1e42a6d16e3de93d85dbf7d4148e3f018eb79e88554be9f75", "price_changes": [{"asset_id": "87854174148074652060467921081181402357467303721471806610111179101805869578687", "price": "0.02", "size": "233000", "side": "BUY", "hash": "556a455bd94ea7fd89e0b1e4d5843d18a32d6a38", "best_bid": "0.805", "best_ask": "0.806"}, {"asset_id": "54533043819946592547517511176940999955633860128497669742211153063842200957669", "price": "0.98", "size": "233000", "side": "SELL", "hash": "cb326288441022d626d18dba536c9dfa3f1b3ff6", "best_bid": "0.194", "best_ask": "0.195"}], "timestamp": "1785163751325", "event_type": "price_change"}}
{"ts": 1785163754.419, "kind": "price_change", "data": {"market": "0x18b1c135d0a40c5894da9412e77311827d9caf16cf4cd6591b247a34730af919", "price_changes": [{"asset_id": "78633590736077251574794513664747155551297291244492840448622550955320930591622", "price": "0.55", "size": "30078.38", "side": "BUY", "hash": "2403a30bf0f7cd870014af049e724de718c3447e", "best_bid": "0.571", "best_ask": "0.572"}, {"asset_id": "40081275558852222228080198821361202017557872256707631666334039001378518619916", "price": "0.45", "size": "30078.38", "side": "SELL", "hash": "575833aadde46c646fd4814af6ae88b5dbc345af", "best_bid": "0.428", "best_ask": "0.429"}], "timestamp": "1785163754419", "event_type": "price_change"}}
{"ts": 1785163757.008, "kind": "price_change", "data": {"market": "0x18b1c135d0a40c5894da9412e77311827d9caf16cf4cd6591b247a34730af919", "price_changes": [{"asset_id": "40081275558852222228080198821361202017557872256707631666334039001378518619916", "price": "0.41", "size": "2931.23", "side": "BUY", "hash": "70790f7151ab354dc38211c16e29fee10ae97ea2", "best_bid": "0.428", "best_ask": "0.429"}, {"asset_id": "78633590736077251574794513664747155551297291244492840448622550955320930591622", "price": "0.59", "size": "2931.23", "side": "SELL", "hash": "4237c353333a98bf5a03f6906f9e8c29f30e15e8", "best_bid": "0.571", "best_ask": "0.572"}], "timestamp": "1785163757008", "event_type": "price_change"}}
{"ts": 1785163757.629, "kind": "price_change", "data": {"market": "0x0f49db97f71c68b1e42a6d16e3de93d85dbf7d4148e3f018eb79e88554be9f75", "price_changes": [{"asset_id": "87854174148074652060467921081181402357467303721471806610111179101805869578687", "price": "0.795", "size": "3127.98", "side": "BUY", "hash": "ca671b1962c734afb8642fc51a21a3a43a828dc4", "best_bid": "0.805", "best_ask": "0.806"}, {"asset_id": "54533043819946592547517511176940999955633860128497669742211153063842200957669", "price": "0.205", "size": "3127.98", "side": "SELL", "hash": "56fbfeccd6c6a3b6d8f2bcdeaa97d19f84001516", "best_bid": "0.194", "best_ask": "0.195"}], "timestamp": "1785163757629", "event_type": "price_change"}}
{"ts": 1785163757.717, "kind": "price_change", "data": {"market": "0x18b1c135d0a40c5894da9412e77311827d9caf16cf4cd6591b247a34730af919", "price_changes": [{"asset_id": "40081275558852222228080198821361202017557872256707631666334039001378518619916", "price": "0.41", "size": "2947.28", "side": "BUY", "hash": "99be22f9d43ee284e488eafaee87a722e2e59012", "best_bid": "0.428", "best_ask": "0.429"}, {"asset_id": "78633590736077251574794513664747155551297291244492840448622550955320930591622", "price": "0.59", "size": "2947.28", "side": "SELL", "hash": "90f7777ec7de99fb206922eb4a71ec653b40f560", "best_bid": "0.571", "best_ask": "0.572"}], "timestamp": "1785163757717", "event_type": "price_change"}}
{"ts": 1785163757.723, "kind": "price_change", "data": {"market": "0x0f49db97f71c68b1e42a6d16e3de93d85dbf7d4148e3f018eb79e88554be9f75", "price_changes": [{"asset_id": "87854174148074652060467921081181402357467303721471806610111179101805869578687", "price": "0.795", "size": "3694.98", "side": "BUY", "hash": "c3a1f56d91c468f489d07d1aa201f05a8623195b", "best_bid": "0.805", "best_ask": "0.806"}, {"asset_id": "54533043819946592547517511176940999955633860128497669742211153063842200957669", "price": "0.205", "size": "3694.98", "side": "SELL", "hash": "9c2675ee603527d0dc09fac7c0c4cab125bc0088", "best_bid": "0.194", "best_ask": "0.195"}], "timestamp": "1785163757723", "event_type": "price_change"}}
{"ts": 1785163758.339, "kind": "price_change", "data": {"market": "0x18b1c135d0a40c5894da9412e77311827d9caf16cf4cd6591b247a34730af919", "price_changes": [{"asset_id": "40081275558852222228080198821361202017557872256707631666334039001378518619916", "price": "0.418", "size": "5840.25", "side": "BUY", "hash": "5b7ddcfd291c0cc36855fb6a6bb165b7fe3f5ed7", "best_bid": "0.428", "best_ask": "0.429"}, {"asset_id": "78633590736077251574794513664747155551297291244492840448622550955320930591622", "price": "0.582", "size": "5840.25", "side": "SELL", "hash": "c3edc99038550623a97ac14755af3cd0f6fed406", "best_bid": "0.571", "best_ask": "0.572"}], "timestamp": "1785163758339", "event_type": "price_change"}}
{"ts": 1785163758.371, "kind": "price_change", "data": {"market": "0x18b1c135d0a40c5894da9412e77311827d9caf16cf4cd6591b247a34730af919", "price_changes": [{"asset_id": "40081275558852222228080198821361202017557872256707631666334039001378518619916", "price": "0.418", "size": "5640.25", "side": "BUY", "hash": "2fa6d36f0fe67b9bfad1debd0c38edfd7d0957c8", "best_bid": "0.428", "best_ask": "0.429"}, {"asset_id": "78633590736077251574794513664747155551297291244492840448622550955320930591622", "price": "0.582", "size": "5640.25", "side": "SELL", "hash": "34416e4198e2e376792594778001d759529ec08e", "best_bid": "0.571", "best_ask": "0.572"}], "timestamp": "1785163758371", "event_type": "price_change"}}
{"ts": 1785163758.412, "kind": "price_change", "data": {"market": "0x18b1c135d0a40c5894da9412e77311827d9caf16cf4cd6591b247a34730af919", "price_changes": [{"asset_id": "40081275558852222228080198821361202017557872256707631666334039001378518619916", "price": "0.417", "size": "1200", "side": "BUY", "hash": "6843bc46b20082bed69e267550ec805789ef2ae1", "best_bid": "0.428", "best_ask": "0.429"}, {"asset_id": "78633590736077251574794513664747155551297291244492840448622550955320930591622", "price": "0.583", "size": "1200", "side": "SELL", "hash": "972251200ba67b76e216b2ff68f3a048a6598884", "best_bid": "0.571", "best_ask": "0.572"}], "timestamp": "1785163758412", "event_type": "price_change"}}
{"ts": 1785163758.428, "kind": "price_change", "data": {"market": "0x18b1c135d0a40c5894da9412e77311827d9caf16cf4cd6591b247a34730af919", "price_changes": [{"asset_id": "40081275558852222228080198821361202017557872256707631666334039001378518619916", "price": "0.418", "size": "6718.25", "side": "BUY", "hash": "b1cd277a52141ad726db3f559d7480ac23f92afb", "best_bid": "0.428", "best_ask": "0.429"}, {"asset_id": "78633590736077251574794513664747155551297291244492840448622550955320930591622", "price": "0.582", "size": "6718.25", "side": "SELL", "hash": "e2ea48c98944b55ea8579da3d09ebeecba2bc31a", "best_bid": "0.571", "best_ask": "0.572"}], "timestamp": "1785163758428", "event_type": "price_change"}}
{"ts": 1785163758.462, "kind": "price_change", "data": {"market": "0x18b1c135d0a40c5894da9412e77311827d9caf16cf4cd6591b247a34730af919", "price_changes": [{"asset_id": "40081275558852222228080198821361202017557872256707631666334039001378518619916", "price": "0.417", "size": "1000", "side": "BUY", "hash": "4d479c40a6207cd7b1cead360e3f11694e4ab2f2", "best_bid": "0.428", "best_ask": "0.429"}, {"asset_id": "78633590736077251574794513664747155551297291244492840448622550955320930591622", "price": "0.583", "size": "1000", "side": "SELL", "hash": "cb61365f333f8b668cb28c1b449698cf990681f4", "best_bid": "0.571", "best_ask": "0.572"}], "timestamp": "1785163758462", "event_type": "price_change"}}
{"ts": 1785163758.502, "kind": "price_change", "data": {"market": "0x18b1c135d0a40c5894da9412e77311827d9caf16cf4cd6591b247a34730af919", "price_changes": [{"asset_id": "40081275558852222228080198821361202017557872256707631666334039001378518619916", "price": "0.418", "size": "6918.25", "side": "BUY", "hash": "8ef313eb987a324a328b5cb7d665cfad974da8c4", "best_bid": "0.428", "best_ask": "0.429"}, {"asset_id": "78633590736077251574794513664747155551297291244492840448622550955320930591622", "price": "0.582", "size": "6918.25", "side": "SELL", "hash": "e2c126bd37dceba97ed7944d988619686f6a880b", "best_bid": "0.571", "best_ask": "0.572"}], "timestamp": "1785163758502", "event_type": "price_change"}}
{"ts": 1785163758.644331, "kind": "orders_out", "data": [{"token_id": "40081275558852222228080198821361202017557872256707631666334039001378518619916", "side": "BUY", "price": 0.387, "size": 7.75}, {"token_id": "78633590736077251574794513664747155551297291244492840448622550955320930591622", "side": "BUY", "price": 0.529, "size": 5.67}]}
{"ts": 1785163759.45, "kind": "price_change", "data": {"market": "0x18b1c135d0a40c5894da9412e77311827d9caf16cf4cd6591b247a34730af919", "price_changes": [{"asset_id": "78633590736077251574794513664747155551297291244492840448622550955320930591622", "price": "0.532", "size": "74115.71", "side": "BUY", "hash": "2dcd33cae04a28b10c352034b86bafdaa9d1efee", "best_bid": "0.571", "best_ask": "0.572"}, {"asset_id": "40081275558852222228080198821361202017557872256707631666334039001378518619916", "price": "0.468", "size": "74115.71", "side": "SELL", "hash": "c49089a1864f493150ff5382485fc153794defe4", "best_bid": "0.428", "best_ask": "0.429"}], "timestamp": "1785163759450", "event_type": "price_change"}}
{"ts": 1785163761.0, "kind": "price_change", "data": {"market": "0x18b1c135d0a40c5894da9412e77311827d9caf16cf4cd6591b247a34730af919", "price_changes": [{"asset_id": "40081275558852222228080198821361202017557872256707631666334039001378518619916", "price": "0.23", "size": "0", "side": "BUY", "hash": "503ee6228e6ff1c38a7a516ca61adb5f13d8bfda", "best_bid": "0.428", "best_ask": "0.429"}, {"asset_id": "78633590736077251574794513664747155551297291244492840448622550955320930591622", "price": "0.77", "size": "0", "side": "SELL", "hash": "f9b0162b9bc3d5d474995b65b18d31b3ab599e38", "best_bid": "0.571", "best_ask": "0.572"}], "timestamp": "1785163761000", "event_type": "price_change"}}
{"ts": 1785163766.065, "kind": "price_change", "data": {"market": "0x0f49db97f71c68b1e42a6d16e3de93d85dbf7d4148e3f018eb79e88554be9f75", "price_changes": [{"asset_id": "87854174148074652060467921081181402357467303721471806610111179101805869578687", "price": "0.795", "size": "3128.98", "side": "BUY", "hash": "ee88fb60ee10fc651087700d0fbdb9c7e9ed3958", "best_bid": "0.805", "best_ask": "0.806"}, {"asset_id": "54533043819946592547517511176940999955633860128497669742211153063842200957669", "price": "0.205", "size": "3128.98", "side": "SELL", "hash": "cb471e4de634b1482805ed13daf98399ec8729a9", "best_bid": "0.194", "best_ask": "0.195"}], "timestamp": "1785163766065", "event_type": "price_change"}}
{"ts": 1785163766.166, "kind": "price_change", "data": {"market": "0x0f49db97f71c68b1e42a6d16e3de93d85dbf7d4148e3f018eb79e88554be9f75", "price_changes": [{"asset_id": "87854174148074652060467921081181402357467303721471806610111179101805869578687", "price": "0.795", "size": "3694.98", "side": "BUY", "hash": "6cea124be5eeeac2fe5d18cf4aa5a8ad84811fe0", "best_bid": "0.805", "best_ask": "0.806"}, {"asset_id": "54533043819946592547517511176940999955633860128497669742211153063842200957669", "price": "0.205", "size": "3694.98", "side": "SELL", "hash": "c5ce1289c24ebb4918b767e769bc72d5fea42728", "best_bid": "0.194", "best_ask": "0.195"}], "timestamp": "1785163766166", "event_type": "price_change"}}
{"ts": 1785163766.222, "kind": "price_change", "data": {"market": "0x0f49db97f71c68b1e42a6d16e3de93d85dbf7d4148e3f018eb79e88554be9f75", "price_changes": [{"asset_id": "54533043819946592547517511176940999955633860128497669742211153063842200957669", "price": "0.158", "size": "25522", "side": "BUY", "hash": "36ed4438cd3ce670fd2668e96392b5c714e67eeb", "best_bid": "0.194", "best_ask": "0.195"}, {"asset_id": "87854174148074652060467921081181402357467303721471806610111179101805869578687", "price": "0.842", "size": "25522", "side": "SELL", "hash": "4e50a5df06ac82f539e016005134d91cfe43125c", "best_bid": "0.805", "best_ask": "0.806"}], "timestamp": "1785163766222", "event_type": "price_change"}}
{"ts": 1785163766.37885, "kind": "orders_out", "data": [{"token_id": "54533043819946592547517511176940999955633860128497669742211153063842200957669", "side": "BUY", "price": 0.153, "size": 19.61}]}
{"ts": 1785163766.498, "kind": "price_change", "data": {"market": "0x0f49db97f71c68b1e42a6d16e3de93d85dbf7d4148e3f018eb79e88554be9f75", "price_changes": [{"asset_id": "54533043819946592547517511176940999955633860128497669742211153063842200957669", "price": "0.009", "size": "13888.88", "side": "BUY", "hash": "374634581c3d15061753cb164dc1de6271c1b2d8", "best_bid": "0.194", "best_ask": "0.195"}, {"asset_id": "87854174148074652060467921081181402357467303721471806610111179101805869578687", "price": "0.991", "size": "13888.88", "side": "SELL", "hash": "2b417f4127186b3278cab66274f3963b1ac9bc8a", "best_bid": "0.805", "best_ask": "0.806"}], "timestamp": "1785163766498", "event_type": "price_change"}}
{"ts": 1785163766.501, "kind": "price_change", "data": {"market": "0x0f49db97f71c68b1e42a6d16e3de93d85dbf7d4148e3f018eb79e88554be9f75", "price_changes": [{"asset_id": "54533043819946592547517511176940999955633860128497669742211153063842200957669", "price": "0.007", "size": "53571.42", "side": "BUY", "hash": "3d57771e48c9e4de83a6df7c58bf8d7a3c3031e9", "best_bid": "0.194", "best_ask": "0.195"}, {"asset_id": "87854174148074652060467921081181402357467303721471806610111179101805869578687", "price": "0.993", "size": "53571.42", "side": "SELL", "hash": "acb2e94aedfcf4996dbb459b3f1d7504b0404777", "best_bid": "0.805", "best_ask": "0.806"}], "timestamp": "1785163766501", "event_type": "price_change"}}
{"ts": 1785163766.563, "kind": "price_change", "data": {"market": "0x0f49db97f71c68b1e42a6d16e3de93d85dbf7d4148e3f018eb79e88554be9f75", "price_changes": [{"asset_id": "87854174148074652060467921081181402357467303721471806610111179101805869578687", "price": "0.788", "size": "188", "side": "BUY", "hash": "25ea359d46c07a03d263990e42297264fb661746", "best_bid": "0.805", "best_ask": "0.806"}, {"asset_id": "54533043819946592547517511176940999955633860128497669742211153063842200957669", "price": "0.212", "size": "188", "side": "SELL", "hash": "14b6a596e679aeb9447663b59243ec7a49d61727", "best_bid": "0.194", "best_ask": "0.195"}], "timestamp": "1785163766563", "event_type": "price_change"}}
{"ts": 1785163766.673, "kind": "price_change", "data": {"market": "0x18b1c135d0a40c5894da9412e77311827d9caf16cf4cd6591b247a34730af919", "price_changes": [{"asset_id": "40081275558852222228080198821361202017557872256707631666334039001378518619916", "price": "0.418", "size": "5842.25", "side": "BUY", "hash": "dff4a5a9141fa3cd03a54e82ceb57ad3ed372922", "best_bid": "0.428", "best_ask": "0.429"}, {"asset_id": "78633590736077251574794513664747155551297291244492840448622550955320930591622", "price": "0.582", "size": "5842.25", "side": "SELL", "hash": "fb840ce06c69141b00e0045e69b6b1af677ff580", "best_bid": "0.571", "best_ask": "0.572"}], "timestamp": "1785163766673", "event_type": "price_change"}}
{"ts": 1785163766.7, "kind": "price_change", "data": {"market": "0x18b1c135d0a40c5894da9412e77311827d9caf16cf4cd6591b247a34730af919", "price_changes": [{"asset_id": "40081275558852222228080198821361202017557872256707631666334039001378518619916", "price": "0.418", "size": "5642.25", "side": "BUY", "hash": "2defdd07ef8d07ce1a7ba0678a9abcf36fd27a35", "best_bid": "0.428", "best_ask": "0.429"}, {"asset_id": "78633590736077251574794513664747155551297291244492840448622550955320930591622", "price": "0.582", "size": "5642.25", "side": "SELL", "hash": "78a5e1522c79df26263532e59beeb411de7c8562", "best_bid": "0.571", "best_ask": "0.572"}], "timestamp": "1785163766700", "event_type": "price_change"}}
{"ts": 1785163766.737, "kind": "price_change", "data": {"market": "0x18b1c135d0a40c5894da9412e77311827d9caf16cf4cd6591b247a34730af919", "price_changes": [{"asset_id": "40081275558852222228080198821361202017557872256707631666334039001378518619916", "price": "0.417", "size": "1200", "side": "BUY", "hash": "03dcb84ffb60384227d9116e33ccf5e3df80eb20", "best_bid": "0.428", "best_ask": "0.429"}, {"asset_id": "78633590736077251574794513664747155551297291244492840448622550955320930591622", "price": "0.583", "size": "1200", "side": "SELL", "hash": "ed967f4cf9175fff707b89a662cf9b86990b72a6", "best_bid": "0.571", "best_ask": "0.572"}], "timestamp": "1785163766737", "event_type": "price_change"}}
{"ts": 1785163766.758, "kind": "price_change", "data": {"market": "0x18b1c135d0a40c5894da9412e77311827d9caf16cf4cd6591b247a34730af919", "price_changes": [{"asset_id": "40081275558852222228080198821361202017557872256707631666334039001378518619916", "price": "0.418", "size": "6718.25", "side": "BUY", "hash": "b3470d86f6321f2d3fb92d94b10d9b17862ed0a2", "best_bid": "0.428", "best_ask": "0.429"}, {"asset_id": "78633590736077251574794513664747155551297291244492840448622550955320930591622", "price": "0.582", "size": "6718.25", "side": "SELL", "hash": "dc674bc887476f107a3ade915a7d3b9cc7e63598", "best_bid": "0.571", "best_ask": "0.572"}], "timestamp": "1785163766758", "event_type": "price_change"}}
{"ts": 1785163766.789, "kind": "price_change", "data": {"market": "0x18b1c135d0a40c5894da9412e77311827d9caf16cf4cd6591b247a34730af919", "price_changes": [{"asset_id": "40081275558852222228080198821361202017557872256707631666334039001378518619916", "price": "0.417", "size": "1000", "side": "BUY", "hash": "648f9ce2714e3c37eb4a48ef4aaf6218280e6903", "best_bid": "0.428", "best_ask": "0.429"}, {"asset_id": "78633590736077251574794513664747155551297291244492840448622550955320930591622", "price": "0.583", "size": "1000", "side": "SELL", "hash": "9baf60bd50c6cf5d36ed27c3420e7293395c21d4", "best_bid": "0.571", "best_ask": "0.572"}], "timestamp": "1785163766789", "event_type": "price_change"}}
{"ts": 1785163766.821, "kind": "price_change", "data": {"market": "0x18b1c135d0a40c5894da9412e77311827d9caf16cf4cd6591b247a34730af919", "price_changes": [{"asset_id": "40081275558852222228080198821361202017557872256707631666334039001378518619916", "price": "0.418", "size": "6918.25", "side": "BUY", "hash": "f99b612001347f6912e58d0d94025827557be63b", "best_bid": "0.428", "best_ask": "0.429"}, {"asset_id": "78633590736077251574794513664747155551297291244492840448622550955320930591622", "price": "0.582", "size": "6918.25", "side": "SELL", "hash": "64dd2d895495742ffe80b9b96530d47669e47937", "best_bid": "0.571", "best_ask": "0.572"}], "timestamp": "1785163766821", "event_type": "price_change"}}
{"ts": 1785163767.002, "kind": "price_change", "data": {"market": "0x18b1c135d0a40c5894da9412e77311827d9caf16cf4cd6591b247a34730af919", "price_changes": [{"asset_id": "78633590736077251574794513664747155551297291244492840448622550955320930591622", "price": "0.02", "size": "750", "side": "BUY", "hash": "8aa9d3d6e24ed725122de556ea27af230af320b9", "best_bid": "0.571", "best_ask": "0.572"}, {"asset_id": "40081275558852222228080198821361202017557872256707631666334039001378518619916", "price": "0.98", "size": "750", "side": "SELL", "hash": "77a3b5265e0562cce2bdd0046bcd4536318c0e2f", "best_bid": "0.428", "best_ask": "0.429"}], "timestamp": "1785163767002", "event_type": "price_change"}}
{"ts": 1785163767.807, "kind": "price_change", "data": {"market": "0x0f49db97f71c68b1e42a6d16e3de93d85dbf7d4148e3f018eb79e88554be9f75", "price_changes": [{"asset_id": "54533043819946592547517511176940999955633860128497669742211153063842200957669", "price": "0.04", "size": "300", "side": "BUY", "hash": "c65e04b66cabf07fbf00cfeda49d12856a40b25a", "best_bid": "0.194", "best_ask": "0.195"}, {"asset_id": "87854174148074652060467921081181402357467303721471806610111179101805869578687", "price": "0.96", "size": "300", "side": "SELL", "hash": "ff9851b9b714fea9e9d950628f505bba0c5af311", "best_bid": "0.805", "best_ask": "0.806"}], "timestamp": "1785163767807", "event_type": "price_change"}}
{"ts": 1785163767.81, "kind": "price_change", "data": {"market": "0x0f49db97f71c68b1e42a6d16e3de93d85dbf7d4148e3f018eb79e88554be9f75", "price_changes": [{"asset_id": "87854174148074652060467921081181402357467303721471806610111179101805869578687", "price": "0.64", "size": "234", "side": "BUY", "hash": "2d44be963e987c13fb4fc4dc2d8e5fab3537b404", "best_bid": "0.805", "best_ask": "0.806"}, {"asset_id": "54533043819946592547517511176940999955633860128497669742211153063842200957669", "price": "0.36", "size": "234", "side": "SELL", "hash": "9331a8fd0b8b30bda70a202426b9476ac89accbf", "best_bid": "0.194", "best_ask": "0.195"}], "timestamp": "1785163767810", "event_type": "price_change"}}
{"ts": 1785163767.833, "kind": "price_change", "data": {"market": "0x0f49db97f71c68b1e42a6d16e3de93d85dbf7d4148e3f018eb79e88554be9f75", "price_changes": [{"asset_id": "87854174148074652060467921081181402357467303721471806610111179101805869578687", "price": "0.77", "size": "389.97", "side": "BUY", "hash": "5fe3c26d07d4e3760efadc2fbe6f57c62ace0085", "best_bid": "0.805", "best_ask": "0.806"}, {"asset_id": "54533043819946592547517511176940999955633860128497669742211153063842200957669", "price": "0.23", "size": "389.97", "side": "SELL", "hash": "05ad441e3262f3c1df7b724bb43dea167c998a9e", "best_bid": "0.194", "best_ask": "0.195"}], "timestamp": "1785163767833", "event_type": "price_change"}}
{"ts": 1785163767.865, "kind": "price_change", "data": {"market": "0x0f49db97f71c68b1e42a6d16e3de93d85dbf7d4148e3f018eb79e88554be9f75", "price_changes": [{"asset_id": "87854174148074652060467921081181402357467303721471806610111179101805869578687", "price": "0.785", "size": "2729", "side": "BUY", "hash": "0c9bf86412338fc0bb9d757b908ac36c54b51fee", "best_bid": "0.805", "best_ask": "0.806"}, {"asset_id": "54533043819946592547517511176940999955633860128497669742211153063842200957669", "price": "0.215", "size": "2729", "side": "SELL", "hash": "24f2fc63358fc508b331c780ff758439d05ea962", "best_bid": "0.194", "best_ask": "0.195"}], "timestamp": "1785163767865", "event_type": "price_change"}}
{"ts": 1785163768.137, "kind": "price_change", "data": {"market": "0x18b1c135d0a40c5894da9412e77311827d9caf16cf4cd6591b247a34730af919", "price_changes": [{"asset_id": "40081275558852222228080198821361202017557872256707631666334039001378518619916", "price": "0.23", "size": "1086", "side": "BUY", "hash": "3b7dbdd93338a09379d3cbf819fcff3b608fb88b", "best_bid": "0.428", "best_ask": "0.429"}, {"asset_id": "78633590736077251574794513664747155551297291244492840448622550955320930591622", "price": "0.77", "size": "1086", "side": "SELL", "hash": "1659cf7f0ba581a332910dad5d4d8cff638ca6e9", "best_bid": "0.571", "best_ask": "0.572"}], "timestamp": "1785163768137", "event_type": "price_change"}}
{"ts": 1785163768.167, "kind": "price_change", "data": {"market": "0x18b1c135d0a40c5894da9412e77311827d9caf16cf4cd6591b247a34730af919", "price_changes": [{"asset_id": "40081275558852222228080198821361202017557872256707631666334039001378518619916", "price": "0.408", "size": "4929", "side": "BUY", "hash": "a5b77998a691ac947846ed5984359a31056220bb", "best_bid": "0.428", "best_ask": "0.429"}, {"asset_id": "78633590736077251574794513664747155551297291244492840448622550955320930591622", "price": "0.592", "size": "4929", "side": "SELL", "hash": "233beb3bf7410af6ae078b57dd5bf5130d3983b5", "best_bid": "0.571", "best_ask": "0.572"}], "timestamp": "1785163768167", "event_type": "price_change"}}
{"ts": 1785163768.169, "kind": "price_change", "data": {"market": "0x18b1c135d0a40c5894da9412e77311827d9caf16cf4cd6591b247a34730af919", "price_changes": [{"asset_id": "78633590736077251574794513664747155551297291244492840448622550955320930591622", "price": "0.551", "size": "28623.96", "side": "BUY", "hash": "72bde79406ac407d41ac1aedc745da7a4d7a9ae1", "best_bid": "0.571", "best_ask": "0.572"}, {"asset_id": "40081275558852222228080198821361202017557872256707631666334039001378518619916", "price": "0.449", "size": "28623.96", "side": "SELL", "hash": "03b130e7a3e59c314acc4ed9de4b76ae79d68355", "best_bid": "0.428", "best_ask": "0.429"}], "timestamp": "1785163768169", "event_type": "price_change"}}
{"ts": 1785163769.578, "kind": "price_change", "data": {"market": "0x18b1c135d0a40c5894da9412e77311827d9caf16cf4cd6591b247a34730af919", "price_changes": [{"asset_id": "40081275558852222228080198821361202017557872256707631666334039001378518619916", "price": "0.418", "size": "6987.45", "side": "BUY", "hash": "9bbab68c83fb456fce4a0c10047cec25739d5ee9", "best_bid": "0.428", "best_ask": "0.429"}, {"asset_id": "78633590736077251574794513664747155551297291244492840448622550955320930591622", "price": "0.582", "size": "6987.45", "side": "SELL", "hash": "6a23f8a0cb13b592487838c98bf91c908c47ba48", "best_bid": "0.571", "best_ask": "0.572"}], "timestamp": "1785163769578", "event_type": "price_change"}}
{"ts": 1785163769.607, "kind": "price_change", "data": {"market": "0x18b1c135d0a40c5894da9412e77311827d9caf16cf4cd6591b247a34730af919", "price_changes": [{"asset_id": "40081275558852222228080198821361202017557872256707631666334039001378518619916", "price": "0.412", "size": "11323.8", "side": "BUY", "hash": "ae10b7d1264f06a5fa55f79da6a24c324a919dbb", "best_bid": "0.428", "best_ask": "0.429"}, {"asset_id": "78633590736077251574794513664747155551297291244492840448622550955320930591622", "price": "0.588", "size": "11323.8", "side": "SELL", "hash": "88dfd824f34c998b98b48e0b5054a134313e8f3b", "best_bid": "0.571", "best_ask": "0.572"}], "timestamp": "1785163769607", "event_type": "price_change"}}
{"ts": 1785163769.608, "kind": "price_change", "data": {"market": "0x18b1c135d0a40c5894da9412e77311827d9caf16cf4cd6591b247a34730af919", "price_changes": [{"asset_id": "40081275558852222228080198821361202017557872256707631666334039001378518619916", "price": "0.411", "size": "36907.4", "side": "BUY", "hash": "eecd34aca951971738bee38eb6d3cd39c33bd52f", "best_bid": "0.428", "best_ask": "0.429"}, {"asset_id": "78633590736077251574794513664747155551297291244492840448622550955320930591622", "price": "0.589", "size": "36907.4", "side": "SELL", "hash": "6033b9d2caee1bcfbddc827c5163524fa0744f9f", "best_bid": "0.571", "best_ask": "0.572"}], "timestamp": "1785163769608", "event_type": "price_change"}}
{"ts": 1785163769.613, "kind": "price_change", "data": {"market": "0x18b1c135d0a40c5894da9412e77311827d9caf16cf4cd6591b247a34730af919", "price_changes": [{"asset_id": "40081275558852222228080198821361202017557872256707631666334039001378518619916", "price": "0.399", "size": "10218.2", "side": "BUY", "hash": "6f43aee62d5d85c5afc1360e60cd80d0da5003ba", "best_bid": "0.428", "best_ask": "0.429"}, {"asset_id": "78633590736077251574794513664747155551297291244492840448622550955320930591622", "price": "0.601", "size": "10218.2", "side": "SELL", "hash": "13e6ac77dfd2011600da3236ece99e85bb45f259", "best_bid": "0.571", "best_ask": "0.572"}], "timestamp": "1785163769613", "event_type": "price_change"}}
{"ts": 1785163769.616, "kind": "price_change", "data": {"market": "0x18b1c135d0a40c5894da9412e77311827d9caf16cf4cd6591b247a34730af919", "price_changes": [{"asset_id": "40081275558852222228080198821361202017557872256707631666334039001378518619916", "price": "0.398", "size": "14592.5", "side": "BUY", "hash": "a872f72e435be9da1f842510ce0d97dc058dad98", "best_bid": "0.428", "best_ask": "0.429"}, {"asset_id": "78633590736077251574794513664747155551297291244492840448622550955320930591622", "price": "0.602", "size": "14592.5", "side": "SELL", "hash": "e19d2863cd19673d11d0892c0c8644bba0a19e5a", "best_bid": "0.571", "best_ask": "0.572"}], "timestamp": "1785163769616", "event_type": "price_change"}}
{"ts": 1785163769.622, "kind": "price_change", "data": {"market": "0x18b1c135d0a40c5894da9412e77311827d9caf16cf4cd6591b247a34730af919", "price_changes": [{"asset_id": "78633590736077251574794513664747155551297291244492840448622550955320930591622", "price": "0.55", "size": "30379.18", "side": "BUY", "hash": "0a4e31fdcecd4c00f69096b807b4e41e904e733c", "best_bid": "0.571", "best_ask": "0.572"}, {"asset_id": "40081275558852222228080198821361202017557872256707631666334039001378518619916", "price": "0.45", "size": "30379.18", "side": "SELL", "hash": "93503f7f24ed27bb8d8e64d9a2df5171d9f76494", "best_bid": "0.428", "best_ask": "0.429"}], "timestamp": "1785163769622", "event_type": "price_change"}}
{"ts": 1785163769.639, "kind": "price_change", "data": {"market": "0x18b1c135d0a40c5894da9412e77311827d9caf16cf4cd6591b247a34730af919", "price_changes": [{"asset_id": "78633590736077251574794513664747155551297291244492840448622550955320930591622", "price": "0.551", "size": "28910.16", "side": "BUY", "hash": "d596663bd710bf9199f6fabd741b2db01a3eec4a", "best_bid": "0.571", "best_ask": "0.572"}, {"asset_id": "40081275558852222228080198821361202017557872256707631666334039001378518619916", "price": "0.449", "size": "28910.16", "side": "SELL", "hash": "3d3bf81bd6d2b33a3da6ed186fb80547f14f8a3c", "best_bid": "0.428", "best_ask": "0.429"}], "timestamp": "1785163769639", "event_type": "price_change"}}
{"ts": 1785163769.642, "kind": "price_change", "data": {"market": "0x18b1c135d0a40c5894da9412e77311827d9caf16cf4cd6591b247a34730af919", "price_changes": [{"asset_id": "78633590736077251574794513664747155551297291244492840448622550955320930591622", "price": "0.561", "size": "11894.8", "side": "BUY", "hash": "6c93856332c44f921dbf8e2045aff82f223375d2", "best_bid": "0.571", "best_ask": "0.572"}, {"asset_id": "40081275558852222228080198821361202017557872256707631666334039001378518619916", "price": "0.439", "size": "11894.8", "side": "SELL", "hash": "386fd2c5010e363a46d8ed624735957f4c992081", "best_bid": "0.428", "best_ask": "0.429"}], "timestamp": "1785163769642", "event_type": "price_change"}}
{"ts": 1785163769.653, "kind": "price_change", "data": {"market": "0x18b1c135d0a40c5894da9412e77311827d9caf16cf4cd6591b247a34730af919", "price_changes": [{"asset_id": "78633590736077251574794513664747155551297291244492840448622550955320930591622", "price": "0.555", "size": "12364.59", "side": "BUY", "hash": "38e25559cf875d6151bdc968f777616ec01270bb", "best_bid": "0.571", "best_ask": "0.572"}, {"asset_id": "40081275558852222228080198821361202017557872256707631666334039001378518619916", "price": "0.445", "size": "12364.59", "side": "SELL", "hash": "f0700be4773f43fcd51adb888ab0d00c5a039ec9", "best_bid": "0.428", "best_ask": "0.429"}], "timestamp": "1785163769653", "event_type": "price_change"}}
{"ts": 1785163769.656, "kind": "price_change", "data": {"market": "0x18b1c135d0a40c5894da9412e77311827d9caf16cf4cd6591b247a34730af919", "price_changes": [{"asset_id": "40081275558852222228080198821361202017557872256707631666334039001378518619916", "price": "0.397", "size": "50704", "side": "BUY", "hash": "f59cf2fe05506dab10f593fcc8d0f342db2d3092", "best_bid": "0.428", "best_ask": "0.429"}, {"asset_id": "78633590736077251574794513664747155551297291244492840448622550955320930591622", "price": "0.603", "size": "50704", "side": "SELL", "hash": "fde91cb87b0d1ddc2abb6af267c3739997758afa", "best_bid": "0.571", "best_ask": "0.572"}], "timestamp": "1785163769656", "event_type": "price_change"}}
{"ts": 1785163769.661, "kind": "price_change", "data": {"market": "0x18b1c135d0a40c5894da9412e77311827d9caf16cf4cd6591b247a34730af919", "price_changes": [{"asset_id": "78633590736077251574794513664747155551297291244492840448622550955320930591622", "price": "0.532", "size": "74856.91", "side": "BUY", "hash": "d0b8e82cacf4afe9fff84908cebfe8eef957e422", "best_bid": "0.571", "best_ask": "0.572"}, {"asset_id": "40081275558852222228080198821361202017557872256707631666334039001378518619916", "price": "0.468", "size": "74856.91", "side": "SELL", "hash": "43aeb445d40b49f856ea4cbe1e3af6e5fcff7588", "best_bid": "0.428", "best_ask": "0.429"}], "timestamp": "1785163769661", "event_type": "price_change"}}
{"ts": 1785163769.664, "kind": "price_change", "data": {"market": "0x18b1c135d0a40c5894da9412e77311827d9caf16cf4cd6591b247a34730af919", "price_changes": [{"asset_id": "78633590736077251574794513664747155551297291244492840448622550955320930591622", "price": "0.56", "size": "5894.39", "side": "BUY", "hash": "d2b95a0f34a61f9239bb28e482ebcf2c2b40e9f4", "best_bid": "0.571", "best_ask": "0.572"}, {"asset_id": "40081275558852222228080198821361202017557872256707631666334039001378518619916", "price": "0.44", "size": "5894.39", "side": "SELL", "hash": "e7d7548ae84a36603628be09bd3f6cf9e3d42cd0", "best_bid": "0.428", "best_ask": "0.429"}], "timestamp": "1785163769664", "event_type": "price_change"}}
{"ts": 1785163771.087, "kind": "price_change", "data": {"market": "0x18b1c135d0a40c5894da9412e77311827d9caf16cf4cd6591b247a34730af919", "price_changes": [{"asset_id": "40081275558852222228080198821361202017557872256707631666334039001378518619916", "price": "0.05", "size": "0", "side": "BUY", "hash": "5b2556be5ef91f248ed10f236ca0d6b0f6aa3647", "best_bid": "0.428", "best_ask": "0.429"}, {"asset_id": "78633590736077251574794513664747155551297291244492840448622550955320930591622", "price": "0.95", "size": "0", "side": "SELL", "hash": "c39a52b3bbed01e62fbfa955698358f0c219617b", "best_bid": "0.571", "best_ask": "0.572"}], "timestamp": "1785163771087", "event_type": "price_change"}}
{"ts": 1785163771.415, "kind": "price_change", "data": {"market": "0x0f49db97f71c68b1e42a6d16e3de93d85dbf7d4148e3f018eb79e88554be9f75", "price_changes": [{"asset_id": "54533043819946592547517511176940999955633860128497669742211153063842200957669", "price": "0.158", "size": "61915", "side": "BUY", "hash": "566b4c7303391fa449cb817b37f4c16b198bd8c2", "best_bid": "0.194", "best_ask": "0.195"}, {"asset_id": "87854174148074652060467921081181402357467303721471806610111179101805869578687", "price": "0.842", "size": "61915", "side": "SELL", "hash": "d600fec351d65bc071c40c09075222c4113e3ef7", "best_bid": "0.805", "best_ask": "0.806"}], "timestamp": "1785163771415", "event_type": "price_change"}}
{"ts": 1785163773.001, "kind": "price_change", "data": {"market": "0x18b1c135d0a40c5894da9412e77311827d9caf16cf4cd6591b247a34730af919", "price_changes": [{"asset_id": "78633590736077251574794513664747155551297291244492840448622550955320930591622", "price": "0.004", "size": "5000", "side": "BUY", "hash": "cf2602364216c4ae6eab6637f0785f22c03018a4", "best_bid": "0.571", "best_ask": "0.572"}, {"asset_id": "40081275558852222228080198821361202017557872256707631666334039001378518619916", "price": "0.996", "size": "5000", "side": "SELL", "hash": "3338a76dc3d89d342b4f46e6fc6639913cb9369a", "best_bid": "0.428", "best_ask": "0.429"}], "timestamp": "1785163773001", "event_type": "price_change"}}
{"ts": 1785163773.41, "kind": "price_change", "data": {"market": "0x0f49db97f71c68b1e42a6d16e3de93d85dbf7d4148e3f018eb79e88554be9f75", "price_changes": [{"asset_id": "54533043819946592547517511176940999955633860128497669742211153063842200957669", "price": "0.007", "size": "0", "side": "BUY", "hash": "d779a81c3482b63db08ae25ac363aa22b4efb28f", "best_bid": "0.194", "best_ask": "0.195"}, {"asset_id": "87854174148074652060467921081181402357467303721471806610111179101805869578687", "price": "0.993", "size": "0", "side": "SELL", "hash": "f2eb81104c1e2e76f9e7603c56b32fe10f3b97b1", "best_bid": "0.805", "best_ask": "0.806"}], "timestamp": "1785163773410", "event_type": "price_change"}}
{"ts": 1785163773.41, "kind": "price_change", "data": {"market": "0x0f49db97f71c68b1e42a6d16e3de93d85dbf7d4148e3f018eb79e88554be9f75", "price_changes": [{"asset_id": "54533043819946592547517511176940999955633860128497669742211153063842200957669", "price": "0.009", "size": "0", "side": "BUY", "hash": "d779a81c3482b63db08ae25ac363aa22b4efb28f", "best_bid": "0.194", "best_ask": "0.195"}, {"asset_id": "87854174148074652060467921081181402357467303721471806610111179101805869578687", "price": "0.991", "size": "0", "side": "SELL", "hash": "f2eb81104c1e2e76f9e7603c56b32fe10f3b97b1", "best_bid": "0.805", "best_ask": "0.806"}], "timestamp": "1785163773410", "event_type": "price_change"}}
{"ts": 1785163773.671, "kind": "price_change", "data": {"market": "0x18b1c135d0a40c5894da9412e77311827d9caf16cf4cd6591b247a34730af919", "price_changes": [{"asset_id": "78633590736077251574794513664747155551297291244492840448622550955320930591622", "price": "0.02", "size": "75750", "side": "BUY", "hash": "af356410a54e8ce12ef74775a81bb6720754aa89", "best_bid": "0.571", "best_ask": "0.572"}, {"asset_id": "40081275558852222228080198821361202017557872256707631666334039001378518619916", "price": "0.98", "size": "75750", "side": "SELL", "hash": "a7c46cbe3a262268e2973a31405ac38c198e03d9", "best_bid": "0.428", "best_ask": "0.429"}], "timestamp": "1785163773671", "event_type": "price_change"}}
{"ts": 1785163774.012, "kind": "price_change", "data": {"market": "0x0f49db97f71c68b1e42a6d16e3de93d85dbf7d4148e3f018eb79e88554be9f75", "price_changes": [{"asset_id": "87854174148074652060467921081181402357467303721471806610111179101805869578687", "price": "0.803", "size": "12334.97", "side": "BUY", "hash": "4c5e6254ed5d08008c540f8bf3de301dd0e7dbf1", "best_bid": "0.805", "best_ask": "0.806"}, {"asset_id": "54533043819946592547517511176940999955633860128497669742211153063842200957669", "price": "0.197", "size": "12334.97", "side": "SELL", "hash": "fba15554d66a445d1b0d3b646f27b35b28a806dd", "best_bid": "0.194", "best_ask": "0.195"}], "timestamp": "1785163774012", "event_type": "price_change"}}
{"ts": 1785163774.024, "kind": "price_change", "data": {"market": "0x0f49db97f71c68b1e42a6d16e3de93d85dbf7d4148e3f018eb79e88554be9f75", "price_changes": [{"asset_id": "54533043819946592547517511176940999955633860128497669742211153063842200957669", "price": "0.193", "size": "10887", "side": "BUY", "hash": "0bdb054193d65abfae20f7367d97fc2aad753479", "best_bid": "0.194", "best_ask": "0.195"}, {"asset_id": "87854174148074652060467921081181402357467303721471806610111179101805869578687", "price": "0.807", "size": "10887", "side": "SELL", "hash": "7c77b117a710bbe14c8015aa17da6d490b212728", "best_bid": "0.805", "best_ask": "0.806"}], "timestamp": "1785163774024", "event_type": "price_change"}}
{"ts": 1785163774.336, "kind": "price_change", "data": {"market": "0x0f49db97f71c68b1e42a6d16e3de93d85dbf7d4148e3f018eb79e88554be9f75", "price_changes": [{"asset_id": "87854174148074652060467921081181402357467303721471806610111179101805869578687", "price": "0.803", "size": "12434.97", "side": "BUY", "hash": "c2efdaaacd38c140e3125c49bd420f1cf1e8e5c6", "best_bid": "0.805", "best_ask": "0.806"}, {"asset_id": "54533043819946592547517511176940999955633860128497669742211153063842200957669", "price": "0.197", "size": "12434.97", "side": "SELL", "hash": "f2bac2852074482dfdb2d8b58b60f6de283d8762", "best_bid": "0.194", "best_ask": "0.195"}], "timestamp": "1785163774336", "event_type": "price_change"}}
{"ts": 1785163774.588, "kind": "price_change", "data": {"market": "0x0f49db97f71c68b1e42a6d16e3de93d85dbf7d4148e3f018eb79e88554be9f75", "price_changes": [{"asset_id": "54533043819946592547517511176940999955633860128497669742211153063842200957669", "price": "0.193", "size": "10987", "side": "BUY", "hash": "24a1069d1eb5341ed4fbfa48123bd15046bf8cc8", "best_bid": "0.194", "best_ask": "0.195"}, {"asset_id": "87854174148074652060467921081181402357467303721471806610111179101805869578687", "price": "0.807", "size": "10987", "side": "SELL", "hash": "8d7fd57274a6eb9065689225c7ebb919f338602f", "best_bid": "0.805", "best_ask": "0.806"}], "timestamp": "1785163774588", "event_type": "price_change"}}
{"ts": 1785163774.984, "kind": "price_change", "data": {"market": "0x18b1c135d0a40c5894da9412e77311827d9caf16cf4cd6591b247a34730af919", "price_changes": [{"asset_id": "40081275558852222228080198821361202017557872256707631666334039001378518619916", "price": "0.41", "size": "2931.23", "side": "BUY", "hash": "d02b56faa3de0aae1303e5092c87aa9f35595eb3", "best_bid": "0.428", "best_ask": "0.429"}, {"asset_id": "78633590736077251574794513664747155551297291244492840448622550955320930591622", "price": "0.59", "size": "2931.23", "side": "SELL", "hash": "4b675e2fedb40b9712f0dc0cd33ea564eada35a5", "best_bid": "0.571", "best_ask": "0.572"}], "timestamp": "1785163774984", "event_type": "price_change"}}
{"ts": 1785163775.695, "kind": "price_change", "data": {"market": "0x18b1c135d0a40c5894da9412e77311827d9caf16cf4cd6591b247a34730af919", "price_changes": [{"asset_id": "78633590736077251574794513664747155551297291244492840448622550955320930591622", "price": "0.08", "size": "27500", "side": "BUY", "hash": "e8a610b41d325acf4b4f8ae745002bc286e52119", "best_bid": "0.571", "best_ask": "0.572"}, {"asset_id": "40081275558852222228080198821361202017557872256707631666334039001378518619916", "price": "0.92", "size": "27500", "side": "SELL", "hash": "5fcf5606c3225e3380c5682a012d2694f6b9805d", "best_bid": "0.428", "best_ask": "0.429"}], "timestamp": "1785163775695", "event_type": "price_change"}}
{"ts": 1785163775.707, "kind": "price_change", "data": {"market": "0x18b1c135d0a40c5894da9412e77311827d9caf16cf4cd6591b247a34730af919", "price_changes": [{"asset_id": "40081275558852222228080198821361202017557872256707631666334039001378518619916", "price": "0.41", "size": "2947.28", "side": "BUY", "hash": "467c4dc0379eb7e9b86a2482b8446330b273b9be", "best_bid": "0.428", "best_ask": "0.429"}, {"asset_id": "78633590736077251574794513664747155551297291244492840448622550955320930591622", "price": "0.59", "size": "2947.28", "side": "SELL", "hash": "664591f928bca47b6f34bf925b78b8e71787418e", "best_bid": "0.571", "best_ask": "0.572"}], "timestamp": "1785163775707", "event_type": "price_change"}}
{"ts": 1785163777.382, "kind": "price_change", "data": {"market": "0x0f49db97f71c68b1e42a6d16e3de93d85dbf7d4148e3f018eb79e88554be9f75", "price_changes": [{"asset_id": "87854174148074652060467921081181402357467303721471806610111179101805869578687", "price": "0.001", "size": "6146756.01", "side": "BUY", "hash": "01af0cf2c6df06bce11c61b201a36c8064691387", "best_bid": "0.805", "best_ask": "0.806"}, {"asset_id": "54533043819946592547517511176940999955633860128497669742211153063842200957669", "price": "0.999", "size": "6146756.01", "side": "SELL", "hash": "3c145bb1abf3fe3c17cc41a5a9e6060ba8ee1d57", "best_bid": "0.194", "best_ask": "0.195"}], "timestamp": "1785163777382", "event_type": "price_change"}}
{"ts": 1785163777.384, "kind": "price_change", "data": {"market": "0x0f49db97f71c68b1e42a6d16e3de93d85dbf7d4148e3f018eb79e88554be9f75", "price_changes": [{"asset_id": "87854174148074652060467921081181402357467303721471806610111179101805869578687", "price": "0.001", "size": "6147766.01", "side": "BUY", "hash": "2d9ddd1054018f115ea3a05471c77f92328958e9", "best_bid": "0.805", "best_ask": "0.806"}, {"asset_id": "54533043819946592547517511176940999955633860128497669742211153063842200957669", "price": "0.999", "size": "6147766.01", "side": "SELL", "hash": "4aa65e7ef041ce21baf9efc977f6d06e5d62bb6a", "best_bid": "0.194", "best_ask": "0.195"}], "timestamp": "1785163777384", "event_type": "price_change"}}
{"ts": 1785163779.111, "kind": "price_change", "data": {"market": "0x18b1c135d0a40c5894da9412e77311827d9caf16cf4cd6591b247a34730af919", "price_changes": [{"asset_id": "40081275558852222228080198821361202017557872256707631666334039001378518619916", "price": "0.507", "size": "0", "side": "SELL", "hash": "5003e87b6923449eee1655a1f299bfd7674dfa12", "best_bid": "0.428", "best_ask": "0.429"}, {"asset_id": "78633590736077251574794513664747155551297291244492840448622550955320930591622", "price": "0.493", "size": "0", "side": "BUY", "hash": "6362bb4123f4fb591321c6c91e27903ac2b1c5ef", "best_bid": "0.571", "best_ask": "0.572"}], "timestamp": "1785163779111", "event_type": "price_change"}}
{"ts": 1785163779.424973, "kind": "orders_out", "data": [{"token_id": "40081275558852222228080198821361202017557872256707631666334039001378518619916", "side": "BUY", "price": 0.387, "size": 7.75}, {"token_id": "78633590736077251574794513664747155551297291244492840448622550955320930591622", "side": "BUY", "price": 0.529, "size": 5.67}]}
{"ts": 1785163780.032, "kind": "price_change", "data": {"market": "0x18b1c135d0a40c5894da9412e77311827d9caf16cf4cd6591b247a34730af919", "price_changes": [{"asset_id": "40081275558852222228080198821361202017557872256707631666334039001378518619916", "price": "0.506", "size": "36.7", "side": "SELL", "hash": "07bba571c9a47e692a8703c8e3325ee7ca73e754", "best_bid": "0.428", "best_ask": "0.429"}, {"asset_id": "78633590736077251574794513664747155551297291244492840448622550955320930591622", "price": "0.494", "size": "36.7", "side": "BUY", "hash": "9d5db8a7443078d5d2df7b50ea2510b2fc1608fe", "best_bid": "0.571", "best_ask": "0.572"}], "timestamp": "1785163780032", "event_type": "price_change"}}
{"ts": 1785163782.741, "kind": "price_change", "data": {"market": "0x18b1c135d0a40c5894da9412e77311827d9caf16cf4cd6591b247a34730af919", "price_changes": [{"asset_id": "78633590736077251574794513664747155551297291244492840448622550955320930591622", "price": "0.004", "size": "15016.91", "side": "BUY", "hash": "a1832973541c10bb8cb2a0ca910aa3c9eded6d2a", "best_bid": "0.571", "best_ask": "0.572"}, {"asset_id": "40081275558852222228080198821361202017557872256707631666334039001378518619916", "price": "0.996", "size": "15016.91", "side": "SELL", "hash": "372074cd2daaf09b048dcb8f40a0c45377c28ac5", "best_bid": "0.428", "best_ask": "0.429"}], "timestamp": "1785163782741", "event_type": "price_change"}}
{"ts": 1785163785.011, "kind": "price_change", "data": {"market": "0x18b1c135d0a40c5894da9412e77311827d9caf16cf4cd6591b247a34730af919", "price_changes": [{"asset_id": "78633590736077251574794513664747155551297291244492840448622550955320930591622", "price": "0.311", "size": "0", "side": "BUY", "hash": "747dcb71a13e1209bfc8bdb42e9f3e9755f7bfae", "best_bid": "0.571", "best_ask": "0.572"}, {"asset_id": "40081275558852222228080198821361202017557872256707631666334039001378518619916", "price": "0.689", "size": "0", "side": "SELL", "hash": "683757a1e11a368b4012fffdcea04361dd4a5745", "best_bid": "0.428", "best_ask": "0.429"}], "timestamp": "1785163785011", "event_type": "price_change"}}
{"ts": 1785163793.536, "kind": "price_change", "data": {"market": "0x18b1c135d0a40c5894da9412e77311827d9caf16cf4cd6591b247a34730af919", "price_changes": [{"asset_id": "78633590736077251574794513664747155551297291244492840448622550955320930591622", "price": "0.372", "size": "48.28", "side": "BUY", "hash": "4e4e68525612cdd1f43158752a3b75fccc1faadc", "best_bid": "0.571", "best_ask": "0.572"}, {"asset_id": "40081275558852222228080198821361202017557872256707631666334039001378518619916", "price": "0.628", "size": "48.28", "side": "SELL", "hash": "429764ee12a7533a55fbaa90ec26677b4b4775fd", "best_bid": "0.428", "best_ask": "0.429"}], "timestamp": "1785163793536", "event_type": "price_change"}}
{"ts": 1785163794.023, "kind": "price_change", "data": {"market": "0x18b1c135d0a40c5894da9412e77311827d9caf16cf4cd6591b247a34730af919", "price_changes": [{"asset_id": "40081275558852222228080198821361202017557872256707631666334039001378518619916", "price": "0.41", "size": "2931.23", "side": "BUY", "hash": "d8fd3b019796f2bfbf67f2af42a25f86a30e7a23", "best_bid": "0.428", "best_ask": "0.429"}, {"asset_id": "78633590736077251574794513664747155551297291244492840448622550955320930591622", "price": "0.59", "size": "2931.23", "side": "SELL", "hash": "17293fe260b3bc8abead06b803989118238398a3", "best_bid": "0.571", "best_ask": "0.572"}], "timestamp": "1785163794023", "event_type": "price_change"}}
{"ts": 1785163794.134, "kind": "price_change", "data": {"market": "0x18b1c135d0a40c5894da9412e77311827d9caf16cf4cd6591b247a34730af919", "price_changes": [{"asset_id": "40081275558852222228080198821361202017557872256707631666334039001378518619916", "price": "0.506", "size": "0", "side": "SELL", "hash": "05d4ceb6912d670f92f20bad56751e4f2a61211c", "best_bid": "0.428", "best_ask": "0.429"}, {"asset_id": "78633590736077251574794513664747155551297291244492840448622550955320930591622", "price": "0.494", "size": "0", "side": "BUY", "hash": "7859681a6dbfa30062207a7968836ebc0b99859d", "best_bid": "0.571", "best_ask": "0.572"}], "timestamp": "1785163794134", "event_type": "price_change"}}
{"ts": 1785163794.557, "kind": "price_change", "data": {"market": "0x18b1c135d0a40c5894da9412e77311827d9caf16cf4cd6591b247a34730af919", "price_changes": [{"asset_id": "40081275558852222228080198821361202017557872256707631666334039001378518619916", "price": "0.41", "size": "2947.28", "side": "BUY", "hash": "7d19118dd88f2104b2683815f4e4a9e229a963fc", "best_bid": "0.428", "best_ask": "0.429"}, {"asset_id": "78633590736077251574794513664747155551297291244492840448622550955320930591622", "price": "0.59", "size": "2947.28", "side": "SELL", "hash": "0718793d516323632a9f7d09ca20c948915d6bc0", "best_bid": "0.571", "best_ask": "0.572"}], "timestamp": "1785163794557", "event_type": "price_change"}}
{"ts": 1785163796.324, "kind": "price_change", "data": {"market": "0x18b1c135d0a40c5894da9412e77311827d9caf16cf4cd6591b247a34730af919", "price_changes": [{"asset_id": "78633590736077251574794513664747155551297291244492840448622550955320930591622", "price": "0.561", "size": "11777", "side": "BUY", "hash": "6e03b269f1f235d1f20c9b5a28f6dd328f493087", "best_bid": "0.571", "best_ask": "0.572"}, {"asset_id": "40081275558852222228080198821361202017557872256707631666334039001378518619916", "price": "0.439", "size": "11777", "side": "SELL", "hash": "f69a7f0cd6f06e665e027b768b5b1b8dbace4377", "best_bid": "0.428", "best_ask": "0.429"}], "timestamp": "1785163796324", "event_type": "price_change"}}
{"ts": 1785163798.742, "kind": "price_change", "data": {"market": "0x18b1c135d0a40c5894da9412e77311827d9caf16cf4cd6591b247a34730af919", "price_changes": [{"asset_id": "78633590736077251574794513664747155551297291244492840448622550955320930591622", "price": "0.482", "size": "161.09", "side": "BUY", "hash": "0579ea0ed3b0a6ab5b972ac09eeaa432959b0bdb", "best_bid": "0.571", "best_ask": "0.572"}, {"asset_id": "40081275558852222228080198821361202017557872256707631666334039001378518619916", "price": "0.518", "size": "161.09", "side": "SELL", "hash": "14c65a56fd2ed03f1c77322f776217b21ba4c79c", "best_bid": "0.428", "best_ask": "0.429"}], "timestamp": "1785163798742", "event_type": "price_change"}}
{"ts": 1785163798.763, "kind": "price_change", "data": {"market": "0x18b1c135d0a40c5894da9412e77311827d9caf16cf4cd6591b247a34730af919", "price_changes": [{"asset_id": "78633590736077251574794513664747155551297291244492840448622550955320930591622", "price": "0.485", "size": "0", "side": "BUY", "hash": "f542c500a5308dd48fb09637e09aa9de4d51cc55", "best_bid": "0.571", "best_ask": "0.572"}, {"asset_id": "40081275558852222228080198821361202017557872256707631666334039001378518619916", "price": "0.515", "size": "0", "side": "SELL", "hash": "d675ef2638ef7a03fd2c882bd313f820614c3f9f", "best_bid": "0.428", "best_ask": "0.429"}], "timestamp": "1785163798763", "event_type": "price_change"}}
{"ts": 1785163798.763, "kind": "price_change", "data": {"market": "0x18b1c135d0a40c5894da9412e77311827d9caf16cf4cd6591b247a34730af919", "price_changes": [{"asset_id": "78633590736077251574794513664747155551297291244492840448622550955320930591622", "price": "0.482", "size": "0", "side": "BUY", "hash": "f542c500a5308dd48fb09637e09aa9de4d51cc55", "best_bid": "0.571", "best_ask": "0.572"}, {"asset_id": "40081275558852222228080198821361202017557872256707631666334039001378518619916", "price": "0.518", "size": "0", "side": "SELL", "hash": "d675ef2638ef7a03fd2c882bd313f820614c3f9f", "best_bid": "0.428", "best_ask": "0.429"}], "timestamp": "1785163798763", "event_type": "price_change"}}
{"ts": 1785163798.777, "kind": "price_change", "data": {"market": "0x18b1c135d0a40c5894da9412e77311827d9caf16cf4cd6591b247a34730af919", "price_changes": [{"asset_id": "78633590736077251574794513664747155551297291244492840448622550955320930591622", "price": "0.485", "size": "30", "side": "BUY", "hash": "5963dd118786e2835024224b4b3e16c3ae355735", "best_bid": "0.571", "best_ask": "0.572"}, {"asset_id": "40081275558852222228080198821361202017557872256707631666334039001378518619916", "price": "0.515", "size": "30", "side": "SELL", "hash": "1aad02d239360d67b59960ae49c944908c255eb2", "best_bid": "0.428", "best_ask": "0.429"}], "timestamp": "1785163798777", "event_type": "price_change"}}
{"ts": 1785163798.779, "kind": "price_change", "data": {"market": "0x18b1c135d0a40c5894da9412e77311827d9caf16cf4cd6591b247a34730af919", "price_changes": [{"asset_id": "78633590736077251574794513664747155551297291244492840448622550955320930591622", "price": "0.486", "size": "10", "side": "BUY", "hash": "a5505e67c1a6361180fbb554f90d8e74c7d6c3c3", "best_bid": "0.571", "best_ask": "0.572"}, {"asset_id": "40081275558852222228080198821361202017557872256707631666334039001378518619916", "price": "0.514", "size": "10", "side": "SELL", "hash": "61df0c15832ec43ad027d637aa19593c2eaef9f0", "best_bid": "0.428", "best_ask": "0.429"}], "timestamp": "1785163798779", "event_type": "price_change"}}
{"ts": 1785163798.814, "kind": "price_change", "data": {"market": "0x18b1c135d0a40c5894da9412e77311827d9caf16cf4cd6591b247a34730af919", "price_changes": [{"asset_id": "78633590736077251574794513664747155551297291244492840448622550955320930591622", "price": "0.486", "size": "0", "side": "BUY", "hash": "855e033d88d5c10743af893f68fff5b733a29349", "best_bid": "0.571", "best_ask": "0.572"}, {"asset_id": "40081275558852222228080198821361202017557872256707631666334039001378518619916", "price": "0.514", "size": "0", "side": "SELL", "hash": "1b10f37e191c86d1b7acdc61024ebaad2fa8aaf9", "best_bid": "0.428", "best_ask": "0.429"}], "timestamp": "1785163798814", "event_type": "price_change"}}
{"ts": 1785163798.814, "kind": "price_change", "data": {"market": "0x18b1c135d0a40c5894da9412e77311827d9caf16cf4cd6591b247a34730af919", "price_changes": [{"asset_id": "78633590736077251574794513664747155551297291244492840448622550955320930591622", "price": "0.485", "size": "0", "side": "BUY", "hash": "855e033d88d5c10743af893f68fff5b733a29349", "best_bid": "0.571", "best_ask": "0.572"}, {"asset_id": "40081275558852222228080198821361202017557872256707631666334039001378518619916", "price": "0.515", "size": "0", "side": "SELL", "hash": "1b10f37e191c86d1b7acdc61024ebaad2fa8aaf9", "best_bid": "0.428", "best_ask": "0.429"}], "timestamp": "1785163798814", "event_type": "price_change"}}
{"ts": 1785163798.835, "kind": "price_change", "data": {"market": "0x18b1c135d0a40c5894da9412e77311827d9caf16cf4cd6591b247a34730af919", "price_changes": [{"asset_id": "78633590736077251574794513664747155551297291244492840448622550955320930591622", "price": "0.482", "size": "30", "side": "BUY", "hash": "d044b1f5aa05955495e74804975b9d9df4887858", "best_bid": "0.571", "best_ask": "0.572"}, {"asset_id": "40081275558852222228080198821361202017557872256707631666334039001378518619916", "price": "0.518", "size": "30", "side": "SELL", "hash": "1dd790f5dc2a27d2754dfe13a4c1765dde1429cf", "best_bid": "0.428", "best_ask": "0.429"}], "timestamp": "1785163798835", "event_type": "price_change"}}
{"ts": 1785163798.836, "kind": "price_change", "data": {"market": "0x18b1c135d0a40c5894da9412e77311827d9caf16cf4cd6591b247a34730af919", "price_changes": [{"asset_id": "78633590736077251574794513664747155551297291244492840448622550955320930591622", "price": "0.482", "size": "40", "side": "BUY", "hash": "24be3655e6c35cfd5c266d62263e6b73eebeccfe", "best_bid": "0.571", "best_ask": "0.572"}, {"asset_id": "40081275558852222228080198821361202017557872256707631666334039001378518619916", "price": "0.518", "size": "40", "side": "SELL", "hash": "4a7823def10c2f2183f77ddc7ff35db8ba160160", "best_bid": "0.428", "best_ask": "0.429"}], "timestamp": "1785163798836", "event_type": "price_change"}}
{"ts": 1785163803.157, "kind": "price_change", "data": {"market": "0x0f49db97f71c68b1e42a6d16e3de93d85dbf7d4148e3f018eb79e88554be9f75", "price_changes": [{"asset_id": "54533043819946592547517511176940999955633860128497669742211153063842200957669", "price": "0.174", "size": "10919", "side": "BUY", "hash": "aaa18464f1d6bc77fb69298c75a58152187ec63b", "best_bid": "0.194", "best_ask": "0.195"}, {"asset_id": "87854174148074652060467921081181402357467303721471806610111179101805869578687", "price": "0.826", "size": "10919", "side": "SELL", "hash": "da89043c5249bfa27b62d828fb94e8f62d63bedf", "best_bid": "0.805", "best_ask": "0.806"}], "timestamp": "1785163803157", "event_type": "price_change"}}
{"ts": 1785163803.469239, "kind": "orders_out", "data": [{"token_id": "54533043819946592547517511176940999955633860128497669742211153063842200957669", "side": "BUY", "price": 0.153, "size": 19.61}]}
{"ts": 1785163804.189, "kind": "price_change", "data": {"market": "0x18b1c135d0a40c5894da9412e77311827d9caf16cf4cd6591b247a34730af919", "price_changes": [{"asset_id": "40081275558852222228080198821361202017557872256707631666334039001378518619916", "price": "0.418", "size": "6918.25", "side": "BUY", "hash": "759662d1e9ec9105c64cffab66cfa76ee857532c", "best_bid": "0.428", "best_ask": "0.429"}, {"asset_id": "78633590736077251574794513664747155551297291244492840448622550955320930591622", "price": "0.582", "size": "6918.25", "side": "SELL", "hash": "198d2ea1bf8676d53355b6b67629df549dbfc558", "best_bid": "0.571", "best_ask": "0.572"}], "timestamp": "1785163804189", "event_type": "price_change"}}
{"ts": 1785163804.735944, "kind": "orders_out", "data": [{"token_id": "40081275558852222228080198821361202017557872256707631666334039001378518619916", "side": "BUY", "price": 0.387, "size": 7.75}, {"token_id": "78633590736077251574794513664747155551297291244492840448622550955320930591622", "side": "BUY", "price": 0.529, "size": 5.67}]}
{"ts": 1785163808.796, "kind": "price_change", "data": {"market": "0x18b1c135d0a40c5894da9412e77311827d9caf16cf4cd6591b247a34730af919", "price_changes": [{"asset_id": "78633590736077251574794513664747155551297291244492840448622550955320930591622", "price": "0.485", "size": "77", "side": "BUY", "hash": "e18715cc4e963031c2c180a7281f9e80bc0280c6", "best_bid": "0.571", "best_ask": "0.572"}, {"asset_id": "40081275558852222228080198821361202017557872256707631666334039001378518619916", "price": "0.515", "size": "77", "side": "SELL", "hash": "314cc9c40cb7a595a680ad2d34404f3942925709", "best_bid": "0.428", "best_ask": "0.429"}], "timestamp": "1785163808796", "event_type": "price_change"}}
{"ts": 1785163808.797, "kind": "price_change", "data": {"market": "0x18b1c135d0a40c5894da9412e77311827d9caf16cf4cd6591b247a34730af919", "price_changes": [{"asset_id": "78633590736077251574794513664747155551297291244492840448622550955320930591622", "price": "0.482", "size": "201.09", "side": "BUY", "hash": "358d95bcec9dbfec2dd048cbc9ad68b2129dfcde", "best_bid": "0.571", "best_ask": "0.572"}, {"asset_id": "40081275558852222228080198821361202017557872256707631666334039001378518619916", "price": "0.518", "size": "201.09", "side": "SELL", "hash": "e07f80911769493086bf1ccf05edc1e7d60e1dc8", "best_bid": "0.428", "best_ask": "0.429"}], "timestamp": "1785163808797", "event_type": "price_change"}}
{"ts": 1785163809.949, "kind": "price_change", "data": {"market": "0x18b1c135d0a40c5894da9412e77311827d9caf16cf4cd6591b247a34730af919", "price_changes": [{"asset_id": "40081275558852222228080198821361202017557872256707631666334039001378518619916", "price": "0.397", "size": "50202", "side": "BUY", "hash": "817a7f63bc2475f29d65980904ec5d0efbafec07", "best_bid": "0.428", "best_ask": "0.429"}, {"asset_id": "78633590736077251574794513664747155551297291244492840448622550955320930591622", "price": "0.603", "size": "50202", "side": "SELL", "hash": "7ba48d2e26ddbf737dbbd55603f6dcfa53739e1e", "best_bid": "0.571", "best_ask": "0.572"}], "timestamp": "1785163809949", "event_type": "price_change"}}
{"ts": 1785163811.021, "kind": "price_change", "data": {"market": "0x18b1c135d0a40c5894da9412e77311827d9caf16cf4cd6591b247a34730af919", "price_changes": [{"asset_id": "40081275558852222228080198821361202017557872256707631666334039001378518619916", "price": "0.41", "size": "2931.23", "side": "BUY", "hash": "1033eac16a04376a9b522945ced3aa1f2b436706", "best_bid": "0.428", "best_ask": "0.429"}, {"asset_id": "78633590736077251574794513664747155551297291244492840448622550955320930591622", "price": "0.59", "size": "2931.23", "side": "SELL", "hash": "ec6382763b1a56fde924290b2ce203c5bddf3394", "best_bid": "0.571", "best_ask": "0.572"}], "timestamp": "1785163811021", "event_type": "price_change"}}
{"ts": 1785163811.593, "kind": "price_change", "data": {"market": "0x18b1c135d0a40c5894da9412e77311827d9caf16cf4cd6591b247a34730af919", "price_changes": [{"asset_id": "40081275558852222228080198821361202017557872256707631666334039001378518619916", "price": "0.507", "size": "36.7", "side": "SELL", "hash": "63f1dca32fa996af0b0eea9914e948cc0c3a9c88", "best_bid": "0.428", "best_ask": "0.429"}, {"asset_id": "78633590736077251574794513664747155551297291244492840448622550955320930591622", "price": "0.493", "size": "36.7", "side": "BUY", "hash": "44cdfd0f831beb42aae1e42bb4acd1ebcbfdbc45", "best_bid": "0.571", "best_ask": "0.572"}], "timestamp": "1785163811593", "event_type": "price_change"}}
{"ts": 1785163811.615, "kind": "price_change", "data": {"market": "0x18b1c135d0a40c5894da9412e77311827d9caf16cf4cd6591b247a34730af919", "price_changes": [{"asset_id": "40081275558852222228080198821361202017557872256707631666334039001378518619916", "price": "0.41", "size": "2947.28", "side": "BUY", "hash": "7f173b10e4cfde8a9560115d59e9c45bfc00f3d7", "best_bid": "0.428", "best_ask": "0.429"}, {"asset_id": "78633590736077251574794513664747155551297291244492840448622550955320930591622", "price": "0.59", "size": "2947.28", "side": "SELL", "hash": "f5fc0816ff3503945e477fd02b474e8086102c9b", "best_bid": "0.571", "best_ask": "0.572"}], "timestamp": "1785163811615", "event_type": "price_change"}}
{"ts": 1785163813.872, "kind": "price_change", "data": {"market": "0x0f49db97f71c68b1e42a6d16e3de93d85dbf7d4148e3f018eb79e88554be9f75", "price_changes": [{"asset_id": "54533043819946592547517511176940999955633860128497669742211153063842200957669", "price": "0.007", "size": "53571.42", "side": "BUY", "hash": "09bab92c7bc34878a4ca421e52d07bb12f99ca7a", "best_bid": "0.194", "best_ask": "0.195"}, {"asset_id": "87854174148074652060467921081181402357467303721471806610111179101805869578687", "price": "0.993", "size": "53571.42", "side": "SELL", "hash": "8f694881f278a9fae2052ffcac1097be9222c359", "best_bid": "0.805", "best_ask": "0.806"}], "timestamp": "1785163813872", "event_type": "price_change"}}
{"ts": 1785163813.875, "kind": "price_change", "data": {"market": "0x0f49db97f71c68b1e42a6d16e3de93d85dbf7d4148e3f018eb79e88554be9f75", "price_changes": [{"asset_id": "54533043819946592547517511176940999955633860128497669742211153063842200957669", "price": "0.009", "size": "13888.88", "side": "BUY", "hash": "dc7230735a62218f0eb171022568d86562d3b3a7", "best_bid": "0.194", "best_ask": "0.195"}, {"asset_id": "87854174148074652060467921081181402357467303721471806610111179101805869578687", "price": "0.991", "size": "13888.88", "side": "SELL", "hash": "81d1479793bc7ba66d7f464f0cc38a025082c883", "best_bid": "0.805", "best_ask": "0.806"}], "timestamp": "1785163813875", "event_type": "price_change"}}
{"ts": 1785163816.078, "kind": "price_change", "data": {"market": "0x18b1c135d0a40c5894da9412e77311827d9caf16cf4cd6591b247a34730af919", "price_changes": [{"asset_id": "78633590736077251574794513664747155551297291244492840448622550955320930591622", "price": "0.551", "size": "28623.96", "side": "BUY", "hash": "c129de4e8fee4f4d7f183bb110571923f454fe0f", "best_bid": "0.571", "best_ask": "0.572"}, {"asset_id": "40081275558852222228080198821361202017557872256707631666334039001378518619916", "price": "0.449", "size": "28623.96", "side": "SELL", "hash": "d832eb1702ad56c7d866b17aad68478b25e020fd", "best_bid": "0.428", "best_ask": "0.429"}], "timestamp": "1785163816078", "event_type": "price_change"}}
{"ts": 1785163817.772, "kind": "price_change", "data": {"market": "0x0f49db97f71c68b1e42a6d16e3de93d85dbf7d4148e3f018eb79e88554be9f75", "price_changes": [{"asset_id": "54533043819946592547517511176940999955633860128497669742211153063842200957669", "price": "0.174", "size": "11559", "side": "BUY", "hash": "afcf4758bd66a6a30bd4daf7b088c5d844fd152d", "best_bid": "0.194", "best_ask": "0.195"}, {"asset_id": "87854174148074652060467921081181402357467303721471806610111179101805869578687", "price": "0.826", "size": "11559", "side": "SELL", "hash": "282985bbdc276f3cb33a2af007c9f0d125ee53e3", "best_bid": "0.805", "best_ask": "0.806"}], "timestamp": "1785163817772", "event_type": "price_change"}}
{"ts": 1785163818.07, "kind": "price_change", "data": {"market": "0x0f49db97f71c68b1e42a6d16e3de93d85dbf7d4148e3f018eb79e88554be9f75", "price_changes": [{"asset_id": "87854174148074652060467921081181402357467303721471806610111179101805869578687", "price": "0.795", "size": "3127.98", "side": "BUY", "hash": "9d9c2c2cc5287aed804f2e4edf8569211d13ec0a", "best_bid": "0.805", "best_ask": "0.806"}, {"asset_id": "54533043819946592547517511176940999955633860128497669742211153063842200957669", "price": "0.205", "size": "3127.98", "side": "SELL", "hash": "5dc991c0be3956b1051c63a342c9cb6b81bf2e10", "best_bid": "0.194", "best_ask": "0.195"}], "timestamp": "1785163818070", "event_type": "price_change"}}
{"ts": 1785163818.14, "kind": "price_change", "data": {"market": "0x0f49db97f71c68b1e42a6d16e3de93d85dbf7d4148e3f018eb79e88554be9f75", "price_changes": [{"asset_id": "87854174148074652060467921081181402357467303721471806610111179101805869578687", "price": "0.795", "size": "3694.98", "side": "BUY", "hash": "2ab66435a294bc9b5a6da31606c6e0400585f2d6", "best_bid": "0.805", "best_ask": "0.806"}, {"asset_id": "54533043819946592547517511176940999955633860128497669742211153063842200957669", "price": "0.205", "size": "3694.98", "side": "SELL", "hash": "4872bcac03bd4743cd61838ce1debe76733d67f9", "best_bid": "0.194", "best_ask": "0.195"}], "timestamp": "1785163818140", "event_type": "price_change"}}
{"ts": 1785163818.395, "kind": "price_change", "data": {"market": "0x0f49db97f71c68b1e42a6d16e3de93d85dbf7d4148e3f018eb79e88554be9f75", "price_changes": [{"asset_id": "54533043819946592547517511176940999955633860128497669742211153063842200957669", "price": "0.007", "size": "0", "side": "BUY", "hash": "f002a672c02e810df22b766f11415038a97cb79b", "best_bid": "0.194", "best_ask": "0.195"}, {"asset_id": "87854174148074652060467921081181402357467303721471806610111179101805869578687", "price": "0.993", "size": "0", "side": "SELL", "hash": "26742d3552284be1d20b8f6ad045ad9bc73b46f2", "best_bid": "0.805", "best_ask": "0.806"}], "timestamp": "1785163818395", "event_type": "price_change"}}
{"ts": 1785163818.395, "kind": "price_change", "data": {"market": "0x0f49db97f71c68b1e42a6d16e3de93d85dbf7d4148e3f018eb79e88554be9f75", "price_changes": [{"asset_id": "54533043819946592547517511176940999955633860128497669742211153063842200957669", "price": "0.009", "size": "0", "side": "BUY", "hash": "f002a672c02e810df22b766f11415038a97cb79b", "best_bid": "0.194", "best_ask": "0.195"}, {"asset_id": "87854174148074652060467921081181402357467303721471806610111179101805869578687", "price": "0.991", "size": "0", "side": "SELL", "hash": "26742d3552284be1d20b8f6ad045ad9bc73b46f2", "best_bid": "0.805", "best_ask": "0.806"}], "timestamp": "1785163818395", "event_type": "price_change"}}
{"ts": 1785163818.629, "kind": "price_change", "data": {"market": "0x18b1c135d0a40c5894da9412e77311827d9caf16cf4cd6591b247a34730af919", "price_changes": [{"asset_id": "40081275558852222228080198821361202017557872256707631666334039001378518619916", "price": "0.418", "size": "5840.25", "side": "BUY", "hash": "505ed85765de68083be0fd2ef6a89f571f5087ab", "best_bid": "0.428", "best_ask": "0.429"}, {"asset_id": "78633590736077251574794513664747155551297291244492840448622550955320930591622", "price": "0.582", "size": "5840.25", "side": "SELL", "hash": "5791ffb3ae11254d5550e5cfe91064a81dd37508", "best_bid": "0.571", "best_ask": "0.572"}], "timestamp": "1785163818629", "event_type": "price_change"}}
{"ts": 1785163818.666, "kind": "price_change", "data": {"market": "0x18b1c135d0a40c5894da9412e77311827d9caf16cf4cd6591b247a34730af919", "price_changes": [{"asset_id": "40081275558852222228080198821361202017557872256707631666334039001378518619916", "price": "0.418", "size": "5640.25", "side": "BUY", "hash": "1d0d578092ec5afe66e6273aaee3a1a12af23cc4", "best_bid": "0.428", "best_ask": "0.429"}, {"asset_id": "78633590736077251574794513664747155551297291244492840448622550955320930591622", "price": "0.582", "size": "5640.25", "side": "SELL", "hash": "f5cc08b2763d7b3cbd6028f4739bde95340a6efb", "best_bid": "0.571", "best_ask": "0.572"}], "timestamp": "1785163818666", "event_type": "price_change"}}
{"ts": 1785163818.694, "kind": "price_change", "data": {"market": "0x18b1c135d0a40c5894da9412e77311827d9caf16cf4cd6591b247a34730af919", "price_changes": [{"asset_id": "40081275558852222228080198821361202017557872256707631666334039001378518619916", "price": "0.418", "size": "6718.25", "side": "BUY", "hash": "b0f37ac65387b870110247a753b382bc086aeead", "best_bid": "0.428", "best_ask": "0.429"}, {"asset_id": "78633590736077251574794513664747155551297291244492840448622550955320930591622", "price": "0.582", "size": "6718.25", "side": "SELL", "hash": "f4ae5186ea70d12a4557ae73cd24717194b13e96", "best_bid": "0.571", "best_ask": "0.572"}], "timestamp": "1785163818694", "event_type": "price_change"}}
{"ts": 1785163818.702, "kind": "price_change", "data": {"market": "0x18b1c135d0a40c5894da9412e77311827d9caf16cf4cd6591b247a34730af919", "price_changes": [{"asset_id": "40081275558852222228080198821361202017557872256707631666334039001378518619916", "price": "0.417", "size": "1200", "side": "BUY", "hash": "37437a2f264b56132f76d741ad45514edd6d1acf", "best_bid": "0.428", "best_ask": "0.429"}, {"asset_id": "78633590736077251574794513664747155551297291244492840448622550955320930591622", "price": "0.583", "size": "1200", "side": "SELL", "hash": "1264f289a4361bb8fa730c4f8e86d87944b0aae3", "best_bid": "0.571", "best_ask": "0.572"}], "timestamp": "1785163818702", "event_type": "price_change"}}
{"ts": 1785163818.735, "kind": "price_change", "data": {"market": "0x18b1c135d0a40c5894da9412e77311827d9caf16cf4cd6591b247a34730af919", "price_changes": [{"asset_id": "40081275558852222228080198821361202017557872256707631666334039001378518619916", "price": "0.398", "size": "14448", "side": "BUY", "hash": "b54aee7adb5a2f0f303172b8ada002c9b8c466a5", "best_bid": "0.428", "best_ask": "0.429"}, {"asset_id": "78633590736077251574794513664747155551297291244492840448622550955320930591622", "price": "0.602", "size": "14448", "side": "SELL", "hash": "8a90f3a1e36918c14a044565d01ca5eeefd4c7b9", "best_bid": "0.571", "best_ask": "0.572"}], "timestamp": "1785163818735", "event_type": "price_change"}}
{"ts": 1785163818.735, "kind": "price_change", "data": {"market": "0x18b1c135d0a40c5894da9412e77311827d9caf16cf4cd6591b247a34730af919", "price_changes": [{"asset_id": "78633590736077251574794513664747155551297291244492840448622550955320930591622", "price": "0.555", "size": "12242.19", "side": "BUY", "hash": "8a90f3a1e36918c14a044565d01ca5eeefd4c7b9", "best_bid": "0.571", "best_ask": "0.572"}, {"asset_id": "40081275558852222228080198821361202017557872256707631666334039001378518619916", "price": "0.445", "size": "12242.19", "side": "SELL", "hash": "b54aee7adb5a2f0f303172b8ada002c9b8c466a5", "best_bid": "0.428", "best_ask": "0.429"}], "timestamp": "1785163818735", "event_type": "price_change"}}
{"ts": 1785163818.735, "kind": "price_change", "data": {"market": "0x18b1c135d0a40c5894da9412e77311827d9caf16cf4cd6591b247a34730af919", "price_changes": [{"asset_id": "78633590736077251574794513664747155551297291244492840448622550955320930591622", "price": "0.55", "size": "30078.38", "side": "BUY", "hash": "8a90f3a1e36918c14a044565d01ca5eeefd4c7b9", "best_bid": "0.571", "best_ask": "0.572"}, {"asset_id": "40081275558852222228080198821361202017557872256707631666334039001378518619916", "price": "0.45", "size": "30078.38", "side": "SELL", "hash": "b54aee7adb5a2f0f303172b8ada002c9b8c466a5", "best_bid": "0.428", "best_ask": "0.429"}], "timestamp": "1785163818735", "event_type": "price_change"}}
{"ts": 1785163818.735, "kind": "price_change", "data": {"market": "0x18b1c135d0a40c5894da9412e77311827d9caf16cf4cd6591b247a34730af919", "price_changes": [{"asset_id": "40081275558852222228080198821361202017557872256707631666334039001378518619916", "price": "0.411", "size": "36542", "side": "BUY", "hash": "b54aee7adb5a2f0f303172b8ada002c9b8c466a5", "best_bid": "0.428", "best_ask": "0.429"}, {"asset_id": "78633590736077251574794513664747155551297291244492840448622550955320930591622", "price": "0.589", "size": "36542", "side": "SELL", "hash": "8a90f3a1e36918c14a044565d01ca5eeefd4c7b9", "best_bid": "0.571", "best_ask": "0.572"}], "timestamp": "1785163818735", "event_type": "price_change"}}
{"ts": 1785163818.735, "kind": "price_change", "data": {"market": "0x18b1c135d0a40c5894da9412e77311827d9caf16cf4cd6591b247a34730af919", "price_changes": [{"asset_id": "40081275558852222228080198821361202017557872256707631666334039001378518619916", "price": "0.412", "size": "11211.7", "side": "BUY", "hash": "b54aee7adb5a2f0f303172b8ada002c9b8c466a5", "best_bid": "0.428", "best_ask": "0.429"}, {"asset_id": "78633590736077251574794513664747155551297291244492840448622550955320930591622", "price": "0.588", "size": "11211.7", "side": "SELL", "hash": "8a90f3a1e36918c14a044565d01ca5eeefd4c7b9", "best_bid": "0.571", "best_ask": "0.572"}], "timestamp": "1785163818735", "event_type": "price_change"}}
{"ts": 1785163818.735, "kind": "price_change", "data": {"market": "0x18b1c135d0a40c5894da9412e77311827d9caf16cf4cd6591b247a34730af919", "price_changes": [{"asset_id": "78633590736077251574794513664747155551297291244492840448622550955320930591622", "price": "0.532", "size": "74115.71", "side": "BUY", "hash": "8a90f3a1e36918c14a044565d01ca5eeefd4c7b9", "best_bid": "0.571", "best_ask": "0.572"}, {"asset_id": "40081275558852222228080198821361202017557872256707631666334039001378518619916", "price": "0.468", "size": "74115.71", "side": "SELL", "hash": "b54aee7adb5a2f0f303172b8ada002c9b8c466a5", "best_bid": "0.428", "best_ask": "0.429"}], "timestamp": "1785163818735", "event_type": "price_change"}}
{"ts": 1785163818.735, "kind": "price_change", "data": {"market": "0x18b1c135d0a40c5894da9412e77311827d9caf16cf4cd6591b247a34730af919", "price_changes": [{"asset_id": "78633590736077251574794513664747155551297291244492840448622550955320930591622", "price": "0.56", "size": "5835.99", "side": "BUY", "hash": "8a90f3a1e36918c14a044565d01ca5eeefd4c7b9", "best_bid": "0.571", "best_ask": "0.572"}, {"asset_id": "40081275558852222228080198821361202017557872256707631666334039001378518619916", "price": "0.44", "size": "5835.99", "side": "SELL", "hash": "b54aee7adb5a2f0f303172b8ada002c9b8c466a5", "best_bid": "0.428", "best_ask": "0.429"}], "timestamp": "1785163818735", "event_type": "price_change"}}
{"ts": 1785163818.735, "kind": "price_change", "data": {"market": "0x18b1c135d0a40c5894da9412e77311827d9caf16cf4cd6591b247a34730af919", "price_changes": [{"asset_id": "40081275558852222228080198821361202017557872256707631666334039001378518619916", "price": "0.399", "size": "10117", "side": "BUY", "hash": "b54aee7adb5a2f0f303172b8ada002c9b8c466a5", "best_bid": "0.428", "best_ask": "0.429"}, {"asset_id": "78633590736077251574794513664747155551297291244492840448622550955320930591622", "price": "0.601", "size": "10117", "side": "SELL", "hash": "8a90f3a1e36918c14a044565d01ca5eeefd4c7b9", "best_bid": "0.571", "best_ask": "0.572"}], "timestamp": "1785163818735", "event_type": "price_change"}}
{"ts": 1785163818.766, "kind": "price_change", "data": {"market": "0x18b1c135d0a40c5894da9412e77311827d9caf16cf4cd6591b247a34730af919", "price_changes": [{"asset_id": "40081275558852222228080198821361202017557872256707631666334039001378518619916", "price": "0.417", "size": "1000", "side": "BUY", "hash": "eb19f7b59d066ba2f30921d431f04599e1dcf97e", "best_bid": "0.428", "best_ask": "0.429"}, {"asset_id": "78633590736077251574794513664747155551297291244492840448622550955320930591622", "price": "0.583", "size": "1000", "side": "SELL", "hash": "b1df8cff4dea1dc784039fcfd5febbffca82a4a1", "best_bid": "0.571", "best_ask": "0.572"}], "timestamp": "1785163818766", "event_type": "price_change"}}
{"ts": 1785163818.819, "kind": "price_change", "data": {"market": "0x18b1c135d0a40c5894da9412e77311827d9caf16cf4cd6591b247a34730af919", "price_changes": [{"asset_id": "40081275558852222228080198821361202017557872256707631666334039001378518619916", "price": "0.418", "size": "6918.25", "side": "BUY", "hash": "acfd9e6f5509e260d9d87427e6729200ec0b86c2", "best_bid": "0.428", "best_ask": "0.429"}, {"asset_id": "78633590736077251574794513664747155551297291244492840448622550955320930591622", "price": "0.582", "size": "6918.25", "side": "SELL", "hash": "8a38d58eb3f107760797860d1f82c9df61ac2ed5", "best_bid": "0.571", "best_ask": "0.572"}], "timestamp": "1785163818819", "event_type": "price_change"}}
{"ts": 1785163820.001, "kind": "price_change", "data": {"market": "0x18b1c135d0a40c5894da9412e77311827d9caf16cf4cd6591b247a34730af919", "price_changes": [{"asset_id": "78633590736077251574794513664747155551297291244492840448622550955320930591622", "price": "0.492", "size": "0", "side": "BUY", "hash": "d8fa03f05f6381f6bb1e02d6e6b97240f0d4cba6", "best_bid": "0.571", "best_ask": "0.572"}, {"asset_id": "40081275558852222228080198821361202017557872256707631666334039001378518619916", "price": "0.508", "size": "0", "side": "SELL", "hash": "9a77945711f263b2c6781c484632e82b5c8e2b94", "best_bid": "0.428", "best_ask": "0.429"}], "timestamp": "1785163820001", "event_type": "price_change"}}
{"ts": 1785163820.3563352, "kind": "orders_out", "data": [{"token_id": "40081275558852222228080198821361202017557872256707631666334039001378518619916", "side": "BUY", "price": 0.387, "size": 7.75}, {"token_id": "78633590736077251574794513664747155551297291244492840448622550955320930591622", "side": "BUY", "price": 0.529, "size": 5.67}]}
{"ts": 1785163820.264, "kind": "price_change", "data": {"market": "0x18b1c135d0a40c5894da9412e77311827d9caf16cf4cd6591b247a34730af919", "price_changes": [{"asset_id": "40081275558852222228080198821361202017557872256707631666334039001378518619916", "price": "0.507", "size": "0", "side": "SELL", "hash": "4888fc58dbf519d503770fe00011324ebdbab0f5", "best_bid": "0.428", "best_ask": "0.429"}, {"asset_id": "78633590736077251574794513664747155551297291244492840448622550955320930591622", "price": "0.493", "size": "0", "side": "BUY", "hash": "af5c02c86798de0ce1f82f51677ba7c6c8a74ba8", "best_bid": "0.571", "best_ask": "0.572"}], "timestamp": "1785163820264", "event_type": "price_change"}}
{"ts": 1785163820.459, "kind": "price_change", "data": {"market": "0x18b1c135d0a40c5894da9412e77311827d9caf16cf4cd6591b247a34730af919", "price_changes": [{"asset_id": "40081275558852222228080198821361202017557872256707631666334039001378518619916", "price": "0.509", "size": "36.7", "side": "SELL", "hash": "eafb3473331eadcfd469ed97de0cbd73c8375676", "best_bid": "0.428", "best_ask": "0.429"}, {"asset_id": "78633590736077251574794513664747155551297291244492840448622550955320930591622", "price": "0.491", "size": "36.7", "side": "BUY", "hash": "758e19986a9dd673fe323e60f49b170a0c5d00ee", "best_bid": "0.571", "best_ask": "0.572"}], "timestamp": "1785163820459", "event_type": "price_change"}}
{"ts": 1785163822.295, "kind": "price_change", "data": {"market": "0x18b1c135d0a40c5894da9412e77311827d9caf16cf4cd6591b247a34730af919", "price_changes": [{"asset_id": "40081275558852222228080198821361202017557872256707631666334039001378518619916", "price": "0.412", "size": "11323.8", "side": "BUY", "hash": "9e831811399229b39cf590580d402ab5975988d6", "best_bid": "0.428", "best_ask": "0.429"}, {"asset_id": "78633590736077251574794513664747155551297291244492840448622550955320930591622", "price": "0.588", "size": "11323.8", "side": "SELL", "hash": "41b46816bb29315112c216f201fa23c8a066aef0", "best_bid": "0.571", "best_ask": "0.572"}], "timestamp": "1785163822295", "event_type": "price_change"}}
{"ts": 1785163822.3, "kind": "price_change", "data": {"market": "0x18b1c135d0a40c5894da9412e77311827d9caf16cf4cd6591b247a34730af919", "price_changes": [{"asset_id": "40081275558852222228080198821361202017557872256707631666334039001378518619916", "price": "0.398", "size": "14592.5", "side": "BUY", "hash": "023a70a1e3d81f23cb3b092578c2029124370f8e", "best_bid": "0.428", "best_ask": "0.429"}, {"asset_id": "78633590736077251574794513664747155551297291244492840448622550955320930591622", "price": "0.602", "size": "14592.5", "side": "SELL", "hash": "63371861df806b43a3738455b5550cf58b93a7fa", "best_bid": "0.571", "best_ask": "0.572"}], "timestamp": "1785163822300", "event_type": "price_change"}}
{"ts": 1785163822.302, "kind": "price_change", "data": {"market": "0x18b1c135d0a40c5894da9412e77311827d9caf16cf4cd6591b247a34730af919", "price_changes": [{"asset_id": "40081275558852222228080198821361202017557872256707631666334039001378518619916", "price": "0.397", "size": "50704", "side": "BUY", "hash": "42e47c121ef956b3aaa1832e5fc30d69f08ea079", "best_bid": "0.428", "best_ask": "0.429"}, {"asset_id": "78633590736077251574794513664747155551297291244492840448622550955320930591622", "price": "0.603", "size": "50704", "side": "SELL", "hash": "984fe503a398655fd9d977ba67d6fbc364f1f6ce", "best_bid": "0.571", "best_ask": "0.572"}], "timestamp": "1785163822302", "event_type": "price_change"}}
{"ts": 1785163822.314, "kind": "price_change", "data": {"market": "0x18b1c135d0a40c5894da9412e77311827d9caf16cf4cd6591b247a34730af919", "price_changes": [{"asset_id": "40081275558852222228080198821361202017557872256707631666334039001378518619916", "price": "0.411", "size": "36907.4", "side": "BUY", "hash": "7485cb502f4a084c663a6bb708214841cdf9c23e", "best_bid": "0.428", "best_ask": "0.429"}, {"asset_id": "78633590736077251574794513664747155551297291244492840448622550955320930591622", "price": "0.589", "size": "36907.4", "side": "SELL", "hash": "ccba441fb596fc7ed024bf0937594eef38ee2a8d", "best_bid": "0.571", "best_ask": "0.572"}], "timestamp": "1785163822314", "event_type": "price_change"}}
{"ts": 1785163822.322, "kind": "price_change", "data": {"market": "0x18b1c135d0a40c5894da9412e77311827d9caf16cf4cd6591b247a34730af919", "price_changes": [{"asset_id": "78633590736077251574794513664747155551297291244492840448622550955320930591622", "price": "0.493", "size": "60", "side": "BUY", "hash": "67e11e4a8e2c788aeb7be0effb74fae9eea56c2c", "best_bid": "0.571", "best_ask": "0.572"}, {"asset_id": "40081275558852222228080198821361202017557872256707631666334039001378518619916", "price": "0.507", "size": "60", "side": "SELL", "hash": "4cde50253c5e4757f75392ce6fe459a1fd5ea339", "best_bid": "0.428", "best_ask": "0.429"}], "timestamp": "1785163822322", "event_type": "price_change"}}
{"ts": 1785163822.33, "kind": "price_change", "data": {"market": "0x18b1c135d0a40c5894da9412e77311827d9caf16cf4cd6591b247a34730af919", "price_changes": [{"asset_id": "78633590736077251574794513664747155551297291244492840448622550955320930591622", "price": "0.55", "size": "30379.18", "side": "BUY", "hash": "ab9c3098c148edf94c19bf23efc55de8ed3397ed", "best_bid": "0.571", "best_ask": "0.572"}, {"asset_id": "40081275558852222228080198821361202017557872256707631666334039001378518619916", "price": "0.45", "size": "30379.18", "side": "SELL", "hash": "4a0eaf53267328c70c1e3bab3bb9e19910e694bd", "best_bid": "0.428", "best_ask": "0.429"}], "timestamp": "1785163822330", "event_type": "price_change"}}
{"ts": 1785163822.338, "kind": "price_change", "data": {"market": "0x18b1c135d0a40c5894da9412e77311827d9caf16cf4cd6591b247a34730af919", "price_changes": [{"asset_id": "78633590736077251574794513664747155551297291244492840448622550955320930591622", "price": "0.532", "size": "74856.91", "side": "BUY", "hash": "a11d34fe5463db9a875c6fdae54746a710abb53e", "best_bid": "0.571", "best_ask": "0.572"}, {"asset_id": "40081275558852222228080198821361202017557872256707631666334039001378518619916", "price": "0.468", "size": "74856.91", "side": "SELL", "hash": "d68c8742fa31df2c449e0852acbbd9fda119e020", "best_bid": "0.428", "best_ask": "0.429"}], "timestamp": "1785163822338", "event_type": "price_change"}}
{"ts": 1785163822.35, "kind": "price_change", "data": {"market": "0x18b1c135d0a40c5894da9412e77311827d9caf16cf4cd6591b247a34730af919", "price_changes": [{"asset_id": "78633590736077251574794513664747155551297291244492840448622550955320930591622", "price": "0.551", "size": "28910.16", "side": "BUY", "hash": "02472b188b9b22f51e59adc6946772fbf2a6bd20", "best_bid": "0.571", "best_ask": "0.572"}, {"asset_id": "40081275558852222228080198821361202017557872256707631666334039001378518619916", "price": "0.449", "size": "28910.16", "side": "SELL", "hash": "563c167343877f63b7306a29a326ec202f43a0e5", "best_bid": "0.428", "best_ask": "0.429"}], "timestamp": "1785163822350", "event_type": "price_change"}}
{"ts": 1785163822.354, "kind": "price_change", "data": {"market": "0x18b1c135d0a40c5894da9412e77311827d9caf16cf4cd6591b247a34730af919", "price_changes": [{"asset_id": "40081275558852222228080198821361202017557872256707631666334039001378518619916", "price": "0.399", "size": "10218.2", "side": "BUY", "hash": "715a9b05d46b5d1f99bdb1acb0a1b21636015400", "best_bid": "0.428", "best_ask": "0.429"}, {"asset_id": "78633590736077251574794513664747155551297291244492840448622550955320930591622", "price": "0.601", "size": "10218.2", "side": "SELL", "hash": "5410b27537d921301e48a6c86d883fd7808fc94b", "best_bid": "0.571", "best_ask": "0.572"}], "timestamp": "1785163822354", "event_type": "price_change"}}
{"ts": 1785163822.357, "kind": "price_change", "data": {"market": "0x18b1c135d0a40c5894da9412e77311827d9caf16cf4cd6591b247a34730af919", "price_changes": [{"asset_id": "40081275558852222228080198821361202017557872256707631666334039001378518619916", "price": "0.418", "size": "6987.45", "side": "BUY", "hash": "f35cb471944c37e12ad24d615dc91351ab7c7c28", "best_bid": "0.428", "best_ask": "0.429"}, {"asset_id": "78633590736077251574794513664747155551297291244492840448622550955320930591622", "price": "0.582", "size": "6987.45", "side": "SELL", "hash": "63b4d615c2ee7ac7b0f671d069676a7f7609be71", "best_bid": "0.571", "best_ask": "0.572"}], "timestamp": "1785163822357", "event_type": "price_change"}}
{"ts": 1785163822.37, "kind": "price_change", "data": {"market": "0x18b1c135d0a40c5894da9412e77311827d9caf16cf4cd6591b247a34730af919", "price_changes": [{"asset_id": "78633590736077251574794513664747155551297291244492840448622550955320930591622", "price": "0.555", "size": "12364.59", "side": "BUY", "hash": "af5b55c9593e92f4bf18f63f45371893309ad689", "best_bid": "0.571", "best_ask": "0.572"}, {"asset_id": "40081275558852222228080198821361202017557872256707631666334039001378518619916", "price": "0.445", "size": "12364.59", "side": "SELL", "hash": "77907de4ced7e887ff8de8ce536604e63e2be02c", "best_bid": "0.428", "best_ask": "0.429"}], "timestamp": "1785163822370", "event_type": "price_change"}}
{"ts": 1785163822.371, "kind": "price_change", "data": {"market": "0x18b1c135d0a40c5894da9412e77311827d9caf16cf4cd6591b247a34730af919", "price_changes": [{"asset_id": "78633590736077251574794513664747155551297291244492840448622550955320930591622", "price": "0.561", "size": "11894.8", "side": "BUY", "hash": "48198398cdf2a943563e13f1c58c5fd00e8821f0", "best_bid": "0.571", "best_ask": "0.572"}, {"asset_id": "40081275558852222228080198821361202017557872256707631666334039001378518619916", "price": "0.439", "size": "11894.8", "side": "SELL", "hash": "4123d3a3e886c5c4bd1888f53dd63d1420c9fa85", "best_bid": "0.428", "best_ask": "0.429"}], "timestamp": "1785163822371", "event_type": "price_change"}}
{"ts": 1785163822.373, "kind": "price_change", "data": {"market": "0x18b1c135d0a40c5894da9412e77311827d9caf16cf4cd6591b247a34730af919", "price_changes": [{"asset_id": "78633590736077251574794513664747155551297291244492840448622550955320930591622", "price": "0.56", "size": "5894.39", "side": "BUY", "hash": "0a296f1a7b4c677317b6f23e0f6776546536bb89", "best_bid": "0.571", "best_ask": "0.572"}, {"asset_id": "40081275558852222228080198821361202017557872256707631666334039001378518619916", "price": "0.44", "size": "5894.39", "side": "SELL", "hash": "37c416f09f685920f9b265c5b0a0d007b217a64d", "best_bid": "0.428", "best_ask": "0.429"}], "timestamp": "1785163822373", "event_type": "price_change"}}
{"ts": 1785163826.556, "kind": "price_change", "data": {"market": "0x0f49db97f71c68b1e42a6d16e3de93d85dbf7d4148e3f018eb79e88554be9f75", "price_changes": [{"asset_id": "87854174148074652060467921081181402357467303721471806610111179101805869578687", "price": "0.795", "size": "3128.98", "side": "BUY", "hash": "21f50e3f0c333f7b2d49e51f66906d695f282b97", "best_bid": "0.805", "best_ask": "0.806"}, {"asset_id": "54533043819946592547517511176940999955633860128497669742211153063842200957669", "price": "0.205", "size": "3128.98", "side": "SELL", "hash": "83bda22a182a1660865df36f1c9f83aa0e58c8c0", "best_bid": "0.194", "best_ask": "0.195"}], "timestamp": "1785163826556", "event_type": "price_change"}}
{"ts": 1785163826.558, "kind": "price_change", "data": {"market": "0x18b1c135d0a40c5894da9412e77311827d9caf16cf4cd6591b247a34730af919", "price_changes": [{"asset_id": "40081275558852222228080198821361202017557872256707631666334039001378518619916", "price": "0.509", "size": "0", "side": "SELL", "hash": "46cf333c1632701a1dc55c539ae75d2ac411f8b2", "best_bid": "0.428", "best_ask": "0.429"}, {"asset_id": "78633590736077251574794513664747155551297291244492840448622550955320930591622", "price": "0.491", "size": "0", "side": "BUY", "hash": "0b76870676349ae52fcc9964bd22618146c12c0b", "best_bid": "0.571", "best_ask": "0.572"}], "timestamp": "1785163826558", "event_type": "price_change"}}
{"ts": 1785163826.635, "kind": "price_change", "data": {"market": "0x0f49db97f71c68b1e42a6d16e3de93d85dbf7d4148e3f018eb79e88554be9f75", "price_changes": [{"asset_id": "87854174148074652060467921081181402357467303721471806610111179101805869578687", "price": "0.795", "size": "3694.98", "side": "BUY", "hash": "e488d1a13e61e08fd8d370e630f5e13442d5553b", "best_bid": "0.805", "best_ask": "0.806"}, {"asset_id": "54533043819946592547517511176940999955633860128497669742211153063842200957669", "price": "0.205", "size": "3694.98", "side": "SELL", "hash": "f5539c04f0898515b60b5ea7103403a9964f8baa", "best_bid": "0.194", "best_ask": "0.195"}], "timestamp": "1785163826635", "event_type": "price_change"}}
{"ts": 1785163826.737, "kind": "price_change", "data": {"market": "0x18b1c135d0a40c5894da9412e77311827d9caf16cf4cd6591b247a34730af919", "price_changes": [{"asset_id": "40081275558852222228080198821361202017557872256707631666334039001378518619916", "price": "0.506", "size": "36.7", "side": "SELL", "hash": "40d357a62f7b97714e2e1cda4980500c7afe59b7", "best_bid": "0.428", "best_ask": "0.429"}, {"asset_id": "78633590736077251574794513664747155551297291244492840448622550955320930591622", "price": "0.494", "size": "36.7", "side": "BUY", "hash": "5037e820213bc987f447581b8466b9561de19b62", "best_bid": "0.571", "best_ask": "0.572"}], "timestamp": "1785163826737", "event_type": "price_change"}}
{"ts": 1785163826.867989, "kind": "orders_out", "data": [{"token_id": "54533043819946592547517511176940999955633860128497669742211153063842200957669", "side": "BUY", "price": 0.153, "size": 19.61}]}
{"ts": 1785163827.151, "kind": "price_change", "data": {"market": "0x18b1c135d0a40c5894da9412e77311827d9caf16cf4cd6591b247a34730af919", "price_changes": [{"asset_id": "40081275558852222228080198821361202017557872256707631666334039001378518619916", "price": "0.418", "size": "5911.45", "side": "BUY", "hash": "625cf1e75d00abd075c6212e56915ef43f8f6999", "best_bid": "0.428", "best_ask": "0.429"}, {"asset_id": "78633590736077251574794513664747155551297291244492840448622550955320930591622", "price": "0.582", "size": "5911.45", "side": "SELL", "hash": "efa3ee238a22aacdf8fbb0edd54e406d437c3913", "best_bid": "0.571", "best_ask": "0.572"}], "timestamp": "1785163827151", "event_type": "price_change"}}
{"ts": 1785163827.184, "kind": "price_change", "data": {"market": "0x18b1c135d0a40c5894da9412e77311827d9caf16cf4cd6591b247a34730af919", "price_changes": [{"asset_id": "40081275558852222228080198821361202017557872256707631666334039001378518619916", "price": "0.418", "size": "5711.45", "side": "BUY", "hash": "50323a997e0f26f921fb320ba61cc445e081491e", "best_bid": "0.428", "best_ask": "0.429"}, {"asset_id": "78633590736077251574794513664747155551297291244492840448622550955320930591622", "price": "0.582", "size": "5711.45", "side": "SELL", "hash": "ab1929658d48bbb4061de2a6cd731af91bd32d76", "best_bid": "0.571", "best_ask": "0.572"}], "timestamp": "1785163827184", "event_type": "price_change"}}
{"ts": 1785163827.22, "kind": "price_change", "data": {"market": "0x18b1c135d0a40c5894da9412e77311827d9caf16cf4cd6591b247a34730af919", "price_changes": [{"asset_id": "40081275558852222228080198821361202017557872256707631666334039001378518619916", "price": "0.417", "size": "1200", "side": "BUY", "hash": "35fd5d8f777dc6d1659bc4e030b4b5b7e2dc21c9", "best_bid": "0.428", "best_ask": "0.429"}, {"asset_id": "78633590736077251574794513664747155551297291244492840448622550955320930591622", "price": "0.583", "size": "1200", "side": "SELL", "hash": "f57375213c66b0b20197b9463a15026e19bb6a68", "best_bid": "0.571", "best_ask": "0.572"}], "timestamp": "1785163827220", "event_type": "price_change"}}
{"ts": 1785163827.239, "kind": "price_change", "data": {"market": "0x18b1c135d0a40c5894da9412e77311827d9caf16cf4cd6591b247a34730af919", "price_changes": [{"asset_id": "40081275558852222228080198821361202017557872256707631666334039001378518619916", "price": "0.418", "size": "6787.45", "side": "BUY", "hash": "ff3574633a1057dc08715e297418821ba07fee29", "best_bid": "0.428", "best_ask": "0.429"}, {"asset_id": "78633590736077251574794513664747155551297291244492840448622550955320930591622", "price": "0.582", "size": "6787.45", "side": "SELL", "hash": "914957154a121e1103b0a3f0ea57979ecbd8f19d", "best_bid": "0.571", "best_ask": "0.572"}], "timestamp": "1785163827239", "event_type": "price_change"}}
{"ts": 1785163827.28, "kind": "price_change", "data": {"market": "0x18b1c135d0a40c5894da9412e77311827d9caf16cf4cd6591b247a34730af919", "price_changes": [{"asset_id": "40081275558852222228080198821361202017557872256707631666334039001378518619916", "price": "0.417", "size": "1000", "side": "BUY", "hash": "c304d3d66b26a2e82204da53cfd3ed85cdaddf6e", "best_bid": "0.428", "best_ask": "0.429"}, {"asset_id": "78633590736077251574794513664747155551297291244492840448622550955320930591622", "price": "0.583", "size": "1000", "side": "SELL", "hash": "13b891939f3f4e6112e254cd2c9cc8c3d62f4ec5", "best_bid": "0.571", "best_ask": "0.572"}], "timestamp": "1785163827280", "event_type": "price_change"}}
{"ts": 1785163827.313, "kind": "price_change", "data": {"market": "0x18b1c135d0a40c5894da9412e77311827d9caf16cf4cd6591b247a34730af919", "price_changes": [{"asset_id": "40081275558852222228080198821361202017557872256707631666334039001378518619916", "price": "0.418", "size": "6987.45", "side": "BUY", "hash": "1259ec89ddb3824db75fede7c8285e7aed1e11f2", "best_bid": "0.428", "best_ask": "0.429"}, {"asset_id": "78633590736077251574794513664747155551297291244492840448622550955320930591622", "price": "0.582", "size": "6987.45", "side": "SELL", "hash": "ef4a4821d5eab7374f03b10ecc7be84ed32650b5", "best_bid": "0.571", "best_ask": "0.572"}], "timestamp": "1785163827313", "event_type": "price_change"}}
{"ts": 1785163827.796, "kind": "price_change", "data": {"market": "0x18b1c135d0a40c5894da9412e77311827d9caf16cf4cd6591b247a34730af919", "price_changes": [{"asset_id": "40081275558852222228080198821361202017557872256707631666334039001378518619916", "price": "0.41", "size": "2931.23", "side": "BUY", "hash": "a70602d98d91993a1a5d708c341483c965619cf0", "best_bid": "0.428", "best_ask": "0.429"}, {"asset_id": "78633590736077251574794513664747155551297291244492840448622550955320930591622", "price": "0.59", "size": "2931.23", "side": "SELL", "hash": "f76baf86a0cfaf9574e292b1ff87e1874a4db713", "best_bid": "0.571", "best_ask": "0.572"}], "timestamp": "1785163827796", "event_type": "price_change"}}
{"ts": 1785163828.319, "kind": "price_change", "data": {"market": "0x18b1c135d0a40c5894da9412e77311827d9caf16cf4cd6591b247a34730af919", "price_changes": [{"asset_id": "40081275558852222228080198821361202017557872256707631666334039001378518619916", "price": "0.41", "size": "2947.28", "side": "BUY", "hash": "784db392eccab8876cd17230c2f46fe026077dc6", "best_bid": "0.428", "best_ask": "0.429"}, {"asset_id": "78633590736077251574794513664747155551297291244492840448622550955320930591622", "price": "0.59", "size": "2947.28", "side": "SELL", "hash": "f4c3c98d2d53b9fff4c4fad2209f7c29afc3f614", "best_bid": "0.571", "best_ask": "0.572"}], "timestamp": "1785163828319", "event_type": "price_change"}}
{"ts": 1785163834.256, "kind": "price_change", "data": {"market": "0x0f49db97f71c68b1e42a6d16e3de93d85dbf7d4148e3f018eb79e88554be9f75", "price_changes": [{"asset_id": "54533043819946592547517511176940999955633860128497669742211153063842200957669", "price": "0.193", "size": "11194", "side": "BUY", "hash": "b70dc15fa3c5d2de5d89e344e4d3c0d2faa3fb03", "best_bid": "0.194", "best_ask": "0.195"}, {"asset_id": "87854174148074652060467921081181402357467303721471806610111179101805869578687", "price": "0.807", "size": "11194", "side": "SELL", "hash": "3d3e05f4e46be90be4b5671a082b758779722542", "best_bid": "0.805", "best_ask": "0.806"}], "timestamp": "1785163834256", "event_type": "price_change"}}
{"ts": 1785163835.006, "kind": "price_change", "data": {"market": "0x18b1c135d0a40c5894da9412e77311827d9caf16cf4cd6591b247a34730af919", "price_changes": [{"asset_id": "40081275558852222228080198821361202017557872256707631666334039001378518619916", "price": "0.411", "size": "36707.4", "side": "BUY", "hash": "7586a4f1947824055036da754e04c9ca3e9ae8b3", "best_bid": "0.428", "best_ask": "0.429"}, {"asset_id": "78633590736077251574794513664747155551297291244492840448622550955320930591622", "price": "0.589", "size": "36707.4", "side": "SELL", "hash": "78eada89ef024ebe048b19cf75c2e8f72724897e", "best_bid": "0.571", "best_ask": "0.572"}], "timestamp": "1785163835006", "event_type": "price_change"}}
{"ts": 1785163835.087, "kind": "price_change", "data": {"market": "0x18b1c135d0a40c5894da9412e77311827d9caf16cf4cd6591b247a34730af919", "price_changes": [{"asset_id": "40081275558852222228080198821361202017557872256707631666334039001378518619916", "price": "0.411", "size": "36907.4", "side": "BUY", "hash": "f5f094de99ecd3d5a4121c94d4e48b3b05582466", "best_bid": "0.428", "best_ask": "0.429"}, {"asset_id": "78633590736077251574794513664747155551297291244492840448622550955320930591622", "price": "0.589", "size": "36907.4", "side": "SELL", "hash": "921cbc589506bc96c84972cb634db2d7e17202a6", "best_bid": "0.571", "best_ask": "0.572"}], "timestamp": "1785163835087", "event_type": "price_change"}}
{"ts": 1785163837.384, "kind": "price_change", "data": {"market": "0x0f49db97f71c68b1e42a6d16e3de93d85dbf7d4148e3f018eb79e88554be9f75", "price_changes": [{"asset_id": "87854174148074652060467921081181402357467303721471806610111179101805869578687", "price": "0.001", "size": "6148776.01", "side": "BUY", "hash": "110fe1a3577207fc03be731a70f7a4562aab4b4c", "best_bid": "0.805", "best_ask": "0.806"}, {"asset_id": "54533043819946592547517511176940999955633860128497669742211153063842200957669", "price": "0.999", "size": "6148776.01", "side": "SELL", "hash": "4850895072b8174297b808be8abcbabb14fde0ec", "best_bid": "0.194", "best_ask": "0.195"}], "timestamp": "1785163837384", "event_type": "price_change"}}
{"ts": 1785163837.388, "kind": "price_change", "data": {"market": "0x0f49db97f71c68b1e42a6d16e3de93d85dbf7d4148e3f018eb79e88554be9f75", "price_changes": [{"asset_id": "87854174148074652060467921081181402357467303721471806610111179101805869578687", "price": "0.001", "size": "6147766.01", "side": "BUY", "hash": "e057ac801cbc2d348e31d0ccb7b4846b9614e83e", "best_bid": "0.805", "best_ask": "0.806"}, {"asset_id": "54533043819946592547517511176940999955633860128497669742211153063842200957669", "price": "0.999", "size": "6147766.01", "side": "SELL", "hash": "fff4b17ebd4b4385e1d4eaa58ba39ae2b189b092", "best_bid": "0.194", "best_ask": "0.195"}], "timestamp": "1785163837388", "event_type": "price_change"}}
{"ts": 1785163837.707932, "kind": "orders_out", "data": [{"token_id": "54533043819946592547517511176940999955633860128497669742211153063842200957669", "side": "BUY", "price": 0.144, "size": 10.42}]}
{"ts": 1785163839.824, "kind": "price_change", "data": {"market": "0x18b1c135d0a40c5894da9412e77311827d9caf16cf4cd6591b247a34730af919", "price_changes": [{"asset_id": "40081275558852222228080198821361202017557872256707631666334039001378518619916", "price": "0.506", "size": "0", "side": "SELL", "hash": "7ef744bfbd47ed3333ed6299f78e887875ddf32d", "best_bid": "0.428", "best_ask": "0.429"}, {"asset_id": "78633590736077251574794513664747155551297291244492840448622550955320930591622", "price": "0.494", "size": "0", "side": "BUY", "hash": "486508fc610e2317f4e2483d664e8ad2b56dd66e", "best_bid": "0.571", "best_ask": "0.572"}], "timestamp": "1785163839824", "event_type": "price_change"}}
{"ts": 1785163840.0, "kind": "price_change", "data": {"market": "0x0f49db97f71c68b1e42a6d16e3de93d85dbf7d4148e3f018eb79e88554be9f75", "price_changes": [{"asset_id": "87854174148074652060467921081181402357467303721471806610111179101805869578687", "price": "0.37", "size": "0", "side": "BUY", "hash": "9bc8ecc1b397d574c2bc0e7bd9f196d2f355444a", "best_bid": "0.805", "best_ask": "0.806"}, {"asset_id": "54533043819946592547517511176940999955633860128497669742211153063842200957669", "price": "0.63", "size": "0", "side": "SELL", "hash": "7c66f2cf8ec7118d9600344e177ff46afdb29815", "best_bid": "0.194", "best_ask": "0.195"}], "timestamp": "1785163840000", "event_type": "price_change"}}
{"ts": 1785163840.966, "kind": "price_change", "data": {"market": "0x18b1c135d0a40c5894da9412e77311827d9caf16cf4cd6591b247a34730af919", "price_changes": [{"asset_id": "40081275558852222228080198821361202017557872256707631666334039001378518619916", "price": "0.505", "size": "36.7", "side": "SELL", "hash": "22d497f6512b84cad9ced9045625db17a09bde1d", "best_bid": "0.428", "best_ask": "0.429"}, {"asset_id": "78633590736077251574794513664747155551297291244492840448622550955320930591622", "price": "0.495", "size": "36.7", "side": "BUY", "hash": "c4c34be94f0df3028f83b9966a1f9fe321adfb7c", "best_bid": "0.571", "best_ask": "0.572"}], "timestamp": "1785163840966", "event_type": "price_change"}}
{"ts": 1785163841.482, "kind": "price_change", "data": {"market": "0x18b1c135d0a40c5894da9412e77311827d9caf16cf4cd6591b247a34730af919", "price_changes": [{"asset_id": "78633590736077251574794513664747155551297291244492840448622550955320930591622", "price": "0.445", "size": "0", "side": "BUY", "hash": "62a9e5f2506cf87a817d6a7f530fd7c5862d9cf0", "best_bid": "0.571", "best_ask": "0.572"}, {"asset_id": "40081275558852222228080198821361202017557872256707631666334039001378518619916", "price": "0.555", "size": "0", "side": "SELL", "hash": "4beb869128645a7079e69556621da75a640b23ec", "best_bid": "0.428", "best_ask": "0.429"}], "timestamp": "1785163841482", "event_type": "price_change"}}
{"ts": 1785163841.632, "kind": "price_change", "data": {"market": "0x0f49db97f71c68b1e42a6d16e3de93d85dbf7d4148e3f018eb79e88554be9f75", "price_changes": [{"asset_id": "54533043819946592547517511176940999955633860128497669742211153063842200957669", "price": "0.193", "size": "11094", "side": "BUY", "hash": "4461651fa529aaf414ee38a87591a365bd9079f9", "best_bid": "0.194", "best_ask": "0.195"}, {"asset_id": "87854174148074652060467921081181402357467303721471806610111179101805869578687", "price": "0.807", "size": "11094", "side": "SELL", "hash": "f22489aef410fb19b54920c0f9181c54136f8754", "best_bid": "0.805", "best_ask": "0.806"}], "timestamp": "1785163841632", "event_type": "price_change"}}
{"ts": 1785163841.638, "kind": "price_change", "data": {"market": "0x18b1c135d0a40c5894da9412e77311827d9caf16cf4cd6591b247a34730af919", "price_changes": [{"asset_id": "40081275558852222228080198821361202017557872256707631666334039001378518619916", "price": "0.505", "size": "0", "side": "SELL", "hash": "01e5b2bf2f49e77a79f67c3a89605c7dd960deac", "best_bid": "0.428", "best_ask": "0.429"}, {"asset_id": "78633590736077251574794513664747155551297291244492840448622550955320930591622", "price": "0.495", "size": "0", "side": "BUY", "hash": "321c88546fa8a927b57376d95785fe8bd0fe211e", "best_bid": "0.571", "best_ask": "0.572"}], "timestamp": "1785163841638", "event_type": "price_change"}}
{"ts": 1785163841.719, "kind": "price_change", "data": {"market": "0x0f49db97f71c68b1e42a6d16e3de93d85dbf7d4148e3f018eb79e88554be9f75", "price_changes": [{"asset_id": "54533043819946592547517511176940999955633860128497669742211153063842200957669", "price": "0.174", "size": "8111", "side": "BUY", "hash": "7811ddcc7e7037ae06515cffcedc1d9c36222f9e", "best_bid": "0.194", "best_ask": "0.195"}, {"asset_id": "87854174148074652060467921081181402357467303721471806610111179101805869578687", "price": "0.826", "size": "8111", "side": "SELL", "hash": "1abf99ffa6eb05314b552848e4e394700dd55338", "best_bid": "0.805", "best_ask": "0.806"}], "timestamp": "1785163841719", "event_type": "price_change"}}
{"ts": 1785163841.753, "kind": "price_change", "data": {"market": "0x0f49db97f71c68b1e42a6d16e3de93d85dbf7d4148e3f018eb79e88554be9f75", "price_changes": [{"asset_id": "54533043819946592547517511176940999955633860128497669742211153063842200957669", "price": "0.174", "size": "11559", "side": "BUY", "hash": "fbf490837fbead64d598c8a8e666be1688024983", "best_bid": "0.194", "best_ask": "0.195"}, {"asset_id": "87854174148074652060467921081181402357467303721471806610111179101805869578687", "price": "0.826", "size": "11559", "side": "SELL", "hash": "7978e676a3e9ef6757a62cd596bf82e1c7ada40f", "best_bid": "0.805", "best_ask": "0.806"}], "timestamp": "1785163841753", "event_type": "price_change"}}
{"ts": 1785163841.787, "kind": "price_change", "data": {"market": "0x18b1c135d0a40c5894da9412e77311827d9caf16cf4cd6591b247a34730af919", "price_changes": [{"asset_id": "78633590736077251574794513664747155551297291244492840448622550955320930591622", "price": "0.445", "size": "100", "side": "BUY", "hash": "da38bd9bd1b2c1c7a8ddea90ea3e5cf2a2805291", "best_bid": "0.571", "best_ask": "0.572"}, {"asset_id": "40081275558852222228080198821361202017557872256707631666334039001378518619916", "price": "0.555", "size": "100", "side": "SELL", "hash": "563eac3954af69dbadd1e8cfdd4423bb661f2676", "best_bid": "0.428", "best_ask": "0.429"}], "timestamp": "1785163841787", "event_type": "price_change"}}
{"ts": 1785163841.999, "kind": "price_change", "data": {"market": "0x18b1c135d0a40c5894da9412e77311827d9caf16cf4cd6591b247a34730af919", "price_changes": [{"asset_id": "40081275558852222228080198821361202017557872256707631666334039001378518619916", "price": "0.506", "size": "36.7", "side": "SELL", "hash": "4c3e3cf7655d1f8ece7d51a40c71d38a68cca54b", "best_bid": "0.428", "best_ask": "0.429"}, {"asset_id": "78633590736077251574794513664747155551297291244492840448622550955320930591622", "price": "0.494", "size": "36.7", "side": "BUY", "hash": "7d7baa98f987d3c7aa061aaae3d4cac4b0a22c44", "best_bid": "0.571", "best_ask": "0.572"}], "timestamp": "1785163841999", "event_type": "price_change"}}
{"ts": 1785163842.007, "kind": "price_change", "data": {"market": "0x18b1c135d0a40c5894da9412e77311827d9caf16cf4cd6591b247a34730af919", "price_changes": [{"asset_id": "40081275558852222228080198821361202017557872256707631666334039001378518619916", "price": "0.03", "size": "118750", "side": "BUY", "hash": "15ce159b4fc56fe28c655e5b14b20e67b11f2f8d", "best_bid": "0.428", "best_ask": "0.429"}, {"asset_id": "78633590736077251574794513664747155551297291244492840448622550955320930591622", "price": "0.97", "size": "118750", "side": "SELL", "hash": "fd2a365d865a9cbb3b42c9bfd80d3f3cbc9d2be9", "best_bid": "0.571", "best_ask": "0.572"}], "timestamp": "1785163842007", "event_type": "price_change"}}
{"ts": 1785163842.007, "kind": "price_change", "data": {"market": "0x18b1c135d0a40c5894da9412e77311827d9caf16cf4cd6591b247a34730af919", "price_changes": [{"asset_id": "78633590736077251574794513664747155551297291244492840448622550955320930591622", "price": "0.08", "size": "12500", "side": "BUY", "hash": "fd2a365d865a9cbb3b42c9bfd80d3f3cbc9d2be9", "best_bid": "0.571", "best_ask": "0.572"}, {"asset_id": "40081275558852222228080198821361202017557872256707631666334039001378518619916", "price": "0.92", "size": "12500", "side": "SELL", "hash": "15ce159b4fc56fe28c655e5b14b20e67b11f2f8d", "best_bid": "0.428", "best_ask": "0.429"}], "timestamp": "1785163842007", "event_type": "price_change"}}
{"ts": 1785163842.129, "kind": "price_change", "data": {"market": "0x0f49db97f71c68b1e42a6d16e3de93d85dbf7d4148e3f018eb79e88554be9f75", "price_changes": [{"asset_id": "87854174148074652060467921081181402357467303721471806610111179101805869578687", "price": "0.804", "size": "868.01", "side": "BUY", "hash": "ade5334edd01f7e4ac41ebcde224c8cb4a20ba46", "best_bid": "0.805", "best_ask": "0.806"}, {"asset_id": "54533043819946592547517511176940999955633860128497669742211153063842200957669", "price": "0.196", "size": "868.01", "side": "SELL", "hash": "36dec6cc82bb25d82dd4ef9d942dbd875bd95038", "best_bid": "0.194", "best_ask": "0.195"}], "timestamp": "1785163842129", "event_type": "price_change"}}
{"ts": 1785163842.228, "kind": "price_change", "data": {"market": "0x0f49db97f71c68b1e42a6d16e3de93d85dbf7d4148e3f018eb79e88554be9f75", "price_changes": [{"asset_id": "87854174148074652060467921081181402357467303721471806610111179101805869578687", "price": "0.785", "size": "1965", "side": "BUY", "hash": "59f4368dce9d101bb569e9f626c8f01cd6123751", "best_bid": "0.805", "best_ask": "0.806"}, {"asset_id": "54533043819946592547517511176940999955633860128497669742211153063842200957669", "price": "0.215", "size": "1965", "side": "SELL", "hash": "83150224d1c29b2c3138571111d156a5f318478b", "best_bid": "0.194", "best_ask": "0.195"}], "timestamp": "1785163842228", "event_type": "price_change"}}
{"ts": 1785163842.262, "kind": "price_change", "data": {"market": "0x0f49db97f71c68b1e42a6d16e3de93d85dbf7d4148e3f018eb79e88554be9f75", "price_changes": [{"asset_id": "87854174148074652060467921081181402357467303721471806610111179101805869578687", "price": "0.785", "size": "2729", "side": "BUY", "hash": "41683c8f274935024b2d3f2124d18b00904eafdc", "best_bid": "0.805", "best_ask": "0.806"}, {"asset_id": "54533043819946592547517511176940999955633860128497669742211153063842200957669", "price": "0.215", "size": "2729", "side": "SELL", "hash": "5cd3462f158e9f8c2246d014d58123497971436f", "best_bid": "0.194", "best_ask": "0.195"}], "timestamp": "1785163842262", "event_type": "price_change"}}
{"ts": 1785163844.411, "kind": "price_change", "data": {"market": "0x18b1c135d0a40c5894da9412e77311827d9caf16cf4cd6591b247a34730af919", "price_changes": [{"asset_id": "78633590736077251574794513664747155551297291244492840448622550955320930591622", "price": "0.08", "size": "27500", "side": "BUY", "hash": "bf6178be0cc3b78e6062bc18874e57a2b48f4609", "best_bid": "0.571", "best_ask": "0.572"}, {"asset_id": "40081275558852222228080198821361202017557872256707631666334039001378518619916", "price": "0.92", "size": "27500", "side": "SELL", "hash": "5195eee7e1b7731b9c3cd9adf65e06157e92df95", "best_bid": "0.428", "best_ask": "0.429"}], "timestamp": "1785163844411", "event_type": "price_change"}}
{"ts": 1785163844.412, "kind": "price_change", "data": {"market": "0x18b1c135d0a40c5894da9412e77311827d9caf16cf4cd6591b247a34730af919", "price_changes": [{"asset_id": "40081275558852222228080198821361202017557872256707631666334039001378518619916", "price": "0.03", "size": "158750", "side": "BUY", "hash": "c23cc131f39c90f4888cb6c052d828d251b22afd", "best_bid": "0.428", "best_ask": "0.429"}, {"asset_id": "78633590736077251574794513664747155551297291244492840448622550955320930591622", "price": "0.97", "size": "158750", "side": "SELL", "hash": "6ba46dd43e307efd70404dd59e83471f57a30aad", "best_bid": "0.571", "best_ask": "0.572"}], "timestamp": "1785163844412", "event_type": "price_change"}}
{"ts": 1785163844.80253, "kind": "orders_out", "data": [{"token_id": "40081275558852222228080198821361202017557872256707631666334039001378518619916", "side": "BUY", "price": 0.387, "size": 7.75}, {"token_id": "78633590736077251574794513664747155551297291244492840448622550955320930591622", "side": "BUY", "price": 0.529, "size": 5.67}]}
{"ts": 1785163846.004, "kind": "price_change", "data": {"market": "0x0f49db97f71c68b1e42a6d16e3de93d85dbf7d4148e3f018eb79e88554be9f75", "price_changes": [{"asset_id": "87854174148074652060467921081181402357467303721471806610111179101805869578687", "price": "0.004", "size": "0", "side": "BUY", "hash": "d825462a190df6480c3f3b5a8ca259440ff5c69e", "best_bid": "0.805", "best_ask": "0.806"}, {"asset_id": "54533043819946592547517511176940999955633860128497669742211153063842200957669", "price": "0.996", "size": "0", "side": "SELL", "hash": "07343841fea7eb39afac8d725f05358be23858e3", "best_bid": "0.194", "best_ask": "0.195"}], "timestamp": "1785163846004", "event_type": "price_change"}}
{"ts": 1785163846.203, "kind": "price_change", "data": {"market": "0x18b1c135d0a40c5894da9412e77311827d9caf16cf4cd6591b247a34730af919", "price_changes": [{"asset_id": "40081275558852222228080198821361202017557872256707631666334039001378518619916", "price": "0.41", "size": "2931.23", "side": "BUY", "hash": "861fc3a65a8b68c20cc71ff9ea32a19dfa1d5724", "best_bid": "0.428", "best_ask": "0.429"}, {"asset_id": "78633590736077251574794513664747155551297291244492840448622550955320930591622", "price": "0.59", "size": "2931.23", "side": "SELL", "hash": "06aff14d8aaf7abed7dff11466686a033ef3d045", "best_bid": "0.571", "best_ask": "0.572"}], "timestamp": "1785163846203", "event_type": "price_change"}}
{"ts": 1785163846.898, "kind": "price_change", "data": {"market": "0x18b1c135d0a40c5894da9412e77311827d9caf16cf4cd6591b247a34730af919", "price_changes": [{"asset_id": "40081275558852222228080198821361202017557872256707631666334039001378518619916", "price": "0.41", "size": "2947.28", "side": "BUY", "hash": "6c567a03207edf1aa3ea7372aa65f19031e30ffe", "best_bid": "0.428", "best_ask": "0.429"}, {"asset_id": "78633590736077251574794513664747155551297291244492840448622550955320930591622", "price": "0.59", "size": "2947.28", "side": "SELL", "hash": "f36e676c5cebd6cda979b4379b092a900f0de949", "best_bid": "0.571", "best_ask": "0.572"}], "timestamp": "1785163846898", "event_type": "price_change"}}
{"ts": 1785163848.001, "kind": "price_change", "data": {"market": "0x0f49db97f71c68b1e42a6d16e3de93d85dbf7d4148e3f018eb79e88554be9f75", "price_changes": [{"asset_id": "87854174148074652060467921081181402357467303721471806610111179101805869578687", "price": "0.37", "size": "2702", "side": "BUY", "hash": "0222ba2da4dd84e25cb236aea3184328a7992ab3", "best_bid": "0.805", "best_ask": "0.806"}, {"asset_id": "54533043819946592547517511176940999955633860128497669742211153063842200957669", "price": "0.63", "size": "2702", "side": "SELL", "hash": "5e252541730d92bed386aba187c7def620f3c711", "best_bid": "0.194", "best_ask": "0.195"}], "timestamp": "1785163848001", "event_type": "price_change"}}
{"ts": 1785163849.002, "kind": "price_change", "data": {"market": "0x0f49db97f71c68b1e42a6d16e3de93d85dbf7d4148e3f018eb79e88554be9f75", "price_changes": [{"asset_id": "87854174148074652060467921081181402357467303721471806610111179101805869578687", "price": "0.02", "size": "13000", "side": "BUY", "hash": "b0ddaa96bd65e3929447927eb0d74ae47a16babb", "best_bid": "0.805", "best_ask": "0.806"}, {"asset_id": "54533043819946592547517511176940999955633860128497669742211153063842200957669", "price": "0.98", "size": "13000", "side": "SELL", "hash": "76018f7d481edb49245e400e612494aeea8e9b68", "best_bid": "0.194", "best_ask": "0.195"}], "timestamp": "1785163849002", "event_type": "price_change"}}
{"ts": 1785163849.002, "kind": "price_change", "data": {"market": "0x0f49db97f71c68b1e42a6d16e3de93d85dbf7d4148e3f018eb79e88554be9f75", "price_changes": [{"asset_id": "87854174148074652060467921081181402357467303721471806610111179101805869578687", "price": "0.02", "size": "13000", "side": "BUY", "hash": "b0ddaa96bd65e3929447927eb0d74ae47a16babb", "best_bid": "0.805", "best_ask": "0.806"}, {"asset_id": "54533043819946592547517511176940999955633860128497669742211153063842200957669", "price": "0.98", "size": "13000", "side": "SELL", "hash": "76018f7d481edb49245e400e612494aeea8e9b68", "best_bid": "0.194", "best_ask": "0.195"}], "timestamp": "1785163849002", "event_type": "price_change"}}
{"ts": 1785163849.003, "kind": "price_change", "data": {"market": "0x0f49db97f71c68b1e42a6d16e3de93d85dbf7d4148e3f018eb79e88554be9f75", "price_changes": [{"asset_id": "87854174148074652060467921081181402357467303721471806610111179101805869578687", "price": "0.02", "size": "13000", "side": "BUY", "hash": "121d0c28a74382f80297f62f5e8e9f08c50158a8", "best_bid": "0.805", "best_ask": "0.806"}, {"asset_id": "54533043819946592547517511176940999955633860128497669742211153063842200957669", "price": "0.98", "size": "13000", "side": "SELL", "hash": "b475d88a86c121add7a55625af860c38454f3ec8", "best_bid": "0.194", "best_ask": "0.195"}], "timestamp": "1785163849003", "event_type": "price_change"}}
{"ts": 1785163849.309553, "kind": "orders_out", "data": [{"token_id": "54533043819946592547517511176940999955633860128497669742211153063842200957669", "side": "BUY", "price": 0.153, "size": 19.61}]}
{"ts": 1785163853.556, "kind": "price_change", "data": {"market": "0x0f49db97f71c68b1e42a6d16e3de93d85dbf7d4148e3f018eb79e88554be9f75", "price_changes": [{"asset_id": "87854174148074652060467921081181402357467303721471806610111179101805869578687", "price": "0.004", "size": "12500", "side": "BUY", "hash": "be506dfaf14d2c8b6094865cfd9f89f2e5b4c830", "best_bid": "0.805", "best_ask": "0.806"}, {"asset_id": "54533043819946592547517511176940999955633860128497669742211153063842200957669", "price": "0.996", "size": "12500", "side": "SELL", "hash": "75d8c02b94fefbb46ee257b8275b4d491fed8883", "best_bid": "0.194", "best_ask": "0.195"}], "timestamp": "1785163853556", "event_type": "price_change"}}
{"ts": 1785163853.581, "kind": "price_change", "data": {"market": "0x18b1c135d0a40c5894da9412e77311827d9caf16cf4cd6591b247a34730af919", "price_changes": [{"asset_id": "78633590736077251574794513664747155551297291244492840448622550955320930591622", "price": "0.371", "size": "0", "side": "BUY", "hash": "4dd09e6ff1e44fb3e1ae70e9aab019578991ee4e", "best_bid": "0.571", "best_ask": "0.572"}, {"asset_id": "40081275558852222228080198821361202017557872256707631666334039001378518619916", "price": "0.629", "size": "0", "side": "SELL", "hash": "0b0555b0afdc0bacf6ec267b6874cbbc9b81927f", "best_bid": "0.428", "best_ask": "0.429"}], "timestamp": "1785163853581", "event_type": "price_change"}}
{"ts": 1785163853.609, "kind": "price_change", "data": {"market": "0x18b1c135d0a40c5894da9412e77311827d9caf16cf4cd6591b247a34730af919", "price_changes": [{"asset_id": "78633590736077251574794513664747155551297291244492840448622550955320930591622", "price": "0.373", "size": "400", "side": "BUY", "hash": "f41b16ef258b0fecfcb4be9b57b352cb0dfb8617", "best_bid": "0.571", "best_ask": "0.572"}, {"asset_id": "40081275558852222228080198821361202017557872256707631666334039001378518619916", "price": "0.627", "size": "400", "side": "SELL", "hash": "4a2dfe6528167b7892dc6672076e165741ed7b8f", "best_bid": "0.428", "best_ask": "0.429"}], "timestamp": "1785163853609", "event_type": "price_change"}}
{"ts": 1785163859.424, "kind": "price_change", "data": {"market": "0x18b1c135d0a40c5894da9412e77311827d9caf16cf4cd6591b247a34730af919", "price_changes": [{"asset_id": "40081275558852222228080198821361202017557872256707631666334039001378518619916", "price": "0.506", "size": "0", "side": "SELL", "hash": "e9eeb7eccea43b644fcb57db4716674c8e95e48d", "best_bid": "0.428", "best_ask": "0.429"}, {"asset_id": "78633590736077251574794513664747155551297291244492840448622550955320930591622", "price": "0.494", "size": "0", "side": "BUY", "hash": "532cb1c91a92da78869796890bf202637d61e53a", "best_bid": "0.571", "best_ask": "0.572"}], "timestamp": "1785163859424", "event_type": "price_change"}}
{"ts": 1785163860.478, "kind": "price_change", "data": {"market": "0x18b1c135d0a40c5894da9412e77311827d9caf16cf4cd6591b247a34730af919", "price_changes": [{"asset_id": "40081275558852222228080198821361202017557872256707631666334039001378518619916", "price": "0.505", "size": "36.7", "side": "SELL", "hash": "89830e18d5e7d0b4b02a4ac6f4aab798105ea7da", "best_bid": "0.428", "best_ask": "0.429"}, {"asset_id": "78633590736077251574794513664747155551297291244492840448622550955320930591622", "price": "0.495", "size": "36.7", "side": "BUY", "hash": "60d23257328eb689a327a0f44eb1399b1b5166b4", "best_bid": "0.571", "best_ask": "0.572"}], "timestamp": "1785163860478", "event_type": "price_change"}}
{"ts": 1785163861.122, "kind": "price_change", "data": {"market": "0x18b1c135d0a40c5894da9412e77311827d9caf16cf4cd6591b247a34730af919", "price_changes": [{"asset_id": "40081275558852222228080198821361202017557872256707631666334039001378518619916", "price": "0.505", "size": "0", "side": "SELL", "hash": "e1c1517cd7ac7deb5a35d9fe22152901acc2d492", "best_bid": "0.428", "best_ask": "0.429"}, {"asset_id": "78633590736077251574794513664747155551297291244492840448622550955320930591622", "price": "0.495", "size": "0", "side": "BUY", "hash": "2309e86624121020d63d819a8034aca1496ca5d7", "best_bid": "0.571", "best_ask": "0.572"}], "timestamp": "1785163861122", "event_type": "price_change"}}
{"ts": 1785163861.213, "kind": "price_change", "data": {"market": "0x0f49db97f71c68b1e42a6d16e3de93d85dbf7d4148e3f018eb79e88554be9f75", "price_changes": [{"asset_id": "87854174148074652060467921081181402357467303721471806610111179101805869578687", "price": "0.02", "size": "88000", "side": "BUY", "hash": "12750e263e81d52f85945bf70382bd68a8345b07", "best_bid": "0.805", "best_ask": "0.806"}, {"asset_id": "54533043819946592547517511176940999955633860128497669742211153063842200957669", "price": "0.98", "size": "88000", "side": "SELL", "hash": "ef286efa26e0102e5d88caffe62f29f13e7c3ba3", "best_bid": "0.194", "best_ask": "0.195"}], "timestamp": "1785163861213", "event_type": "price_change"}}
{"ts": 1785163861.214, "kind": "price_change", "data": {"market": "0x0f49db97f71c68b1e42a6d16e3de93d85dbf7d4148e3f018eb79e88554be9f75", "price_changes": [{"asset_id": "87854174148074652060467921081181402357467303721471806610111179101805869578687", "price": "0.02", "size": "148000", "side": "BUY", "hash": "c2df8b01cf7303b850a4a18360c5507a8421c282", "best_bid": "0.805", "best_ask": "0.806"}, {"asset_id": "54533043819946592547517511176940999955633860128497669742211153063842200957669", "price": "0.98", "size": "148000", "side": "SELL", "hash": "e97118fdab297fbb6ed43494479b305fa9b3ac03", "best_bid": "0.194", "best_ask": "0.195"}], "timestamp": "1785163861214", "event_type": "price_change"}}
{"ts": 1785163861.214, "kind": "price_change", "data": {"market": "0x0f49db97f71c68b1e42a6d16e3de93d85dbf7d4148e3f018eb79e88554be9f75", "price_changes": [{"asset_id": "87854174148074652060467921081181402357467303721471806610111179101805869578687", "price": "0.02", "size": "233000", "side": "BUY", "hash": "243eab6381653d2879159bc47616fe5dd2fd9273", "best_bid": "0.805", "best_ask": "0.806"}, {"asset_id": "54533043819946592547517511176940999955633860128497669742211153063842200957669", "price": "0.98", "size": "233000", "side": "SELL", "hash": "0466326adbad73186f339f59fe48d2021ce23456", "best_bid": "0.194", "best_ask": "0.195"}], "timestamp": "1785163861214", "event_type": "price_change"}}
{"ts": 1785163861.637, "kind": "price_change", "data": {"market": "0x18b1c135d0a40c5894da9412e77311827d9caf16cf4cd6591b247a34730af919", "price_changes": [{"asset_id": "40081275558852222228080198821361202017557872256707631666334039001378518619916", "price": "0.506", "size": "36.7", "side": "SELL", "hash": "c6d156450e15e2aa7174b9431d0ebe2efa10fb7c", "best_bid": "0.428", "best_ask": "0.429"}, {"asset_id": "78633590736077251574794513664747155551297291244492840448622550955320930591622", "price": "0.494", "size": "36.7", "side": "BUY", "hash": "5f810a7a3ed425c70cf58b31f845d2cec58a2f22", "best_bid": "0.571", "best_ask": "0.572"}], "timestamp": "1785163861637", "event_type": "price_change"}}
{"ts": 1785163863.746, "kind": "price_change", "data": {"market": "0x0f49db97f71c68b1e42a6d16e3de93d85dbf7d4148e3f018eb79e88554be9f75", "price_changes": [{"asset_id": "87854174148074652060467921081181402357467303721471806610111179101805869578687", "price": "0.02", "size": "220500", "side": "BUY", "hash": "854e6be737cb088f419e35fcc32f8c675c50b776", "best_bid": "0.805", "best_ask": "0.806"}, {"asset_id": "54533043819946592547517511176940999955633860128497669742211153063842200957669", "price": "0.98", "size": "220500", "side": "SELL", "hash": "6bef895b8c2e7f0daef8a27e68847ad577c5ecb5", "best_bid": "0.194", "best_ask": "0.195"}], "timestamp": "1785163863746", "event_type": "price_change"}}
{"ts": 1785163863.753, "kind": "price_change", "data": {"market": "0x0f49db97f71c68b1e42a6d16e3de93d85dbf7d4148e3f018eb79e88554be9f75", "price_changes": [{"asset_id": "54533043819946592547517511176940999955633860128497669742211153063842200957669", "price": "0.04", "size": "4050", "side": "BUY", "hash": "295f4255f3fb2be54689b3cd5628d0c7913b3bcc", "best_bid": "0.194", "best_ask": "0.195"}, {"asset_id": "87854174148074652060467921081181402357467303721471806610111179101805869578687", "price": "0.96", "size": "4050", "side": "SELL", "hash": "1f4bca1a97eacffcd64b5f8af58b10f33b097663", "best_bid": "0.805", "best_ask": "0.806"}], "timestamp": "1785163863753", "event_type": "price_change"}}
{"ts": 1785163864.437, "kind": "price_change", "data": {"market": "0x18b1c135d0a40c5894da9412e77311827d9caf16cf4cd6591b247a34730af919", "price_changes": [{"asset_id": "40081275558852222228080198821361202017557872256707631666334039001378518619916", "price": "0.41", "size": "2931.23", "side": "BUY", "hash": "2bcd256ea1b9839af4c1b316d8e8aa6c1a43b00e", "best_bid": "0.428", "best_ask": "0.429"}, {"asset_id": "78633590736077251574794513664747155551297291244492840448622550955320930591622", "price": "0.59", "size": "2931.23", "side": "SELL", "hash": "3bbf84838f4e35d3b0a06ebe4d6a924fe43532fb", "best_bid": "0.571", "best_ask": "0.572"}], "timestamp": "1785163864437", "event_type": "price_change"}}
{"ts": 1785163864.743422, "kind": "orders_out", "data": [{"token_id": "40081275558852222228080198821361202017557872256707631666334039001378518619916", "side": "BUY", "price": 0.387, "size": 7.75}, {"token_id": "78633590736077251574794513664747155551297291244492840448622550955320930591622", "side": "BUY", "price": 0.529, "size": 5.67}]}
{"ts": 1785163864.882, "kind": "price_change", "data": {"market": "0x18b1c135d0a40c5894da9412e77311827d9caf16cf4cd6591b247a34730af919", "price_changes": [{"asset_id": "40081275558852222228080198821361202017557872256707631666334039001378518619916", "price": "0.41", "size": "2947.28", "side": "BUY", "hash": "840e332ee65d19ed1dca30f3550379ee65708314", "best_bid": "0.428", "best_ask": "0.429"}, {"asset_id": "78633590736077251574794513664747155551297291244492840448622550955320930591622", "price": "0.59", "size": "2947.28", "side": "SELL", "hash": "70ce51a39b429cb8b1c27151a4bf6663111d376f", "best_bid": "0.571", "best_ask": "0.572"}], "timestamp": "1785163864882", "event_type": "price_change"}}
{"ts": 1785163865.581, "kind": "price_change", "data": {"market": "0x0f49db97f71c68b1e42a6d16e3de93d85dbf7d4148e3f018eb79e88554be9f75", "price_changes": [{"asset_id": "54533043819946592547517511176940999955633860128497669742211153063842200957669", "price": "0.007", "size": "53571.42", "side": "BUY", "hash": "61d09b8ed5ae6ae4dda58e47951e69d54248daef", "best_bid": "0.194", "best_ask": "0.195"}, {"asset_id": "87854174148074652060467921081181402357467303721471806610111179101805869578687", "price": "0.993", "size": "53571.42", "side": "SELL", "hash": "fa27f8ea19d1877de9482f8bfda494e9dd493979", "best_bid": "0.805", "best_ask": "0.806"}], "timestamp": "1785163865581", "event_type": "price_change"}}
{"ts": 1785163865.583, "kind": "price_change", "data": {"market": "0x0f49db97f71c68b1e42a6d16e3de93d85dbf7d4148e3f018eb79e88554be9f75", "price_changes": [{"asset_id": "54533043819946592547517511176940999955633860128497669742211153063842200957669", "price": "0.009", "size": "13888.88", "side": "BUY", "hash": "592318629eb58c6a1b9f00be023ddda505b45be1", "best_bid": "0.194", "best_ask": "0.195"}, {"asset_id": "87854174148074652060467921081181402357467303721471806610111179101805869578687", "price": "0.991", "size": "13888.88", "side": "SELL", "hash": "14637587867dc0e8b8d9e67274470b107173e28b", "best_bid": "0.805", "best_ask": "0.806"}], "timestamp": "1785163865583", "event_type": "price_change"}}
{"ts": 1785163865.88775, "kind": "orders_out", "data": [{"token_id": "54533043819946592547517511176940999955633860128497669742211153063842200957669", "side": "BUY", "price": 0.153, "size": 19.61}]}
{"ts": 1785163870.021, "kind": "price_change", "data": {"market": "0x18b1c135d0a40c5894da9412e77311827d9caf16cf4cd6591b247a34730af919", "price_changes": [{"asset_id": "78633590736077251574794513664747155551297291244492840448622550955320930591622", "price": "0.482", "size": "161.09", "side": "BUY", "hash": "2368aba08aaaff64360e09ef42fbc7eda47b1c5c", "best_bid": "0.571", "best_ask": "0.572"}, {"asset_id": "40081275558852222228080198821361202017557872256707631666334039001378518619916", "price": "0.518", "size": "161.09", "side": "SELL", "hash": "4c62ac5b021c3b79983e4efa8bdba9802abb4942", "best_bid": "0.428", "best_ask": "0.429"}], "timestamp": "1785163870021", "event_type": "price_change"}}
{"ts": 1785163870.049, "kind": "price_change", "data": {"market": "0x18b1c135d0a40c5894da9412e77311827d9caf16cf4cd6591b247a34730af919", "price_changes": [{"asset_id": "78633590736077251574794513664747155551297291244492840448622550955320930591622", "price": "0.486", "size": "10", "side": "BUY", "hash": "dc382e300fff76d96fa9539bb3c42e2665a187c3", "best_bid": "0.571", "best_ask": "0.572"}, {"asset_id": "40081275558852222228080198821361202017557872256707631666334039001378518619916", "price": "0.514", "size": "10", "side": "SELL", "hash": "558baec3c1267b791e576eff5425a59052b23561", "best_bid": "0.428", "best_ask": "0.429"}], "timestamp": "1785163870049", "event_type": "price_change"}}
{"ts": 1785163870.05, "kind": "price_change", "data": {"market": "0x18b1c135d0a40c5894da9412e77311827d9caf16cf4cd6591b247a34730af919", "price_changes": [{"asset_id": "78633590736077251574794513664747155551297291244492840448622550955320930591622", "price": "0.485", "size": "107", "side": "BUY", "hash": "ceac70e9efe306ce0f9776f2a05a88ec2257fcaf", "best_bid": "0.571", "best_ask": "0.572"}, {"asset_id": "40081275558852222228080198821361202017557872256707631666334039001378518619916", "price": "0.515", "size": "107", "side": "SELL", "hash": "19cbcbc4a9e8879bc900a10fe55803576ccffe72", "best_bid": "0.428", "best_ask": "0.429"}], "timestamp": "1785163870050", "event_type": "price_change"}}
{"ts": 1785163870.087, "kind": "price_change", "data": {"market": "0x18b1c135d0a40c5894da9412e77311827d9caf16cf4cd6591b247a34730af919", "price_changes": [{"asset_id": "78633590736077251574794513664747155551297291244492840448622550955320930591622", "price": "0.482", "size": "0", "side": "BUY", "hash": "a8fa40fbd20297b99390f8bd836f0d0434b5d4de", "best_bid": "0.571", "best_ask": "0.572"}, {"asset_id": "40081275558852222228080198821361202017557872256707631666334039001378518619916", "price": "0.518", "size": "0", "side": "SELL", "hash": "062231e20af5322302a0b74a6d7e48aa19bd14d6", "best_bid": "0.428", "best_ask": "0.429"}], "timestamp": "1785163870087", "event_type": "price_change"}}
{"ts": 1785163870.087, "kind": "price_change", "data": {"market": "0x18b1c135d0a40c5894da9412e77311827d9caf16cf4cd6591b247a34730af919", "price_changes": [{"asset_id": "78633590736077251574794513664747155551297291244492840448622550955320930591622", "price": "0.485", "size": "30", "side": "BUY", "hash": "a8fa40fbd20297b99390f8bd836f0d0434b5d4de", "best_bid": "0.571", "best_ask": "0.572"}, {"asset_id": "40081275558852222228080198821361202017557872256707631666334039001378518619916", "price": "0.515", "size": "30", "side": "SELL", "hash": "062231e20af5322302a0b74a6d7e48aa19bd14d6", "best_bid": "0.428", "best_ask": "0.429"}], "timestamp": "1785163870087", "event_type": "price_change"}}
{"ts": 1785163870.1, "kind": "price_change", "data": {"market": "0x18b1c135d0a40c5894da9412e77311827d9caf16cf4cd6591b247a34730af919", "price_changes": [{"asset_id": "40081275558852222228080198821361202017557872256707631666334039001378518619916", "price": "0.506", "size": "0", "side": "SELL", "hash": "1094976e5334abb24a935119f06db4870d1b295b", "best_bid": "0.428", "best_ask": "0.429"}, {"asset_id": "78633590736077251574794513664747155551297291244492840448622550955320930591622", "price": "0.494", "size": "0", "side": "BUY", "hash": "b8d61925dc4e5a312ea40fe23b8d9b9e7cc3b0c6", "best_bid": "0.571", "best_ask": "0.572"}], "timestamp": "1785163870100", "event_type": "price_change"}}
{"ts": 1785163870.112, "kind": "price_change", "data": {"market": "0x18b1c135d0a40c5894da9412e77311827d9caf16cf4cd6591b247a34730af919", "price_changes": [{"asset_id": "78633590736077251574794513664747155551297291244492840448622550955320930591622", "price": "0.486", "size": "0", "side": "BUY", "hash": "be54b931470557f489d76a1c65d9ad4a5b6cf954", "best_bid": "0.571", "best_ask": "0.572"}, {"asset_id": "40081275558852222228080198821361202017557872256707631666334039001378518619916", "price": "0.514", "size": "0", "side": "SELL", "hash": "c5389198d4eafcffe6f41f9dd7d23cc0b5361582", "best_bid": "0.428", "best_ask": "0.429"}], "timestamp": "1785163870112", "event_type": "price_change"}}
{"ts": 1785163870.112, "kind": "price_change", "data": {"market": "0x18b1c135d0a40c5894da9412e77311827d9caf16cf4cd6591b247a34730af919", "price_changes": [{"asset_id": "78633590736077251574794513664747155551297291244492840448622550955320930591622", "price": "0.485", "size": "0", "side": "BUY", "hash": "be54b931470557f489d76a1c65d9ad4a5b6cf954", "best_bid": "0.571", "best_ask": "0.572"}, {"asset_id": "40081275558852222228080198821361202017557872256707631666334039001378518619916", "price": "0.515", "size": "0", "side": "SELL", "hash": "c5389198d4eafcffe6f41f9dd7d23cc0b5361582", "best_bid": "0.428", "best_ask": "0.429"}], "timestamp": "1785163870112", "event_type": "price_change"}}
{"ts": 1785163870.149, "kind": "price_change", "data": {"market": "0x18b1c135d0a40c5894da9412e77311827d9caf16cf4cd6591b247a34730af919", "price_changes": [{"asset_id": "78633590736077251574794513664747155551297291244492840448622550955320930591622", "price": "0.549", "size": "0", "side": "BUY", "hash": "0c1e9bce2c557081f39589f7107dbcf135200484", "best_bid": "0.571", "best_ask": "0.572"}, {"asset_id": "40081275558852222228080198821361202017557872256707631666334039001378518619916", "price": "0.451", "size": "0", "side": "SELL", "hash": "627aa7cfe195c59a5afc712b236ee75cd0765e3c", "best_bid": "0.428", "best_ask": "0.429"}], "timestamp": "1785163870149", "event_type": "price_change"}}
{"ts": 1785163870.201, "kind": "price_change", "data": {"market": "0x18b1c135d0a40c5894da9412e77311827d9caf16cf4cd6591b247a34730af919", "price_changes": [{"asset_id": "78633590736077251574794513664747155551297291244492840448622550955320930591622", "price": "0.482", "size": "30", "side": "BUY", "hash": "281a1feb3db757e581e633b29c995b8614f88434", "best_bid": "0.571", "best_ask": "0.572"}, {"asset_id": "40081275558852222228080198821361202017557872256707631666334039001378518619916", "price": "0.518", "size": "30", "side": "SELL", "hash": "410f5336142ff7ef19e271e4dd5a0ab8cd625816", "best_bid": "0.428", "best_ask": "0.429"}], "timestamp": "1785163870201", "event_type": "price_change"}}
{"ts": 1785163870.202, "kind": "price_change", "data": {"market": "0x18b1c135d0a40c5894da9412e77311827d9caf16cf4cd6591b247a34730af919", "price_changes": [{"asset_id": "78633590736077251574794513664747155551297291244492840448622550955320930591622", "price": "0.482", "size": "40", "side": "BUY", "hash": "269f717d1a13c7d10be9ec2e4a5d166693c10e89", "best_bid": "0.571", "best_ask": "0.572"}, {"asset_id": "40081275558852222228080198821361202017557872256707631666334039001378518619916", "price": "0.518", "size": "40", "side": "SELL", "hash": "d6ba7efe46c810be6204eccff3b22cfd68aa193e", "best_bid": "0.428", "best_ask": "0.429"}], "timestamp": "1785163870202", "event_type": "price_change"}}
{"ts": 1785163870.34, "kind": "price_change", "data": {"market": "0x0f49db97f71c68b1e42a6d16e3de93d85dbf7d4148e3f018eb79e88554be9f75", "price_changes": [{"asset_id": "54533043819946592547517511176940999955633860128497669742211153063842200957669", "price": "0.04", "size": "300", "side": "BUY", "hash": "31103804d4225bb263df417341792b8e8522cbbf", "best_bid": "0.194", "best_ask": "0.195"}, {"asset_id": "87854174148074652060467921081181402357467303721471806610111179101805869578687", "price": "0.96", "size": "300", "side": "SELL", "hash": "118b53d5189f3e9f4fb29e361a8054a1f6cb1413", "best_bid": "0.805", "best_ask": "0.806"}], "timestamp": "1785163870340", "event_type": "price_change"}}
{"ts": 1785163870.354, "kind": "price_change", "data": {"market": "0x0f49db97f71c68b1e42a6d16e3de93d85dbf7d4148e3f018eb79e88554be9f75", "price_changes": [{"asset_id": "87854174148074652060467921081181402357467303721471806610111179101805869578687", "price": "0.03", "size": "8333", "side": "BUY", "hash": "1164883e28657ae940d9c4f45d505f1cb5da22ce", "best_bid": "0.805", "best_ask": "0.806"}, {"asset_id": "54533043819946592547517511176940999955633860128497669742211153063842200957669", "price": "0.97", "size": "8333", "side": "SELL", "hash": "06b8f70d1ad4340450c487394acf302d6141ac46", "best_bid": "0.194", "best_ask": "0.195"}], "timestamp": "1785163870354", "event_type": "price_change"}}
{"ts": 1785163871.026, "kind": "price_change", "data": {"market": "0x0f49db97f71c68b1e42a6d16e3de93d85dbf7d4148e3f018eb79e88554be9f75", "price_changes": [{"asset_id": "54533043819946592547517511176940999955633860128497669742211153063842200957669", "price": "0.009", "size": "0", "side": "BUY", "hash": "c0f5cb0bc56eea5ee60e786b8846eda27e82319d", "best_bid": "0.194", "best_ask": "0.195"}, {"asset_id": "87854174148074652060467921081181402357467303721471806610111179101805869578687", "price": "0.991", "size": "0", "side": "SELL", "hash": "2b7d9075896fc8b60df6af339b3a95f620709bd3", "best_bid": "0.805", "best_ask": "0.806"}], "timestamp": "1785163871026", "event_type": "price_change"}}
{"ts": 1785163871.026, "kind": "price_change", "data": {"market": "0x0f49db97f71c68b1e42a6d16e3de93d85dbf7d4148e3f018eb79e88554be9f75", "price_changes": [{"asset_id": "54533043819946592547517511176940999955633860128497669742211153063842200957669", "price": "0.007", "size": "0", "side": "BUY", "hash": "c0f5cb0bc56eea5ee60e786b8846eda27e82319d", "best_bid": "0.194", "best_ask": "0.195"}, {"asset_id": "87854174148074652060467921081181402357467303721471806610111179101805869578687", "price": "0.993", "size": "0", "side": "SELL", "hash": "2b7d9075896fc8b60df6af339b3a95f620709bd3", "best_bid": "0.805", "best_ask": "0.806"}], "timestamp": "1785163871026", "event_type": "price_change"}}
{"ts": 1785163871.284, "kind": "price_change", "data": {"market": "0x18b1c135d0a40c5894da9412e77311827d9caf16cf4cd6591b247a34730af919", "price_changes": [{"asset_id": "40081275558852222228080198821361202017557872256707631666334039001378518619916", "price": "0.505", "size": "36.7", "side": "SELL", "hash": "926fe10cef25b0fcacd5ad9126702b92e6e3e71d", "best_bid": "0.428", "best_ask": "0.429"}, {"asset_id": "78633590736077251574794513664747155551297291244492840448622550955320930591622", "price": "0.495", "size": "36.7", "side": "BUY", "hash": "110b14bd1212498e2f03a0e159a15c7afc9ca3e0", "best_bid": "0.571", "best_ask": "0.572"}], "timestamp": "1785163871284", "event_type": "price_change"}}
{"ts": 1785163872.075, "kind": "price_change", "data": {"market": "0x18b1c135d0a40c5894da9412e77311827d9caf16cf4cd6591b247a34730af919", "price_changes": [{"asset_id": "78633590736077251574794513664747155551297291244492840448622550955320930591622", "price": "0.372", "size": "0", "side": "BUY", "hash": "b44657afc38fed0111a828c566bc16a23a01e2c0", "best_bid": "0.571", "best_ask": "0.572"}, {"asset_id": "40081275558852222228080198821361202017557872256707631666334039001378518619916", "price": "0.628", "size": "0", "side": "SELL", "hash": "bdff465b069fb703044b7c60925f79e74ad8bc42", "best_bid": "0.428", "best_ask": "0.429"}], "timestamp": "1785163872075", "event_type": "price_change"}}
{"ts": 1785163872.101, "kind": "price_change", "data": {"market": "0x18b1c135d0a40c5894da9412e77311827d9caf16cf4cd6591b247a34730af919", "price_changes": [{"asset_id": "78633590736077251574794513664747155551297291244492840448622550955320930591622", "price": "0.373", "size": "0", "side": "BUY", "hash": "1822bb2659c993db164060f270beb09e920c9608", "best_bid": "0.571", "best_ask": "0.572"}, {"asset_id": "40081275558852222228080198821361202017557872256707631666334039001378518619916", "price": "0.627", "size": "0", "side": "SELL", "hash": "d0b6b45edc5c6fda9c38eac91ad72277a6197096", "best_bid": "0.428", "best_ask": "0.429"}], "timestamp": "1785163872101", "event_type": "price_change"}}
{"ts": 1785163872.129, "kind": "price_change", "data": {"market": "0x18b1c135d0a40c5894da9412e77311827d9caf16cf4cd6591b247a34730af919", "price_changes": [{"asset_id": "78633590736077251574794513664747155551297291244492840448622550955320930591622", "price": "0.371", "size": "400", "side": "BUY", "hash": "345cb43ce9d24f0dd6a23ccbd9372cfdbad4c6c5", "best_bid": "0.571", "best_ask": "0.572"}, {"asset_id": "40081275558852222228080198821361202017557872256707631666334039001378518619916", "price": "0.629", "size": "400", "side": "SELL", "hash": "65b5364538046441e872ccb4553f60a8a95430b1", "best_bid": "0.428", "best_ask": "0.429"}], "timestamp": "1785163872129", "event_type": "price_change"}}
{"ts": 1785163872.635, "kind": "price_change", "data": {"market": "0x18b1c135d0a40c5894da9412e77311827d9caf16cf4cd6591b247a34730af919", "price_changes": [{"asset_id": "40081275558852222228080198821361202017557872256707631666334039001378518619916", "price": "0.505", "size": "0", "side": "SELL", "hash": "be63b056d6489750b1910944b01942fa521c765e", "best_bid": "0.428", "best_ask": "0.429"}, {"asset_id": "78633590736077251574794513664747155551297291244492840448622550955320930591622", "price": "0.495", "size": "0", "side": "BUY", "hash": "f7d1d0a13ad2e8224fe068c90e2ae992dde072b1", "best_bid": "0.571", "best_ask": "0.572"}], "timestamp": "1785163872635", "event_type": "price_change"}}
{"ts": 1785163873.021, "kind": "price_change", "data": {"market": "0x18b1c135d0a40c5894da9412e77311827d9caf16cf4cd6591b247a34730af919", "price_changes": [{"asset_id": "40081275558852222228080198821361202017557872256707631666334039001378518619916", "price": "0.506", "size": "36.7", "side": "SELL", "hash": "092fc596a897584173089bf92d8b903369740fa6", "best_bid": "0.428", "best_ask": "0.429"}, {"asset_id": "78633590736077251574794513664747155551297291244492840448622550955320930591622", "price": "0.494", "size": "36.7", "side": "BUY", "hash": "246c7cc2b592412dc6590b0479fb0c0033cda299", "best_bid": "0.571", "best_ask": "0.572"}], "timestamp": "1785163873021", "event_type": "price_change"}}
{"ts": 1785163873.509, "kind": "price_change", "data": {"market": "0x18b1c135d0a40c5894da9412e77311827d9caf16cf4cd6591b247a34730af919", "price_changes": [{"asset_id": "78633590736077251574794513664747155551297291244492840448622550955320930591622", "price": "0.374", "size": "48.28", "side": "BUY", "hash": "3070ca0bb37e237deaf0e9b5945327d6213bb417", "best_bid": "0.571", "best_ask": "0.572"}, {"asset_id": "40081275558852222228080198821361202017557872256707631666334039001378518619916", "price": "0.626", "size": "48.28", "side": "SELL", "hash": "3b5cf66f1d28e5b1c5dee187075b6d58d79364c1", "best_bid": "0.428", "best_ask": "0.429"}], "timestamp": "1785163873509", "event_type": "price_change"}}
{"ts": 1785163876.995, "kind": "price_change", "data": {"market": "0x0f49db97f71c68b1e42a6d16e3de93d85dbf7d4148e3f018eb79e88554be9f75", "price_changes": [{"asset_id": "87854174148074652060467921081181402357467303721471806610111179101805869578687", "price": "0.03", "size": "0", "side": "BUY", "hash": "5d3b52ef0dd0b052fda1fffcc9b687ea11abe2aa", "best_bid": "0.805", "best_ask": "0.806"}, {"asset_id": "54533043819946592547517511176940999955633860128497669742211153063842200957669", "price": "0.97", "size": "0", "side": "SELL", "hash": "bfa0d962739f886d8b0af01e4593452b8d8943c7", "best_bid": "0.194", "best_ask": "0.195"}], "timestamp": "1785163876995", "event_type": "price_change"}}
{"ts": 1785163877.0, "kind": "price_change", "data": {"market": "0x0f49db97f71c68b1e42a6d16e3de93d85dbf7d4148e3f018eb79e88554be9f75", "price_changes": [{"asset_id": "54533043819946592547517511176940999955633860128497669742211153063842200957669", "price": "0.04", "size": "4050", "side": "BUY", "hash": "62b16c35ec7afca15e8b796f524d6ed331c75dbe", "best_bid": "0.194", "best_ask": "0.195"}, {"asset_id": "87854174148074652060467921081181402357467303721471806610111179101805869578687", "price": "0.96", "size": "4050", "side": "SELL", "hash": "7e99117d5239b33434462f40ddb82cbe03e84f7e", "best_bid": "0.805", "best_ask": "0.806"}], "timestamp": "1785163877000", "event_type": "price_change"}}
{"ts": 1785163878.12, "kind": "price_change", "data": {"market": "0x0f49db97f71c68b1e42a6d16e3de93d85dbf7d4148e3f018eb79e88554be9f75", "price_changes": [{"asset_id": "87854174148074652060467921081181402357467303721471806610111179101805869578687", "price": "0.795", "size": "3127.98", "side": "BUY", "hash": "51e8dcf842a6b7b116e632d377fcf9a94eb15df3", "best_bid": "0.805", "best_ask": "0.806"}, {"asset_id": "54533043819946592547517511176940999955633860128497669742211153063842200957669", "price": "0.205", "size": "3127.98", "side": "SELL", "hash": "40022b8036635620c973336049f744a734ead05d", "best_bid": "0.194", "best_ask": "0.195"}], "timestamp": "1785163878120", "event_type": "price_change"}}
{"ts": 1785163878.191, "kind": "price_change", "data": {"market": "0x0f49db97f71c68b1e42a6d16e3de93d85dbf7d4148e3f018eb79e88554be9f75", "price_changes": [{"asset_id": "87854174148074652060467921081181402357467303721471806610111179101805869578687", "price": "0.795", "size": "3694.98", "side": "BUY", "hash": "aed9ec005120c605142271ab8520719a4fac3e9f", "best_bid": "0.805", "best_ask": "0.806"}, {"asset_id": "54533043819946592547517511176940999955633860128497669742211153063842200957669", "price": "0.205", "size": "3694.98", "side": "SELL", "hash": "4d709ddab5741196292bb510cec8438877afe02f", "best_bid": "0.194", "best_ask": "0.195"}], "timestamp": "1785163878191", "event_type": "price_change"}}
{"ts": 1785163878.643, "kind": "price_change", "data": {"market": "0x18b1c135d0a40c5894da9412e77311827d9caf16cf4cd6591b247a34730af919", "price_changes": [{"asset_id": "40081275558852222228080198821361202017557872256707631666334039001378518619916", "price": "0.418", "size": "5909.45", "side": "BUY", "hash": "1d4aaa4317eba908f13ab327649e61a47f737167", "best_bid": "0.428", "best_ask": "0.429"}, {"asset_id": "78633590736077251574794513664747155551297291244492840448622550955320930591622", "price": "0.582", "size": "5909.45", "side": "SELL", "hash": "6a835a6b1c13a871cb8f937d0deb9702ba742258", "best_bid": "0.571", "best_ask": "0.572"}], "timestamp": "1785163878643", "event_type": "price_change"}}
{"ts": 1785163878.676, "kind": "price_change", "data": {"market": "0x18b1c135d0a40c5894da9412e77311827d9caf16cf4cd6591b247a34730af919", "price_changes": [{"asset_id": "40081275558852222228080198821361202017557872256707631666334039001378518619916", "price": "0.418", "size": "5709.45", "side": "BUY", "hash": "34181c3d8e7dabbe93513c57d9efd7df27527576", "best_bid": "0.428", "best_ask": "0.429"}, {"asset_id": "78633590736077251574794513664747155551297291244492840448622550955320930591622", "price": "0.582", "size": "5709.45", "side": "SELL", "hash": "cbd0f5c58d7244d130ac1e0afe8b4444246f7be1", "best_bid": "0.571", "best_ask": "0.572"}], "timestamp": "1785163878676", "event_type": "price_change"}}
{"ts": 1785163878.709, "kind": "price_change", "data": {"market": "0x18b1c135d0a40c5894da9412e77311827d9caf16cf4cd6591b247a34730af919", "price_changes": [{"asset_id": "40081275558852222228080198821361202017557872256707631666334039001378518619916", "price": "0.417", "size": "1200", "side": "BUY", "hash": "49afead0d69188f16846de3edbc459ba6759f4ed", "best_bid": "0.428", "best_ask": "0.429"}, {"asset_id": "78633590736077251574794513664747155551297291244492840448622550955320930591622", "price": "0.583", "size": "1200", "side": "SELL", "hash": "f50c2e6e4dba41e47b516d5514bc17ce0057c7de", "best_bid": "0.571", "best_ask": "0.572"}], "timestamp": "1785163878709", "event_type": "price_change"}}
{"ts": 1785163878.716, "kind": "price_change", "data": {"market": "0x18b1c135d0a40c5894da9412e77311827d9caf16cf4cd6591b247a34730af919", "price_changes": [{"asset_id": "40081275558852222228080198821361202017557872256707631666334039001378518619916", "price": "0.418", "size": "6787.45", "side": "BUY", "hash": "b55bcc25e196fbba7cf601d33a45b30bbda7b597", "best_bid": "0.428", "best_ask": "0.429"}, {"asset_id": "78633590736077251574794513664747155551297291244492840448622550955320930591622", "price": "0.582", "size": "6787.45", "side": "SELL", "hash": "838715e312b9d94cc173ccdcc376169574070082", "best_bid": "0.571", "best_ask": "0.572"}], "timestamp": "1785163878716", "event_type": "price_change"}}
{"ts": 1785163878.747, "kind": "price_change", "data": {"market": "0x18b1c135d0a40c5894da9412e77311827d9caf16cf4cd6591b247a34730af919", "price_changes": [{"asset_id": "40081275558852222228080198821361202017557872256707631666334039001378518619916", "price": "0.417", "size": "1000", "side": "BUY", "hash": "cc07509c1e1651c37e90e5bea7b75c01902be423", "best_bid": "0.428", "best_ask": "0.429"}, {"asset_id": "78633590736077251574794513664747155551297291244492840448622550955320930591622", "price": "0.583", "size": "1000", "side": "SELL", "hash": "f58a0aaffa77bff943de202ebcabbe7b11685986", "best_bid": "0.571", "best_ask": "0.572"}], "timestamp": "1785163878747", "event_type": "price_change"}}
{"ts": 1785163878.78, "kind": "price_change", "data": {"market": "0x18b1c135d0a40c5894da9412e77311827d9caf16cf4cd6591b247a34730af919", "price_changes": [{"asset_id": "40081275558852222228080198821361202017557872256707631666334039001378518619916", "price": "0.418", "size": "6987.45", "side": "BUY", "hash": "9c09eb56126df7df29a584fdec47909b2273bff3", "best_bid": "0.428", "best_ask": "0.429"}, {"asset_id": "78633590736077251574794513664747155551297291244492840448622550955320930591622", "price": "0.582", "size": "6987.45", "side": "SELL", "hash": "9ae31a11ec7a70dedc8b8457f379c664c481cecb", "best_bid": "0.571", "best_ask": "0.572"}], "timestamp": "1785163878780", "event_type": "price_change"}}
{"ts": 1785163880.071, "kind": "price_change", "data": {"market": "0x18b1c135d0a40c5894da9412e77311827d9caf16cf4cd6591b247a34730af919", "price_changes": [{"asset_id": "78633590736077251574794513664747155551297291244492840448622550955320930591622", "price": "0.482", "size": "201.09", "side": "BUY", "hash": "20840d8dac27984c4c82146f648bd31ce66ac24e", "best_bid": "0.571", "best_ask": "0.572"}, {"asset_id": "40081275558852222228080198821361202017557872256707631666334039001378518619916", "price": "0.518", "size": "201.09", "side": "SELL", "hash": "8ab3fe64016f06ae872e2aef227f84b1342e3513", "best_bid": "0.428", "best_ask": "0.429"}], "timestamp": "1785163880071", "event_type": "price_change"}}
{"ts": 1785163880.08, "kind": "price_change", "data": {"market": "0x18b1c135d0a40c5894da9412e77311827d9caf16cf4cd6591b247a34730af919", "price_changes": [{"asset_id": "78633590736077251574794513664747155551297291244492840448622550955320930591622", "price": "0.485", "size": "77", "side": "BUY", "hash": "2fbb0a4fcdce4ccb00dcebf5ae8bb6a6267d3ac1", "best_bid": "0.571", "best_ask": "0.572"}, {"asset_id": "40081275558852222228080198821361202017557872256707631666334039001378518619916", "price": "0.515", "size": "77", "side": "SELL", "hash": "e5158f60cdce1b2b1f749c63eca7eb7233645576", "best_bid": "0.428", "best_ask": "0.429"}], "timestamp": "1785163880080", "event_type": "price_change"}}
{"ts": 1785163881.996, "kind": "price_change", "data": {"market": "0x18b1c135d0a40c5894da9412e77311827d9caf16cf4cd6591b247a34730af919", "price_changes": [{"asset_id": "40081275558852222228080198821361202017557872256707631666334039001378518619916", "price": "0.41", "size": "2931.23", "side": "BUY", "hash": "24768b411a593cc05c1f486676e612292c965f66", "best_bid": "0.428", "best_ask": "0.429"}, {"asset_id": "78633590736077251574794513664747155551297291244492840448622550955320930591622", "price": "0.59", "size": "2931.23", "side": "SELL", "hash": "537d6d65a2929d45b7db809374b452d6ba613b90", "best_bid": "0.571", "best_ask": "0.572"}], "timestamp": "1785163881996", "event_type": "price_change"}}
{"ts": 1785163882.629, "kind": "price_change", "data": {"market": "0x18b1c135d0a40c5894da9412e77311827d9caf16cf4cd6591b247a34730af919", "price_changes": [{"asset_id": "40081275558852222228080198821361202017557872256707631666334039001378518619916", "price": "0.41", "size": "2947.28", "side": "BUY", "hash": "538b52718fd885fa981f2f31108861fcdd4f680c", "best_bid": "0.428", "best_ask": "0.429"}, {"asset_id": "78633590736077251574794513664747155551297291244492840448622550955320930591622", "price": "0.59", "size": "2947.28", "side": "SELL", "hash": "3d764b0a111074895e04aa5327662aa9e9de48ee", "best_bid": "0.571", "best_ask": "0.572"}], "timestamp": "1785163882629", "event_type": "price_change"}}
{"ts": 1785163883.0, "kind": "price_change", "data": {"market": "0x0f49db97f71c68b1e42a6d16e3de93d85dbf7d4148e3f018eb79e88554be9f75", "price_changes": [{"asset_id": "54533043819946592547517511176940999955633860128497669742211153063842200957669", "price": "0.003", "size": "11073", "side": "BUY", "hash": "c52cd06f706997a96912c92b1d275599cd0e690a", "best_bid": "0.194", "best_ask": "0.195"}, {"asset_id": "87854174148074652060467921081181402357467303721471806610111179101805869578687", "price": "0.997", "size": "11073", "side": "SELL", "hash": "3d95768224ced864e74fea88aa2bf4ec78819a57", "best_bid": "0.805", "best_ask": "0.806"}], "timestamp": "1785163883000", "event_type": "price_change"}}
{"ts": 1785163887.11, "kind": "price_change", "data": {"market": "0x0f49db97f71c68b1e42a6d16e3de93d85dbf7d4148e3f018eb79e88554be9f75", "price_changes": [{"asset_id": "87854174148074652060467921081181402357467303721471806610111179101805869578687", "price": "0.795", "size": "3128.98", "side": "BUY", "hash": "a848df68fa1a7857a2952c6ee6568483d7eb03d2", "best_bid": "0.805", "best_ask": "0.806"}, {"asset_id": "54533043819946592547517511176940999955633860128497669742211153063842200957669", "price": "0.205", "size": "3128.98", "side": "SELL", "hash": "398c556693a3f16651917941335c2d1c4b8d7309", "best_bid": "0.194", "best_ask": "0.195"}], "timestamp": "1785163887110", "event_type": "price_change"}}
{"ts": 1785163887.2, "kind": "price_change", "data": {"market": "0x0f49db97f71c68b1e42a6d16e3de93d85dbf7d4148e3f018eb79e88554be9f75", "price_changes": [{"asset_id": "87854174148074652060467921081181402357467303721471806610111179101805869578687", "price": "0.795", "size": "3694.98", "side": "BUY", "hash": "666074e43ccd6e54954fbc1265bada1eb1e5402c", "best_bid": "0.805", "best_ask": "0.806"}, {"asset_id": "54533043819946592547517511176940999955633860128497669742211153063842200957669", "price": "0.205", "size": "3694.98", "side": "SELL", "hash": "81d72541975d2665f701075fb65aa3fed214bba6", "best_bid": "0.194", "best_ask": "0.195"}], "timestamp": "1785163887200", "event_type": "price_change"}}
{"ts": 1785163887.4115, "kind": "orders_out", "data": [{"token_id": "54533043819946592547517511176940999955633860128497669742211153063842200957669", "side": "BUY", "price": 0.153, "size": 19.61}]}
{"ts": 1785163887.706, "kind": "price_change", "data": {"market": "0x18b1c135d0a40c5894da9412e77311827d9caf16cf4cd6591b247a34730af919", "price_changes": [{"asset_id": "40081275558852222228080198821361202017557872256707631666334039001378518619916", "price": "0.418", "size": "5911.45", "side": "BUY", "hash": "eb0340badd0634f89ed0d7dcc10a7e40019adc5b", "best_bid": "0.428", "best_ask": "0.429"}, {"asset_id": "78633590736077251574794513664747155551297291244492840448622550955320930591622", "price": "0.582", "size": "5911.45", "side": "SELL", "hash": "670ec582b2dc50f458156bfddb16a34253077764", "best_bid": "0.571", "best_ask": "0.572"}], "timestamp": "1785163887706", "event_type": "price_change"}}
{"ts": 1785163887.734, "kind": "price_change", "data": {"market": "0x18b1c135d0a40c5894da9412e77311827d9caf16cf4cd6591b247a34730af919", "price_changes": [{"asset_id": "40081275558852222228080198821361202017557872256707631666334039001378518619916", "price": "0.418", "size": "5711.45", "side": "BUY", "hash": "939a5356cc186bb79adbf00417c10e8e62b9f0db", "best_bid": "0.428", "best_ask": "0.429"}, {"asset_id": "78633590736077251574794513664747155551297291244492840448622550955320930591622", "price": "0.582", "size": "5711.45", "side": "SELL", "hash": "1c5af5a904d85fd3751ef2076c9d4d90a787802f", "best_bid": "0.571", "best_ask": "0.572"}], "timestamp": "1785163887734", "event_type": "price_change"}}
{"ts": 1785163887.769, "kind": "price_change", "data": {"market": "0x18b1c135d0a40c5894da9412e77311827d9caf16cf4cd6591b247a34730af919", "price_changes": [{"asset_id": "40081275558852222228080198821361202017557872256707631666334039001378518619916", "price": "0.417", "size": "1200", "side": "BUY", "hash": "2523342bcf4d3735b5ddf4ca2c719646c2e3cfe6", "best_bid": "0.428", "best_ask": "0.429"}, {"asset_id": "78633590736077251574794513664747155551297291244492840448622550955320930591622", "price": "0.583", "size": "1200", "side": "SELL", "hash": "80e3234a0a765f4e4e4c30af2aa087d5e8fbcf2a", "best_bid": "0.571", "best_ask": "0.572"}], "timestamp": "1785163887769", "event_type": "price_change"}}
{"ts": 1785163887.784, "kind": "price_change", "data": {"market": "0x18b1c135d0a40c5894da9412e77311827d9caf16cf4cd6591b247a34730af919", "price_changes": [{"asset_id": "78633590736077251574794513664747155551297291244492840448622550955320930591622", "price": "0.549", "size": "9.99", "side": "BUY", "hash": "1a618cdb4eff2dc5e8ec545a207f9aff0e4affdb", "best_bid": "0.571", "best_ask": "0.572"}, {"asset_id": "40081275558852222228080198821361202017557872256707631666334039001378518619916", "price": "0.451", "size": "9.99", "side": "SELL", "hash": "c0c586fc1856105afb50e1dc2596dff40741d09f", "best_bid": "0.428", "best_ask": "0.429"}], "timestamp": "1785163887784", "event_type": "price_change"}}
{"ts": 1785163887.789, "kind": "price_change", "data": {"market": "0x18b1c135d0a40c5894da9412e77311827d9caf16cf4cd6591b247a34730af919", "price_changes": [{"asset_id": "40081275558852222228080198821361202017557872256707631666334039001378518619916", "price": "0.418", "size": "6787.45", "side": "BUY", "hash": "52284a7363c252e914ed07dce8106ee84c859f08", "best_bid": "0.428", "best_ask": "0.429"}, {"asset_id": "78633590736077251574794513664747155551297291244492840448622550955320930591622", "price": "0.582", "size": "6787.45", "side": "SELL", "hash": "996ea1970ce5fe338f011124254f039843ebe212", "best_bid": "0.571", "best_ask": "0.572"}], "timestamp": "1785163887789", "event_type": "price_change"}}
{"ts": 1785163887.822, "kind": "price_change", "data": {"market": "0x18b1c135d0a40c5894da9412e77311827d9caf16cf4cd6591b247a34730af919", "price_changes": [{"asset_id": "40081275558852222228080198821361202017557872256707631666334039001378518619916", "price": "0.417", "size": "1000", "side": "BUY", "hash": "0452f3e72d43a1041db4e0df51048e0ed748a0c3", "best_bid": "0.428", "best_ask": "0.429"}, {"asset_id": "78633590736077251574794513664747155551297291244492840448622550955320930591622", "price": "0.583", "size": "1000", "side": "SELL", "hash": "04a37c442a065de98a77b22de1420893196522da", "best_bid": "0.571", "best_ask": "0.572"}], "timestamp": "1785163887822", "event_type": "price_change"}}
{"ts": 1785163887.857, "kind": "price_change", "data": {"market": "0x18b1c135d0a40c5894da9412e77311827d9caf16cf4cd6591b247a34730af919", "price_changes": [{"asset_id": "40081275558852222228080198821361202017557872256707631666334039001378518619916", "price": "0.418", "size": "6987.45", "side": "BUY", "hash": "90dab8ddacf02df215c77e24d198e55dad90c7be", "best_bid": "0.428", "best_ask": "0.429"}, {"asset_id": "78633590736077251574794513664747155551297291244492840448622550955320930591622", "price": "0.582", "size": "6987.45", "side": "SELL", "hash": "7482b02d73e138c164ebfd8267ada08adeebb82d", "best_bid": "0.571", "best_ask": "0.572"}], "timestamp": "1785163887857", "event_type": "price_change"}}
{"ts": 1785163888.19, "kind": "price_change", "data": {"market": "0x18b1c135d0a40c5894da9412e77311827d9caf16cf4cd6591b247a34730af919", "price_changes": [{"asset_id": "40081275558852222228080198821361202017557872256707631666334039001378518619916", "price": "0.506", "size": "0", "side": "SELL", "hash": "a6f319e85e0a37469b0118b9a655f23de81fce65", "best_bid": "0.428", "best_ask": "0.429"}, {"asset_id": "78633590736077251574794513664747155551297291244492840448622550955320930591622", "price": "0.494", "size": "0", "side": "BUY", "hash": "3a271038189b303b42a8486d7369ff4abb2390e3", "best_bid": "0.571", "best_ask": "0.572"}], "timestamp": "1785163888190", "event_type": "price_change"}}
{"ts": 1785163889.003, "kind": "price_change", "data": {"market": "0x18b1c135d0a40c5894da9412e77311827d9caf16cf4cd6591b247a34730af919", "price_changes": [{"asset_id": "40081275558852222228080198821361202017557872256707631666334039001378518619916", "price": "0.171", "size": "0", "side": "BUY", "hash": "d7f56792cb5fe29a01836e5833e971ab50b304fd", "best_bid": "0.428", "best_ask": "0.429"}, {"asset_id": "78633590736077251574794513664747155551297291244492840448622550955320930591622", "price": "0.829", "size": "0", "side": "SELL", "hash": "32392b136592215cccf943942ad08788e1e07027", "best_bid": "0.571", "best_ask": "0.572"}], "timestamp": "1785163889003", "event_type": "price_change"}}
{"ts": 1785163889.003, "kind": "price_change", "data": {"market": "0x18b1c135d0a40c5894da9412e77311827d9caf16cf4cd6591b247a34730af919", "price_changes": [{"asset_id": "40081275558852222228080198821361202017557872256707631666334039001378518619916", "price": "0.171", "size": "0", "side": "BUY", "hash": "d7f56792cb5fe29a01836e5833e971ab50b304fd", "best_bid": "0.428", "best_ask": "0.429"}, {"asset_id": "78633590736077251574794513664747155551297291244492840448622550955320930591622", "price": "0.829", "size": "0", "side": "SELL", "hash": "32392b136592215cccf943942ad08788e1e07027", "best_bid": "0.571", "best_ask": "0.572"}], "timestamp": "1785163889003", "event_type": "price_change"}}
{"ts": 1785163889.346, "kind": "price_change", "data": {"market": "0x18b1c135d0a40c5894da9412e77311827d9caf16cf4cd6591b247a34730af919", "price_changes": [{"asset_id": "40081275558852222228080198821361202017557872256707631666334039001378518619916", "price": "0.505", "size": "36.7", "side": "SELL", "hash": "541bc34708eb01cc7e9ac209f6f2e369f85e7608", "best_bid": "0.428", "best_ask": "0.429"}, {"asset_id": "78633590736077251574794513664747155551297291244492840448622550955320930591622", "price": "0.495", "size": "36.7", "side": "BUY", "hash": "db81500bfa56247c62caccfe6597496fb095ed7d", "best_bid": "0.571", "best_ask": "0.572"}], "timestamp": "1785163889346", "event_type": "price_change"}}
{"ts": 1785163890.356, "kind": "price_change", "data": {"market": "0x18b1c135d0a40c5894da9412e77311827d9caf16cf4cd6591b247a34730af919", "price_changes": [{"asset_id": "40081275558852222228080198821361202017557872256707631666334039001378518619916", "price": "0.421", "size": "1000", "side": "BUY", "hash": "f8c6b31dfaaed0c68c511ed877a2b2b2bff6005d", "best_bid": "0.428", "best_ask": "0.429"}, {"asset_id": "78633590736077251574794513664747155551297291244492840448622550955320930591622", "price": "0.579", "size": "1000", "side": "SELL", "hash": "11f511c7b9d91171b039b411ba5578bef9c83188", "best_bid": "0.571", "best_ask": "0.572"}], "timestamp": "1785163890356", "event_type": "price_change"}}
{"ts": 1785163890.395, "kind": "price_change", "data": {"market": "0x18b1c135d0a40c5894da9412e77311827d9caf16cf4cd6591b247a34730af919", "price_changes": [{"asset_id": "40081275558852222228080198821361202017557872256707631666334039001378518619916", "price": "0.505", "size": "0", "side": "SELL", "hash": "992c15f23917eb1bc323845dea3c25418868a1fa", "best_bid": "0.428", "best_ask": "0.429"}, {"asset_id": "78633590736077251574794513664747155551297291244492840448622550955320930591622", "price": "0.495", "size": "0", "side": "BUY", "hash": "850883c9af67e8225ecfd617c68f47452ecf927f", "best_bid": "0.571", "best_ask": "0.572"}], "timestamp": "1785163890395", "event_type": "price_change"}}
{"ts": 1785163890.739, "kind": "price_change", "data": {"market": "0x18b1c135d0a40c5894da9412e77311827d9caf16cf4cd6591b247a34730af919", "price_changes": [{"asset_id": "40081275558852222228080198821361202017557872256707631666334039001378518619916", "price": "0.506", "size": "36.7", "side": "SELL", "hash": "d65d8b467e76bfc7233262fd328472f7e0cb90ba", "best_bid": "0.428", "best_ask": "0.429"}, {"asset_id": "78633590736077251574794513664747155551297291244492840448622550955320930591622", "price": "0.494", "size": "36.7", "side": "BUY", "hash": "8b8c09b7c518d4c57b49443b8eda533b70d83912", "best_bid": "0.571", "best_ask": "0.572"}], "timestamp": "1785163890739", "event_type": "price_change"}}
{"ts": 1785163892.463, "kind": "price_change", "data": {"market": "0x0f49db97f71c68b1e42a6d16e3de93d85dbf7d4148e3f018eb79e88554be9f75", "price_changes": [{"asset_id": "54533043819946592547517511176940999955633860128497669742211153063842200957669", "price": "0.003", "size": "14406.33", "side": "BUY", "hash": "d33e4939e68e851954c91745f63c18659ef942e8", "best_bid": "0.194", "best_ask": "0.195"}, {"asset_id": "87854174148074652060467921081181402357467303721471806610111179101805869578687", "price": "0.997", "size": "14406.33", "side": "SELL", "hash": "b41e040f4933d3ee8878f7ac7bf3fabae900a774", "best_bid": "0.805", "best_ask": "0.806"}], "timestamp": "1785163892463", "event_type": "price_change"}}
{"ts": 1785163893.002, "kind": "price_change", "data": {"market": "0x18b1c135d0a40c5894da9412e77311827d9caf16cf4cd6591b247a34730af919", "price_changes": [{"asset_id": "40081275558852222228080198821361202017557872256707631666334039001378518619916", "price": "0.28", "size": "0", "side": "BUY", "hash": "1e2f13630697a5bedf3148b01da497f2c5402564", "best_bid": "0.428", "best_ask": "0.429"}, {"asset_id": "78633590736077251574794513664747155551297291244492840448622550955320930591622", "price": "0.72", "size": "0", "side": "SELL", "hash": "5d73a4cb18597104c991ec5ad630eafd557520c5", "best_bid": "0.571", "best_ask": "0.572"}], "timestamp": "1785163893002", "event_type": "price_change"}}
{"ts": 1785163894.596, "kind": "price_change", "data": {"market": "0x18b1c135d0a40c5894da9412e77311827d9caf16cf4cd6591b247a34730af919", "price_changes": [{"asset_id": "40081275558852222228080198821361202017557872256707631666334039001378518619916", "price": "0.421", "size": "1220", "side": "BUY", "hash": "29012eebf0fb4787d307f25c904409ec491d204d", "best_bid": "0.428", "best_ask": "0.429"}, {"asset_id": "78633590736077251574794513664747155551297291244492840448622550955320930591622", "price": "0.579", "size": "1220", "side": "SELL", "hash": "f6b8d306dcbe70df3297ba4be2cc5590c485ae54", "best_bid": "0.571", "best_ask": "0.572"}], "timestamp": "1785163894596", "event_type": "price_change"}}
{"ts": 1785163896.69, "kind": "price_change", "data": {"market": "0x18b1c135d0a40c5894da9412e77311827d9caf16cf4cd6591b247a34730af919", "price_changes": [{"asset_id": "78633590736077251574794513664747155551297291244492840448622550955320930591622", "price": "0.08", "size": "29375", "side": "BUY", "hash": "d96bfbc62b18d691e6ee56fc927cf8c3bf01a9cb", "best_bid": "0.571", "best_ask": "0.572"}, {"asset_id": "40081275558852222228080198821361202017557872256707631666334039001378518619916", "price": "0.92", "size": "29375", "side": "SELL", "hash": "3fbffef5537b651488ab8c700a8d6eef01f5afbc", "best_bid": "0.428", "best_ask": "0.429"}], "timestamp": "1785163896690", "event_type": "price_change"}}
{"ts": 1785163897.38, "kind": "price_change", "data": {"market": "0x0f49db97f71c68b1e42a6d16e3de93d85dbf7d4148e3f018eb79e88554be9f75", "price_changes": [{"asset_id": "87854174148074652060467921081181402357467303721471806610111179101805869578687", "price": "0.001", "size": "6146756.01", "side": "BUY", "hash": "35fcf6c50f85189e11c80edcdb6fc8c1c892501a", "best_bid": "0.805", "best_ask": "0.806"}, {"asset_id": "54533043819946592547517511176940999955633860128497669742211153063842200957669", "price": "0.999", "size": "6146756.01", "side": "SELL", "hash": "f540ba4cd882762db7a53ebfc4f016ec04e2a6fe", "best_bid": "0.194", "best_ask": "0.195"}], "timestamp": "1785163897380", "event_type": "price_change"}}
{"ts": 1785163897.382, "kind": "price_change", "data": {"market": "0x0f49db97f71c68b1e42a6d16e3de93d85dbf7d4148e3f018eb79e88554be9f75", "price_changes": [{"asset_id": "87854174148074652060467921081181402357467303721471806610111179101805869578687", "price": "0.001", "size": "6147766.01", "side": "BUY", "hash": "d52c4a477a94b858a1b703bf9a54e164bbe45084", "best_bid": "0.805", "best_ask": "0.806"}, {"asset_id": "54533043819946592547517511176940999955633860128497669742211153063842200957669", "price": "0.999", "size": "6147766.01", "side": "SELL", "hash": "68f3c25a7cb1bec18498fe6b626484a71b7242f9", "best_bid": "0.194", "best_ask": "0.195"}], "timestamp": "1785163897382", "event_type": "price_change"}}
{"ts": 1785163898.684, "kind": "price_change", "data": {"market": "0x18b1c135d0a40c5894da9412e77311827d9caf16cf4cd6591b247a34730af919", "price_changes": [{"asset_id": "78633590736077251574794513664747155551297291244492840448622550955320930591622", "price": "0.564", "size": "2100", "side": "BUY", "hash": "26bc7c003f29db6a3f1027dfc1bb32871e0f79d4", "best_bid": "0.571", "best_ask": "0.572"}, {"asset_id": "40081275558852222228080198821361202017557872256707631666334039001378518619916", "price": "0.436", "size": "2100", "side": "SELL", "hash": "bba001f96572cade6d545414738766bba03f4d90", "best_bid": "0.428", "best_ask": "0.429"}], "timestamp": "1785163898684", "event_type": "price_change"}}
{"ts": 1785163899.001, "kind": "price_change", "data": {"market": "0x18b1c135d0a40c5894da9412e77311827d9caf16cf4cd6591b247a34730af919", "price_changes": [{"asset_id": "78633590736077251574794513664747155551297291244492840448622550955320930591622", "price": "0.02", "size": "750", "side": "BUY", "hash": "722e642b2d928929c487412c502bbf03066b2ed8", "best_bid": "0.571", "best_ask": "0.572"}, {"asset_id": "40081275558852222228080198821361202017557872256707631666334039001378518619916", "price": "0.98", "size": "750", "side": "SELL", "hash": "4d9bb8dd8d042fa5b33a3ea368636e4292f21cd1", "best_bid": "0.428", "best_ask": "0.429"}], "timestamp": "1785163899001", "event_type": "price_change"}}
{"ts": 1785163899.813, "kind": "price_change", "data": {"market": "0x18b1c135d0a40c5894da9412e77311827d9caf16cf4cd6591b247a34730af919", "price_changes": [{"asset_id": "78633590736077251574794513664747155551297291244492840448622550955320930591622", "price": "0.564", "size": "2320", "side": "BUY", "hash": "c94a853ff2e23a22f605080d503fc0aee25458f0", "best_bid": "0.571", "best_ask": "0.572"}, {"asset_id": "40081275558852222228080198821361202017557872256707631666334039001378518619916", "price": "0.436", "size": "2320", "side": "SELL", "hash": "21bd7059b12a25ff78344a1f0a27d828fd036deb", "best_bid": "0.428", "best_ask": "0.429"}], "timestamp": "1785163899813", "event_type": "price_change"}}
{"ts": 1785163899.871, "kind": "price_change", "data": {"market": "0x18b1c135d0a40c5894da9412e77311827d9caf16cf4cd6591b247a34730af919", "price_changes": [{"asset_id": "40081275558852222228080198821361202017557872256707631666334039001378518619916", "price": "0.41", "size": "2931.23", "side": "BUY", "hash": "6de4abac3d918c8bc6b97b5d730726441594ccaf", "best_bid": "0.428", "best_ask": "0.429"}, {"asset_id": "78633590736077251574794513664747155551297291244492840448622550955320930591622", "price": "0.59", "size": "2931.23", "side": "SELL", "hash": "b07e71df5b1eb2f1d4594a5d2fb648239cdf8d11", "best_bid": "0.571", "best_ask": "0.572"}], "timestamp": "1785163899871", "event_type": "price_change"}}
{"ts": 1785163900.387, "kind": "price_change", "data": {"market": "0x18b1c135d0a40c5894da9412e77311827d9caf16cf4cd6591b247a34730af919", "price_changes": [{"asset_id": "40081275558852222228080198821361202017557872256707631666334039001378518619916", "price": "0.506", "size": "0", "side": "SELL", "hash": "f7b9e6cab0c81665f3ec2baa11495d010302aedb", "best_bid": "0.428", "best_ask": "0.429"}, {"asset_id": "78633590736077251574794513664747155551297291244492840448622550955320930591622", "price": "0.494", "size": "0", "side": "BUY", "hash": "b37497f3a6a08c48954e0eac5b69cde5a41b74db", "best_bid": "0.571", "best_ask": "0.572"}], "timestamp": "1785163900387", "event_type": "price_change"}}
