{"ts": 1785163900.433, "kind": "price_change", "data": {"market": "0x18b1c135d0a40c5894da9412e77311827d9caf16cf4cd6591b247a34730af919", "price_changes": [{"asset_id": "40081275558852222228080198821361202017557872256707631666334039001378518619916", "price": "0.41", "size": "2947.28", "side": "BUY", "hash": "5fd57b412e7c75c8944c4c94f53c9b24e6c05a26", "best_bid": "0.428", "best_ask": "0.429"}, {"asset_id": "78633590736077251574794513664747155551297291244492840448622550955320930591622", "price": "0.59", "size": "2947.28", "side": "SELL", "hash": "c11bfc2bc0be0c0d4eb679fdedec3c769db8dea3", "best_bid": "0.571", "best_ask": "0.572"}], "timestamp": "1785163900433", "event_type": "price_change"}}
{"ts": 1785163900.465, "kind": "price_change", "data": {"market": "0x18b1c135d0a40c5894da9412e77311827d9caf16cf4cd6591b247a34730af919", "price_changes": [{"asset_id": "78633590736077251574794513664747155551297291244492840448622550955320930591622", "price": "0.549", "size": "0", "side": "BUY", "hash": "762fe7a2b5f6af443c4256369d20ebda81ed19a7", "best_bid": "0.571", "best_ask": "0.572"}, {"asset_id": "40081275558852222228080198821361202017557872256707631666334039001378518619916", "price": "0.451", "size": "0", "side": "SELL", "hash": "4ba7152640c9f2b7c149bede0878669093c29869", "best_bid": "0.428", "best_ask": "0.429"}], "timestamp": "1785163900465", "event_type": "price_change"}}
{"ts": 1785163901.0, "kind": "price_change", "data": {"market": "0x18b1c135d0a40c5894da9412e77311827d9caf16cf4cd6591b247a34730af919", "price_changes": [{"asset_id": "78633590736077251574794513664747155551297291244492840448622550955320930591622", "price": "0.08", "size": "16875", "side": "BUY", "hash": "20fe4a3924e8f5b1a187f763f3bc753ee4646ce9", "best_bid": "0.571", "best_ask": "0.572"}, {"asset_id": "40081275558852222228080198821361202017557872256707631666334039001378518619916", "price": "0.92", "size": "16875", "side": "SELL", "hash": "6408324ba2acd6e63788f190b10b8119f9d63a9b", "best_bid": "0.428", "best_ask": "0.429"}], "timestamp": "1785163901000", "event_type": "price_change"}}
{"ts": 1785163901.791, "kind": "price_change", "data": {"market": "0x18b1c135d0a40c5894da9412e77311827d9caf16cf4cd6591b247a34730af919", "price_changes": [{"asset_id": "40081275558852222228080198821361202017557872256707631666334039001378518619916", "price": "0.505", "size": "36.7", "side": "SELL", "hash": "e87897e6d2133f95b9b22b2610448b39ccac996d", "best_bid": "0.428", "best_ask": "0.429"}, {"asset_id": "78633590736077251574794513664747155551297291244492840448622550955320930591622", "price": "0.495", "size": "36.7", "side": "BUY", "hash": "80213c97ac56bb47e65e71f366e347baf561a424", "best_bid": "0.571", "best_ask": "0.572"}], "timestamp": "1785163901791", "event_type": "price_change"}}
{"ts": 1785163903.459, "kind": "price_change", "data": {"market": "0x18b1c135d0a40c5894da9412e77311827d9caf16cf4cd6591b247a34730af919", "price_changes": [{"asset_id": "40081275558852222228080198821361202017557872256707631666334039001378518619916", "price": "0.05", "size": "20000", "side": "BUY", "hash": "af773a23652b62cdbcb33700157f15151023d561", "best_bid": "0.428", "best_ask": "0.429"}, {"asset_id": "78633590736077251574794513664747155551297291244492840448622550955320930591622", "price": "0.95", "size": "20000", "side": "SELL", "hash": "d9851228a66da7bfe9cdce740aa659d868ba82c3", "best_bid": "0.571", "best_ask": "0.572"}], "timestamp": "1785163903459", "event_type": "price_change"}}
{"ts": 1785163903.578, "kind": "price_change", "data": {"market": "0x18b1c135d0a40c5894da9412e77311827d9caf16cf4cd6591b247a34730af919", "price_changes": [{"asset_id": "40081275558852222228080198821361202017557872256707631666334039001378518619916", "price": "0.505", "size": "0", "side": "SELL", "hash": "778ff20ee45eecfa8964b4f70dc4ce8715250c69", "best_bid": "0.428", "best_ask": "0.429"}, {"asset_id": "78633590736077251574794513664747155551297291244492840448622550955320930591622", "price": "0.495", "size": "0", "side": "BUY", "hash": "1dfbe26e07072564c52fa6971fa066555221fa8a", "best_bid": "0.571", "best_ask": "0.572"}], "timestamp": "1785163903578", "event_type": "price_change"}}
{"ts": 1785163903.908, "kind": "price_change", "data": {"market": "0x18b1c135d0a40c5894da9412e77311827d9caf16cf4cd6591b247a34730af919", "price_changes": [{"asset_id": "40081275558852222228080198821361202017557872256707631666334039001378518619916", "price": "0.506", "size": "36.7", "side": "SELL", "hash": "c0aa4c43b4157cebbd03228b86c3de471033ac53", "best_bid": "0.428", "best_ask": "0.429"}, {"asset_id": "78633590736077251574794513664747155551297291244492840448622550955320930591622", "price": "0.494", "size": "36.7", "side": "BUY", "hash": "29d07d4f99eca6f842ee4c59991c4b765e760779", "best_bid": "0.571", "best_ask": "0.572"}], "timestamp": "1785163903908", "event_type": "price_change"}}
{"ts": 1785163908.685, "kind": "price_change", "data": {"market": "0x18b1c135d0a40c5894da9412e77311827d9caf16cf4cd6591b247a34730af919", "price_changes": [{"asset_id": "78633590736077251574794513664747155551297291244492840448622550955320930591622", "price": "0.02", "size": "75750", "side": "BUY", "hash": "ee14b407155e758bb0fa9422cde13c9a4b8f877b", "best_bid": "0.571", "best_ask": "0.572"}, {"asset_id": "40081275558852222228080198821361202017557872256707631666334039001378518619916", "price": "0.98", "size": "75750", "side": "SELL", "hash": "625a4b0d6b72a340edbc627cdeeb234fb7a6c9c1", "best_bid": "0.428", "best_ask": "0.429"}], "timestamp": "1785163908685", "event_type": "price_change"}}
{"ts": 1785163909.992, "kind": "price_change", "data": {"market": "0x18b1c135d0a40c5894da9412e77311827d9caf16cf4cd6591b247a34730af919", "price_changes": [{"asset_id": "40081275558852222228080198821361202017557872256707631666334039001378518619916", "price": "0.418", "size": "7288.45", "side": "BUY", "hash": "a42b4ad38dcfde844ba8deacba2fa53d3042a6d6", "best_bid": "0.428", "best_ask": "0.429"}, {"asset_id": "78633590736077251574794513664747155551297291244492840448622550955320930591622", "price": "0.582", "size": "7288.45", "side": "SELL", "hash": "a0d30308a2a1a79884a7ed55f1789249eb089e69", "best_bid": "0.571", "best_ask": "0.572"}], "timestamp": "1785163909992", "event_type": "price_change"}}
{"ts": 1785163912.577, "kind": "price_change", "data": {"market": "0x18b1c135d0a40c5894da9412e77311827d9caf16cf4cd6591b247a34730af919", "price_changes": [{"asset_id": "78633590736077251574794513664747155551297291244492840448622550955320930591622", "price": "0.57", "size": "4495.84", "side": "BUY", "hash": "534456c8bd0207e71d55ec35b0e60793a6875364", "best_bid": "0.571", "best_ask": "0.572"}, {"asset_id": "40081275558852222228080198821361202017557872256707631666334039001378518619916", "price": "0.43", "size": "4495.84", "side": "SELL", "hash": "0be40ad14ce49a637c6a693689babbda5693d300", "best_bid": "0.428", "best_ask": "0.429"}], "timestamp": "1785163912577", "event_type": "price_change"}}
{"ts": 1785163912.577, "kind": "price_change", "data": {"market": "0x18b1c135d0a40c5894da9412e77311827d9caf16cf4cd6591b247a34730af919", "price_changes": [{"asset_id": "40081275558852222228080198821361202017557872256707631666334039001378518619916", "price": "0.427", "size": "8459.99", "side": "BUY", "hash": "7c4a772da8f1a74693a09a93fa920af5395a77f2", "best_bid": "0.428", "best_ask": "0.429"}, {"asset_id": "78633590736077251574794513664747155551297291244492840448622550955320930591622", "price": "0.573", "size": "8459.99", "side": "SELL", "hash": "9675ab7df78845b1006228911b8018db85592bc3", "best_bid": "0.571", "best_ask": "0.572"}], "timestamp": "1785163912577", "event_type": "price_change"}}
{"ts": 1785163915.595, "kind": "price_change", "data": {"market": "0x18b1c135d0a40c5894da9412e77311827d9caf16cf4cd6591b247a34730af919", "price_changes": [{"asset_id": "40081275558852222228080198821361202017557872256707631666334039001378518619916", "price": "0.417", "size": "1201", "side": "BUY", "hash": "efb6a3d44a6becf98f904ecf9eb4d842367bfd9b", "best_bid": "0.428", "best_ask": "0.429"}, {"asset_id": "78633590736077251574794513664747155551297291244492840448622550955320930591622", "price": "0.583", "size": "1201", "side": "SELL", "hash": "85b18135ab861a89b4342896bf869f6381ac3555", "best_bid": "0.571", "best_ask": "0.572"}], "timestamp": "1785163915595", "event_type": "price_change"}}
{"ts": 1785163915.657, "kind": "price_change", "data": {"market": "0x0f49db97f71c68b1e42a6d16e3de93d85dbf7d4148e3f018eb79e88554be9f75", "price_changes": [{"asset_id": "54533043819946592547517511176940999955633860128497669742211153063842200957669", "price": "0.009", "size": "13888.88", "side": "BUY", "hash": "d32cc2eb1f9b859ab0469639ed72787630c59585", "best_bid": "0.194", "best_ask": "0.195"}, {"asset_id": "87854174148074652060467921081181402357467303721471806610111179101805869578687", "price": "0.991", "size": "13888.88", "side": "SELL", "hash": "8663c320eb8ad3c461bbdc7ab157f7056a922b68", "best_bid": "0.805", "best_ask": "0.806"}], "timestamp": "1785163915657", "event_type": "price_change"}}
{"ts": 1785163915.662, "kind": "price_change", "data": {"market": "0x0f49db97f71c68b1e42a6d16e3de93d85dbf7d4148e3f018eb79e88554be9f75", "price_changes": [{"asset_id": "54533043819946592547517511176940999955633860128497669742211153063842200957669", "price": "0.007", "size": "53571.42", "side": "BUY", "hash": "55e2cf200f5d162b74fd4c5e937c33a2112e5d38", "best_bid": "0.194", "best_ask": "0.195"}, {"asset_id": "87854174148074652060467921081181402357467303721471806610111179101805869578687", "price": "0.993", "size": "53571.42", "side": "SELL", "hash": "257134d6d644fd74ed28d42e0858f2b838a87629", "best_bid": "0.805", "best_ask": "0.806"}], "timestamp": "1785163915662", "event_type": "price_change"}}
{"ts": 1785163915.9590201, "kind": "orders_out", "data": [{"token_id": "54533043819946592547517511176940999955633860128497669742211153063842200957669", "side": "BUY", "price": 0.153, "size": 19.61}]}
{"ts": 1785163916.0, "kind": "price_change", "data": {"market": "0x18b1c135d0a40c5894da9412e77311827d9caf16cf4cd6591b247a34730af919", "price_changes": [{"asset_id": "40081275558852222228080198821361202017557872256707631666334039001378518619916", "price": "0.003", "size": "11000", "side": "BUY", "hash": "7f39f2df13cbc593bd2a6f5d89586666ec4083bd", "best_bid": "0.428", "best_ask": "0.429"}, {"asset_id": "78633590736077251574794513664747155551297291244492840448622550955320930591622", "price": "0.997", "size": "11000", "side": "SELL", "hash": "f2c5a24234bf6a69ef3c7db0282c5d23f3348c80", "best_bid": "0.571", "best_ask": "0.572"}], "timestamp": "1785163916000", "event_type": "price_change"}}
{"ts": 1785163918.642, "kind": "price_change", "data": {"market": "0x18b1c135d0a40c5894da9412e77311827d9caf16cf4cd6591b247a34730af919", "price_changes": [{"asset_id": "40081275558852222228080198821361202017557872256707631666334039001378518619916", "price": "0.41", "size": "2931.23", "side": "BUY", "hash": "d3edaf6151b8dc3c2a812e767646cc75488b31b1", "best_bid": "0.428", "best_ask": "0.429"}, {"asset_id": "78633590736077251574794513664747155551297291244492840448622550955320930591622", "price": "0.59", "size": "2931.23", "side": "SELL", "hash": "da4076cb9713813277977f3e36350f2e14d377b0", "best_bid": "0.571", "best_ask": "0.572"}], "timestamp": "1785163918642", "event_type": "price_change"}}
{"ts": 1785163918.964, "kind": "price_change", "data": {"market": "0x0f49db97f71c68b1e42a6d16e3de93d85dbf7d4148e3f018eb79e88554be9f75", "price_changes": [{"asset_id": "54533043819946592547517511176940999955633860128497669742211153063842200957669", "price": "0.04", "size": "300", "side": "BUY", "hash": "43a09baa948445c04581412e6dda6686a00b02ff", "best_bid": "0.194", "best_ask": "0.195"}, {"asset_id": "87854174148074652060467921081181402357467303721471806610111179101805869578687", "price": "0.96", "size": "300", "side": "SELL", "hash": "d24a3f6b1fedd64c498488a369e2e79eda2c60a6", "best_bid": "0.805", "best_ask": "0.806"}], "timestamp": "1785163918964", "event_type": "price_change"}}
{"ts": 1785163918.97, "kind": "price_change", "data": {"market": "0x0f49db97f71c68b1e42a6d16e3de93d85dbf7d4148e3f018eb79e88554be9f75", "price_changes": [{"asset_id": "54533043819946592547517511176940999955633860128497669742211153063842200957669", "price": "0.02", "size": "8000", "side": "BUY", "hash": "68a72c3f34a40af43ffc4ce151b21c36972a90be", "best_bid": "0.194", "best_ask": "0.195"}, {"asset_id": "87854174148074652060467921081181402357467303721471806610111179101805869578687", "price": "0.98", "size": "8000", "side": "SELL", "hash": "ff931a0898a6958e10e343ddafdded1486d904b2", "best_bid": "0.805", "best_ask": "0.806"}], "timestamp": "1785163918970", "event_type": "price_change"}}
{"ts": 1785163919.115, "kind": "price_change", "data": {"market": "0x18b1c135d0a40c5894da9412e77311827d9caf16cf4cd6591b247a34730af919", "price_changes": [{"asset_id": "40081275558852222228080198821361202017557872256707631666334039001378518619916", "price": "0.41", "size": "2947.28", "side": "BUY", "hash": "f4fde11d2e8b286e36b1cd5f91b38ca95b3ee587", "best_bid": "0.428", "best_ask": "0.429"}, {"asset_id": "78633590736077251574794513664747155551297291244492840448622550955320930591622", "price": "0.59", "size": "2947.28", "side": "SELL", "hash": "24acbc59447e92964b98c0dbe4d75683400dc010", "best_bid": "0.571", "best_ask": "0.572"}], "timestamp": "1785163919115", "event_type": "price_change"}}
{"ts": 1785163919.187, "kind": "price_change", "data": {"market": "0x18b1c135d0a40c5894da9412e77311827d9caf16cf4cd6591b247a34730af919", "price_changes": [{"asset_id": "78633590736077251574794513664747155551297291244492840448622550955320930591622", "price": "0.549", "size": "9.99", "side": "BUY", "hash": "7ab6beab52927c4ddff0c54842ad74df1348d16e", "best_bid": "0.571", "best_ask": "0.572"}, {"asset_id": "40081275558852222228080198821361202017557872256707631666334039001378518619916", "price": "0.451", "size": "9.99", "side": "SELL", "hash": "2876d9e1df29f96223e3c39c1172556b23ed7897", "best_bid": "0.428", "best_ask": "0.429"}], "timestamp": "1785163919187", "event_type": "price_change"}}
{"ts": 1785163919.598, "kind": "price_change", "data": {"market": "0x18b1c135d0a40c5894da9412e77311827d9caf16cf4cd6591b247a34730af919", "price_changes": [{"asset_id": "78633590736077251574794513664747155551297291244492840448622550955320930591622", "price": "0.561", "size": "12268.8", "side": "BUY", "hash": "bfcfe9fc91c0f2a41266b6612be75f58d2b30756", "best_bid": "0.571", "best_ask": "0.572"}, {"asset_id": "40081275558852222228080198821361202017557872256707631666334039001378518619916", "price": "0.439", "size": "12268.8", "side": "SELL", "hash": "d241a64f629e5a54cd64372455881565d373aafd", "best_bid": "0.428", "best_ask": "0.429"}], "timestamp": "1785163919598", "event_type": "price_change"}}
{"ts": 1785163921.574, "kind": "price_change", "data": {"market": "0x0f49db97f71c68b1e42a6d16e3de93d85dbf7d4148e3f018eb79e88554be9f75", "price_changes": [{"asset_id": "54533043819946592547517511176940999955633860128497669742211153063842200957669", "price": "0.007", "size": "0", "side": "BUY", "hash": "ad5dfdfca93ea2518539e7185afa1e454585456a", "best_bid": "0.194", "best_ask": "0.195"}, {"asset_id": "87854174148074652060467921081181402357467303721471806610111179101805869578687", "price": "0.993", "size": "0", "side": "SELL", "hash": "d982a0c03e798a710232fe0d4ee6b1fd49e6ac3f", "best_bid": "0.805", "best_ask": "0.806"}], "timestamp": "1785163921574", "event_type": "price_change"}}
{"ts": 1785163921.574, "kind": "price_change", "data": {"market": "0x0f49db97f71c68b1e42a6d16e3de93d85dbf7d4148e3f018eb79e88554be9f75", "price_changes": [{"asset_id": "54533043819946592547517511176940999955633860128497669742211153063842200957669", "price": "0.009", "size": "0", "side": "BUY", "hash": "ad5dfdfca93ea2518539e7185afa1e454585456a", "best_bid": "0.194", "best_ask": "0.195"}, {"asset_id": "87854174148074652060467921081181402357467303721471806610111179101805869578687", "price": "0.991", "size": "0", "side": "SELL", "hash": "d982a0c03e798a710232fe0d4ee6b1fd49e6ac3f", "best_bid": "0.805", "best_ask": "0.806"}], "timestamp": "1785163921574", "event_type": "price_change"}}
{"ts": 1785163921.66, "kind": "price_change", "data": {"market": "0x18b1c135d0a40c5894da9412e77311827d9caf16cf4cd6591b247a34730af919", "price_changes": [{"asset_id": "40081275558852222228080198821361202017557872256707631666334039001378518619916", "price": "0.506", "size": "0", "side": "SELL", "hash": "ee206dffbe1d3237357e9281b2848ebb2ff368c4", "best_bid": "0.428", "best_ask": "0.429"}, {"asset_id": "78633590736077251574794513664747155551297291244492840448622550955320930591622", "price": "0.494", "size": "0", "side": "BUY", "hash": "5b8228028491970e2e4bff49ff017ad59f3b23eb", "best_bid": "0.571", "best_ask": "0.572"}], "timestamp": "1785163921660", "event_type": "price_change"}}
{"ts": 1785163921.737, "kind": "price_change", "data": {"market": "0x18b1c135d0a40c5894da9412e77311827d9caf16cf4cd6591b247a34730af919", "price_changes": [{"asset_id": "78633590736077251574794513664747155551297291244492840448622550955320930591622", "price": "0.549", "size": "0", "side": "BUY", "hash": "8f7d68842100546f47f3544df469118763fabd03", "best_bid": "0.571", "best_ask": "0.572"}, {"asset_id": "40081275558852222228080198821361202017557872256707631666334039001378518619916", "price": "0.451", "size": "0", "side": "SELL", "hash": "9e008581a6fb866fc7ed567629734e60d40be91b", "best_bid": "0.428", "best_ask": "0.429"}], "timestamp": "1785163921737", "event_type": "price_change"}}
{"ts": 1785163922.344, "kind": "price_change", "data": {"market": "0x18b1c135d0a40c5894da9412e77311827d9caf16cf4cd6591b247a34730af919", "price_changes": [{"asset_id": "40081275558852222228080198821361202017557872256707631666334039001378518619916", "price": "0.003", "size": "19333.33", "side": "BUY", "hash": "f5af5b94fbcb1e1bc8a84671ae1389a89bd337ef", "best_bid": "0.428", "best_ask": "0.429"}, {"asset_id": "78633590736077251574794513664747155551297291244492840448622550955320930591622", "price": "0.997", "size": "19333.33", "side": "SELL", "hash": "7cd3f8b599748c95f301202e41f5ae737e3ab4cb", "best_bid": "0.571", "best_ask": "0.572"}], "timestamp": "1785163922344", "event_type": "price_change"}}
{"ts": 1785163922.475, "kind": "price_change", "data": {"market": "0x18b1c135d0a40c5894da9412e77311827d9caf16cf4cd6591b247a34730af919", "price_changes": [{"asset_id": "78633590736077251574794513664747155551297291244492840448622550955320930591622", "price": "0.561", "size": "11868.8", "side": "BUY", "hash": "98ef1b4526931dc4af0bdf84013fb0fbab5c90ea", "best_bid": "0.571", "best_ask": "0.572"}, {"asset_id": "40081275558852222228080198821361202017557872256707631666334039001378518619916", "price": "0.439", "size": "11868.8", "side": "SELL", "hash": "37a44e5652112292e30db2ba2336e9e4368727b9", "best_bid": "0.428", "best_ask": "0.429"}], "timestamp": "1785163922475", "event_type": "price_change"}}
{"ts": 1785163922.475, "kind": "price_change", "data": {"market": "0x18b1c135d0a40c5894da9412e77311827d9caf16cf4cd6591b247a34730af919", "price_changes": [{"asset_id": "40081275558852222228080198821361202017557872256707631666334039001378518619916", "price": "0.418", "size": "6888.45", "side": "BUY", "hash": "37a44e5652112292e30db2ba2336e9e4368727b9", "best_bid": "0.428", "best_ask": "0.429"}, {"asset_id": "78633590736077251574794513664747155551297291244492840448622550955320930591622", "price": "0.582", "size": "6888.45", "side": "SELL", "hash": "98ef1b4526931dc4af0bdf84013fb0fbab5c90ea", "best_bid": "0.571", "best_ask": "0.572"}], "timestamp": "1785163922475", "event_type": "price_change"}}
{"ts": 1785163922.843, "kind": "price_change", "data": {"market": "0x18b1c135d0a40c5894da9412e77311827d9caf16cf4cd6591b247a34730af919", "price_changes": [{"asset_id": "40081275558852222228080198821361202017557872256707631666334039001378518619916", "price": "0.505", "size": "36.7", "side": "SELL", "hash": "185ad5f6392a7717c8522b7d75cd2c76141dfab7", "best_bid": "0.428", "best_ask": "0.429"}, {"asset_id": "78633590736077251574794513664747155551297291244492840448622550955320930591622", "price": "0.495", "size": "36.7", "side": "BUY", "hash": "afbc636fcb777ccd68feafaa2fe1ce500d14e86d", "best_bid": "0.571", "best_ask": "0.572"}], "timestamp": "1785163922843", "event_type": "price_change"}}
{"ts": 1785163924.138, "kind": "price_change", "data": {"market": "0x18b1c135d0a40c5894da9412e77311827d9caf16cf4cd6591b247a34730af919", "price_changes": [{"asset_id": "40081275558852222228080198821361202017557872256707631666334039001378518619916", "price": "0.505", "size": "0", "side": "SELL", "hash": "10c4c1c0aaef350f20429a24a917e40823339760", "best_bid": "0.428", "best_ask": "0.429"}, {"asset_id": "78633590736077251574794513664747155551297291244492840448622550955320930591622", "price": "0.495", "size": "0", "side": "BUY", "hash": "e2c80b2ec0ddcdcec81123e78c2792ae62ca05b3", "best_bid": "0.571", "best_ask": "0.572"}], "timestamp": "1785163924138", "event_type": "price_change"}}
{"ts": 1785163924.539, "kind": "price_change", "data": {"market": "0x18b1c135d0a40c5894da9412e77311827d9caf16cf4cd6591b247a34730af919", "price_changes": [{"asset_id": "40081275558852222228080198821361202017557872256707631666334039001378518619916", "price": "0.506", "size": "36.7", "side": "SELL", "hash": "0e84a0b791ab3b42faec355c840f6958c46513f8", "best_bid": "0.428", "best_ask": "0.429"}, {"asset_id": "78633590736077251574794513664747155551297291244492840448622550955320930591622", "price": "0.494", "size": "36.7", "side": "BUY", "hash": "fae220fcd3b7ba1df98905ac120aeef537b6bca6", "best_bid": "0.571", "best_ask": "0.572"}], "timestamp": "1785163924539", "event_type": "price_change"}}
{"ts": 1785163927.0, "kind": "price_change", "data": {"market": "0x0f49db97f71c68b1e42a6d16e3de93d85dbf7d4148e3f018eb79e88554be9f75", "price_changes": [{"asset_id": "54533043819946592547517511176940999955633860128497669742211153063842200957669", "price": "0.193", "size": "10894", "side": "BUY", "hash": "77c18e86c45fad8d1222460a927a8f045aeb52fb", "best_bid": "0.194", "best_ask": "0.195"}, {"asset_id": "87854174148074652060467921081181402357467303721471806610111179101805869578687", "price": "0.807", "size": "10894", "side": "SELL", "hash": "1206a012405ad8d1a837715f7e696d8cc4866b32", "best_bid": "0.805", "best_ask": "0.806"}], "timestamp": "1785163927000", "event_type": "price_change"}}
{"ts": 1785163927.0, "kind": "price_change", "data": {"market": "0x0f49db97f71c68b1e42a6d16e3de93d85dbf7d4148e3f018eb79e88554be9f75", "price_changes": [{"asset_id": "87854174148074652060467921081181402357467303721471806610111179101805869578687", "price": "0.803", "size": "12234.97", "side": "BUY", "hash": "1206a012405ad8d1a837715f7e696d8cc4866b32", "best_bid": "0.805", "best_ask": "0.806"}, {"asset_id": "54533043819946592547517511176940999955633860128497669742211153063842200957669", "price": "0.197", "size": "12234.97", "side": "SELL", "hash": "77c18e86c45fad8d1222460a927a8f045aeb52fb", "best_bid": "0.194", "best_ask": "0.195"}], "timestamp": "1785163927000", "event_type": "price_change"}}
{"ts": 1785163927.002, "kind": "price_change", "data": {"market": "0x0f49db97f71c68b1e42a6d16e3de93d85dbf7d4148e3f018eb79e88554be9f75", "price_changes": [{"asset_id": "54533043819946592547517511176940999955633860128497669742211153063842200957669", "price": "0.193", "size": "10894", "side": "BUY", "hash": "2ee649908ac545a2ce280ae02cdaac2e934bec64", "best_bid": "0.194", "best_ask": "0.195"}, {"asset_id": "87854174148074652060467921081181402357467303721471806610111179101805869578687", "price": "0.807", "size": "10894", "side": "SELL", "hash": "5c08b2b45f5e499dfc571b5759aeb50aa941fe5b", "best_bid": "0.805", "best_ask": "0.806"}], "timestamp": "1785163927002", "event_type": "price_change"}}
{"ts": 1785163927.003, "kind": "price_change", "data": {"market": "0x0f49db97f71c68b1e42a6d16e3de93d85dbf7d4148e3f018eb79e88554be9f75", "price_changes": [{"asset_id": "87854174148074652060467921081181402357467303721471806610111179101805869578687", "price": "0.803", "size": "12234.97", "side": "BUY", "hash": "bcef7a21edd5798da2b6275c43db7bcbb2d6900f", "best_bid": "0.805", "best_ask": "0.806"}, {"asset_id": "54533043819946592547517511176940999955633860128497669742211153063842200957669", "price": "0.197", "size": "12234.97", "side": "SELL", "hash": "1eb8f49ec1c611f0e63da5ff1b16e5602aa153e3", "best_bid": "0.194", "best_ask": "0.195"}], "timestamp": "1785163927003", "event_type": "price_change"}}
{"ts": 1785163927.037, "kind": "price_change", "data": {"market": "0x0f49db97f71c68b1e42a6d16e3de93d85dbf7d4148e3f018eb79e88554be9f75", "price_changes": [{"asset_id": "54533043819946592547517511176940999955633860128497669742211153063842200957669", "price": "0.193", "size": "10994", "side": "BUY", "hash": "f40f15eab4fcfd6a189b7553649af481edf1ed6b", "best_bid": "0.194", "best_ask": "0.195"}, {"asset_id": "87854174148074652060467921081181402357467303721471806610111179101805869578687", "price": "0.807", "size": "10994", "side": "SELL", "hash": "67efee78519803421151021e7b2abd04d2fc1036", "best_bid": "0.805", "best_ask": "0.806"}], "timestamp": "1785163927037", "event_type": "price_change"}}
{"ts": 1785163927.04, "kind": "price_change", "data": {"market": "0x0f49db97f71c68b1e42a6d16e3de93d85dbf7d4148e3f018eb79e88554be9f75", "price_changes": [{"asset_id": "87854174148074652060467921081181402357467303721471806610111179101805869578687", "price": "0.803", "size": "12334.97", "side": "BUY", "hash": "f31900da371f427d656c772dd0f506f02532b5ea", "best_bid": "0.805", "best_ask": "0.806"}, {"asset_id": "54533043819946592547517511176940999955633860128497669742211153063842200957669", "price": "0.197", "size": "12334.97", "side": "SELL", "hash": "7b4c23474937ff117f1b5ff1e0223f1c7c362d35", "best_bid": "0.194", "best_ask": "0.195"}], "timestamp": "1785163927040", "event_type": "price_change"}}
{"ts": 1785163927.051, "kind": "price_change", "data": {"market": "0x0f49db97f71c68b1e42a6d16e3de93d85dbf7d4148e3f018eb79e88554be9f75", "price_changes": [{"asset_id": "54533043819946592547517511176940999955633860128497669742211153063842200957669", "price": "0.193", "size": "11094", "side": "BUY", "hash": "d21c63db7db0cbeb3c241a57e918c8192a10956d", "best_bid": "0.194", "best_ask": "0.195"}, {"asset_id": "87854174148074652060467921081181402357467303721471806610111179101805869578687", "price": "0.807", "size": "11094", "side": "SELL", "hash": "0957ee2890aea337d8c23a0cf25fb12d0d80ecd3", "best_bid": "0.805", "best_ask": "0.806"}], "timestamp": "1785163927051", "event_type": "price_change"}}
{"ts": 1785163927.053, "kind": "price_change", "data": {"market": "0x0f49db97f71c68b1e42a6d16e3de93d85dbf7d4148e3f018eb79e88554be9f75", "price_changes": [{"asset_id": "87854174148074652060467921081181402357467303721471806610111179101805869578687", "price": "0.803", "size": "12434.97", "side": "BUY", "hash": "74a824cca4edc6f9ee36d4ade33f3081b1a5a17b", "best_bid": "0.805", "best_ask": "0.806"}, {"asset_id": "54533043819946592547517511176940999955633860128497669742211153063842200957669", "price": "0.197", "size": "12434.97", "side": "SELL", "hash": "0e2d47a056353c61c940571544c0a907d79ad926", "best_bid": "0.194", "best_ask": "0.195"}], "timestamp": "1785163927053", "event_type": "price_change"}}
{"ts": 1785163927.141, "kind": "price_change", "data": {"market": "0x0f49db97f71c68b1e42a6d16e3de93d85dbf7d4148e3f018eb79e88554be9f75", "price_changes": [{"asset_id": "54533043819946592547517511176940999955633860128497669742211153063842200957669", "price": "0.02", "size": "500", "side": "BUY", "hash": "a0992f56abadb65f72f1c76b5dea5c95ab45e3ae", "best_bid": "0.194", "best_ask": "0.195"}, {"asset_id": "87854174148074652060467921081181402357467303721471806610111179101805869578687", "price": "0.98", "size": "500", "side": "SELL", "hash": "877e3075a12a2df23cb8f76b7b8c235838662498", "best_bid": "0.805", "best_ask": "0.806"}], "timestamp": "1785163927141", "event_type": "price_change"}}
{"ts": 1785163927.152, "kind": "price_change", "data": {"market": "0x0f49db97f71c68b1e42a6d16e3de93d85dbf7d4148e3f018eb79e88554be9f75", "price_changes": [{"asset_id": "54533043819946592547517511176940999955633860128497669742211153063842200957669", "price": "0.04", "size": "4050", "side": "BUY", "hash": "f9c8b7cfc49afd8498ec2491b30c80efa16bb785", "best_bid": "0.194", "best_ask": "0.195"}, {"asset_id": "87854174148074652060467921081181402357467303721471806610111179101805869578687", "price": "0.96", "size": "4050", "side": "SELL", "hash": "cd55c6ec35543edc7ba8026da1154681f367781c", "best_bid": "0.805", "best_ask": "0.806"}], "timestamp": "1785163927152", "event_type": "price_change"}}
{"ts": 1785163930.514, "kind": "price_change", "data": {"market": "0x18b1c135d0a40c5894da9412e77311827d9caf16cf4cd6591b247a34730af919", "price_changes": [{"asset_id": "40081275558852222228080198821361202017557872256707631666334039001378518619916", "price": "0.506", "size": "0", "side": "SELL", "hash": "9e8ef3f328d1064366c3ad87099393feb6193c2e", "best_bid": "0.428", "best_ask": "0.429"}, {"asset_id": "78633590736077251574794513664747155551297291244492840448622550955320930591622", "price": "0.494", "size": "0", "side": "BUY", "hash": "97c45e9a7875935ebd2e4c5d13e839fe9c8edfa8", "best_bid": "0.571", "best_ask": "0.572"}], "timestamp": "1785163930514", "event_type": "price_change"}}
{"ts": 1785163931.0, "kind": "price_change", "data": {"market": "0x0f49db97f71c68b1e42a6d16e3de93d85dbf7d4148e3f018eb79e88554be9f75", "price_changes": [{"asset_id": "54533043819946592547517511176940999955633860128497669742211153063842200957669", "price": "0.184", "size": "1082", "side": "BUY", "hash": "69f550fdd585c45acee1ee80e5e15009cfac324f", "best_bid": "0.194", "best_ask": "0.195"}, {"asset_id": "87854174148074652060467921081181402357467303721471806610111179101805869578687", "price": "0.816", "size": "1082", "side": "SELL", "hash": "507638f73a7ffaf688587e7664941532a94ec6b2", "best_bid": "0.805", "best_ask": "0.806"}], "timestamp": "1785163931000", "event_type": "price_change"}}
{"ts": 1785163931.30585, "kind": "orders_out", "data": [{"token_id": "54533043819946592547517511176940999955633860128497669742211153063842200957669", "side": "BUY", "price": 0.153, "size": 19.61}]}
{"ts": 1785163931.501, "kind": "price_change", "data": {"market": "0x18b1c135d0a40c5894da9412e77311827d9caf16cf4cd6591b247a34730af919", "price_changes": [{"asset_id": "40081275558852222228080198821361202017557872256707631666334039001378518619916", "price": "0.505", "size": "36.7", "side": "SELL", "hash": "e824d670e076afd49902b17fbc5bd331f26711a4", "best_bid": "0.428", "best_ask": "0.429"}, {"asset_id": "78633590736077251574794513664747155551297291244492840448622550955320930591622", "price": "0.495", "size": "36.7", "side": "BUY", "hash": "e49f22d22ea869778bbd410e775f3e04aa52a339", "best_bid": "0.571", "best_ask": "0.572"}], "timestamp": "1785163931501", "event_type": "price_change"}}
{"ts": 1785163932.0, "kind": "price_change", "data": {"market": "0x18b1c135d0a40c5894da9412e77311827d9caf16cf4cd6591b247a34730af919", "price_changes": [{"asset_id": "78633590736077251574794513664747155551297291244492840448622550955320930591622", "price": "0.55", "size": "30179.18", "side": "BUY", "hash": "1f745aa5621978240c90d24ee6d93ee53a6b481d", "best_bid": "0.571", "best_ask": "0.572"}, {"asset_id": "40081275558852222228080198821361202017557872256707631666334039001378518619916", "price": "0.45", "size": "30179.18", "side": "SELL", "hash": "284611772a833702ff1fa9861bff5f9a0eeeecea", "best_bid": "0.428", "best_ask": "0.429"}], "timestamp": "1785163932000", "event_type": "price_change"}}
{"ts": 1785163932.001, "kind": "price_change", "data": {"market": "0x18b1c135d0a40c5894da9412e77311827d9caf16cf4cd6591b247a34730af919", "price_changes": [{"asset_id": "40081275558852222228080198821361202017557872256707631666334039001378518619916", "price": "0.412", "size": "11123.8", "side": "BUY", "hash": "fa306a9f91c31d8e01fb332bd96fb5e399b7fc37", "best_bid": "0.428", "best_ask": "0.429"}, {"asset_id": "78633590736077251574794513664747155551297291244492840448622550955320930591622", "price": "0.588", "size": "11123.8", "side": "SELL", "hash": "bc7da98105e745d358988c6ea0d67a34a9839c33", "best_bid": "0.571", "best_ask": "0.572"}], "timestamp": "1785163932001", "event_type": "price_change"}}
{"ts": 1785163932.002, "kind": "price_change", "data": {"market": "0x18b1c135d0a40c5894da9412e77311827d9caf16cf4cd6591b247a34730af919", "price_changes": [{"asset_id": "78633590736077251574794513664747155551297291244492840448622550955320930591622", "price": "0.551", "size": "28710.16", "side": "BUY", "hash": "b8f30a08a3d3905e25b12d50e67e8c4bdab8bdcd", "best_bid": "0.571", "best_ask": "0.572"}, {"asset_id": "40081275558852222228080198821361202017557872256707631666334039001378518619916", "price": "0.449", "size": "28710.16", "side": "SELL", "hash": "1735688346ec9ef3ed8a0a7b9eb53f85987c9fc1", "best_bid": "0.428", "best_ask": "0.429"}], "timestamp": "1785163932002", "event_type": "price_change"}}
{"ts": 1785163932.041, "kind": "price_change", "data": {"market": "0x18b1c135d0a40c5894da9412e77311827d9caf16cf4cd6591b247a34730af919", "price_changes": [{"asset_id": "78633590736077251574794513664747155551297291244492840448622550955320930591622", "price": "0.55", "size": "30379.18", "side": "BUY", "hash": "4edade3dc0519752d1799f948452539ced780ebf", "best_bid": "0.571", "best_ask": "0.572"}, {"asset_id": "40081275558852222228080198821361202017557872256707631666334039001378518619916", "price": "0.45", "size": "30379.18", "side": "SELL", "hash": "8430af620362052ad2358a2d61cb926531c547ee", "best_bid": "0.428", "best_ask": "0.429"}], "timestamp": "1785163932041", "event_type": "price_change"}}
{"ts": 1785163932.044, "kind": "price_change", "data": {"market": "0x18b1c135d0a40c5894da9412e77311827d9caf16cf4cd6591b247a34730af919", "price_changes": [{"asset_id": "40081275558852222228080198821361202017557872256707631666334039001378518619916", "price": "0.412", "size": "11323.8", "side": "BUY", "hash": "db8657822544dffa7401e7ad8ddb69451825087c", "best_bid": "0.428", "best_ask": "0.429"}, {"asset_id": "78633590736077251574794513664747155551297291244492840448622550955320930591622", "price": "0.588", "size": "11323.8", "side": "SELL", "hash": "4422433acf4f6a0a6e0be55ef53760b8767070e7", "best_bid": "0.571", "best_ask": "0.572"}], "timestamp": "1785163932044", "event_type": "price_change"}}
{"ts": 1785163932.052, "kind": "price_change", "data": {"market": "0x18b1c135d0a40c5894da9412e77311827d9caf16cf4cd6591b247a34730af919", "price_changes": [{"asset_id": "78633590736077251574794513664747155551297291244492840448622550955320930591622", "price": "0.551", "size": "28910.16", "side": "BUY", "hash": "024bdcbd364a8c9910718e4d550d316c482d6d8f", "best_bid": "0.571", "best_ask": "0.572"}, {"asset_id": "40081275558852222228080198821361202017557872256707631666334039001378518619916", "price": "0.449", "size": "28910.16", "side": "SELL", "hash": "c89d93be0364c0e26ca38408067b43c69267aca3", "best_bid": "0.428", "best_ask": "0.429"}], "timestamp": "1785163932052", "event_type": "price_change"}}
{"ts": 1785163932.167, "kind": "price_change", "data": {"market": "0x18b1c135d0a40c5894da9412e77311827d9caf16cf4cd6591b247a34730af919", "price_changes": [{"asset_id": "40081275558852222228080198821361202017557872256707631666334039001378518619916", "price": "0.418", "size": "7288.45", "side": "BUY", "hash": "28697ccb59a3710d423347cf3052c85c50b5836f", "best_bid": "0.428", "best_ask": "0.429"}, {"asset_id": "78633590736077251574794513664747155551297291244492840448622550955320930591622", "price": "0.582", "size": "7288.45", "side": "SELL", "hash": "10fb0c16740637e294c4f58810a805ac63151a28", "best_bid": "0.571", "best_ask": "0.572"}], "timestamp": "1785163932167", "event_type": "price_change"}}
{"ts": 1785163932.172, "kind": "price_change", "data": {"market": "0x18b1c135d0a40c5894da9412e77311827d9caf16cf4cd6591b247a34730af919", "price_changes": [{"asset_id": "78633590736077251574794513664747155551297291244492840448622550955320930591622", "price": "0.561", "size": "12268.8", "side": "BUY", "hash": "c8740139d560173a245726661dd586a094b7d30e", "best_bid": "0.571", "best_ask": "0.572"}, {"asset_id": "40081275558852222228080198821361202017557872256707631666334039001378518619916", "price": "0.439", "size": "12268.8", "side": "SELL", "hash": "b307c038020c3ca6b28fc7771fd8d6925d34779e", "best_bid": "0.428", "best_ask": "0.429"}], "timestamp": "1785163932172", "event_type": "price_change"}}
{"ts": 1785163932.25, "kind": "price_change", "data": {"market": "0x18b1c135d0a40c5894da9412e77311827d9caf16cf4cd6591b247a34730af919", "price_changes": [{"asset_id": "40081275558852222228080198821361202017557872256707631666334039001378518619916", "price": "0.505", "size": "0", "side": "SELL", "hash": "fd88de508b42014118af061cf1043847ed08b55e", "best_bid": "0.428", "best_ask": "0.429"}, {"asset_id": "78633590736077251574794513664747155551297291244492840448622550955320930591622", "price": "0.495", "size": "0", "side": "BUY", "hash": "3146938a66a451d5b60c7f829e4e89093b733f55", "best_bid": "0.571", "best_ask": "0.572"}], "timestamp": "1785163932250", "event_type": "price_change"}}
{"ts": 1785163932.613, "kind": "price_change", "data": {"market": "0x18b1c135d0a40c5894da9412e77311827d9caf16cf4cd6591b247a34730af919", "price_changes": [{"asset_id": "40081275558852222228080198821361202017557872256707631666334039001378518619916", "price": "0.506", "size": "36.7", "side": "SELL", "hash": "93941370ac6db8da28c3fc6c1ef4ab15c964926c", "best_bid": "0.428", "best_ask": "0.429"}, {"asset_id": "78633590736077251574794513664747155551297291244492840448622550955320930591622", "price": "0.494", "size": "36.7", "side": "BUY", "hash": "c89f297993adab3d6e7b619f484032cc3b262d30", "best_bid": "0.571", "best_ask": "0.572"}], "timestamp": "1785163932613", "event_type": "price_change"}}
{"ts": 1785163933.768, "kind": "price_change", "data": {"market": "0x18b1c135d0a40c5894da9412e77311827d9caf16cf4cd6591b247a34730af919", "price_changes": [{"asset_id": "78633590736077251574794513664747155551297291244492840448622550955320930591622", "price": "0.371", "size": "0", "side": "BUY", "hash": "2177fe934f210df17259efb6a4487be04fb49f73", "best_bid": "0.571", "best_ask": "0.572"}, {"asset_id": "40081275558852222228080198821361202017557872256707631666334039001378518619916", "price": "0.629", "size": "0", "side": "SELL", "hash": "ac52d7d58126bbf5fca06d72f2b24be02fbea892", "best_bid": "0.428", "best_ask": "0.429"}], "timestamp": "1785163933768", "event_type": "price_change"}}
{"ts": 1785163933.792, "kind": "price_change", "data": {"market": "0x18b1c135d0a40c5894da9412e77311827d9caf16cf4cd6591b247a34730af919", "price_changes": [{"asset_id": "78633590736077251574794513664747155551297291244492840448622550955320930591622", "price": "0.375", "size": "400", "side": "BUY", "hash": "6efce75a7e62b9190a82274e71da2112fae3c772", "best_bid": "0.571", "best_ask": "0.572"}, {"asset_id": "40081275558852222228080198821361202017557872256707631666334039001378518619916", "price": "0.625", "size": "400", "side": "SELL", "hash": "ece26962fddc2929e8dbbb1cbc0d8a4cae0c2020", "best_bid": "0.428", "best_ask": "0.429"}], "timestamp": "1785163933792", "event_type": "price_change"}}
{"ts": 1785163935.998, "kind": "price_change", "data": {"market": "0x18b1c135d0a40c5894da9412e77311827d9caf16cf4cd6591b247a34730af919", "price_changes": [{"asset_id": "40081275558852222228080198821361202017557872256707631666334039001378518619916", "price": "0.41", "size": "2931.23", "side": "BUY", "hash": "0066c9899ec62a0a56ce7c8a399ebf7efa830217", "best_bid": "0.428", "best_ask": "0.429"}, {"asset_id": "78633590736077251574794513664747155551297291244492840448622550955320930591622", "price": "0.59", "size": "2931.23", "side": "SELL", "hash": "f32c55879bdb3659b492f1b1604584a866fdb8ee", "best_bid": "0.571", "best_ask": "0.572"}], "timestamp": "1785163935998", "event_type": "price_change"}}
{"ts": 1785163936.0, "kind": "price_change", "data": {"market": "0x0f49db97f71c68b1e42a6d16e3de93d85dbf7d4148e3f018eb79e88554be9f75", "price_changes": [{"asset_id": "54533043819946592547517511176940999955633860128497669742211153063842200957669", "price": "0.183", "size": "476", "side": "BUY", "hash": "6db8b973808b01920f13f2915c0334206f3e64c3", "best_bid": "0.194", "best_ask": "0.195"}, {"asset_id": "87854174148074652060467921081181402357467303721471806610111179101805869578687", "price": "0.817", "size": "476", "side": "SELL", "hash": "e72fbf882713137d4212feafbffdf0ea12f2caf2", "best_bid": "0.805", "best_ask": "0.806"}], "timestamp": "1785163936000", "event_type": "price_change"}}
{"ts": 1785163936.684, "kind": "price_change", "data": {"market": "0x18b1c135d0a40c5894da9412e77311827d9caf16cf4cd6591b247a34730af919", "price_changes": [{"asset_id": "40081275558852222228080198821361202017557872256707631666334039001378518619916", "price": "0.41", "size": "2947.28", "side": "BUY", "hash": "4030d5f3d98d3d78a8091022086fffe1393dc796", "best_bid": "0.428", "best_ask": "0.429"}, {"asset_id": "78633590736077251574794513664747155551297291244492840448622550955320930591622", "price": "0.59", "size": "2947.28", "side": "SELL", "hash": "2a34151a0f245df8379ee52e08b389ff0e2e07fd", "best_bid": "0.571", "best_ask": "0.572"}], "timestamp": "1785163936684", "event_type": "price_change"}}
{"ts": 1785163938.637, "kind": "price_change", "data": {"market": "0x0f49db97f71c68b1e42a6d16e3de93d85dbf7d4148e3f018eb79e88554be9f75", "price_changes": [{"asset_id": "87854174148074652060467921081181402357467303721471806610111179101805869578687", "price": "0.795", "size": "3127.98", "side": "BUY", "hash": "57c2d42180bc7a66ea4ebb1d19ebe410fbfd60c0", "best_bid": "0.805", "best_ask": "0.806"}, {"asset_id": "54533043819946592547517511176940999955633860128497669742211153063842200957669", "price": "0.205", "size": "3127.98", "side": "SELL", "hash": "e722c9517cfb3c970e44cbca242d71f73a675c62", "best_bid": "0.194", "best_ask": "0.195"}], "timestamp": "1785163938637", "event_type": "price_change"}}
{"ts": 1785163938.707, "kind": "price_change", "data": {"market": "0x0f49db97f71c68b1e42a6d16e3de93d85dbf7d4148e3f018eb79e88554be9f75", "price_changes": [{"asset_id": "87854174148074652060467921081181402357467303721471806610111179101805869578687", "price": "0.795", "size": "3694.98", "side": "BUY", "hash": "094cfb552da7c20110c2b19da55b97259e2efddb", "best_bid": "0.805", "best_ask": "0.806"}, {"asset_id": "54533043819946592547517511176940999955633860128497669742211153063842200957669", "price": "0.205", "size": "3694.98", "side": "SELL", "hash": "10a4d5ca36ef764b25634007cef06a634515c3d1", "best_bid": "0.194", "best_ask": "0.195"}], "timestamp": "1785163938707", "event_type": "price_change"}}
{"ts": 1785163939.244, "kind": "price_change", "data": {"market": "0x18b1c135d0a40c5894da9412e77311827d9caf16cf4cd6591b247a34730af919", "price_changes": [{"asset_id": "40081275558852222228080198821361202017557872256707631666334039001378518619916", "price": "0.418", "size": "6210.45", "side": "BUY", "hash": "13d8d6dd845e502c24898c6dbe6d03e3add3fb36", "best_bid": "0.428", "best_ask": "0.429"}, {"asset_id": "78633590736077251574794513664747155551297291244492840448622550955320930591622", "price": "0.582", "size": "6210.45", "side": "SELL", "hash": "82cf57c757a5a66c3957e12df6ba8c87bfbb69ef", "best_bid": "0.571", "best_ask": "0.572"}], "timestamp": "1785163939244", "event_type": "price_change"}}
{"ts": 1785163939.33, "kind": "price_change", "data": {"market": "0x18b1c135d0a40c5894da9412e77311827d9caf16cf4cd6591b247a34730af919", "price_changes": [{"asset_id": "40081275558852222228080198821361202017557872256707631666334039001378518619916", "price": "0.418", "size": "7288.45", "side": "BUY", "hash": "e36172039e3218c24eaf03d66afd5017538d1db4", "best_bid": "0.428", "best_ask": "0.429"}, {"asset_id": "78633590736077251574794513664747155551297291244492840448622550955320930591622", "price": "0.582", "size": "7288.45", "side": "SELL", "hash": "ca38adb48240a4e7d5ad9f1c42647f5d6d5cc27c", "best_bid": "0.571", "best_ask": "0.572"}], "timestamp": "1785163939330", "event_type": "price_change"}}
{"ts": 1785163940.271, "kind": "price_change", "data": {"market": "0x18b1c135d0a40c5894da9412e77311827d9caf16cf4cd6591b247a34730af919", "price_changes": [{"asset_id": "78633590736077251574794513664747155551297291244492840448622550955320930591622", "price": "0.482", "size": "161.09", "side": "BUY", "hash": "04c61f401a38fbb339f1f985d5ca828344837614", "best_bid": "0.571", "best_ask": "0.572"}, {"asset_id": "40081275558852222228080198821361202017557872256707631666334039001378518619916", "price": "0.518", "size": "161.09", "side": "SELL", "hash": "0923acdf58e82f0b3fa2ee95fefdecc51ab59da6", "best_bid": "0.428", "best_ask": "0.429"}], "timestamp": "1785163940271", "event_type": "price_change"}}
{"ts": 1785163940.297, "kind": "price_change", "data": {"market": "0x18b1c135d0a40c5894da9412e77311827d9caf16cf4cd6591b247a34730af919", "price_changes": [{"asset_id": "78633590736077251574794513664747155551297291244492840448622550955320930591622", "price": "0.485", "size": "107", "side": "BUY", "hash": "7d584d82cbf04e5f53a9bfdb595ccf47fb043da4", "best_bid": "0.571", "best_ask": "0.572"}, {"asset_id": "40081275558852222228080198821361202017557872256707631666334039001378518619916", "price": "0.515", "size": "107", "side": "SELL", "hash": "87c06300e069032fc62d45baef4cfb3c3b0b0115", "best_bid": "0.428", "best_ask": "0.429"}], "timestamp": "1785163940297", "event_type": "price_change"}}
{"ts": 1785163940.298, "kind": "price_change", "data": {"market": "0x18b1c135d0a40c5894da9412e77311827d9caf16cf4cd6591b247a34730af919", "price_changes": [{"asset_id": "78633590736077251574794513664747155551297291244492840448622550955320930591622", "price": "0.486", "size": "10", "side": "BUY", "hash": "daacb63c9bbd8941dc3fa2fa9b96c91b20d1c905", "best_bid": "0.571", "best_ask": "0.572"}, {"asset_id": "40081275558852222228080198821361202017557872256707631666334039001378518619916", "price": "0.514", "size": "10", "side": "SELL", "hash": "518374e8fb17d9c5fd1a152aa61593bbf2fbc0b8", "best_bid": "0.428", "best_ask": "0.429"}], "timestamp": "1785163940298", "event_type": "price_change"}}
{"ts": 1785163940.364, "kind": "price_change", "data": {"market": "0x18b1c135d0a40c5894da9412e77311827d9caf16cf4cd6591b247a34730af919", "price_changes": [{"asset_id": "78633590736077251574794513664747155551297291244492840448622550955320930591622", "price": "0.485", "size": "30", "side": "BUY", "hash": "02979169b6f17249186fd73bc200c4cdbc7c4c70", "best_bid": "0.571", "best_ask": "0.572"}, {"asset_id": "40081275558852222228080198821361202017557872256707631666334039001378518619916", "price": "0.515", "size": "30", "side": "SELL", "hash": "749a3f204b596c685098f4aff6ca30de0df916e5", "best_bid": "0.428", "best_ask": "0.429"}], "timestamp": "1785163940364", "event_type": "price_change"}}
{"ts": 1785163940.364, "kind": "price_change", "data": {"market": "0x18b1c135d0a40c5894da9412e77311827d9caf16cf4cd6591b247a34730af919", "price_changes": [{"asset_id": "78633590736077251574794513664747155551297291244492840448622550955320930591622", "price": "0.482", "size": "0", "side": "BUY", "hash": "02979169b6f17249186fd73bc200c4cdbc7c4c70", "best_bid": "0.571", "best_ask": "0.572"}, {"asset_id": "40081275558852222228080198821361202017557872256707631666334039001378518619916", "price": "0.518", "size": "0", "side": "SELL", "hash": "749a3f204b596c685098f4aff6ca30de0df916e5", "best_bid": "0.428", "best_ask": "0.429"}], "timestamp": "1785163940364", "event_type": "price_change"}}
{"ts": 1785163940.389, "kind": "price_change", "data": {"market": "0x18b1c135d0a40c5894da9412e77311827d9caf16cf4cd6591b247a34730af919", "price_changes": [{"asset_id": "78633590736077251574794513664747155551297291244492840448622550955320930591622", "price": "0.486", "size": "0", "side": "BUY", "hash": "c2821b22ec43a95bacdf3b7fd767d952a13f2a61", "best_bid": "0.571", "best_ask": "0.572"}, {"asset_id": "40081275558852222228080198821361202017557872256707631666334039001378518619916", "price": "0.514", "size": "0", "side": "SELL", "hash": "8a162ae5748942a746d2cedaa4f01d8ebc87cd56", "best_bid": "0.428", "best_ask": "0.429"}], "timestamp": "1785163940389", "event_type": "price_change"}}
{"ts": 1785163940.389, "kind": "price_change", "data": {"market": "0x18b1c135d0a40c5894da9412e77311827d9caf16cf4cd6591b247a34730af919", "price_changes": [{"asset_id": "78633590736077251574794513664747155551297291244492840448622550955320930591622", "price": "0.485", "size": "0", "side": "BUY", "hash": "c2821b22ec43a95bacdf3b7fd767d952a13f2a61", "best_bid": "0.571", "best_ask": "0.572"}, {"asset_id": "40081275558852222228080198821361202017557872256707631666334039001378518619916", "price": "0.515", "size": "0", "side": "SELL", "hash": "8a162ae5748942a746d2cedaa4f01d8ebc87cd56", "best_bid": "0.428", "best_ask": "0.429"}], "timestamp": "1785163940389", "event_type": "price_change"}}
{"ts": 1785163940.457, "kind": "price_change", "data": {"market": "0x18b1c135d0a40c5894da9412e77311827d9caf16cf4cd6591b247a34730af919", "price_changes": [{"asset_id": "78633590736077251574794513664747155551297291244492840448622550955320930591622", "price": "0.482", "size": "10", "side": "BUY", "hash": "fa7c62d0bd63b3445e2b70c3e80ff28c18e0804c", "best_bid": "0.571", "best_ask": "0.572"}, {"asset_id": "40081275558852222228080198821361202017557872256707631666334039001378518619916", "price": "0.518", "size": "10", "side": "SELL", "hash": "0bae59c74365d877a79e1afd2bd2b85becc1a1d8", "best_bid": "0.428", "best_ask": "0.429"}], "timestamp": "1785163940457", "event_type": "price_change"}}
{"ts": 1785163940.461, "kind": "price_change", "data": {"market": "0x18b1c135d0a40c5894da9412e77311827d9caf16cf4cd6591b247a34730af919", "price_changes": [{"asset_id": "78633590736077251574794513664747155551297291244492840448622550955320930591622", "price": "0.482", "size": "40", "side": "BUY", "hash": "d9ddb4d6b8c21a84127a73c9ee60694c41dfc4b9", "best_bid": "0.571", "best_ask": "0.572"}, {"asset_id": "40081275558852222228080198821361202017557872256707631666334039001378518619916", "price": "0.518", "size": "40", "side": "SELL", "hash": "4a063c0abf69cfee796170b696d69a7fffd2403d", "best_bid": "0.428", "best_ask": "0.429"}], "timestamp": "1785163940461", "event_type": "price_change"}}
{"ts": 1785163941.006, "kind": "price_change", "data": {"market": "0x0f49db97f71c68b1e42a6d16e3de93d85dbf7d4148e3f018eb79e88554be9f75", "price_changes": [{"asset_id": "87854174148074652060467921081181402357467303721471806610111179101805869578687", "price": "0.795", "size": "3431.98", "side": "BUY", "hash": "8f5360623996e696858059b29692bfc1981903b2", "best_bid": "0.805", "best_ask": "0.806"}, {"asset_id": "54533043819946592547517511176940999955633860128497669742211153063842200957669", "price": "0.205", "size": "3431.98", "side": "SELL", "hash": "b063db6647b81961b62bc44d7291a78d9039792a", "best_bid": "0.194", "best_ask": "0.195"}], "timestamp": "1785163941006", "event_type": "price_change"}}
{"ts": 1785163947.877, "kind": "price_change", "data": {"market": "0x0f49db97f71c68b1e42a6d16e3de93d85dbf7d4148e3f018eb79e88554be9f75", "price_changes": [{"asset_id": "87854174148074652060467921081181402357467303721471806610111179101805869578687", "price": "0.795", "size": "2865.98", "side": "BUY", "hash": "80264b83b1ca83172cf3ce24e914245e3e7b2a66", "best_bid": "0.805", "best_ask": "0.806"}, {"asset_id": "54533043819946592547517511176940999955633860128497669742211153063842200957669", "price": "0.205", "size": "2865.98", "side": "SELL", "hash": "0d04600947236973bbaf076098049abb26415e76", "best_bid": "0.194", "best_ask": "0.195"}], "timestamp": "1785163947877", "event_type": "price_change"}}
{"ts": 1785163947.974, "kind": "price_change", "data": {"market": "0x0f49db97f71c68b1e42a6d16e3de93d85dbf7d4148e3f018eb79e88554be9f75", "price_changes": [{"asset_id": "87854174148074652060467921081181402357467303721471806610111179101805869578687", "price": "0.795", "size": "3431.98", "side": "BUY", "hash": "8658ece61dd4f1b028f795b337517c0b03dacfc1", "best_bid": "0.805", "best_ask": "0.806"}, {"asset_id": "54533043819946592547517511176940999955633860128497669742211153063842200957669", "price": "0.205", "size": "3431.98", "side": "SELL", "hash": "e7a2d96784e4fd2452ad07899bd3e52828456d15", "best_bid": "0.194", "best_ask": "0.195"}], "timestamp": "1785163947974", "event_type": "price_change"}}
{"ts": 1785163947.973, "kind": "price_change", "data": {"market": "0x18b1c135d0a40c5894da9412e77311827d9caf16cf4cd6591b247a34730af919", "price_changes": [{"asset_id": "40081275558852222228080198821361202017557872256707631666334039001378518619916", "price": "0.506", "size": "0", "side": "SELL", "hash": "d5c5ed8cff35286e3979407b275d5d67a42ad24c", "best_bid": "0.428", "best_ask": "0.429"}, {"asset_id": "78633590736077251574794513664747155551297291244492840448622550955320930591622", "price": "0.494", "size": "0", "side": "BUY", "hash": "006d6527d539bd1a85c20667e4b8e149e1c0cac9", "best_bid": "0.571", "best_ask": "0.572"}], "timestamp": "1785163947973", "event_type": "price_change"}}
{"ts": 1785163948.137, "kind": "price_change", "data": {"market": "0x0f49db97f71c68b1e42a6d16e3de93d85dbf7d4148e3f018eb79e88554be9f75", "price_changes": [{"asset_id": "54533043819946592547517511176940999955633860128497669742211153063842200957669", "price": "0.179", "size": "80002.56", "side": "BUY", "hash": "e296c4c5e113c565db0b9bd86152eaa975b6924e", "best_bid": "0.194", "best_ask": "0.195"}, {"asset_id": "87854174148074652060467921081181402357467303721471806610111179101805869578687", "price": "0.821", "size": "80002.56", "side": "SELL", "hash": "94797c0259958b17506950226d3eaed27944e4fe", "best_bid": "0.805", "best_ask": "0.806"}], "timestamp": "1785163948137", "event_type": "price_change"}}
{"ts": 1785163948.525, "kind": "price_change", "data": {"market": "0x18b1c135d0a40c5894da9412e77311827d9caf16cf4cd6591b247a34730af919", "price_changes": [{"asset_id": "40081275558852222228080198821361202017557872256707631666334039001378518619916", "price": "0.418", "size": "6212.45", "side": "BUY", "hash": "710b83de1dd929e6bad42ffe3b767b580aaaa869", "best_bid": "0.428", "best_ask": "0.429"}, {"asset_id": "78633590736077251574794513664747155551297291244492840448622550955320930591622", "price": "0.582", "size": "6212.45", "side": "SELL", "hash": "67d6ce351d8c3d97abdc5800c5a69ab0210fd889", "best_bid": "0.571", "best_ask": "0.572"}], "timestamp": "1785163948525", "event_type": "price_change"}}
{"ts": 1785163948.608, "kind": "price_change", "data": {"market": "0x18b1c135d0a40c5894da9412e77311827d9caf16cf4cd6591b247a34730af919", "price_changes": [{"asset_id": "40081275558852222228080198821361202017557872256707631666334039001378518619916", "price": "0.418", "size": "7288.45", "side": "BUY", "hash": "69e7eb1028b36e33de78c8573687e5dd0b33379e", "best_bid": "0.428", "best_ask": "0.429"}, {"asset_id": "78633590736077251574794513664747155551297291244492840448622550955320930591622", "price": "0.582", "size": "7288.45", "side": "SELL", "hash": "2f2d2de4856b2486a3b716857ad3e3e9c22113f5", "best_bid": "0.571", "best_ask": "0.572"}], "timestamp": "1785163948608", "event_type": "price_change"}}
{"ts": 1785163949.05, "kind": "price_change", "data": {"market": "0x18b1c135d0a40c5894da9412e77311827d9caf16cf4cd6591b247a34730af919", "price_changes": [{"asset_id": "40081275558852222228080198821361202017557872256707631666334039001378518619916", "price": "0.505", "size": "36.7", "side": "SELL", "hash": "808b23ec7706c2719032407f7217fdd3d13af106", "best_bid": "0.428", "best_ask": "0.429"}, {"asset_id": "78633590736077251574794513664747155551297291244492840448622550955320930591622", "price": "0.495", "size": "36.7", "side": "BUY", "hash": "a2e3039eaf4e558532ac3e1d0affbe88f32b6bd1", "best_bid": "0.571", "best_ask": "0.572"}], "timestamp": "1785163949050", "event_type": "price_change"}}
{"ts": 1785163953.333, "kind": "price_change", "data": {"market": "0x18b1c135d0a40c5894da9412e77311827d9caf16cf4cd6591b247a34730af919", "price_changes": [{"asset_id": "40081275558852222228080198821361202017557872256707631666334039001378518619916", "price": "0.41", "size": "2931.23", "side": "BUY", "hash": "9c9ca00a89282645544be86f144b12e1a1ea91bc", "best_bid": "0.428", "best_ask": "0.429"}, {"asset_id": "78633590736077251574794513664747155551297291244492840448622550955320930591622", "price": "0.59", "size": "2931.23", "side": "SELL", "hash": "fae5e21cbfeaeca46b9b31f42a672cfcff770325", "best_bid": "0.571", "best_ask": "0.572"}], "timestamp": "1785163953333", "event_type": "price_change"}}
{"ts": 1785163953.381, "kind": "price_change", "data": {"market": "0x0f49db97f71c68b1e42a6d16e3de93d85dbf7d4148e3f018eb79e88554be9f75", "price_changes": [{"asset_id": "54533043819946592547517511176940999955633860128497669742211153063842200957669", "price": "0.179", "size": "81592.56", "side": "BUY", "hash": "19d1057ea296df409062bbb3387fe90c3fac4022", "best_bid": "0.194", "best_ask": "0.195"}, {"asset_id": "87854174148074652060467921081181402357467303721471806610111179101805869578687", "price": "0.821", "size": "81592.56", "side": "SELL", "hash": "08afaaf705dec9b639a6d9617f4e51219c5c7a13", "best_bid": "0.805", "best_ask": "0.806"}], "timestamp": "1785163953381", "event_type": "price_change"}}
{"ts": 1785163953.6801012, "kind": "orders_out", "data": [{"token_id": "54533043819946592547517511176940999955633860128497669742211153063842200957669", "side": "BUY", "price": 0.153, "size": 19.61}]}
{"ts": 1785163953.921, "kind": "price_change", "data": {"market": "0x18b1c135d0a40c5894da9412e77311827d9caf16cf4cd6591b247a34730af919", "price_changes": [{"asset_id": "40081275558852222228080198821361202017557872256707631666334039001378518619916", "price": "0.41", "size": "2947.28", "side": "BUY", "hash": "cdcac2a87672ec9cf11932b597a5a0fbebba674f", "best_bid": "0.428", "best_ask": "0.429"}, {"asset_id": "78633590736077251574794513664747155551297291244492840448622550955320930591622", "price": "0.59", "size": "2947.28", "side": "SELL", "hash": "4fb460bdf55e90342c3c136b12e875a33f4cabe8", "best_bid": "0.571", "best_ask": "0.572"}], "timestamp": "1785163953921", "event_type": "price_change"}}
{"ts": 1785163954.842, "kind": "price_change", "data": {"market": "0x18b1c135d0a40c5894da9412e77311827d9caf16cf4cd6591b247a34730af919", "price_changes": [{"asset_id": "40081275558852222228080198821361202017557872256707631666334039001378518619916", "price": "0.505", "size": "0", "side": "SELL", "hash": "2018fbe8c88c5ff0e327cbec2526d60eed3de8dd", "best_bid": "0.428", "best_ask": "0.429"}, {"asset_id": "78633590736077251574794513664747155551297291244492840448622550955320930591622", "price": "0.495", "size": "0", "side": "BUY", "hash": "ce8fea6fc8a4367053d159bde42eff5f78c31b1e", "best_bid": "0.571", "best_ask": "0.572"}], "timestamp": "1785163954842", "event_type": "price_change"}}
{"ts": 1785163955.738, "kind": "price_change", "data": {"market": "0x18b1c135d0a40c5894da9412e77311827d9caf16cf4cd6591b247a34730af919", "price_changes": [{"asset_id": "40081275558852222228080198821361202017557872256707631666334039001378518619916", "price": "0.505", "size": "36.7", "side": "SELL", "hash": "a486f91060c5c1bb433c38c7e930990b9220a0e3", "best_bid": "0.428", "best_ask": "0.429"}, {"asset_id": "78633590736077251574794513664747155551297291244492840448622550955320930591622", "price": "0.495", "size": "36.7", "side": "BUY", "hash": "1c5014d6143960857727593134445ff6a737753b", "best_bid": "0.571", "best_ask": "0.572"}], "timestamp": "1785163955738", "event_type": "price_change"}}
{"ts": 1785163957.382, "kind": "price_change", "data": {"market": "0x0f49db97f71c68b1e42a6d16e3de93d85dbf7d4148e3f018eb79e88554be9f75", "price_changes": [{"asset_id": "87854174148074652060467921081181402357467303721471806610111179101805869578687", "price": "0.001", "size": "6148776.01", "side": "BUY", "hash": "99023c4a05d030c992a42575e64c9963240c5124", "best_bid": "0.805", "best_ask": "0.806"}, {"asset_id": "54533043819946592547517511176940999955633860128497669742211153063842200957669", "price": "0.999", "size": "6148776.01", "side": "SELL", "hash": "4fb812235ea5adcda0990cc35f8bfa5e87d78983", "best_bid": "0.194", "best_ask": "0.195"}], "timestamp": "1785163957382", "event_type": "price_change"}}
{"ts": 1785163957.388, "kind": "price_change", "data": {"market": "0x0f49db97f71c68b1e42a6d16e3de93d85dbf7d4148e3f018eb79e88554be9f75", "price_changes": [{"asset_id": "87854174148074652060467921081181402357467303721471806610111179101805869578687", "price": "0.001", "size": "6147766.01", "side": "BUY", "hash": "32f06fdbeaa95efe7c378f1e8be72790191b86f6", "best_bid": "0.805", "best_ask": "0.806"}, {"asset_id": "54533043819946592547517511176940999955633860128497669742211153063842200957669", "price": "0.999", "size": "6147766.01", "side": "SELL", "hash": "39c7056ef29c4ac16d4f2e4daeadedba37470519", "best_bid": "0.194", "best_ask": "0.195"}], "timestamp": "1785163957388", "event_type": "price_change"}}
{"ts": 1785163961.001, "kind": "price_change", "data": {"market": "0x18b1c135d0a40c5894da9412e77311827d9caf16cf4cd6591b247a34730af919", "price_changes": [{"asset_id": "78633590736077251574794513664747155551297291244492840448622550955320930591622", "price": "0.004", "size": "5000", "side": "BUY", "hash": "bbfaefbc9ef75ad5779531503bac80266320215a", "best_bid": "0.571", "best_ask": "0.572"}, {"asset_id": "40081275558852222228080198821361202017557872256707631666334039001378518619916", "price": "0.996", "size": "5000", "side": "SELL", "hash": "ee936aaa05eeebcdf318dbe4018800661b31941a", "best_bid": "0.428", "best_ask": "0.429"}], "timestamp": "1785163961001", "event_type": "price_change"}}
{"ts": 1785163961.104, "kind": "price_change", "data": {"market": "0x18b1c135d0a40c5894da9412e77311827d9caf16cf4cd6591b247a34730af919", "price_changes": [{"asset_id": "40081275558852222228080198821361202017557872256707631666334039001378518619916", "price": "0.505", "size": "0", "side": "SELL", "hash": "4ac9a829fa8ad45400bb2c7763f8657403d982c2", "best_bid": "0.428", "best_ask": "0.429"}, {"asset_id": "78633590736077251574794513664747155551297291244492840448622550955320930591622", "price": "0.495", "size": "0", "side": "BUY", "hash": "c0652477f2791655f4b2389b335e52076dfc61ba", "best_bid": "0.571", "best_ask": "0.572"}], "timestamp": "1785163961104", "event_type": "price_change"}}
{"ts": 1785163962.13, "kind": "price_change", "data": {"market": "0x18b1c135d0a40c5894da9412e77311827d9caf16cf4cd6591b247a34730af919", "price_changes": [{"asset_id": "40081275558852222228080198821361202017557872256707631666334039001378518619916", "price": "0.505", "size": "36.7", "side": "SELL", "hash": "3829fd42b68fc1ee1622d11e209311ef06a3b61b", "best_bid": "0.428", "best_ask": "0.429"}, {"asset_id": "78633590736077251574794513664747155551297291244492840448622550955320930591622", "price": "0.495", "size": "36.7", "side": "BUY", "hash": "8e7c175f1816731359e058024bdcec0c0f29528f", "best_bid": "0.571", "best_ask": "0.572"}], "timestamp": "1785163962130", "event_type": "price_change"}}
{"ts": 1785163962.334, "kind": "price_change", "data": {"market": "0x18b1c135d0a40c5894da9412e77311827d9caf16cf4cd6591b247a34730af919", "price_changes": [{"asset_id": "78633590736077251574794513664747155551297291244492840448622550955320930591622", "price": "0.374", "size": "0", "side": "BUY", "hash": "1d5a00fd93a2eab6414007d46d30209e9f776084", "best_bid": "0.571", "best_ask": "0.572"}, {"asset_id": "40081275558852222228080198821361202017557872256707631666334039001378518619916", "price": "0.626", "size": "0", "side": "SELL", "hash": "54bda8f4715aa90a1aab17a6bbc72411e00dc56e", "best_bid": "0.428", "best_ask": "0.429"}], "timestamp": "1785163962334", "event_type": "price_change"}}
{"ts": 1785163962.356, "kind": "price_change", "data": {"market": "0x18b1c135d0a40c5894da9412e77311827d9caf16cf4cd6591b247a34730af919", "price_changes": [{"asset_id": "78633590736077251574794513664747155551297291244492840448622550955320930591622", "price": "0.375", "size": "0", "side": "BUY", "hash": "cb5496d47dc15fd9c068fb2a1e2552b116db84ad", "best_bid": "0.571", "best_ask": "0.572"}, {"asset_id": "40081275558852222228080198821361202017557872256707631666334039001378518619916", "price": "0.625", "size": "0", "side": "SELL", "hash": "491514a7d524f8a7c1d4fd0fa274ac91edba505e", "best_bid": "0.428", "best_ask": "0.429"}], "timestamp": "1785163962356", "event_type": "price_change"}}
{"ts": 1785163962.401, "kind": "price_change", "data": {"market": "0x18b1c135d0a40c5894da9412e77311827d9caf16cf4cd6591b247a34730af919", "price_changes": [{"asset_id": "78633590736077251574794513664747155551297291244492840448622550955320930591622", "price": "0.371", "size": "400", "side": "BUY", "hash": "48bde615459e34e239da0bce62dc880b72fc5522", "best_bid": "0.571", "best_ask": "0.572"}, {"asset_id": "40081275558852222228080198821361202017557872256707631666334039001378518619916", "price": "0.629", "size": "400", "side": "SELL", "hash": "5ae4c97c2e851f88d6be2ddca716b265bf5cf246", "best_bid": "0.428", "best_ask": "0.429"}], "timestamp": "1785163962401", "event_type": "price_change"}}
{"ts": 1785163963.513, "kind": "price_change", "data": {"market": "0x0f49db97f71c68b1e42a6d16e3de93d85dbf7d4148e3f018eb79e88554be9f75", "price_changes": [{"asset_id": "54533043819946592547517511176940999955633860128497669742211153063842200957669", "price": "0.009", "size": "13888.88", "side": "BUY", "hash": "804aea609e4c6afb88cacf716de73b32415d210b", "best_bid": "0.194", "best_ask": "0.195"}, {"asset_id": "87854174148074652060467921081181402357467303721471806610111179101805869578687", "price": "0.991", "size": "13888.88", "side": "SELL", "hash": "95ac36e1ad6adcfa11f317a8647db8bd267e8f27", "best_bid": "0.805", "best_ask": "0.806"}], "timestamp": "1785163963513", "event_type": "price_change"}}
{"ts": 1785163963.516, "kind": "price_change", "data": {"market": "0x0f49db97f71c68b1e42a6d16e3de93d85dbf7d4148e3f018eb79e88554be9f75", "price_changes": [{"asset_id": "54533043819946592547517511176940999955633860128497669742211153063842200957669", "price": "0.007", "size": "53571.42", "side": "BUY", "hash": "53f5e6cbaf5ee5fdbe7a8a5bf1c156809e785808", "best_bid": "0.194", "best_ask": "0.195"}, {"asset_id": "87854174148074652060467921081181402357467303721471806610111179101805869578687", "price": "0.993", "size": "53571.42", "side": "SELL", "hash": "81a3c3ff0c6b2dcaa10008d4ed5977783d586710", "best_bid": "0.805", "best_ask": "0.806"}], "timestamp": "1785163963516", "event_type": "price_change"}}
{"ts": 1785163963.781, "kind": "price_change", "data": {"market": "0x18b1c135d0a40c5894da9412e77311827d9caf16cf4cd6591b247a34730af919", "price_changes": [{"asset_id": "40081275558852222228080198821361202017557872256707631666334039001378518619916", "price": "0.171", "size": "1947.36", "side": "BUY", "hash": "e56553190738b9ce3b8c0c5de7379dfd500dcdf3", "best_bid": "0.428", "best_ask": "0.429"}, {"asset_id": "78633590736077251574794513664747155551297291244492840448622550955320930591622", "price": "0.829", "size": "1947.36", "side": "SELL", "hash": "493e928f1bc8f124c75ddcfb0cfed58a61fd7e6b", "best_bid": "0.571", "best_ask": "0.572"}], "timestamp": "1785163963781", "event_type": "price_change"}}
{"ts": 1785163963.793, "kind": "price_change", "data": {"market": "0x18b1c135d0a40c5894da9412e77311827d9caf16cf4cd6591b247a34730af919", "price_changes": [{"asset_id": "40081275558852222228080198821361202017557872256707631666334039001378518619916", "price": "0.171", "size": "2970.75", "side": "BUY", "hash": "eb31a99c70239896079f60b7bad30f8c7928d80b", "best_bid": "0.428", "best_ask": "0.429"}, {"asset_id": "78633590736077251574794513664747155551297291244492840448622550955320930591622", "price": "0.829", "size": "2970.75", "side": "SELL", "hash": "2218824749a210024291f1ac7acde487661ca852", "best_bid": "0.571", "best_ask": "0.572"}], "timestamp": "1785163963793", "event_type": "price_change"}}
{"ts": 1785163963.883, "kind": "price_change", "data": {"market": "0x18b1c135d0a40c5894da9412e77311827d9caf16cf4cd6591b247a34730af919", "price_changes": [{"asset_id": "40081275558852222228080198821361202017557872256707631666334039001378518619916", "price": "0.505", "size": "0", "side": "SELL", "hash": "ffb07f10ac033b3a5e1ccaf1874cb43e9222fbbd", "best_bid": "0.428", "best_ask": "0.429"}, {"asset_id": "78633590736077251574794513664747155551297291244492840448622550955320930591622", "price": "0.495", "size": "0", "side": "BUY", "hash": "488c7cfc3973e2f85ae6b960d1abcc9aaddf56e3", "best_bid": "0.571", "best_ask": "0.572"}], "timestamp": "1785163963883", "event_type": "price_change"}}
{"ts": 1785163964.247, "kind": "price_change", "data": {"market": "0x18b1c135d0a40c5894da9412e77311827d9caf16cf4cd6591b247a34730af919", "price_changes": [{"asset_id": "40081275558852222228080198821361202017557872256707631666334039001378518619916", "price": "0.506", "size": "36.7", "side": "SELL", "hash": "d0c462882904c3a6c24e7eac3768a8c3d650c71c", "best_bid": "0.428", "best_ask": "0.429"}, {"asset_id": "78633590736077251574794513664747155551297291244492840448622550955320930591622", "price": "0.494", "size": "36.7", "side": "BUY", "hash": "18c6e3766d068a06ea8ac21e93bd93da663260d1", "best_bid": "0.571", "best_ask": "0.572"}], "timestamp": "1785163964247", "event_type": "price_change"}}
{"ts": 1785163965.648, "kind": "price_change", "data": {"market": "0x18b1c135d0a40c5894da9412e77311827d9caf16cf4cd6591b247a34730af919", "price_changes": [{"asset_id": "78633590736077251574794513664747155551297291244492840448622550955320930591622", "price": "0.004", "size": "15016.91", "side": "BUY", "hash": "d97793e05881cc4dde4138bd4b91178c547e9ba6", "best_bid": "0.571", "best_ask": "0.572"}, {"asset_id": "40081275558852222228080198821361202017557872256707631666334039001378518619916", "price": "0.996", "size": "15016.91", "side": "SELL", "hash": "cca4ccf0d0069b0e20d57a55fac1be5edeac532c", "best_bid": "0.428", "best_ask": "0.429"}], "timestamp": "1785163965648", "event_type": "price_change"}}
{"ts": 1785163966.283, "kind": "price_change", "data": {"market": "0x0f49db97f71c68b1e42a6d16e3de93d85dbf7d4148e3f018eb79e88554be9f75", "price_changes": [{"asset_id": "54533043819946592547517511176940999955633860128497669742211153063842200957669", "price": "0.04", "size": "300", "side": "BUY", "hash": "d7cd3f7632380c01aae584b76cebe069a4a054c5", "best_bid": "0.194", "best_ask": "0.195"}, {"asset_id": "87854174148074652060467921081181402357467303721471806610111179101805869578687", "price": "0.96", "size": "300", "side": "SELL", "hash": "b5075fd1730c2ea4e8f30ec1334e446c1805048f", "best_bid": "0.805", "best_ask": "0.806"}], "timestamp": "1785163966283", "event_type": "price_change"}}
{"ts": 1785163966.295, "kind": "price_change", "data": {"market": "0x0f49db97f71c68b1e42a6d16e3de93d85dbf7d4148e3f018eb79e88554be9f75", "price_changes": [{"asset_id": "54533043819946592547517511176940999955633860128497669742211153063842200957669", "price": "0.02", "size": "8000", "side": "BUY", "hash": "dfcccb7e7eeca3617e15a8186a617092a1d9bac0", "best_bid": "0.194", "best_ask": "0.195"}, {"asset_id": "87854174148074652060467921081181402357467303721471806610111179101805869578687", "price": "0.98", "size": "8000", "side": "SELL", "hash": "4be90aa4796e32b31669e1de7c6b0733f89d2e14", "best_bid": "0.805", "best_ask": "0.806"}], "timestamp": "1785163966295", "event_type": "price_change"}}
{"ts": 1785163969.146, "kind": "price_change", "data": {"market": "0x18b1c135d0a40c5894da9412e77311827d9caf16cf4cd6591b247a34730af919", "price_changes": [{"asset_id": "40081275558852222228080198821361202017557872256707631666334039001378518619916", "price": "0.41", "size": "2931.23", "side": "BUY", "hash": "77b0a269205b175ac47f0b3eed22d03b90266a26", "best_bid": "0.428", "best_ask": "0.429"}, {"asset_id": "78633590736077251574794513664747155551297291244492840448622550955320930591622", "price": "0.59", "size": "2931.23", "side": "SELL", "hash": "350029a6ee941f994e9478d5cb90584ba30cfd69", "best_bid": "0.571", "best_ask": "0.572"}], "timestamp": "1785163969146", "event_type": "price_change"}}
{"ts": 1785163969.437, "kind": "price_change", "data": {"market": "0x18b1c135d0a40c5894da9412e77311827d9caf16cf4cd6591b247a34730af919", "price_changes": [{"asset_id": "78633590736077251574794513664747155551297291244492840448622550955320930591622", "price": "0.311", "size": "48.28", "side": "BUY", "hash": "aa4a60a5f62f00c2034b0c9633460a6685e8a34d", "best_bid": "0.571", "best_ask": "0.572"}, {"asset_id": "40081275558852222228080198821361202017557872256707631666334039001378518619916", "price": "0.689", "size": "48.28", "side": "SELL", "hash": "a9506186a773005e313c194c872e834d55632611", "best_bid": "0.428", "best_ask": "0.429"}], "timestamp": "1785163969437", "event_type": "price_change"}}
{"ts": 1785163969.507, "kind": "price_change", "data": {"market": "0x18b1c135d0a40c5894da9412e77311827d9caf16cf4cd6591b247a34730af919", "price_changes": [{"asset_id": "78633590736077251574794513664747155551297291244492840448622550955320930591622", "price": "0.549", "size": "9.99", "side": "BUY", "hash": "4bd282b9b28630678fe65d329eb4f1ec76c15c69", "best_bid": "0.571", "best_ask": "0.572"}, {"asset_id": "40081275558852222228080198821361202017557872256707631666334039001378518619916", "price": "0.451", "size": "9.99", "side": "SELL", "hash": "b65145758c8fcfcf4af860a69043945efeb1645b", "best_bid": "0.428", "best_ask": "0.429"}], "timestamp": "1785163969507", "event_type": "price_change"}}
{"ts": 1785163969.861, "kind": "price_change", "data": {"market": "0x18b1c135d0a40c5894da9412e77311827d9caf16cf4cd6591b247a34730af919", "price_changes": [{"asset_id": "40081275558852222228080198821361202017557872256707631666334039001378518619916", "price": "0.41", "size": "2947.28", "side": "BUY", "hash": "201901ecfafa2506e9b50bb1ffd3b20749a13698", "best_bid": "0.428", "best_ask": "0.429"}, {"asset_id": "78633590736077251574794513664747155551297291244492840448622550955320930591622", "price": "0.59", "size": "2947.28", "side": "SELL", "hash": "50a893ba5ab50c8de10f741bb4b59fc043657a69", "best_bid": "0.571", "best_ask": "0.572"}], "timestamp": "1785163969861", "event_type": "price_change"}}
{"ts": 1785163970.0, "kind": "price_change", "data": {"market": "0x18b1c135d0a40c5894da9412e77311827d9caf16cf4cd6591b247a34730af919", "price_changes": [{"asset_id": "40081275558852222228080198821361202017557872256707631666334039001378518619916", "price": "0.03", "size": "118750", "side": "BUY", "hash": "e9b263aca0f0d94cfbdcf73b0910c6699bb199f8", "best_bid": "0.428", "best_ask": "0.429"}, {"asset_id": "78633590736077251574794513664747155551297291244492840448622550955320930591622", "price": "0.97", "size": "118750", "side": "SELL", "hash": "175064e828c57fb5c932f4cbcb0b3d6f8de33cd7", "best_bid": "0.571", "best_ask": "0.572"}], "timestamp": "1785163970000", "event_type": "price_change"}}
{"ts": 1785163970.001, "kind": "price_change", "data": {"market": "0x18b1c135d0a40c5894da9412e77311827d9caf16cf4cd6591b247a34730af919", "price_changes": [{"asset_id": "78633590736077251574794513664747155551297291244492840448622550955320930591622", "price": "0.08", "size": "1875", "side": "BUY", "hash": "b0cf1e8518349ce8e77d5c45aa39d0e65a12cad6", "best_bid": "0.571", "best_ask": "0.572"}, {"asset_id": "40081275558852222228080198821361202017557872256707631666334039001378518619916", "price": "0.92", "size": "1875", "side": "SELL", "hash": "3a2ab09e10f4707c2924c26680c792b4f4b4a8c5", "best_bid": "0.428", "best_ask": "0.429"}], "timestamp": "1785163970001", "event_type": "price_change"}}
{"ts": 1785163973.0, "kind": "price_change", "data": {"market": "0x0f49db97f71c68b1e42a6d16e3de93d85dbf7d4148e3f018eb79e88554be9f75", "price_changes": [{"asset_id": "87854174148074652060467921081181402357467303721471806610111179101805869578687", "price": "0.37", "size": "0", "side": "BUY", "hash": "8212dcd76e81a832bb68d83874b323cffadf3e4a", "best_bid": "0.805", "best_ask": "0.806"}, {"asset_id": "54533043819946592547517511176940999955633860128497669742211153063842200957669", "price": "0.63", "size": "0", "side": "SELL", "hash": "d8150051d4ffa7274dbe660243724309b945be03", "best_bid": "0.194", "best_ask": "0.195"}], "timestamp": "1785163973000", "event_type": "price_change"}}
{"ts": 1785163973.323126, "kind": "orders_out", "data": [{"token_id": "54533043819946592547517511176940999955633860128497669742211153063842200957669", "side": "BUY", "price": 0.153, "size": 19.61}]}
{"ts": 1785163974.171, "kind": "price_change", "data": {"market": "0x0f49db97f71c68b1e42a6d16e3de93d85dbf7d4148e3f018eb79e88554be9f75", "price_changes": [{"asset_id": "54533043819946592547517511176940999955633860128497669742211153063842200957669", "price": "0.007", "size": "0", "side": "BUY", "hash": "0cc22b71eeca160351f860aaaea46d4d7d26714b", "best_bid": "0.194", "best_ask": "0.195"}, {"asset_id": "87854174148074652060467921081181402357467303721471806610111179101805869578687", "price": "0.993", "size": "0", "side": "SELL", "hash": "dfe9cc653086398d4ebda84aafbb8de02d01a007", "best_bid": "0.805", "best_ask": "0.806"}], "timestamp": "1785163974171", "event_type": "price_change"}}
{"ts": 1785163974.171, "kind": "price_change", "data": {"market": "0x0f49db97f71c68b1e42a6d16e3de93d85dbf7d4148e3f018eb79e88554be9f75", "price_changes": [{"asset_id": "54533043819946592547517511176940999955633860128497669742211153063842200957669", "price": "0.009", "size": "0", "side": "BUY", "hash": "0cc22b71eeca160351f860aaaea46d4d7d26714b", "best_bid": "0.194", "best_ask": "0.195"}, {"asset_id": "87854174148074652060467921081181402357467303721471806610111179101805869578687", "price": "0.991", "size": "0", "side": "SELL", "hash": "dfe9cc653086398d4ebda84aafbb8de02d01a007", "best_bid": "0.805", "best_ask": "0.806"}], "timestamp": "1785163974171", "event_type": "price_change"}}
{"ts": 1785163975.386, "kind": "price_change", "data": {"market": "0x0f49db97f71c68b1e42a6d16e3de93d85dbf7d4148e3f018eb79e88554be9f75", "price_changes": [{"asset_id": "54533043819946592547517511176940999955633860128497669742211153063842200957669", "price": "0.02", "size": "500", "side": "BUY", "hash": "32e6e0961e86aee0f7a9a99b77b537fa68e3b4ba", "best_bid": "0.194", "best_ask": "0.195"}, {"asset_id": "87854174148074652060467921081181402357467303721471806610111179101805869578687", "price": "0.98", "size": "500", "side": "SELL", "hash": "a634390a93db5f2f0208f31f61cd7ba4937d6566", "best_bid": "0.805", "best_ask": "0.806"}], "timestamp": "1785163975386", "event_type": "price_change"}}
{"ts": 1785163975.423, "kind": "price_change", "data": {"market": "0x0f49db97f71c68b1e42a6d16e3de93d85dbf7d4148e3f018eb79e88554be9f75", "price_changes": [{"asset_id": "54533043819946592547517511176940999955633860128497669742211153063842200957669", "price": "0.04", "size": "4050", "side": "BUY", "hash": "469252cadacea078362941cd4c0e3aecf8ceabd9", "best_bid": "0.194", "best_ask": "0.195"}, {"asset_id": "87854174148074652060467921081181402357467303721471806610111179101805869578687", "price": "0.96", "size": "4050", "side": "SELL", "hash": "79c8fff70a9bfd013559da0fa91a5cc9c3e9c06f", "best_bid": "0.805", "best_ask": "0.806"}], "timestamp": "1785163975423", "event_type": "price_change"}}
{"ts": 1785163977.851, "kind": "price_change", "data": {"market": "0x18b1c135d0a40c5894da9412e77311827d9caf16cf4cd6591b247a34730af919", "price_changes": [{"asset_id": "40081275558852222228080198821361202017557872256707631666334039001378518619916", "price": "0.03", "size": "158750", "side": "BUY", "hash": "95db27576c2c970e760d846766e3bd2c2e1afc32", "best_bid": "0.428", "best_ask": "0.429"}, {"asset_id": "78633590736077251574794513664747155551297291244492840448622550955320930591622", "price": "0.97", "size": "158750", "side": "SELL", "hash": "356cebf713417722e2343e7a1c50ba4c33dcf52f", "best_bid": "0.571", "best_ask": "0.572"}], "timestamp": "1785163977851", "event_type": "price_change"}}
{"ts": 1785163977.852, "kind": "price_change", "data": {"market": "0x18b1c135d0a40c5894da9412e77311827d9caf16cf4cd6591b247a34730af919", "price_changes": [{"asset_id": "78633590736077251574794513664747155551297291244492840448622550955320930591622", "price": "0.08", "size": "16875", "side": "BUY", "hash": "8011435563dc32aca2a0458354a5699af25c6dca", "best_bid": "0.571", "best_ask": "0.572"}, {"asset_id": "40081275558852222228080198821361202017557872256707631666334039001378518619916", "price": "0.92", "size": "16875", "side": "SELL", "hash": "e498c8e06281ae34e451a9785f3fbed4eda3d857", "best_bid": "0.428", "best_ask": "0.429"}], "timestamp": "1785163977852", "event_type": "price_change"}}
{"ts": 1785163980.935, "kind": "price_change", "data": {"market": "0x0f49db97f71c68b1e42a6d16e3de93d85dbf7d4148e3f018eb79e88554be9f75", "price_changes": [{"asset_id": "87854174148074652060467921081181402357467303721471806610111179101805869578687", "price": "0.37", "size": "2702", "side": "BUY", "hash": "a8a56814e236cf6ff66badb8043563a775c3fa88", "best_bid": "0.805", "best_ask": "0.806"}, {"asset_id": "54533043819946592547517511176940999955633860128497669742211153063842200957669", "price": "0.63", "size": "2702", "side": "SELL", "hash": "f3a5807fc879719447909623fe9bb8402670524d", "best_bid": "0.194", "best_ask": "0.195"}], "timestamp": "1785163980935", "event_type": "price_change"}}
{"ts": 1785163981.648, "kind": "price_change", "data": {"market": "0x18b1c135d0a40c5894da9412e77311827d9caf16cf4cd6591b247a34730af919", "price_changes": [{"asset_id": "40081275558852222228080198821361202017557872256707631666334039001378518619916", "price": "0.506", "size": "0", "side": "SELL", "hash": "44dfde93b49b2f5224523f79700ed61894c5239a", "best_bid": "0.428", "best_ask": "0.429"}, {"asset_id": "78633590736077251574794513664747155551297291244492840448622550955320930591622", "price": "0.494", "size": "0", "side": "BUY", "hash": "d5726c2c62da1fa9a89bdf77b80092fb18078ceb", "best_bid": "0.571", "best_ask": "0.572"}], "timestamp": "1785163981648", "event_type": "price_change"}}
{"ts": 1785163981.762, "kind": "price_change", "data": {"market": "0x18b1c135d0a40c5894da9412e77311827d9caf16cf4cd6591b247a34730af919", "price_changes": [{"asset_id": "78633590736077251574794513664747155551297291244492840448622550955320930591622", "price": "0.549", "size": "0", "side": "BUY", "hash": "9ad562358ab13a8534d8e51c19ae8a963f2f489b", "best_bid": "0.571", "best_ask": "0.572"}, {"asset_id": "40081275558852222228080198821361202017557872256707631666334039001378518619916", "price": "0.451", "size": "0", "side": "SELL", "hash": "bc5cc011bf30d164088ddfe02063bd9fb3bfcf3b", "best_bid": "0.428", "best_ask": "0.429"}], "timestamp": "1785163981762", "event_type": "price_change"}}
{"ts": 1785163982.661, "kind": "price_change", "data": {"market": "0x18b1c135d0a40c5894da9412e77311827d9caf16cf4cd6591b247a34730af919", "price_changes": [{"asset_id": "40081275558852222228080198821361202017557872256707631666334039001378518619916", "price": "0.505", "size": "36.7", "side": "SELL", "hash": "76543d77f5291300c6020d82f9e499a0e47530b5", "best_bid": "0.428", "best_ask": "0.429"}, {"asset_id": "78633590736077251574794513664747155551297291244492840448622550955320930591622", "price": "0.495", "size": "36.7", "side": "BUY", "hash": "846e87e75a857eaa52d63aab8558d685ae8523f2", "best_bid": "0.571", "best_ask": "0.572"}], "timestamp": "1785163982661", "event_type": "price_change"}}
{"ts": 1785163986.692, "kind": "price_change", "data": {"market": "0x18b1c135d0a40c5894da9412e77311827d9caf16cf4cd6591b247a34730af919", "price_changes": [{"asset_id": "40081275558852222228080198821361202017557872256707631666334039001378518619916", "price": "0.41", "size": "2931.23", "side": "BUY", "hash": "cf66f0715512039b2c80d136775a3f77b3ebfe42", "best_bid": "0.428", "best_ask": "0.429"}, {"asset_id": "78633590736077251574794513664747155551297291244492840448622550955320930591622", "price": "0.59", "size": "2931.23", "side": "SELL", "hash": "a4a0a4a05effde73be91d677b3ee738e91266360", "best_bid": "0.571", "best_ask": "0.572"}], "timestamp": "1785163986692", "event_type": "price_change"}}
{"ts": 1785163987.001, "kind": "price_change", "data": {"market": "0x0f49db97f71c68b1e42a6d16e3de93d85dbf7d4148e3f018eb79e88554be9f75", "price_changes": [{"asset_id": "87854174148074652060467921081181402357467303721471806610111179101805869578687", "price": "0.02", "size": "500", "side": "BUY", "hash": "7644ad9b5ce3988ad699402e5f1ed1f99c2c0b2d", "best_bid": "0.805", "best_ask": "0.806"}, {"asset_id": "54533043819946592547517511176940999955633860128497669742211153063842200957669", "price": "0.98", "size": "500", "side": "SELL", "hash": "a4518c8f3431d0092c590bc8a35ad2f3b76b411d", "best_bid": "0.194", "best_ask": "0.195"}], "timestamp": "1785163987001", "event_type": "price_change"}}
{"ts": 1785163987.002, "kind": "price_change", "data": {"market": "0x0f49db97f71c68b1e42a6d16e3de93d85dbf7d4148e3f018eb79e88554be9f75", "price_changes": [{"asset_id": "87854174148074652060467921081181402357467303721471806610111179101805869578687", "price": "0.02", "size": "500", "side": "BUY", "hash": "2067f5d600f8ceefcff04cbabdc5c007379f040e", "best_bid": "0.805", "best_ask": "0.806"}, {"asset_id": "54533043819946592547517511176940999955633860128497669742211153063842200957669", "price": "0.98", "size": "500", "side": "SELL", "hash": "1e1e291a6a129fb4ab73892553d208cd40c2ab9e", "best_bid": "0.194", "best_ask": "0.195"}], "timestamp": "1785163987002", "event_type": "price_change"}}
{"ts": 1785163987.004, "kind": "price_change", "data": {"market": "0x0f49db97f71c68b1e42a6d16e3de93d85dbf7d4148e3f018eb79e88554be9f75", "price_changes": [{"asset_id": "87854174148074652060467921081181402357467303721471806610111179101805869578687", "price": "0.02", "size": "500", "side": "BUY", "hash": "7d79955731ed44732dcb2556b589d722b97bfd24", "best_bid": "0.805", "best_ask": "0.806"}, {"asset_id": "54533043819946592547517511176940999955633860128497669742211153063842200957669", "price": "0.98", "size": "500", "side": "SELL", "hash": "d4a4f44f39326285755ca47c61ebc11bdb123af8", "best_bid": "0.194", "best_ask": "0.195"}], "timestamp": "1785163987004", "event_type": "price_change"}}
{"ts": 1785163987.186, "kind": "price_change", "data": {"market": "0x18b1c135d0a40c5894da9412e77311827d9caf16cf4cd6591b247a34730af919", "price_changes": [{"asset_id": "40081275558852222228080198821361202017557872256707631666334039001378518619916", "price": "0.41", "size": "2947.28", "side": "BUY", "hash": "3b30bf2dfe935dcdc76e083b51827fb20df51e13", "best_bid": "0.428", "best_ask": "0.429"}, {"asset_id": "78633590736077251574794513664747155551297291244492840448622550955320930591622", "price": "0.59", "size": "2947.28", "side": "SELL", "hash": "7b449c76a71a3902f6aec0d1a871ad9c92799038", "best_bid": "0.571", "best_ask": "0.572"}], "timestamp": "1785163987186", "event_type": "price_change"}}
{"ts": 1785163988.692, "kind": "price_change", "data": {"market": "0x18b1c135d0a40c5894da9412e77311827d9caf16cf4cd6591b247a34730af919", "price_changes": [{"asset_id": "40081275558852222228080198821361202017557872256707631666334039001378518619916", "price": "0.505", "size": "0", "side": "SELL", "hash": "1a3fc3617259841d7cb7b7d09ca6831db5485c32", "best_bid": "0.428", "best_ask": "0.429"}, {"asset_id": "78633590736077251574794513664747155551297291244492840448622550955320930591622", "price": "0.495", "size": "0", "side": "BUY", "hash": "14109ac5fcb32da03a86ecda16f4a4b71f15a949", "best_bid": "0.571", "best_ask": "0.572"}], "timestamp": "1785163988692", "event_type": "price_change"}}
{"ts": 1785163989.595, "kind": "price_change", "data": {"market": "0x18b1c135d0a40c5894da9412e77311827d9caf16cf4cd6591b247a34730af919", "price_changes": [{"asset_id": "40081275558852222228080198821361202017557872256707631666334039001378518619916", "price": "0.505", "size": "36.7", "side": "SELL", "hash": "90c248ecd525a7fcce19a01ad2952bb2a94fa2d1", "best_bid": "0.428", "best_ask": "0.429"}, {"asset_id": "78633590736077251574794513664747155551297291244492840448622550955320930591622", "price": "0.495", "size": "36.7", "side": "BUY", "hash": "88496e67a249ed256152e3e728c4e7cb6d1219bd", "best_bid": "0.571", "best_ask": "0.572"}], "timestamp": "1785163989595", "event_type": "price_change"}}
{"ts": 1785163990.462, "kind": "price_change", "data": {"market": "0x18b1c135d0a40c5894da9412e77311827d9caf16cf4cd6591b247a34730af919", "price_changes": [{"asset_id": "78633590736077251574794513664747155551297291244492840448622550955320930591622", "price": "0.482", "size": "201.09", "side": "BUY", "hash": "d1b09b2f63b1d626b7d6a983fd94d991763acef7", "best_bid": "0.571", "best_ask": "0.572"}, {"asset_id": "40081275558852222228080198821361202017557872256707631666334039001378518619916", "price": "0.518", "size": "201.09", "side": "SELL", "hash": "9e5f85b351c821563f54e2f7b15290c648885b45", "best_bid": "0.428", "best_ask": "0.429"}], "timestamp": "1785163990462", "event_type": "price_change"}}
{"ts": 1785163990.547, "kind": "price_change", "data": {"market": "0x18b1c135d0a40c5894da9412e77311827d9caf16cf4cd6591b247a34730af919", "price_changes": [{"asset_id": "78633590736077251574794513664747155551297291244492840448622550955320930591622", "price": "0.485", "size": "77", "side": "BUY", "hash": "1e7d331f74ac165f6910ee2e5d1c5518448a5b51", "best_bid": "0.571", "best_ask": "0.572"}, {"asset_id": "40081275558852222228080198821361202017557872256707631666334039001378518619916", "price": "0.515", "size": "77", "side": "SELL", "hash": "331cbeb5bfd9dbaeacce848211a29c3e8dd213cc", "best_bid": "0.428", "best_ask": "0.429"}], "timestamp": "1785163990547", "event_type": "price_change"}}
{"ts": 1785163990.849, "kind": "price_change", "data": {"market": "0x0f49db97f71c68b1e42a6d16e3de93d85dbf7d4148e3f018eb79e88554be9f75", "price_changes": [{"asset_id": "87854174148074652060467921081181402357467303721471806610111179101805869578687", "price": "0.652", "size": "0", "side": "BUY", "hash": "7c2e54880fd2f1d4e0a637eb183ca6836a086ec6", "best_bid": "0.805", "best_ask": "0.806"}, {"asset_id": "54533043819946592547517511176940999955633860128497669742211153063842200957669", "price": "0.348", "size": "0", "side": "SELL", "hash": "313fdbf4fa07714d1196ceb0301e961b84efa00a", "best_bid": "0.194", "best_ask": "0.195"}], "timestamp": "1785163990849", "event_type": "price_change"}}
{"ts": 1785163991.01, "kind": "price_change", "data": {"market": "0x18b1c135d0a40c5894da9412e77311827d9caf16cf4cd6591b247a34730af919", "price_changes": [{"asset_id": "78633590736077251574794513664747155551297291244492840448622550955320930591622", "price": "0.551", "size": "28710.16", "side": "BUY", "hash": "115cc78040f7ab4659288a88974634390246eb42", "best_bid": "0.571", "best_ask": "0.572"}, {"asset_id": "40081275558852222228080198821361202017557872256707631666334039001378518619916", "price": "0.449", "size": "28710.16", "side": "SELL", "hash": "34bb8ebb8cf6de12a3efc41e3551fd3bf53ed165", "best_bid": "0.428", "best_ask": "0.429"}], "timestamp": "1785163991010", "event_type": "price_change"}}
{"ts": 1785163991.101, "kind": "price_change", "data": {"market": "0x0f49db97f71c68b1e42a6d16e3de93d85dbf7d4148e3f018eb79e88554be9f75", "price_changes": [{"asset_id": "87854174148074652060467921081181402357467303721471806610111179101805869578687", "price": "0.698", "size": "35", "side": "BUY", "hash": "fbe01dd50e79bfca5831cffcdb1bcb8c13e41f15", "best_bid": "0.805", "best_ask": "0.806"}, {"asset_id": "54533043819946592547517511176940999955633860128497669742211153063842200957669", "price": "0.302", "size": "35", "side": "SELL", "hash": "35a8a1efc635b85c827378abf7b9fc7fa545e414", "best_bid": "0.194", "best_ask": "0.195"}], "timestamp": "1785163991101", "event_type": "price_change"}}
{"ts": 1785163991.244, "kind": "price_change", "data": {"market": "0x18b1c135d0a40c5894da9412e77311827d9caf16cf4cd6591b247a34730af919", "price_changes": [{"asset_id": "78633590736077251574794513664747155551297291244492840448622550955320930591622", "price": "0.551", "size": "28910.16", "side": "BUY", "hash": "7192b87bc37689db707d15316eb509384b0e8c79", "best_bid": "0.571", "best_ask": "0.572"}, {"asset_id": "40081275558852222228080198821361202017557872256707631666334039001378518619916", "price": "0.449", "size": "28910.16", "side": "SELL", "hash": "75ef2c4e9d4a8bc7af3b3f57c38e1f67c8c3a3ed", "best_bid": "0.428", "best_ask": "0.429"}], "timestamp": "1785163991244", "event_type": "price_change"}}
{"ts": 1785163992.945, "kind": "price_change", "data": {"market": "0x0f49db97f71c68b1e42a6d16e3de93d85dbf7d4148e3f018eb79e88554be9f75", "price_changes": [{"asset_id": "54533043819946592547517511176940999955633860128497669742211153063842200957669", "price": "0.18", "size": "11724.84", "side": "BUY", "hash": "159a28d8d9a2bbc8631241c04344c403720ed710", "best_bid": "0.194", "best_ask": "0.195"}, {"asset_id": "87854174148074652060467921081181402357467303721471806610111179101805869578687", "price": "0.82", "size": "11724.84", "side": "SELL", "hash": "d65f827a4b4b47d7810b0656c01acb6f7fd73ae9", "best_bid": "0.805", "best_ask": "0.806"}], "timestamp": "1785163992945", "event_type": "price_change"}}
{"ts": 1785163993.308467, "kind": "orders_out", "data": [{"token_id": "54533043819946592547517511176940999955633860128497669742211153063842200957669", "side": "BUY", "price": 0.153, "size": 19.61}]}
{"ts": 1785163995.89, "kind": "price_change", "data": {"market": "0x0f49db97f71c68b1e42a6d16e3de93d85dbf7d4148e3f018eb79e88554be9f75", "price_changes": [{"asset_id": "87854174148074652060467921081181402357467303721471806610111179101805869578687", "price": "0.02", "size": "75500", "side": "BUY", "hash": "65b64c98cba7555a19120bc3973615c5728dc1a1", "best_bid": "0.805", "best_ask": "0.806"}, {"asset_id": "54533043819946592547517511176940999955633860128497669742211153063842200957669", "price": "0.98", "size": "75500", "side": "SELL", "hash": "a4aaa015c940170572b47823a7953c2f4ccf6fb9", "best_bid": "0.194", "best_ask": "0.195"}], "timestamp": "1785163995890", "event_type": "price_change"}}
{"ts": 1785163995.891, "kind": "price_change", "data": {"market": "0x0f49db97f71c68b1e42a6d16e3de93d85dbf7d4148e3f018eb79e88554be9f75", "price_changes": [{"asset_id": "87854174148074652060467921081181402357467303721471806610111179101805869578687", "price": "0.02", "size": "135500", "side": "BUY", "hash": "0caeb77d1f8f15fddad4dc748bc02a22ba38601f", "best_bid": "0.805", "best_ask": "0.806"}, {"asset_id": "54533043819946592547517511176940999955633860128497669742211153063842200957669", "price": "0.98", "size": "135500", "side": "SELL", "hash": "d40df7cb8e59c601914b3b4caf070e06e4e71f45", "best_bid": "0.194", "best_ask": "0.195"}], "timestamp": "1785163995891", "event_type": "price_change"}}
{"ts": 1785163995.892, "kind": "price_change", "data": {"market": "0x0f49db97f71c68b1e42a6d16e3de93d85dbf7d4148e3f018eb79e88554be9f75", "price_changes": [{"asset_id": "87854174148074652060467921081181402357467303721471806610111179101805869578687", "price": "0.02", "size": "220500", "side": "BUY", "hash": "544ba0227e26f634516250f0a70c829bf00247a3", "best_bid": "0.805", "best_ask": "0.806"}, {"asset_id": "54533043819946592547517511176940999955633860128497669742211153063842200957669", "price": "0.98", "size": "220500", "side": "SELL", "hash": "eace3fd7bddb35b32f23c8a49eea7894e5492591", "best_bid": "0.194", "best_ask": "0.195"}], "timestamp": "1785163995892", "event_type": "price_change"}}
{"ts": 1785163996.421, "kind": "price_change", "data": {"market": "0x18b1c135d0a40c5894da9412e77311827d9caf16cf4cd6591b247a34730af919", "price_changes": [{"asset_id": "40081275558852222228080198821361202017557872256707631666334039001378518619916", "price": "0.505", "size": "0", "side": "SELL", "hash": "9a84d133e864b1f2ef76118446a87a6d07f6b1d7", "best_bid": "0.428", "best_ask": "0.429"}, {"asset_id": "78633590736077251574794513664747155551297291244492840448622550955320930591622", "price": "0.495", "size": "0", "side": "BUY", "hash": "9d4fe73240c028a53e45ce3c3d2ffccf6e621eb5", "best_bid": "0.571", "best_ask": "0.572"}], "timestamp": "1785163996421", "event_type": "price_change"}}
{"ts": 1785163997.034, "kind": "price_change", "data": {"market": "0x18b1c135d0a40c5894da9412e77311827d9caf16cf4cd6591b247a34730af919", "price_changes": [{"asset_id": "40081275558852222228080198821361202017557872256707631666334039001378518619916", "price": "0.505", "size": "36.7", "side": "SELL", "hash": "4ef28a1b82a1ebc12554ce454471967bf06ab997", "best_bid": "0.428", "best_ask": "0.429"}, {"asset_id": "78633590736077251574794513664747155551297291244492840448622550955320930591622", "price": "0.495", "size": "36.7", "side": "BUY", "hash": "a6d65929b1a9818964a5e308b0334a0150aaf481", "best_bid": "0.571", "best_ask": "0.572"}], "timestamp": "1785163997034", "event_type": "price_change"}}
{"ts": 1785163997.873, "kind": "price_change", "data": {"market": "0x0f49db97f71c68b1e42a6d16e3de93d85dbf7d4148e3f018eb79e88554be9f75", "price_changes": [{"asset_id": "87854174148074652060467921081181402357467303721471806610111179101805869578687", "price": "0.795", "size": "3131.98", "side": "BUY", "hash": "e31bdb6ea3677c1574e35ed463cafec8e96d382c", "best_bid": "0.805", "best_ask": "0.806"}, {"asset_id": "54533043819946592547517511176940999955633860128497669742211153063842200957669", "price": "0.205", "size": "3131.98", "side": "SELL", "hash": "607ab01c958cb77b666052fe7b820ef556b6611f", "best_bid": "0.194", "best_ask": "0.195"}], "timestamp": "1785163997873", "event_type": "price_change"}}
{"ts": 1785163997.873, "kind": "price_change", "data": {"market": "0x0f49db97f71c68b1e42a6d16e3de93d85dbf7d4148e3f018eb79e88554be9f75", "price_changes": [{"asset_id": "54533043819946592547517511176940999955633860128497669742211153063842200957669", "price": "0.184", "size": "782", "side": "BUY", "hash": "607ab01c958cb77b666052fe7b820ef556b6611f", "best_bid": "0.194", "best_ask": "0.195"}, {"asset_id": "87854174148074652060467921081181402357467303721471806610111179101805869578687", "price": "0.816", "size": "782", "side": "SELL", "hash": "e31bdb6ea3677c1574e35ed463cafec8e96d382c", "best_bid": "0.805", "best_ask": "0.806"}], "timestamp": "1785163997873", "event_type": "price_change"}}
{"ts": 1785163998.543, "kind": "price_change", "data": {"market": "0x18b1c135d0a40c5894da9412e77311827d9caf16cf4cd6591b247a34730af919", "price_changes": [{"asset_id": "40081275558852222228080198821361202017557872256707631666334039001378518619916", "price": "0.505", "size": "0", "side": "SELL", "hash": "c14ac7300922fdf193785832418b5ed0b395173f", "best_bid": "0.428", "best_ask": "0.429"}, {"asset_id": "78633590736077251574794513664747155551297291244492840448622550955320930591622", "price": "0.495", "size": "0", "side": "BUY", "hash": "2b5940d11b07be74fa886733016e4bab5030175c", "best_bid": "0.571", "best_ask": "0.572"}], "timestamp": "1785163998543", "event_type": "price_change"}}
{"ts": 1785163998.822, "kind": "price_change", "data": {"market": "0x18b1c135d0a40c5894da9412e77311827d9caf16cf4cd6591b247a34730af919", "price_changes": [{"asset_id": "40081275558852222228080198821361202017557872256707631666334039001378518619916", "price": "0.506", "size": "36.7", "side": "SELL", "hash": "128a433b5ac53f8ca5b1c7b7155e5857e78616a4", "best_bid": "0.428", "best_ask": "0.429"}, {"asset_id": "78633590736077251574794513664747155551297291244492840448622550955320930591622", "price": "0.494", "size": "36.7", "side": "BUY", "hash": "a3460739f8483fac38288b8ed72f442f0a98b9db", "best_bid": "0.571", "best_ask": "0.572"}], "timestamp": "1785163998822", "event_type": "price_change"}}
{"ts": 1785163998.88, "kind": "price_change", "data": {"market": "0x0f49db97f71c68b1e42a6d16e3de93d85dbf7d4148e3f018eb79e88554be9f75", "price_changes": [{"asset_id": "87854174148074652060467921081181402357467303721471806610111179101805869578687", "price": "0.795", "size": "2564.98", "side": "BUY", "hash": "5efcb2ebe3fcc8864548f499303cdb606525c628", "best_bid": "0.805", "best_ask": "0.806"}, {"asset_id": "54533043819946592547517511176940999955633860128497669742211153063842200957669", "price": "0.205", "size": "2564.98", "side": "SELL", "hash": "856c94506459210b6fe00cd27ee238dc147d72f8", "best_bid": "0.194", "best_ask": "0.195"}], "timestamp": "1785163998880", "event_type": "price_change"}}
{"ts": 1785163998.945, "kind": "price_change", "data": {"market": "0x0f49db97f71c68b1e42a6d16e3de93d85dbf7d4148e3f018eb79e88554be9f75", "price_changes": [{"asset_id": "87854174148074652060467921081181402357467303721471806610111179101805869578687", "price": "0.795", "size": "3131.98", "side": "BUY", "hash": "9160eff32d0f493777a9468e3c80fa5bffa0baf1", "best_bid": "0.805", "best_ask": "0.806"}, {"asset_id": "54533043819946592547517511176940999955633860128497669742211153063842200957669", "price": "0.205", "size": "3131.98", "side": "SELL", "hash": "0d1803e89ec43f8a58c42a2452e9f7bd6b1c23e0", "best_bid": "0.194", "best_ask": "0.195"}], "timestamp": "1785163998945", "event_type": "price_change"}}
{"ts": 1785163999.423, "kind": "price_change", "data": {"market": "0x18b1c135d0a40c5894da9412e77311827d9caf16cf4cd6591b247a34730af919", "price_changes": [{"asset_id": "40081275558852222228080198821361202017557872256707631666334039001378518619916", "price": "0.418", "size": "6210.45", "side": "BUY", "hash": "1aa369872ba3be513ee5ce9dfde41f954541503b", "best_bid": "0.428", "best_ask": "0.429"}, {"asset_id": "78633590736077251574794513664747155551297291244492840448622550955320930591622", "price": "0.582", "size": "6210.45", "side": "SELL", "hash": "aa0f7f12671a3a414c8c77379fd53a245e1f2740", "best_bid": "0.571", "best_ask": "0.572"}], "timestamp": "1785163999423", "event_type": "price_change"}}
{"ts": 1785163999.503, "kind": "price_change", "data": {"market": "0x18b1c135d0a40c5894da9412e77311827d9caf16cf4cd6591b247a34730af919", "price_changes": [{"asset_id": "40081275558852222228080198821361202017557872256707631666334039001378518619916", "price": "0.418", "size": "7288.45", "side": "BUY", "hash": "e816b6f1327aa4e0807e84a23cb4cfe672fd5982", "best_bid": "0.428", "best_ask": "0.429"}, {"asset_id": "78633590736077251574794513664747155551297291244492840448622550955320930591622", "price": "0.582", "size": "7288.45", "side": "SELL", "hash": "b4028f8d29fcfeb6637c4e52520475a56288d767", "best_bid": "0.571", "best_ask": "0.572"}], "timestamp": "1785163999503", "event_type": "price_change"}}
{"ts": 1785164004.471, "kind": "price_change", "data": {"market": "0x18b1c135d0a40c5894da9412e77311827d9caf16cf4cd6591b247a34730af919", "price_changes": [{"asset_id": "40081275558852222228080198821361202017557872256707631666334039001378518619916", "price": "0.41", "size": "2931.23", "side": "BUY", "hash": "bbdc8c5bcdd5a98dffb815ff163b5799d7adc6c4", "best_bid": "0.428", "best_ask": "0.429"}, {"asset_id": "78633590736077251574794513664747155551297291244492840448622550955320930591622", "price": "0.59", "size": "2931.23", "side": "SELL", "hash": "7d6f1f3ae7e34b2d8e3dc6aba8955075527bb92c", "best_bid": "0.571", "best_ask": "0.572"}], "timestamp": "1785164004471", "event_type": "price_change"}}
{"ts": 1785164005.175, "kind": "price_change", "data": {"market": "0x18b1c135d0a40c5894da9412e77311827d9caf16cf4cd6591b247a34730af919", "price_changes": [{"asset_id": "40081275558852222228080198821361202017557872256707631666334039001378518619916", "price": "0.41", "size": "2947.28", "side": "BUY", "hash": "eeae8aa7a3a995831573d2ca116992498785caa5", "best_bid": "0.428", "best_ask": "0.429"}, {"asset_id": "78633590736077251574794513664747155551297291244492840448622550955320930591622", "price": "0.59", "size": "2947.28", "side": "SELL", "hash": "77195a0a73d274c6fb2870618b112c1d72f58eee", "best_bid": "0.571", "best_ask": "0.572"}], "timestamp": "1785164005175", "event_type": "price_change"}}
{"ts": 1785164007.987, "kind": "price_change", "data": {"market": "0x0f49db97f71c68b1e42a6d16e3de93d85dbf7d4148e3f018eb79e88554be9f75", "price_changes": [{"asset_id": "87854174148074652060467921081181402357467303721471806610111179101805869578687", "price": "0.795", "size": "3431.98", "side": "BUY", "hash": "77d55b9dff3cda0147a762108638a1aaeef193a4", "best_bid": "0.805", "best_ask": "0.806"}, {"asset_id": "54533043819946592547517511176940999955633860128497669742211153063842200957669", "price": "0.205", "size": "3431.98", "side": "SELL", "hash": "1e0d8a5252cae6dbb6b987946902e73dd4487a35", "best_bid": "0.194", "best_ask": "0.195"}], "timestamp": "1785164007987", "event_type": "price_change"}}
{"ts": 1785164007.991, "kind": "price_change", "data": {"market": "0x0f49db97f71c68b1e42a6d16e3de93d85dbf7d4148e3f018eb79e88554be9f75", "price_changes": [{"asset_id": "54533043819946592547517511176940999955633860128497669742211153063842200957669", "price": "0.184", "size": "1082", "side": "BUY", "hash": "6a2df138c94091576000ba9285e5e757288e1be9", "best_bid": "0.194", "best_ask": "0.195"}, {"asset_id": "87854174148074652060467921081181402357467303721471806610111179101805869578687", "price": "0.816", "size": "1082", "side": "SELL", "hash": "7fcbd3237806ed5464c7c02d58f773cdbb337f0d", "best_bid": "0.805", "best_ask": "0.806"}], "timestamp": "1785164007991", "event_type": "price_change"}}
{"ts": 1785164008.388, "kind": "price_change", "data": {"market": "0x18b1c135d0a40c5894da9412e77311827d9caf16cf4cd6591b247a34730af919", "price_changes": [{"asset_id": "40081275558852222228080198821361202017557872256707631666334039001378518619916", "price": "0.506", "size": "0", "side": "SELL", "hash": "00883b6731780b878e4bd5f23068495f12f0912a", "best_bid": "0.428", "best_ask": "0.429"}, {"asset_id": "78633590736077251574794513664747155551297291244492840448622550955320930591622", "price": "0.494", "size": "0", "side": "BUY", "hash": "59893cd46d3a5ff622c5d25b0e981e99896e2544", "best_bid": "0.571", "best_ask": "0.572"}], "timestamp": "1785164008388", "event_type": "price_change"}}
{"ts": 1785164008.473, "kind": "price_change", "data": {"market": "0x0f49db97f71c68b1e42a6d16e3de93d85dbf7d4148e3f018eb79e88554be9f75", "price_changes": [{"asset_id": "87854174148074652060467921081181402357467303721471806610111179101805869578687", "price": "0.795", "size": "2865.98", "side": "BUY", "hash": "1e65a99d0beb0a7e646a25b7e882e3c0091d3072", "best_bid": "0.805", "best_ask": "0.806"}, {"asset_id": "54533043819946592547517511176940999955633860128497669742211153063842200957669", "price": "0.205", "size": "2865.98", "side": "SELL", "hash": "5a9760e420818994f21bb5805a923aa734abcb6e", "best_bid": "0.194", "best_ask": "0.195"}], "timestamp": "1785164008473", "event_type": "price_change"}}
{"ts": 1785164008.562, "kind": "price_change", "data": {"market": "0x0f49db97f71c68b1e42a6d16e3de93d85dbf7d4148e3f018eb79e88554be9f75", "price_changes": [{"asset_id": "87854174148074652060467921081181402357467303721471806610111179101805869578687", "price": "0.795", "size": "3431.98", "side": "BUY", "hash": "e44ef026cafc80b90994c41876e2a07c135af67c", "best_bid": "0.805", "best_ask": "0.806"}, {"asset_id": "54533043819946592547517511176940999955633860128497669742211153063842200957669", "price": "0.205", "size": "3431.98", "side": "SELL", "hash": "f0f30ccc061a4983883f2c50143b53dd230b4e78", "best_bid": "0.194", "best_ask": "0.195"}], "timestamp": "1785164008562", "event_type": "price_change"}}
{"ts": 1785164009.001, "kind": "price_change", "data": {"market": "0x0f49db97f71c68b1e42a6d16e3de93d85dbf7d4148e3f018eb79e88554be9f75", "price_changes": [{"asset_id": "87854174148074652060467921081181402357467303721471806610111179101805869578687", "price": "0.78", "size": "823", "side": "BUY", "hash": "d9de7d01006524d44b6f8035a9ffe297fd23d930", "best_bid": "0.805", "best_ask": "0.806"}, {"asset_id": "54533043819946592547517511176940999955633860128497669742211153063842200957669", "price": "0.22", "size": "823", "side": "SELL", "hash": "dcf9d4a31f4537f1743934029f86f7273b8991a1", "best_bid": "0.194", "best_ask": "0.195"}], "timestamp": "1785164009001", "event_type": "price_change"}}
{"ts": 1785164009.14, "kind": "price_change", "data": {"market": "0x18b1c135d0a40c5894da9412e77311827d9caf16cf4cd6591b247a34730af919", "price_changes": [{"asset_id": "40081275558852222228080198821361202017557872256707631666334039001378518619916", "price": "0.418", "size": "6212.45", "side": "BUY", "hash": "8d8f01fe1f3aaf5f4d3c55170e1cb6bd496fe8b8", "best_bid": "0.428", "best_ask": "0.429"}, {"asset_id": "78633590736077251574794513664747155551297291244492840448622550955320930591622", "price": "0.582", "size": "6212.45", "side": "SELL", "hash": "0698387a0f0d8cd4b789cd142e6cd8a37a7f6515", "best_bid": "0.571", "best_ask": "0.572"}], "timestamp": "1785164009140", "event_type": "price_change"}}
{"ts": 1785164009.222, "kind": "price_change", "data": {"market": "0x18b1c135d0a40c5894da9412e77311827d9caf16cf4cd6591b247a34730af919", "price_changes": [{"asset_id": "40081275558852222228080198821361202017557872256707631666334039001378518619916", "price": "0.418", "size": "7288.45", "side": "BUY", "hash": "e5727dd3c749676d631fac7ff60c036d526b131c", "best_bid": "0.428", "best_ask": "0.429"}, {"asset_id": "78633590736077251574794513664747155551297291244492840448622550955320930591622", "price": "0.582", "size": "7288.45", "side": "SELL", "hash": "b646332d18000a48b373e30dd37adf1e10491b85", "best_bid": "0.571", "best_ask": "0.572"}], "timestamp": "1785164009222", "event_type": "price_change"}}
{"ts": 1785164009.354, "kind": "price_change", "data": {"market": "0x18b1c135d0a40c5894da9412e77311827d9caf16cf4cd6591b247a34730af919", "price_changes": [{"asset_id": "40081275558852222228080198821361202017557872256707631666334039001378518619916", "price": "0.505", "size": "36.7", "side": "SELL", "hash": "91ecb3f1ee6b3aeca3b305cb886801345cd4eb09", "best_bid": "0.428", "best_ask": "0.429"}, {"asset_id": "78633590736077251574794513664747155551297291244492840448622550955320930591622", "price": "0.495", "size": "36.7", "side": "BUY", "hash": "691f9e4e4dcb57a7dedea676bc65e4a0b72f59d2", "best_bid": "0.571", "best_ask": "0.572"}], "timestamp": "1785164009354", "event_type": "price_change"}}
{"ts": 1785164010.533, "kind": "price_change", "data": {"market": "0x18b1c135d0a40c5894da9412e77311827d9caf16cf4cd6591b247a34730af919", "price_changes": [{"asset_id": "40081275558852222228080198821361202017557872256707631666334039001378518619916", "price": "0.505", "size": "0", "side": "SELL", "hash": "14c8e9a9c93503a219a9fb7fd38e2e93da0b1fed", "best_bid": "0.428", "best_ask": "0.429"}, {"asset_id": "78633590736077251574794513664747155551297291244492840448622550955320930591622", "price": "0.495", "size": "0", "side": "BUY", "hash": "6d47e32e055fc5ac3779afc15b90d679923f90f8", "best_bid": "0.571", "best_ask": "0.572"}], "timestamp": "1785164010533", "event_type": "price_change"}}
{"ts": 1785164010.868, "kind": "price_change", "data": {"market": "0x18b1c135d0a40c5894da9412e77311827d9caf16cf4cd6591b247a34730af919", "price_changes": [{"asset_id": "40081275558852222228080198821361202017557872256707631666334039001378518619916", "price": "0.506", "size": "36.7", "side": "SELL", "hash": "0341a99d0d8c83a3c05888b1c039f7f5724daeb4", "best_bid": "0.428", "best_ask": "0.429"}, {"asset_id": "78633590736077251574794513664747155551297291244492840448622550955320930591622", "price": "0.494", "size": "36.7", "side": "BUY", "hash": "f682899873b4e145a7b92b01a5c9a1d3698025ac", "best_bid": "0.571", "best_ask": "0.572"}], "timestamp": "1785164010868", "event_type": "price_change"}}
{"ts": 1785164013.705, "kind": "price_change", "data": {"market": "0x0f49db97f71c68b1e42a6d16e3de93d85dbf7d4148e3f018eb79e88554be9f75", "price_changes": [{"asset_id": "54533043819946592547517511176940999955633860128497669742211153063842200957669", "price": "0.009", "size": "13888.88", "side": "BUY", "hash": "6e93c893117bece32ac032b335c66b403f92a28b", "best_bid": "0.194", "best_ask": "0.195"}, {"asset_id": "87854174148074652060467921081181402357467303721471806610111179101805869578687", "price": "0.991", "size": "13888.88", "side": "SELL", "hash": "1e46e7575cb5255605756ebda1329046ff5fadb2", "best_bid": "0.805", "best_ask": "0.806"}], "timestamp": "1785164013705", "event_type": "price_change"}}
{"ts": 1785164013.708, "kind": "price_change", "data": {"market": "0x0f49db97f71c68b1e42a6d16e3de93d85dbf7d4148e3f018eb79e88554be9f75", "price_changes": [{"asset_id": "54533043819946592547517511176940999955633860128497669742211153063842200957669", "price": "0.007", "size": "53571.42", "side": "BUY", "hash": "daee1cfe5d047d690d949fa945d4ae5caff865ca", "best_bid": "0.194", "best_ask": "0.195"}, {"asset_id": "87854174148074652060467921081181402357467303721471806610111179101805869578687", "price": "0.993", "size": "53571.42", "side": "SELL", "hash": "46b8328c765e766550ac7cb4664fb27aa673c6bf", "best_bid": "0.805", "best_ask": "0.806"}], "timestamp": "1785164013708", "event_type": "price_change"}}
{"ts": 1785164015.002, "kind": "price_change", "data": {"market": "0x0f49db97f71c68b1e42a6d16e3de93d85dbf7d4148e3f018eb79e88554be9f75", "price_changes": [{"asset_id": "87854174148074652060467921081181402357467303721471806610111179101805869578687", "price": "0.803", "size": "12334.97", "side": "BUY", "hash": "12955e5aec86275accff693bc065941e5cc7eba4", "best_bid": "0.805", "best_ask": "0.806"}, {"asset_id": "54533043819946592547517511176940999955633860128497669742211153063842200957669", "price": "0.197", "size": "12334.97", "side": "SELL", "hash": "bf3d1bc82c3d1a7888ac9036c00ed837c52a500a", "best_bid": "0.194", "best_ask": "0.195"}], "timestamp": "1785164015002", "event_type": "price_change"}}
{"ts": 1785164015.012, "kind": "price_change", "data": {"market": "0x0f49db97f71c68b1e42a6d16e3de93d85dbf7d4148e3f018eb79e88554be9f75", "price_changes": [{"asset_id": "54533043819946592547517511176940999955633860128497669742211153063842200957669", "price": "0.193", "size": "10994", "side": "BUY", "hash": "30f036ce60b8f031c6b3901fef2ec0f367978c70", "best_bid": "0.194", "best_ask": "0.195"}, {"asset_id": "87854174148074652060467921081181402357467303721471806610111179101805869578687", "price": "0.807", "size": "10994", "side": "SELL", "hash": "435b565804f1ad43753bca25d068b986dcc441b1", "best_bid": "0.805", "best_ask": "0.806"}], "timestamp": "1785164015012", "event_type": "price_change"}}
{"ts": 1785164015.071, "kind": "price_change", "data": {"market": "0x0f49db97f71c68b1e42a6d16e3de93d85dbf7d4148e3f018eb79e88554be9f75", "price_changes": [{"asset_id": "87854174148074652060467921081181402357467303721471806610111179101805869578687", "price": "0.803", "size": "12434.97", "side": "BUY", "hash": "8449f3b4dbb781d579aad8d96e8b55280604294f", "best_bid": "0.805", "best_ask": "0.806"}, {"asset_id": "54533043819946592547517511176940999955633860128497669742211153063842200957669", "price": "0.197", "size": "12434.97", "side": "SELL", "hash": "3a26b4d6143ac441be5024ca6937414cb73a95d3", "best_bid": "0.194", "best_ask": "0.195"}], "timestamp": "1785164015071", "event_type": "price_change"}}
{"ts": 1785164015.462, "kind": "price_change", "data": {"market": "0x0f49db97f71c68b1e42a6d16e3de93d85dbf7d4148e3f018eb79e88554be9f75", "price_changes": [{"asset_id": "54533043819946592547517511176940999955633860128497669742211153063842200957669", "price": "0.193", "size": "11094", "side": "BUY", "hash": "8708e5fe3299c2d4b6888ec56bbbd919a8b08cdb", "best_bid": "0.194", "best_ask": "0.195"}, {"asset_id": "87854174148074652060467921081181402357467303721471806610111179101805869578687", "price": "0.807", "size": "11094", "side": "SELL", "hash": "af4be28dd95ad8fe135ea7fd7a378c26ece3b952", "best_bid": "0.805", "best_ask": "0.806"}], "timestamp": "1785164015462", "event_type": "price_change"}}
{"ts": 1785164015.713, "kind": "price_change", "data": {"market": "0x0f49db97f71c68b1e42a6d16e3de93d85dbf7d4148e3f018eb79e88554be9f75", "price_changes": [{"asset_id": "54533043819946592547517511176940999955633860128497669742211153063842200957669", "price": "0.18", "size": "11835.95", "side": "BUY", "hash": "36e3cd11ee8b60f7fc834ef5e44ff6665db191fb", "best_bid": "0.194", "best_ask": "0.195"}, {"asset_id": "87854174148074652060467921081181402357467303721471806610111179101805869578687", "price": "0.82", "size": "11835.95", "side": "SELL", "hash": "e8720fb57bf192d9fc91cd97fde9871681b2156f", "best_bid": "0.805", "best_ask": "0.806"}], "timestamp": "1785164015713", "event_type": "price_change"}}
{"ts": 1785164017.379, "kind": "price_change", "data": {"market": "0x0f49db97f71c68b1e42a6d16e3de93d85dbf7d4148e3f018eb79e88554be9f75", "price_changes": [{"asset_id": "87854174148074652060467921081181402357467303721471806610111179101805869578687", "price": "0.001", "size": "6146756.01", "side": "BUY", "hash": "3ce62c34b04375516476aaac11363583644379f2", "best_bid": "0.805", "best_ask": "0.806"}, {"asset_id": "54533043819946592547517511176940999955633860128497669742211153063842200957669", "price": "0.999", "size": "6146756.01", "side": "SELL", "hash": "add558f500b442e454bb94e3d65d824634534054", "best_bid": "0.194", "best_ask": "0.195"}], "timestamp": "1785164017379", "event_type": "price_change"}}
{"ts": 1785164017.384, "kind": "price_change", "data": {"market": "0x0f49db97f71c68b1e42a6d16e3de93d85dbf7d4148e3f018eb79e88554be9f75", "price_changes": [{"asset_id": "87854174148074652060467921081181402357467303721471806610111179101805869578687", "price": "0.001", "size": "6147766.01", "side": "BUY", "hash": "d2e8d378191f7ab645fc3f72f456261a7d8436eb", "best_bid": "0.805", "best_ask": "0.806"}, {"asset_id": "54533043819946592547517511176940999955633860128497669742211153063842200957669", "price": "0.999", "size": "6147766.01", "side": "SELL", "hash": "e315d57cd0ad85e8e3df93408d7e9574b97e36f2", "best_bid": "0.194", "best_ask": "0.195"}], "timestamp": "1785164017384", "event_type": "price_change"}}
{"ts": 1785164018.257, "kind": "price_change", "data": {"market": "0x18b1c135d0a40c5894da9412e77311827d9caf16cf4cd6591b247a34730af919", "price_changes": [{"asset_id": "40081275558852222228080198821361202017557872256707631666334039001378518619916", "price": "0.506", "size": "0", "side": "SELL", "hash": "8f65293249318e428080caf749c8aca9040e2233", "best_bid": "0.428", "best_ask": "0.429"}, {"asset_id": "78633590736077251574794513664747155551297291244492840448622550955320930591622", "price": "0.494", "size": "0", "side": "BUY", "hash": "c82496b2dd8920ffb0765b0024fdb16c0667ab86", "best_bid": "0.571", "best_ask": "0.572"}], "timestamp": "1785164018257", "event_type": "price_change"}}
{"ts": 1785164018.857, "kind": "price_change", "data": {"market": "0x0f49db97f71c68b1e42a6d16e3de93d85dbf7d4148e3f018eb79e88554be9f75", "price_changes": [{"asset_id": "54533043819946592547517511176940999955633860128497669742211153063842200957669", "price": "0.009", "size": "0", "side": "BUY", "hash": "1ab4725700450df3721f35a9ba3f72714a1bc641", "best_bid": "0.194", "best_ask": "0.195"}, {"asset_id": "87854174148074652060467921081181402357467303721471806610111179101805869578687", "price": "0.991", "size": "0", "side": "SELL", "hash": "3e65d0a339024cbc9c9bd0b12418d5aa4443839c", "best_bid": "0.805", "best_ask": "0.806"}], "timestamp": "1785164018857", "event_type": "price_change"}}
{"ts": 1785164018.857, "kind": "price_change", "data": {"market": "0x0f49db97f71c68b1e42a6d16e3de93d85dbf7d4148e3f018eb79e88554be9f75", "price_changes": [{"asset_id": "54533043819946592547517511176940999955633860128497669742211153063842200957669", "price": "0.007", "size": "0", "side": "BUY", "hash": "1ab4725700450df3721f35a9ba3f72714a1bc641", "best_bid": "0.194", "best_ask": "0.195"}, {"asset_id": "87854174148074652060467921081181402357467303721471806610111179101805869578687", "price": "0.993", "size": "0", "side": "SELL", "hash": "3e65d0a339024cbc9c9bd0b12418d5aa4443839c", "best_bid": "0.805", "best_ask": "0.806"}], "timestamp": "1785164018857", "event_type": "price_change"}}
{"ts": 1785164019.206, "kind": "price_change", "data": {"market": "0x18b1c135d0a40c5894da9412e77311827d9caf16cf4cd6591b247a34730af919", "price_changes": [{"asset_id": "40081275558852222228080198821361202017557872256707631666334039001378518619916", "price": "0.505", "size": "36.7", "side": "SELL", "hash": "7aa8fa18aef46911f7396e7b3b52abed142b02de", "best_bid": "0.428", "best_ask": "0.429"}, {"asset_id": "78633590736077251574794513664747155551297291244492840448622550955320930591622", "price": "0.495", "size": "36.7", "side": "BUY", "hash": "c9a41c89b5ee9b468ab872a7324ee426ee56424b", "best_bid": "0.571", "best_ask": "0.572"}], "timestamp": "1785164019206", "event_type": "price_change"}}
{"ts": 1785164023.684, "kind": "price_change", "data": {"market": "0x18b1c135d0a40c5894da9412e77311827d9caf16cf4cd6591b247a34730af919", "price_changes": [{"asset_id": "40081275558852222228080198821361202017557872256707631666334039001378518619916", "price": "0.41", "size": "2931.23", "side": "BUY", "hash": "894cd21aadef18cc6bdbb0320ff890f159c69849", "best_bid": "0.428", "best_ask": "0.429"}, {"asset_id": "78633590736077251574794513664747155551297291244492840448622550955320930591622", "price": "0.59", "size": "2931.23", "side": "SELL", "hash": "60154e7c0843f234cede00609144facbbcdc16ab", "best_bid": "0.571", "best_ask": "0.572"}], "timestamp": "1785164023684", "event_type": "price_change"}}
{"ts": 1785164024.368, "kind": "price_change", "data": {"market": "0x18b1c135d0a40c5894da9412e77311827d9caf16cf4cd6591b247a34730af919", "price_changes": [{"asset_id": "40081275558852222228080198821361202017557872256707631666334039001378518619916", "price": "0.41", "size": "2947.28", "side": "BUY", "hash": "3358d6a66c16cdb5ef2379782621b8b2ca56deb1", "best_bid": "0.428", "best_ask": "0.429"}, {"asset_id": "78633590736077251574794513664747155551297291244492840448622550955320930591622", "price": "0.59", "size": "2947.28", "side": "SELL", "hash": "069f00d353c0ae13cc721ce8f7b68206cfe2ac82", "best_bid": "0.571", "best_ask": "0.572"}], "timestamp": "1785164024368", "event_type": "price_change"}}
{"ts": 1785164025.929, "kind": "price_change", "data": {"market": "0x18b1c135d0a40c5894da9412e77311827d9caf16cf4cd6591b247a34730af919", "price_changes": [{"asset_id": "40081275558852222228080198821361202017557872256707631666334039001378518619916", "price": "0.505", "size": "0", "side": "SELL", "hash": "fa5896c590283e119020539b7f19336fccbbaf7c", "best_bid": "0.428", "best_ask": "0.429"}, {"asset_id": "78633590736077251574794513664747155551297291244492840448622550955320930591622", "price": "0.495", "size": "0", "side": "BUY", "hash": "4cb5b32ce63ba62de153ae95bc8b08c23a178e68", "best_bid": "0.571", "best_ask": "0.572"}], "timestamp": "1785164025929", "event_type": "price_change"}}
{"ts": 1785164026.53, "kind": "price_change", "data": {"market": "0x18b1c135d0a40c5894da9412e77311827d9caf16cf4cd6591b247a34730af919", "price_changes": [{"asset_id": "40081275558852222228080198821361202017557872256707631666334039001378518619916", "price": "0.505", "size": "36.7", "side": "SELL", "hash": "c51ca150569b48abcc466a5ada4b438b68bfcbe2", "best_bid": "0.428", "best_ask": "0.429"}, {"asset_id": "78633590736077251574794513664747155551297291244492840448622550955320930591622", "price": "0.495", "size": "36.7", "side": "BUY", "hash": "87f7018135120712572739455749dd65587fce5a", "best_bid": "0.571", "best_ask": "0.572"}], "timestamp": "1785164026530", "event_type": "price_change"}}
{"ts": 1785164027.578, "kind": "price_change", "data": {"market": "0x18b1c135d0a40c5894da9412e77311827d9caf16cf4cd6591b247a34730af919", "price_changes": [{"asset_id": "40081275558852222228080198821361202017557872256707631666334039001378518619916", "price": "0.505", "size": "0", "side": "SELL", "hash": "9e64118874a5733acea0f2861974d5aafa8ca8af", "best_bid": "0.428", "best_ask": "0.429"}, {"asset_id": "78633590736077251574794513664747155551297291244492840448622550955320930591622", "price": "0.495", "size": "0", "side": "BUY", "hash": "a564ff61f70061ab8be57437b44e84d049771cc6", "best_bid": "0.571", "best_ask": "0.572"}], "timestamp": "1785164027578", "event_type": "price_change"}}
{"ts": 1785164027.87, "kind": "price_change", "data": {"market": "0x18b1c135d0a40c5894da9412e77311827d9caf16cf4cd6591b247a34730af919", "price_changes": [{"asset_id": "40081275558852222228080198821361202017557872256707631666334039001378518619916", "price": "0.506", "size": "36.7", "side": "SELL", "hash": "4ca0c50ab1fb6ad4b341742ba09d53ef01fb7626", "best_bid": "0.428", "best_ask": "0.429"}, {"asset_id": "78633590736077251574794513664747155551297291244492840448622550955320930591622", "price": "0.494", "size": "36.7", "side": "BUY", "hash": "0b40a64beefe2f94bedfbe38e7d36985735b25c7", "best_bid": "0.571", "best_ask": "0.572"}], "timestamp": "1785164027870", "event_type": "price_change"}}
{"ts": 1785164029.002, "kind": "price_change", "data": {"market": "0x18b1c135d0a40c5894da9412e77311827d9caf16cf4cd6591b247a34730af919", "price_changes": [{"asset_id": "40081275558852222228080198821361202017557872256707631666334039001378518619916", "price": "0.05", "size": "0", "side": "BUY", "hash": "15ce1f0c0474cc573e4141a9d65ff3a3c0890cb9", "best_bid": "0.428", "best_ask": "0.429"}, {"asset_id": "78633590736077251574794513664747155551297291244492840448622550955320930591622", "price": "0.95", "size": "0", "side": "SELL", "hash": "663c5870713a009447f44ab6a6bae224cc59f936", "best_bid": "0.571", "best_ask": "0.572"}], "timestamp": "1785164029002", "event_type": "price_change"}}
{"ts": 1785164032.0, "kind": "price_change", "data": {"market": "0x0f49db97f71c68b1e42a6d16e3de93d85dbf7d4148e3f018eb79e88554be9f75", "price_changes": [{"asset_id": "87854174148074652060467921081181402357467303721471806610111179101805869578687", "price": "0.004", "size": "0", "side": "BUY", "hash": "c8f5a9e76c0be67f182e5885e25668a0ee4a51c6", "best_bid": "0.805", "best_ask": "0.806"}, {"asset_id": "54533043819946592547517511176940999955633860128497669742211153063842200957669", "price": "0.996", "size": "0", "side": "SELL", "hash": "4c97adbfb3a4ad81ca30e87e0b766cc2c73ba2a9", "best_bid": "0.194", "best_ask": "0.195"}], "timestamp": "1785164032000", "event_type": "price_change"}}
{"ts": 1785164032.3041248, "kind": "orders_out", "data": [{"token_id": "54533043819946592547517511176940999955633860128497669742211153063842200957669", "side": "BUY", "price": 0.153, "size": 19.61}]}
{"ts": 1785164034.002, "kind": "price_change", "data": {"market": "0x18b1c135d0a40c5894da9412e77311827d9caf16cf4cd6591b247a34730af919", "price_changes": [{"asset_id": "78633590736077251574794513664747155551297291244492840448622550955320930591622", "price": "0.02", "size": "750", "side": "BUY", "hash": "baa7638adaff8f253d722287f8c8ae35b5d94e51", "best_bid": "0.571", "best_ask": "0.572"}, {"asset_id": "40081275558852222228080198821361202017557872256707631666334039001378518619916", "price": "0.98", "size": "750", "side": "SELL", "hash": "dc894c0af441d50abe643f0a91da5d4420d3625f", "best_bid": "0.428", "best_ask": "0.429"}], "timestamp": "1785164034002", "event_type": "price_change"}}
{"ts": 1785164035.165, "kind": "price_change", "data": {"market": "0x18b1c135d0a40c5894da9412e77311827d9caf16cf4cd6591b247a34730af919", "price_changes": [{"asset_id": "40081275558852222228080198821361202017557872256707631666334039001378518619916", "price": "0.05", "size": "20000", "side": "BUY", "hash": "fb97164245cc8f36642cb5d3258ecb284247fb36", "best_bid": "0.428", "best_ask": "0.429"}, {"asset_id": "78633590736077251574794513664747155551297291244492840448622550955320930591622", "price": "0.95", "size": "20000", "side": "SELL", "hash": "59a1390294d3f14f6c90cf1e672ef437e25e6092", "best_bid": "0.571", "best_ask": "0.572"}], "timestamp": "1785164035165", "event_type": "price_change"}}
{"ts": 1785164040.334, "kind": "price_change", "data": {"market": "0x0f49db97f71c68b1e42a6d16e3de93d85dbf7d4148e3f018eb79e88554be9f75", "price_changes": [{"asset_id": "87854174148074652060467921081181402357467303721471806610111179101805869578687", "price": "0.004", "size": "12500", "side": "BUY", "hash": "13ffa49629392aa53d78711dd8780e46e061a8f8", "best_bid": "0.805", "best_ask": "0.806"}, {"asset_id": "54533043819946592547517511176940999955633860128497669742211153063842200957669", "price": "0.996", "size": "12500", "side": "SELL", "hash": "dd2a6017b760873cd860aa75fe6cd2e9e0a5ad48", "best_bid": "0.194", "best_ask": "0.195"}], "timestamp": "1785164040334", "event_type": "price_change"}}
{"ts": 1785164040.762, "kind": "price_change", "data": {"market": "0x18b1c135d0a40c5894da9412e77311827d9caf16cf4cd6591b247a34730af919", "price_changes": [{"asset_id": "78633590736077251574794513664747155551297291244492840448622550955320930591622", "price": "0.02", "size": "75750", "side": "BUY", "hash": "84b2431d50aa89acb16b18702fdc834895e35e90", "best_bid": "0.571", "best_ask": "0.572"}, {"asset_id": "40081275558852222228080198821361202017557872256707631666334039001378518619916", "price": "0.98", "size": "75750", "side": "SELL", "hash": "dea0dc88849c72e6ca2ae7942411fb37b93c4b88", "best_bid": "0.428", "best_ask": "0.429"}], "timestamp": "1785164040762", "event_type": "price_change"}}
{"ts": 1785164041.701, "kind": "price_change", "data": {"market": "0x18b1c135d0a40c5894da9412e77311827d9caf16cf4cd6591b247a34730af919", "price_changes": [{"asset_id": "40081275558852222228080198821361202017557872256707631666334039001378518619916", "price": "0.506", "size": "0", "side": "SELL", "hash": "ced23b0fd2d8aefd59ecd1e8c49288ad2df0e38b", "best_bid": "0.428", "best_ask": "0.429"}, {"asset_id": "78633590736077251574794513664747155551297291244492840448622550955320930591622", "price": "0.494", "size": "0", "side": "BUY", "hash": "a848d59ff7b41a11a8c695a12851372645409b55", "best_bid": "0.571", "best_ask": "0.572"}], "timestamp": "1785164041701", "event_type": "price_change"}}
{"ts": 1785164041.891, "kind": "price_change", "data": {"market": "0x18b1c135d0a40c5894da9412e77311827d9caf16cf4cd6591b247a34730af919", "price_changes": [{"asset_id": "40081275558852222228080198821361202017557872256707631666334039001378518619916", "price": "0.41", "size": "2931.23", "side": "BUY", "hash": "d6780a83cb00c96ebe165869e7f52f3be91decf4", "best_bid": "0.428", "best_ask": "0.429"}, {"asset_id": "78633590736077251574794513664747155551297291244492840448622550955320930591622", "price": "0.59", "size": "2931.23", "side": "SELL", "hash": "83204476ecab24e517e9feb9a6be361d7c9350cb", "best_bid": "0.571", "best_ask": "0.572"}], "timestamp": "1785164041891", "event_type": "price_change"}}
{"ts": 1785164041.931, "kind": "price_change", "data": {"market": "0x18b1c135d0a40c5894da9412e77311827d9caf16cf4cd6591b247a34730af919", "price_changes": [{"asset_id": "40081275558852222228080198821361202017557872256707631666334039001378518619916", "price": "0.418", "size": "7088.45", "side": "BUY", "hash": "c4fd373ab02f28096e4bb11a4ea23ed60dfc0c5d", "best_bid": "0.428", "best_ask": "0.429"}, {"asset_id": "78633590736077251574794513664747155551297291244492840448622550955320930591622", "price": "0.582", "size": "7088.45", "side": "SELL", "hash": "8f1e5ef5d040165eda0d2edd370cbd23da13fedd", "best_bid": "0.571", "best_ask": "0.572"}], "timestamp": "1785164041931", "event_type": "price_change"}}
{"ts": 1785164041.931, "kind": "price_change", "data": {"market": "0x18b1c135d0a40c5894da9412e77311827d9caf16cf4cd6591b247a34730af919", "price_changes": [{"asset_id": "78633590736077251574794513664747155551297291244492840448622550955320930591622", "price": "0.551", "size": "28710.16", "side": "BUY", "hash": "8f1e5ef5d040165eda0d2edd370cbd23da13fedd", "best_bid": "0.571", "best_ask": "0.572"}, {"asset_id": "40081275558852222228080198821361202017557872256707631666334039001378518619916", "price": "0.449", "size": "28710.16", "side": "SELL", "hash": "c4fd373ab02f28096e4bb11a4ea23ed60dfc0c5d", "best_bid": "0.428", "best_ask": "0.429"}], "timestamp": "1785164041931", "event_type": "price_change"}}
{"ts": 1785164041.964, "kind": "price_change", "data": {"market": "0x18b1c135d0a40c5894da9412e77311827d9caf16cf4cd6591b247a34730af919", "price_changes": [{"asset_id": "40081275558852222228080198821361202017557872256707631666334039001378518619916", "price": "0.411", "size": "37107.4", "side": "BUY", "hash": "de20ad0aca681041f8239386a0b9aa29c717d9a8", "best_bid": "0.428", "best_ask": "0.429"}, {"asset_id": "78633590736077251574794513664747155551297291244492840448622550955320930591622", "price": "0.589", "size": "37107.4", "side": "SELL", "hash": "79848cf3526e3b07c5cdbb8f420594671930bdc2", "best_bid": "0.571", "best_ask": "0.572"}], "timestamp": "1785164041964", "event_type": "price_change"}}
{"ts": 1785164041.965, "kind": "price_change", "data": {"market": "0x18b1c135d0a40c5894da9412e77311827d9caf16cf4cd6591b247a34730af919", "price_changes": [{"asset_id": "78633590736077251574794513664747155551297291244492840448622550955320930591622", "price": "0.55", "size": "30579.18", "side": "BUY", "hash": "7c5837a8faf34c50923b3cf4e9d34f88adbf60d6", "best_bid": "0.571", "best_ask": "0.572"}, {"asset_id": "40081275558852222228080198821361202017557872256707631666334039001378518619916", "price": "0.45", "size": "30579.18", "side": "SELL", "hash": "1e61a385fb487717c1b0f9535b1fec9a39916960", "best_bid": "0.428", "best_ask": "0.429"}], "timestamp": "1785164041965", "event_type": "price_change"}}
{"ts": 1785164042.449, "kind": "price_change", "data": {"market": "0x18b1c135d0a40c5894da9412e77311827d9caf16cf4cd6591b247a34730af919", "price_changes": [{"asset_id": "40081275558852222228080198821361202017557872256707631666334039001378518619916", "price": "0.41", "size": "2947.28", "side": "BUY", "hash": "3e974d23166383161afce23b0b1a9c99fc16b3da", "best_bid": "0.428", "best_ask": "0.429"}, {"asset_id": "78633590736077251574794513664747155551297291244492840448622550955320930591622", "price": "0.59", "size": "2947.28", "side": "SELL", "hash": "8959b6b4a2992006a3215f5da7e27a97cdd2e101", "best_bid": "0.571", "best_ask": "0.572"}], "timestamp": "1785164042449", "event_type": "price_change"}}
{"ts": 1785164042.954, "kind": "price_change", "data": {"market": "0x18b1c135d0a40c5894da9412e77311827d9caf16cf4cd6591b247a34730af919", "price_changes": [{"asset_id": "40081275558852222228080198821361202017557872256707631666334039001378518619916", "price": "0.505", "size": "36.7", "side": "SELL", "hash": "b0c92a71cb8238f895b7fe888138e93a7100b23d", "best_bid": "0.428", "best_ask": "0.429"}, {"asset_id": "78633590736077251574794513664747155551297291244492840448622550955320930591622", "price": "0.495", "size": "36.7", "side": "BUY", "hash": "597043493bd519ae467b105afede13736a7a45a8", "best_bid": "0.571", "best_ask": "0.572"}], "timestamp": "1785164042954", "event_type": "price_change"}}
{"ts": 1785164048.133, "kind": "price_change", "data": {"market": "0x18b1c135d0a40c5894da9412e77311827d9caf16cf4cd6591b247a34730af919", "price_changes": [{"asset_id": "40081275558852222228080198821361202017557872256707631666334039001378518619916", "price": "0.505", "size": "0", "side": "SELL", "hash": "769242d6379817126785e25ad3e22f4321687ffd", "best_bid": "0.428", "best_ask": "0.429"}, {"asset_id": "78633590736077251574794513664747155551297291244492840448622550955320930591622", "price": "0.495", "size": "0", "side": "BUY", "hash": "c519c480c2314430141d10ba71ebea62a4a7018a", "best_bid": "0.571", "best_ask": "0.572"}], "timestamp": "1785164048133", "event_type": "price_change"}}
{"ts": 1785164049.165, "kind": "price_change", "data": {"market": "0x18b1c135d0a40c5894da9412e77311827d9caf16cf4cd6591b247a34730af919", "price_changes": [{"asset_id": "40081275558852222228080198821361202017557872256707631666334039001378518619916", "price": "0.505", "size": "36.7", "side": "SELL", "hash": "e44a589ea9eca7a18d3704df7628e45ca86e5330", "best_bid": "0.428", "best_ask": "0.429"}, {"asset_id": "78633590736077251574794513664747155551297291244492840448622550955320930591622", "price": "0.495", "size": "36.7", "side": "BUY", "hash": "430d309c67efdddf6606b3523e6e3d3474a403f3", "best_bid": "0.571", "best_ask": "0.572"}], "timestamp": "1785164049165", "event_type": "price_change"}}
{"ts": 1785164050.497, "kind": "price_change", "data": {"market": "0x18b1c135d0a40c5894da9412e77311827d9caf16cf4cd6591b247a34730af919", "price_changes": [{"asset_id": "78633590736077251574794513664747155551297291244492840448622550955320930591622", "price": "0.311", "size": "0", "side": "BUY", "hash": "ab21fd0552e8e332e1628e15858ed28784394c05", "best_bid": "0.571", "best_ask": "0.572"}, {"asset_id": "40081275558852222228080198821361202017557872256707631666334039001378518619916", "price": "0.689", "size": "0", "side": "SELL", "hash": "22c91f6affa57eb7978667d614ec4b1bff758441", "best_bid": "0.428", "best_ask": "0.429"}], "timestamp": "1785164050497", "event_type": "price_change"}}
{"ts": 1785164050.517, "kind": "price_change", "data": {"market": "0x18b1c135d0a40c5894da9412e77311827d9caf16cf4cd6591b247a34730af919", "price_changes": [{"asset_id": "78633590736077251574794513664747155551297291244492840448622550955320930591622", "price": "0.482", "size": "161.09", "side": "BUY", "hash": "eb7e84463ce7191e7d18e130bc5a292be214ad9d", "best_bid": "0.571", "best_ask": "0.572"}, {"asset_id": "40081275558852222228080198821361202017557872256707631666334039001378518619916", "price": "0.518", "size": "161.09", "side": "SELL", "hash": "4087472ef99098c486e1b721a894c65cf24676a1", "best_bid": "0.428", "best_ask": "0.429"}], "timestamp": "1785164050517", "event_type": "price_change"}}
{"ts": 1785164050.546, "kind": "price_change", "data": {"market": "0x18b1c135d0a40c5894da9412e77311827d9caf16cf4cd6591b247a34730af919", "price_changes": [{"asset_id": "78633590736077251574794513664747155551297291244492840448622550955320930591622", "price": "0.485", "size": "107", "side": "BUY", "hash": "51ffe2f659d89c75acf2b9054c99e3fd78aa333f", "best_bid": "0.571", "best_ask": "0.572"}, {"asset_id": "40081275558852222228080198821361202017557872256707631666334039001378518619916", "price": "0.515", "size": "107", "side": "SELL", "hash": "4326ce5d2352fb806d72a20f6c9435ad6d14a011", "best_bid": "0.428", "best_ask": "0.429"}], "timestamp": "1785164050546", "event_type": "price_change"}}
{"ts": 1785164050.547, "kind": "price_change", "data": {"market": "0x18b1c135d0a40c5894da9412e77311827d9caf16cf4cd6591b247a34730af919", "price_changes": [{"asset_id": "78633590736077251574794513664747155551297291244492840448622550955320930591622", "price": "0.486", "size": "10", "side": "BUY", "hash": "2701ab9d09a4f940dad3829ef45170eb03299256", "best_bid": "0.571", "best_ask": "0.572"}, {"asset_id": "40081275558852222228080198821361202017557872256707631666334039001378518619916", "price": "0.514", "size": "10", "side": "SELL", "hash": "130c1cf2f88102f7f9066d26cbaf6b23d7e1f980", "best_bid": "0.428", "best_ask": "0.429"}], "timestamp": "1785164050547", "event_type": "price_change"}}
{"ts": 1785164050.571, "kind": "price_change", "data": {"market": "0x18b1c135d0a40c5894da9412e77311827d9caf16cf4cd6591b247a34730af919", "price_changes": [{"asset_id": "78633590736077251574794513664747155551297291244492840448622550955320930591622", "price": "0.482", "size": "0", "side": "BUY", "hash": "e572942106aa2da5c64d912590ba121e5373e2ac", "best_bid": "0.571", "best_ask": "0.572"}, {"asset_id": "40081275558852222228080198821361202017557872256707631666334039001378518619916", "price": "0.518", "size": "0", "side": "SELL", "hash": "af8bd192571701ade74d15a898b785fbfdf356e1", "best_bid": "0.428", "best_ask": "0.429"}], "timestamp": "1785164050571", "event_type": "price_change"}}
{"ts": 1785164050.571, "kind": "price_change", "data": {"market": "0x18b1c135d0a40c5894da9412e77311827d9caf16cf4cd6591b247a34730af919", "price_changes": [{"asset_id": "78633590736077251574794513664747155551297291244492840448622550955320930591622", "price": "0.485", "size": "30", "side": "BUY", "hash": "e572942106aa2da5c64d912590ba121e5373e2ac", "best_bid": "0.571", "best_ask": "0.572"}, {"asset_id": "40081275558852222228080198821361202017557872256707631666334039001378518619916", "price": "0.515", "size": "30", "side": "SELL", "hash": "af8bd192571701ade74d15a898b785fbfdf356e1", "best_bid": "0.428", "best_ask": "0.429"}], "timestamp": "1785164050571", "event_type": "price_change"}}
{"ts": 1785164050.592, "kind": "price_change", "data": {"market": "0x18b1c135d0a40c5894da9412e77311827d9caf16cf4cd6591b247a34730af919", "price_changes": [{"asset_id": "78633590736077251574794513664747155551297291244492840448622550955320930591622", "price": "0.486", "size": "0", "side": "BUY", "hash": "a948a7535f574089ddeb9a0babb3aa5f8c29a59c", "best_bid": "0.571", "best_ask": "0.572"}, {"asset_id": "40081275558852222228080198821361202017557872256707631666334039001378518619916", "price": "0.514", "size": "0", "side": "SELL", "hash": "cbeb54be0984853c896477c8aa189af01fcdf9bc", "best_bid": "0.428", "best_ask": "0.429"}], "timestamp": "1785164050592", "event_type": "price_change"}}
{"ts": 1785164050.592, "kind": "price_change", "data": {"market": "0x18b1c135d0a40c5894da9412e77311827d9caf16cf4cd6591b247a34730af919", "price_changes": [{"asset_id": "78633590736077251574794513664747155551297291244492840448622550955320930591622", "price": "0.485", "size": "0", "side": "BUY", "hash": "a948a7535f574089ddeb9a0babb3aa5f8c29a59c", "best_bid": "0.571", "best_ask": "0.572"}, {"asset_id": "40081275558852222228080198821361202017557872256707631666334039001378518619916", "price": "0.515", "size": "0", "side": "SELL", "hash": "cbeb54be0984853c896477c8aa189af01fcdf9bc", "best_bid": "0.428", "best_ask": "0.429"}], "timestamp": "1785164050592", "event_type": "price_change"}}
{"ts": 1785164050.618, "kind": "price_change", "data": {"market": "0x18b1c135d0a40c5894da9412e77311827d9caf16cf4cd6591b247a34730af919", "price_changes": [{"asset_id": "78633590736077251574794513664747155551297291244492840448622550955320930591622", "price": "0.482", "size": "30", "side": "BUY", "hash": "35900bec09f0bbc9b620e3920899f79856a88a43", "best_bid": "0.571", "best_ask": "0.572"}, {"asset_id": "40081275558852222228080198821361202017557872256707631666334039001378518619916", "price": "0.518", "size": "30", "side": "SELL", "hash": "d098c508e5a6de3d21e1914b67c951c9eb7d33a3", "best_bid": "0.428", "best_ask": "0.429"}], "timestamp": "1785164050618", "event_type": "price_change"}}
{"ts": 1785164050.62, "kind": "price_change", "data": {"market": "0x18b1c135d0a40c5894da9412e77311827d9caf16cf4cd6591b247a34730af919", "price_changes": [{"asset_id": "78633590736077251574794513664747155551297291244492840448622550955320930591622", "price": "0.482", "size": "40", "side": "BUY", "hash": "abd4a44a0963b8d6511e6fc9c47f9d89847e13a9", "best_bid": "0.571", "best_ask": "0.572"}, {"asset_id": "40081275558852222228080198821361202017557872256707631666334039001378518619916", "price": "0.518", "size": "40", "side": "SELL", "hash": "9bdac588a104f976c5324ed70042a8451f373921", "best_bid": "0.428", "best_ask": "0.429"}], "timestamp": "1785164050620", "event_type": "price_change"}}
{"ts": 1785164050.654, "kind": "price_change", "data": {"market": "0x18b1c135d0a40c5894da9412e77311827d9caf16cf4cd6591b247a34730af919", "price_changes": [{"asset_id": "78633590736077251574794513664747155551297291244492840448622550955320930591622", "price": "0.479", "size": "238.09", "side": "BUY", "hash": "e3bec29e8f31b00e3b93bf491c976a870dfe3f15", "best_bid": "0.571", "best_ask": "0.572"}, {"asset_id": "40081275558852222228080198821361202017557872256707631666334039001378518619916", "price": "0.521", "size": "238.09", "side": "SELL", "hash": "b08bf5ae91005b6074b9fad85588ad08750db449", "best_bid": "0.428", "best_ask": "0.429"}], "timestamp": "1785164050654", "event_type": "price_change"}}
{"ts": 1785164050.692, "kind": "price_change", "data": {"market": "0x18b1c135d0a40c5894da9412e77311827d9caf16cf4cd6591b247a34730af919", "price_changes": [{"asset_id": "78633590736077251574794513664747155551297291244492840448622550955320930591622", "price": "0.479", "size": "0", "side": "BUY", "hash": "181211aa12560002f9da715f856698f1b58d9e91", "best_bid": "0.571", "best_ask": "0.572"}, {"asset_id": "40081275558852222228080198821361202017557872256707631666334039001378518619916", "price": "0.521", "size": "0", "side": "SELL", "hash": "36beed4c259b026b09ecfde15e429e739dbe3894", "best_bid": "0.428", "best_ask": "0.429"}], "timestamp": "1785164050692", "event_type": "price_change"}}
{"ts": 1785164054.34, "kind": "price_change", "data": {"market": "0x18b1c135d0a40c5894da9412e77311827d9caf16cf4cd6591b247a34730af919", "price_changes": [{"asset_id": "78633590736077251574794513664747155551297291244492840448622550955320930591622", "price": "0.372", "size": "48.28", "side": "BUY", "hash": "cec12bf6d464e6cf251f7c09d1dacd3eaca2b84f", "best_bid": "0.571", "best_ask": "0.572"}, {"asset_id": "40081275558852222228080198821361202017557872256707631666334039001378518619916", "price": "0.628", "size": "48.28", "side": "SELL", "hash": "2d56ac02d7ff7271517d2d70615dbc684c077efc", "best_bid": "0.428", "best_ask": "0.429"}], "timestamp": "1785164054340", "event_type": "price_change"}}
{"ts": 1785164055.497, "kind": "price_change", "data": {"market": "0x18b1c135d0a40c5894da9412e77311827d9caf16cf4cd6591b247a34730af919", "price_changes": [{"asset_id": "40081275558852222228080198821361202017557872256707631666334039001378518619916", "price": "0.505", "size": "0", "side": "SELL", "hash": "cef892476d6d3906c5e190a78b81cd8ad3bfaaf7", "best_bid": "0.428", "best_ask": "0.429"}, {"asset_id": "78633590736077251574794513664747155551297291244492840448622550955320930591622", "price": "0.495", "size": "0", "side": "BUY", "hash": "993be9f864cdda1bf45f5114640b61b36b30b6bc", "best_bid": "0.571", "best_ask": "0.572"}], "timestamp": "1785164055497", "event_type": "price_change"}}
{"ts": 1785164056.281, "kind": "price_change", "data": {"market": "0x18b1c135d0a40c5894da9412e77311827d9caf16cf4cd6591b247a34730af919", "price_changes": [{"asset_id": "40081275558852222228080198821361202017557872256707631666334039001378518619916", "price": "0.505", "size": "36.7", "side": "SELL", "hash": "fe82c1acf1518a70fd78f50cb635e60ec78309dc", "best_bid": "0.428", "best_ask": "0.429"}, {"asset_id": "78633590736077251574794513664747155551297291244492840448622550955320930591622", "price": "0.495", "size": "36.7", "side": "BUY", "hash": "69749265e75d368ae41cd181f20e52cf0bc42176", "best_bid": "0.571", "best_ask": "0.572"}], "timestamp": "1785164056281", "event_type": "price_change"}}
{"ts": 1785164057.035, "kind": "price_change", "data": {"market": "0x18b1c135d0a40c5894da9412e77311827d9caf16cf4cd6591b247a34730af919", "price_changes": [{"asset_id": "40081275558852222228080198821361202017557872256707631666334039001378518619916", "price": "0.505", "size": "0", "side": "SELL", "hash": "5bd1fa1be09179c376cf0dee40268f40deb87b40", "best_bid": "0.428", "best_ask": "0.429"}, {"asset_id": "78633590736077251574794513664747155551297291244492840448622550955320930591622", "price": "0.495", "size": "0", "side": "BUY", "hash": "c49aa8553b6d97f07246004f7257c3b395a650b6", "best_bid": "0.571", "best_ask": "0.572"}], "timestamp": "1785164057035", "event_type": "price_change"}}
{"ts": 1785164057.355, "kind": "price_change", "data": {"market": "0x18b1c135d0a40c5894da9412e77311827d9caf16cf4cd6591b247a34730af919", "price_changes": [{"asset_id": "40081275558852222228080198821361202017557872256707631666334039001378518619916", "price": "0.506", "size": "36.7", "side": "SELL", "hash": "262e17371f2b41bb951e1e7f4ed24f4772034e3e", "best_bid": "0.428", "best_ask": "0.429"}, {"asset_id": "78633590736077251574794513664747155551297291244492840448622550955320930591622", "price": "0.494", "size": "36.7", "side": "BUY", "hash": "f71fd3009233c71c59eb8f9937c5d235b63e0386", "best_bid": "0.571", "best_ask": "0.572"}], "timestamp": "1785164057355", "event_type": "price_change"}}
{"ts": 1785164058.612, "kind": "price_change", "data": {"market": "0x18b1c135d0a40c5894da9412e77311827d9caf16cf4cd6591b247a34730af919", "price_changes": [{"asset_id": "78633590736077251574794513664747155551297291244492840448622550955320930591622", "price": "0.551", "size": "27622.16", "side": "BUY", "hash": "ce99af17dfd9fc9f904a573bcbacd56372f4dc89", "best_bid": "0.571", "best_ask": "0.572"}, {"asset_id": "40081275558852222228080198821361202017557872256707631666334039001378518619916", "price": "0.449", "size": "27622.16", "side": "SELL", "hash": "38aec8c5b4b0bd129df796b71ce4e960d76c246f", "best_bid": "0.428", "best_ask": "0.429"}], "timestamp": "1785164058612", "event_type": "price_change"}}
{"ts": 1785164058.641, "kind": "price_change", "data": {"market": "0x18b1c135d0a40c5894da9412e77311827d9caf16cf4cd6591b247a34730af919", "price_changes": [{"asset_id": "78633590736077251574794513664747155551297291244492840448622550955320930591622", "price": "0.551", "size": "28710.16", "side": "BUY", "hash": "53814d305f9de7651627de107e0df463bd1c57c3", "best_bid": "0.571", "best_ask": "0.572"}, {"asset_id": "40081275558852222228080198821361202017557872256707631666334039001378518619916", "price": "0.449", "size": "28710.16", "side": "SELL", "hash": "61a86d8baf78f71852324525e163f92002207d84", "best_bid": "0.428", "best_ask": "0.429"}], "timestamp": "1785164058641", "event_type": "price_change"}}
{"ts": 1785164058.978, "kind": "price_change", "data": {"market": "0x0f49db97f71c68b1e42a6d16e3de93d85dbf7d4148e3f018eb79e88554be9f75", "price_changes": [{"asset_id": "87854174148074652060467921081181402357467303721471806610111179101805869578687", "price": "0.795", "size": "2864.98", "side": "BUY", "hash": "42bc4be574e4c3d044d8731563be55c8bf732d93", "best_bid": "0.805", "best_ask": "0.806"}, {"asset_id": "54533043819946592547517511176940999955633860128497669742211153063842200957669", "price": "0.205", "size": "2864.98", "side": "SELL", "hash": "8459bf827504abd6981dcfd5393c1996d936e949", "best_bid": "0.194", "best_ask": "0.195"}], "timestamp": "1785164058978", "event_type": "price_change"}}
{"ts": 1785164059.047, "kind": "price_change", "data": {"market": "0x0f49db97f71c68b1e42a6d16e3de93d85dbf7d4148e3f018eb79e88554be9f75", "price_changes": [{"asset_id": "87854174148074652060467921081181402357467303721471806610111179101805869578687", "price": "0.795", "size": "3431.98", "side": "BUY", "hash": "c1d388f42ce72288e2ce54628860d5f56c59d0aa", "best_bid": "0.805", "best_ask": "0.806"}, {"asset_id": "54533043819946592547517511176940999955633860128497669742211153063842200957669", "price": "0.205", "size": "3431.98", "side": "SELL", "hash": "d3edddc0c2f0b9d9a5881ebdeeffd0af385db39e", "best_bid": "0.194", "best_ask": "0.195"}], "timestamp": "1785164059047", "event_type": "price_change"}}
{"ts": 1785164059.513, "kind": "price_change", "data": {"market": "0x18b1c135d0a40c5894da9412e77311827d9caf16cf4cd6591b247a34730af919", "price_changes": [{"asset_id": "40081275558852222228080198821361202017557872256707631666334039001378518619916", "price": "0.418", "size": "6010.45", "side": "BUY", "hash": "842b967f9e26fe8b1b6cb078271a0f4741fa13bd", "best_bid": "0.428", "best_ask": "0.429"}, {"asset_id": "78633590736077251574794513664747155551297291244492840448622550955320930591622", "price": "0.582", "size": "6010.45", "side": "SELL", "hash": "e5b5ae0f0cabec4211202e1aea037dd6799ca169", "best_bid": "0.571", "best_ask": "0.572"}], "timestamp": "1785164059513", "event_type": "price_change"}}
{"ts": 1785164059.588, "kind": "price_change", "data": {"market": "0x18b1c135d0a40c5894da9412e77311827d9caf16cf4cd6591b247a34730af919", "price_changes": [{"asset_id": "40081275558852222228080198821361202017557872256707631666334039001378518619916", "price": "0.418", "size": "7088.45", "side": "BUY", "hash": "06a1c5f65b751d55d8ddabdb6703ab26400b7976", "best_bid": "0.428", "best_ask": "0.429"}, {"asset_id": "78633590736077251574794513664747155551297291244492840448622550955320930591622", "price": "0.582", "size": "7088.45", "side": "SELL", "hash": "a319fef2633c973aa4263c976bd99aa881c8a312", "best_bid": "0.571", "best_ask": "0.572"}], "timestamp": "1785164059588", "event_type": "price_change"}}
{"ts": 1785164062.711, "kind": "price_change", "data": {"market": "0x18b1c135d0a40c5894da9412e77311827d9caf16cf4cd6591b247a34730af919", "price_changes": [{"asset_id": "40081275558852222228080198821361202017557872256707631666334039001378518619916", "price": "0.41", "size": "2931.23", "side": "BUY", "hash": "4b9d0cd5a879644da6fbc0c883526416e7ac110c", "best_bid": "0.428", "best_ask": "0.429"}, {"asset_id": "78633590736077251574794513664747155551297291244492840448622550955320930591622", "price": "0.59", "size": "2931.23", "side": "SELL", "hash": "25d5ae8c9905e088b2b25bf086363ad9f7685f10", "best_bid": "0.571", "best_ask": "0.572"}], "timestamp": "1785164062711", "event_type": "price_change"}}
{"ts": 1785164062.754, "kind": "price_change", "data": {"market": "0x0f49db97f71c68b1e42a6d16e3de93d85dbf7d4148e3f018eb79e88554be9f75", "price_changes": [{"asset_id": "54533043819946592547517511176940999955633860128497669742211153063842200957669", "price": "0.009", "size": "13888.88", "side": "BUY", "hash": "a19e26fba85c92581c381d2a22a9e9097a2c8100", "best_bid": "0.194", "best_ask": "0.195"}, {"asset_id": "87854174148074652060467921081181402357467303721471806610111179101805869578687", "price": "0.991", "size": "13888.88", "side": "SELL", "hash": "ce1d6a3e3154aa22f787bf1b0558ae5e3cc947c1", "best_bid": "0.805", "best_ask": "0.806"}], "timestamp": "1785164062754", "event_type": "price_change"}}
{"ts": 1785164062.757, "kind": "price_change", "data": {"market": "0x0f49db97f71c68b1e42a6d16e3de93d85dbf7d4148e3f018eb79e88554be9f75", "price_changes": [{"asset_id": "54533043819946592547517511176940999955633860128497669742211153063842200957669", "price": "0.007", "size": "53571.42", "side": "BUY", "hash": "3b896e1fc74564226e1a0049b757983c7ef20344", "best_bid": "0.194", "best_ask": "0.195"}, {"asset_id": "87854174148074652060467921081181402357467303721471806610111179101805869578687", "price": "0.993", "size": "53571.42", "side": "SELL", "hash": "032940795117f987be0081dd4f48ee6a297f702a", "best_bid": "0.805", "best_ask": "0.806"}], "timestamp": "1785164062757", "event_type": "price_change"}}
{"ts": 1785164063.52, "kind": "price_change", "data": {"market": "0x18b1c135d0a40c5894da9412e77311827d9caf16cf4cd6591b247a34730af919", "price_changes": [{"asset_id": "40081275558852222228080198821361202017557872256707631666334039001378518619916", "price": "0.41", "size": "2947.28", "side": "BUY", "hash": "714b009e31a1e47c29f900bf3503b3769e544ae1", "best_bid": "0.428", "best_ask": "0.429"}, {"asset_id": "78633590736077251574794513664747155551297291244492840448622550955320930591622", "price": "0.59", "size": "2947.28", "side": "SELL", "hash": "b2d5bc50150222b97a82e901f08586a368ecb9c3", "best_bid": "0.571", "best_ask": "0.572"}], "timestamp": "1785164063520", "event_type": "price_change"}}
{"ts": 1785164067.746, "kind": "price_change", "data": {"market": "0x0f49db97f71c68b1e42a6d16e3de93d85dbf7d4148e3f018eb79e88554be9f75", "price_changes": [{"asset_id": "54533043819946592547517511176940999955633860128497669742211153063842200957669", "price": "0.007", "size": "0", "side": "BUY", "hash": "d0be9d53739aee985b7ad00b18ea2758426f26a1", "best_bid": "0.194", "best_ask": "0.195"}, {"asset_id": "87854174148074652060467921081181402357467303721471806610111179101805869578687", "price": "0.993", "size": "0", "side": "SELL", "hash": "6630c9f90b9b6e5eb6b78b8d32c82c1c8e57c67b", "best_bid": "0.805", "best_ask": "0.806"}], "timestamp": "1785164067746", "event_type": "price_change"}}
{"ts": 1785164067.746, "kind": "price_change", "data": {"market": "0x0f49db97f71c68b1e42a6d16e3de93d85dbf7d4148e3f018eb79e88554be9f75", "price_changes": [{"asset_id": "54533043819946592547517511176940999955633860128497669742211153063842200957669", "price": "0.009", "size": "0", "side": "BUY", "hash": "d0be9d53739aee985b7ad00b18ea2758426f26a1", "best_bid": "0.194", "best_ask": "0.195"}, {"asset_id": "87854174148074652060467921081181402357467303721471806610111179101805869578687", "price": "0.991", "size": "0", "side": "SELL", "hash": "6630c9f90b9b6e5eb6b78b8d32c82c1c8e57c67b", "best_bid": "0.805", "best_ask": "0.806"}], "timestamp": "1785164067746", "event_type": "price_change"}}
{"ts": 1785164068.116308, "kind": "orders_out", "data": [{"token_id": "54533043819946592547517511176940999955633860128497669742211153063842200957669", "side": "BUY", "price": 0.153, "size": 19.61}]}
{"ts": 1785164068.303, "kind": "price_change", "data": {"market": "0x18b1c135d0a40c5894da9412e77311827d9caf16cf4cd6591b247a34730af919", "price_changes": [{"asset_id": "40081275558852222228080198821361202017557872256707631666334039001378518619916", "price": "0.506", "size": "0", "side": "SELL", "hash": "767a30f06547ac49a6c1aee9cc7baba86876fe98", "best_bid": "0.428", "best_ask": "0.429"}, {"asset_id": "78633590736077251574794513664747155551297291244492840448622550955320930591622", "price": "0.494", "size": "0", "side": "BUY", "hash": "726861d400f730abd403b435e49fc322ead06444", "best_bid": "0.571", "best_ask": "0.572"}], "timestamp": "1785164068303", "event_type": "price_change"}}
{"ts": 1785164068.916, "kind": "price_change", "data": {"market": "0x0f49db97f71c68b1e42a6d16e3de93d85dbf7d4148e3f018eb79e88554be9f75", "price_changes": [{"asset_id": "87854174148074652060467921081181402357467303721471806610111179101805869578687", "price": "0.795", "size": "2865.98", "side": "BUY", "hash": "fd4276fd5906fa27775c10de74eda59428b8b821", "best_bid": "0.805", "best_ask": "0.806"}, {"asset_id": "54533043819946592547517511176940999955633860128497669742211153063842200957669", "price": "0.205", "size": "2865.98", "side": "SELL", "hash": "5fa6fe661f1eb7b6012ef379131b91ea5c9a23bd", "best_bid": "0.194", "best_ask": "0.195"}], "timestamp": "1785164068916", "event_type": "price_change"}}
{"ts": 1785164068.991, "kind": "price_change", "data": {"market": "0x0f49db97f71c68b1e42a6d16e3de93d85dbf7d4148e3f018eb79e88554be9f75", "price_changes": [{"asset_id": "87854174148074652060467921081181402357467303721471806610111179101805869578687", "price": "0.795", "size": "3431.98", "side": "BUY", "hash": "1f1f4a244ae9b39a0bf292f50a977bca624fd9d7", "best_bid": "0.805", "best_ask": "0.806"}, {"asset_id": "54533043819946592547517511176940999955633860128497669742211153063842200957669", "price": "0.205", "size": "3431.98", "side": "SELL", "hash": "319f083bb9797fa1c8b6597fa232520bfeebf24b", "best_bid": "0.194", "best_ask": "0.195"}], "timestamp": "1785164068991", "event_type": "price_change"}}
{"ts": 1785164069.3, "kind": "price_change", "data": {"market": "0x18b1c135d0a40c5894da9412e77311827d9caf16cf4cd6591b247a34730af919", "price_changes": [{"asset_id": "40081275558852222228080198821361202017557872256707631666334039001378518619916", "price": "0.505", "size": "36.7", "side": "SELL", "hash": "404f6b03a3923f7a6c6c54d438b6d281ddda1e3e", "best_bid": "0.428", "best_ask": "0.429"}, {"asset_id": "78633590736077251574794513664747155551297291244492840448622550955320930591622", "price": "0.495", "size": "36.7", "side": "BUY", "hash": "9762b97de59b440de184b325bc416420a97ad13b", "best_bid": "0.571", "best_ask": "0.572"}], "timestamp": "1785164069300", "event_type": "price_change"}}
{"ts": 1785164069.587, "kind": "price_change", "data": {"market": "0x18b1c135d0a40c5894da9412e77311827d9caf16cf4cd6591b247a34730af919", "price_changes": [{"asset_id": "40081275558852222228080198821361202017557872256707631666334039001378518619916", "price": "0.418", "size": "6012.45", "side": "BUY", "hash": "83a8c57c346510688a94f85b42c7f83b2e5d3b90", "best_bid": "0.428", "best_ask": "0.429"}, {"asset_id": "78633590736077251574794513664747155551297291244492840448622550955320930591622", "price": "0.582", "size": "6012.45", "side": "SELL", "hash": "c77ec9483c72c6683e009989308e786c3ff3deaa", "best_bid": "0.571", "best_ask": "0.572"}], "timestamp": "1785164069587", "event_type": "price_change"}}
{"ts": 1785164069.676, "kind": "price_change", "data": {"market": "0x18b1c135d0a40c5894da9412e77311827d9caf16cf4cd6591b247a34730af919", "price_changes": [{"asset_id": "40081275558852222228080198821361202017557872256707631666334039001378518619916", "price": "0.418", "size": "7088.45", "side": "BUY", "hash": "6859eac5439fad099a71c75505660b14a9fdb58e", "best_bid": "0.428", "best_ask": "0.429"}, {"asset_id": "78633590736077251574794513664747155551297291244492840448622550955320930591622", "price": "0.582", "size": "7088.45", "side": "SELL", "hash": "7c71a030a3ff8accc389604015beb1abe1ddcce7", "best_bid": "0.571", "best_ask": "0.572"}], "timestamp": "1785164069676", "event_type": "price_change"}}
{"ts": 1785164069.683, "kind": "price_change", "data": {"market": "0x18b1c135d0a40c5894da9412e77311827d9caf16cf4cd6591b247a34730af919", "price_changes": [{"asset_id": "40081275558852222228080198821361202017557872256707631666334039001378518619916", "price": "0.418", "size": "7019.25", "side": "BUY", "hash": "0aece89d4c4b3a3cbfd861bfb92a8bff5848b372", "best_bid": "0.428", "best_ask": "0.429"}, {"asset_id": "78633590736077251574794513664747155551297291244492840448622550955320930591622", "price": "0.582", "size": "7019.25", "side": "SELL", "hash": "f5463d1a7855671407902fef71a61944cb902473", "best_bid": "0.571", "best_ask": "0.572"}], "timestamp": "1785164069683", "event_type": "price_change"}}
{"ts": 1785164069.757, "kind": "price_change", "data": {"market": "0x18b1c135d0a40c5894da9412e77311827d9caf16cf4cd6591b247a34730af919", "price_changes": [{"asset_id": "40081275558852222228080198821361202017557872256707631666334039001378518619916", "price": "0.505", "size": "0", "side": "SELL", "hash": "0245bbc60ac6482efc22bb4d7aeaf5d17f3f5a7e", "best_bid": "0.428", "best_ask": "0.429"}, {"asset_id": "78633590736077251574794513664747155551297291244492840448622550955320930591622", "price": "0.495", "size": "0", "side": "BUY", "hash": "8448ecf0412c94ca431796bb011327ceab418b08", "best_bid": "0.571", "best_ask": "0.572"}], "timestamp": "1785164069757", "event_type": "price_change"}}
{"ts": 1785164069.989, "kind": "price_change", "data": {"market": "0x18b1c135d0a40c5894da9412e77311827d9caf16cf4cd6591b247a34730af919", "price_changes": [{"asset_id": "40081275558852222228080198821361202017557872256707631666334039001378518619916", "price": "0.506", "size": "36.7", "side": "SELL", "hash": "b70a27e6fae45269fe3f84ad9526e2fffa094cd7", "best_bid": "0.428", "best_ask": "0.429"}, {"asset_id": "78633590736077251574794513664747155551297291244492840448622550955320930591622", "price": "0.494", "size": "36.7", "side": "BUY", "hash": "38b75d833bf9e86dc57ce72d7222d7347c723740", "best_bid": "0.571", "best_ask": "0.572"}], "timestamp": "1785164069989", "event_type": "price_change"}}
{"ts": 1785164070.658, "kind": "price_change", "data": {"market": "0x18b1c135d0a40c5894da9412e77311827d9caf16cf4cd6591b247a34730af919", "price_changes": [{"asset_id": "78633590736077251574794513664747155551297291244492840448622550955320930591622", "price": "0.482", "size": "201.09", "side": "BUY", "hash": "cf569b8a88db3a5f0ec4a6d6d3d5b535c8e9609e", "best_bid": "0.571", "best_ask": "0.572"}, {"asset_id": "40081275558852222228080198821361202017557872256707631666334039001378518619916", "price": "0.518", "size": "201.09", "side": "SELL", "hash": "d9c273a04616dca9961ea7f8e126493a35ea7587", "best_bid": "0.428", "best_ask": "0.429"}], "timestamp": "1785164070658", "event_type": "price_change"}}
{"ts": 1785164070.675, "kind": "price_change", "data": {"market": "0x18b1c135d0a40c5894da9412e77311827d9caf16cf4cd6591b247a34730af919", "price_changes": [{"asset_id": "78633590736077251574794513664747155551297291244492840448622550955320930591622", "price": "0.485", "size": "77", "side": "BUY", "hash": "13adb754b22ad7660379712b7712c600cf429693", "best_bid": "0.571", "best_ask": "0.572"}, {"asset_id": "40081275558852222228080198821361202017557872256707631666334039001378518619916", "price": "0.515", "size": "77", "side": "SELL", "hash": "186e6d87c6cb0a62f11fae5e139837b87df1f36f", "best_bid": "0.428", "best_ask": "0.429"}], "timestamp": "1785164070675", "event_type": "price_change"}}
{"ts": 1785164071.0, "kind": "price_change", "data": {"market": "0x0f49db97f71c68b1e42a6d16e3de93d85dbf7d4148e3f018eb79e88554be9f75", "price_changes": [{"asset_id": "54533043819946592547517511176940999955633860128497669742211153063842200957669", "price": "0.003", "size": "11073", "side": "BUY", "hash": "fad46496b8d4bf2a3fbc2fd46aa75db88ffdd35d", "best_bid": "0.194", "best_ask": "0.195"}, {"asset_id": "87854174148074652060467921081181402357467303721471806610111179101805869578687", "price": "0.997", "size": "11073", "side": "SELL", "hash": "a6f4e6630738ee548c27accab16bda92bb8dfa56", "best_bid": "0.805", "best_ask": "0.806"}], "timestamp": "1785164071000", "event_type": "price_change"}}
{"ts": 1785164073.0, "kind": "price_change", "data": {"market": "0x0f49db97f71c68b1e42a6d16e3de93d85dbf7d4148e3f018eb79e88554be9f75", "price_changes": [{"asset_id": "87854174148074652060467921081181402357467303721471806610111179101805869578687", "price": "0.64", "size": "0", "side": "BUY", "hash": "7c997f5c44bbd426e260406bf0f6313a961d6fa6", "best_bid": "0.805", "best_ask": "0.806"}, {"asset_id": "54533043819946592547517511176940999955633860128497669742211153063842200957669", "price": "0.36", "size": "0", "side": "SELL", "hash": "7a4767fbec6e9613c464608bae60b75b7d3249b8", "best_bid": "0.194", "best_ask": "0.195"}], "timestamp": "1785164073000", "event_type": "price_change"}}
{"ts": 1785164073.705, "kind": "price_change", "data": {"market": "0x18b1c135d0a40c5894da9412e77311827d9caf16cf4cd6591b247a34730af919", "price_changes": [{"asset_id": "40081275558852222228080198821361202017557872256707631666334039001378518619916", "price": "0.412", "size": "11211.7", "side": "BUY", "hash": "617abe6ff84aca4c355269d37f9190d30dd91908", "best_bid": "0.428", "best_ask": "0.429"}, {"asset_id": "78633590736077251574794513664747155551297291244492840448622550955320930591622", "price": "0.588", "size": "11211.7", "side": "SELL", "hash": "c050159391898ec02103c3d871aaf691cb20ed09", "best_bid": "0.571", "best_ask": "0.572"}], "timestamp": "1785164073705", "event_type": "price_change"}}
{"ts": 1785164074.001, "kind": "price_change", "data": {"market": "0x18b1c135d0a40c5894da9412e77311827d9caf16cf4cd6591b247a34730af919", "price_changes": [{"asset_id": "40081275558852222228080198821361202017557872256707631666334039001378518619916", "price": "0.23", "size": "0", "side": "BUY", "hash": "3ee620019b45dfa874b72d2b45cbddd6f7a01398", "best_bid": "0.428", "best_ask": "0.429"}, {"asset_id": "78633590736077251574794513664747155551297291244492840448622550955320930591622", "price": "0.77", "size": "0", "side": "SELL", "hash": "0c5a3cb9fa6c508fd0bfae08d6aa6612f5745dd6", "best_bid": "0.571", "best_ask": "0.572"}], "timestamp": "1785164074001", "event_type": "price_change"}}
{"ts": 1785164076.002, "kind": "price_change", "data": {"market": "0x18b1c135d0a40c5894da9412e77311827d9caf16cf4cd6591b247a34730af919", "price_changes": [{"asset_id": "40081275558852222228080198821361202017557872256707631666334039001378518619916", "price": "0.411", "size": "36907.4", "side": "BUY", "hash": "26148db700e90e7c5aedfef4df33a8ab1ebf87d9", "best_bid": "0.428", "best_ask": "0.429"}, {"asset_id": "78633590736077251574794513664747155551297291244492840448622550955320930591622", "price": "0.589", "size": "36907.4", "side": "SELL", "hash": "fe8051ed65637670a0509ba8ceecd19c139c155c", "best_bid": "0.571", "best_ask": "0.572"}], "timestamp": "1785164076002", "event_type": "price_change"}}
{"ts": 1785164076.04, "kind": "price_change", "data": {"market": "0x18b1c135d0a40c5894da9412e77311827d9caf16cf4cd6591b247a34730af919", "price_changes": [{"asset_id": "40081275558852222228080198821361202017557872256707631666334039001378518619916", "price": "0.411", "size": "37107.4", "side": "BUY", "hash": "ac9edb40d5ae8098599c20436af2ce1d3bc9e634", "best_bid": "0.428", "best_ask": "0.429"}, {"asset_id": "78633590736077251574794513664747155551297291244492840448622550955320930591622", "price": "0.589", "size": "37107.4", "side": "SELL", "hash": "bb16af859b85e7e51d1a06a0264c5efadbc71916", "best_bid": "0.571", "best_ask": "0.572"}], "timestamp": "1785164076040", "event_type": "price_change"}}
{"ts": 1785164077.384, "kind": "price_change", "data": {"market": "0x0f49db97f71c68b1e42a6d16e3de93d85dbf7d4148e3f018eb79e88554be9f75", "price_changes": [{"asset_id": "87854174148074652060467921081181402357467303721471806610111179101805869578687", "price": "0.001", "size": "6146756.01", "side": "BUY", "hash": "6a26d05efe2d03d44bbdddbdd0485c0134cc45b5", "best_bid": "0.805", "best_ask": "0.806"}, {"asset_id": "54533043819946592547517511176940999955633860128497669742211153063842200957669", "price": "0.999", "size": "6146756.01", "side": "SELL", "hash": "b66ce763c966b3e78bccdb3d57b71d9671569b75", "best_bid": "0.194", "best_ask": "0.195"}], "timestamp": "1785164077384", "event_type": "price_change"}}
{"ts": 1785164077.385, "kind": "price_change", "data": {"market": "0x0f49db97f71c68b1e42a6d16e3de93d85dbf7d4148e3f018eb79e88554be9f75", "price_changes": [{"asset_id": "87854174148074652060467921081181402357467303721471806610111179101805869578687", "price": "0.001", "size": "6147766.01", "side": "BUY", "hash": "ea78bac64daeaedfe01d2de9ce72321e5212a60e", "best_bid": "0.805", "best_ask": "0.806"}, {"asset_id": "54533043819946592547517511176940999955633860128497669742211153063842200957669", "price": "0.999", "size": "6147766.01", "side": "SELL", "hash": "46d8861f361b91a6a20d86bd94fa47fee62ed58a", "best_bid": "0.194", "best_ask": "0.195"}], "timestamp": "1785164077385", "event_type": "price_change"}}
{"ts": 1785164077.538, "kind": "price_change", "data": {"market": "0x18b1c135d0a40c5894da9412e77311827d9caf16cf4cd6591b247a34730af919", "price_changes": [{"asset_id": "40081275558852222228080198821361202017557872256707631666334039001378518619916", "price": "0.411", "size": "36742", "side": "BUY", "hash": "c2c23dadab8d414beea19ab61b98ec1ce69c220d", "best_bid": "0.428", "best_ask": "0.429"}, {"asset_id": "78633590736077251574794513664747155551297291244492840448622550955320930591622", "price": "0.589", "size": "36742", "side": "SELL", "hash": "dce5a66991825e0b16858935b06432f881852c31", "best_bid": "0.571", "best_ask": "0.572"}], "timestamp": "1785164077538", "event_type": "price_change"}}
{"ts": 1785164079.776, "kind": "price_change", "data": {"market": "0x0f49db97f71c68b1e42a6d16e3de93d85dbf7d4148e3f018eb79e88554be9f75", "price_changes": [{"asset_id": "54533043819946592547517511176940999955633860128497669742211153063842200957669", "price": "0.003", "size": "14406.33", "side": "BUY", "hash": "1e04d585b2dffd2e1005667628e31b220411ecde", "best_bid": "0.194", "best_ask": "0.195"}, {"asset_id": "87854174148074652060467921081181402357467303721471806610111179101805869578687", "price": "0.997", "size": "14406.33", "side": "SELL", "hash": "178be58383de89563c870c660fc6d35faadbcc2a", "best_bid": "0.805", "best_ask": "0.806"}], "timestamp": "1785164079776", "event_type": "price_change"}}
{"ts": 1785164079.877, "kind": "price_change", "data": {"market": "0x18b1c135d0a40c5894da9412e77311827d9caf16cf4cd6591b247a34730af919", "price_changes": [{"asset_id": "40081275558852222228080198821361202017557872256707631666334039001378518619916", "price": "0.506", "size": "0", "side": "SELL", "hash": "a2be34120c26477b1362fe40f2669baf0895e92f", "best_bid": "0.428", "best_ask": "0.429"}, {"asset_id": "78633590736077251574794513664747155551297291244492840448622550955320930591622", "price": "0.494", "size": "0", "side": "BUY", "hash": "54a2ba30778cd1d223122292f5102b9cbc9ce295", "best_bid": "0.571", "best_ask": "0.572"}], "timestamp": "1785164079877", "event_type": "price_change"}}
{"ts": 1785164080.032, "kind": "price_change", "data": {"market": "0x18b1c135d0a40c5894da9412e77311827d9caf16cf4cd6591b247a34730af919", "price_changes": [{"asset_id": "40081275558852222228080198821361202017557872256707631666334039001378518619916", "price": "0.399", "size": "10117", "side": "BUY", "hash": "e1839272bdee74c647a62bc0b395c550a098893f", "best_bid": "0.428", "best_ask": "0.429"}, {"asset_id": "78633590736077251574794513664747155551297291244492840448622550955320930591622", "price": "0.601", "size": "10117", "side": "SELL", "hash": "e91ab7575450868565f31e37b3e05022178b12f9", "best_bid": "0.571", "best_ask": "0.572"}], "timestamp": "1785164080032", "event_type": "price_change"}}
{"ts": 1785164080.537, "kind": "price_change", "data": {"market": "0x18b1c135d0a40c5894da9412e77311827d9caf16cf4cd6591b247a34730af919", "price_changes": [{"asset_id": "40081275558852222228080198821361202017557872256707631666334039001378518619916", "price": "0.41", "size": "2931.23", "side": "BUY", "hash": "83e139b857353a64acb35079993363eff9e068f9", "best_bid": "0.428", "best_ask": "0.429"}, {"asset_id": "78633590736077251574794513664747155551297291244492840448622550955320930591622", "price": "0.59", "size": "2931.23", "side": "SELL", "hash": "e017ba15159b7652e07eeea4cc9eb68cda55a63c", "best_bid": "0.571", "best_ask": "0.572"}], "timestamp": "1785164080537", "event_type": "price_change"}}
{"ts": 1785164080.864, "kind": "price_change", "data": {"market": "0x18b1c135d0a40c5894da9412e77311827d9caf16cf4cd6591b247a34730af919", "price_changes": [{"asset_id": "40081275558852222228080198821361202017557872256707631666334039001378518619916", "price": "0.505", "size": "36.7", "side": "SELL", "hash": "602b03214aefa1145caa8f89fa4c85c740a35088", "best_bid": "0.428", "best_ask": "0.429"}, {"asset_id": "78633590736077251574794513664747155551297291244492840448622550955320930591622", "price": "0.495", "size": "36.7", "side": "BUY", "hash": "4f907260ff02f6c83445625f1da7323b5a3344f1", "best_bid": "0.571", "best_ask": "0.572"}], "timestamp": "1785164080864", "event_type": "price_change"}}
{"ts": 1785164080.94, "kind": "price_change", "data": {"market": "0x18b1c135d0a40c5894da9412e77311827d9caf16cf4cd6591b247a34730af919", "price_changes": [{"asset_id": "40081275558852222228080198821361202017557872256707631666334039001378518619916", "price": "0.41", "size": "2947.28", "side": "BUY", "hash": "e191f0356763a280cd5477064344f2f2ad9d2465", "best_bid": "0.428", "best_ask": "0.429"}, {"asset_id": "78633590736077251574794513664747155551297291244492840448622550955320930591622", "price": "0.59", "size": "2947.28", "side": "SELL", "hash": "96fe510419b9eaf8fd4c231418e33323037e9b34", "best_bid": "0.571", "best_ask": "0.572"}], "timestamp": "1785164080940", "event_type": "price_change"}}
{"ts": 1785164081.007, "kind": "price_change", "data": {"market": "0x0f49db97f71c68b1e42a6d16e3de93d85dbf7d4148e3f018eb79e88554be9f75", "price_changes": [{"asset_id": "87854174148074652060467921081181402357467303721471806610111179101805869578687", "price": "0.02", "size": "233000", "side": "BUY", "hash": "9600c240f64277b745e57b5a1d58c389a235504f", "best_bid": "0.805", "best_ask": "0.806"}, {"asset_id": "54533043819946592547517511176940999955633860128497669742211153063842200957669", "price": "0.98", "size": "233000", "side": "SELL", "hash": "b8b995396b8461c5b277a83f274279547835fa66", "best_bid": "0.194", "best_ask": "0.195"}], "timestamp": "1785164081007", "event_type": "price_change"}}
{"ts": 1785164081.301, "kind": "price_change", "data": {"market": "0x18b1c135d0a40c5894da9412e77311827d9caf16cf4cd6591b247a34730af919", "price_changes": [{"asset_id": "78633590736077251574794513664747155551297291244492840448622550955320930591622", "price": "0.08", "size": "20000", "side": "BUY", "hash": "0d705bc43ee528b198229cff07948bb2396d0df4", "best_bid": "0.571", "best_ask": "0.572"}, {"asset_id": "40081275558852222228080198821361202017557872256707631666334039001378518619916", "price": "0.92", "size": "20000", "side": "SELL", "hash": "3cbf8faffb15f7f7461ca6998200bc5119870f82", "best_bid": "0.428", "best_ask": "0.429"}], "timestamp": "1785164081301", "event_type": "price_change"}}
{"ts": 1785164084.535, "kind": "price_change", "data": {"market": "0x18b1c135d0a40c5894da9412e77311827d9caf16cf4cd6591b247a34730af919", "price_changes": [{"asset_id": "40081275558852222228080198821361202017557872256707631666334039001378518619916", "price": "0.398", "size": "14448", "side": "BUY", "hash": "ffb8935062a05ba1923f32f303eff7a6838a37b4", "best_bid": "0.428", "best_ask": "0.429"}, {"asset_id": "78633590736077251574794513664747155551297291244492840448622550955320930591622", "price": "0.602", "size": "14448", "side": "SELL", "hash": "fbc20c5dab70f161b7d30ac6e131aa2feb8f30bc", "best_bid": "0.571", "best_ask": "0.572"}], "timestamp": "1785164084535", "event_type": "price_change"}}
{"ts": 1785164085.73, "kind": "price_change", "data": {"market": "0x18b1c135d0a40c5894da9412e77311827d9caf16cf4cd6591b247a34730af919", "price_changes": [{"asset_id": "40081275558852222228080198821361202017557872256707631666334039001378518619916", "price": "0.505", "size": "0", "side": "SELL", "hash": "4650f54dce2483f28ce38244e278d007d4d08ea8", "best_bid": "0.428", "best_ask": "0.429"}, {"asset_id": "78633590736077251574794513664747155551297291244492840448622550955320930591622", "price": "0.495", "size": "0", "side": "BUY", "hash": "7c7f4db50acc82d32f4f729d7870a8d7f5d773d1", "best_bid": "0.571", "best_ask": "0.572"}], "timestamp": "1785164085730", "event_type": "price_change"}}
{"ts": 1785164086.62, "kind": "price_change", "data": {"market": "0x18b1c135d0a40c5894da9412e77311827d9caf16cf4cd6591b247a34730af919", "price_changes": [{"asset_id": "40081275558852222228080198821361202017557872256707631666334039001378518619916", "price": "0.505", "size": "36.7", "side": "SELL", "hash": "84e5c109258d4b947301cccced7a938e413b3736", "best_bid": "0.428", "best_ask": "0.429"}, {"asset_id": "78633590736077251574794513664747155551297291244492840448622550955320930591622", "price": "0.495", "size": "36.7", "side": "BUY", "hash": "308bd9a9f7a74b0d8a4a0def166bd33a78d5049f", "best_bid": "0.571", "best_ask": "0.572"}], "timestamp": "1785164086620", "event_type": "price_change"}}
{"ts": 1785164088.1, "kind": "price_change", "data": {"market": "0x18b1c135d0a40c5894da9412e77311827d9caf16cf4cd6591b247a34730af919", "price_changes": [{"asset_id": "40081275558852222228080198821361202017557872256707631666334039001378518619916", "price": "0.418", "size": "7431.25", "side": "BUY", "hash": "995641e95e62e2fa8e0b1211437bb5196aa698d8", "best_bid": "0.428", "best_ask": "0.429"}, {"asset_id": "78633590736077251574794513664747155551297291244492840448622550955320930591622", "price": "0.582", "size": "7431.25", "side": "SELL", "hash": "9f0c1b19103de43adae5f3615bc02b8ae8d8e436", "best_bid": "0.571", "best_ask": "0.572"}], "timestamp": "1785164088100", "event_type": "price_change"}}
{"ts": 1785164088.173, "kind": "price_change", "data": {"market": "0x18b1c135d0a40c5894da9412e77311827d9caf16cf4cd6591b247a34730af919", "price_changes": [{"asset_id": "40081275558852222228080198821361202017557872256707631666334039001378518619916", "price": "0.397", "size": "50202", "side": "BUY", "hash": "cc51a2b5ba46aea88edb61c44b6b51965698ec36", "best_bid": "0.428", "best_ask": "0.429"}, {"asset_id": "78633590736077251574794513664747155551297291244492840448622550955320930591622", "price": "0.603", "size": "50202", "side": "SELL", "hash": "e9d0d20391bec38154744233c401e4837423d9cf", "best_bid": "0.571", "best_ask": "0.572"}], "timestamp": "1785164088173", "event_type": "price_change"}}
{"ts": 1785164088.794, "kind": "price_change", "data": {"market": "0x18b1c135d0a40c5894da9412e77311827d9caf16cf4cd6591b247a34730af919", "price_changes": [{"asset_id": "40081275558852222228080198821361202017557872256707631666334039001378518619916", "price": "0.505", "size": "0", "side": "SELL", "hash": "c14d6624e401418c0af8e1553b63d610178236c0", "best_bid": "0.428", "best_ask": "0.429"}, {"asset_id": "78633590736077251574794513664747155551297291244492840448622550955320930591622", "price": "0.495", "size": "0", "side": "BUY", "hash": "2e17f10bc79906cf14453785597f34b631b94982", "best_bid": "0.571", "best_ask": "0.572"}], "timestamp": "1785164088794", "event_type": "price_change"}}
{"ts": 1785164089.108, "kind": "price_change", "data": {"market": "0x18b1c135d0a40c5894da9412e77311827d9caf16cf4cd6591b247a34730af919", "price_changes": [{"asset_id": "40081275558852222228080198821361202017557872256707631666334039001378518619916", "price": "0.506", "size": "36.7", "side": "SELL", "hash": "16e4ac01d731fd40fba35e02459bbb2dd72883c1", "best_bid": "0.428", "best_ask": "0.429"}, {"asset_id": "78633590736077251574794513664747155551297291244492840448622550955320930591622", "price": "0.494", "size": "36.7", "side": "BUY", "hash": "3c80a071d9cedbdd0b001b0c8bd75104d35a5eaf", "best_bid": "0.571", "best_ask": "0.572"}], "timestamp": "1785164089108", "event_type": "price_change"}}
{"ts": 1785164089.844, "kind": "price_change", "data": {"market": "0x0f49db97f71c68b1e42a6d16e3de93d85dbf7d4148e3f018eb79e88554be9f75", "price_changes": [{"asset_id": "54533043819946592547517511176940999955633860128497669742211153063842200957669", "price": "0.187", "size": "36.49", "side": "BUY", "hash": "ecfc38731e2f6f5e0ca6cf7181445cacb42f2d19", "best_bid": "0.194", "best_ask": "0.195"}, {"asset_id": "87854174148074652060467921081181402357467303721471806610111179101805869578687", "price": "0.813", "size": "36.49", "side": "SELL", "hash": "c05c83421cc5c4f37c6ea3510fb132495f5509d0", "best_bid": "0.805", "best_ask": "0.806"}], "timestamp": "1785164089844", "event_type": "price_change"}}
{"ts": 1785164089.844, "kind": "price_change", "data": {"market": "0x0f49db97f71c68b1e42a6d16e3de93d85dbf7d4148e3f018eb79e88554be9f75", "price_changes": [{"asset_id": "54533043819946592547517511176940999955633860128497669742211153063842200957669", "price": "0.184", "size": "862", "side": "BUY", "hash": "ecfc38731e2f6f5e0ca6cf7181445cacb42f2d19", "best_bid": "0.194", "best_ask": "0.195"}, {"asset_id": "87854174148074652060467921081181402357467303721471806610111179101805869578687", "price": "0.816", "size": "862", "side": "SELL", "hash": "c05c83421cc5c4f37c6ea3510fb132495f5509d0", "best_bid": "0.805", "best_ask": "0.806"}], "timestamp": "1785164089844", "event_type": "price_change"}}
{"ts": 1785164089.844, "kind": "price_change", "data": {"market": "0x0f49db97f71c68b1e42a6d16e3de93d85dbf7d4148e3f018eb79e88554be9f75", "price_changes": [{"asset_id": "87854174148074652060467921081181402357467303721471806610111179101805869578687", "price": "0.798", "size": "2046.41", "side": "BUY", "hash": "c05c83421cc5c4f37c6ea3510fb132495f5509d0", "best_bid": "0.805", "best_ask": "0.806"}, {"asset_id": "54533043819946592547517511176940999955633860128497669742211153063842200957669", "price": "0.202", "size": "2046.41", "side": "SELL", "hash": "ecfc38731e2f6f5e0ca6cf7181445cacb42f2d19", "best_bid": "0.194", "best_ask": "0.195"}], "timestamp": "1785164089844", "event_type": "price_change"}}
{"ts": 1785164089.844, "kind": "price_change", "data": {"market": "0x0f49db97f71c68b1e42a6d16e3de93d85dbf7d4148e3f018eb79e88554be9f75", "price_changes": [{"asset_id": "87854174148074652060467921081181402357467303721471806610111179101805869578687", "price": "0.795", "size": "3211.98", "side": "BUY", "hash": "c05c83421cc5c4f37c6ea3510fb132495f5509d0", "best_bid": "0.805", "best_ask": "0.806"}, {"asset_id": "54533043819946592547517511176940999955633860128497669742211153063842200957669", "price": "0.205", "size": "3211.98", "side": "SELL", "hash": "ecfc38731e2f6f5e0ca6cf7181445cacb42f2d19", "best_bid": "0.194", "best_ask": "0.195"}], "timestamp": "1785164089844", "event_type": "price_change"}}
{"ts": 1785164090.02, "kind": "price_change", "data": {"market": "0x0f49db97f71c68b1e42a6d16e3de93d85dbf7d4148e3f018eb79e88554be9f75", "price_changes": [{"asset_id": "54533043819946592547517511176940999955633860128497669742211153063842200957669", "price": "0.187", "size": "256.49", "side": "BUY", "hash": "3ad83f8143ef703269123742dd76b608a933f393", "best_bid": "0.194", "best_ask": "0.195"}, {"asset_id": "87854174148074652060467921081181402357467303721471806610111179101805869578687", "price": "0.813", "size": "256.49", "side": "SELL", "hash": "2df5efc60bf016b49c059174ed26498b8a08c6d9", "best_bid": "0.805", "best_ask": "0.806"}], "timestamp": "1785164090020", "event_type": "price_change"}}
{"ts": 1785164090.021, "kind": "price_change", "data": {"market": "0x0f49db97f71c68b1e42a6d16e3de93d85dbf7d4148e3f018eb79e88554be9f75", "price_changes": [{"asset_id": "87854174148074652060467921081181402357467303721471806610111179101805869578687", "price": "0.795", "size": "3431.98", "side": "BUY", "hash": "fa824f3916539dd56b81ff5b3e8eaae0dfc38147", "best_bid": "0.805", "best_ask": "0.806"}, {"asset_id": "54533043819946592547517511176940999955633860128497669742211153063842200957669", "price": "0.205", "size": "3431.98", "side": "SELL", "hash": "1a9fba926663254c96e113c0796554540f7c726a", "best_bid": "0.194", "best_ask": "0.195"}], "timestamp": "1785164090021", "event_type": "price_change"}}
{"ts": 1785164090.032, "kind": "price_change", "data": {"market": "0x0f49db97f71c68b1e42a6d16e3de93d85dbf7d4148e3f018eb79e88554be9f75", "price_changes": [{"asset_id": "87854174148074652060467921081181402357467303721471806610111179101805869578687", "price": "0.798", "size": "2266.41", "side": "BUY", "hash": "1c7cc594f4e5a158375869e81989082ef35a4109", "best_bid": "0.805", "best_ask": "0.806"}, {"asset_id": "54533043819946592547517511176940999955633860128497669742211153063842200957669", "price": "0.202", "size": "2266.41", "side": "SELL", "hash": "befda2d9db695c81a08dc9d78d1f3d9ef43ff5f4", "best_bid": "0.194", "best_ask": "0.195"}], "timestamp": "1785164090032", "event_type": "price_change"}}
{"ts": 1785164090.033, "kind": "price_change", "data": {"market": "0x0f49db97f71c68b1e42a6d16e3de93d85dbf7d4148e3f018eb79e88554be9f75", "price_changes": [{"asset_id": "54533043819946592547517511176940999955633860128497669742211153063842200957669", "price": "0.184", "size": "1082", "side": "BUY", "hash": "37d9066b3374c1f9eea1cc874600c4bd4f4a1d44", "best_bid": "0.194", "best_ask": "0.195"}, {"asset_id": "87854174148074652060467921081181402357467303721471806610111179101805869578687", "price": "0.816", "size": "1082", "side": "SELL", "hash": "6803e2d6d01bf1f2d6d34512e2cc65bc3b666600", "best_bid": "0.805", "best_ask": "0.806"}], "timestamp": "1785164090033", "event_type": "price_change"}}
{"ts": 1785164090.153441, "kind": "orders_out", "data": [{"token_id": "54533043819946592547517511176940999955633860128497669742211153063842200957669", "side": "BUY", "price": 0.153, "size": 19.61}]}
{"ts": 1785164091.106, "kind": "price_change", "data": {"market": "0x18b1c135d0a40c5894da9412e77311827d9caf16cf4cd6591b247a34730af919", "price_changes": [{"asset_id": "78633590736077251574794513664747155551297291244492840448622550955320930591622", "price": "0.561", "size": "12151", "side": "BUY", "hash": "ceef1754fc94e0502942664bef5fe058da6cc7c9", "best_bid": "0.571", "best_ask": "0.572"}, {"asset_id": "40081275558852222228080198821361202017557872256707631666334039001378518619916", "price": "0.439", "size": "12151", "side": "SELL", "hash": "2c3a93334177a6479ef78cb8f0d2b6dabdf58aad", "best_bid": "0.428", "best_ask": "0.429"}], "timestamp": "1785164091106", "event_type": "price_change"}}
{"ts": 1785164091.516, "kind": "price_change", "data": {"market": "0x0f49db97f71c68b1e42a6d16e3de93d85dbf7d4148e3f018eb79e88554be9f75", "price_changes": [{"asset_id": "87854174148074652060467921081181402357467303721471806610111179101805869578687", "price": "0.78", "size": "923", "side": "BUY", "hash": "bb27056d0a4276cbea0caf5e7cc633c496a235db", "best_bid": "0.805", "best_ask": "0.806"}, {"asset_id": "54533043819946592547517511176940999955633860128497669742211153063842200957669", "price": "0.22", "size": "923", "side": "SELL", "hash": "f13eee751f0fec8a8dd6aa1e5b266bf0578bb547", "best_bid": "0.194", "best_ask": "0.195"}], "timestamp": "1785164091516", "event_type": "price_change"}}
{"ts": 1785164092.499, "kind": "price_change", "data": {"market": "0x18b1c135d0a40c5894da9412e77311827d9caf16cf4cd6591b247a34730af919", "price_changes": [{"asset_id": "78633590736077251574794513664747155551297291244492840448622550955320930591622", "price": "0.561", "size": "12458", "side": "BUY", "hash": "7c59de244cea81f279384aa4d4f3a62fa9a321cc", "best_bid": "0.571", "best_ask": "0.572"}, {"asset_id": "40081275558852222228080198821361202017557872256707631666334039001378518619916", "price": "0.439", "size": "12458", "side": "SELL", "hash": "1f1242aa0d30acfbb1fc243c30cca84f55fb6fc0", "best_bid": "0.428", "best_ask": "0.429"}], "timestamp": "1785164092499", "event_type": "price_change"}}
{"ts": 1785164093.0, "kind": "price_change", "data": {"market": "0x0f49db97f71c68b1e42a6d16e3de93d85dbf7d4148e3f018eb79e88554be9f75", "price_changes": [{"asset_id": "54533043819946592547517511176940999955633860128497669742211153063842200957669", "price": "0.184", "size": "520", "side": "BUY", "hash": "9eefcd036cc838493e7ba861712859f1b17928f9", "best_bid": "0.194", "best_ask": "0.195"}, {"asset_id": "87854174148074652060467921081181402357467303721471806610111179101805869578687", "price": "0.816", "size": "520", "side": "SELL", "hash": "88b4262f3338837ca18d19d220daf1521dde5743", "best_bid": "0.805", "best_ask": "0.806"}], "timestamp": "1785164093000", "event_type": "price_change"}}
{"ts": 1785164094.394, "kind": "price_change", "data": {"market": "0x18b1c135d0a40c5894da9412e77311827d9caf16cf4cd6591b247a34730af919", "price_changes": [{"asset_id": "78633590736077251574794513664747155551297291244492840448622550955320930591622", "price": "0.56", "size": "5835.99", "side": "BUY", "hash": "5c207f6cf57e21117665a9fa237745da93211e94", "best_bid": "0.571", "best_ask": "0.572"}, {"asset_id": "40081275558852222228080198821361202017557872256707631666334039001378518619916", "price": "0.44", "size": "5835.99", "side": "SELL", "hash": "af9852ee89bda240c1fe555fe7c15949350e9318", "best_bid": "0.428", "best_ask": "0.429"}], "timestamp": "1785164094394", "event_type": "price_change"}}
{"ts": 1785164097.053, "kind": "price_change", "data": {"market": "0x18b1c135d0a40c5894da9412e77311827d9caf16cf4cd6591b247a34730af919", "price_changes": [{"asset_id": "40081275558852222228080198821361202017557872256707631666334039001378518619916", "price": "0.41", "size": "2931.23", "side": "BUY", "hash": "286fa7ad452916a6a39ed6eecaddca89705181a7", "best_bid": "0.428", "best_ask": "0.429"}, {"asset_id": "78633590736077251574794513664747155551297291244492840448622550955320930591622", "price": "0.59", "size": "2931.23", "side": "SELL", "hash": "d749228a9245792b4534c9b1ce4456d2a38fe586", "best_bid": "0.571", "best_ask": "0.572"}], "timestamp": "1785164097053", "event_type": "price_change"}}
{"ts": 1785164097.465, "kind": "price_change", "data": {"market": "0x18b1c135d0a40c5894da9412e77311827d9caf16cf4cd6591b247a34730af919", "price_changes": [{"asset_id": "78633590736077251574794513664747155551297291244492840448622550955320930591622", "price": "0.555", "size": "12242.19", "side": "BUY", "hash": "28759519c9217bef667daf3d0c18341d1da1b42a", "best_bid": "0.571", "best_ask": "0.572"}, {"asset_id": "40081275558852222228080198821361202017557872256707631666334039001378518619916", "price": "0.445", "size": "12242.19", "side": "SELL", "hash": "56c67c796b9cc99d11fb3ee26659b4d914649994", "best_bid": "0.428", "best_ask": "0.429"}], "timestamp": "1785164097465", "event_type": "price_change"}}
{"ts": 1785164097.998, "kind": "price_change", "data": {"market": "0x18b1c135d0a40c5894da9412e77311827d9caf16cf4cd6591b247a34730af919", "price_changes": [{"asset_id": "40081275558852222228080198821361202017557872256707631666334039001378518619916", "price": "0.41", "size": "2947.28", "side": "BUY", "hash": "afff157d908a67c9aed2e6677d592ca46cfed587", "best_bid": "0.428", "best_ask": "0.429"}, {"asset_id": "78633590736077251574794513664747155551297291244492840448622550955320930591622", "price": "0.59", "size": "2947.28", "side": "SELL", "hash": "7a951d63f08e6aab2d9563aae5b4bb1e1fd07ebb", "best_bid": "0.571", "best_ask": "0.572"}], "timestamp": "1785164097998", "event_type": "price_change"}}
{"ts": 1785164098.001, "kind": "price_change", "data": {"market": "0x0f49db97f71c68b1e42a6d16e3de93d85dbf7d4148e3f018eb79e88554be9f75", "price_changes": [{"asset_id": "54533043819946592547517511176940999955633860128497669742211153063842200957669", "price": "0.183", "size": "100", "side": "BUY", "hash": "c8792de036d6f0a726463bc860e052000338a095", "best_bid": "0.194", "best_ask": "0.195"}, {"asset_id": "87854174148074652060467921081181402357467303721471806610111179101805869578687", "price": "0.817", "size": "100", "side": "SELL", "hash": "b2df4631aa466b9a99e80eb4dff17a7b23ff8599", "best_bid": "0.805", "best_ask": "0.806"}], "timestamp": "1785164098001", "event_type": "price_change"}}
{"ts": 1785164101.259, "kind": "price_change", "data": {"market": "0x18b1c135d0a40c5894da9412e77311827d9caf16cf4cd6591b247a34730af919", "price_changes": [{"asset_id": "78633590736077251574794513664747155551297291244492840448622550955320930591622", "price": "0.551", "size": "28423.96", "side": "BUY", "hash": "908970ea08cac008bd49ddd38df002577f3d8819", "best_bid": "0.571", "best_ask": "0.572"}, {"asset_id": "40081275558852222228080198821361202017557872256707631666334039001378518619916", "price": "0.449", "size": "28423.96", "side": "SELL", "hash": "8a91a96b08f379c4c4d2717ddac052438d00b96b", "best_bid": "0.428", "best_ask": "0.429"}], "timestamp": "1785164101259", "event_type": "price_change"}}
{"ts": 1785164101.541, "kind": "price_change", "data": {"market": "0x18b1c135d0a40c5894da9412e77311827d9caf16cf4cd6591b247a34730af919", "price_changes": [{"asset_id": "40081275558852222228080198821361202017557872256707631666334039001378518619916", "price": "0.506", "size": "0", "side": "SELL", "hash": "0c0261ca245d36c195a2a9572a583b6c9f4cf18b", "best_bid": "0.428", "best_ask": "0.429"}, {"asset_id": "78633590736077251574794513664747155551297291244492840448622550955320930591622", "price": "0.494", "size": "0", "side": "BUY", "hash": "306fcfff6ad8ce1dd55acc6d1e585d73c068b885", "best_bid": "0.571", "best_ask": "0.572"}], "timestamp": "1785164101541", "event_type": "price_change"}}
{"ts": 1785164102.001, "kind": "price_change", "data": {"market": "0x18b1c135d0a40c5894da9412e77311827d9caf16cf4cd6591b247a34730af919", "price_changes": [{"asset_id": "40081275558852222228080198821361202017557872256707631666334039001378518619916", "price": "0.003", "size": "11000", "side": "BUY", "hash": "ebbffea46326732071a05cb1630b61873a4e0aba", "best_bid": "0.428", "best_ask": "0.429"}, {"asset_id": "78633590736077251574794513664747155551297291244492840448622550955320930591622", "price": "0.997", "size": "11000", "side": "SELL", "hash": "3feb064089b6d95732f02d13c8ef9a652551ec97", "best_bid": "0.571", "best_ask": "0.572"}], "timestamp": "1785164102001", "event_type": "price_change"}}
{"ts": 1785164102.854, "kind": "price_change", "data": {"market": "0x18b1c135d0a40c5894da9412e77311827d9caf16cf4cd6591b247a34730af919", "price_changes": [{"asset_id": "40081275558852222228080198821361202017557872256707631666334039001378518619916", "price": "0.505", "size": "36.7", "side": "SELL", "hash": "c261ec223d56765082ab6d14dbeb79c7862ec87a", "best_bid": "0.428", "best_ask": "0.429"}, {"asset_id": "78633590736077251574794513664747155551297291244492840448622550955320930591622", "price": "0.495", "size": "36.7", "side": "BUY", "hash": "8366828c6b98c6df0a751b944336e53d7b3831e5", "best_bid": "0.571", "best_ask": "0.572"}], "timestamp": "1785164102854", "event_type": "price_change"}}
{"ts": 1785164103.0, "kind": "price_change", "data": {"market": "0x0f49db97f71c68b1e42a6d16e3de93d85dbf7d4148e3f018eb79e88554be9f75", "price_changes": [{"asset_id": "87854174148074652060467921081181402357467303721471806610111179101805869578687", "price": "0.795", "size": "3215.98", "side": "BUY", "hash": "ae0887629594f288594b4b8541c963ac8f4cabc4", "best_bid": "0.805", "best_ask": "0.806"}, {"asset_id": "54533043819946592547517511176940999955633860128497669742211153063842200957669", "price": "0.205", "size": "3215.98", "side": "SELL", "hash": "d8cf080591cd3c3e0c68f28f4c976b1c3b9042ca", "best_bid": "0.194", "best_ask": "0.195"}], "timestamp": "1785164103000", "event_type": "price_change"}}
{"ts": 1785164103.0, "kind": "price_change", "data": {"market": "0x18b1c135d0a40c5894da9412e77311827d9caf16cf4cd6591b247a34730af919", "price_changes": [{"asset_id": "40081275558852222228080198821361202017557872256707631666334039001378518619916", "price": "0.03", "size": "118750", "side": "BUY", "hash": "2936b1997e5b445fa78ea8cb20dd993813f1160f", "best_bid": "0.428", "best_ask": "0.429"}, {"asset_id": "78633590736077251574794513664747155551297291244492840448622550955320930591622", "price": "0.97", "size": "118750", "side": "SELL", "hash": "cefc06fa961b647d465f68cf7397d89f1f4176e7", "best_bid": "0.571", "best_ask": "0.572"}], "timestamp": "1785164103000", "event_type": "price_change"}}
{"ts": 1785164103.001, "kind": "price_change", "data": {"market": "0x18b1c135d0a40c5894da9412e77311827d9caf16cf4cd6591b247a34730af919", "price_changes": [{"asset_id": "78633590736077251574794513664747155551297291244492840448622550955320930591622", "price": "0.08", "size": "5000", "side": "BUY", "hash": "c5c3621a34b1dd76d27b2482791947b7467e3b19", "best_bid": "0.571", "best_ask": "0.572"}, {"asset_id": "40081275558852222228080198821361202017557872256707631666334039001378518619916", "price": "0.92", "size": "5000", "side": "SELL", "hash": "9663f075bd3ceb72b1202465bd529848f5340017", "best_bid": "0.428", "best_ask": "0.429"}], "timestamp": "1785164103001", "event_type": "price_change"}}
{"ts": 1785164103.877, "kind": "price_change", "data": {"market": "0x18b1c135d0a40c5894da9412e77311827d9caf16cf4cd6591b247a34730af919", "price_changes": [{"asset_id": "78633590736077251574794513664747155551297291244492840448622550955320930591622", "price": "0.55", "size": "30278.38", "side": "BUY", "hash": "2ecc2b79909ac3c61bfe617f3a2a1c4f1d578db8", "best_bid": "0.571", "best_ask": "0.572"}, {"asset_id": "40081275558852222228080198821361202017557872256707631666334039001378518619916", "price": "0.45", "size": "30278.38", "side": "SELL", "hash": "9debd0e592acc01527eeb1a528451bcde67b0d15", "best_bid": "0.428", "best_ask": "0.429"}], "timestamp": "1785164103877", "event_type": "price_change"}}
{"ts": 1785164105.008, "kind": "price_change", "data": {"market": "0x18b1c135d0a40c5894da9412e77311827d9caf16cf4cd6591b247a34730af919", "price_changes": [{"asset_id": "40081275558852222228080198821361202017557872256707631666334039001378518619916", "price": "0.003", "size": "19333.33", "side": "BUY", "hash": "0acd138e1793312789bb30e279ebfdc7ea464202", "best_bid": "0.428", "best_ask": "0.429"}, {"asset_id": "78633590736077251574794513664747155551297291244492840448622550955320930591622", "price": "0.997", "size": "19333.33", "side": "SELL", "hash": "29150c07fd37db8f1369f70454da49f29491575d", "best_bid": "0.571", "best_ask": "0.572"}], "timestamp": "1785164105008", "event_type": "price_change"}}
{"ts": 1785164106.003, "kind": "price_change", "data": {"market": "0x0f49db97f71c68b1e42a6d16e3de93d85dbf7d4148e3f018eb79e88554be9f75", "price_changes": [{"asset_id": "87854174148074652060467921081181402357467303721471806610111179101805869578687", "price": "0.37", "size": "0", "side": "BUY", "hash": "dfd7c0e45d19934bf48c34d4622b34740ca6ef51", "best_bid": "0.805", "best_ask": "0.806"}, {"asset_id": "54533043819946592547517511176940999955633860128497669742211153063842200957669", "price": "0.63", "size": "0", "side": "SELL", "hash": "b8f211f85b1194f5469a71fef6f87699bdba39b8", "best_bid": "0.194", "best_ask": "0.195"}], "timestamp": "1785164106003", "event_type": "price_change"}}
