{"ts": 1785163539.553, "kind": "price_change", "data": {"market": "0x18b1c135d0a40c5894da9412e77311827d9caf16cf4cd6591b247a34730af919", "price_changes": [{"asset_id": "40081275558852222228080198821361202017557872256707631666334039001378518619916", "price": "0.505", "size": "36.7", "side": "SELL", "hash": "65bed32217a1650ee07b5e464e58f355d2e7996f", "best_bid": "0.428", "best_ask": "0.429"}, {"asset_id": "78633590736077251574794513664747155551297291244492840448622550955320930591622", "price": "0.495", "size": "36.7", "side": "BUY", "hash": "8feb4a00eb988de3759e9c2bc32a5bf15f8ff3c8", "best_bid": "0.571", "best_ask": "0.572"}], "timestamp": "1785163539553", "event_type": "price_change"}}
{"ts": 1785163539.884, "kind": "price_change", "data": {"market": "0x18b1c135d0a40c5894da9412e77311827d9caf16cf4cd6591b247a34730af919", "price_changes": [{"asset_id": "40081275558852222228080198821361202017557872256707631666334039001378518619916", "price": "0.41", "size": "2947.28", "side": "BUY", "hash": "31840ca5ec5c17a7aa7a7f9b55f604f8b5051e4a", "best_bid": "0.428", "best_ask": "0.429"}, {"asset_id": "78633590736077251574794513664747155551297291244492840448622550955320930591622", "price": "0.59", "size": "2947.28", "side": "SELL", "hash": "1814374bcaa09a3733d68d1a22de72c5a0a7a7cc", "best_bid": "0.571", "best_ask": "0.572"}], "timestamp": "1785163539884", "event_type": "price_change"}}
{"ts": 1785163540.719, "kind": "price_change", "data": {"market": "0x18b1c135d0a40c5894da9412e77311827d9caf16cf4cd6591b247a34730af919", "price_changes": [{"asset_id": "40081275558852222228080198821361202017557872256707631666334039001378518619916", "price": "0.505", "size": "0", "side": "SELL", "hash": "5b1ca256b1e9020b97d212026ab5b692761dd4f9", "best_bid": "0.428", "best_ask": "0.429"}, {"asset_id": "78633590736077251574794513664747155551297291244492840448622550955320930591622", "price": "0.495", "size": "0", "side": "BUY", "hash": "31b891e8954c382540c572c70cab960a0e14a3f3", "best_bid": "0.571", "best_ask": "0.572"}], "timestamp": "1785163540719", "event_type": "price_change"}}
{"ts": 1785163541.163, "kind": "price_change", "data": {"market": "0x18b1c135d0a40c5894da9412e77311827d9caf16cf4cd6591b247a34730af919", "price_changes": [{"asset_id": "40081275558852222228080198821361202017557872256707631666334039001378518619916", "price": "0.507", "size": "36.7", "side": "SELL", "hash": "ceced5b76afeb58b94a9032ee6231ce2afaac87e", "best_bid": "0.428", "best_ask": "0.429"}, {"asset_id": "78633590736077251574794513664747155551297291244492840448622550955320930591622", "price": "0.493", "size": "36.7", "side": "BUY", "hash": "30cde74f3e9475539f463fdd71893d8b18722071", "best_bid": "0.571", "best_ask": "0.572"}], "timestamp": "1785163541163", "event_type": "price_change"}}
{"ts": 1785163543.001, "kind": "price_change", "data": {"market": "0x18b1c135d0a40c5894da9412e77311827d9caf16cf4cd6591b247a34730af919", "price_changes": [{"asset_id": "40081275558852222228080198821361202017557872256707631666334039001378518619916", "price": "0.003", "size": "11000", "side": "BUY", "hash": "4555ad356f274bac5fa7606e88eaa354ba6e5db1", "best_bid": "0.428", "best_ask": "0.429"}, {"asset_id": "78633590736077251574794513664747155551297291244492840448622550955320930591622", "price": "0.997", "size": "11000", "side": "SELL", "hash": "0b7d88f67d172d4cdecdc867617faeddadd9d124", "best_bid": "0.571", "best_ask": "0.572"}], "timestamp": "1785163543001", "event_type": "price_change"}}
{"ts": 1785163551.617, "kind": "price_change", "data": {"market": "0x18b1c135d0a40c5894da9412e77311827d9caf16cf4cd6591b247a34730af919", "price_changes": [{"asset_id": "40081275558852222228080198821361202017557872256707631666334039001378518619916", "price": "0.003", "size": "19333.33", "side": "BUY", "hash": "3c27160cddfe1c07672aec722181faca99ab1bb1", "best_bid": "0.428", "best_ask": "0.429"}, {"asset_id": "78633590736077251574794513664747155551297291244492840448622550955320930591622", "price": "0.997", "size": "19333.33", "side": "SELL", "hash": "7f27c966a4aa1de919b3df06b77c399425c57bec", "best_bid": "0.571", "best_ask": "0.572"}], "timestamp": "1785163551617", "event_type": "price_change"}}
{"ts": 1785163551.92171, "kind": "orders_out", "data": [{"token_id": "40081275558852222228080198821361202017557872256707631666334039001378518619916", "side": "BUY", "price": 0.387, "size": 7.75}, {"token_id": "78633590736077251574794513664747155551297291244492840448622550955320930591622", "side": "BUY", "price": 0.529, "size": 5.67}]}
{"ts": 1785163559.397, "kind": "price_change", "data": {"market": "0x18b1c135d0a40c5894da9412e77311827d9caf16cf4cd6591b247a34730af919", "price_changes": [{"asset_id": "40081275558852222228080198821361202017557872256707631666334039001378518619916", "price": "0.41", "size": "2931.23", "side": "BUY", "hash": "0756058c779cb9af43e0229674becc924f127a7b", "best_bid": "0.428", "best_ask": "0.429"}, {"asset_id": "78633590736077251574794513664747155551297291244492840448622550955320930591622", "price": "0.59", "size": "2931.23", "side": "SELL", "hash": "f9e5b7072a4482a8fc608cc08268929ea57622fb", "best_bid": "0.571", "best_ask": "0.572"}], "timestamp": "1785163559397", "event_type": "price_change"}}
{"ts": 1785163559.928, "kind": "price_change", "data": {"market": "0x18b1c135d0a40c5894da9412e77311827d9caf16cf4cd6591b247a34730af919", "price_changes": [{"asset_id": "40081275558852222228080198821361202017557872256707631666334039001378518619916", "price": "0.41", "size": "2947.28", "side": "BUY", "hash": "626cbcc62d49d60deac6403ba8931b1c8910e4c0", "best_bid": "0.428", "best_ask": "0.429"}, {"asset_id": "78633590736077251574794513664747155551297291244492840448622550955320930591622", "price": "0.59", "size": "2947.28", "side": "SELL", "hash": "3076f348377ac5cf3be11dcbd0f503cdf10a5906", "best_bid": "0.571", "best_ask": "0.572"}], "timestamp": "1785163559928", "event_type": "price_change"}}
{"ts": 1785163563.987, "kind": "price_change", "data": {"market": "0x18b1c135d0a40c5894da9412e77311827d9caf16cf4cd6591b247a34730af919", "price_changes": [{"asset_id": "78633590736077251574794513664747155551297291244492840448622550955320930591622", "price": "0.482", "size": "201.09", "side": "BUY", "hash": "a283f5bdb4ca143a7638a499895a3336699f513a", "best_bid": "0.571", "best_ask": "0.572"}, {"asset_id": "40081275558852222228080198821361202017557872256707631666334039001378518619916", "price": "0.518", "size": "201.09", "side": "SELL", "hash": "79118161f291bf37e26775189a33d2b935848215", "best_bid": "0.428", "best_ask": "0.429"}], "timestamp": "1785163563987", "event_type": "price_change"}}
{"ts": 1785163563.989, "kind": "price_change", "data": {"market": "0x18b1c135d0a40c5894da9412e77311827d9caf16cf4cd6591b247a34730af919", "price_changes": [{"asset_id": "78633590736077251574794513664747155551297291244492840448622550955320930591622", "price": "0.485", "size": "77", "side": "BUY", "hash": "f102d17df62d19891e2a9679b65fda49c972c1f3", "best_bid": "0.571", "best_ask": "0.572"}, {"asset_id": "40081275558852222228080198821361202017557872256707631666334039001378518619916", "price": "0.515", "size": "77", "side": "SELL", "hash": "d8101f8899f0c293f555397ac650076e3024122e", "best_bid": "0.428", "best_ask": "0.429"}], "timestamp": "1785163563989", "event_type": "price_change"}}
{"ts": 1785163568.552, "kind": "price_change", "data": {"market": "0x18b1c135d0a40c5894da9412e77311827d9caf16cf4cd6591b247a34730af919", "price_changes": [{"asset_id": "40081275558852222228080198821361202017557872256707631666334039001378518619916", "price": "0.507", "size": "0", "side": "SELL", "hash": "6a7b82e7d57256f599be042a705221df097ca4c1", "best_bid": "0.428", "best_ask": "0.429"}, {"asset_id": "78633590736077251574794513664747155551297291244492840448622550955320930591622", "price": "0.493", "size": "0", "side": "BUY", "hash": "8bc048cb29e0524c2e552839de5174233dd8d824", "best_bid": "0.571", "best_ask": "0.572"}], "timestamp": "1785163568552", "event_type": "price_change"}}
{"ts": 1785163568.556, "kind": "price_change", "data": {"market": "0x0f49db97f71c68b1e42a6d16e3de93d85dbf7d4148e3f018eb79e88554be9f75", "price_changes": [{"asset_id": "54533043819946592547517511176940999955633860128497669742211153063842200957669", "price": "0.009", "size": "13888.88", "side": "BUY", "hash": "c1115399ed21e46ca9a4271677d3671d37ba9afd", "best_bid": "0.194", "best_ask": "0.195"}, {"asset_id": "87854174148074652060467921081181402357467303721471806610111179101805869578687", "price": "0.991", "size": "13888.88", "side": "SELL", "hash": "9422ede3be0d66b22293e539f424a4fab384c929", "best_bid": "0.805", "best_ask": "0.806"}], "timestamp": "1785163568556", "event_type": "price_change"}}
{"ts": 1785163568.562, "kind": "price_change", "data": {"market": "0x0f49db97f71c68b1e42a6d16e3de93d85dbf7d4148e3f018eb79e88554be9f75", "price_changes": [{"asset_id": "54533043819946592547517511176940999955633860128497669742211153063842200957669", "price": "0.007", "size": "53571.42", "side": "BUY", "hash": "91b418f94a57d68764898880f6e441802c6b6cc9", "best_bid": "0.194", "best_ask": "0.195"}, {"asset_id": "87854174148074652060467921081181402357467303721471806610111179101805869578687", "price": "0.993", "size": "53571.42", "side": "SELL", "hash": "bee54c4bdb100d5bfdd7610326f9bd3ba34f997d", "best_bid": "0.805", "best_ask": "0.806"}], "timestamp": "1785163568562", "event_type": "price_change"}}
{"ts": 1785163568.865921, "kind": "orders_out", "data": [{"token_id": "54533043819946592547517511176940999955633860128497669742211153063842200957669", "side": "BUY", "price": 0.144, "size": 10.42}]}
{"ts": 1785163568.818, "kind": "price_change", "data": {"market": "0x0f49db97f71c68b1e42a6d16e3de93d85dbf7d4148e3f018eb79e88554be9f75", "price_changes": [{"asset_id": "87854174148074652060467921081181402357467303721471806610111179101805869578687", "price": "0.664", "size": "0", "side": "BUY", "hash": "6f13ad0a680efdb0fe57005d1da1e2f0bc631c34", "best_bid": "0.805", "best_ask": "0.806"}, {"asset_id": "54533043819946592547517511176940999955633860128497669742211153063842200957669", "price": "0.336", "size": "0", "side": "SELL", "hash": "f0ed3abcf073e5da30d6bb5dbb0e61c6b9897978", "best_bid": "0.194", "best_ask": "0.195"}], "timestamp": "1785163568818", "event_type": "price_change"}}
{"ts": 1785163568.98, "kind": "price_change", "data": {"market": "0x0f49db97f71c68b1e42a6d16e3de93d85dbf7d4148e3f018eb79e88554be9f75", "price_changes": [{"asset_id": "87854174148074652060467921081181402357467303721471806610111179101805869578687", "price": "0.698", "size": "35", "side": "BUY", "hash": "d277a1e9bccbda79238937a7a3c2c817427d902a", "best_bid": "0.805", "best_ask": "0.806"}, {"asset_id": "54533043819946592547517511176940999955633860128497669742211153063842200957669", "price": "0.302", "size": "35", "side": "SELL", "hash": "dac96122020ba67e3c2818bc511fae088d9849a0", "best_bid": "0.194", "best_ask": "0.195"}], "timestamp": "1785163568980", "event_type": "price_change"}}
{"ts": 1785163569.155303, "kind": "orders_out", "data": [{"token_id": "54533043819946592547517511176940999955633860128497669742211153063842200957669", "side": "BUY", "price": 0.153, "size": 19.61}]}
{"ts": 1785163569.719, "kind": "price_change", "data": {"market": "0x18b1c135d0a40c5894da9412e77311827d9caf16cf4cd6591b247a34730af919", "price_changes": [{"asset_id": "40081275558852222228080198821361202017557872256707631666334039001378518619916", "price": "0.506", "size": "36.7", "side": "SELL", "hash": "8e172c2c1149693a48fb5bc4fe1f79bb0b819496", "best_bid": "0.428", "best_ask": "0.429"}, {"asset_id": "78633590736077251574794513664747155551297291244492840448622550955320930591622", "price": "0.494", "size": "36.7", "side": "BUY", "hash": "4f2683d456524e8a15eb0212f0064f2bafddc9f6", "best_bid": "0.571", "best_ask": "0.572"}], "timestamp": "1785163569719", "event_type": "price_change"}}
{"ts": 1785163570.578, "kind": "price_change", "data": {"market": "0x18b1c135d0a40c5894da9412e77311827d9caf16cf4cd6591b247a34730af919", "price_changes": [{"asset_id": "40081275558852222228080198821361202017557872256707631666334039001378518619916", "price": "0.506", "size": "0", "side": "SELL", "hash": "f8636651d5686ddace5fdd206d0984423aaa9fb3", "best_bid": "0.428", "best_ask": "0.429"}, {"asset_id": "78633590736077251574794513664747155551297291244492840448622550955320930591622", "price": "0.494", "size": "0", "side": "BUY", "hash": "c3011ece7a85ce467f9f485b611497c77910f4e3", "best_bid": "0.571", "best_ask": "0.572"}], "timestamp": "1785163570578", "event_type": "price_change"}}
{"ts": 1785163570.856, "kind": "price_change", "data": {"market": "0x18b1c135d0a40c5894da9412e77311827d9caf16cf4cd6591b247a34730af919", "price_changes": [{"asset_id": "40081275558852222228080198821361202017557872256707631666334039001378518619916", "price": "0.507", "size": "36.7", "side": "SELL", "hash": "e4dc3acd435920a58675875ca6c1ee2f2bd36861", "best_bid": "0.428", "best_ask": "0.429"}, {"asset_id": "78633590736077251574794513664747155551297291244492840448622550955320930591622", "price": "0.493", "size": "36.7", "side": "BUY", "hash": "c0f43841e073bfb8ffe798078652b05a441f9ae4", "best_bid": "0.571", "best_ask": "0.572"}], "timestamp": "1785163570856", "event_type": "price_change"}}
{"ts": 1785163574.31, "kind": "price_change", "data": {"market": "0x0f49db97f71c68b1e42a6d16e3de93d85dbf7d4148e3f018eb79e88554be9f75", "price_changes": [{"asset_id": "54533043819946592547517511176940999955633860128497669742211153063842200957669", "price": "0.007", "size": "0", "side": "BUY", "hash": "217bf8c499b076402e27a00858f8da41eaab6d87", "best_bid": "0.194", "best_ask": "0.195"}, {"asset_id": "87854174148074652060467921081181402357467303721471806610111179101805869578687", "price": "0.993", "size": "0", "side": "SELL", "hash": "19e23063630d3dd93bad287c6a3eb9141b070ad1", "best_bid": "0.805", "best_ask": "0.806"}], "timestamp": "1785163574310", "event_type": "price_change"}}
{"ts": 1785163574.31, "kind": "price_change", "data": {"market": "0x0f49db97f71c68b1e42a6d16e3de93d85dbf7d4148e3f018eb79e88554be9f75", "price_changes": [{"asset_id": "54533043819946592547517511176940999955633860128497669742211153063842200957669", "price": "0.009", "size": "0", "side": "BUY", "hash": "217bf8c499b076402e27a00858f8da41eaab6d87", "best_bid": "0.194", "best_ask": "0.195"}, {"asset_id": "87854174148074652060467921081181402357467303721471806610111179101805869578687", "price": "0.991", "size": "0", "side": "SELL", "hash": "19e23063630d3dd93bad287c6a3eb9141b070ad1", "best_bid": "0.805", "best_ask": "0.806"}], "timestamp": "1785163574310", "event_type": "price_change"}}
{"ts": 1785163574.381, "kind": "price_change", "data": {"market": "0x0f49db97f71c68b1e42a6d16e3de93d85dbf7d4148e3f018eb79e88554be9f75", "price_changes": [{"asset_id": "54533043819946592547517511176940999955633860128497669742211153063842200957669", "price": "0.176", "size": "12210.93", "side": "BUY", "hash": "353ec33b26b321af06c99513d0f09b12a07d93a8", "best_bid": "0.194", "best_ask": "0.195"}, {"asset_id": "87854174148074652060467921081181402357467303721471806610111179101805869578687", "price": "0.824", "size": "12210.93", "side": "SELL", "hash": "150e8e229ce92218efde5231f2c9fb49cbb3e786", "best_bid": "0.805", "best_ask": "0.806"}], "timestamp": "1785163574381", "event_type": "price_change"}}
{"ts": 1785163574.382, "kind": "price_change", "data": {"market": "0x0f49db97f71c68b1e42a6d16e3de93d85dbf7d4148e3f018eb79e88554be9f75", "price_changes": [{"asset_id": "54533043819946592547517511176940999955633860128497669742211153063842200957669", "price": "0.04", "size": "300", "side": "BUY", "hash": "26ea84715cead57fe48ed6d502af2480fcb531dc", "best_bid": "0.194", "best_ask": "0.195"}, {"asset_id": "87854174148074652060467921081181402357467303721471806610111179101805869578687", "price": "0.96", "size": "300", "side": "SELL", "hash": "8cc7da3f17a5b9ab14c718806359f9b79f01ddc9", "best_bid": "0.805", "best_ask": "0.806"}], "timestamp": "1785163574382", "event_type": "price_change"}}
{"ts": 1785163574.457, "kind": "price_change", "data": {"market": "0x0f49db97f71c68b1e42a6d16e3de93d85dbf7d4148e3f018eb79e88554be9f75", "price_changes": [{"asset_id": "54533043819946592547517511176940999955633860128497669742211153063842200957669", "price": "0.02", "size": "8000", "side": "BUY", "hash": "928fd5a5e5b5d93fd6ad0e43f030f2e8d145a9ba", "best_bid": "0.194", "best_ask": "0.195"}, {"asset_id": "87854174148074652060467921081181402357467303721471806610111179101805869578687", "price": "0.98", "size": "8000", "side": "SELL", "hash": "4851539185837b72fe6513acca0bef648c574687", "best_bid": "0.805", "best_ask": "0.806"}], "timestamp": "1785163574457", "event_type": "price_change"}}
{"ts": 1785163575.031, "kind": "price_change", "data": {"market": "0x18b1c135d0a40c5894da9412e77311827d9caf16cf4cd6591b247a34730af919", "price_changes": [{"asset_id": "78633590736077251574794513664747155551297291244492840448622550955320930591622", "price": "0.08", "size": "14375", "side": "BUY", "hash": "b71002f6fa08f799e3a94a5b1e943847740304a4", "best_bid": "0.571", "best_ask": "0.572"}, {"asset_id": "40081275558852222228080198821361202017557872256707631666334039001378518619916", "price": "0.92", "size": "14375", "side": "SELL", "hash": "7ad60969018f075254d4f54c63a54a178b9a28cb", "best_bid": "0.428", "best_ask": "0.429"}], "timestamp": "1785163575031", "event_type": "price_change"}}
{"ts": 1785163575.081, "kind": "price_change", "data": {"market": "0x18b1c135d0a40c5894da9412e77311827d9caf16cf4cd6591b247a34730af919", "price_changes": [{"asset_id": "40081275558852222228080198821361202017557872256707631666334039001378518619916", "price": "0.03", "size": "118750", "side": "BUY", "hash": "912b3b735efaac2bc0da1794bc8a23cd7c7b3968", "best_bid": "0.428", "best_ask": "0.429"}, {"asset_id": "78633590736077251574794513664747155551297291244492840448622550955320930591622", "price": "0.97", "size": "118750", "side": "SELL", "hash": "ea26efa91129106651fddfe322531e7c43217a44", "best_bid": "0.571", "best_ask": "0.572"}], "timestamp": "1785163575081", "event_type": "price_change"}}
{"ts": 1785163575.224, "kind": "price_change", "data": {"market": "0x0f49db97f71c68b1e42a6d16e3de93d85dbf7d4148e3f018eb79e88554be9f75", "price_changes": [{"asset_id": "54533043819946592547517511176940999955633860128497669742211153063842200957669", "price": "0.17", "size": "5989.88", "side": "BUY", "hash": "5e624f92d1a6b36275ff4f1026c02d67d49722bc", "best_bid": "0.194", "best_ask": "0.195"}, {"asset_id": "87854174148074652060467921081181402357467303721471806610111179101805869578687", "price": "0.83", "size": "5989.88", "side": "SELL", "hash": "a814b7d4b1818f7235576a6ea7bcaf954f315b8f", "best_bid": "0.805", "best_ask": "0.806"}], "timestamp": "1785163575224", "event_type": "price_change"}}
{"ts": 1785163575.226, "kind": "price_change", "data": {"market": "0x0f49db97f71c68b1e42a6d16e3de93d85dbf7d4148e3f018eb79e88554be9f75", "price_changes": [{"asset_id": "54533043819946592547517511176940999955633860128497669742211153063842200957669", "price": "0.16", "size": "2850", "side": "BUY", "hash": "0e244de61e2739c2c4a8fad16cfc32f6e09bc698", "best_bid": "0.194", "best_ask": "0.195"}, {"asset_id": "87854174148074652060467921081181402357467303721471806610111179101805869578687", "price": "0.84", "size": "2850", "side": "SELL", "hash": "78cd393db4cd9059a8f1a1a7268a8b6de6aae700", "best_bid": "0.805", "best_ask": "0.806"}], "timestamp": "1785163575226", "event_type": "price_change"}}
{"ts": 1785163575.360366, "kind": "orders_out", "data": [{"token_id": "40081275558852222228080198821361202017557872256707631666334039001378518619916", "side": "BUY", "price": 0.387, "size": 7.75}, {"token_id": "78633590736077251574794513664747155551297291244492840448622550955320930591622", "side": "BUY", "price": 0.529, "size": 5.67}]}
{"ts": 1785163575.687, "kind": "price_change", "data": {"market": "0x0f49db97f71c68b1e42a6d16e3de93d85dbf7d4148e3f018eb79e88554be9f75", "price_changes": [{"asset_id": "87854174148074652060467921081181402357467303721471806610111179101805869578687", "price": "0.795", "size": "2890.98", "side": "BUY", "hash": "fa6cedcc908d019030e0db43e867a6f238a40736", "best_bid": "0.805", "best_ask": "0.806"}, {"asset_id": "54533043819946592547517511176940999955633860128497669742211153063842200957669", "price": "0.205", "size": "2890.98", "side": "SELL", "hash": "f7a23569c53789e194b37a96fd74f173172ab0a7", "best_bid": "0.194", "best_ask": "0.195"}], "timestamp": "1785163575687", "event_type": "price_change"}}
{"ts": 1785163575.772, "kind": "price_change", "data": {"market": "0x0f49db97f71c68b1e42a6d16e3de93d85dbf7d4148e3f018eb79e88554be9f75", "price_changes": [{"asset_id": "87854174148074652060467921081181402357467303721471806610111179101805869578687", "price": "0.795", "size": "3457.98", "side": "BUY", "hash": "f0f270c12e850f95e474a3d40e63adfc9cdfb1cb", "best_bid": "0.805", "best_ask": "0.806"}, {"asset_id": "54533043819946592547517511176940999955633860128497669742211153063842200957669", "price": "0.205", "size": "3457.98", "side": "SELL", "hash": "0234c1838d6f017a8617595d7b604500f5ec8ff3", "best_bid": "0.194", "best_ask": "0.195"}], "timestamp": "1785163575772", "event_type": "price_change"}}
{"ts": 1785163576.315, "kind": "price_change", "data": {"market": "0x18b1c135d0a40c5894da9412e77311827d9caf16cf4cd6591b247a34730af919", "price_changes": [{"asset_id": "40081275558852222228080198821361202017557872256707631666334039001378518619916", "price": "0.418", "size": "5970.05", "side": "BUY", "hash": "14a3d03f38db552173e6a5e644dd7fa37cfe0bd7", "best_bid": "0.428", "best_ask": "0.429"}, {"asset_id": "78633590736077251574794513664747155551297291244492840448622550955320930591622", "price": "0.582", "size": "5970.05", "side": "SELL", "hash": "0ba5fa2a65bfd611f2190cb081adb61ede4fd79a", "best_bid": "0.571", "best_ask": "0.572"}], "timestamp": "1785163576315", "event_type": "price_change"}}
{"ts": 1785163576.393, "kind": "price_change", "data": {"market": "0x18b1c135d0a40c5894da9412e77311827d9caf16cf4cd6591b247a34730af919", "price_changes": [{"asset_id": "40081275558852222228080198821361202017557872256707631666334039001378518619916", "price": "0.418", "size": "7048.05", "side": "BUY", "hash": "29414169d58c01abd9be3b81229c7227ed85f3ad", "best_bid": "0.428", "best_ask": "0.429"}, {"asset_id": "78633590736077251574794513664747155551297291244492840448622550955320930591622", "price": "0.582", "size": "7048.05", "side": "SELL", "hash": "3cf69ffeb5fac70db25d8e5bb54226103787ff66", "best_bid": "0.571", "best_ask": "0.572"}], "timestamp": "1785163576393", "event_type": "price_change"}}
{"ts": 1785163576.702, "kind": "price_change", "data": {"market": "0x18b1c135d0a40c5894da9412e77311827d9caf16cf4cd6591b247a34730af919", "price_changes": [{"asset_id": "40081275558852222228080198821361202017557872256707631666334039001378518619916", "price": "0.41", "size": "2931.23", "side": "BUY", "hash": "368b9f274b326ad81640b8a3065d2d2ef95eebf3", "best_bid": "0.428", "best_ask": "0.429"}, {"asset_id": "78633590736077251574794513664747155551297291244492840448622550955320930591622", "price": "0.59", "size": "2931.23", "side": "SELL", "hash": "c0ed9e519e05c103ca6ab59b72d7ad6315254df2", "best_bid": "0.571", "best_ask": "0.572"}], "timestamp": "1785163576702", "event_type": "price_change"}}
{"ts": 1785163577.286, "kind": "price_change", "data": {"market": "0x18b1c135d0a40c5894da9412e77311827d9caf16cf4cd6591b247a34730af919", "price_changes": [{"asset_id": "40081275558852222228080198821361202017557872256707631666334039001378518619916", "price": "0.41", "size": "2947.28", "side": "BUY", "hash": "178c80301ac31481949992bb43fa53df32fa57ac", "best_bid": "0.428", "best_ask": "0.429"}, {"asset_id": "78633590736077251574794513664747155551297291244492840448622550955320930591622", "price": "0.59", "size": "2947.28", "side": "SELL", "hash": "17e67a9f1647574338a1a26edf9b56d6c0e1d6bc", "best_bid": "0.571", "best_ask": "0.572"}], "timestamp": "1785163577286", "event_type": "price_change"}}
{"ts": 1785163578.0, "kind": "price_change", "data": {"market": "0x0f49db97f71c68b1e42a6d16e3de93d85dbf7d4148e3f018eb79e88554be9f75", "price_changes": [{"asset_id": "87854174148074652060467921081181402357467303721471806610111179101805869578687", "price": "0.37", "size": "0", "side": "BUY", "hash": "05e2cf08e19f6d4764c4535c95c1b77237b38a44", "best_bid": "0.805", "best_ask": "0.806"}, {"asset_id": "54533043819946592547517511176940999955633860128497669742211153063842200957669", "price": "0.63", "size": "0", "side": "SELL", "hash": "dbae3f4c987bccb3aff2e75fa8608c2b0d849634", "best_bid": "0.194", "best_ask": "0.195"}], "timestamp": "1785163578000", "event_type": "price_change"}}
{"ts": 1785163582.295, "kind": "price_change", "data": {"market": "0x18b1c135d0a40c5894da9412e77311827d9caf16cf4cd6591b247a34730af919", "price_changes": [{"asset_id": "78633590736077251574794513664747155551297291244492840448622550955320930591622", "price": "0.08", "size": "29375", "side": "BUY", "hash": "bfc566ac1da4f120f61b397a1dbd626d69b7f8ca", "best_bid": "0.571", "best_ask": "0.572"}, {"asset_id": "40081275558852222228080198821361202017557872256707631666334039001378518619916", "price": "0.92", "size": "29375", "side": "SELL", "hash": "88fbbed6a8aff5c1aeb2e78265f930e8c910de1c", "best_bid": "0.428", "best_ask": "0.429"}], "timestamp": "1785163582295", "event_type": "price_change"}}
{"ts": 1785163582.296, "kind": "price_change", "data": {"market": "0x18b1c135d0a40c5894da9412e77311827d9caf16cf4cd6591b247a34730af919", "price_changes": [{"asset_id": "40081275558852222228080198821361202017557872256707631666334039001378518619916", "price": "0.03", "size": "158750", "side": "BUY", "hash": "1e0b99f38ee651b787c441831bde3fc41fb351a5", "best_bid": "0.428", "best_ask": "0.429"}, {"asset_id": "78633590736077251574794513664747155551297291244492840448622550955320930591622", "price": "0.97", "size": "158750", "side": "SELL", "hash": "2d5fa5aa185722aa72b85d16bf8f5aff5c13ceb2", "best_bid": "0.571", "best_ask": "0.572"}], "timestamp": "1785163582296", "event_type": "price_change"}}
{"ts": 1785163582.389, "kind": "price_change", "data": {"market": "0x0f49db97f71c68b1e42a6d16e3de93d85dbf7d4148e3f018eb79e88554be9f75", "price_changes": [{"asset_id": "87854174148074652060467921081181402357467303721471806610111179101805869578687", "price": "0.803", "size": "12434.97", "side": "BUY", "hash": "f3c3c08b8bcc89281aea3f1685376c18008cceef", "best_bid": "0.805", "best_ask": "0.806"}, {"asset_id": "54533043819946592547517511176940999955633860128497669742211153063842200957669", "price": "0.197", "size": "12434.97", "side": "SELL", "hash": "1aae76a64af9c7606e75f45ff18a6266c689d890", "best_bid": "0.194", "best_ask": "0.195"}], "timestamp": "1785163582389", "event_type": "price_change"}}
{"ts": 1785163584.003, "kind": "price_change", "data": {"market": "0x18b1c135d0a40c5894da9412e77311827d9caf16cf4cd6591b247a34730af919", "price_changes": [{"asset_id": "78633590736077251574794513664747155551297291244492840448622550955320930591622", "price": "0.08", "size": "27500", "side": "BUY", "hash": "5008ae0613e64785868db9ae989f83cf9eb0c359", "best_bid": "0.571", "best_ask": "0.572"}, {"asset_id": "40081275558852222228080198821361202017557872256707631666334039001378518619916", "price": "0.92", "size": "27500", "side": "SELL", "hash": "90cdad8172de19b5f8b083577de8580e1ae86112", "best_bid": "0.428", "best_ask": "0.429"}], "timestamp": "1785163584003", "event_type": "price_change"}}
{"ts": 1785163584.083, "kind": "price_change", "data": {"market": "0x0f49db97f71c68b1e42a6d16e3de93d85dbf7d4148e3f018eb79e88554be9f75", "price_changes": [{"asset_id": "87854174148074652060467921081181402357467303721471806610111179101805869578687", "price": "0.37", "size": "2702", "side": "BUY", "hash": "41ba06df33e4ba9c6af6073ae1611e81823585b5", "best_bid": "0.805", "best_ask": "0.806"}, {"asset_id": "54533043819946592547517511176940999955633860128497669742211153063842200957669", "price": "0.63", "size": "2702", "side": "SELL", "hash": "5aeef19dbee957252d03baece9578b9fef969b6e", "best_bid": "0.194", "best_ask": "0.195"}], "timestamp": "1785163584083", "event_type": "price_change"}}
{"ts": 1785163585.219, "kind": "price_change", "data": {"market": "0x0f49db97f71c68b1e42a6d16e3de93d85dbf7d4148e3f018eb79e88554be9f75", "price_changes": [{"asset_id": "87854174148074652060467921081181402357467303721471806610111179101805869578687", "price": "0.795", "size": "2891.98", "side": "BUY", "hash": "6f4e685a01c8dd2fd4935ef9bf9d513a8301432b", "best_bid": "0.805", "best_ask": "0.806"}, {"asset_id": "54533043819946592547517511176940999955633860128497669742211153063842200957669", "price": "0.205", "size": "2891.98", "side": "SELL", "hash": "2517682c71da7ac03c29f5c135ab744213af03e9", "best_bid": "0.194", "best_ask": "0.195"}], "timestamp": "1785163585219", "event_type": "price_change"}}
{"ts": 1785163585.293, "kind": "price_change", "data": {"market": "0x0f49db97f71c68b1e42a6d16e3de93d85dbf7d4148e3f018eb79e88554be9f75", "price_changes": [{"asset_id": "87854174148074652060467921081181402357467303721471806610111179101805869578687", "price": "0.795", "size": "3457.98", "side": "BUY", "hash": "fe2b4c4be564c32f5239b84668336e721793ab38", "best_bid": "0.805", "best_ask": "0.806"}, {"asset_id": "54533043819946592547517511176940999955633860128497669742211153063842200957669", "price": "0.205", "size": "3457.98", "side": "SELL", "hash": "9a6d387aac32eed2f498022784a679737f2e0a63", "best_bid": "0.194", "best_ask": "0.195"}], "timestamp": "1785163585293", "event_type": "price_change"}}
{"ts": 1785163585.547978, "kind": "orders_out", "data": [{"token_id": "54533043819946592547517511176940999955633860128497669742211153063842200957669", "side": "BUY", "price": 0.144, "size": 10.42}]}
{"ts": 1785163585.773, "kind": "price_change", "data": {"market": "0x18b1c135d0a40c5894da9412e77311827d9caf16cf4cd6591b247a34730af919", "price_changes": [{"asset_id": "40081275558852222228080198821361202017557872256707631666334039001378518619916", "price": "0.418", "size": "5972.05", "side": "BUY", "hash": "addd892fccc6c8d866f843c0976df599cea028e8", "best_bid": "0.428", "best_ask": "0.429"}, {"asset_id": "78633590736077251574794513664747155551297291244492840448622550955320930591622", "price": "0.582", "size": "5972.05", "side": "SELL", "hash": "ee3236b796a7dd5fb15ba0f8d8fdad3ece8136a9", "best_bid": "0.571", "best_ask": "0.572"}], "timestamp": "1785163585773", "event_type": "price_change"}}
{"ts": 1785163585.844, "kind": "price_change", "data": {"market": "0x18b1c135d0a40c5894da9412e77311827d9caf16cf4cd6591b247a34730af919", "price_changes": [{"asset_id": "40081275558852222228080198821361202017557872256707631666334039001378518619916", "price": "0.418", "size": "7048.05", "side": "BUY", "hash": "ad231911ed594b5518045625a5c4e9d2c0d3055c", "best_bid": "0.428", "best_ask": "0.429"}, {"asset_id": "78633590736077251574794513664747155551297291244492840448622550955320930591622", "price": "0.582", "size": "7048.05", "side": "SELL", "hash": "bdaf00bb30647a81e3525b13601db655ad80fbd0", "best_bid": "0.571", "best_ask": "0.572"}], "timestamp": "1785163585844", "event_type": "price_change"}}
{"ts": 1785163587.05, "kind": "price_change", "data": {"market": "0x0f49db97f71c68b1e42a6d16e3de93d85dbf7d4148e3f018eb79e88554be9f75", "price_changes": [{"asset_id": "54533043819946592547517511176940999955633860128497669742211153063842200957669", "price": "0.02", "size": "500", "side": "BUY", "hash": "4e67ebdd5dd6cf601a66b254213862e7174f1aac", "best_bid": "0.194", "best_ask": "0.195"}, {"asset_id": "87854174148074652060467921081181402357467303721471806610111179101805869578687", "price": "0.98", "size": "500", "side": "SELL", "hash": "62b3378439a4b9191bdd4364effe77745f1806a5", "best_bid": "0.805", "best_ask": "0.806"}], "timestamp": "1785163587050", "event_type": "price_change"}}
{"ts": 1785163587.056, "kind": "price_change", "data": {"market": "0x0f49db97f71c68b1e42a6d16e3de93d85dbf7d4148e3f018eb79e88554be9f75", "price_changes": [{"asset_id": "87854174148074652060467921081181402357467303721471806610111179101805869578687", "price": "0.02", "size": "233000", "side": "BUY", "hash": "4789953b73e6c03012b80a6ad77eb62c1ab7b602", "best_bid": "0.805", "best_ask": "0.806"}, {"asset_id": "54533043819946592547517511176940999955633860128497669742211153063842200957669", "price": "0.98", "size": "233000", "side": "SELL", "hash": "96a39d2d5e2144d827d5c2bd5c2cb9a43b1f6e0e", "best_bid": "0.194", "best_ask": "0.195"}], "timestamp": "1785163587056", "event_type": "price_change"}}
{"ts": 1785163587.341, "kind": "price_change", "data": {"market": "0x18b1c135d0a40c5894da9412e77311827d9caf16cf4cd6591b247a34730af919", "price_changes": [{"asset_id": "40081275558852222228080198821361202017557872256707631666334039001378518619916", "price": "0.28", "size": "535", "side": "BUY", "hash": "bd3ceb1b6b1b38a341f4cbffe904a71f0407a6b4", "best_bid": "0.428", "best_ask": "0.429"}, {"asset_id": "78633590736077251574794513664747155551297291244492840448622550955320930591622", "price": "0.72", "size": "535", "side": "SELL", "hash": "bef21fc6705ceb1f916e51e62f20afe18dcd0ae8", "best_bid": "0.571", "best_ask": "0.572"}], "timestamp": "1785163587341", "event_type": "price_change"}}
{"ts": 1785163588.0, "kind": "price_change", "data": {"market": "0x0f49db97f71c68b1e42a6d16e3de93d85dbf7d4148e3f018eb79e88554be9f75", "price_changes": [{"asset_id": "87854174148074652060467921081181402357467303721471806610111179101805869578687", "price": "0.02", "size": "13000", "side": "BUY", "hash": "fa92cc0f151073cbc8dce836b9826f14a5d2a8a0", "best_bid": "0.805", "best_ask": "0.806"}, {"asset_id": "54533043819946592547517511176940999955633860128497669742211153063842200957669", "price": "0.98", "size": "13000", "side": "SELL", "hash": "6ee67b803eb308a4f8f78e0ccf6960f3fead7cfb", "best_bid": "0.194", "best_ask": "0.195"}], "timestamp": "1785163588000", "event_type": "price_change"}}
{"ts": 1785163588.0, "kind": "price_change", "data": {"market": "0x18b1c135d0a40c5894da9412e77311827d9caf16cf4cd6591b247a34730af919", "price_changes": [{"asset_id": "78633590736077251574794513664747155551297291244492840448622550955320930591622", "price": "0.004", "size": "5000", "side": "BUY", "hash": "75e1a63eda091ef4c4bdd61104b556e539c11bb3", "best_bid": "0.571", "best_ask": "0.572"}, {"asset_id": "40081275558852222228080198821361202017557872256707631666334039001378518619916", "price": "0.996", "size": "5000", "side": "SELL", "hash": "ea73d08bf65de1e2f2c9664b46dfe95d423877a7", "best_bid": "0.428", "best_ask": "0.429"}], "timestamp": "1785163588000", "event_type": "price_change"}}
{"ts": 1785163588.001, "kind": "price_change", "data": {"market": "0x0f49db97f71c68b1e42a6d16e3de93d85dbf7d4148e3f018eb79e88554be9f75", "price_changes": [{"asset_id": "87854174148074652060467921081181402357467303721471806610111179101805869578687", "price": "0.02", "size": "13000", "side": "BUY", "hash": "206c4f93e1a1279ebc5f0674e4d8e40486afec86", "best_bid": "0.805", "best_ask": "0.806"}, {"asset_id": "54533043819946592547517511176940999955633860128497669742211153063842200957669", "price": "0.98", "size": "13000", "side": "SELL", "hash": "520191478f56afed6e8e52100b96785dd557a955", "best_bid": "0.194", "best_ask": "0.195"}], "timestamp": "1785163588001", "event_type": "price_change"}}
{"ts": 1785163588.003, "kind": "price_change", "data": {"market": "0x0f49db97f71c68b1e42a6d16e3de93d85dbf7d4148e3f018eb79e88554be9f75", "price_changes": [{"asset_id": "87854174148074652060467921081181402357467303721471806610111179101805869578687", "price": "0.02", "size": "13000", "side": "BUY", "hash": "86b448803f4a405860d044b82f791951273bfd86", "best_bid": "0.805", "best_ask": "0.806"}, {"asset_id": "54533043819946592547517511176940999955633860128497669742211153063842200957669", "price": "0.98", "size": "13000", "side": "SELL", "hash": "5ca72a4abe03a8cfa612524744a3bf74c0af6f4d", "best_bid": "0.194", "best_ask": "0.195"}], "timestamp": "1785163588003", "event_type": "price_change"}}
{"ts": 1785163589.0, "kind": "price_change", "data": {"market": "0x18b1c135d0a40c5894da9412e77311827d9caf16cf4cd6591b247a34730af919", "price_changes": [{"asset_id": "40081275558852222228080198821361202017557872256707631666334039001378518619916", "price": "0.428", "size": "58502.52", "side": "BUY", "hash": "c4b298498ac5c0133b5441f30598d803b8eba451", "best_bid": "0.428", "best_ask": "0.429"}, {"asset_id": "78633590736077251574794513664747155551297291244492840448622550955320930591622", "price": "0.572", "size": "58502.52", "side": "SELL", "hash": "60c5980283fc9f5d4be4e827063ed2d9ded46612", "best_bid": "0.571", "best_ask": "0.572"}], "timestamp": "1785163589000", "event_type": "price_change"}}
{"ts": 1785163589.026, "kind": "price_change", "data": {"market": "0x18b1c135d0a40c5894da9412e77311827d9caf16cf4cd6591b247a34730af919", "price_changes": [{"asset_id": "40081275558852222228080198821361202017557872256707631666334039001378518619916", "price": "0.427", "size": "7059.99", "side": "BUY", "hash": "bac49d5deca5601dfdb3c08e0b93670d06ca1592", "best_bid": "0.428", "best_ask": "0.429"}, {"asset_id": "78633590736077251574794513664747155551297291244492840448622550955320930591622", "price": "0.573", "size": "7059.99", "side": "SELL", "hash": "12a8dbd4c8345365fd8e13dbe27b9330490c5b55", "best_bid": "0.571", "best_ask": "0.572"}], "timestamp": "1785163589026", "event_type": "price_change"}}
{"ts": 1785163589.039, "kind": "price_change", "data": {"market": "0x18b1c135d0a40c5894da9412e77311827d9caf16cf4cd6591b247a34730af919", "price_changes": [{"asset_id": "40081275558852222228080198821361202017557872256707631666334039001378518619916", "price": "0.427", "size": "6659.99", "side": "BUY", "hash": "d4e20da21a41e3d36f939be7d91ff923858a1301", "best_bid": "0.428", "best_ask": "0.429"}, {"asset_id": "78633590736077251574794513664747155551297291244492840448622550955320930591622", "price": "0.573", "size": "6659.99", "side": "SELL", "hash": "f1085912884e414e8bf876daeac9b6f69c98cd87", "best_bid": "0.571", "best_ask": "0.572"}], "timestamp": "1785163589039", "event_type": "price_change"}}
{"ts": 1785163589.041, "kind": "price_change", "data": {"market": "0x18b1c135d0a40c5894da9412e77311827d9caf16cf4cd6591b247a34730af919", "price_changes": [{"asset_id": "40081275558852222228080198821361202017557872256707631666334039001378518619916", "price": "0.427", "size": "6209.99", "side": "BUY", "hash": "79b61ffb5efc874ba758edd21df3c698a4829a42", "best_bid": "0.428", "best_ask": "0.429"}, {"asset_id": "78633590736077251574794513664747155551297291244492840448622550955320930591622", "price": "0.573", "size": "6209.99", "side": "SELL", "hash": "7ffebe25468c7d5c0892e8294f2eef2c760d1d66", "best_bid": "0.571", "best_ask": "0.572"}], "timestamp": "1785163589041", "event_type": "price_change"}}
{"ts": 1785163589.052, "kind": "price_change", "data": {"market": "0x18b1c135d0a40c5894da9412e77311827d9caf16cf4cd6591b247a34730af919", "price_changes": [{"asset_id": "40081275558852222228080198821361202017557872256707631666334039001378518619916", "price": "0.426", "size": "7827.22", "side": "BUY", "hash": "5b73212cbf9e1caf65311da436195a8deeb90aa0", "best_bid": "0.428", "best_ask": "0.429"}, {"asset_id": "78633590736077251574794513664747155551297291244492840448622550955320930591622", "price": "0.574", "size": "7827.22", "side": "SELL", "hash": "7e23c663db9d237da226384c1f69b980c643600d", "best_bid": "0.571", "best_ask": "0.572"}], "timestamp": "1785163589052", "event_type": "price_change"}}
{"ts": 1785163589.068, "kind": "price_change", "data": {"market": "0x18b1c135d0a40c5894da9412e77311827d9caf16cf4cd6591b247a34730af919", "price_changes": [{"asset_id": "40081275558852222228080198821361202017557872256707631666334039001378518619916", "price": "0.418", "size": "6848.05", "side": "BUY", "hash": "94a386a08c8c85ebcc11948bae462c21f55b8c16", "best_bid": "0.428", "best_ask": "0.429"}, {"asset_id": "78633590736077251574794513664747155551297291244492840448622550955320930591622", "price": "0.582", "size": "6848.05", "side": "SELL", "hash": "c6b250d7b795e8e1debed4ef09ec89332e27c4e9", "best_bid": "0.571", "best_ask": "0.572"}], "timestamp": "1785163589068", "event_type": "price_change"}}
{"ts": 1785163589.097, "kind": "price_change", "data": {"market": "0x18b1c135d0a40c5894da9412e77311827d9caf16cf4cd6591b247a34730af919", "price_changes": [{"asset_id": "40081275558852222228080198821361202017557872256707631666334039001378518619916", "price": "0.411", "size": "36707.4", "side": "BUY", "hash": "abda83957548c4d401d10dc5e70629f9f7095026", "best_bid": "0.428", "best_ask": "0.429"}, {"asset_id": "78633590736077251574794513664747155551297291244492840448622550955320930591622", "price": "0.589", "size": "36707.4", "side": "SELL", "hash": "fe4c633fc85a72d334229a0883211fa9d1ec65a1", "best_bid": "0.571", "best_ask": "0.572"}], "timestamp": "1785163589097", "event_type": "price_change"}}
{"ts": 1785163589.115, "kind": "price_change", "data": {"market": "0x18b1c135d0a40c5894da9412e77311827d9caf16cf4cd6591b247a34730af919", "price_changes": [{"asset_id": "40081275558852222228080198821361202017557872256707631666334039001378518619916", "price": "0.415", "size": "2200", "side": "BUY", "hash": "0f8f6f2ff61967ec03d162bc78d3b135d4000922", "best_bid": "0.428", "best_ask": "0.429"}, {"asset_id": "78633590736077251574794513664747155551297291244492840448622550955320930591622", "price": "0.585", "size": "2200", "side": "SELL", "hash": "ebaee4c6f526d9dfc50ac8cd1bf080a506bcaaf3", "best_bid": "0.571", "best_ask": "0.572"}], "timestamp": "1785163589115", "event_type": "price_change"}}
{"ts": 1785163589.124, "kind": "price_change", "data": {"market": "0x18b1c135d0a40c5894da9412e77311827d9caf16cf4cd6591b247a34730af919", "price_changes": [{"asset_id": "78633590736077251574794513664747155551297291244492840448622550955320930591622", "price": "0.549", "size": "9.99", "side": "BUY", "hash": "7ff48c2c27f10977232852209069506df75cbe2c", "best_bid": "0.571", "best_ask": "0.572"}, {"asset_id": "40081275558852222228080198821361202017557872256707631666334039001378518619916", "price": "0.451", "size": "9.99", "side": "SELL", "hash": "770f96eebd4831246796169b20ed779dc0b34ec7", "best_bid": "0.428", "best_ask": "0.429"}], "timestamp": "1785163589124", "event_type": "price_change"}}
{"ts": 1785163589.13, "kind": "price_change", "data": {"market": "0x18b1c135d0a40c5894da9412e77311827d9caf16cf4cd6591b247a34730af919", "price_changes": [{"asset_id": "40081275558852222228080198821361202017557872256707631666334039001378518619916", "price": "0.41", "size": "3147.28", "side": "BUY", "hash": "736376ef5ff088dcd7231fe88bf1609d97227345", "best_bid": "0.428", "best_ask": "0.429"}, {"asset_id": "78633590736077251574794513664747155551297291244492840448622550955320930591622", "price": "0.59", "size": "3147.28", "side": "SELL", "hash": "2c00fa82443efd3c9b7378a0ede0e4713df1ccae", "best_bid": "0.571", "best_ask": "0.572"}], "timestamp": "1785163589130", "event_type": "price_change"}}
{"ts": 1785163591.869, "kind": "price_change", "data": {"market": "0x0f49db97f71c68b1e42a6d16e3de93d85dbf7d4148e3f018eb79e88554be9f75", "price_changes": [{"asset_id": "87854174148074652060467921081181402357467303721471806610111179101805869578687", "price": "0.02", "size": "98000", "side": "BUY", "hash": "d27576a30ab4d6188e81e0af0a029bf717957fa3", "best_bid": "0.805", "best_ask": "0.806"}, {"asset_id": "54533043819946592547517511176940999955633860128497669742211153063842200957669", "price": "0.98", "size": "98000", "side": "SELL", "hash": "877a7545b4baa2872e4e71b60b1908c857544a29", "best_bid": "0.194", "best_ask": "0.195"}], "timestamp": "1785163591869", "event_type": "price_change"}}
{"ts": 1785163591.87, "kind": "price_change", "data": {"market": "0x0f49db97f71c68b1e42a6d16e3de93d85dbf7d4148e3f018eb79e88554be9f75", "price_changes": [{"asset_id": "87854174148074652060467921081181402357467303721471806610111179101805869578687", "price": "0.02", "size": "173000", "side": "BUY", "hash": "739b490c1d8b54180d4053c6e17ccdb3dbb0e368", "best_bid": "0.805", "best_ask": "0.806"}, {"asset_id": "54533043819946592547517511176940999955633860128497669742211153063842200957669", "price": "0.98", "size": "173000", "side": "SELL", "hash": "72f93ce5384fcee0e50768a553f34b6c4d83062c", "best_bid": "0.194", "best_ask": "0.195"}], "timestamp": "1785163591870", "event_type": "price_change"}}
{"ts": 1785163591.871, "kind": "price_change", "data": {"market": "0x0f49db97f71c68b1e42a6d16e3de93d85dbf7d4148e3f018eb79e88554be9f75", "price_changes": [{"asset_id": "87854174148074652060467921081181402357467303721471806610111179101805869578687", "price": "0.02", "size": "233000", "side": "BUY", "hash": "ce2061e2191c5b0ca0a3928c7f0a9ee4ba5c2144", "best_bid": "0.805", "best_ask": "0.806"}, {"asset_id": "54533043819946592547517511176940999955633860128497669742211153063842200957669", "price": "0.98", "size": "233000", "side": "SELL", "hash": "748bfefc8e8db4cd565061e05d02df8593b0065c", "best_bid": "0.194", "best_ask": "0.195"}], "timestamp": "1785163591871", "event_type": "price_change"}}
{"ts": 1785163592.212, "kind": "price_change", "data": {"market": "0x18b1c135d0a40c5894da9412e77311827d9caf16cf4cd6591b247a34730af919", "price_changes": [{"asset_id": "78633590736077251574794513664747155551297291244492840448622550955320930591622", "price": "0.371", "size": "0", "side": "BUY", "hash": "5452932544d193d1d967362862cd26ddddfeec8e", "best_bid": "0.571", "best_ask": "0.572"}, {"asset_id": "40081275558852222228080198821361202017557872256707631666334039001378518619916", "price": "0.629", "size": "0", "side": "SELL", "hash": "cb75db6b9cc2d8c5491c89658eea37b3d323a6cf", "best_bid": "0.428", "best_ask": "0.429"}], "timestamp": "1785163592212", "event_type": "price_change"}}
{"ts": 1785163592.244, "kind": "price_change", "data": {"market": "0x18b1c135d0a40c5894da9412e77311827d9caf16cf4cd6591b247a34730af919", "price_changes": [{"asset_id": "78633590736077251574794513664747155551297291244492840448622550955320930591622", "price": "0.373", "size": "400", "side": "BUY", "hash": "5c2fd25f53da758f43405f7a2a622bc8ec980ef6", "best_bid": "0.571", "best_ask": "0.572"}, {"asset_id": "40081275558852222228080198821361202017557872256707631666334039001378518619916", "price": "0.627", "size": "400", "side": "SELL", "hash": "cf3fb958df6ab7f23771ceda5b3c535413063601", "best_bid": "0.428", "best_ask": "0.429"}], "timestamp": "1785163592244", "event_type": "price_change"}}
{"ts": 1785163592.272, "kind": "price_change", "data": {"market": "0x18b1c135d0a40c5894da9412e77311827d9caf16cf4cd6591b247a34730af919", "price_changes": [{"asset_id": "78633590736077251574794513664747155551297291244492840448622550955320930591622", "price": "0.549", "size": "0", "side": "BUY", "hash": "5da404323e559392db8e1b9e87ae3ab37f6fb693", "best_bid": "0.571", "best_ask": "0.572"}, {"asset_id": "40081275558852222228080198821361202017557872256707631666334039001378518619916", "price": "0.451", "size": "0", "side": "SELL", "hash": "7abfb6f464388780cc67404e64443af08b8d04de", "best_bid": "0.428", "best_ask": "0.429"}], "timestamp": "1785163592272", "event_type": "price_change"}}
{"ts": 1785163592.516651, "kind": "orders_out", "data": [{"token_id": "40081275558852222228080198821361202017557872256707631666334039001378518619916", "side": "BUY", "price": 0.387, "size": 7.75}, {"token_id": "78633590736077251574794513664747155551297291244492840448622550955320930591622", "side": "BUY", "price": 0.529, "size": 5.67}]}
{"ts": 1785163594.799, "kind": "price_change", "data": {"market": "0x18b1c135d0a40c5894da9412e77311827d9caf16cf4cd6591b247a34730af919", "price_changes": [{"asset_id": "78633590736077251574794513664747155551297291244492840448622550955320930591622", "price": "0.004", "size": "15016.91", "side": "BUY", "hash": "92175d0bb2e5011b544fa749fd418359e78e14d3", "best_bid": "0.571", "best_ask": "0.572"}, {"asset_id": "40081275558852222228080198821361202017557872256707631666334039001378518619916", "price": "0.996", "size": "15016.91", "side": "SELL", "hash": "4b668aa6312823a53e4ee4edf9dcaacbfb734f30", "best_bid": "0.428", "best_ask": "0.429"}], "timestamp": "1785163594799", "event_type": "price_change"}}
{"ts": 1785163594.835, "kind": "price_change", "data": {"market": "0x18b1c135d0a40c5894da9412e77311827d9caf16cf4cd6591b247a34730af919", "price_changes": [{"asset_id": "40081275558852222228080198821361202017557872256707631666334039001378518619916", "price": "0.427", "size": "6809.99", "side": "BUY", "hash": "5dd04d765d6b0715b3ac7aa7b3dbfe594077b40f", "best_bid": "0.428", "best_ask": "0.429"}, {"asset_id": "78633590736077251574794513664747155551297291244492840448622550955320930591622", "price": "0.573", "size": "6809.99", "side": "SELL", "hash": "dd77e04685e7ef79873c8df27cc06edcd68a47f7", "best_bid": "0.571", "best_ask": "0.572"}], "timestamp": "1785163594835", "event_type": "price_change"}}
{"ts": 1785163594.84, "kind": "price_change", "data": {"market": "0x18b1c135d0a40c5894da9412e77311827d9caf16cf4cd6591b247a34730af919", "price_changes": [{"asset_id": "40081275558852222228080198821361202017557872256707631666334039001378518619916", "price": "0.426", "size": "8827.22", "side": "BUY", "hash": "86d013e8a2e14e7a7f8030cef850f08cae7544c9", "best_bid": "0.428", "best_ask": "0.429"}, {"asset_id": "78633590736077251574794513664747155551297291244492840448622550955320930591622", "price": "0.574", "size": "8827.22", "side": "SELL", "hash": "f06f9d55aa11509970abae3771ba6d1521dc42db", "best_bid": "0.571", "best_ask": "0.572"}], "timestamp": "1785163594840", "event_type": "price_change"}}
{"ts": 1785163594.845, "kind": "price_change", "data": {"market": "0x18b1c135d0a40c5894da9412e77311827d9caf16cf4cd6591b247a34730af919", "price_changes": [{"asset_id": "40081275558852222228080198821361202017557872256707631666334039001378518619916", "price": "0.427", "size": "7209.99", "side": "BUY", "hash": "669d40507290850a53ed0e6ba66edfd6e8008b91", "best_bid": "0.428", "best_ask": "0.429"}, {"asset_id": "78633590736077251574794513664747155551297291244492840448622550955320930591622", "price": "0.573", "size": "7209.99", "side": "SELL", "hash": "7b1315eb84a3b3c36e041bdaf6c37a9ae4751bfc", "best_bid": "0.571", "best_ask": "0.572"}], "timestamp": "1785163594845", "event_type": "price_change"}}
{"ts": 1785163594.849, "kind": "price_change", "data": {"market": "0x18b1c135d0a40c5894da9412e77311827d9caf16cf4cd6591b247a34730af919", "price_changes": [{"asset_id": "40081275558852222228080198821361202017557872256707631666334039001378518619916", "price": "0.427", "size": "7659.99", "side": "BUY", "hash": "556b9044f8f741bfd3722eb27c2e880330645214", "best_bid": "0.428", "best_ask": "0.429"}, {"asset_id": "78633590736077251574794513664747155551297291244492840448622550955320930591622", "price": "0.573", "size": "7659.99", "side": "SELL", "hash": "be2d486623204a8fbffcfec2005f66b9858dd744", "best_bid": "0.571", "best_ask": "0.572"}], "timestamp": "1785163594849", "event_type": "price_change"}}
{"ts": 1785163594.864, "kind": "price_change", "data": {"market": "0x18b1c135d0a40c5894da9412e77311827d9caf16cf4cd6591b247a34730af919", "price_changes": [{"asset_id": "40081275558852222228080198821361202017557872256707631666334039001378518619916", "price": "0.41", "size": "2947.28", "side": "BUY", "hash": "a2d987c1b5a1f3e2e68feb10796ef7350ab7097e", "best_bid": "0.428", "best_ask": "0.429"}, {"asset_id": "78633590736077251574794513664747155551297291244492840448622550955320930591622", "price": "0.59", "size": "2947.28", "side": "SELL", "hash": "99c73935fe3bc3ad32254acf3325e7a6168b8b21", "best_bid": "0.571", "best_ask": "0.572"}], "timestamp": "1785163594864", "event_type": "price_change"}}
{"ts": 1785163594.872, "kind": "price_change", "data": {"market": "0x18b1c135d0a40c5894da9412e77311827d9caf16cf4cd6591b247a34730af919", "price_changes": [{"asset_id": "40081275558852222228080198821361202017557872256707631666334039001378518619916", "price": "0.415", "size": "2000", "side": "BUY", "hash": "4144f782ef333fced71fcbfc2826138c8ec64fa3", "best_bid": "0.428", "best_ask": "0.429"}, {"asset_id": "78633590736077251574794513664747155551297291244492840448622550955320930591622", "price": "0.585", "size": "2000", "side": "SELL", "hash": "c66e74e69f7aae4ca3cbe2b7ae30a517b140d293", "best_bid": "0.571", "best_ask": "0.572"}], "timestamp": "1785163594872", "event_type": "price_change"}}
{"ts": 1785163594.897, "kind": "price_change", "data": {"market": "0x18b1c135d0a40c5894da9412e77311827d9caf16cf4cd6591b247a34730af919", "price_changes": [{"asset_id": "40081275558852222228080198821361202017557872256707631666334039001378518619916", "price": "0.411", "size": "36907.4", "side": "BUY", "hash": "694853ce7b3cb0307acf3fa77826544e6cc9ea45", "best_bid": "0.428", "best_ask": "0.429"}, {"asset_id": "78633590736077251574794513664747155551297291244492840448622550955320930591622", "price": "0.589", "size": "36907.4", "side": "SELL", "hash": "c57e68f886765f0242fe20513b557edb72749706", "best_bid": "0.571", "best_ask": "0.572"}], "timestamp": "1785163594897", "event_type": "price_change"}}
{"ts": 1785163594.909, "kind": "price_change", "data": {"market": "0x18b1c135d0a40c5894da9412e77311827d9caf16cf4cd6591b247a34730af919", "price_changes": [{"asset_id": "40081275558852222228080198821361202017557872256707631666334039001378518619916", "price": "0.418", "size": "7048.05", "side": "BUY", "hash": "2e8b405337ce55d79f2eec3bfe3c5067994bb71a", "best_bid": "0.428", "best_ask": "0.429"}, {"asset_id": "78633590736077251574794513664747155551297291244492840448622550955320930591622", "price": "0.582", "size": "7048.05", "side": "SELL", "hash": "1817d094cbd7c9bc46f24c83602383537aaee1d6", "best_bid": "0.571", "best_ask": "0.572"}], "timestamp": "1785163594909", "event_type": "price_change"}}
{"ts": 1785163594.919, "kind": "price_change", "data": {"market": "0x18b1c135d0a40c5894da9412e77311827d9caf16cf4cd6591b247a34730af919", "price_changes": [{"asset_id": "78633590736077251574794513664747155551297291244492840448622550955320930591622", "price": "0.549", "size": "9.99", "side": "BUY", "hash": "1a4c1307eac4d8ec2a00bedb23eff59ade34d538", "best_bid": "0.571", "best_ask": "0.572"}, {"asset_id": "40081275558852222228080198821361202017557872256707631666334039001378518619916", "price": "0.451", "size": "9.99", "side": "SELL", "hash": "5ec46c49906dbdd936d967428fef4cc1972a9d36", "best_bid": "0.428", "best_ask": "0.429"}], "timestamp": "1785163594919", "event_type": "price_change"}}
{"ts": 1785163595.057, "kind": "price_change", "data": {"market": "0x18b1c135d0a40c5894da9412e77311827d9caf16cf4cd6591b247a34730af919", "price_changes": [{"asset_id": "40081275558852222228080198821361202017557872256707631666334039001378518619916", "price": "0.41", "size": "2931.23", "side": "BUY", "hash": "5347ac18d2c7253d6aff1deeb685b4e1624c6f3f", "best_bid": "0.428", "best_ask": "0.429"}, {"asset_id": "78633590736077251574794513664747155551297291244492840448622550955320930591622", "price": "0.59", "size": "2931.23", "side": "SELL", "hash": "d4093380f6654088766964c05dce4e1a8f2c4d38", "best_bid": "0.571", "best_ask": "0.572"}], "timestamp": "1785163595057", "event_type": "price_change"}}
{"ts": 1785163595.633, "kind": "price_change", "data": {"market": "0x18b1c135d0a40c5894da9412e77311827d9caf16cf4cd6591b247a34730af919", "price_changes": [{"asset_id": "40081275558852222228080198821361202017557872256707631666334039001378518619916", "price": "0.41", "size": "2947.28", "side": "BUY", "hash": "d36f52c0ebf4c2081014c1f87037366af78eee7f", "best_bid": "0.428", "best_ask": "0.429"}, {"asset_id": "78633590736077251574794513664747155551297291244492840448622550955320930591622", "price": "0.59", "size": "2947.28", "side": "SELL", "hash": "fa9103f79e19b90718ca52854e50111a904e4fa0", "best_bid": "0.571", "best_ask": "0.572"}], "timestamp": "1785163595633", "event_type": "price_change"}}
{"ts": 1785163597.0, "kind": "price_change", "data": {"market": "0x18b1c135d0a40c5894da9412e77311827d9caf16cf4cd6591b247a34730af919", "price_changes": [{"asset_id": "40081275558852222228080198821361202017557872256707631666334039001378518619916", "price": "0.418", "size": "6636.05", "side": "BUY", "hash": "e34a6533f05ad8e3726f57efeb7516deb8b48e4b", "best_bid": "0.428", "best_ask": "0.429"}, {"asset_id": "78633590736077251574794513664747155551297291244492840448622550955320930591622", "price": "0.582", "size": "6636.05", "side": "SELL", "hash": "4f9a4ba396129f9da5afd23ab76005d4b97a2d8f", "best_bid": "0.571", "best_ask": "0.572"}], "timestamp": "1785163597000", "event_type": "price_change"}}
{"ts": 1785163597.38, "kind": "price_change", "data": {"market": "0x0f49db97f71c68b1e42a6d16e3de93d85dbf7d4148e3f018eb79e88554be9f75", "price_changes": [{"asset_id": "87854174148074652060467921081181402357467303721471806610111179101805869578687", "price": "0.001", "size": "6146756.01", "side": "BUY", "hash": "f8956d125f92d6da531830fb3c8a8eeb271470f0", "best_bid": "0.805", "best_ask": "0.806"}, {"asset_id": "54533043819946592547517511176940999955633860128497669742211153063842200957669", "price": "0.999", "size": "6146756.01", "side": "SELL", "hash": "e16c0b8594bf6817ddfb7e832f498b71f7a48cf8", "best_bid": "0.194", "best_ask": "0.195"}], "timestamp": "1785163597380", "event_type": "price_change"}}
{"ts": 1785163597.381, "kind": "price_change", "data": {"market": "0x0f49db97f71c68b1e42a6d16e3de93d85dbf7d4148e3f018eb79e88554be9f75", "price_changes": [{"asset_id": "87854174148074652060467921081181402357467303721471806610111179101805869578687", "price": "0.001", "size": "6147766.01", "side": "BUY", "hash": "91d6c7f92523178c67608e9e1399b9ce9c4bc607", "best_bid": "0.805", "best_ask": "0.806"}, {"asset_id": "54533043819946592547517511176940999955633860128497669742211153063842200957669", "price": "0.999", "size": "6147766.01", "side": "SELL", "hash": "1f976726fe5aefd158cb08d73bc7053c382f01dd", "best_bid": "0.194", "best_ask": "0.195"}], "timestamp": "1785163597381", "event_type": "price_change"}}
{"ts": 1785163598.472, "kind": "price_change", "data": {"market": "0x18b1c135d0a40c5894da9412e77311827d9caf16cf4cd6591b247a34730af919", "price_changes": [{"asset_id": "40081275558852222228080198821361202017557872256707631666334039001378518619916", "price": "0.507", "size": "0", "side": "SELL", "hash": "54877a43b94ce4863e5c96fb6da5976e13d26583", "best_bid": "0.428", "best_ask": "0.429"}, {"asset_id": "78633590736077251574794513664747155551297291244492840448622550955320930591622", "price": "0.493", "size": "0", "side": "BUY", "hash": "aa3989ae356b6034fec5f59d81bcfd31fe137faf", "best_bid": "0.571", "best_ask": "0.572"}], "timestamp": "1785163598472", "event_type": "price_change"}}
{"ts": 1785163599.599, "kind": "price_change", "data": {"market": "0x18b1c135d0a40c5894da9412e77311827d9caf16cf4cd6591b247a34730af919", "price_changes": [{"asset_id": "40081275558852222228080198821361202017557872256707631666334039001378518619916", "price": "0.506", "size": "36.7", "side": "SELL", "hash": "20612ed158e56f7209b450017e70283fb79fb4ec", "best_bid": "0.428", "best_ask": "0.429"}, {"asset_id": "78633590736077251574794513664747155551297291244492840448622550955320930591622", "price": "0.494", "size": "36.7", "side": "BUY", "hash": "c95417ce6db73e2b29cb95beef2edfe7223708ce", "best_bid": "0.571", "best_ask": "0.572"}], "timestamp": "1785163599599", "event_type": "price_change"}}
{"ts": 1785163600.281, "kind": "price_change", "data": {"market": "0x18b1c135d0a40c5894da9412e77311827d9caf16cf4cd6591b247a34730af919", "price_changes": [{"asset_id": "40081275558852222228080198821361202017557872256707631666334039001378518619916", "price": "0.506", "size": "0", "side": "SELL", "hash": "6d2ba62711b6cc2e36f5e7c2099bf5484fe867d7", "best_bid": "0.428", "best_ask": "0.429"}, {"asset_id": "78633590736077251574794513664747155551297291244492840448622550955320930591622", "price": "0.494", "size": "0", "side": "BUY", "hash": "cd52a5f9e2ff8e7b471baa518910dce564afbcdd", "best_bid": "0.571", "best_ask": "0.572"}], "timestamp": "1785163600281", "event_type": "price_change"}}
{"ts": 1785163600.367, "kind": "price_change", "data": {"market": "0x18b1c135d0a40c5894da9412e77311827d9caf16cf4cd6591b247a34730af919", "price_changes": [{"asset_id": "78633590736077251574794513664747155551297291244492840448622550955320930591622", "price": "0.549", "size": "0", "side": "BUY", "hash": "8546a3ff22e5ec37f13cdd92bbaf725dccf1cefd", "best_bid": "0.571", "best_ask": "0.572"}, {"asset_id": "40081275558852222228080198821361202017557872256707631666334039001378518619916", "price": "0.451", "size": "0", "side": "SELL", "hash": "b107f114d36e27fcd88449907d47260b9387eead", "best_bid": "0.428", "best_ask": "0.429"}], "timestamp": "1785163600367", "event_type": "price_change"}}
{"ts": 1785163600.533, "kind": "price_change", "data": {"market": "0x18b1c135d0a40c5894da9412e77311827d9caf16cf4cd6591b247a34730af919", "price_changes": [{"asset_id": "40081275558852222228080198821361202017557872256707631666334039001378518619916", "price": "0.507", "size": "36.7", "side": "SELL", "hash": "48621cac46212faed06739c6493cd8fc3ee87a86", "best_bid": "0.428", "best_ask": "0.429"}, {"asset_id": "78633590736077251574794513664747155551297291244492840448622550955320930591622", "price": "0.493", "size": "36.7", "side": "BUY", "hash": "3e7e716ff852730a2475d4dd0ddf4d65523153c8", "best_bid": "0.571", "best_ask": "0.572"}], "timestamp": "1785163600533", "event_type": "price_change"}}
{"ts": 1785163600.591382, "kind": "orders_out", "data": [{"token_id": "40081275558852222228080198821361202017557872256707631666334039001378518619916", "side": "BUY", "price": 0.387, "size": 7.75}, {"token_id": "78633590736077251574794513664747155551297291244492840448622550955320930591622", "side": "BUY", "price": 0.529, "size": 5.67}]}
{"ts": 1785163602.0, "kind": "price_change", "data": {"market": "0x18b1c135d0a40c5894da9412e77311827d9caf16cf4cd6591b247a34730af919", "price_changes": [{"asset_id": "78633590736077251574794513664747155551297291244492840448622550955320930591622", "price": "0.561", "size": "11634.9", "side": "BUY", "hash": "912c2879255873abeecaed85cb6382ec94822f16", "best_bid": "0.571", "best_ask": "0.572"}, {"asset_id": "40081275558852222228080198821361202017557872256707631666334039001378518619916", "price": "0.439", "size": "11634.9", "side": "SELL", "hash": "135604054193458bfce7c01ff2b0c7d5ee31e039", "best_bid": "0.428", "best_ask": "0.429"}], "timestamp": "1785163602000", "event_type": "price_change"}}
{"ts": 1785163611.625, "kind": "price_change", "data": {"market": "0x18b1c135d0a40c5894da9412e77311827d9caf16cf4cd6591b247a34730af919", "price_changes": [{"asset_id": "40081275558852222228080198821361202017557872256707631666334039001378518619916", "price": "0.41", "size": "2931.23", "side": "BUY", "hash": "2ec75a124e8ad4717b2be129c4304ac9bdd2d502", "best_bid": "0.428", "best_ask": "0.429"}, {"asset_id": "78633590736077251574794513664747155551297291244492840448622550955320930591622", "price": "0.59", "size": "2931.23", "side": "SELL", "hash": "22b498519ba92e8081b18e66a808b81a4d966824", "best_bid": "0.571", "best_ask": "0.572"}], "timestamp": "1785163611625", "event_type": "price_change"}}
{"ts": 1785163611.834, "kind": "price_change", "data": {"market": "0x18b1c135d0a40c5894da9412e77311827d9caf16cf4cd6591b247a34730af919", "price_changes": [{"asset_id": "78633590736077251574794513664747155551297291244492840448622550955320930591622", "price": "0.372", "size": "0", "side": "BUY", "hash": "efb826c4c81948e14192a04c406dfbc3ac47e55f", "best_bid": "0.571", "best_ask": "0.572"}, {"asset_id": "40081275558852222228080198821361202017557872256707631666334039001378518619916", "price": "0.628", "size": "0", "side": "SELL", "hash": "4453b54d24ea15ed909650da486a356a85e5f251", "best_bid": "0.428", "best_ask": "0.429"}], "timestamp": "1785163611834", "event_type": "price_change"}}
{"ts": 1785163611.863, "kind": "price_change", "data": {"market": "0x18b1c135d0a40c5894da9412e77311827d9caf16cf4cd6591b247a34730af919", "price_changes": [{"asset_id": "78633590736077251574794513664747155551297291244492840448622550955320930591622", "price": "0.373", "size": "0", "side": "BUY", "hash": "dccee42f883e569761f7f55c8c4b3a9e00776d32", "best_bid": "0.571", "best_ask": "0.572"}, {"asset_id": "40081275558852222228080198821361202017557872256707631666334039001378518619916", "price": "0.627", "size": "0", "side": "SELL", "hash": "eae90988f6240d424b88964d74bcd90928271ec2", "best_bid": "0.428", "best_ask": "0.429"}], "timestamp": "1785163611863", "event_type": "price_change"}}
{"ts": 1785163611.893, "kind": "price_change", "data": {"market": "0x18b1c135d0a40c5894da9412e77311827d9caf16cf4cd6591b247a34730af919", "price_changes": [{"asset_id": "78633590736077251574794513664747155551297291244492840448622550955320930591622", "price": "0.371", "size": "400", "side": "BUY", "hash": "c3b4d0cf23768714b6a96d41e3eb35606c3a3caf", "best_bid": "0.571", "best_ask": "0.572"}, {"asset_id": "40081275558852222228080198821361202017557872256707631666334039001378518619916", "price": "0.629", "size": "400", "side": "SELL", "hash": "3ada97df8bcfdf1ac276d696097461a33793c6d6", "best_bid": "0.428", "best_ask": "0.429"}], "timestamp": "1785163611893", "event_type": "price_change"}}
{"ts": 1785163612.301, "kind": "price_change", "data": {"market": "0x18b1c135d0a40c5894da9412e77311827d9caf16cf4cd6591b247a34730af919", "price_changes": [{"asset_id": "40081275558852222228080198821361202017557872256707631666334039001378518619916", "price": "0.41", "size": "2947.28", "side": "BUY", "hash": "8c4f17764520d13de2ae93a9f84c3ad47d0f51d4", "best_bid": "0.428", "best_ask": "0.429"}, {"asset_id": "78633590736077251574794513664747155551297291244492840448622550955320930591622", "price": "0.59", "size": "2947.28", "side": "SELL", "hash": "a9f76810d0acbc236f8f781708d9e5bf1222950b", "best_bid": "0.571", "best_ask": "0.572"}], "timestamp": "1785163612301", "event_type": "price_change"}}
{"ts": 1785163612.607465, "kind": "orders_out", "data": [{"token_id": "40081275558852222228080198821361202017557872256707631666334039001378518619916", "side": "BUY", "price": 0.387, "size": 7.75}, {"token_id": "78633590736077251574794513664747155551297291244492840448622550955320930591622", "side": "BUY", "price": 0.529, "size": 5.67}]}
{"ts": 1785163614.636, "kind": "price_change", "data": {"market": "0x18b1c135d0a40c5894da9412e77311827d9caf16cf4cd6591b247a34730af919", "price_changes": [{"asset_id": "78633590736077251574794513664747155551297291244492840448622550955320930591622", "price": "0.374", "size": "48.28", "side": "BUY", "hash": "ca3681ebda3536c0eafaf5de9b739f92be847455", "best_bid": "0.571", "best_ask": "0.572"}, {"asset_id": "40081275558852222228080198821361202017557872256707631666334039001378518619916", "price": "0.626", "size": "48.28", "side": "SELL", "hash": "317ac2fe8ce460bcb5382c17fa53a5153e3203e2", "best_bid": "0.428", "best_ask": "0.429"}], "timestamp": "1785163614636", "event_type": "price_change"}}
{"ts": 1785163618.312, "kind": "price_change", "data": {"market": "0x18b1c135d0a40c5894da9412e77311827d9caf16cf4cd6591b247a34730af919", "price_changes": [{"asset_id": "40081275558852222228080198821361202017557872256707631666334039001378518619916", "price": "0.42", "size": "1816.74", "side": "BUY", "hash": "5c9fb549412feae5b372884aca4f0a4445edb1d6", "best_bid": "0.428", "best_ask": "0.429"}, {"asset_id": "78633590736077251574794513664747155551297291244492840448622550955320930591622", "price": "0.58", "size": "1816.74", "side": "SELL", "hash": "c2000e3f632aa54ffb72805efcdf09ff74e8e7a6", "best_bid": "0.571", "best_ask": "0.572"}], "timestamp": "1785163618312", "event_type": "price_change"}}
{"ts": 1785163618.864, "kind": "price_change", "data": {"market": "0x18b1c135d0a40c5894da9412e77311827d9caf16cf4cd6591b247a34730af919", "price_changes": [{"asset_id": "40081275558852222228080198821361202017557872256707631666334039001378518619916", "price": "0.42", "size": "2216.74", "side": "BUY", "hash": "d610f22a0724dd11ef455db8a4678187ca15bc6e", "best_bid": "0.428", "best_ask": "0.429"}, {"asset_id": "78633590736077251574794513664747155551297291244492840448622550955320930591622", "price": "0.58", "size": "2216.74", "side": "SELL", "hash": "7a901e228959332b34afaa09708bae452ad5eb3d", "best_bid": "0.571", "best_ask": "0.572"}], "timestamp": "1785163618864", "event_type": "price_change"}}
{"ts": 1785163622.89, "kind": "price_change", "data": {"market": "0x18b1c135d0a40c5894da9412e77311827d9caf16cf4cd6591b247a34730af919", "price_changes": [{"asset_id": "40081275558852222228080198821361202017557872256707631666334039001378518619916", "price": "0.418", "size": "6236.05", "side": "BUY", "hash": "4ba8f977c15190fa0cc8fabe516bb117d7d5e173", "best_bid": "0.428", "best_ask": "0.429"}, {"asset_id": "78633590736077251574794513664747155551297291244492840448622550955320930591622", "price": "0.582", "size": "6236.05", "side": "SELL", "hash": "b1a06ddeacb171d00b88ed2121169ad5a0186708", "best_bid": "0.571", "best_ask": "0.572"}], "timestamp": "1785163622890", "event_type": "price_change"}}
{"ts": 1785163622.89, "kind": "price_change", "data": {"market": "0x18b1c135d0a40c5894da9412e77311827d9caf16cf4cd6591b247a34730af919", "price_changes": [{"asset_id": "78633590736077251574794513664747155551297291244492840448622550955320930591622", "price": "0.561", "size": "11234.9", "side": "BUY", "hash": "b1a06ddeacb171d00b88ed2121169ad5a0186708", "best_bid": "0.571", "best_ask": "0.572"}, {"asset_id": "40081275558852222228080198821361202017557872256707631666334039001378518619916", "price": "0.439", "size": "11234.9", "side": "SELL", "hash": "4ba8f977c15190fa0cc8fabe516bb117d7d5e173", "best_bid": "0.428", "best_ask": "0.429"}], "timestamp": "1785163622890", "event_type": "price_change"}}
{"ts": 1785163624.143, "kind": "price_change", "data": {"market": "0x18b1c135d0a40c5894da9412e77311827d9caf16cf4cd6591b247a34730af919", "price_changes": [{"asset_id": "78633590736077251574794513664747155551297291244492840448622550955320930591622", "price": "0.482", "size": "161.09", "side": "BUY", "hash": "6af942819d7fa40e86b5378d9397b0d9ec1d18ae", "best_bid": "0.571", "best_ask": "0.572"}, {"asset_id": "40081275558852222228080198821361202017557872256707631666334039001378518619916", "price": "0.518", "size": "161.09", "side": "SELL", "hash": "242593c2c8a951451398222afe9e34511d55c858", "best_bid": "0.428", "best_ask": "0.429"}], "timestamp": "1785163624143", "event_type": "price_change"}}
{"ts": 1785163624.176, "kind": "price_change", "data": {"market": "0x18b1c135d0a40c5894da9412e77311827d9caf16cf4cd6591b247a34730af919", "price_changes": [{"asset_id": "78633590736077251574794513664747155551297291244492840448622550955320930591622", "price": "0.485", "size": "107", "side": "BUY", "hash": "316a137ab4152fb7a23621171b16e551eace5218", "best_bid": "0.571", "best_ask": "0.572"}, {"asset_id": "40081275558852222228080198821361202017557872256707631666334039001378518619916", "price": "0.515", "size": "107", "side": "SELL", "hash": "77cbb444aab4ffc12baf70944ded124a089e2611", "best_bid": "0.428", "best_ask": "0.429"}], "timestamp": "1785163624176", "event_type": "price_change"}}
{"ts": 1785163624.176, "kind": "price_change", "data": {"market": "0x18b1c135d0a40c5894da9412e77311827d9caf16cf4cd6591b247a34730af919", "price_changes": [{"asset_id": "78633590736077251574794513664747155551297291244492840448622550955320930591622", "price": "0.486", "size": "10", "side": "BUY", "hash": "d185faaffe4446763bb5f8839caf8f3fb58329a3", "best_bid": "0.571", "best_ask": "0.572"}, {"asset_id": "40081275558852222228080198821361202017557872256707631666334039001378518619916", "price": "0.514", "size": "10", "side": "SELL", "hash": "1b6266e699b5dc55a9a9f4f0dd3d6203734054ba", "best_bid": "0.428", "best_ask": "0.429"}], "timestamp": "1785163624176", "event_type": "price_change"}}
{"ts": 1785163624.199, "kind": "price_change", "data": {"market": "0x18b1c135d0a40c5894da9412e77311827d9caf16cf4cd6591b247a34730af919", "price_changes": [{"asset_id": "78633590736077251574794513664747155551297291244492840448622550955320930591622", "price": "0.482", "size": "0", "side": "BUY", "hash": "7d7a0855cf7f9be3606dc465317ef7429cc66cde", "best_bid": "0.571", "best_ask": "0.572"}, {"asset_id": "40081275558852222228080198821361202017557872256707631666334039001378518619916", "price": "0.518", "size": "0", "side": "SELL", "hash": "16256ae2d4af2271173573c7bf03d5235fa3e771", "best_bid": "0.428", "best_ask": "0.429"}], "timestamp": "1785163624199", "event_type": "price_change"}}
{"ts": 1785163624.199, "kind": "price_change", "data": {"market": "0x18b1c135d0a40c5894da9412e77311827d9caf16cf4cd6591b247a34730af919", "price_changes": [{"asset_id": "78633590736077251574794513664747155551297291244492840448622550955320930591622", "price": "0.485", "size": "30", "side": "BUY", "hash": "7d7a0855cf7f9be3606dc465317ef7429cc66cde", "best_bid": "0.571", "best_ask": "0.572"}, {"asset_id": "40081275558852222228080198821361202017557872256707631666334039001378518619916", "price": "0.515", "size": "30", "side": "SELL", "hash": "16256ae2d4af2271173573c7bf03d5235fa3e771", "best_bid": "0.428", "best_ask": "0.429"}], "timestamp": "1785163624199", "event_type": "price_change"}}
{"ts": 1785163624.226, "kind": "price_change", "data": {"market": "0x18b1c135d0a40c5894da9412e77311827d9caf16cf4cd6591b247a34730af919", "price_changes": [{"asset_id": "78633590736077251574794513664747155551297291244492840448622550955320930591622", "price": "0.486", "size": "0", "side": "BUY", "hash": "112d37b517b17641339fa661cf41ecafaae80e03", "best_bid": "0.571", "best_ask": "0.572"}, {"asset_id": "40081275558852222228080198821361202017557872256707631666334039001378518619916", "price": "0.514", "size": "0", "side": "SELL", "hash": "8fd4469538f53845d5ad5e45f30ae4b102b54ecc", "best_bid": "0.428", "best_ask": "0.429"}], "timestamp": "1785163624226", "event_type": "price_change"}}
{"ts": 1785163624.226, "kind": "price_change", "data": {"market": "0x18b1c135d0a40c5894da9412e77311827d9caf16cf4cd6591b247a34730af919", "price_changes": [{"asset_id": "78633590736077251574794513664747155551297291244492840448622550955320930591622", "price": "0.485", "size": "0", "side": "BUY", "hash": "112d37b517b17641339fa661cf41ecafaae80e03", "best_bid": "0.571", "best_ask": "0.572"}, {"asset_id": "40081275558852222228080198821361202017557872256707631666334039001378518619916", "price": "0.515", "size": "0", "side": "SELL", "hash": "8fd4469538f53845d5ad5e45f30ae4b102b54ecc", "best_bid": "0.428", "best_ask": "0.429"}], "timestamp": "1785163624226", "event_type": "price_change"}}
{"ts": 1785163624.254, "kind": "price_change", "data": {"market": "0x18b1c135d0a40c5894da9412e77311827d9caf16cf4cd6591b247a34730af919", "price_changes": [{"asset_id": "78633590736077251574794513664747155551297291244492840448622550955320930591622", "price": "0.482", "size": "10", "side": "BUY", "hash": "96fbeb7553f8f6f2299461105f5ca923acf47c71", "best_bid": "0.571", "best_ask": "0.572"}, {"asset_id": "40081275558852222228080198821361202017557872256707631666334039001378518619916", "price": "0.518", "size": "10", "side": "SELL", "hash": "03f35bb7e3df67521c8ec5aa857bf84e6af099a7", "best_bid": "0.428", "best_ask": "0.429"}], "timestamp": "1785163624254", "event_type": "price_change"}}
{"ts": 1785163624.254, "kind": "price_change", "data": {"market": "0x18b1c135d0a40c5894da9412e77311827d9caf16cf4cd6591b247a34730af919", "price_changes": [{"asset_id": "78633590736077251574794513664747155551297291244492840448622550955320930591622", "price": "0.482", "size": "40", "side": "BUY", "hash": "4f88de55ad45d997c84d0a9d61dfaeaf75969ebd", "best_bid": "0.571", "best_ask": "0.572"}, {"asset_id": "40081275558852222228080198821361202017557872256707631666334039001378518619916", "price": "0.518", "size": "40", "side": "SELL", "hash": "deb8e2e13022500a80ec8021498190b89ec7a8f3", "best_bid": "0.428", "best_ask": "0.429"}], "timestamp": "1785163624254", "event_type": "price_change"}}
{"ts": 1785163625.021, "kind": "price_change", "data": {"market": "0x0f49db97f71c68b1e42a6d16e3de93d85dbf7d4148e3f018eb79e88554be9f75", "price_changes": [{"asset_id": "54533043819946592547517511176940999955633860128497669742211153063842200957669", "price": "0.007", "size": "53571.42", "side": "BUY", "hash": "5f3f3693a1e945c67e13f5c8ea2efcb67736a9a5", "best_bid": "0.194", "best_ask": "0.195"}, {"asset_id": "87854174148074652060467921081181402357467303721471806610111179101805869578687", "price": "0.993", "size": "53571.42", "side": "SELL", "hash": "8c11c3ac3fb670c671575533eb2ca78a1d1312ad", "best_bid": "0.805", "best_ask": "0.806"}], "timestamp": "1785163625021", "event_type": "price_change"}}
{"ts": 1785163625.023, "kind": "price_change", "data": {"market": "0x0f49db97f71c68b1e42a6d16e3de93d85dbf7d4148e3f018eb79e88554be9f75", "price_changes": [{"asset_id": "54533043819946592547517511176940999955633860128497669742211153063842200957669", "price": "0.009", "size": "13888.88", "side": "BUY", "hash": "be3c49df2e6c7fc89a0fae0fff0d6f9af4123edc", "best_bid": "0.194", "best_ask": "0.195"}, {"asset_id": "87854174148074652060467921081181402357467303721471806610111179101805869578687", "price": "0.991", "size": "13888.88", "side": "SELL", "hash": "235144a5a904b66c19947087d56067278c11b6bd", "best_bid": "0.805", "best_ask": "0.806"}], "timestamp": "1785163625023", "event_type": "price_change"}}
{"ts": 1785163625.095, "kind": "price_change", "data": {"market": "0x0f49db97f71c68b1e42a6d16e3de93d85dbf7d4148e3f018eb79e88554be9f75", "price_changes": [{"asset_id": "54533043819946592547517511176940999955633860128497669742211153063842200957669", "price": "0.176", "size": "12220.93", "side": "BUY", "hash": "c70c357c8622893e3978803089704ca339ef2377", "best_bid": "0.194", "best_ask": "0.195"}, {"asset_id": "87854174148074652060467921081181402357467303721471806610111179101805869578687", "price": "0.824", "size": "12220.93", "side": "SELL", "hash": "1ef3d579f09ee983ca93f34891c3cbc5fa1747d7", "best_bid": "0.805", "best_ask": "0.806"}], "timestamp": "1785163625095", "event_type": "price_change"}}
{"ts": 1785163625.3267179, "kind": "orders_out", "data": [{"token_id": "54533043819946592547517511176940999955633860128497669742211153063842200957669", "side": "BUY", "price": 0.153, "size": 19.61}]}
{"ts": 1785163626.627, "kind": "price_change", "data": {"market": "0x0f49db97f71c68b1e42a6d16e3de93d85dbf7d4148e3f018eb79e88554be9f75", "price_changes": [{"asset_id": "54533043819946592547517511176940999955633860128497669742211153063842200957669", "price": "0.174", "size": "3902", "side": "BUY", "hash": "ce6f348d68038820224337eed5e9d190a3f9a92b", "best_bid": "0.194", "best_ask": "0.195"}, {"asset_id": "87854174148074652060467921081181402357467303721471806610111179101805869578687", "price": "0.826", "size": "3902", "side": "SELL", "hash": "7b66fc8b0e6a6c89c93e391bbf57e479e72bb847", "best_bid": "0.805", "best_ask": "0.806"}], "timestamp": "1785163626627", "event_type": "price_change"}}
{"ts": 1785163626.864, "kind": "price_change", "data": {"market": "0x0f49db97f71c68b1e42a6d16e3de93d85dbf7d4148e3f018eb79e88554be9f75", "price_changes": [{"asset_id": "54533043819946592547517511176940999955633860128497669742211153063842200957669", "price": "0.174", "size": "11373", "side": "BUY", "hash": "e068c9bdd7753ac85a543ad9d39bb7ec9389eaec", "best_bid": "0.194", "best_ask": "0.195"}, {"asset_id": "87854174148074652060467921081181402357467303721471806610111179101805869578687", "price": "0.826", "size": "11373", "side": "SELL", "hash": "09a65120a0ac67b0db9a2c76e1f5275be6728356", "best_bid": "0.805", "best_ask": "0.806"}], "timestamp": "1785163626864", "event_type": "price_change"}}
{"ts": 1785163628.885, "kind": "price_change", "data": {"market": "0x18b1c135d0a40c5894da9412e77311827d9caf16cf4cd6591b247a34730af919", "price_changes": [{"asset_id": "40081275558852222228080198821361202017557872256707631666334039001378518619916", "price": "0.507", "size": "0", "side": "SELL", "hash": "8769feec7cf088f2e530a2e9ee876fc4c97c91d0", "best_bid": "0.428", "best_ask": "0.429"}, {"asset_id": "78633590736077251574794513664747155551297291244492840448622550955320930591622", "price": "0.493", "size": "0", "side": "BUY", "hash": "73d36cc6d416a90045d7c76111f20503d3480a70", "best_bid": "0.571", "best_ask": "0.572"}], "timestamp": "1785163628885", "event_type": "price_change"}}
{"ts": 1785163629.0, "kind": "price_change", "data": {"market": "0x18b1c135d0a40c5894da9412e77311827d9caf16cf4cd6591b247a34730af919", "price_changes": [{"asset_id": "78633590736077251574794513664747155551297291244492840448622550955320930591622", "price": "0.02", "size": "750", "side": "BUY", "hash": "9bcd1cbcef05fbea035ac2275c3edcedf0395ae3", "best_bid": "0.571", "best_ask": "0.572"}, {"asset_id": "40081275558852222228080198821361202017557872256707631666334039001378518619916", "price": "0.98", "size": "750", "side": "SELL", "hash": "a44f788f9cf03f3a8637ba41ed147b538b9af18e", "best_bid": "0.428", "best_ask": "0.429"}], "timestamp": "1785163629000", "event_type": "price_change"}}
{"ts": 1785163629.983, "kind": "price_change", "data": {"market": "0x18b1c135d0a40c5894da9412e77311827d9caf16cf4cd6591b247a34730af919", "price_changes": [{"asset_id": "40081275558852222228080198821361202017557872256707631666334039001378518619916", "price": "0.506", "size": "36.7", "side": "SELL", "hash": "d9793b7b6abdc48921a5f260593b6a96985ea08f", "best_bid": "0.428", "best_ask": "0.429"}, {"asset_id": "78633590736077251574794513664747155551297291244492840448622550955320930591622", "price": "0.494", "size": "36.7", "side": "BUY", "hash": "75ad9e764b0ed783d26c197aa3bde1a36f0c067c", "best_bid": "0.571", "best_ask": "0.572"}], "timestamp": "1785163629983", "event_type": "price_change"}}
{"ts": 1785163630.668, "kind": "price_change", "data": {"market": "0x0f49db97f71c68b1e42a6d16e3de93d85dbf7d4148e3f018eb79e88554be9f75", "price_changes": [{"asset_id": "87854174148074652060467921081181402357467303721471806610111179101805869578687", "price": "0.785", "size": "1032", "side": "BUY", "hash": "9292432e116a83c2be0da27dc5a3affb9b48ba6d", "best_bid": "0.805", "best_ask": "0.806"}, {"asset_id": "54533043819946592547517511176940999955633860128497669742211153063842200957669", "price": "0.215", "size": "1032", "side": "SELL", "hash": "ee62c14bb9eecfbbdfe067cda8d2fbe44b294e40", "best_bid": "0.194", "best_ask": "0.195"}], "timestamp": "1785163630668", "event_type": "price_change"}}
{"ts": 1785163630.744, "kind": "price_change", "data": {"market": "0x18b1c135d0a40c5894da9412e77311827d9caf16cf4cd6591b247a34730af919", "price_changes": [{"asset_id": "40081275558852222228080198821361202017557872256707631666334039001378518619916", "price": "0.506", "size": "0", "side": "SELL", "hash": "84b8dec41636d096f7725bbf761e7d9bb28fc0f8", "best_bid": "0.428", "best_ask": "0.429"}, {"asset_id": "78633590736077251574794513664747155551297291244492840448622550955320930591622", "price": "0.494", "size": "0", "side": "BUY", "hash": "7736fb96ce3dbd3d2f42f27b63039046e08c952d", "best_bid": "0.571", "best_ask": "0.572"}], "timestamp": "1785163630744", "event_type": "price_change"}}
{"ts": 1785163630.909, "kind": "price_change", "data": {"market": "0x0f49db97f71c68b1e42a6d16e3de93d85dbf7d4148e3f018eb79e88554be9f75", "price_changes": [{"asset_id": "87854174148074652060467921081181402357467303721471806610111179101805869578687", "price": "0.785", "size": "2688", "side": "BUY", "hash": "356fa319718853436276fa85bd3b4fc80e5f7522", "best_bid": "0.805", "best_ask": "0.806"}, {"asset_id": "54533043819946592547517511176940999955633860128497669742211153063842200957669", "price": "0.215", "size": "2688", "side": "SELL", "hash": "d7fb925258009a9bdb26b3884d81cbcd3dfc3138", "best_bid": "0.194", "best_ask": "0.195"}], "timestamp": "1785163630909", "event_type": "price_change"}}
{"ts": 1785163630.94, "kind": "price_change", "data": {"market": "0x0f49db97f71c68b1e42a6d16e3de93d85dbf7d4148e3f018eb79e88554be9f75", "price_changes": [{"asset_id": "54533043819946592547517511176940999955633860128497669742211153063842200957669", "price": "0.009", "size": "0", "side": "BUY", "hash": "00d871d161123a1e1936defa7684b2bc050686ff", "best_bid": "0.194", "best_ask": "0.195"}, {"asset_id": "87854174148074652060467921081181402357467303721471806610111179101805869578687", "price": "0.991", "size": "0", "side": "SELL", "hash": "30e2641f86314af0a9a14abd74d700250e87492a", "best_bid": "0.805", "best_ask": "0.806"}], "timestamp": "1785163630940", "event_type": "price_change"}}
{"ts": 1785163630.94, "kind": "price_change", "data": {"market": "0x0f49db97f71c68b1e42a6d16e3de93d85dbf7d4148e3f018eb79e88554be9f75", "price_changes": [{"asset_id": "54533043819946592547517511176940999955633860128497669742211153063842200957669", "price": "0.007", "size": "0", "side": "BUY", "hash": "00d871d161123a1e1936defa7684b2bc050686ff", "best_bid": "0.194", "best_ask": "0.195"}, {"asset_id": "87854174148074652060467921081181402357467303721471806610111179101805869578687", "price": "0.993", "size": "0", "side": "SELL", "hash": "30e2641f86314af0a9a14abd74d700250e87492a", "best_bid": "0.805", "best_ask": "0.806"}], "timestamp": "1785163630940", "event_type": "price_change"}}
{"ts": 1785163631.022, "kind": "price_change", "data": {"market": "0x0f49db97f71c68b1e42a6d16e3de93d85dbf7d4148e3f018eb79e88554be9f75", "price_changes": [{"asset_id": "54533043819946592547517511176940999955633860128497669742211153063842200957669", "price": "0.176", "size": "12210.93", "side": "BUY", "hash": "80f421b52d363415d240d9e59eba4880b2941cb0", "best_bid": "0.194", "best_ask": "0.195"}, {"asset_id": "87854174148074652060467921081181402357467303721471806610111179101805869578687", "price": "0.824", "size": "12210.93", "side": "SELL", "hash": "735eb165c0fa81d2d20ec841c5cdd141fb3ff6b4", "best_bid": "0.805", "best_ask": "0.806"}], "timestamp": "1785163631022", "event_type": "price_change"}}
{"ts": 1785163631.115, "kind": "price_change", "data": {"market": "0x18b1c135d0a40c5894da9412e77311827d9caf16cf4cd6591b247a34730af919", "price_changes": [{"asset_id": "40081275558852222228080198821361202017557872256707631666334039001378518619916", "price": "0.507", "size": "36.7", "side": "SELL", "hash": "567863b1a8bfea1b0e93c0f2fc7e3cdf0927c0e1", "best_bid": "0.428", "best_ask": "0.429"}, {"asset_id": "78633590736077251574794513664747155551297291244492840448622550955320930591622", "price": "0.493", "size": "36.7", "side": "BUY", "hash": "5ac375ae27212162c418378c82eb484dec137d3d", "best_bid": "0.571", "best_ask": "0.572"}], "timestamp": "1785163631115", "event_type": "price_change"}}
{"ts": 1785163631.591, "kind": "price_change", "data": {"market": "0x18b1c135d0a40c5894da9412e77311827d9caf16cf4cd6591b247a34730af919", "price_changes": [{"asset_id": "40081275558852222228080198821361202017557872256707631666334039001378518619916", "price": "0.41", "size": "2931.23", "side": "BUY", "hash": "956adfc8d9730e018baf0c446fa3c31117ba61f8", "best_bid": "0.428", "best_ask": "0.429"}, {"asset_id": "78633590736077251574794513664747155551297291244492840448622550955320930591622", "price": "0.59", "size": "2931.23", "side": "SELL", "hash": "718a84afc795db8237b6d48065004eecf5d22788", "best_bid": "0.571", "best_ask": "0.572"}], "timestamp": "1785163631591", "event_type": "price_change"}}
{"ts": 1785163631.852, "kind": "price_change", "data": {"market": "0x18b1c135d0a40c5894da9412e77311827d9caf16cf4cd6591b247a34730af919", "price_changes": [{"asset_id": "40081275558852222228080198821361202017557872256707631666334039001378518619916", "price": "0.418", "size": "6636.05", "side": "BUY", "hash": "aad952b384c3680063763333bfc41f9044bf32bc", "best_bid": "0.428", "best_ask": "0.429"}, {"asset_id": "78633590736077251574794513664747155551297291244492840448622550955320930591622", "price": "0.582", "size": "6636.05", "side": "SELL", "hash": "116285c9789030ccfcbe5db27565863670b0528c", "best_bid": "0.571", "best_ask": "0.572"}], "timestamp": "1785163631852", "event_type": "price_change"}}
{"ts": 1785163631.853, "kind": "price_change", "data": {"market": "0x18b1c135d0a40c5894da9412e77311827d9caf16cf4cd6591b247a34730af919", "price_changes": [{"asset_id": "78633590736077251574794513664747155551297291244492840448622550955320930591622", "price": "0.561", "size": "11634.9", "side": "BUY", "hash": "96dd842d91db01f8e5ff3a99b75a9e8206353a9c", "best_bid": "0.571", "best_ask": "0.572"}, {"asset_id": "40081275558852222228080198821361202017557872256707631666334039001378518619916", "price": "0.439", "size": "11634.9", "side": "SELL", "hash": "187fcff3d0dec2307a95502de9c3c7a8663700c2", "best_bid": "0.428", "best_ask": "0.429"}], "timestamp": "1785163631853", "event_type": "price_change"}}
{"ts": 1785163632.235, "kind": "price_change", "data": {"market": "0x18b1c135d0a40c5894da9412e77311827d9caf16cf4cd6591b247a34730af919", "price_changes": [{"asset_id": "40081275558852222228080198821361202017557872256707631666334039001378518619916", "price": "0.41", "size": "2947.28", "side": "BUY", "hash": "c4c2c3adc4f610a73c91c4fa948fad32ad406e7d", "best_bid": "0.428", "best_ask": "0.429"}, {"asset_id": "78633590736077251574794513664747155551297291244492840448622550955320930591622", "price": "0.59", "size": "2947.28", "side": "SELL", "hash": "f6b45b9c467b28fbad1b214a32fe031c6f7383d3", "best_bid": "0.571", "best_ask": "0.572"}], "timestamp": "1785163632235", "event_type": "price_change"}}
{"ts": 1785163636.061, "kind": "price_change", "data": {"market": "0x0f49db97f71c68b1e42a6d16e3de93d85dbf7d4148e3f018eb79e88554be9f75", "price_changes": [{"asset_id": "87854174148074652060467921081181402357467303721471806610111179101805869578687", "price": "0.795", "size": "2890.98", "side": "BUY", "hash": "c254d64b9c25bd282092da9df459ee901178609c", "best_bid": "0.805", "best_ask": "0.806"}, {"asset_id": "54533043819946592547517511176940999955633860128497669742211153063842200957669", "price": "0.205", "size": "2890.98", "side": "SELL", "hash": "2828a37e32c1221bd3f23d8cd4e316da11b0d0c7", "best_bid": "0.194", "best_ask": "0.195"}], "timestamp": "1785163636061", "event_type": "price_change"}}
{"ts": 1785163636.15, "kind": "price_change", "data": {"market": "0x0f49db97f71c68b1e42a6d16e3de93d85dbf7d4148e3f018eb79e88554be9f75", "price_changes": [{"asset_id": "87854174148074652060467921081181402357467303721471806610111179101805869578687", "price": "0.795", "size": "3457.98", "side": "BUY", "hash": "391829b064ae672f710ec3c9d6a3e5f1844b98ef", "best_bid": "0.805", "best_ask": "0.806"}, {"asset_id": "54533043819946592547517511176940999955633860128497669742211153063842200957669", "price": "0.205", "size": "3457.98", "side": "SELL", "hash": "c99862d51596e4cc135f8087242d37a2882787ea", "best_bid": "0.194", "best_ask": "0.195"}], "timestamp": "1785163636150", "event_type": "price_change"}}
{"ts": 1785163636.686, "kind": "price_change", "data": {"market": "0x18b1c135d0a40c5894da9412e77311827d9caf16cf4cd6591b247a34730af919", "price_changes": [{"asset_id": "40081275558852222228080198821361202017557872256707631666334039001378518619916", "price": "0.418", "size": "5558.05", "side": "BUY", "hash": "a9a287e4ecbe588f00d0344f0237af1ab62e392d", "best_bid": "0.428", "best_ask": "0.429"}, {"asset_id": "78633590736077251574794513664747155551297291244492840448622550955320930591622", "price": "0.582", "size": "5558.05", "side": "SELL", "hash": "aa4c02153a2a37acb2e99be2a704b05b38260318", "best_bid": "0.571", "best_ask": "0.572"}], "timestamp": "1785163636686", "event_type": "price_change"}}
{"ts": 1785163636.715, "kind": "price_change", "data": {"market": "0x18b1c135d0a40c5894da9412e77311827d9caf16cf4cd6591b247a34730af919", "price_changes": [{"asset_id": "40081275558852222228080198821361202017557872256707631666334039001378518619916", "price": "0.418", "size": "5358.05", "side": "BUY", "hash": "ae986c206a4a84282da40e3d0980135665c42051", "best_bid": "0.428", "best_ask": "0.429"}, {"asset_id": "78633590736077251574794513664747155551297291244492840448622550955320930591622", "price": "0.582", "size": "5358.05", "side": "SELL", "hash": "bd1e66106e94abe3030180c68b5031bd3a1d582a", "best_bid": "0.571", "best_ask": "0.572"}], "timestamp": "1785163636715", "event_type": "price_change"}}
{"ts": 1785163636.747, "kind": "price_change", "data": {"market": "0x18b1c135d0a40c5894da9412e77311827d9caf16cf4cd6591b247a34730af919", "price_changes": [{"asset_id": "40081275558852222228080198821361202017557872256707631666334039001378518619916", "price": "0.417", "size": "1200", "side": "BUY", "hash": "d9ac493a7125672e876ce04aa9a2404216d67c46", "best_bid": "0.428", "best_ask": "0.429"}, {"asset_id": "78633590736077251574794513664747155551297291244492840448622550955320930591622", "price": "0.583", "size": "1200", "side": "SELL", "hash": "2e57c898a279b0312f92e76a729288bd1b2a91c8", "best_bid": "0.571", "best_ask": "0.572"}], "timestamp": "1785163636747", "event_type": "price_change"}}
{"ts": 1785163636.779, "kind": "price_change", "data": {"market": "0x18b1c135d0a40c5894da9412e77311827d9caf16cf4cd6591b247a34730af919", "price_changes": [{"asset_id": "40081275558852222228080198821361202017557872256707631666334039001378518619916", "price": "0.418", "size": "6436.05", "side": "BUY", "hash": "84d8f508015b7ba2eca2a1f60bf8b0d160ac8435", "best_bid": "0.428", "best_ask": "0.429"}, {"asset_id": "78633590736077251574794513664747155551297291244492840448622550955320930591622", "price": "0.582", "size": "6436.05", "side": "SELL", "hash": "789eddbf7796c1010135b9e265839525a63e0606", "best_bid": "0.571", "best_ask": "0.572"}], "timestamp": "1785163636779", "event_type": "price_change"}}
{"ts": 1785163636.815, "kind": "price_change", "data": {"market": "0x18b1c135d0a40c5894da9412e77311827d9caf16cf4cd6591b247a34730af919", "price_changes": [{"asset_id": "40081275558852222228080198821361202017557872256707631666334039001378518619916", "price": "0.417", "size": "1000", "side": "BUY", "hash": "c895013cb0bc89e2be610b5adae331f6a1f3c5bd", "best_bid": "0.428", "best_ask": "0.429"}, {"asset_id": "78633590736077251574794513664747155551297291244492840448622550955320930591622", "price": "0.583", "size": "1000", "side": "SELL", "hash": "1fda96c42538ed11ee50d4d17b85d035e3a68d37", "best_bid": "0.571", "best_ask": "0.572"}], "timestamp": "1785163636815", "event_type": "price_change"}}
{"ts": 1785163636.845, "kind": "price_change", "data": {"market": "0x18b1c135d0a40c5894da9412e77311827d9caf16cf4cd6591b247a34730af919", "price_changes": [{"asset_id": "40081275558852222228080198821361202017557872256707631666334039001378518619916", "price": "0.418", "size": "6636.05", "side": "BUY", "hash": "c9da096ed38cbe60777962415712911afb7b62c3", "best_bid": "0.428", "best_ask": "0.429"}, {"asset_id": "78633590736077251574794513664747155551297291244492840448622550955320930591622", "price": "0.582", "size": "6636.05", "side": "SELL", "hash": "2026cfb0c7a0f471743d2205dc13986d409ed9fb", "best_bid": "0.571", "best_ask": "0.572"}], "timestamp": "1785163636845", "event_type": "price_change"}}
{"ts": 1785163636.922, "kind": "price_change", "data": {"market": "0x18b1c135d0a40c5894da9412e77311827d9caf16cf4cd6591b247a34730af919", "price_changes": [{"asset_id": "78633590736077251574794513664747155551297291244492840448622550955320930591622", "price": "0.549", "size": "9.99", "side": "BUY", "hash": "2e0748342cc37b3a4e3da8e9e46d44b10933b2dc", "best_bid": "0.571", "best_ask": "0.572"}, {"asset_id": "40081275558852222228080198821361202017557872256707631666334039001378518619916", "price": "0.451", "size": "9.99", "side": "SELL", "hash": "0e0382c80b430b33f20fec1ac6cfb67eab160f63", "best_bid": "0.428", "best_ask": "0.429"}], "timestamp": "1785163636922", "event_type": "price_change"}}
{"ts": 1785163636.991061, "kind": "orders_out", "data": [{"token_id": "40081275558852222228080198821361202017557872256707631666334039001378518619916", "side": "BUY", "price": 0.387, "size": 7.75}, {"token_id": "78633590736077251574794513664747155551297291244492840448622550955320930591622", "side": "BUY", "price": 0.529, "size": 5.67}]}
{"ts": 1785163637.001, "kind": "price_change", "data": {"market": "0x18b1c135d0a40c5894da9412e77311827d9caf16cf4cd6591b247a34730af919", "price_changes": [{"asset_id": "78633590736077251574794513664747155551297291244492840448622550955320930591622", "price": "0.08", "size": "15000", "side": "BUY", "hash": "09f685f78047a58d62f3402107ae8cf6e80b7244", "best_bid": "0.571", "best_ask": "0.572"}, {"asset_id": "40081275558852222228080198821361202017557872256707631666334039001378518619916", "price": "0.92", "size": "15000", "side": "SELL", "hash": "107066f616c514c5d8603524201d6795fba633b9", "best_bid": "0.428", "best_ask": "0.429"}], "timestamp": "1785163637001", "event_type": "price_change"}}
{"ts": 1785163641.321, "kind": "price_change", "data": {"market": "0x18b1c135d0a40c5894da9412e77311827d9caf16cf4cd6591b247a34730af919", "price_changes": [{"asset_id": "78633590736077251574794513664747155551297291244492840448622550955320930591622", "price": "0.02", "size": "75750", "side": "BUY", "hash": "22db232aefd22fcf02a719787a257833fd19ea4c", "best_bid": "0.571", "best_ask": "0.572"}, {"asset_id": "40081275558852222228080198821361202017557872256707631666334039001378518619916", "price": "0.98", "size": "75750", "side": "SELL", "hash": "390067470d7bd077ff14404c0dc45e3bc9aa828a", "best_bid": "0.428", "best_ask": "0.429"}], "timestamp": "1785163641321", "event_type": "price_change"}}
{"ts": 1785163643.003, "kind": "price_change", "data": {"market": "0x0f49db97f71c68b1e42a6d16e3de93d85dbf7d4148e3f018eb79e88554be9f75", "price_changes": [{"asset_id": "87854174148074652060467921081181402357467303721471806610111179101805869578687", "price": "0.64", "size": "0", "side": "BUY", "hash": "7ad697a8223cf15a0ff5fafce28e1b6e6c93cdd0", "best_bid": "0.805", "best_ask": "0.806"}, {"asset_id": "54533043819946592547517511176940999955633860128497669742211153063842200957669", "price": "0.36", "size": "0", "side": "SELL", "hash": "953636a69fcef7f8cbcb19c1a0db154dcada6e45", "best_bid": "0.194", "best_ask": "0.195"}], "timestamp": "1785163643003", "event_type": "price_change"}}
{"ts": 1785163644.594, "kind": "price_change", "data": {"market": "0x0f49db97f71c68b1e42a6d16e3de93d85dbf7d4148e3f018eb79e88554be9f75", "price_changes": [{"asset_id": "54533043819946592547517511176940999955633860128497669742211153063842200957669", "price": "0.04", "size": "4050", "side": "BUY", "hash": "d6f83f5cbae4e5e37df36f37e840dca61284ce58", "best_bid": "0.194", "best_ask": "0.195"}, {"asset_id": "87854174148074652060467921081181402357467303721471806610111179101805869578687", "price": "0.96", "size": "4050", "side": "SELL", "hash": "04c676d5e053543ea661375254fda195cc8b4087", "best_bid": "0.805", "best_ask": "0.806"}], "timestamp": "1785163644594", "event_type": "price_change"}}
{"ts": 1785163645.285, "kind": "price_change", "data": {"market": "0x0f49db97f71c68b1e42a6d16e3de93d85dbf7d4148e3f018eb79e88554be9f75", "price_changes": [{"asset_id": "87854174148074652060467921081181402357467303721471806610111179101805869578687", "price": "0.795", "size": "2891.98", "side": "BUY", "hash": "94fb8e9561fbe7bde3398e451efdef0add22e8cc", "best_bid": "0.805", "best_ask": "0.806"}, {"asset_id": "54533043819946592547517511176940999955633860128497669742211153063842200957669", "price": "0.205", "size": "2891.98", "side": "SELL", "hash": "e1624b5c7b42dcbc0a91ad97b00584a158975fe9", "best_bid": "0.194", "best_ask": "0.195"}], "timestamp": "1785163645285", "event_type": "price_change"}}
{"ts": 1785163645.362, "kind": "price_change", "data": {"market": "0x0f49db97f71c68b1e42a6d16e3de93d85dbf7d4148e3f018eb79e88554be9f75", "price_changes": [{"asset_id": "87854174148074652060467921081181402357467303721471806610111179101805869578687", "price": "0.795", "size": "3457.98", "side": "BUY", "hash": "7b7595c7682d68c1a2e3e23992ac38cdb4a0e5ca", "best_bid": "0.805", "best_ask": "0.806"}, {"asset_id": "54533043819946592547517511176940999955633860128497669742211153063842200957669", "price": "0.205", "size": "3457.98", "side": "SELL", "hash": "751c690a9190094d924ad386cf0e6f27c848ba92", "best_bid": "0.194", "best_ask": "0.195"}], "timestamp": "1785163645362", "event_type": "price_change"}}
{"ts": 1785163645.667, "kind": "price_change", "data": {"market": "0x18b1c135d0a40c5894da9412e77311827d9caf16cf4cd6591b247a34730af919", "price_changes": [{"asset_id": "40081275558852222228080198821361202017557872256707631666334039001378518619916", "price": "0.05", "size": "20000", "side": "BUY", "hash": "a30cc468fe724f4fb71b6dddcfcb1654de30c95c", "best_bid": "0.428", "best_ask": "0.429"}, {"asset_id": "78633590736077251574794513664747155551297291244492840448622550955320930591622", "price": "0.95", "size": "20000", "side": "SELL", "hash": "12e39099382285cd613ce9b3abbf7eee3b84ac54", "best_bid": "0.571", "best_ask": "0.572"}], "timestamp": "1785163645667", "event_type": "price_change"}}
{"ts": 1785163645.811, "kind": "price_change", "data": {"market": "0x18b1c135d0a40c5894da9412e77311827d9caf16cf4cd6591b247a34730af919", "price_changes": [{"asset_id": "40081275558852222228080198821361202017557872256707631666334039001378518619916", "price": "0.418", "size": "5560.05", "side": "BUY", "hash": "bbad128c1683ae6c6e9b7aa4e30721de82b3d163", "best_bid": "0.428", "best_ask": "0.429"}, {"asset_id": "78633590736077251574794513664747155551297291244492840448622550955320930591622", "price": "0.582", "size": "5560.05", "side": "SELL", "hash": "4ee36c5dd75b43e209488d55b2da11ec47430599", "best_bid": "0.571", "best_ask": "0.572"}], "timestamp": "1785163645811", "event_type": "price_change"}}
{"ts": 1785163645.848, "kind": "price_change", "data": {"market": "0x18b1c135d0a40c5894da9412e77311827d9caf16cf4cd6591b247a34730af919", "price_changes": [{"asset_id": "40081275558852222228080198821361202017557872256707631666334039001378518619916", "price": "0.418", "size": "5360.05", "side": "BUY", "hash": "dab6641c53dd99a77eee99c377c65785fc1e1674", "best_bid": "0.428", "best_ask": "0.429"}, {"asset_id": "78633590736077251574794513664747155551297291244492840448622550955320930591622", "price": "0.582", "size": "5360.05", "side": "SELL", "hash": "76773fa42482c0335ce5272eb31e32f0ec0d1eff", "best_bid": "0.571", "best_ask": "0.572"}], "timestamp": "1785163645848", "event_type": "price_change"}}
{"ts": 1785163645.878, "kind": "price_change", "data": {"market": "0x18b1c135d0a40c5894da9412e77311827d9caf16cf4cd6591b247a34730af919", "price_changes": [{"asset_id": "40081275558852222228080198821361202017557872256707631666334039001378518619916", "price": "0.418", "size": "6436.05", "side": "BUY", "hash": "4939b9ac960496984a7a64e8532fe025952f3fe8", "best_bid": "0.428", "best_ask": "0.429"}, {"asset_id": "78633590736077251574794513664747155551297291244492840448622550955320930591622", "price": "0.582", "size": "6436.05", "side": "SELL", "hash": "48ef715d37e042f7e969223074e5050f1acccda7", "best_bid": "0.571", "best_ask": "0.572"}], "timestamp": "1785163645878", "event_type": "price_change"}}
{"ts": 1785163645.881, "kind": "price_change", "data": {"market": "0x18b1c135d0a40c5894da9412e77311827d9caf16cf4cd6591b247a34730af919", "price_changes": [{"asset_id": "40081275558852222228080198821361202017557872256707631666334039001378518619916", "price": "0.417", "size": "1200", "side": "BUY", "hash": "e2af3b0da15a21bb81522dec518c70747b0114c9", "best_bid": "0.428", "best_ask": "0.429"}, {"asset_id": "78633590736077251574794513664747155551297291244492840448622550955320930591622", "price": "0.583", "size": "1200", "side": "SELL", "hash": "092a8a56f271c2bfccc40e5fa5cfc05e8fcdbb85", "best_bid": "0.571", "best_ask": "0.572"}], "timestamp": "1785163645881", "event_type": "price_change"}}
{"ts": 1785163645.914, "kind": "price_change", "data": {"market": "0x18b1c135d0a40c5894da9412e77311827d9caf16cf4cd6591b247a34730af919", "price_changes": [{"asset_id": "40081275558852222228080198821361202017557872256707631666334039001378518619916", "price": "0.417", "size": "1000", "side": "BUY", "hash": "2f3d607c7fad18ce04a1f9b483877c3baf557ab2", "best_bid": "0.428", "best_ask": "0.429"}, {"asset_id": "78633590736077251574794513664747155551297291244492840448622550955320930591622", "price": "0.583", "size": "1000", "side": "SELL", "hash": "67baea9497d6b56f6e16559512afe3c1eebc690a", "best_bid": "0.571", "best_ask": "0.572"}], "timestamp": "1785163645914", "event_type": "price_change"}}
{"ts": 1785163645.952, "kind": "price_change", "data": {"market": "0x18b1c135d0a40c5894da9412e77311827d9caf16cf4cd6591b247a34730af919", "price_changes": [{"asset_id": "40081275558852222228080198821361202017557872256707631666334039001378518619916", "price": "0.418", "size": "6636.05", "side": "BUY", "hash": "8d770c559abba0adba2144ac90b9ababd3aa5536", "best_bid": "0.428", "best_ask": "0.429"}, {"asset_id": "78633590736077251574794513664747155551297291244492840448622550955320930591622", "price": "0.582", "size": "6636.05", "side": "SELL", "hash": "d75b0f2a69cbe689c716b963e927a9c5ddaf19c3", "best_bid": "0.571", "best_ask": "0.572"}], "timestamp": "1785163645952", "event_type": "price_change"}}
{"ts": 1785163648.216, "kind": "price_change", "data": {"market": "0x18b1c135d0a40c5894da9412e77311827d9caf16cf4cd6591b247a34730af919", "price_changes": [{"asset_id": "40081275558852222228080198821361202017557872256707631666334039001378518619916", "price": "0.41", "size": "2931.23", "side": "BUY", "hash": "72e6f02737fa706549ba1ded6a5bcb0b339aba29", "best_bid": "0.428", "best_ask": "0.429"}, {"asset_id": "78633590736077251574794513664747155551297291244492840448622550955320930591622", "price": "0.59", "size": "2931.23", "side": "SELL", "hash": "c857b66d9c021f95c54306f91f8be0dc651fac75", "best_bid": "0.571", "best_ask": "0.572"}], "timestamp": "1785163648216", "event_type": "price_change"}}
{"ts": 1785163648.806, "kind": "price_change", "data": {"market": "0x18b1c135d0a40c5894da9412e77311827d9caf16cf4cd6591b247a34730af919", "price_changes": [{"asset_id": "40081275558852222228080198821361202017557872256707631666334039001378518619916", "price": "0.41", "size": "2947.28", "side": "BUY", "hash": "8e8be859a15d981ad8531ddf562691472b8de7fb", "best_bid": "0.428", "best_ask": "0.429"}, {"asset_id": "78633590736077251574794513664747155551297291244492840448622550955320930591622", "price": "0.59", "size": "2947.28", "side": "SELL", "hash": "1afc5dc8de19fb5663dbc051e96f9de42c128ac6", "best_bid": "0.571", "best_ask": "0.572"}], "timestamp": "1785163648806", "event_type": "price_change"}}
{"ts": 1785163654.268, "kind": "price_change", "data": {"market": "0x18b1c135d0a40c5894da9412e77311827d9caf16cf4cd6591b247a34730af919", "price_changes": [{"asset_id": "78633590736077251574794513664747155551297291244492840448622550955320930591622", "price": "0.485", "size": "77", "side": "BUY", "hash": "6bc9e4e99f20d93347cd815693503b156eef55f3", "best_bid": "0.571", "best_ask": "0.572"}, {"asset_id": "40081275558852222228080198821361202017557872256707631666334039001378518619916", "price": "0.515", "size": "77", "side": "SELL", "hash": "10c94ca58144034a050d830b0bce75424d8bcd62", "best_bid": "0.428", "best_ask": "0.429"}], "timestamp": "1785163654268", "event_type": "price_change"}}
{"ts": 1785163654.27, "kind": "price_change", "data": {"market": "0x18b1c135d0a40c5894da9412e77311827d9caf16cf4cd6591b247a34730af919", "price_changes": [{"asset_id": "78633590736077251574794513664747155551297291244492840448622550955320930591622", "price": "0.482", "size": "201.09", "side": "BUY", "hash": "19d4d1702be547caa4ab0b085d438f2b2428a222", "best_bid": "0.571", "best_ask": "0.572"}, {"asset_id": "40081275558852222228080198821361202017557872256707631666334039001378518619916", "price": "0.518", "size": "201.09", "side": "SELL", "hash": "c1f1f6b96877c1faaf9b2fcd7f648f9db6fe6992", "best_bid": "0.428", "best_ask": "0.429"}], "timestamp": "1785163654270", "event_type": "price_change"}}
{"ts": 1785163657.383, "kind": "price_change", "data": {"market": "0x0f49db97f71c68b1e42a6d16e3de93d85dbf7d4148e3f018eb79e88554be9f75", "price_changes": [{"asset_id": "87854174148074652060467921081181402357467303721471806610111179101805869578687", "price": "0.001", "size": "6148776.01", "side": "BUY", "hash": "305d3e9add082048f67295501746954a7eec7b6f", "best_bid": "0.805", "best_ask": "0.806"}, {"asset_id": "54533043819946592547517511176940999955633860128497669742211153063842200957669", "price": "0.999", "size": "6148776.01", "side": "SELL", "hash": "2d47857ae2ca4be0341423f15fc5251f83665f41", "best_bid": "0.194", "best_ask": "0.195"}], "timestamp": "1785163657383", "event_type": "price_change"}}
{"ts": 1785163657.388, "kind": "price_change", "data": {"market": "0x0f49db97f71c68b1e42a6d16e3de93d85dbf7d4148e3f018eb79e88554be9f75", "price_changes": [{"asset_id": "87854174148074652060467921081181402357467303721471806610111179101805869578687", "price": "0.001", "size": "6147766.01", "side": "BUY", "hash": "fd0e94fdfcedd6a6878cbf108177fb9c379b9cc9", "best_bid": "0.805", "best_ask": "0.806"}, {"asset_id": "54533043819946592547517511176940999955633860128497669742211153063842200957669", "price": "0.999", "size": "6147766.01", "side": "SELL", "hash": "bad92ac266ce8a22d526d917a5431a2ba252c4b7", "best_bid": "0.194", "best_ask": "0.195"}], "timestamp": "1785163657388", "event_type": "price_change"}}
{"ts": 1785163658.001, "kind": "price_change", "data": {"market": "0x0f49db97f71c68b1e42a6d16e3de93d85dbf7d4148e3f018eb79e88554be9f75", "price_changes": [{"asset_id": "87854174148074652060467921081181402357467303721471806610111179101805869578687", "price": "0.004", "size": "0", "side": "BUY", "hash": "c2fe271b747f24a7ed0a1bbb8dc728b64a0c7f65", "best_bid": "0.805", "best_ask": "0.806"}, {"asset_id": "54533043819946592547517511176940999955633860128497669742211153063842200957669", "price": "0.996", "size": "0", "side": "SELL", "hash": "d076c79443d97201e41b966082663662351c8a4c", "best_bid": "0.194", "best_ask": "0.195"}], "timestamp": "1785163658001", "event_type": "price_change"}}
{"ts": 1785163659.403, "kind": "price_change", "data": {"market": "0x18b1c135d0a40c5894da9412e77311827d9caf16cf4cd6591b247a34730af919", "price_changes": [{"asset_id": "40081275558852222228080198821361202017557872256707631666334039001378518619916", "price": "0.507", "size": "0", "side": "SELL", "hash": "c354ddda86315359bf7f89216a78a7b76136117b", "best_bid": "0.428", "best_ask": "0.429"}, {"asset_id": "78633590736077251574794513664747155551297291244492840448622550955320930591622", "price": "0.493", "size": "0", "side": "BUY", "hash": "04f47d80b04d33469fe73c6da8f893601553ad79", "best_bid": "0.571", "best_ask": "0.572"}], "timestamp": "1785163659403", "event_type": "price_change"}}
{"ts": 1785163660.385, "kind": "price_change", "data": {"market": "0x18b1c135d0a40c5894da9412e77311827d9caf16cf4cd6591b247a34730af919", "price_changes": [{"asset_id": "40081275558852222228080198821361202017557872256707631666334039001378518619916", "price": "0.506", "size": "36.7", "side": "SELL", "hash": "9f72074c254cf09d1c96d44716b84080ab178e03", "best_bid": "0.428", "best_ask": "0.429"}, {"asset_id": "78633590736077251574794513664747155551297291244492840448622550955320930591622", "price": "0.494", "size": "36.7", "side": "BUY", "hash": "743260ca1ddf55eed7fe84e47e8f143ddfb08068", "best_bid": "0.571", "best_ask": "0.572"}], "timestamp": "1785163660385", "event_type": "price_change"}}
{"ts": 1785163661.463, "kind": "price_change", "data": {"market": "0x18b1c135d0a40c5894da9412e77311827d9caf16cf4cd6591b247a34730af919", "price_changes": [{"asset_id": "40081275558852222228080198821361202017557872256707631666334039001378518619916", "price": "0.506", "size": "0", "side": "SELL", "hash": "ac957d6aaf27c3d0813a19f406543b0331807efe", "best_bid": "0.428", "best_ask": "0.429"}, {"asset_id": "78633590736077251574794513664747155551297291244492840448622550955320930591622", "price": "0.494", "size": "0", "side": "BUY", "hash": "6adcd1f450b79b83f5628cb258c5d4d5aefd24e1", "best_bid": "0.571", "best_ask": "0.572"}], "timestamp": "1785163661463", "event_type": "price_change"}}
{"ts": 1785163661.795, "kind": "price_change", "data": {"market": "0x18b1c135d0a40c5894da9412e77311827d9caf16cf4cd6591b247a34730af919", "price_changes": [{"asset_id": "40081275558852222228080198821361202017557872256707631666334039001378518619916", "price": "0.507", "size": "36.7", "side": "SELL", "hash": "56952d74adb68d4bc30b2c603db1717d6deb6087", "best_bid": "0.428", "best_ask": "0.429"}, {"asset_id": "78633590736077251574794513664747155551297291244492840448622550955320930591622", "price": "0.493", "size": "36.7", "side": "BUY", "hash": "d7855ce513635a73e740003ecb2a5dd4f81ec64a", "best_bid": "0.571", "best_ask": "0.572"}], "timestamp": "1785163661795", "event_type": "price_change"}}
{"ts": 1785163666.902, "kind": "price_change", "data": {"market": "0x0f49db97f71c68b1e42a6d16e3de93d85dbf7d4148e3f018eb79e88554be9f75", "price_changes": [{"asset_id": "87854174148074652060467921081181402357467303721471806610111179101805869578687", "price": "0.004", "size": "12500", "side": "BUY", "hash": "04876f2e162370a0eb8c2a69cf009dba371398e6", "best_bid": "0.805", "best_ask": "0.806"}, {"asset_id": "54533043819946592547517511176940999955633860128497669742211153063842200957669", "price": "0.996", "size": "12500", "side": "SELL", "hash": "602b34c82e92639b0d1a53295b1c7eebe24a38f5", "best_bid": "0.194", "best_ask": "0.195"}], "timestamp": "1785163666902", "event_type": "price_change"}}
{"ts": 1785163666.929, "kind": "price_change", "data": {"market": "0x18b1c135d0a40c5894da9412e77311827d9caf16cf4cd6591b247a34730af919", "price_changes": [{"asset_id": "40081275558852222228080198821361202017557872256707631666334039001378518619916", "price": "0.41", "size": "2931.23", "side": "BUY", "hash": "39cb51d6b2f8341ff33ced5ca441a70f8a28703c", "best_bid": "0.428", "best_ask": "0.429"}, {"asset_id": "78633590736077251574794513664747155551297291244492840448622550955320930591622", "price": "0.59", "size": "2931.23", "side": "SELL", "hash": "b48e37faab067060189f75cf5318caf3cc3c1e70", "best_bid": "0.571", "best_ask": "0.572"}], "timestamp": "1785163666929", "event_type": "price_change"}}
{"ts": 1785163667.209557, "kind": "orders_out", "data": [{"token_id": "54533043819946592547517511176940999955633860128497669742211153063842200957669", "side": "BUY", "price": 0.153, "size": 19.61}]}
{"ts": 1785163667.2345889, "kind": "orders_out", "data": [{"token_id": "40081275558852222228080198821361202017557872256707631666334039001378518619916", "side": "BUY", "price": 0.387, "size": 7.75}, {"token_id": "78633590736077251574794513664747155551297291244492840448622550955320930591622", "side": "BUY", "price": 0.529, "size": 5.67}]}
{"ts": 1785163667.545, "kind": "price_change", "data": {"market": "0x18b1c135d0a40c5894da9412e77311827d9caf16cf4cd6591b247a34730af919", "price_changes": [{"asset_id": "40081275558852222228080198821361202017557872256707631666334039001378518619916", "price": "0.41", "size": "2947.28", "side": "BUY", "hash": "fea64b7093e3183c90ca115789926883fa4f0a83", "best_bid": "0.428", "best_ask": "0.429"}, {"asset_id": "78633590736077251574794513664747155551297291244492840448622550955320930591622", "price": "0.59", "size": "2947.28", "side": "SELL", "hash": "7f9dcb3ff11ef4d1e4083d332c82aa406c0815ec", "best_bid": "0.571", "best_ask": "0.572"}], "timestamp": "1785163667545", "event_type": "price_change"}}
{"ts": 1785163673.361, "kind": "price_change", "data": {"market": "0x0f49db97f71c68b1e42a6d16e3de93d85dbf7d4148e3f018eb79e88554be9f75", "price_changes": [{"asset_id": "54533043819946592547517511176940999955633860128497669742211153063842200957669", "price": "0.009", "size": "13888.88", "side": "BUY", "hash": "834ba518313e50873bfc2b6967eb39de9280fc06", "best_bid": "0.194", "best_ask": "0.195"}, {"asset_id": "87854174148074652060467921081181402357467303721471806610111179101805869578687", "price": "0.991", "size": "13888.88", "side": "SELL", "hash": "180e9165b23e4638447a6ed90c5cd9017cadd62d", "best_bid": "0.805", "best_ask": "0.806"}], "timestamp": "1785163673361", "event_type": "price_change"}}
{"ts": 1785163673.362, "kind": "price_change", "data": {"market": "0x0f49db97f71c68b1e42a6d16e3de93d85dbf7d4148e3f018eb79e88554be9f75", "price_changes": [{"asset_id": "54533043819946592547517511176940999955633860128497669742211153063842200957669", "price": "0.007", "size": "53571.42", "side": "BUY", "hash": "bb9d2e4e71d9b30d29775245d7dce9cdd06c665f", "best_bid": "0.194", "best_ask": "0.195"}, {"asset_id": "87854174148074652060467921081181402357467303721471806610111179101805869578687", "price": "0.993", "size": "53571.42", "side": "SELL", "hash": "93eae52790037fc08f27e49c74242368e8656175", "best_bid": "0.805", "best_ask": "0.806"}], "timestamp": "1785163673362", "event_type": "price_change"}}
{"ts": 1785163673.433, "kind": "price_change", "data": {"market": "0x0f49db97f71c68b1e42a6d16e3de93d85dbf7d4148e3f018eb79e88554be9f75", "price_changes": [{"asset_id": "54533043819946592547517511176940999955633860128497669742211153063842200957669", "price": "0.176", "size": "12220.93", "side": "BUY", "hash": "b2b949ea4888c2165d3a1ef62cae3deda747ae4e", "best_bid": "0.194", "best_ask": "0.195"}, {"asset_id": "87854174148074652060467921081181402357467303721471806610111179101805869578687", "price": "0.824", "size": "12220.93", "side": "SELL", "hash": "b7fffb80b9339fef64c434d9f8c7ade9493325a1", "best_bid": "0.805", "best_ask": "0.806"}], "timestamp": "1785163673433", "event_type": "price_change"}}
{"ts": 1785163673.511, "kind": "price_change", "data": {"market": "0x0f49db97f71c68b1e42a6d16e3de93d85dbf7d4148e3f018eb79e88554be9f75", "price_changes": [{"asset_id": "54533043819946592547517511176940999955633860128497669742211153063842200957669", "price": "0.04", "size": "300", "side": "BUY", "hash": "e12783a684fffb32024ba05fa02ffa2d048ca853", "best_bid": "0.194", "best_ask": "0.195"}, {"asset_id": "87854174148074652060467921081181402357467303721471806610111179101805869578687", "price": "0.96", "size": "300", "side": "SELL", "hash": "ea45168b853a9381b166bbbfc3f06b2b945b798b", "best_bid": "0.805", "best_ask": "0.806"}], "timestamp": "1785163673511", "event_type": "price_change"}}
{"ts": 1785163673.519, "kind": "price_change", "data": {"market": "0x0f49db97f71c68b1e42a6d16e3de93d85dbf7d4148e3f018eb79e88554be9f75", "price_changes": [{"asset_id": "54533043819946592547517511176940999955633860128497669742211153063842200957669", "price": "0.02", "size": "8000", "side": "BUY", "hash": "bbf7aa69754c2763c09392f27369b7352dc6ae9e", "best_bid": "0.194", "best_ask": "0.195"}, {"asset_id": "87854174148074652060467921081181402357467303721471806610111179101805869578687", "price": "0.98", "size": "8000", "side": "SELL", "hash": "dc68a2464f459ceab3110e076e682456ead9b80e", "best_bid": "0.805", "best_ask": "0.806"}], "timestamp": "1785163673519", "event_type": "price_change"}}
{"ts": 1785163674.641, "kind": "price_change", "data": {"market": "0x0f49db97f71c68b1e42a6d16e3de93d85dbf7d4148e3f018eb79e88554be9f75", "price_changes": [{"asset_id": "87854174148074652060467921081181402357467303721471806610111179101805869578687", "price": "0.698", "size": "0", "side": "BUY", "hash": "379013d4f48c22cf74cc42947e2852b0a98bb827", "best_bid": "0.805", "best_ask": "0.806"}, {"asset_id": "54533043819946592547517511176940999955633860128497669742211153063842200957669", "price": "0.302", "size": "0", "side": "SELL", "hash": "16eb4db0aa963c8316519b9b5d40a3130316064c", "best_bid": "0.194", "best_ask": "0.195"}], "timestamp": "1785163674641", "event_type": "price_change"}}
{"ts": 1785163674.686, "kind": "price_change", "data": {"market": "0x0f49db97f71c68b1e42a6d16e3de93d85dbf7d4148e3f018eb79e88554be9f75", "price_changes": [{"asset_id": "87854174148074652060467921081181402357467303721471806610111179101805869578687", "price": "0.663", "size": "0", "side": "BUY", "hash": "c1bef47636753fcb29d3eb55d870d7298503561e", "best_bid": "0.805", "best_ask": "0.806"}, {"asset_id": "54533043819946592547517511176940999955633860128497669742211153063842200957669", "price": "0.337", "size": "0", "side": "SELL", "hash": "26dae2aa96fc271af800cc5fc591055635ac2634", "best_bid": "0.194", "best_ask": "0.195"}], "timestamp": "1785163674686", "event_type": "price_change"}}
{"ts": 1785163674.85, "kind": "price_change", "data": {"market": "0x0f49db97f71c68b1e42a6d16e3de93d85dbf7d4148e3f018eb79e88554be9f75", "price_changes": [{"asset_id": "87854174148074652060467921081181402357467303721471806610111179101805869578687", "price": "0.698", "size": "35", "side": "BUY", "hash": "cf1e594cc2056adf0a22ee37e377837ed7afb31d", "best_bid": "0.805", "best_ask": "0.806"}, {"asset_id": "54533043819946592547517511176940999955633860128497669742211153063842200957669", "price": "0.302", "size": "35", "side": "SELL", "hash": "08f8ec88a8d07d0955965a810dfe5b50fbd3df15", "best_bid": "0.194", "best_ask": "0.195"}], "timestamp": "1785163674850", "event_type": "price_change"}}
{"ts": 1785163674.865, "kind": "price_change", "data": {"market": "0x0f49db97f71c68b1e42a6d16e3de93d85dbf7d4148e3f018eb79e88554be9f75", "price_changes": [{"asset_id": "87854174148074652060467921081181402357467303721471806610111179101805869578687", "price": "0.66", "size": "75", "side": "BUY", "hash": "b3a2a865feea0717567cfe0c68a2fc2ca5eea971", "best_bid": "0.805", "best_ask": "0.806"}, {"asset_id": "54533043819946592547517511176940999955633860128497669742211153063842200957669", "price": "0.34", "size": "75", "side": "SELL", "hash": "8085a0bdd555549846ac2773a2a8bdcd965b57ab", "best_bid": "0.194", "best_ask": "0.195"}], "timestamp": "1785163674865", "event_type": "price_change"}}
{"ts": 1785163675.3, "kind": "price_change", "data": {"market": "0x0f49db97f71c68b1e42a6d16e3de93d85dbf7d4148e3f018eb79e88554be9f75", "price_changes": [{"asset_id": "87854174148074652060467921081181402357467303721471806610111179101805869578687", "price": "0.698", "size": "0", "side": "BUY", "hash": "29c4002ce6d498f319b1aaee81e64ba5caf10004", "best_bid": "0.805", "best_ask": "0.806"}, {"asset_id": "54533043819946592547517511176940999955633860128497669742211153063842200957669", "price": "0.302", "size": "0", "side": "SELL", "hash": "f94e6cc2c0f8ffb1e369f97b78ea47de8f812ab0", "best_bid": "0.194", "best_ask": "0.195"}], "timestamp": "1785163675300", "event_type": "price_change"}}
{"ts": 1785163675.586, "kind": "price_change", "data": {"market": "0x18b1c135d0a40c5894da9412e77311827d9caf16cf4cd6591b247a34730af919", "price_changes": [{"asset_id": "78633590736077251574794513664747155551297291244492840448622550955320930591622", "price": "0.371", "size": "0", "side": "BUY", "hash": "331f0457a35b9632df43bcf5150d5ed6a1fd4274", "best_bid": "0.571", "best_ask": "0.572"}, {"asset_id": "40081275558852222228080198821361202017557872256707631666334039001378518619916", "price": "0.629", "size": "0", "side": "SELL", "hash": "eb5bbfa6d6446668b2eb56e0374d9e1fbbedffd1", "best_bid": "0.428", "best_ask": "0.429"}], "timestamp": "1785163675586", "event_type": "price_change"}}
{"ts": 1785163675.616, "kind": "price_change", "data": {"market": "0x18b1c135d0a40c5894da9412e77311827d9caf16cf4cd6591b247a34730af919", "price_changes": [{"asset_id": "78633590736077251574794513664747155551297291244492840448622550955320930591622", "price": "0.375", "size": "400", "side": "BUY", "hash": "8ba1d8107c7df6ed1a97080ccc27c1f9aafd48ed", "best_bid": "0.571", "best_ask": "0.572"}, {"asset_id": "40081275558852222228080198821361202017557872256707631666334039001378518619916", "price": "0.625", "size": "400", "side": "SELL", "hash": "1f68d8c079acabd79aca0b97612ff58bb7c09bb8", "best_bid": "0.428", "best_ask": "0.429"}], "timestamp": "1785163675616", "event_type": "price_change"}}
{"ts": 1785163675.874, "kind": "price_change", "data": {"market": "0x0f49db97f71c68b1e42a6d16e3de93d85dbf7d4148e3f018eb79e88554be9f75", "price_changes": [{"asset_id": "87854174148074652060467921081181402357467303721471806610111179101805869578687", "price": "0.652", "size": "35", "side": "BUY", "hash": "c89c08b1e0cc17cd2a46b25c609ab3202b746c68", "best_bid": "0.805", "best_ask": "0.806"}, {"asset_id": "54533043819946592547517511176940999955633860128497669742211153063842200957669", "price": "0.348", "size": "35", "side": "SELL", "hash": "b86345b93608c33987d269158aa85983e9fd8b3f", "best_bid": "0.194", "best_ask": "0.195"}], "timestamp": "1785163675874", "event_type": "price_change"}}
{"ts": 1785163678.683, "kind": "price_change", "data": {"market": "0x0f49db97f71c68b1e42a6d16e3de93d85dbf7d4148e3f018eb79e88554be9f75", "price_changes": [{"asset_id": "54533043819946592547517511176940999955633860128497669742211153063842200957669", "price": "0.179", "size": "81592.56", "side": "BUY", "hash": "8652cba005b0a465274ef850965afa4b72a38ba1", "best_bid": "0.194", "best_ask": "0.195"}, {"asset_id": "87854174148074652060467921081181402357467303721471806610111179101805869578687", "price": "0.821", "size": "81592.56", "side": "SELL", "hash": "41ca7b8aa3ca97118ad3658c36fc7376ef0468d7", "best_bid": "0.805", "best_ask": "0.806"}], "timestamp": "1785163678683", "event_type": "price_change"}}
{"ts": 1785163679.679, "kind": "price_change", "data": {"market": "0x18b1c135d0a40c5894da9412e77311827d9caf16cf4cd6591b247a34730af919", "price_changes": [{"asset_id": "40081275558852222228080198821361202017557872256707631666334039001378518619916", "price": "0.408", "size": "3186", "side": "BUY", "hash": "d39a3551378fb7498bc75b4ab3b94d34df3f3d40", "best_bid": "0.428", "best_ask": "0.429"}, {"asset_id": "78633590736077251574794513664747155551297291244492840448622550955320930591622", "price": "0.592", "size": "3186", "side": "SELL", "hash": "178200f91bedabea6737a3d59041a8a7628af33f", "best_bid": "0.571", "best_ask": "0.572"}], "timestamp": "1785163679679", "event_type": "price_change"}}
{"ts": 1785163679.711, "kind": "price_change", "data": {"market": "0x18b1c135d0a40c5894da9412e77311827d9caf16cf4cd6591b247a34730af919", "price_changes": [{"asset_id": "40081275558852222228080198821361202017557872256707631666334039001378518619916", "price": "0.408", "size": "4656", "side": "BUY", "hash": "2c2e430419812755c611316b8feb017aa7439e48", "best_bid": "0.428", "best_ask": "0.429"}, {"asset_id": "78633590736077251574794513664747155551297291244492840448622550955320930591622", "price": "0.592", "size": "4656", "side": "SELL", "hash": "1fe44955672fc95b2987bc040c814fa39df92f30", "best_bid": "0.571", "best_ask": "0.572"}], "timestamp": "1785163679711", "event_type": "price_change"}}
{"ts": 1785163681.001, "kind": "price_change", "data": {"market": "0x18b1c135d0a40c5894da9412e77311827d9caf16cf4cd6591b247a34730af919", "price_changes": [{"asset_id": "40081275558852222228080198821361202017557872256707631666334039001378518619916", "price": "0.171", "size": "0", "side": "BUY", "hash": "b93de56efa914907b733c67f7b81ed96d287e72d", "best_bid": "0.428", "best_ask": "0.429"}, {"asset_id": "78633590736077251574794513664747155551297291244492840448622550955320930591622", "price": "0.829", "size": "0", "side": "SELL", "hash": "bc711738278bc9178400858bfc26806db2ffef48", "best_bid": "0.571", "best_ask": "0.572"}], "timestamp": "1785163681001", "event_type": "price_change"}}
{"ts": 1785163681.002, "kind": "price_change", "data": {"market": "0x18b1c135d0a40c5894da9412e77311827d9caf16cf4cd6591b247a34730af919", "price_changes": [{"asset_id": "40081275558852222228080198821361202017557872256707631666334039001378518619916", "price": "0.171", "size": "0", "side": "BUY", "hash": "ce4e18bb8f95560592cbd2b32da94cfb273450e0", "best_bid": "0.428", "best_ask": "0.429"}, {"asset_id": "78633590736077251574794513664747155551297291244492840448622550955320930591622", "price": "0.829", "size": "0", "side": "SELL", "hash": "06c7f1f66eae474990ff730a74b9440be20e7153", "best_bid": "0.571", "best_ask": "0.572"}], "timestamp": "1785163681002", "event_type": "price_change"}}
{"ts": 1785163682.827, "kind": "price_change", "data": {"market": "0x18b1c135d0a40c5894da9412e77311827d9caf16cf4cd6591b247a34730af919", "price_changes": [{"asset_id": "40081275558852222228080198821361202017557872256707631666334039001378518619916", "price": "0.418", "size": "6991.05", "side": "BUY", "hash": "2c58b1c72be8d53aa1e937b87e5ada3d5763d090", "best_bid": "0.428", "best_ask": "0.429"}, {"asset_id": "78633590736077251574794513664747155551297291244492840448622550955320930591622", "price": "0.582", "size": "6991.05", "side": "SELL", "hash": "a51ad21eadf3fa902e8ffd4411ef25b079f8d2bd", "best_bid": "0.571", "best_ask": "0.572"}], "timestamp": "1785163682827", "event_type": "price_change"}}
{"ts": 1785163682.964, "kind": "price_change", "data": {"market": "0x0f49db97f71c68b1e42a6d16e3de93d85dbf7d4148e3f018eb79e88554be9f75", "price_changes": [{"asset_id": "54533043819946592547517511176940999955633860128497669742211153063842200957669", "price": "0.007", "size": "0", "side": "BUY", "hash": "4a397192d73e51da06462b13c832f1d44843cef3", "best_bid": "0.194", "best_ask": "0.195"}, {"asset_id": "87854174148074652060467921081181402357467303721471806610111179101805869578687", "price": "0.993", "size": "0", "side": "SELL", "hash": "697042f9cd96b011ca835663e38f82d669f035b7", "best_bid": "0.805", "best_ask": "0.806"}], "timestamp": "1785163682964", "event_type": "price_change"}}
{"ts": 1785163682.964, "kind": "price_change", "data": {"market": "0x0f49db97f71c68b1e42a6d16e3de93d85dbf7d4148e3f018eb79e88554be9f75", "price_changes": [{"asset_id": "54533043819946592547517511176940999955633860128497669742211153063842200957669", "price": "0.009", "size": "0", "side": "BUY", "hash": "4a397192d73e51da06462b13c832f1d44843cef3", "best_bid": "0.194", "best_ask": "0.195"}, {"asset_id": "87854174148074652060467921081181402357467303721471806610111179101805869578687", "price": "0.991", "size": "0", "side": "SELL", "hash": "697042f9cd96b011ca835663e38f82d669f035b7", "best_bid": "0.805", "best_ask": "0.806"}], "timestamp": "1785163682964", "event_type": "price_change"}}
{"ts": 1785163683.029, "kind": "price_change", "data": {"market": "0x0f49db97f71c68b1e42a6d16e3de93d85dbf7d4148e3f018eb79e88554be9f75", "price_changes": [{"asset_id": "54533043819946592547517511176940999955633860128497669742211153063842200957669", "price": "0.176", "size": "12210.93", "side": "BUY", "hash": "f072b2f59167eb5b1255f590590e1dfbffd8d0e0", "best_bid": "0.194", "best_ask": "0.195"}, {"asset_id": "87854174148074652060467921081181402357467303721471806610111179101805869578687", "price": "0.824", "size": "12210.93", "side": "SELL", "hash": "bbd9d8355220145c8924c7840767a757f2748389", "best_bid": "0.805", "best_ask": "0.806"}], "timestamp": "1785163683029", "event_type": "price_change"}}
{"ts": 1785163683.503, "kind": "price_change", "data": {"market": "0x0f49db97f71c68b1e42a6d16e3de93d85dbf7d4148e3f018eb79e88554be9f75", "price_changes": [{"asset_id": "54533043819946592547517511176940999955633860128497669742211153063842200957669", "price": "0.177", "size": "581", "side": "BUY", "hash": "93302b9e80b5f36b8640ad0f08960fa4366ac12c", "best_bid": "0.194", "best_ask": "0.195"}, {"asset_id": "87854174148074652060467921081181402357467303721471806610111179101805869578687", "price": "0.823", "size": "581", "side": "SELL", "hash": "703f6fa2e64f290fd7144a22e512b54fb577d2a4", "best_bid": "0.805", "best_ask": "0.806"}], "timestamp": "1785163683503", "event_type": "price_change"}}
{"ts": 1785163684.232, "kind": "price_change", "data": {"market": "0x18b1c135d0a40c5894da9412e77311827d9caf16cf4cd6591b247a34730af919", "price_changes": [{"asset_id": "40081275558852222228080198821361202017557872256707631666334039001378518619916", "price": "0.41", "size": "2931.23", "side": "BUY", "hash": "fcedfc309d4c3152da63d36a681b45b5a0358ee2", "best_bid": "0.428", "best_ask": "0.429"}, {"asset_id": "78633590736077251574794513664747155551297291244492840448622550955320930591622", "price": "0.59", "size": "2931.23", "side": "SELL", "hash": "798023955dfca30d8cfa87fdd2f8311bc3296ba3", "best_bid": "0.571", "best_ask": "0.572"}], "timestamp": "1785163684232", "event_type": "price_change"}}
{"ts": 1785163685.136, "kind": "price_change", "data": {"market": "0x18b1c135d0a40c5894da9412e77311827d9caf16cf4cd6591b247a34730af919", "price_changes": [{"asset_id": "40081275558852222228080198821361202017557872256707631666334039001378518619916", "price": "0.41", "size": "2947.28", "side": "BUY", "hash": "5160a31f6f2ab06b171e6c13dc47a8d72a725069", "best_bid": "0.428", "best_ask": "0.429"}, {"asset_id": "78633590736077251574794513664747155551297291244492840448622550955320930591622", "price": "0.59", "size": "2947.28", "side": "SELL", "hash": "d711349e0b193eb251ce431159e8ed48aaa37373", "best_bid": "0.571", "best_ask": "0.572"}], "timestamp": "1785163685136", "event_type": "price_change"}}
{"ts": 1785163686.001, "kind": "price_change", "data": {"market": "0x0f49db97f71c68b1e42a6d16e3de93d85dbf7d4148e3f018eb79e88554be9f75", "price_changes": [{"asset_id": "87854174148074652060467921081181402357467303721471806610111179101805869578687", "price": "0.803", "size": "12234.97", "side": "BUY", "hash": "596eda73dd9e4830dc829e383bdc5311caef1d82", "best_bid": "0.805", "best_ask": "0.806"}, {"asset_id": "54533043819946592547517511176940999955633860128497669742211153063842200957669", "price": "0.197", "size": "12234.97", "side": "SELL", "hash": "eee1d1f138e9d90d97f12b5f5bcd4d279d2ee0e9", "best_bid": "0.194", "best_ask": "0.195"}], "timestamp": "1785163686001", "event_type": "price_change"}}
{"ts": 1785163686.003, "kind": "price_change", "data": {"market": "0x0f49db97f71c68b1e42a6d16e3de93d85dbf7d4148e3f018eb79e88554be9f75", "price_changes": [{"asset_id": "54533043819946592547517511176940999955633860128497669742211153063842200957669", "price": "0.193", "size": "10787", "side": "BUY", "hash": "a53541ff3f962153f9007aa422dd73ba4f2e0a35", "best_bid": "0.194", "best_ask": "0.195"}, {"asset_id": "87854174148074652060467921081181402357467303721471806610111179101805869578687", "price": "0.807", "size": "10787", "side": "SELL", "hash": "288020d516c74a8d94f7b0e8a22668ff1612d51f", "best_bid": "0.805", "best_ask": "0.806"}], "timestamp": "1785163686003", "event_type": "price_change"}}
{"ts": 1785163686.003, "kind": "price_change", "data": {"market": "0x0f49db97f71c68b1e42a6d16e3de93d85dbf7d4148e3f018eb79e88554be9f75", "price_changes": [{"asset_id": "87854174148074652060467921081181402357467303721471806610111179101805869578687", "price": "0.803", "size": "12234.97", "side": "BUY", "hash": "2aff0e0fe280a452d9b09018cef817f2172aa02e", "best_bid": "0.805", "best_ask": "0.806"}, {"asset_id": "54533043819946592547517511176940999955633860128497669742211153063842200957669", "price": "0.197", "size": "12234.97", "side": "SELL", "hash": "a53541ff3f962153f9007aa422dd73ba4f2e0a35", "best_bid": "0.194", "best_ask": "0.195"}], "timestamp": "1785163686003", "event_type": "price_change"}}
{"ts": 1785163686.004, "kind": "price_change", "data": {"market": "0x0f49db97f71c68b1e42a6d16e3de93d85dbf7d4148e3f018eb79e88554be9f75", "price_changes": [{"asset_id": "54533043819946592547517511176940999955633860128497669742211153063842200957669", "price": "0.193", "size": "10787", "side": "BUY", "hash": "9613e021c83094a1156813b22f8c53e983d34147", "best_bid": "0.194", "best_ask": "0.195"}, {"asset_id": "87854174148074652060467921081181402357467303721471806610111179101805869578687", "price": "0.807", "size": "10787", "side": "SELL", "hash": "1bb34cf133683276b65da96dee49f10c6be4aaa3", "best_bid": "0.805", "best_ask": "0.806"}], "timestamp": "1785163686004", "event_type": "price_change"}}
{"ts": 1785163686.04, "kind": "price_change", "data": {"market": "0x0f49db97f71c68b1e42a6d16e3de93d85dbf7d4148e3f018eb79e88554be9f75", "price_changes": [{"asset_id": "54533043819946592547517511176940999955633860128497669742211153063842200957669", "price": "0.193", "size": "10887", "side": "BUY", "hash": "fd13e2b5a16e961e8ccbc1862a17882870aaa9ef", "best_bid": "0.194", "best_ask": "0.195"}, {"asset_id": "87854174148074652060467921081181402357467303721471806610111179101805869578687", "price": "0.807", "size": "10887", "side": "SELL", "hash": "7e299910a2e1ae1640bf5a908abc0d5e96b04630", "best_bid": "0.805", "best_ask": "0.806"}], "timestamp": "1785163686040", "event_type": "price_change"}}
{"ts": 1785163686.042, "kind": "price_change", "data": {"market": "0x0f49db97f71c68b1e42a6d16e3de93d85dbf7d4148e3f018eb79e88554be9f75", "price_changes": [{"asset_id": "87854174148074652060467921081181402357467303721471806610111179101805869578687", "price": "0.803", "size": "12334.97", "side": "BUY", "hash": "0b1f4aac7a7ac600337089a3e13d2ff09e4f1bcb", "best_bid": "0.805", "best_ask": "0.806"}, {"asset_id": "54533043819946592547517511176940999955633860128497669742211153063842200957669", "price": "0.197", "size": "12334.97", "side": "SELL", "hash": "b1b7eda8f92ece0d344e6636695e08cb7130dce6", "best_bid": "0.194", "best_ask": "0.195"}], "timestamp": "1785163686042", "event_type": "price_change"}}
{"ts": 1785163686.045, "kind": "price_change", "data": {"market": "0x0f49db97f71c68b1e42a6d16e3de93d85dbf7d4148e3f018eb79e88554be9f75", "price_changes": [{"asset_id": "54533043819946592547517511176940999955633860128497669742211153063842200957669", "price": "0.193", "size": "10987", "side": "BUY", "hash": "3269c5146582f77a1d08eff8b3fee938255e94b8", "best_bid": "0.194", "best_ask": "0.195"}, {"asset_id": "87854174148074652060467921081181402357467303721471806610111179101805869578687", "price": "0.807", "size": "10987", "side": "SELL", "hash": "01f97156274d419e59d61815425cab62602693ee", "best_bid": "0.805", "best_ask": "0.806"}], "timestamp": "1785163686045", "event_type": "price_change"}}
{"ts": 1785163686.049, "kind": "price_change", "data": {"market": "0x0f49db97f71c68b1e42a6d16e3de93d85dbf7d4148e3f018eb79e88554be9f75", "price_changes": [{"asset_id": "87854174148074652060467921081181402357467303721471806610111179101805869578687", "price": "0.803", "size": "12434.97", "side": "BUY", "hash": "737497ca4a846f9499d2567a82f91bd2717da117", "best_bid": "0.805", "best_ask": "0.806"}, {"asset_id": "54533043819946592547517511176940999955633860128497669742211153063842200957669", "price": "0.197", "size": "12434.97", "side": "SELL", "hash": "9a20ba70a1be3144af7bb3f909c908d93dfff29a", "best_bid": "0.194", "best_ask": "0.195"}], "timestamp": "1785163686049", "event_type": "price_change"}}
{"ts": 1785163686.092, "kind": "price_change", "data": {"market": "0x0f49db97f71c68b1e42a6d16e3de93d85dbf7d4148e3f018eb79e88554be9f75", "price_changes": [{"asset_id": "54533043819946592547517511176940999955633860128497669742211153063842200957669", "price": "0.176", "size": "12220.93", "side": "BUY", "hash": "c5435828308d9bd8fb38b8d9976ba8011f937b77", "best_bid": "0.194", "best_ask": "0.195"}, {"asset_id": "87854174148074652060467921081181402357467303721471806610111179101805869578687", "price": "0.824", "size": "12220.93", "side": "SELL", "hash": "3e8a89de15939c16c535634346c84fdc521c29dc", "best_bid": "0.805", "best_ask": "0.806"}], "timestamp": "1785163686092", "event_type": "price_change"}}
{"ts": 1785163686.693, "kind": "price_change", "data": {"market": "0x18b1c135d0a40c5894da9412e77311827d9caf16cf4cd6591b247a34730af919", "price_changes": [{"asset_id": "78633590736077251574794513664747155551297291244492840448622550955320930591622", "price": "0.561", "size": "11898.9", "side": "BUY", "hash": "92a55642bbf3c8e5303d5e6cf31c8ea060ba914b", "best_bid": "0.571", "best_ask": "0.572"}, {"asset_id": "40081275558852222228080198821361202017557872256707631666334039001378518619916", "price": "0.439", "size": "11898.9", "side": "SELL", "hash": "fddac61f6a77f39a621de072f0e32c62b617f572", "best_bid": "0.428", "best_ask": "0.429"}], "timestamp": "1785163686693", "event_type": "price_change"}}
{"ts": 1785163687.65, "kind": "price_change", "data": {"market": "0x18b1c135d0a40c5894da9412e77311827d9caf16cf4cd6591b247a34730af919", "price_changes": [{"asset_id": "40081275558852222228080198821361202017557872256707631666334039001378518619916", "price": "0.507", "size": "0", "side": "SELL", "hash": "23431b580e7f6e37490752fb2d25f6880f2ee158", "best_bid": "0.428", "best_ask": "0.429"}, {"asset_id": "78633590736077251574794513664747155551297291244492840448622550955320930591622", "price": "0.493", "size": "0", "side": "BUY", "hash": "730826b003cd619a6ac8bcab986df204de7ec499", "best_bid": "0.571", "best_ask": "0.572"}], "timestamp": "1785163687650", "event_type": "price_change"}}
{"ts": 1785163687.893, "kind": "price_change", "data": {"market": "0x0f49db97f71c68b1e42a6d16e3de93d85dbf7d4148e3f018eb79e88554be9f75", "price_changes": [{"asset_id": "87854174148074652060467921081181402357467303721471806610111179101805869578687", "price": "0.795", "size": "3694.98", "side": "BUY", "hash": "3d49cc6baa35d431e77acbd7e56e9bcd94cb55ab", "best_bid": "0.805", "best_ask": "0.806"}, {"asset_id": "54533043819946592547517511176940999955633860128497669742211153063842200957669", "price": "0.205", "size": "3694.98", "side": "SELL", "hash": "3f4367bcc2e069f27c29590093eb7502f2d16fa4", "best_bid": "0.194", "best_ask": "0.195"}], "timestamp": "1785163687893", "event_type": "price_change"}}
{"ts": 1785163689.246, "kind": "price_change", "data": {"market": "0x18b1c135d0a40c5894da9412e77311827d9caf16cf4cd6591b247a34730af919", "price_changes": [{"asset_id": "40081275558852222228080198821361202017557872256707631666334039001378518619916", "price": "0.506", "size": "36.7", "side": "SELL", "hash": "95b9bd295b455c8c2c878c422f41f77c1cd13b1c", "best_bid": "0.428", "best_ask": "0.429"}, {"asset_id": "78633590736077251574794513664747155551297291244492840448622550955320930591622", "price": "0.494", "size": "36.7", "side": "BUY", "hash": "a7fcb0b4cb55bd79279de6bd066ad87cf7190be5", "best_bid": "0.571", "best_ask": "0.572"}], "timestamp": "1785163689246", "event_type": "price_change"}}
{"ts": 1785163690.695, "kind": "price_change", "data": {"market": "0x18b1c135d0a40c5894da9412e77311827d9caf16cf4cd6591b247a34730af919", "price_changes": [{"asset_id": "40081275558852222228080198821361202017557872256707631666334039001378518619916", "price": "0.408", "size": "1470", "side": "BUY", "hash": "9c9e8a3830d60bded51de0e4154278832751dcc0", "best_bid": "0.428", "best_ask": "0.429"}, {"asset_id": "78633590736077251574794513664747155551297291244492840448622550955320930591622", "price": "0.592", "size": "1470", "side": "SELL", "hash": "d8f1dc4f6b0072b3253fa8d3020ceb61a9fafcbb", "best_bid": "0.571", "best_ask": "0.572"}], "timestamp": "1785163690695", "event_type": "price_change"}}
{"ts": 1785163691.0, "kind": "price_change", "data": {"market": "0x18b1c135d0a40c5894da9412e77311827d9caf16cf4cd6591b247a34730af919", "price_changes": [{"asset_id": "78633590736077251574794513664747155551297291244492840448622550955320930591622", "price": "0.55", "size": "30179.18", "side": "BUY", "hash": "4bd8e0139c2bf172b8cba87e0e8f9bb425f77b23", "best_bid": "0.571", "best_ask": "0.572"}, {"asset_id": "40081275558852222228080198821361202017557872256707631666334039001378518619916", "price": "0.45", "size": "30179.18", "side": "SELL", "hash": "62d726709b48c86a65934e925d566c9fd587dbdb", "best_bid": "0.428", "best_ask": "0.429"}], "timestamp": "1785163691000", "event_type": "price_change"}}
{"ts": 1785163691.002, "kind": "price_change", "data": {"market": "0x18b1c135d0a40c5894da9412e77311827d9caf16cf4cd6591b247a34730af919", "price_changes": [{"asset_id": "78633590736077251574794513664747155551297291244492840448622550955320930591622", "price": "0.551", "size": "28506.16", "side": "BUY", "hash": "a668084d0d9802a77bb5b3035a3a0447b52ebfad", "best_bid": "0.571", "best_ask": "0.572"}, {"asset_id": "40081275558852222228080198821361202017557872256707631666334039001378518619916", "price": "0.449", "size": "28506.16", "side": "SELL", "hash": "41937f7c3c0744ac9247bee4cf0962091641c0e8", "best_bid": "0.428", "best_ask": "0.429"}], "timestamp": "1785163691002", "event_type": "price_change"}}
{"ts": 1785163691.003, "kind": "price_change", "data": {"market": "0x18b1c135d0a40c5894da9412e77311827d9caf16cf4cd6591b247a34730af919", "price_changes": [{"asset_id": "40081275558852222228080198821361202017557872256707631666334039001378518619916", "price": "0.412", "size": "11123.8", "side": "BUY", "hash": "b923e78c9e9efdc86a48a92be4621d6d065e73dd", "best_bid": "0.428", "best_ask": "0.429"}, {"asset_id": "78633590736077251574794513664747155551297291244492840448622550955320930591622", "price": "0.588", "size": "11123.8", "side": "SELL", "hash": "b4ab11806a0d4fe5d4d2eafd0799cf2316bd7d68", "best_bid": "0.571", "best_ask": "0.572"}], "timestamp": "1785163691003", "event_type": "price_change"}}
{"ts": 1785163691.047, "kind": "price_change", "data": {"market": "0x18b1c135d0a40c5894da9412e77311827d9caf16cf4cd6591b247a34730af919", "price_changes": [{"asset_id": "40081275558852222228080198821361202017557872256707631666334039001378518619916", "price": "0.412", "size": "11323.8", "side": "BUY", "hash": "53e96ae6cb2303147520b4b001e4945d38d2d350", "best_bid": "0.428", "best_ask": "0.429"}, {"asset_id": "78633590736077251574794513664747155551297291244492840448622550955320930591622", "price": "0.588", "size": "11323.8", "side": "SELL", "hash": "d8096310d89df4db4d6d52560c65cb8bfb663b0d", "best_bid": "0.571", "best_ask": "0.572"}], "timestamp": "1785163691047", "event_type": "price_change"}}
{"ts": 1785163691.048, "kind": "price_change", "data": {"market": "0x18b1c135d0a40c5894da9412e77311827d9caf16cf4cd6591b247a34730af919", "price_changes": [{"asset_id": "78633590736077251574794513664747155551297291244492840448622550955320930591622", "price": "0.551", "size": "28706.16", "side": "BUY", "hash": "0ec4a281d531676576840f908bb0c7317e55b324", "best_bid": "0.571", "best_ask": "0.572"}, {"asset_id": "40081275558852222228080198821361202017557872256707631666334039001378518619916", "price": "0.449", "size": "28706.16", "side": "SELL", "hash": "d6ef412937d509978388f7f8b2392c4cf8921b24", "best_bid": "0.428", "best_ask": "0.429"}], "timestamp": "1785163691048", "event_type": "price_change"}}
{"ts": 1785163691.05, "kind": "price_change", "data": {"market": "0x18b1c135d0a40c5894da9412e77311827d9caf16cf4cd6591b247a34730af919", "price_changes": [{"asset_id": "78633590736077251574794513664747155551297291244492840448622550955320930591622", "price": "0.55", "size": "30379.18", "side": "BUY", "hash": "2614ec675491c2d8377fc5709f680b41b609d968", "best_bid": "0.571", "best_ask": "0.572"}, {"asset_id": "40081275558852222228080198821361202017557872256707631666334039001378518619916", "price": "0.45", "size": "30379.18", "side": "SELL", "hash": "faa4bd4ddbc50ca14bbd4233972fc1f8f02e3f5e", "best_bid": "0.428", "best_ask": "0.429"}], "timestamp": "1785163691050", "event_type": "price_change"}}
{"ts": 1785163691.296, "kind": "price_change", "data": {"market": "0x0f49db97f71c68b1e42a6d16e3de93d85dbf7d4148e3f018eb79e88554be9f75", "price_changes": [{"asset_id": "54533043819946592547517511176940999955633860128497669742211153063842200957669", "price": "0.02", "size": "500", "side": "BUY", "hash": "1ee9ac7d670e4dde60b019bed16dc8382425d381", "best_bid": "0.194", "best_ask": "0.195"}, {"asset_id": "87854174148074652060467921081181402357467303721471806610111179101805869578687", "price": "0.98", "size": "500", "side": "SELL", "hash": "1e981a678e0875d955fef43195abd583a3a44dd2", "best_bid": "0.805", "best_ask": "0.806"}], "timestamp": "1785163691296", "event_type": "price_change"}}
{"ts": 1785163691.303, "kind": "price_change", "data": {"market": "0x0f49db97f71c68b1e42a6d16e3de93d85dbf7d4148e3f018eb79e88554be9f75", "price_changes": [{"asset_id": "54533043819946592547517511176940999955633860128497669742211153063842200957669", "price": "0.04", "size": "4050", "side": "BUY", "hash": "52b0278ef371ed6af24d38f9612648a89d7a98ab", "best_bid": "0.194", "best_ask": "0.195"}, {"asset_id": "87854174148074652060467921081181402357467303721471806610111179101805869578687", "price": "0.96", "size": "4050", "side": "SELL", "hash": "83ed3a20db03c486200991e55b1bacb270e988ee", "best_bid": "0.805", "best_ask": "0.806"}], "timestamp": "1785163691303", "event_type": "price_change"}}
{"ts": 1785163692.565, "kind": "price_change", "data": {"market": "0x18b1c135d0a40c5894da9412e77311827d9caf16cf4cd6591b247a34730af919", "price_changes": [{"asset_id": "40081275558852222228080198821361202017557872256707631666334039001378518619916", "price": "0.408", "size": "4656", "side": "BUY", "hash": "3fb59cc2a931252aefb600d538b3b14d74c82b20", "best_bid": "0.428", "best_ask": "0.429"}, {"asset_id": "78633590736077251574794513664747155551297291244492840448622550955320930591622", "price": "0.592", "size": "4656", "side": "SELL", "hash": "ee07808f2f80c5608d69c912b0a1eb0574f0f640", "best_bid": "0.571", "best_ask": "0.572"}], "timestamp": "1785163692565", "event_type": "price_change"}}
{"ts": 1785163696.776, "kind": "price_change", "data": {"market": "0x0f49db97f71c68b1e42a6d16e3de93d85dbf7d4148e3f018eb79e88554be9f75", "price_changes": [{"asset_id": "87854174148074652060467921081181402357467303721471806610111179101805869578687", "price": "0.795", "size": "3127.98", "side": "BUY", "hash": "2df47b44d0f82ee158d59d77b3960fd7b99ae479", "best_bid": "0.805", "best_ask": "0.806"}, {"asset_id": "54533043819946592547517511176940999955633860128497669742211153063842200957669", "price": "0.205", "size": "3127.98", "side": "SELL", "hash": "2f2f71c3352917f1730a4a3cc516eb52a1aae487", "best_bid": "0.194", "best_ask": "0.195"}], "timestamp": "1785163696776", "event_type": "price_change"}}
{"ts": 1785163696.868, "kind": "price_change", "data": {"market": "0x0f49db97f71c68b1e42a6d16e3de93d85dbf7d4148e3f018eb79e88554be9f75", "price_changes": [{"asset_id": "87854174148074652060467921081181402357467303721471806610111179101805869578687", "price": "0.795", "size": "3694.98", "side": "BUY", "hash": "c923c6c6d8e45ce0485791abe318179ff339011b", "best_bid": "0.805", "best_ask": "0.806"}, {"asset_id": "54533043819946592547517511176940999955633860128497669742211153063842200957669", "price": "0.205", "size": "3694.98", "side": "SELL", "hash": "fa540f26372650eac6dfaa5171e43bd543c3f51f", "best_bid": "0.194", "best_ask": "0.195"}], "timestamp": "1785163696868", "event_type": "price_change"}}
{"ts": 1785163696.975, "kind": "price_change", "data": {"market": "0x0f49db97f71c68b1e42a6d16e3de93d85dbf7d4148e3f018eb79e88554be9f75", "price_changes": [{"asset_id": "54533043819946592547517511176940999955633860128497669742211153063842200957669", "price": "0.158", "size": "36538", "side": "BUY", "hash": "5bf99178bcd40f6047a5a60f92a14d433e3b3f9f", "best_bid": "0.194", "best_ask": "0.195"}, {"asset_id": "87854174148074652060467921081181402357467303721471806610111179101805869578687", "price": "0.842", "size": "36538", "side": "SELL", "hash": "04c2a6e05cb08241655eebe2cc24b5d1903d8f9c", "best_bid": "0.805", "best_ask": "0.806"}], "timestamp": "1785163696975", "event_type": "price_change"}}
{"ts": 1785163697.002, "kind": "price_change", "data": {"market": "0x0f49db97f71c68b1e42a6d16e3de93d85dbf7d4148e3f018eb79e88554be9f75", "price_changes": [{"asset_id": "54533043819946592547517511176940999955633860128497669742211153063842200957669", "price": "0.003", "size": "11073", "side": "BUY", "hash": "c50633d70faa05d0e986fdf4ad4174e2bcba7a46", "best_bid": "0.194", "best_ask": "0.195"}, {"asset_id": "87854174148074652060467921081181402357467303721471806610111179101805869578687", "price": "0.997", "size": "11073", "side": "SELL", "hash": "1910dcdc8e9f6da8f9f264427098e622f1f21667", "best_bid": "0.805", "best_ask": "0.806"}], "timestamp": "1785163697002", "event_type": "price_change"}}
{"ts": 1785163697.083227, "kind": "orders_out", "data": [{"token_id": "54533043819946592547517511176940999955633860128497669742211153063842200957669", "side": "BUY", "price": 0.153, "size": 19.61}]}
{"ts": 1785163697.409, "kind": "price_change", "data": {"market": "0x18b1c135d0a40c5894da9412e77311827d9caf16cf4cd6591b247a34730af919", "price_changes": [{"asset_id": "40081275558852222228080198821361202017557872256707631666334039001378518619916", "price": "0.418", "size": "5913.05", "side": "BUY", "hash": "ed8fd559795a5f5ba02a144048dcf1637195e240", "best_bid": "0.428", "best_ask": "0.429"}, {"asset_id": "78633590736077251574794513664747155551297291244492840448622550955320930591622", "price": "0.582", "size": "5913.05", "side": "SELL", "hash": "f4dc4fc35eeae1d1a0c7e75905b886e98f8d5880", "best_bid": "0.571", "best_ask": "0.572"}], "timestamp": "1785163697409", "event_type": "price_change"}}
{"ts": 1785163697.439, "kind": "price_change", "data": {"market": "0x18b1c135d0a40c5894da9412e77311827d9caf16cf4cd6591b247a34730af919", "price_changes": [{"asset_id": "40081275558852222228080198821361202017557872256707631666334039001378518619916", "price": "0.418", "size": "5713.05", "side": "BUY", "hash": "ce19988e843feaa3152f7ee3150199d53a31d2f6", "best_bid": "0.428", "best_ask": "0.429"}, {"asset_id": "78633590736077251574794513664747155551297291244492840448622550955320930591622", "price": "0.582", "size": "5713.05", "side": "SELL", "hash": "3f1b70265576f39c93dfe145f7041fe59bd6619c", "best_bid": "0.571", "best_ask": "0.572"}], "timestamp": "1785163697439", "event_type": "price_change"}}
{"ts": 1785163697.469, "kind": "price_change", "data": {"market": "0x18b1c135d0a40c5894da9412e77311827d9caf16cf4cd6591b247a34730af919", "price_changes": [{"asset_id": "40081275558852222228080198821361202017557872256707631666334039001378518619916", "price": "0.417", "size": "1200", "side": "BUY", "hash": "6df08685f54494c08dd2f8ba04ffdc1e2a895e75", "best_bid": "0.428", "best_ask": "0.429"}, {"asset_id": "78633590736077251574794513664747155551297291244492840448622550955320930591622", "price": "0.583", "size": "1200", "side": "SELL", "hash": "55027cd03fefbedb07cbd6571e9b8f8e8dd391cf", "best_bid": "0.571", "best_ask": "0.572"}], "timestamp": "1785163697469", "event_type": "price_change"}}
{"ts": 1785163697.513, "kind": "price_change", "data": {"market": "0x18b1c135d0a40c5894da9412e77311827d9caf16cf4cd6591b247a34730af919", "price_changes": [{"asset_id": "40081275558852222228080198821361202017557872256707631666334039001378518619916", "price": "0.418", "size": "6791.05", "side": "BUY", "hash": "fad0a03bcfc807d74b3f22052eb259e11f0a4a18", "best_bid": "0.428", "best_ask": "0.429"}, {"asset_id": "78633590736077251574794513664747155551297291244492840448622550955320930591622", "price": "0.582", "size": "6791.05", "side": "SELL", "hash": "ef2b097b7c5253a5bc8e6df845fe3a8c3e0f63f4", "best_bid": "0.571", "best_ask": "0.572"}], "timestamp": "1785163697513", "event_type": "price_change"}}
{"ts": 1785163697.54, "kind": "price_change", "data": {"market": "0x18b1c135d0a40c5894da9412e77311827d9caf16cf4cd6591b247a34730af919", "price_changes": [{"asset_id": "40081275558852222228080198821361202017557872256707631666334039001378518619916", "price": "0.417", "size": "1000", "side": "BUY", "hash": "56460f5dca8d5c296c3b07124529c0aef587943a", "best_bid": "0.428", "best_ask": "0.429"}, {"asset_id": "78633590736077251574794513664747155551297291244492840448622550955320930591622", "price": "0.583", "size": "1000", "side": "SELL", "hash": "f2d96959740506918b845f080b2ca9f916d17edf", "best_bid": "0.571", "best_ask": "0.572"}], "timestamp": "1785163697540", "event_type": "price_change"}}
{"ts": 1785163697.575, "kind": "price_change", "data": {"market": "0x18b1c135d0a40c5894da9412e77311827d9caf16cf4cd6591b247a34730af919", "price_changes": [{"asset_id": "40081275558852222228080198821361202017557872256707631666334039001378518619916", "price": "0.418", "size": "6991.05", "side": "BUY", "hash": "d2b3f8c2415b81a9196ffd7e07e5bb09f1b86424", "best_bid": "0.428", "best_ask": "0.429"}, {"asset_id": "78633590736077251574794513664747155551297291244492840448622550955320930591622", "price": "0.582", "size": "6991.05", "side": "SELL", "hash": "be457747d00f7c0f7276be7c33493c175be67610", "best_bid": "0.571", "best_ask": "0.572"}], "timestamp": "1785163697575", "event_type": "price_change"}}
{"ts": 1785163697.601, "kind": "price_change", "data": {"market": "0x18b1c135d0a40c5894da9412e77311827d9caf16cf4cd6591b247a34730af919", "price_changes": [{"asset_id": "40081275558852222228080198821361202017557872256707631666334039001378518619916", "price": "0.398", "size": "144.5", "side": "BUY", "hash": "df8ba79df5ddb998eea947c62c52fbd805a07d8b", "best_bid": "0.428", "best_ask": "0.429"}, {"asset_id": "78633590736077251574794513664747155551297291244492840448622550955320930591622", "price": "0.602", "size": "144.5", "side": "SELL", "hash": "de8f03979a3f55b637b1466bd3110d354c49d988", "best_bid": "0.571", "best_ask": "0.572"}], "timestamp": "1785163697601", "event_type": "price_change"}}
{"ts": 1785163697.715195, "kind": "orders_out", "data": [{"token_id": "40081275558852222228080198821361202017557872256707631666334039001378518619916", "side": "BUY", "price": 0.387, "size": 7.75}, {"token_id": "78633590736077251574794513664747155551297291244492840448622550955320930591622", "side": "BUY", "price": 0.529, "size": 5.67}]}
{"ts": 1785163697.726, "kind": "price_change", "data": {"market": "0x0f49db97f71c68b1e42a6d16e3de93d85dbf7d4148e3f018eb79e88554be9f75", "price_changes": [{"asset_id": "87854174148074652060467921081181402357467303721471806610111179101805869578687", "price": "0.795", "size": "3394.98", "side": "BUY", "hash": "bd1e9340fe0d49caa44b1c55916ef1b5fef74a62", "best_bid": "0.805", "best_ask": "0.806"}, {"asset_id": "54533043819946592547517511176940999955633860128497669742211153063842200957669", "price": "0.205", "size": "3394.98", "side": "SELL", "hash": "141ed24aaa392390c216de706ea44a320dff5a61", "best_bid": "0.194", "best_ask": "0.195"}], "timestamp": "1785163697726", "event_type": "price_change"}}
{"ts": 1785163697.726, "kind": "price_change", "data": {"market": "0x0f49db97f71c68b1e42a6d16e3de93d85dbf7d4148e3f018eb79e88554be9f75", "price_changes": [{"asset_id": "54533043819946592547517511176940999955633860128497669742211153063842200957669", "price": "0.184", "size": "1466", "side": "BUY", "hash": "141ed24aaa392390c216de706ea44a320dff5a61", "best_bid": "0.194", "best_ask": "0.195"}, {"asset_id": "87854174148074652060467921081181402357467303721471806610111179101805869578687", "price": "0.816", "size": "1466", "side": "SELL", "hash": "bd1e9340fe0d49caa44b1c55916ef1b5fef74a62", "best_bid": "0.805", "best_ask": "0.806"}], "timestamp": "1785163697726", "event_type": "price_change"}}
{"ts": 1785163698.834, "kind": "price_change", "data": {"market": "0x18b1c135d0a40c5894da9412e77311827d9caf16cf4cd6591b247a34730af919", "price_changes": [{"asset_id": "78633590736077251574794513664747155551297291244492840448622550955320930591622", "price": "0.374", "size": "0", "side": "BUY", "hash": "9ae1528c24ac603e439f33389adde6e82a274fa9", "best_bid": "0.571", "best_ask": "0.572"}, {"asset_id": "40081275558852222228080198821361202017557872256707631666334039001378518619916", "price": "0.626", "size": "0", "side": "SELL", "hash": "59275c150e1495b9ab54cdadf83b68ae29984715", "best_bid": "0.428", "best_ask": "0.429"}], "timestamp": "1785163698834", "event_type": "price_change"}}
{"ts": 1785163698.857, "kind": "price_change", "data": {"market": "0x18b1c135d0a40c5894da9412e77311827d9caf16cf4cd6591b247a34730af919", "price_changes": [{"asset_id": "78633590736077251574794513664747155551297291244492840448622550955320930591622", "price": "0.375", "size": "0", "side": "BUY", "hash": "89e118137bca2001ee378d62d17492e1ea9506ca", "best_bid": "0.571", "best_ask": "0.572"}, {"asset_id": "40081275558852222228080198821361202017557872256707631666334039001378518619916", "price": "0.625", "size": "0", "side": "SELL", "hash": "26c70d5f1365bf8b2b6d73e053fb6e607a1725a0", "best_bid": "0.428", "best_ask": "0.429"}], "timestamp": "1785163698857", "event_type": "price_change"}}
{"ts": 1785163698.887, "kind": "price_change", "data": {"market": "0x18b1c135d0a40c5894da9412e77311827d9caf16cf4cd6591b247a34730af919", "price_changes": [{"asset_id": "78633590736077251574794513664747155551297291244492840448622550955320930591622", "price": "0.371", "size": "400", "side": "BUY", "hash": "a714ede1e8586a791aed61e0157a2bd9a8f57683", "best_bid": "0.571", "best_ask": "0.572"}, {"asset_id": "40081275558852222228080198821361202017557872256707631666334039001378518619916", "price": "0.629", "size": "400", "side": "SELL", "hash": "383b0b4921d27c188b66c0ea2ee5c24e7800a33c", "best_bid": "0.428", "best_ask": "0.429"}], "timestamp": "1785163698887", "event_type": "price_change"}}
{"ts": 1785163699.933, "kind": "price_change", "data": {"market": "0x18b1c135d0a40c5894da9412e77311827d9caf16cf4cd6591b247a34730af919", "price_changes": [{"asset_id": "78633590736077251574794513664747155551297291244492840448622550955320930591622", "price": "0.551", "size": "26347.16", "side": "BUY", "hash": "218379100687523397be19fee14483fcbf9b4bf5", "best_bid": "0.571", "best_ask": "0.572"}, {"asset_id": "40081275558852222228080198821361202017557872256707631666334039001378518619916", "price": "0.449", "size": "26347.16", "side": "SELL", "hash": "1ea97edfd89de14fe7acfeb86b7c830398927a88", "best_bid": "0.428", "best_ask": "0.429"}], "timestamp": "1785163699933", "event_type": "price_change"}}
{"ts": 1785163699.985, "kind": "price_change", "data": {"market": "0x18b1c135d0a40c5894da9412e77311827d9caf16cf4cd6591b247a34730af919", "price_changes": [{"asset_id": "78633590736077251574794513664747155551297291244492840448622550955320930591622", "price": "0.311", "size": "48.28", "side": "BUY", "hash": "c042842f5549c8c487e1369506a81e86adb07a7c", "best_bid": "0.571", "best_ask": "0.572"}, {"asset_id": "40081275558852222228080198821361202017557872256707631666334039001378518619916", "price": "0.689", "size": "48.28", "side": "SELL", "hash": "857b790ba2cbce10ed16711da815024100bebc44", "best_bid": "0.428", "best_ask": "0.429"}], "timestamp": "1785163699985", "event_type": "price_change"}}
{"ts": 1785163700.171, "kind": "price_change", "data": {"market": "0x18b1c135d0a40c5894da9412e77311827d9caf16cf4cd6591b247a34730af919", "price_changes": [{"asset_id": "78633590736077251574794513664747155551297291244492840448622550955320930591622", "price": "0.551", "size": "28706.16", "side": "BUY", "hash": "3488c88528635e6abe6e60da572cfefde3cb1dbe", "best_bid": "0.571", "best_ask": "0.572"}, {"asset_id": "40081275558852222228080198821361202017557872256707631666334039001378518619916", "price": "0.449", "size": "28706.16", "side": "SELL", "hash": "38669557201822489ace14b4d3fc07ef060ce1c9", "best_bid": "0.428", "best_ask": "0.429"}], "timestamp": "1785163700171", "event_type": "price_change"}}
{"ts": 1785163702.124, "kind": "price_change", "data": {"market": "0x0f49db97f71c68b1e42a6d16e3de93d85dbf7d4148e3f018eb79e88554be9f75", "price_changes": [{"asset_id": "54533043819946592547517511176940999955633860128497669742211153063842200957669", "price": "0.158", "size": "61915", "side": "BUY", "hash": "5f9bbacde42f9a80a27263ad624e334db7675e99", "best_bid": "0.194", "best_ask": "0.195"}, {"asset_id": "87854174148074652060467921081181402357467303721471806610111179101805869578687", "price": "0.842", "size": "61915", "side": "SELL", "hash": "e5f661bff68bfb0b40940ad3a7ba0e7801147a5d", "best_bid": "0.805", "best_ask": "0.806"}], "timestamp": "1785163702124", "event_type": "price_change"}}
{"ts": 1785163702.76, "kind": "price_change", "data": {"market": "0x18b1c135d0a40c5894da9412e77311827d9caf16cf4cd6591b247a34730af919", "price_changes": [{"asset_id": "40081275558852222228080198821361202017557872256707631666334039001378518619916", "price": "0.398", "size": "14592.5", "side": "BUY", "hash": "a68315bf2e7ac5bd2f19af61c1fdf777faed303d", "best_bid": "0.428", "best_ask": "0.429"}, {"asset_id": "78633590736077251574794513664747155551297291244492840448622550955320930591622", "price": "0.602", "size": "14592.5", "side": "SELL", "hash": "116ec8d886454065149a7cd7d0cf23d475f7b4ec", "best_bid": "0.571", "best_ask": "0.572"}], "timestamp": "1785163702760", "event_type": "price_change"}}
{"ts": 1785163704.82, "kind": "price_change", "data": {"market": "0x0f49db97f71c68b1e42a6d16e3de93d85dbf7d4148e3f018eb79e88554be9f75", "price_changes": [{"asset_id": "54533043819946592547517511176940999955633860128497669742211153063842200957669", "price": "0.003", "size": "14406.33", "side": "BUY", "hash": "51bacdde12f7f4fbdadd9c1e831352d64d111b61", "best_bid": "0.194", "best_ask": "0.195"}, {"asset_id": "87854174148074652060467921081181402357467303721471806610111179101805869578687", "price": "0.997", "size": "14406.33", "side": "SELL", "hash": "3f49216b7e581324ad6af0824cb3ec0946b06457", "best_bid": "0.805", "best_ask": "0.806"}], "timestamp": "1785163704820", "event_type": "price_change"}}
{"ts": 1785163705.364, "kind": "price_change", "data": {"market": "0x0f49db97f71c68b1e42a6d16e3de93d85dbf7d4148e3f018eb79e88554be9f75", "price_changes": [{"asset_id": "87854174148074652060467921081181402357467303721471806610111179101805869578687", "price": "0.795", "size": "2828.98", "side": "BUY", "hash": "07d052102070ec46cd1b6c80b7475969496ca919", "best_bid": "0.805", "best_ask": "0.806"}, {"asset_id": "54533043819946592547517511176940999955633860128497669742211153063842200957669", "price": "0.205", "size": "2828.98", "side": "SELL", "hash": "88851c9db12b4341a66dd714ee448c55fa1609e3", "best_bid": "0.194", "best_ask": "0.195"}], "timestamp": "1785163705364", "event_type": "price_change"}}
{"ts": 1785163705.438, "kind": "price_change", "data": {"market": "0x0f49db97f71c68b1e42a6d16e3de93d85dbf7d4148e3f018eb79e88554be9f75", "price_changes": [{"asset_id": "87854174148074652060467921081181402357467303721471806610111179101805869578687", "price": "0.795", "size": "3394.98", "side": "BUY", "hash": "8b57d73343bd03ac56c497d9fa7bad19610159d6", "best_bid": "0.805", "best_ask": "0.806"}, {"asset_id": "54533043819946592547517511176940999955633860128497669742211153063842200957669", "price": "0.205", "size": "3394.98", "side": "SELL", "hash": "a5ae552183225f362492a40f507c5d49f0479f6f", "best_bid": "0.194", "best_ask": "0.195"}], "timestamp": "1785163705438", "event_type": "price_change"}}
{"ts": 1785163705.455, "kind": "price_change", "data": {"market": "0x18b1c135d0a40c5894da9412e77311827d9caf16cf4cd6591b247a34730af919", "price_changes": [{"asset_id": "40081275558852222228080198821361202017557872256707631666334039001378518619916", "price": "0.41", "size": "2931.23", "side": "BUY", "hash": "9603b7f8dff2ead21f7e143d1a1cc58122e6d315", "best_bid": "0.428", "best_ask": "0.429"}, {"asset_id": "78633590736077251574794513664747155551297291244492840448622550955320930591622", "price": "0.59", "size": "2931.23", "side": "SELL", "hash": "5f0e283d1537e9db68057748d369e8245323226a", "best_bid": "0.571", "best_ask": "0.572"}], "timestamp": "1785163705455", "event_type": "price_change"}}
{"ts": 1785163705.902, "kind": "price_change", "data": {"market": "0x18b1c135d0a40c5894da9412e77311827d9caf16cf4cd6591b247a34730af919", "price_changes": [{"asset_id": "40081275558852222228080198821361202017557872256707631666334039001378518619916", "price": "0.418", "size": "5915.05", "side": "BUY", "hash": "feb8b873d411f96e562f22f0d76b594053178c65", "best_bid": "0.428", "best_ask": "0.429"}, {"asset_id": "78633590736077251574794513664747155551297291244492840448622550955320930591622", "price": "0.582", "size": "5915.05", "side": "SELL", "hash": "d9b9c9c5d7fd4d5d73bc02ac05386c4039d99c7e", "best_bid": "0.571", "best_ask": "0.572"}], "timestamp": "1785163705902", "event_type": "price_change"}}
{"ts": 1785163705.93, "kind": "price_change", "data": {"market": "0x18b1c135d0a40c5894da9412e77311827d9caf16cf4cd6591b247a34730af919", "price_changes": [{"asset_id": "40081275558852222228080198821361202017557872256707631666334039001378518619916", "price": "0.418", "size": "5715.05", "side": "BUY", "hash": "35d15170c746f0282fa2b885916735c59587446d", "best_bid": "0.428", "best_ask": "0.429"}, {"asset_id": "78633590736077251574794513664747155551297291244492840448622550955320930591622", "price": "0.582", "size": "5715.05", "side": "SELL", "hash": "9942608e9b9273712b16feae06a7a2ab73a37c47", "best_bid": "0.571", "best_ask": "0.572"}], "timestamp": "1785163705930", "event_type": "price_change"}}
{"ts": 1785163705.973, "kind": "price_change", "data": {"market": "0x18b1c135d0a40c5894da9412e77311827d9caf16cf4cd6591b247a34730af919", "price_changes": [{"asset_id": "40081275558852222228080198821361202017557872256707631666334039001378518619916", "price": "0.417", "size": "1200", "side": "BUY", "hash": "a35a8713e250fc8a9790da858abace8a12031a61", "best_bid": "0.428", "best_ask": "0.429"}, {"asset_id": "78633590736077251574794513664747155551297291244492840448622550955320930591622", "price": "0.583", "size": "1200", "side": "SELL", "hash": "b55e2014a6fc522f78150ac685f4b75e613e4061", "best_bid": "0.571", "best_ask": "0.572"}], "timestamp": "1785163705973", "event_type": "price_change"}}
{"ts": 1785163705.975, "kind": "price_change", "data": {"market": "0x18b1c135d0a40c5894da9412e77311827d9caf16cf4cd6591b247a34730af919", "price_changes": [{"asset_id": "40081275558852222228080198821361202017557872256707631666334039001378518619916", "price": "0.418", "size": "6791.05", "side": "BUY", "hash": "bdf5147b15e3a46634319f828a28d47014ec35ef", "best_bid": "0.428", "best_ask": "0.429"}, {"asset_id": "78633590736077251574794513664747155551297291244492840448622550955320930591622", "price": "0.582", "size": "6791.05", "side": "SELL", "hash": "9a4a6268f2926c58362159556602fa0354610063", "best_bid": "0.571", "best_ask": "0.572"}], "timestamp": "1785163705975", "event_type": "price_change"}}
{"ts": 1785163706.009, "kind": "price_change", "data": {"market": "0x18b1c135d0a40c5894da9412e77311827d9caf16cf4cd6591b247a34730af919", "price_changes": [{"asset_id": "40081275558852222228080198821361202017557872256707631666334039001378518619916", "price": "0.417", "size": "1000", "side": "BUY", "hash": "47b55e3b0a53ae703ae4adb65504610b9fd55ee3", "best_bid": "0.428", "best_ask": "0.429"}, {"asset_id": "78633590736077251574794513664747155551297291244492840448622550955320930591622", "price": "0.583", "size": "1000", "side": "SELL", "hash": "189dc3731f6d0c83ae03503be3fcb9b6a192eb3a", "best_bid": "0.571", "best_ask": "0.572"}], "timestamp": "1785163706009", "event_type": "price_change"}}
{"ts": 1785163706.051, "kind": "price_change", "data": {"market": "0x18b1c135d0a40c5894da9412e77311827d9caf16cf4cd6591b247a34730af919", "price_changes": [{"asset_id": "40081275558852222228080198821361202017557872256707631666334039001378518619916", "price": "0.418", "size": "6991.05", "side": "BUY", "hash": "4ddb2579aba16ebb2598c76d68b22a2598b72a1e", "best_bid": "0.428", "best_ask": "0.429"}, {"asset_id": "78633590736077251574794513664747155551297291244492840448622550955320930591622", "price": "0.582", "size": "6991.05", "side": "SELL", "hash": "683f0a8fa64405bf299899003e2a6da40861750b", "best_bid": "0.571", "best_ask": "0.572"}], "timestamp": "1785163706051", "event_type": "price_change"}}
{"ts": 1785163706.119, "kind": "price_change", "data": {"market": "0x18b1c135d0a40c5894da9412e77311827d9caf16cf4cd6591b247a34730af919", "price_changes": [{"asset_id": "40081275558852222228080198821361202017557872256707631666334039001378518619916", "price": "0.41", "size": "2947.28", "side": "BUY", "hash": "f873cc52083e214aaade3d93a01f597c544b5c5b", "best_bid": "0.428", "best_ask": "0.429"}, {"asset_id": "78633590736077251574794513664747155551297291244492840448622550955320930591622", "price": "0.59", "size": "2947.28", "side": "SELL", "hash": "073a5dfe7a440cc0af5667d8a5d04642a602f2af", "best_bid": "0.571", "best_ask": "0.572"}], "timestamp": "1785163706119", "event_type": "price_change"}}
{"ts": 1785163708.002, "kind": "price_change", "data": {"market": "0x18b1c135d0a40c5894da9412e77311827d9caf16cf4cd6591b247a34730af919", "price_changes": [{"asset_id": "78633590736077251574794513664747155551297291244492840448622550955320930591622", "price": "0.08", "size": "0", "side": "BUY", "hash": "3ab11ed7364eb0344ab06a35218e529ad499cf7d", "best_bid": "0.571", "best_ask": "0.572"}, {"asset_id": "40081275558852222228080198821361202017557872256707631666334039001378518619916", "price": "0.92", "size": "0", "side": "SELL", "hash": "0de810d51f440cd1586a13f160ab06a29133f3e9", "best_bid": "0.428", "best_ask": "0.429"}], "timestamp": "1785163708002", "event_type": "price_change"}}
{"ts": 1785163708.002, "kind": "price_change", "data": {"market": "0x18b1c135d0a40c5894da9412e77311827d9caf16cf4cd6591b247a34730af919", "price_changes": [{"asset_id": "40081275558852222228080198821361202017557872256707631666334039001378518619916", "price": "0.03", "size": "118750", "side": "BUY", "hash": "0de810d51f440cd1586a13f160ab06a29133f3e9", "best_bid": "0.428", "best_ask": "0.429"}, {"asset_id": "78633590736077251574794513664747155551297291244492840448622550955320930591622", "price": "0.97", "size": "118750", "side": "SELL", "hash": "3ab11ed7364eb0344ab06a35218e529ad499cf7d", "best_bid": "0.571", "best_ask": "0.572"}], "timestamp": "1785163708002", "event_type": "price_change"}}
{"ts": 1785163708.894, "kind": "price_change", "data": {"market": "0x0f49db97f71c68b1e42a6d16e3de93d85dbf7d4148e3f018eb79e88554be9f75", "price_changes": [{"asset_id": "54533043819946592547517511176940999955633860128497669742211153063842200957669", "price": "0.184", "size": "1766", "side": "BUY", "hash": "bf067a93fcf0ca0fb6da79837549b8a5ca630f6d", "best_bid": "0.194", "best_ask": "0.195"}, {"asset_id": "87854174148074652060467921081181402357467303721471806610111179101805869578687", "price": "0.816", "size": "1766", "side": "SELL", "hash": "737dcf859fd6f0a5672abf8c5626902600148662", "best_bid": "0.805", "best_ask": "0.806"}], "timestamp": "1785163708894", "event_type": "price_change"}}
{"ts": 1785163708.898, "kind": "price_change", "data": {"market": "0x0f49db97f71c68b1e42a6d16e3de93d85dbf7d4148e3f018eb79e88554be9f75", "price_changes": [{"asset_id": "87854174148074652060467921081181402357467303721471806610111179101805869578687", "price": "0.795", "size": "3694.98", "side": "BUY", "hash": "39c3df40068912215ec2baf36e32d1c993f1b929", "best_bid": "0.805", "best_ask": "0.806"}, {"asset_id": "54533043819946592547517511176940999955633860128497669742211153063842200957669", "price": "0.205", "size": "3694.98", "side": "SELL", "hash": "8455cd83563613045205b98b2390182138509434", "best_bid": "0.194", "best_ask": "0.195"}], "timestamp": "1785163708898", "event_type": "price_change"}}
{"ts": 1785163708.912, "kind": "price_change", "data": {"market": "0x0f49db97f71c68b1e42a6d16e3de93d85dbf7d4148e3f018eb79e88554be9f75", "price_changes": [{"asset_id": "54533043819946592547517511176940999955633860128497669742211153063842200957669", "price": "0.174", "size": "10919", "side": "BUY", "hash": "f7ac5d67b25e063bf1a850c3d9502a2e60f2a0cd", "best_bid": "0.194", "best_ask": "0.195"}, {"asset_id": "87854174148074652060467921081181402357467303721471806610111179101805869578687", "price": "0.826", "size": "10919", "side": "SELL", "hash": "305a5dbc6add6fa69e198e10c160730218888442", "best_bid": "0.805", "best_ask": "0.806"}], "timestamp": "1785163708912", "event_type": "price_change"}}
{"ts": 1785163708.913, "kind": "price_change", "data": {"market": "0x0f49db97f71c68b1e42a6d16e3de93d85dbf7d4148e3f018eb79e88554be9f75", "price_changes": [{"asset_id": "87854174148074652060467921081181402357467303721471806610111179101805869578687", "price": "0.785", "size": "2588", "side": "BUY", "hash": "2ea40459e8a32f6cdac4c9d7978bce8de9575f18", "best_bid": "0.805", "best_ask": "0.806"}, {"asset_id": "54533043819946592547517511176940999955633860128497669742211153063842200957669", "price": "0.215", "size": "2588", "side": "SELL", "hash": "d0b7436feebd1e41aaf0a860ec1792989d30bde3", "best_bid": "0.194", "best_ask": "0.195"}], "timestamp": "1785163708913", "event_type": "price_change"}}
{"ts": 1785163710.001, "kind": "price_change", "data": {"market": "0x0f49db97f71c68b1e42a6d16e3de93d85dbf7d4148e3f018eb79e88554be9f75", "price_changes": [{"asset_id": "87854174148074652060467921081181402357467303721471806610111179101805869578687", "price": "0.37", "size": "0", "side": "BUY", "hash": "0d543f5ef06ba9867c08c99354f2a4fb9becd530", "best_bid": "0.805", "best_ask": "0.806"}, {"asset_id": "54533043819946592547517511176940999955633860128497669742211153063842200957669", "price": "0.63", "size": "0", "side": "SELL", "hash": "84b7fee60be23767cbbe7420786f8d6eecc2f8f1", "best_bid": "0.194", "best_ask": "0.195"}], "timestamp": "1785163710001", "event_type": "price_change"}}
{"ts": 1785163712.828, "kind": "price_change", "data": {"market": "0x18b1c135d0a40c5894da9412e77311827d9caf16cf4cd6591b247a34730af919", "price_changes": [{"asset_id": "40081275558852222228080198821361202017557872256707631666334039001378518619916", "price": "0.418", "size": "6918.25", "side": "BUY", "hash": "102b9572a4da15a502316b85638e0793b4386de2", "best_bid": "0.428", "best_ask": "0.429"}, {"asset_id": "78633590736077251574794513664747155551297291244492840448622550955320930591622", "price": "0.582", "size": "6918.25", "side": "SELL", "hash": "de86b50b68b0538c31f5e3d34aa09552b34f77df", "best_bid": "0.571", "best_ask": "0.572"}], "timestamp": "1785163712828", "event_type": "price_change"}}
{"ts": 1785163714.183, "kind": "price_change", "data": {"market": "0x0f49db97f71c68b1e42a6d16e3de93d85dbf7d4148e3f018eb79e88554be9f75", "price_changes": [{"asset_id": "87854174148074652060467921081181402357467303721471806610111179101805869578687", "price": "0.37", "size": "2702", "side": "BUY", "hash": "adc5ddac4c8b5dc0a333f32013eb7d761a17c787", "best_bid": "0.805", "best_ask": "0.806"}, {"asset_id": "54533043819946592547517511176940999955633860128497669742211153063842200957669", "price": "0.63", "size": "2702", "side": "SELL", "hash": "5f5e50daeb717bcbdc62e72f3bcea700391e73d9", "best_bid": "0.194", "best_ask": "0.195"}], "timestamp": "1785163714183", "event_type": "price_change"}}
{"ts": 1785163714.490717, "kind": "orders_out", "data": [{"token_id": "54533043819946592547517511176940999955633860128497669742211153063842200957669", "side": "BUY", "price": 0.153, "size": 19.61}]}
{"ts": 1785163714.634, "kind": "price_change", "data": {"market": "0x18b1c135d0a40c5894da9412e77311827d9caf16cf4cd6591b247a34730af919", "price_changes": [{"asset_id": "78633590736077251574794513664747155551297291244492840448622550955320930591622", "price": "0.482", "size": "161.09", "side": "BUY", "hash": "69e05e97b7532b42a2ed44d44c3961cbb429ac65", "best_bid": "0.571", "best_ask": "0.572"}, {"asset_id": "40081275558852222228080198821361202017557872256707631666334039001378518619916", "price": "0.518", "size": "161.09", "side": "SELL", "hash": "6c254acc8b6acde54cf409c0e7a0c237f503fe06", "best_bid": "0.428", "best_ask": "0.429"}], "timestamp": "1785163714634", "event_type": "price_change"}}
{"ts": 1785163714.663, "kind": "price_change", "data": {"market": "0x18b1c135d0a40c5894da9412e77311827d9caf16cf4cd6591b247a34730af919", "price_changes": [{"asset_id": "78633590736077251574794513664747155551297291244492840448622550955320930591622", "price": "0.482", "size": "0", "side": "BUY", "hash": "89686b92de0027d86543b9dbc0322a4e70e189c8", "best_bid": "0.571", "best_ask": "0.572"}, {"asset_id": "40081275558852222228080198821361202017557872256707631666334039001378518619916", "price": "0.518", "size": "0", "side": "SELL", "hash": "215c8a95cb6654e43c25b411cfaac2df4282ef9f", "best_bid": "0.428", "best_ask": "0.429"}], "timestamp": "1785163714663", "event_type": "price_change"}}
{"ts": 1785163714.663, "kind": "price_change", "data": {"market": "0x18b1c135d0a40c5894da9412e77311827d9caf16cf4cd6591b247a34730af919", "price_changes": [{"asset_id": "78633590736077251574794513664747155551297291244492840448622550955320930591622", "price": "0.485", "size": "0", "side": "BUY", "hash": "89686b92de0027d86543b9dbc0322a4e70e189c8", "best_bid": "0.571", "best_ask": "0.572"}, {"asset_id": "40081275558852222228080198821361202017557872256707631666334039001378518619916", "price": "0.515", "size": "0", "side": "SELL", "hash": "215c8a95cb6654e43c25b411cfaac2df4282ef9f", "best_bid": "0.428", "best_ask": "0.429"}], "timestamp": "1785163714663", "event_type": "price_change"}}
{"ts": 1785163714.665, "kind": "price_change", "data": {"market": "0x18b1c135d0a40c5894da9412e77311827d9caf16cf4cd6591b247a34730af919", "price_changes": [{"asset_id": "78633590736077251574794513664747155551297291244492840448622550955320930591622", "price": "0.485", "size": "30", "side": "BUY", "hash": "b912bf9a71d928d19e87deb4e4271e0bb09fcd3c", "best_bid": "0.571", "best_ask": "0.572"}, {"asset_id": "40081275558852222228080198821361202017557872256707631666334039001378518619916", "price": "0.515", "size": "30", "side": "SELL", "hash": "8b2ef19a0affdeaec8fe375a85acda8b5da260e2", "best_bid": "0.428", "best_ask": "0.429"}], "timestamp": "1785163714665", "event_type": "price_change"}}
{"ts": 1785163714.666, "kind": "price_change", "data": {"market": "0x18b1c135d0a40c5894da9412e77311827d9caf16cf4cd6591b247a34730af919", "price_changes": [{"asset_id": "78633590736077251574794513664747155551297291244492840448622550955320930591622", "price": "0.486", "size": "10", "side": "BUY", "hash": "f9d0292ab48df21088e7584d2617c080fd8e7618", "best_bid": "0.571", "best_ask": "0.572"}, {"asset_id": "40081275558852222228080198821361202017557872256707631666334039001378518619916", "price": "0.514", "size": "10", "side": "SELL", "hash": "87851380b628c1061254d232e42126cc41e3865e", "best_bid": "0.428", "best_ask": "0.429"}], "timestamp": "1785163714666", "event_type": "price_change"}}
{"ts": 1785163714.694, "kind": "price_change", "data": {"market": "0x18b1c135d0a40c5894da9412e77311827d9caf16cf4cd6591b247a34730af919", "price_changes": [{"asset_id": "78633590736077251574794513664747155551297291244492840448622550955320930591622", "price": "0.486", "size": "0", "side": "BUY", "hash": "503af640c9e0d8df224e6349835c5084650af5ac", "best_bid": "0.571", "best_ask": "0.572"}, {"asset_id": "40081275558852222228080198821361202017557872256707631666334039001378518619916", "price": "0.514", "size": "0", "side": "SELL", "hash": "368e0cb0c47d364b412bdab2d427b2b7379d5c78", "best_bid": "0.428", "best_ask": "0.429"}], "timestamp": "1785163714694", "event_type": "price_change"}}
{"ts": 1785163714.694, "kind": "price_change", "data": {"market": "0x18b1c135d0a40c5894da9412e77311827d9caf16cf4cd6591b247a34730af919", "price_changes": [{"asset_id": "78633590736077251574794513664747155551297291244492840448622550955320930591622", "price": "0.485", "size": "0", "side": "BUY", "hash": "503af640c9e0d8df224e6349835c5084650af5ac", "best_bid": "0.571", "best_ask": "0.572"}, {"asset_id": "40081275558852222228080198821361202017557872256707631666334039001378518619916", "price": "0.515", "size": "0", "side": "SELL", "hash": "368e0cb0c47d364b412bdab2d427b2b7379d5c78", "best_bid": "0.428", "best_ask": "0.429"}], "timestamp": "1785163714694", "event_type": "price_change"}}
{"ts": 1785163714.722, "kind": "price_change", "data": {"market": "0x18b1c135d0a40c5894da9412e77311827d9caf16cf4cd6591b247a34730af919", "price_changes": [{"asset_id": "78633590736077251574794513664747155551297291244492840448622550955320930591622", "price": "0.482", "size": "30", "side": "BUY", "hash": "6ac4c8dae672de4628cd521b7151a2fd2b9fdc21", "best_bid": "0.571", "best_ask": "0.572"}, {"asset_id": "40081275558852222228080198821361202017557872256707631666334039001378518619916", "price": "0.518", "size": "30", "side": "SELL", "hash": "9be1db686d1caea665c1532a51f9885cd3f79aed", "best_bid": "0.428", "best_ask": "0.429"}], "timestamp": "1785163714722", "event_type": "price_change"}}
{"ts": 1785163714.723, "kind": "price_change", "data": {"market": "0x18b1c135d0a40c5894da9412e77311827d9caf16cf4cd6591b247a34730af919", "price_changes": [{"asset_id": "78633590736077251574794513664747155551297291244492840448622550955320930591622", "price": "0.482", "size": "40", "side": "BUY", "hash": "5c8dfd3e5096a1adebda2896debae2c9843172b3", "best_bid": "0.571", "best_ask": "0.572"}, {"asset_id": "40081275558852222228080198821361202017557872256707631666334039001378518619916", "price": "0.518", "size": "40", "side": "SELL", "hash": "5b5351d29f6fde63bd91e9727f2a4bbfba65dcb3", "best_bid": "0.428", "best_ask": "0.429"}], "timestamp": "1785163714723", "event_type": "price_change"}}
{"ts": 1785163714.939981, "kind": "orders_out", "data": [{"token_id": "40081275558852222228080198821361202017557872256707631666334039001378518619916", "side": "BUY", "price": 0.387, "size": 7.75}, {"token_id": "78633590736077251574794513664747155551297291244492840448622550955320930591622", "side": "BUY", "price": 0.529, "size": 5.67}]}
{"ts": 1785163716.077, "kind": "price_change", "data": {"market": "0x18b1c135d0a40c5894da9412e77311827d9caf16cf4cd6591b247a34730af919", "price_changes": [{"asset_id": "40081275558852222228080198821361202017557872256707631666334039001378518619916", "price": "0.03", "size": "158750", "side": "BUY", "hash": "a97621c34159a555ef5c02b10d25ca52284482b4", "best_bid": "0.428", "best_ask": "0.429"}, {"asset_id": "78633590736077251574794513664747155551297291244492840448622550955320930591622", "price": "0.97", "size": "158750", "side": "SELL", "hash": "2e5d27cc645f4f6b3abb5d776d910515e57ba758", "best_bid": "0.571", "best_ask": "0.572"}], "timestamp": "1785163716077", "event_type": "price_change"}}
{"ts": 1785163716.078, "kind": "price_change", "data": {"market": "0x18b1c135d0a40c5894da9412e77311827d9caf16cf4cd6591b247a34730af919", "price_changes": [{"asset_id": "78633590736077251574794513664747155551297291244492840448622550955320930591622", "price": "0.08", "size": "15000", "side": "BUY", "hash": "9664d1889854f8d5383c396e0e024003647a7ab1", "best_bid": "0.571", "best_ask": "0.572"}, {"asset_id": "40081275558852222228080198821361202017557872256707631666334039001378518619916", "price": "0.92", "size": "15000", "side": "SELL", "hash": "6ba2c14bc4f445372496da45f7293314db2dccb6", "best_bid": "0.428", "best_ask": "0.429"}], "timestamp": "1785163716078", "event_type": "price_change"}}
{"ts": 1785163717.002, "kind": "price_change", "data": {"market": "0x0f49db97f71c68b1e42a6d16e3de93d85dbf7d4148e3f018eb79e88554be9f75", "price_changes": [{"asset_id": "87854174148074652060467921081181402357467303721471806610111179101805869578687", "price": "0.02", "size": "13000", "side": "BUY", "hash": "77b9e922c6edd3059d0adf60196983c423393d6d", "best_bid": "0.805", "best_ask": "0.806"}, {"asset_id": "54533043819946592547517511176940999955633860128497669742211153063842200957669", "price": "0.98", "size": "13000", "side": "SELL", "hash": "c3c8d2e700a295ad0f5c05676f62e5ab0af11e97", "best_bid": "0.194", "best_ask": "0.195"}], "timestamp": "1785163717002", "event_type": "price_change"}}
{"ts": 1785163717.002, "kind": "price_change", "data": {"market": "0x0f49db97f71c68b1e42a6d16e3de93d85dbf7d4148e3f018eb79e88554be9f75", "price_changes": [{"asset_id": "87854174148074652060467921081181402357467303721471806610111179101805869578687", "price": "0.02", "size": "13000", "side": "BUY", "hash": "77b9e922c6edd3059d0adf60196983c423393d6d", "best_bid": "0.805", "best_ask": "0.806"}, {"asset_id": "54533043819946592547517511176940999955633860128497669742211153063842200957669", "price": "0.98", "size": "13000", "side": "SELL", "hash": "c3c8d2e700a295ad0f5c05676f62e5ab0af11e97", "best_bid": "0.194", "best_ask": "0.195"}], "timestamp": "1785163717002", "event_type": "price_change"}}
{"ts": 1785163717.004, "kind": "price_change", "data": {"market": "0x0f49db97f71c68b1e42a6d16e3de93d85dbf7d4148e3f018eb79e88554be9f75", "price_changes": [{"asset_id": "87854174148074652060467921081181402357467303721471806610111179101805869578687", "price": "0.02", "size": "13000", "side": "BUY", "hash": "a639a42f6375912e8671c1f2335d4aede7d867cb", "best_bid": "0.805", "best_ask": "0.806"}, {"asset_id": "54533043819946592547517511176940999955633860128497669742211153063842200957669", "price": "0.98", "size": "13000", "side": "SELL", "hash": "10c6dfbc6a9e18298e368cd459bd9fd2d038a606", "best_bid": "0.194", "best_ask": "0.195"}], "timestamp": "1785163717004", "event_type": "price_change"}}
{"ts": 1785163717.379, "kind": "price_change", "data": {"market": "0x0f49db97f71c68b1e42a6d16e3de93d85dbf7d4148e3f018eb79e88554be9f75", "price_changes": [{"asset_id": "87854174148074652060467921081181402357467303721471806610111179101805869578687", "price": "0.001", "size": "6146756.01", "side": "BUY", "hash": "639859490fd4a19ace819826624ab1ea41441a0d", "best_bid": "0.805", "best_ask": "0.806"}, {"asset_id": "54533043819946592547517511176940999955633860128497669742211153063842200957669", "price": "0.999", "size": "6146756.01", "side": "SELL", "hash": "5c96a788c09ade678e74d9694632a23cc1abf207", "best_bid": "0.194", "best_ask": "0.195"}], "timestamp": "1785163717379", "event_type": "price_change"}}
{"ts": 1785163717.382, "kind": "price_change", "data": {"market": "0x0f49db97f71c68b1e42a6d16e3de93d85dbf7d4148e3f018eb79e88554be9f75", "price_changes": [{"asset_id": "87854174148074652060467921081181402357467303721471806610111179101805869578687", "price": "0.001", "size": "6147766.01", "side": "BUY", "hash": "a4326112b1cd7cb4e618b96411fbac98b2a47ff2", "best_bid": "0.805", "best_ask": "0.806"}, {"asset_id": "54533043819946592547517511176940999955633860128497669742211153063842200957669", "price": "0.999", "size": "6147766.01", "side": "SELL", "hash": "88cccca99772fb443f0567f4c76cd27dbe9eabfe", "best_bid": "0.194", "best_ask": "0.195"}], "timestamp": "1785163717382", "event_type": "price_change"}}
{"ts": 1785163717.915, "kind": "price_change", "data": {"market": "0x18b1c135d0a40c5894da9412e77311827d9caf16cf4cd6591b247a34730af919", "price_changes": [{"asset_id": "40081275558852222228080198821361202017557872256707631666334039001378518619916", "price": "0.412", "size": "11211.7", "side": "BUY", "hash": "9b827951c862f78a95138947d3681a486f365dc0", "best_bid": "0.428", "best_ask": "0.429"}, {"asset_id": "78633590736077251574794513664747155551297291244492840448622550955320930591622", "price": "0.588", "size": "11211.7", "side": "SELL", "hash": "d4ceace7dcc64bba86e8387217f5c0172f605649", "best_bid": "0.571", "best_ask": "0.572"}], "timestamp": "1785163717915", "event_type": "price_change"}}
{"ts": 1785163718.801, "kind": "price_change", "data": {"market": "0x0f49db97f71c68b1e42a6d16e3de93d85dbf7d4148e3f018eb79e88554be9f75", "price_changes": [{"asset_id": "54533043819946592547517511176940999955633860128497669742211153063842200957669", "price": "0.007", "size": "53571.42", "side": "BUY", "hash": "c28253044f9910c55717c77d1b6f90216d3eac38", "best_bid": "0.194", "best_ask": "0.195"}, {"asset_id": "87854174148074652060467921081181402357467303721471806610111179101805869578687", "price": "0.993", "size": "53571.42", "side": "SELL", "hash": "238c92d7d36bccdbc461e7029611e49fa8c8b980", "best_bid": "0.805", "best_ask": "0.806"}], "timestamp": "1785163718801", "event_type": "price_change"}}
{"ts": 1785163718.809, "kind": "price_change", "data": {"market": "0x0f49db97f71c68b1e42a6d16e3de93d85dbf7d4148e3f018eb79e88554be9f75", "price_changes": [{"asset_id": "54533043819946592547517511176940999955633860128497669742211153063842200957669", "price": "0.009", "size": "13888.88", "side": "BUY", "hash": "2b659fef4c7f440d741eda206ad7d22efa90cd0d", "best_bid": "0.194", "best_ask": "0.195"}, {"asset_id": "87854174148074652060467921081181402357467303721471806610111179101805869578687", "price": "0.991", "size": "13888.88", "side": "SELL", "hash": "cb588387dd9887880bbe55f440032edaf81900e9", "best_bid": "0.805", "best_ask": "0.806"}], "timestamp": "1785163718809", "event_type": "price_change"}}
{"ts": 1785163719.108, "kind": "price_change", "data": {"market": "0x18b1c135d0a40c5894da9412e77311827d9caf16cf4cd6591b247a34730af919", "price_changes": [{"asset_id": "40081275558852222228080198821361202017557872256707631666334039001378518619916", "price": "0.506", "size": "0", "side": "SELL", "hash": "231ffddd96538b527bcb29d9d88e9a4baafd113e", "best_bid": "0.428", "best_ask": "0.429"}, {"asset_id": "78633590736077251574794513664747155551297291244492840448622550955320930591622", "price": "0.494", "size": "0", "side": "BUY", "hash": "51069dc1852d45e412e0557bba3e6566f55369eb", "best_bid": "0.571", "best_ask": "0.572"}], "timestamp": "1785163719108", "event_type": "price_change"}}
{"ts": 1785163719.171, "kind": "price_change", "data": {"market": "0x18b1c135d0a40c5894da9412e77311827d9caf16cf4cd6591b247a34730af919", "price_changes": [{"asset_id": "78633590736077251574794513664747155551297291244492840448622550955320930591622", "price": "0.549", "size": "0", "side": "BUY", "hash": "9765665269e537949c1f6b42ff328386aa223580", "best_bid": "0.571", "best_ask": "0.572"}, {"asset_id": "40081275558852222228080198821361202017557872256707631666334039001378518619916", "price": "0.451", "size": "0", "side": "SELL", "hash": "c9c42f0f4b86159b991a43a3c3e2b2d228a62f73", "best_bid": "0.428", "best_ask": "0.429"}], "timestamp": "1785163719171", "event_type": "price_change"}}
{"ts": 1785163719.359, "kind": "price_change", "data": {"market": "0x18b1c135d0a40c5894da9412e77311827d9caf16cf4cd6591b247a34730af919", "price_changes": [{"asset_id": "40081275558852222228080198821361202017557872256707631666334039001378518619916", "price": "0.171", "size": "1947.36", "side": "BUY", "hash": "918337afaa7bb02bae406a3dc8df91b5983162ee", "best_bid": "0.428", "best_ask": "0.429"}, {"asset_id": "78633590736077251574794513664747155551297291244492840448622550955320930591622", "price": "0.829", "size": "1947.36", "side": "SELL", "hash": "aa77e765ba590731e087709d7244245d22402e4d", "best_bid": "0.571", "best_ask": "0.572"}], "timestamp": "1785163719359", "event_type": "price_change"}}
{"ts": 1785163719.365, "kind": "price_change", "data": {"market": "0x18b1c135d0a40c5894da9412e77311827d9caf16cf4cd6591b247a34730af919", "price_changes": [{"asset_id": "40081275558852222228080198821361202017557872256707631666334039001378518619916", "price": "0.171", "size": "2970.75", "side": "BUY", "hash": "1599fda0227fb051a49da37d55cd7e41382b19c3", "best_bid": "0.428", "best_ask": "0.429"}, {"asset_id": "78633590736077251574794513664747155551297291244492840448622550955320930591622", "price": "0.829", "size": "2970.75", "side": "SELL", "hash": "e334c531c05772e189036f8c92109c0c5b2a357b", "best_bid": "0.571", "best_ask": "0.572"}], "timestamp": "1785163719365", "event_type": "price_change"}}
{"ts": 1785163719.439, "kind": "price_change", "data": {"market": "0x18b1c135d0a40c5894da9412e77311827d9caf16cf4cd6591b247a34730af919", "price_changes": [{"asset_id": "78633590736077251574794513664747155551297291244492840448622550955320930591622", "price": "0.549", "size": "9.99", "side": "BUY", "hash": "61a09f65fbbfa3a05893e802ec002d24104682df", "best_bid": "0.571", "best_ask": "0.572"}, {"asset_id": "40081275558852222228080198821361202017557872256707631666334039001378518619916", "price": "0.451", "size": "9.99", "side": "SELL", "hash": "5975c537b072b4f5dbfd5f8fafb133ad4eb1eca8", "best_bid": "0.428", "best_ask": "0.429"}], "timestamp": "1785163719439", "event_type": "price_change"}}
{"ts": 1785163720.271, "kind": "price_change", "data": {"market": "0x18b1c135d0a40c5894da9412e77311827d9caf16cf4cd6591b247a34730af919", "price_changes": [{"asset_id": "40081275558852222228080198821361202017557872256707631666334039001378518619916", "price": "0.505", "size": "36.7", "side": "SELL", "hash": "9aac79e70fb71bcb40e9ffb1fa5d63b085b718b6", "best_bid": "0.428", "best_ask": "0.429"}, {"asset_id": "78633590736077251574794513664747155551297291244492840448622550955320930591622", "price": "0.495", "size": "36.7", "side": "BUY", "hash": "d8fa744a241f871a9cde0de16fd15ba9f144018d", "best_bid": "0.571", "best_ask": "0.572"}], "timestamp": "1785163720271", "event_type": "price_change"}}
{"ts": 1785163720.867, "kind": "price_change", "data": {"market": "0x18b1c135d0a40c5894da9412e77311827d9caf16cf4cd6591b247a34730af919", "price_changes": [{"asset_id": "40081275558852222228080198821361202017557872256707631666334039001378518619916", "price": "0.505", "size": "0", "side": "SELL", "hash": "3f868290bf6ccd16934a0a9785fb1d858a32275a", "best_bid": "0.428", "best_ask": "0.429"}, {"asset_id": "78633590736077251574794513664747155551297291244492840448622550955320930591622", "price": "0.495", "size": "0", "side": "BUY", "hash": "b5300921305d04c5354888cae8188b3c5ff063b0", "best_bid": "0.571", "best_ask": "0.572"}], "timestamp": "1785163720867", "event_type": "price_change"}}
{"ts": 1785163720.887, "kind": "price_change", "data": {"market": "0x18b1c135d0a40c5894da9412e77311827d9caf16cf4cd6591b247a34730af919", "price_changes": [{"asset_id": "40081275558852222228080198821361202017557872256707631666334039001378518619916", "price": "0.411", "size": "36542", "side": "BUY", "hash": "51db94a83651d7e5c9ba94c22e8c9feeeda18a7e", "best_bid": "0.428", "best_ask": "0.429"}, {"asset_id": "78633590736077251574794513664747155551297291244492840448622550955320930591622", "price": "0.589", "size": "36542", "side": "SELL", "hash": "d009c5b2fe8cc5b53ea67dff09d7115226e3dedd", "best_bid": "0.571", "best_ask": "0.572"}], "timestamp": "1785163720887", "event_type": "price_change"}}
{"ts": 1785163721.23, "kind": "price_change", "data": {"market": "0x18b1c135d0a40c5894da9412e77311827d9caf16cf4cd6591b247a34730af919", "price_changes": [{"asset_id": "40081275558852222228080198821361202017557872256707631666334039001378518619916", "price": "0.507", "size": "36.7", "side": "SELL", "hash": "b84aa54a99f78ff540643f02d2ce7f28224cb2ad", "best_bid": "0.428", "best_ask": "0.429"}, {"asset_id": "78633590736077251574794513664747155551297291244492840448622550955320930591622", "price": "0.493", "size": "36.7", "side": "BUY", "hash": "9613b3c06b8c319fb1d0eb4d88aee3be729fa58c", "best_bid": "0.571", "best_ask": "0.572"}], "timestamp": "1785163721230", "event_type": "price_change"}}
{"ts": 1785163722.949, "kind": "price_change", "data": {"market": "0x18b1c135d0a40c5894da9412e77311827d9caf16cf4cd6591b247a34730af919", "price_changes": [{"asset_id": "40081275558852222228080198821361202017557872256707631666334039001378518619916", "price": "0.41", "size": "2931.23", "side": "BUY", "hash": "c74255a2f537c3d22ba8246f59cef21ff25d8491", "best_bid": "0.428", "best_ask": "0.429"}, {"asset_id": "78633590736077251574794513664747155551297291244492840448622550955320930591622", "price": "0.59", "size": "2931.23", "side": "SELL", "hash": "3ceeebc982a3d77fecafca01597116216205fcca", "best_bid": "0.571", "best_ask": "0.572"}], "timestamp": "1785163722949", "event_type": "price_change"}}
{"ts": 1785163723.783, "kind": "price_change", "data": {"market": "0x18b1c135d0a40c5894da9412e77311827d9caf16cf4cd6591b247a34730af919", "price_changes": [{"asset_id": "40081275558852222228080198821361202017557872256707631666334039001378518619916", "price": "0.41", "size": "2947.28", "side": "BUY", "hash": "d58dbeb3e2110fb6f4e28104253be14c16b9c79b", "best_bid": "0.428", "best_ask": "0.429"}, {"asset_id": "78633590736077251574794513664747155551297291244492840448622550955320930591622", "price": "0.59", "size": "2947.28", "side": "SELL", "hash": "2e8515177ac682fadb1dc1569b36fe145a603940", "best_bid": "0.571", "best_ask": "0.572"}], "timestamp": "1785163723783", "event_type": "price_change"}}
{"ts": 1785163724.006, "kind": "price_change", "data": {"market": "0x0f49db97f71c68b1e42a6d16e3de93d85dbf7d4148e3f018eb79e88554be9f75", "price_changes": [{"asset_id": "87854174148074652060467921081181402357467303721471806610111179101805869578687", "price": "0.02", "size": "98000", "side": "BUY", "hash": "8a5b1885d1f39e6966d5e960ce64aae79db6a0ce", "best_bid": "0.805", "best_ask": "0.806"}, {"asset_id": "54533043819946592547517511176940999955633860128497669742211153063842200957669", "price": "0.98", "size": "98000", "side": "SELL", "hash": "e4259fc38cd9981ca9f715cd8473d59e6b632660", "best_bid": "0.194", "best_ask": "0.195"}], "timestamp": "1785163724006", "event_type": "price_change"}}
