{"ts": 1785163378.339, "kind": "book", "data": {"market": "0x18b1c135d0a40c5894da9412e77311827d9caf16cf4cd6591b247a34730af919", "asset_id": "40081275558852222228080198821361202017557872256707631666334039001378518619916", "timestamp": "1785163378339", "hash": "ee8a9dc6cc96a29b1d06c8dea9ba18d3eeca709f", "bids": [{"price": "0.001", "size": "2069838"}, {"price": "0.002", "size": "500005"}, {"price": "0.003", "size": "19333.33"}, {"price": "0.004", "size": "50000"}, {"price": "0.005", "size": "21000"}, {"price": "0.01", "size": "392975"}, {"price": "0.011", "size": "5000"}, {"price": "0.02", "size": "322531.25"}, {"price": "0.021", "size": "20000"}, {"price": "0.03", "size": "158750"}, {"price": "0.031", "size": "2000"}, {"price": "0.04", "size": "125643.75"}, {"price": "0.042", "size": "1999.99"}, {"price": "0.052", "size": "1000"}, {"price": "0.06", "size": "35200"}, {"price": "0.07", "size": "33080.36"}, {"price": "0.071", "size": "5555"}, {"price": "0.072", "size": "1000"}, {"price": "0.08", "size": "100"}, {"price": "0.09", "size": "20000"}, {"price": "0.1", "size": "19698.75"}, {"price": "0.11", "size": "13668.36"}, {"price": "0.13", "size": "22932.68"}, {"price": "0.15", "size": "7100"}, {"price": "0.16", "size": "11132.81"}, {"price": "0.161", "size": "5000"}, {"price": "0.17", "size": "5294.11"}, {"price": "0.171", "size": "2970.75"}, {"price": "0.19", "size": "11447.36"}, {"price": "0.193", "size": "3000"}, {"price": "0.2", "size": "727.94"}, {"price": "0.22", "size": "2727.27"}, {"price": "0.221", "size": "50.42"}, {"price": "0.25", "size": "6"}, {"price": "0.257", "size": "6"}, {"price": "0.26", "size": "50"}, {"price": "0.262", "size": "218.02"}, {"price": "0.269", "size": "120"}, {"price": "0.276", "size": "120"}, {"price": "0.28", "size": "535"}, {"price": "0.282", "size": "120"}, {"price": "0.289", "size": "120"}, {"price": "0.29", "size": "3500"}, {"price": "0.292", "size": "5005"}, {"price": "0.295", "size": "5000"}, {"price": "0.296", "size": "2120"}, {"price": "0.297", "size": "20"}, {"price": "0.298", "size": "10000"}, {"price": "0.299", "size": "6375.08"}, {"price": "0.3", "size": "1955"}, {"price": "0.302", "size": "120"}, {"price": "0.309", "size": "140"}, {"price": "0.311", "size": "50"}, {"price": "0.315", "size": "120"}, {"price": "0.32", "size": "6683.49"}, {"price": "0.322", "size": "4120"}, {"price": "0.33", "size": "500"}, {"price": "0.332", "size": "60"}, {"price": "0.34", "size": "104.99"}, {"price": "0.35", "size": "100"}, {"price": "0.358", "size": "10500"}, {"price": "0.361", "size": "38.96"}, {"price": "0.363", "size": "3000"}, {"price": "0.364", "size": "200"}, {"price": "0.365", "size": "571.07"}, {"price": "0.369", "size": "2493"}, {"price": "0.37", "size": "520"}, {"price": "0.371", "size": "350"}, {"price": "0.372", "size": "300"}, {"price": "0.373", "size": "421.99"}, {"price": "0.375", "size": "423.27"}, {"price": "0.377", "size": "200.1"}, {"price": "0.379", "size": "265"}, {"price": "0.38", "size": "646.99"}, {"price": "0.381", "size": "647"}, {"price": "0.382", "size": "10"}, {"price": "0.384", "size": "200.1"}, {"price": "0.385", "size": "620"}, {"price": "0.387", "size": "1185.69"}, {"price": "0.39", "size": "3420"}, {"price": "0.391", "size": "100"}, {"price": "0.394", "size": "28"}, {"price": "0.395", "size": "1531"}, {"price": "0.396", "size": "229523.83"}, {"price": "0.397", "size": "50202"}, {"price": "0.398", "size": "14448"}, {"price": "0.399", "size": "10117"}, {"price": "0.4", "size": "2311.13"}, {"price": "0.401", "size": "1800"}, {"price": "0.404", "size": "937.91"}, {"price": "0.407", "size": "10"}, {"price": "0.408", "size": "4656"}, {"price": "0.41", "size": "2947.28"}, {"price": "0.411", "size": "36542"}, {"price": "0.412", "size": "11211.7"}, {"price": "0.414", "size": "300"}, {"price": "0.415", "size": "2000"}, {"price": "0.416", "size": "310"}, {"price": "0.417", "size": "1201"}, {"price": "0.418", "size": "7276.25"}, {"price": "0.419", "size": "1100"}, {"price": "0.42", "size": "2216.74"}, {"price": "0.421", "size": "1220"}, {"price": "0.422", "size": "1111"}, {"price": "0.423", "size": "1000"}, {"price": "0.424", "size": "2769.4"}, {"price": "0.425", "size": "7135.54"}, {"price": "0.426", "size": "7827.22"}, {"price": "0.427", "size": "7659.99"}, {"price": "0.428", "size": "59302.52"}], "asks": [{"price": "0.999", "size": "11015340.94"}, {"price": "0.998", "size": "4007510.34"}, {"price": "0.997", "size": "1010000"}, {"price": "0.996", "size": "15016.91"}, {"price": "0.995", "size": "7.22"}, {"price": "0.994", "size": "302500"}, {"price": "0.99", "size": "1001270"}, {"price": "0.989", "size": "1100005.25"}, {"price": "0.988", "size": "5916.5"}, {"price": "0.98", "size": "75750"}, {"price": "0.979", "size": "90000"}, {"price": "0.978", "size": "7.97"}, {"price": "0.97", "size": "40500"}, {"price": "0.967", "size": "30000"}, {"price": "0.966", "size": "62352.94"}, {"price": "0.96", "size": "250"}, {"price": "0.95", "size": "1000"}, {"price": "0.94", "size": "225916.66"}, {"price": "0.939", "size": "84083.5"}, {"price": "0.938", "size": "6.23"}, {"price": "0.929", "size": "30000"}, {"price": "0.928", "size": "20000"}, {"price": "0.92", "size": "16875"}, {"price": "0.91", "size": "21666.66"}, {"price": "0.907", "size": "4800"}, {"price": "0.904", "size": "10000"}, {"price": "0.9", "size": "850"}, {"price": "0.89", "size": "19096.9"}, {"price": "0.889", "size": "30000"}, {"price": "0.86", "size": "12857.14"}, {"price": "0.859", "size": "8000"}, {"price": "0.85", "size": "500"}, {"price": "0.83", "size": "8823.52"}, {"price": "0.829", "size": "5.16"}, {"price": "0.81", "size": "21167.76"}, {"price": "0.8", "size": "6300"}, {"price": "0.77", "size": "19926.62"}, {"price": "0.74", "size": "15865.57"}, {"price": "0.739", "size": "9000"}, {"price": "0.72", "size": "2678.57"}, {"price": "0.71", "size": "10668.1"}, {"price": "0.7", "size": "550"}, {"price": "0.697", "size": "5000"}, {"price": "0.69", "size": "1935.48"}, {"price": "0.67", "size": "7500"}, {"price": "0.667", "size": "5000"}, {"price": "0.66", "size": "1323.52"}, {"price": "0.65", "size": "5"}, {"price": "0.637", "size": "5000"}, {"price": "0.63", "size": "37"}, {"price": "0.629", "size": "400"}, {"price": "0.626", "size": "49.27"}, {"price": "0.607", "size": "5000"}, {"price": "0.6", "size": "175.77"}, {"price": "0.59", "size": "55.24"}, {"price": "0.586", "size": "5000"}, {"price": "0.58", "size": "200"}, {"price": "0.576", "size": "5000"}, {"price": "0.569", "size": "700"}, {"price": "0.566", "size": "5100"}, {"price": "0.557", "size": "26637.09"}, {"price": "0.556", "size": "5000"}, {"price": "0.555", "size": "100"}, {"price": "0.547", "size": "17000"}, {"price": "0.545", "size": "5000"}, {"price": "0.543", "size": "700"}, {"price": "0.54", "size": "5"}, {"price": "0.539", "size": "50"}, {"price": "0.535", "size": "5000"}, {"price": "0.534", "size": "100"}, {"price": "0.53", "size": "5599.98"}, {"price": "0.529", "size": "9500"}, {"price": "0.525", "size": "2088"}, {"price": "0.524", "size": "100"}, {"price": "0.52", "size": "81.71"}, {"price": "0.519", "size": "25"}, {"price": "0.518", "size": "201.09"}, {"price": "0.515", "size": "77"}, {"price": "0.51", "size": "216"}, {"price": "0.508", "size": "60"}, {"price": "0.507", "size": "36.7"}, {"price": "0.5", "size": "5037.44"}, {"price": "0.499", "size": "3016"}, {"price": "0.495", "size": "20"}, {"price": "0.49", "size": "1249.98"}, {"price": "0.48", "size": "650"}, {"price": "0.476", "size": "647"}, {"price": "0.468", "size": "74856.91"}, {"price": "0.467", "size": "2000"}, {"price": "0.465", "size": "1999.99"}, {"price": "0.46", "size": "1800"}, {"price": "0.459", "size": "499.95"}, {"price": "0.458", "size": "5"}, {"price": "0.456", "size": "600"}, {"price": "0.453", "size": "1420"}, {"price": "0.452", "size": "10"}, {"price": "0.45", "size": "30379.18"}, {"price": "0.449", "size": "28706.16"}, {"price": "0.448", "size": "780.04"}, {"price": "0.446", "size": "1419.99"}, {"price": "0.445", "size": "12364.59"}, {"price": "0.443", "size": "420"}, {"price": "0.441", "size": "300"}, {"price": "0.44", "size": "5894.39"}, {"price": "0.439", "size": "12194"}, {"price": "0.437", "size": "100"}, {"price": "0.436", "size": "2320"}, {"price": "0.435", "size": "300"}, {"price": "0.43", "size": "3695.84"}, {"price": "0.429", "size": "16025.06"}], "tick_size": "0.001", "event_type": "book", "last_trade_price": "0.429"}}
{"ts": 1785163378.339, "kind": "book", "data": {"market": "0x18b1c135d0a40c5894da9412e77311827d9caf16cf4cd6591b247a34730af919", "asset_id": "78633590736077251574794513664747155551297291244492840448622550955320930591622", "timestamp": "1785163378339", "hash": "a63d6f4e6bea22072bd643b0a039304202e1badb", "bids": [{"price": "0.001", "size": "11015340.94"}, {"price": "0.002", "size": "4007510.34"}, {"price": "0.003", "size": "1010000"}, {"price": "0.004", "size": "15016.91"}, {"price": "0.005", "size": "7.22"}, {"price": "0.006", "size": "302500"}, {"price": "0.01", "size": "1001270"}, {"price": "0.011", "size": "1100005.25"}, {"price": "0.012", "size": "5916.5"}, {"price": "0.02", "size": "75750"}, {"price": "0.021", "size": "90000"}, {"price": "0.022", "size": "7.97"}, {"price": "0.03", "size": "40500"}, {"price": "0.033", "size": "30000"}, {"price": "0.034", "size": "62352.94"}, {"price": "0.04", "size": "250"}, {"price": "0.05", "size": "1000"}, {"price": "0.06", "size": "225916.66"}, {"price": "0.061", "size": "84083.5"}, {"price": "0.062", "size": "6.23"}, {"price": "0.071", "size": "30000"}, {"price": "0.072", "size": "20000"}, {"price": "0.08", "size": "16875"}, {"price": "0.09", "size": "21666.66"}, {"price": "0.093", "size": "4800"}, {"price": "0.096", "size": "10000"}, {"price": "0.1", "size": "850"}, {"price": "0.11", "size": "19096.9"}, {"price": "0.111", "size": "30000"}, {"price": "0.14", "size": "12857.14"}, {"price": "0.141", "size": "8000"}, {"price": "0.15", "size": "500"}, {"price": "0.17", "size": "8823.52"}, {"price": "0.171", "size": "5.16"}, {"price": "0.19", "size": "21167.76"}, {"price": "0.2", "size": "6300"}, {"price": "0.23", "size": "19926.62"}, {"price": "0.26", "size": "15865.57"}, {"price": "0.261", "size": "9000"}, {"price": "0.28", "size": "2678.57"}, {"price": "0.29", "size": "10668.1"}, {"price": "0.3", "size": "550"}, {"price": "0.303", "size": "5000"}, {"price": "0.31", "size": "1935.48"}, {"price": "0.33", "size": "7500"}, {"price": "0.333", "size": "5000"}, {"price": "0.34", "size": "1323.52"}, {"price": "0.35", "size": "5"}, {"price": "0.363", "size": "5000"}, {"price": "0.37", "size": "37"}, {"price": "0.371", "size": "400"}, {"price": "0.374", "size": "49.27"}, {"price": "0.393", "size": "5000"}, {"price": "0.4", "size": "175.77"}, {"price": "0.41", "size": "55.24"}, {"price": "0.414", "size": "5000"}, {"price": "0.42", "size": "200"}, {"price": "0.424", "size": "5000"}, {"price": "0.431", "size": "700"}, {"price": "0.434", "size": "5100"}, {"price": "0.443", "size": "26637.09"}, {"price": "0.444", "size": "5000"}, {"price": "0.445", "size": "100"}, {"price": "0.453", "size": "17000"}, {"price": "0.455", "size": "5000"}, {"price": "0.457", "size": "700"}, {"price": "0.46", "size": "5"}, {"price": "0.461", "size": "50"}, {"price": "0.465", "size": "5000"}, {"price": "0.466", "size": "100"}, {"price": "0.47", "size": "5599.98"}, {"price": "0.471", "size": "9500"}, {"price": "0.475", "size": "2088"}, {"price": "0.476", "size": "100"}, {"price": "0.48", "size": "81.71"}, {"price": "0.481", "size": "25"}, {"price": "0.482", "size": "201.09"}, {"price": "0.485", "size": "77"}, {"price": "0.49", "size": "216"}, {"price": "0.492", "size": "60"}, {"price": "0.493", "size": "36.7"}, {"price": "0.5", "size": "5037.44"}, {"price": "0.501", "size": "3016"}, {"price": "0.505", "size": "20"}, {"price": "0.51", "size": "1249.98"}, {"price": "0.52", "size": "650"}, {"price": "0.524", "size": "647"}, {"price": "0.532", "size": "74856.91"}, {"price": "0.533", "size": "2000"}, {"price": "0.535", "size": "1999.99"}, {"price": "0.54", "size": "1800"}, {"price": "0.541", "size": "499.95"}, {"price": "0.542", "size": "5"}, {"price": "0.544", "size": "600"}, {"price": "0.547", "size": "1420"}, {"price": "0.548", "size": "10"}, {"price": "0.55", "size": "30379.18"}, {"price": "0.551", "size": "28706.16"}, {"price": "0.552", "size": "780.04"}, {"price": "0.554", "size": "1419.99"}, {"price": "0.555", "size": "12364.59"}, {"price": "0.557", "size": "420"}, {"price": "0.559", "size": "300"}, {"price": "0.56", "size": "5894.39"}, {"price": "0.561", "size": "12194"}, {"price": "0.563", "size": "100"}, {"price": "0.564", "size": "2320"}, {"price": "0.565", "size": "300"}, {"price": "0.57", "size": "3695.84"}, {"price": "0.571", "size": "16025.06"}], "asks": [{"price": "0.999", "size": "2069838"}, {"price": "0.998", "size": "500005"}, {"price": "0.997", "size": "19333.33"}, {"price": "0.996", "size": "50000"}, {"price": "0.995", "size": "21000"}, {"price": "0.99", "size": "392975"}, {"price": "0.989", "size": "5000"}, {"price": "0.98", "size": "322531.25"}, {"price": "0.979", "size": "20000"}, {"price": "0.97", "size": "158750"}, {"price": "0.969", "size": "2000"}, {"price": "0.96", "size": "125643.75"}, {"price": "0.958", "size": "1999.99"}, {"price": "0.948", "size": "1000"}, {"price": "0.94", "size": "35200"}, {"price": "0.93", "size": "33080.36"}, {"price": "0.929", "size": "5555"}, {"price": "0.928", "size": "1000"}, {"price": "0.92", "size": "100"}, {"price": "0.91", "size": "20000"}, {"price": "0.9", "size": "19698.75"}, {"price": "0.89", "size": "13668.36"}, {"price": "0.87", "size": "22932.68"}, {"price": "0.85", "size": "7100"}, {"price": "0.84", "size": "11132.81"}, {"price": "0.839", "size": "5000"}, {"price": "0.83", "size": "5294.11"}, {"price": "0.829", "size": "2970.75"}, {"price": "0.81", "size": "11447.36"}, {"price": "0.807", "size": "3000"}, {"price": "0.8", "size": "727.94"}, {"price": "0.78", "size": "2727.27"}, {"price": "0.779", "size": "50.42"}, {"price": "0.75", "size": "6"}, {"price": "0.743", "size": "6"}, {"price": "0.74", "size": "50"}, {"price": "0.738", "size": "218.02"}, {"price": "0.731", "size": "120"}, {"price": "0.724", "size": "120"}, {"price": "0.72", "size": "535"}, {"price": "0.718", "size": "120"}, {"price": "0.711", "size": "120"}, {"price": "0.71", "size": "3500"}, {"price": "0.708", "size": "5005"}, {"price": "0.705", "size": "5000"}, {"price": "0.704", "size": "2120"}, {"price": "0.703", "size": "20"}, {"price": "0.702", "size": "10000"}, {"price": "0.701", "size": "6375.08"}, {"price": "0.7", "size": "1955"}, {"price": "0.698", "size": "120"}, {"price": "0.691", "size": "140"}, {"price": "0.689", "size": "50"}, {"price": "0.685", "size": "120"}, {"price": "0.68", "size": "6683.49"}, {"price": "0.678", "size": "4120"}, {"price": "0.67", "size": "500"}, {"price": "0.668", "size": "60"}, {"price": "0.66", "size": "104.99"}, {"price": "0.65", "size": "100"}, {"price": "0.642", "size": "10500"}, {"price": "0.639", "size": "38.96"}, {"price": "0.637", "size": "3000"}, {"price": "0.636", "size": "200"}, {"price": "0.635", "size": "571.07"}, {"price": "0.631", "size": "2493"}, {"price": "0.63", "size": "520"}, {"price": "0.629", "size": "350"}, {"price": "0.628", "size": "300"}, {"price": "0.627", "size": "421.99"}, {"price": "0.625", "size": "423.27"}, {"price": "0.623", "size": "200.1"}, {"price": "0.621", "size": "265"}, {"price": "0.62", "size": "646.99"}, {"price": "0.619", "size": "647"}, {"price": "0.618", "size": "10"}, {"price": "0.616", "size": "200.1"}, {"price": "0.615", "size": "620"}, {"price": "0.613", "size": "1185.69"}, {"price": "0.61", "size": "3420"}, {"price": "0.609", "size": "100"}, {"price": "0.606", "size": "28"}, {"price": "0.605", "size": "1531"}, {"price": "0.604", "size": "229523.83"}, {"price": "0.603", "size": "50202"}, {"price": "0.602", "size": "14448"}, {"price": "0.601", "size": "10117"}, {"price": "0.6", "size": "2311.13"}, {"price": "0.599", "size": "1800"}, {"price": "0.596", "size": "937.91"}, {"price": "0.593", "size": "10"}, {"price": "0.592", "size": "4656"}, {"price": "0.59", "size": "2947.28"}, {"price": "0.589", "size": "36542"}, {"price": "0.588", "size": "11211.7"}, {"price": "0.586", "size": "300"}, {"price": "0.585", "size": "2000"}, {"price": "0.584", "size": "310"}, {"price": "0.583", "size": "1201"}, {"price": "0.582", "size": "7276.25"}, {"price": "0.581", "size": "1100"}, {"price": "0.58", "size": "2216.74"}, {"price": "0.579", "size": "1220"}, {"price": "0.578", "size": "1111"}, {"price": "0.577", "size": "1000"}, {"price": "0.576", "size": "2769.4"}, {"price": "0.575", "size": "7135.54"}, {"price": "0.574", "size": "7827.22"}, {"price": "0.573", "size": "7659.99"}, {"price": "0.572", "size": "59302.52"}], "tick_size": "0.001", "event_type": "book", "last_trade_price": "0.429"}}
{"ts": 1785163380.296893, "kind": "orders_out", "data": [{"token_id": "54533043819946592547517511176940999955633860128497669742211153063842200957669", "side": "BUY", "price": 0.153, "size": 19.61}]}
{"ts": 1785163380.299694, "kind": "orders_out", "data": [{"token_id": "40081275558852222228080198821361202017557872256707631666334039001378518619916", "side": "BUY", "price": 0.387, "size": 7.75}, {"token_id": "78633590736077251574794513664747155551297291244492840448622550955320930591622", "side": "BUY", "price": 0.529, "size": 5.67}]}
{"ts": 1785163380.572, "kind": "price_change", "data": {"market": "0x18b1c135d0a40c5894da9412e77311827d9caf16cf4cd6591b247a34730af919", "price_changes": [{"asset_id": "78633590736077251574794513664747155551297291244492840448622550955320930591622", "price": "0.56", "size": "5835.99", "side": "BUY", "hash": "ec62ff7a88d4d395eea18f19d152255843b8df69", "best_bid": "0.571", "best_ask": "0.572"}, {"asset_id": "40081275558852222228080198821361202017557872256707631666334039001378518619916", "price": "0.44", "size": "5835.99", "side": "SELL", "hash": "1a6b1dedd050876e19a62bead32a070caa8209cc", "best_bid": "0.428", "best_ask": "0.429"}], "timestamp": "1785163380572", "event_type": "price_change"}}
{"ts": 1785163381.391, "kind": "price_change", "data": {"market": "0x18b1c135d0a40c5894da9412e77311827d9caf16cf4cd6591b247a34730af919", "price_changes": [{"asset_id": "40081275558852222228080198821361202017557872256707631666334039001378518619916", "price": "0.05", "size": "20000", "side": "BUY", "hash": "34f50aa045b589da972a7d9c233ef8873185db5e", "best_bid": "0.428", "best_ask": "0.429"}, {"asset_id": "78633590736077251574794513664747155551297291244492840448622550955320930591622", "price": "0.95", "size": "20000", "side": "SELL", "hash": "55562b0d9eba4a4ce5b7a8cbb3024224a5e3b676", "best_bid": "0.571", "best_ask": "0.572"}], "timestamp": "1785163381391", "event_type": "price_change"}}
{"ts": 1785163385.468, "kind": "price_change", "data": {"market": "0x18b1c135d0a40c5894da9412e77311827d9caf16cf4cd6591b247a34730af919", "price_changes": [{"asset_id": "40081275558852222228080198821361202017557872256707631666334039001378518619916", "price": "0.426", "size": "8827.22", "side": "BUY", "hash": "3d25139eba2a5d983f5e73505c302e87b8e219fa", "best_bid": "0.428", "best_ask": "0.429"}, {"asset_id": "78633590736077251574794513664747155551297291244492840448622550955320930591622", "price": "0.574", "size": "8827.22", "side": "SELL", "hash": "7ea3d52a7f7da0dd7258799fcb3856cbf029398d", "best_bid": "0.571", "best_ask": "0.572"}], "timestamp": "1785163385468", "event_type": "price_change"}}
{"ts": 1785163385.614, "kind": "price_change", "data": {"market": "0x18b1c135d0a40c5894da9412e77311827d9caf16cf4cd6591b247a34730af919", "price_changes": [{"asset_id": "78633590736077251574794513664747155551297291244492840448622550955320930591622", "price": "0.565", "size": "1300", "side": "BUY", "hash": "feb749042a5fd653c52a25b4d9198013d7b5468a", "best_bid": "0.571", "best_ask": "0.572"}, {"asset_id": "40081275558852222228080198821361202017557872256707631666334039001378518619916", "price": "0.435", "size": "1300", "side": "SELL", "hash": "c9edb761631509a975447b8fdd25da9ec9115a11", "best_bid": "0.428", "best_ask": "0.429"}], "timestamp": "1785163385614", "event_type": "price_change"}}
{"ts": 1785163385.631, "kind": "price_change", "data": {"market": "0x18b1c135d0a40c5894da9412e77311827d9caf16cf4cd6591b247a34730af919", "price_changes": [{"asset_id": "78633590736077251574794513664747155551297291244492840448622550955320930591622", "price": "0.551", "size": "27618.16", "side": "BUY", "hash": "02af17ca76121e6d189a5c1a800efd9a84d100b1", "best_bid": "0.571", "best_ask": "0.572"}, {"asset_id": "40081275558852222228080198821361202017557872256707631666334039001378518619916", "price": "0.449", "size": "27618.16", "side": "SELL", "hash": "3b142f2bb3e89811a506d8251229a3bbf11e3a60", "best_bid": "0.428", "best_ask": "0.429"}], "timestamp": "1785163385631", "event_type": "price_change"}}
{"ts": 1785163385.665, "kind": "price_change", "data": {"market": "0x18b1c135d0a40c5894da9412e77311827d9caf16cf4cd6591b247a34730af919", "price_changes": [{"asset_id": "78633590736077251574794513664747155551297291244492840448622550955320930591622", "price": "0.551", "size": "28706.16", "side": "BUY", "hash": "bd7e0bbecb7f206fa6d4b4844025ac85525ffdeb", "best_bid": "0.571", "best_ask": "0.572"}, {"asset_id": "40081275558852222228080198821361202017557872256707631666334039001378518619916", "price": "0.449", "size": "28706.16", "side": "SELL", "hash": "2d91f253c0701f86ed5a318472e8264884ad7754", "best_bid": "0.428", "best_ask": "0.429"}], "timestamp": "1785163385665", "event_type": "price_change"}}
{"ts": 1785163386.009, "kind": "price_change", "data": {"market": "0x18b1c135d0a40c5894da9412e77311827d9caf16cf4cd6591b247a34730af919", "price_changes": [{"asset_id": "78633590736077251574794513664747155551297291244492840448622550955320930591622", "price": "0.555", "size": "12242.19", "side": "BUY", "hash": "23f66e24f29185dc8d64ad480ff008d575c181eb", "best_bid": "0.571", "best_ask": "0.572"}, {"asset_id": "40081275558852222228080198821361202017557872256707631666334039001378518619916", "price": "0.445", "size": "12242.19", "side": "SELL", "hash": "1ddb03a7a42216659f2cf7ec717e212bc5573c3b", "best_bid": "0.428", "best_ask": "0.429"}], "timestamp": "1785163386009", "event_type": "price_change"}}
{"ts": 1785163389.611, "kind": "price_change", "data": {"market": "0x18b1c135d0a40c5894da9412e77311827d9caf16cf4cd6591b247a34730af919", "price_changes": [{"asset_id": "78633590736077251574794513664747155551297291244492840448622550955320930591622", "price": "0.551", "size": "28421.96", "side": "BUY", "hash": "c62be9fc829eaf63a14bc844ddda78fe0b624f8a", "best_bid": "0.571", "best_ask": "0.572"}, {"asset_id": "40081275558852222228080198821361202017557872256707631666334039001378518619916", "price": "0.449", "size": "28421.96", "side": "SELL", "hash": "d44b708af3c842f3f793b51b0c26711d3f27597b", "best_bid": "0.428", "best_ask": "0.429"}], "timestamp": "1785163389611", "event_type": "price_change"}}
{"ts": 1785163391.709, "kind": "price_change", "data": {"market": "0x18b1c135d0a40c5894da9412e77311827d9caf16cf4cd6591b247a34730af919", "price_changes": [{"asset_id": "40081275558852222228080198821361202017557872256707631666334039001378518619916", "price": "0.41", "size": "2931.23", "side": "BUY", "hash": "26ca92a91181cb4a729d692773c6a7f945540428", "best_bid": "0.428", "best_ask": "0.429"}, {"asset_id": "78633590736077251574794513664747155551297291244492840448622550955320930591622", "price": "0.59", "size": "2931.23", "side": "SELL", "hash": "42c11f182150fdecc36d76af39976ce1a73e52c4", "best_bid": "0.571", "best_ask": "0.572"}], "timestamp": "1785163391709", "event_type": "price_change"}}
{"ts": 1785163392.416, "kind": "price_change", "data": {"market": "0x18b1c135d0a40c5894da9412e77311827d9caf16cf4cd6591b247a34730af919", "price_changes": [{"asset_id": "40081275558852222228080198821361202017557872256707631666334039001378518619916", "price": "0.41", "size": "2947.28", "side": "BUY", "hash": "508a0faa01faff283ab71997c289ee15dafbf5e7", "best_bid": "0.428", "best_ask": "0.429"}, {"asset_id": "78633590736077251574794513664747155551297291244492840448622550955320930591622", "price": "0.59", "size": "2947.28", "side": "SELL", "hash": "7830a79d180a036c15bbe0d63853059ad361eb70", "best_bid": "0.571", "best_ask": "0.572"}], "timestamp": "1785163392416", "event_type": "price_change"}}
{"ts": 1785163394.336, "kind": "price_change", "data": {"market": "0x0f49db97f71c68b1e42a6d16e3de93d85dbf7d4148e3f018eb79e88554be9f75", "price_changes": [{"asset_id": "87854174148074652060467921081181402357467303721471806610111179101805869578687", "price": "0.795", "size": "3127.98", "side": "BUY", "hash": "61efa113fa2952bb5bc7da622434f85d34d7d3c2", "best_bid": "0.805", "best_ask": "0.806"}, {"asset_id": "54533043819946592547517511176940999955633860128497669742211153063842200957669", "price": "0.205", "size": "3127.98", "side": "SELL", "hash": "bec850fc8eb2c4c9203deedc4c8965ecf6da2001", "best_bid": "0.194", "best_ask": "0.195"}], "timestamp": "1785163394336", "event_type": "price_change"}}
{"ts": 1785163394.439, "kind": "price_change", "data": {"market": "0x0f49db97f71c68b1e42a6d16e3de93d85dbf7d4148e3f018eb79e88554be9f75", "price_changes": [{"asset_id": "87854174148074652060467921081181402357467303721471806610111179101805869578687", "price": "0.795", "size": "3694.98", "side": "BUY", "hash": "178c074b0b48d0e734bd5bb47d53de1abeb2ad75", "best_bid": "0.805", "best_ask": "0.806"}, {"asset_id": "54533043819946592547517511176940999955633860128497669742211153063842200957669", "price": "0.205", "size": "3694.98", "side": "SELL", "hash": "a98f8e2440a0796a880ca2b7b5477524024e7cc3", "best_bid": "0.194", "best_ask": "0.195"}], "timestamp": "1785163394439", "event_type": "price_change"}}
{"ts": 1785163395.112, "kind": "price_change", "data": {"market": "0x18b1c135d0a40c5894da9412e77311827d9caf16cf4cd6591b247a34730af919", "price_changes": [{"asset_id": "40081275558852222228080198821361202017557872256707631666334039001378518619916", "price": "0.418", "size": "6198.25", "side": "BUY", "hash": "ffe377ffe7ff2289dbb9719cef7cbbc4da09fb5e", "best_bid": "0.428", "best_ask": "0.429"}, {"asset_id": "78633590736077251574794513664747155551297291244492840448622550955320930591622", "price": "0.582", "size": "6198.25", "side": "SELL", "hash": "7adf61bcaf508e849893a3e26c23de05eefa7717", "best_bid": "0.571", "best_ask": "0.572"}], "timestamp": "1785163395112", "event_type": "price_change"}}
{"ts": 1785163395.226, "kind": "price_change", "data": {"market": "0x18b1c135d0a40c5894da9412e77311827d9caf16cf4cd6591b247a34730af919", "price_changes": [{"asset_id": "40081275558852222228080198821361202017557872256707631666334039001378518619916", "price": "0.418", "size": "7276.25", "side": "BUY", "hash": "30b345c3c6580c34dcc503d3ee3d618d3dade1e3", "best_bid": "0.428", "best_ask": "0.429"}, {"asset_id": "78633590736077251574794513664747155551297291244492840448622550955320930591622", "price": "0.582", "size": "7276.25", "side": "SELL", "hash": "8237f745ab269898284fa1968acf5ce3fb4520c7", "best_bid": "0.571", "best_ask": "0.572"}], "timestamp": "1785163395226", "event_type": "price_change"}}
{"ts": 1785163395.579, "kind": "price_change", "data": {"market": "0x18b1c135d0a40c5894da9412e77311827d9caf16cf4cd6591b247a34730af919", "price_changes": [{"asset_id": "78633590736077251574794513664747155551297291244492840448622550955320930591622", "price": "0.57", "size": "3095.84", "side": "BUY", "hash": "4be72ac32de5880036268158244c64d580a036d3", "best_bid": "0.571", "best_ask": "0.572"}, {"asset_id": "40081275558852222228080198821361202017557872256707631666334039001378518619916", "price": "0.43", "size": "3095.84", "side": "SELL", "hash": "1d815b834e77f4398898b54e9a4b7521345a4406", "best_bid": "0.428", "best_ask": "0.429"}], "timestamp": "1785163395579", "event_type": "price_change"}}
{"ts": 1785163395.579, "kind": "price_change", "data": {"market": "0x18b1c135d0a40c5894da9412e77311827d9caf16cf4cd6591b247a34730af919", "price_changes": [{"asset_id": "40081275558852222228080198821361202017557872256707631666334039001378518619916", "price": "0.427", "size": "7059.99", "side": "BUY", "hash": "1d815b834e77f4398898b54e9a4b7521345a4406", "best_bid": "0.428", "best_ask": "0.429"}, {"asset_id": "78633590736077251574794513664747155551297291244492840448622550955320930591622", "price": "0.573", "size": "7059.99", "side": "SELL", "hash": "4be72ac32de5880036268158244c64d580a036d3", "best_bid": "0.571", "best_ask": "0.572"}], "timestamp": "1785163395579", "event_type": "price_change"}}
{"ts": 1785163397.867, "kind": "price_change", "data": {"market": "0x0f49db97f71c68b1e42a6d16e3de93d85dbf7d4148e3f018eb79e88554be9f75", "price_changes": [{"asset_id": "54533043819946592547517511176940999955633860128497669742211153063842200957669", "price": "0.184", "size": "1466", "side": "BUY", "hash": "2dabb0cdb99dba1c04c38573450a5bd2f2fd78d7", "best_bid": "0.194", "best_ask": "0.195"}, {"asset_id": "87854174148074652060467921081181402357467303721471806610111179101805869578687", "price": "0.816", "size": "1466", "side": "SELL", "hash": "60f4327d2287775e137247211ea70e79dfb1e5e5", "best_bid": "0.805", "best_ask": "0.806"}], "timestamp": "1785163397867", "event_type": "price_change"}}
{"ts": 1785163397.867, "kind": "price_change", "data": {"market": "0x0f49db97f71c68b1e42a6d16e3de93d85dbf7d4148e3f018eb79e88554be9f75", "price_changes": [{"asset_id": "87854174148074652060467921081181402357467303721471806610111179101805869578687", "price": "0.795", "size": "3394.98", "side": "BUY", "hash": "60f4327d2287775e137247211ea70e79dfb1e5e5", "best_bid": "0.805", "best_ask": "0.806"}, {"asset_id": "54533043819946592547517511176940999955633860128497669742211153063842200957669", "price": "0.205", "size": "3394.98", "side": "SELL", "hash": "2dabb0cdb99dba1c04c38573450a5bd2f2fd78d7", "best_bid": "0.194", "best_ask": "0.195"}], "timestamp": "1785163397867", "event_type": "price_change"}}
{"ts": 1785163397.954, "kind": "price_change", "data": {"market": "0x0f49db97f71c68b1e42a6d16e3de93d85dbf7d4148e3f018eb79e88554be9f75", "price_changes": [{"asset_id": "54533043819946592547517511176940999955633860128497669742211153063842200957669", "price": "0.176", "size": "12220.93", "side": "BUY", "hash": "79694a4d40b4423a498af32b79f46507fe09a15c", "best_bid": "0.194", "best_ask": "0.195"}, {"asset_id": "87854174148074652060467921081181402357467303721471806610111179101805869578687", "price": "0.824", "size": "12220.93", "side": "SELL", "hash": "5107c96f67389644430a0ff8055dd63e1559339f", "best_bid": "0.805", "best_ask": "0.806"}], "timestamp": "1785163397954", "event_type": "price_change"}}
{"ts": 1785163398.52, "kind": "price_change", "data": {"market": "0x18b1c135d0a40c5894da9412e77311827d9caf16cf4cd6591b247a34730af919", "price_changes": [{"asset_id": "78633590736077251574794513664747155551297291244492840448622550955320930591622", "price": "0.55", "size": "30078.38", "side": "BUY", "hash": "372b1e844b24e7583e9063edc24c2270e1aec79f", "best_bid": "0.571", "best_ask": "0.572"}, {"asset_id": "40081275558852222228080198821361202017557872256707631666334039001378518619916", "price": "0.45", "size": "30078.38", "side": "SELL", "hash": "67cfaced522cef8598e5b6974c51e0681d016525", "best_bid": "0.428", "best_ask": "0.429"}], "timestamp": "1785163398520", "event_type": "price_change"}}
{"ts": 1785163402.004, "kind": "price_change", "data": {"market": "0x18b1c135d0a40c5894da9412e77311827d9caf16cf4cd6591b247a34730af919", "price_changes": [{"asset_id": "40081275558852222228080198821361202017557872256707631666334039001378518619916", "price": "0.418", "size": "6975.25", "side": "BUY", "hash": "9f80554684af50dd8ae5a9dd3305072d1b5f260b", "best_bid": "0.428", "best_ask": "0.429"}, {"asset_id": "78633590736077251574794513664747155551297291244492840448622550955320930591622", "price": "0.582", "size": "6975.25", "side": "SELL", "hash": "2651dd7321de0d586559c0524e5f1052541a8cf8", "best_bid": "0.571", "best_ask": "0.572"}], "timestamp": "1785163402004", "event_type": "price_change"}}
{"ts": 1785163402.005, "kind": "price_change", "data": {"market": "0x18b1c135d0a40c5894da9412e77311827d9caf16cf4cd6591b247a34730af919", "price_changes": [{"asset_id": "78633590736077251574794513664747155551297291244492840448622550955320930591622", "price": "0.004", "size": "5000", "side": "BUY", "hash": "97232b1dfc9ac446d8fa94f7789e1d253425857c", "best_bid": "0.571", "best_ask": "0.572"}, {"asset_id": "40081275558852222228080198821361202017557872256707631666334039001378518619916", "price": "0.996", "size": "5000", "side": "SELL", "hash": "09157a70d990f3cce16d48fee846872011fb2f30", "best_bid": "0.428", "best_ask": "0.429"}], "timestamp": "1785163402005", "event_type": "price_change"}}
{"ts": 1785163402.081, "kind": "price_change", "data": {"market": "0x18b1c135d0a40c5894da9412e77311827d9caf16cf4cd6591b247a34730af919", "price_changes": [{"asset_id": "78633590736077251574794513664747155551297291244492840448622550955320930591622", "price": "0.548", "size": "19.99", "side": "BUY", "hash": "e11b85bc2166b1aa900382558b1e20bc164dc0c3", "best_bid": "0.571", "best_ask": "0.572"}, {"asset_id": "40081275558852222228080198821361202017557872256707631666334039001378518619916", "price": "0.452", "size": "19.99", "side": "SELL", "hash": "92d71a3f0c867cb9723ee1fc3fea182daa31b386", "best_bid": "0.428", "best_ask": "0.429"}], "timestamp": "1785163402081", "event_type": "price_change"}}
{"ts": 1785163402.161, "kind": "price_change", "data": {"market": "0x18b1c135d0a40c5894da9412e77311827d9caf16cf4cd6591b247a34730af919", "price_changes": [{"asset_id": "78633590736077251574794513664747155551297291244492840448622550955320930591622", "price": "0.532", "size": "74115.71", "side": "BUY", "hash": "8baab1ae803f0e81f70d19766f5941f47bf9ef90", "best_bid": "0.571", "best_ask": "0.572"}, {"asset_id": "40081275558852222228080198821361202017557872256707631666334039001378518619916", "price": "0.468", "size": "74115.71", "side": "SELL", "hash": "31a0f36dd52b706f9146aea29a66ced688ea2fa4", "best_bid": "0.428", "best_ask": "0.429"}], "timestamp": "1785163402161", "event_type": "price_change"}}
{"ts": 1785163404.155, "kind": "price_change", "data": {"market": "0x0f49db97f71c68b1e42a6d16e3de93d85dbf7d4148e3f018eb79e88554be9f75", "price_changes": [{"asset_id": "87854174148074652060467921081181402357467303721471806610111179101805869578687", "price": "0.795", "size": "2828.98", "side": "BUY", "hash": "4767fe4c4d23e9ae044ac45e3ab9799c219d7f49", "best_bid": "0.805", "best_ask": "0.806"}, {"asset_id": "54533043819946592547517511176940999955633860128497669742211153063842200957669", "price": "0.205", "size": "2828.98", "side": "SELL", "hash": "ca9950c9c2aa5ba7a79f277a1d1a20f189b010a1", "best_bid": "0.194", "best_ask": "0.195"}], "timestamp": "1785163404155", "event_type": "price_change"}}
{"ts": 1785163404.24, "kind": "price_change", "data": {"market": "0x0f49db97f71c68b1e42a6d16e3de93d85dbf7d4148e3f018eb79e88554be9f75", "price_changes": [{"asset_id": "87854174148074652060467921081181402357467303721471806610111179101805869578687", "price": "0.795", "size": "3394.98", "side": "BUY", "hash": "6e9ab5f78a75d3acabb7570aa3ba842d21444fe6", "best_bid": "0.805", "best_ask": "0.806"}, {"asset_id": "54533043819946592547517511176940999955633860128497669742211153063842200957669", "price": "0.205", "size": "3394.98", "side": "SELL", "hash": "b80deb65374c80a28248715fc769193864eb9f4d", "best_bid": "0.194", "best_ask": "0.195"}], "timestamp": "1785163404240", "event_type": "price_change"}}
{"ts": 1785163404.461256, "kind": "orders_out", "data": [{"token_id": "54533043819946592547517511176940999955633860128497669742211153063842200957669", "side": "BUY", "price": 0.153, "size": 19.61}]}
{"ts": 1785163404.803, "kind": "price_change", "data": {"market": "0x18b1c135d0a40c5894da9412e77311827d9caf16cf4cd6591b247a34730af919", "price_changes": [{"asset_id": "40081275558852222228080198821361202017557872256707631666334039001378518619916", "price": "0.418", "size": "5899.25", "side": "BUY", "hash": "90a955e7d22702bb7c74728589ebe83ee18f9e06", "best_bid": "0.428", "best_ask": "0.429"}, {"asset_id": "78633590736077251574794513664747155551297291244492840448622550955320930591622", "price": "0.582", "size": "5899.25", "side": "SELL", "hash": "90785149d64f9f166a9673c53c0af624d109e674", "best_bid": "0.571", "best_ask": "0.572"}], "timestamp": "1785163404803", "event_type": "price_change"}}
{"ts": 1785163404.84, "kind": "price_change", "data": {"market": "0x18b1c135d0a40c5894da9412e77311827d9caf16cf4cd6591b247a34730af919", "price_changes": [{"asset_id": "40081275558852222228080198821361202017557872256707631666334039001378518619916", "price": "0.418", "size": "5699.25", "side": "BUY", "hash": "0046f7167bde3e35467ede54c871318258bb4ecf", "best_bid": "0.428", "best_ask": "0.429"}, {"asset_id": "78633590736077251574794513664747155551297291244492840448622550955320930591622", "price": "0.582", "size": "5699.25", "side": "SELL", "hash": "292c6f21753130e548ca57faaf58b53c9376e3f0", "best_bid": "0.571", "best_ask": "0.572"}], "timestamp": "1785163404840", "event_type": "price_change"}}
{"ts": 1785163404.878, "kind": "price_change", "data": {"market": "0x18b1c135d0a40c5894da9412e77311827d9caf16cf4cd6591b247a34730af919", "price_changes": [{"asset_id": "40081275558852222228080198821361202017557872256707631666334039001378518619916", "price": "0.417", "size": "1401", "side": "BUY", "hash": "16603333369ee58ccd608f3665f9380aae42bf2c", "best_bid": "0.428", "best_ask": "0.429"}, {"asset_id": "78633590736077251574794513664747155551297291244492840448622550955320930591622", "price": "0.583", "size": "1401", "side": "SELL", "hash": "23312f0b798c357ccb961eb2e8fc2fc7da26b98f", "best_bid": "0.571", "best_ask": "0.572"}], "timestamp": "1785163404878", "event_type": "price_change"}}
{"ts": 1785163404.879, "kind": "price_change", "data": {"market": "0x18b1c135d0a40c5894da9412e77311827d9caf16cf4cd6591b247a34730af919", "price_changes": [{"asset_id": "40081275558852222228080198821361202017557872256707631666334039001378518619916", "price": "0.418", "size": "6775.25", "side": "BUY", "hash": "0efd0304d7424a33946295e262a73c9a5630aa69", "best_bid": "0.428", "best_ask": "0.429"}, {"asset_id": "78633590736077251574794513664747155551297291244492840448622550955320930591622", "price": "0.582", "size": "6775.25", "side": "SELL", "hash": "9c0bee0ccb47995fbd1d98d13722a8a2a28cba86", "best_bid": "0.571", "best_ask": "0.572"}], "timestamp": "1785163404879", "event_type": "price_change"}}
{"ts": 1785163404.911, "kind": "price_change", "data": {"market": "0x18b1c135d0a40c5894da9412e77311827d9caf16cf4cd6591b247a34730af919", "price_changes": [{"asset_id": "40081275558852222228080198821361202017557872256707631666334039001378518619916", "price": "0.417", "size": "1201", "side": "BUY", "hash": "e7926f9a4499c32f6e62dfd05c8dd0484c66f5c6", "best_bid": "0.428", "best_ask": "0.429"}, {"asset_id": "78633590736077251574794513664747155551297291244492840448622550955320930591622", "price": "0.583", "size": "1201", "side": "SELL", "hash": "56c274c95c8457ffc6cabac104e7c843eb4675e0", "best_bid": "0.571", "best_ask": "0.572"}], "timestamp": "1785163404911", "event_type": "price_change"}}
{"ts": 1785163404.944, "kind": "price_change", "data": {"market": "0x18b1c135d0a40c5894da9412e77311827d9caf16cf4cd6591b247a34730af919", "price_changes": [{"asset_id": "40081275558852222228080198821361202017557872256707631666334039001378518619916", "price": "0.418", "size": "6975.25", "side": "BUY", "hash": "0b89ace7379f8c691abf97a0c078cfb34fa5f2c4", "best_bid": "0.428", "best_ask": "0.429"}, {"asset_id": "78633590736077251574794513664747155551297291244492840448622550955320930591622", "price": "0.582", "size": "6975.25", "side": "SELL", "hash": "506fa3199507d4793a5fb4fc5f9ae57e2275233b", "best_bid": "0.571", "best_ask": "0.572"}], "timestamp": "1785163404944", "event_type": "price_change"}}
{"ts": 1785163405.518, "kind": "price_change", "data": {"market": "0x18b1c135d0a40c5894da9412e77311827d9caf16cf4cd6591b247a34730af919", "price_changes": [{"asset_id": "40081275558852222228080198821361202017557872256707631666334039001378518619916", "price": "0.427", "size": "7659.99", "side": "BUY", "hash": "09b8569e9cba1330a92e27c7cb55db5040c8f277", "best_bid": "0.428", "best_ask": "0.429"}, {"asset_id": "78633590736077251574794513664747155551297291244492840448622550955320930591622", "price": "0.573", "size": "7659.99", "side": "SELL", "hash": "9c273d5383626b5ace1940adf235291b3ffcd440", "best_bid": "0.571", "best_ask": "0.572"}], "timestamp": "1785163405518", "event_type": "price_change"}}
{"ts": 1785163405.652, "kind": "price_change", "data": {"market": "0x18b1c135d0a40c5894da9412e77311827d9caf16cf4cd6591b247a34730af919", "price_changes": [{"asset_id": "78633590736077251574794513664747155551297291244492840448622550955320930591622", "price": "0.57", "size": "3695.84", "side": "BUY", "hash": "41cd61d241973c10b304bfc65f22f1bb242959e8", "best_bid": "0.571", "best_ask": "0.572"}, {"asset_id": "40081275558852222228080198821361202017557872256707631666334039001378518619916", "price": "0.43", "size": "3695.84", "side": "SELL", "hash": "8848141abbbfeb2c5a255506a60b83627a478939", "best_bid": "0.428", "best_ask": "0.429"}], "timestamp": "1785163405652", "event_type": "price_change"}}
{"ts": 1785163405.71, "kind": "price_change", "data": {"market": "0x18b1c135d0a40c5894da9412e77311827d9caf16cf4cd6591b247a34730af919", "price_changes": [{"asset_id": "78633590736077251574794513664747155551297291244492840448622550955320930591622", "price": "0.548", "size": "10", "side": "BUY", "hash": "b98d3a97d5ca8bc466f2d1c315806715825a26eb", "best_bid": "0.571", "best_ask": "0.572"}, {"asset_id": "40081275558852222228080198821361202017557872256707631666334039001378518619916", "price": "0.452", "size": "10", "side": "SELL", "hash": "e37aaebd85bb97b43a3fe4a9791d06ac313bd3e6", "best_bid": "0.428", "best_ask": "0.429"}], "timestamp": "1785163405710", "event_type": "price_change"}}
{"ts": 1785163405.823251, "kind": "orders_out", "data": [{"token_id": "40081275558852222228080198821361202017557872256707631666334039001378518619916", "side": "BUY", "price": 0.387, "size": 7.75}, {"token_id": "78633590736077251574794513664747155551297291244492840448622550955320930591622", "side": "BUY", "price": 0.529, "size": 5.67}]}
{"ts": 1785163406.255, "kind": "price_change", "data": {"market": "0x18b1c135d0a40c5894da9412e77311827d9caf16cf4cd6591b247a34730af919", "price_changes": [{"asset_id": "40081275558852222228080198821361202017557872256707631666334039001378518619916", "price": "0.507", "size": "0", "side": "SELL", "hash": "67746781f688e63f70e3f88f52909446ced8903f", "best_bid": "0.428", "best_ask": "0.429"}, {"asset_id": "78633590736077251574794513664747155551297291244492840448622550955320930591622", "price": "0.493", "size": "0", "side": "BUY", "hash": "41cecce14a5c09145454f28ad0959ffb425fadcf", "best_bid": "0.571", "best_ask": "0.572"}], "timestamp": "1785163406255", "event_type": "price_change"}}
{"ts": 1785163406.332, "kind": "price_change", "data": {"market": "0x18b1c135d0a40c5894da9412e77311827d9caf16cf4cd6591b247a34730af919", "price_changes": [{"asset_id": "78633590736077251574794513664747155551297291244492840448622550955320930591622", "price": "0.549", "size": "9.99", "side": "BUY", "hash": "e9ac68cd1f6b37105a4295b6d8cabba378f45785", "best_bid": "0.571", "best_ask": "0.572"}, {"asset_id": "40081275558852222228080198821361202017557872256707631666334039001378518619916", "price": "0.451", "size": "9.99", "side": "SELL", "hash": "ddfc4dd7900525aa90c4786e8956bf49b420d056", "best_bid": "0.428", "best_ask": "0.429"}], "timestamp": "1785163406332", "event_type": "price_change"}}
{"ts": 1785163406.895, "kind": "price_change", "data": {"market": "0x0f49db97f71c68b1e42a6d16e3de93d85dbf7d4148e3f018eb79e88554be9f75", "price_changes": [{"asset_id": "54533043819946592547517511176940999955633860128497669742211153063842200957669", "price": "0.184", "size": "1766", "side": "BUY", "hash": "991a4395b758d99305af1060587e3fc7b4af496b", "best_bid": "0.194", "best_ask": "0.195"}, {"asset_id": "87854174148074652060467921081181402357467303721471806610111179101805869578687", "price": "0.816", "size": "1766", "side": "SELL", "hash": "a5740c795952de98153d5e7af36d0c58b73859b7", "best_bid": "0.805", "best_ask": "0.806"}], "timestamp": "1785163406895", "event_type": "price_change"}}
{"ts": 1785163406.903, "kind": "price_change", "data": {"market": "0x0f49db97f71c68b1e42a6d16e3de93d85dbf7d4148e3f018eb79e88554be9f75", "price_changes": [{"asset_id": "87854174148074652060467921081181402357467303721471806610111179101805869578687", "price": "0.795", "size": "3694.98", "side": "BUY", "hash": "302743b7f232c2da3874a8779364dfff33a2e0a4", "best_bid": "0.805", "best_ask": "0.806"}, {"asset_id": "54533043819946592547517511176940999955633860128497669742211153063842200957669", "price": "0.205", "size": "3694.98", "side": "SELL", "hash": "efbfae4196d6d477a31526b599e9583480e72ccb", "best_bid": "0.194", "best_ask": "0.195"}], "timestamp": "1785163406903", "event_type": "price_change"}}
{"ts": 1785163407.0, "kind": "price_change", "data": {"market": "0x18b1c135d0a40c5894da9412e77311827d9caf16cf4cd6591b247a34730af919", "price_changes": [{"asset_id": "40081275558852222228080198821361202017557872256707631666334039001378518619916", "price": "0.417", "size": "1000", "side": "BUY", "hash": "82e911d96acd872a38fbdf7286c2d7db6f7b3b5b", "best_bid": "0.428", "best_ask": "0.429"}, {"asset_id": "78633590736077251574794513664747155551297291244492840448622550955320930591622", "price": "0.583", "size": "1000", "side": "SELL", "hash": "3e140391932200489492f83dd7c181616142e211", "best_bid": "0.571", "best_ask": "0.572"}], "timestamp": "1785163407000", "event_type": "price_change"}}
{"ts": 1785163407.305668, "kind": "orders_out", "data": [{"token_id": "40081275558852222228080198821361202017557872256707631666334039001378518619916", "side": "BUY", "price": 0.387, "size": 7.75}, {"token_id": "78633590736077251574794513664747155551297291244492840448622550955320930591622", "side": "BUY", "price": 0.529, "size": 5.67}]}
{"ts": 1785163407.431, "kind": "price_change", "data": {"market": "0x18b1c135d0a40c5894da9412e77311827d9caf16cf4cd6591b247a34730af919", "price_changes": [{"asset_id": "40081275558852222228080198821361202017557872256707631666334039001378518619916", "price": "0.506", "size": "36.7", "side": "SELL", "hash": "4b9b16d8fcf8a2da435047ec633b599fc9fa7f5d", "best_bid": "0.428", "best_ask": "0.429"}, {"asset_id": "78633590736077251574794513664747155551297291244492840448622550955320930591622", "price": "0.494", "size": "36.7", "side": "BUY", "hash": "2e75086bc792075fe9a6fe022529ffe518f0222f", "best_bid": "0.571", "best_ask": "0.572"}], "timestamp": "1785163407431", "event_type": "price_change"}}
{"ts": 1785163408.829, "kind": "price_change", "data": {"market": "0x18b1c135d0a40c5894da9412e77311827d9caf16cf4cd6591b247a34730af919", "price_changes": [{"asset_id": "78633590736077251574794513664747155551297291244492840448622550955320930591622", "price": "0.004", "size": "15016.91", "side": "BUY", "hash": "8dd4e173861d85027ddaf1fdb57292c7dd664761", "best_bid": "0.571", "best_ask": "0.572"}, {"asset_id": "40081275558852222228080198821361202017557872256707631666334039001378518619916", "price": "0.996", "size": "15016.91", "side": "SELL", "hash": "42789e31117874484a9ec06844045d0936bd6539", "best_bid": "0.428", "best_ask": "0.429"}], "timestamp": "1785163408829", "event_type": "price_change"}}
{"ts": 1785163410.397, "kind": "price_change", "data": {"market": "0x18b1c135d0a40c5894da9412e77311827d9caf16cf4cd6591b247a34730af919", "price_changes": [{"asset_id": "40081275558852222228080198821361202017557872256707631666334039001378518619916", "price": "0.41", "size": "2931.23", "side": "BUY", "hash": "2640914369b0ddb43904c15f7e9bd7a97d75769a", "best_bid": "0.428", "best_ask": "0.429"}, {"asset_id": "78633590736077251574794513664747155551297291244492840448622550955320930591622", "price": "0.59", "size": "2931.23", "side": "SELL", "hash": "3b122be92c73401cf8122d4380738ab2e4b30f00", "best_bid": "0.571", "best_ask": "0.572"}], "timestamp": "1785163410397", "event_type": "price_change"}}
{"ts": 1785163410.419, "kind": "price_change", "data": {"market": "0x18b1c135d0a40c5894da9412e77311827d9caf16cf4cd6591b247a34730af919", "price_changes": [{"asset_id": "78633590736077251574794513664747155551297291244492840448622550955320930591622", "price": "0.371", "size": "0", "side": "BUY", "hash": "20fdfae234183f8854d35ba2fbec4ebdac531ee7", "best_bid": "0.571", "best_ask": "0.572"}, {"asset_id": "40081275558852222228080198821361202017557872256707631666334039001378518619916", "price": "0.629", "size": "0", "side": "SELL", "hash": "bfd304c4de377d4f9e22518058f640db2cfa24b3", "best_bid": "0.428", "best_ask": "0.429"}], "timestamp": "1785163410419", "event_type": "price_change"}}
{"ts": 1785163410.456, "kind": "price_change", "data": {"market": "0x18b1c135d0a40c5894da9412e77311827d9caf16cf4cd6591b247a34730af919", "price_changes": [{"asset_id": "78633590736077251574794513664747155551297291244492840448622550955320930591622", "price": "0.375", "size": "400", "side": "BUY", "hash": "d5149c78a9f8a0a7c9e833cc9a77223ceb8c55ff", "best_bid": "0.571", "best_ask": "0.572"}, {"asset_id": "40081275558852222228080198821361202017557872256707631666334039001378518619916", "price": "0.625", "size": "400", "side": "SELL", "hash": "4fa6ecfdf5a6b6420102960af64a879c64834bf4", "best_bid": "0.428", "best_ask": "0.429"}], "timestamp": "1785163410456", "event_type": "price_change"}}
{"ts": 1785163410.569, "kind": "price_change", "data": {"market": "0x18b1c135d0a40c5894da9412e77311827d9caf16cf4cd6591b247a34730af919", "price_changes": [{"asset_id": "40081275558852222228080198821361202017557872256707631666334039001378518619916", "price": "0.418", "size": "7048.05", "side": "BUY", "hash": "b1e3b3b5dd439bcb4f9fc127b40c52c7985ee163", "best_bid": "0.428", "best_ask": "0.429"}, {"asset_id": "78633590736077251574794513664747155551297291244492840448622550955320930591622", "price": "0.582", "size": "7048.05", "side": "SELL", "hash": "9425d4c96c3acee23694eef162dc57f1f4f9d7fd", "best_bid": "0.571", "best_ask": "0.572"}], "timestamp": "1785163410569", "event_type": "price_change"}}
{"ts": 1785163410.608, "kind": "price_change", "data": {"market": "0x18b1c135d0a40c5894da9412e77311827d9caf16cf4cd6591b247a34730af919", "price_changes": [{"asset_id": "78633590736077251574794513664747155551297291244492840448622550955320930591622", "price": "0.532", "size": "74864.31", "side": "BUY", "hash": "b567a7f27b47379f8f05d3fada88e5f7905be90e", "best_bid": "0.571", "best_ask": "0.572"}, {"asset_id": "40081275558852222228080198821361202017557872256707631666334039001378518619916", "price": "0.468", "size": "74864.31", "side": "SELL", "hash": "8ab7ce78634c938bf4da45c2714c3a73ca376589", "best_bid": "0.428", "best_ask": "0.429"}], "timestamp": "1785163410608", "event_type": "price_change"}}
{"ts": 1785163410.609, "kind": "price_change", "data": {"market": "0x18b1c135d0a40c5894da9412e77311827d9caf16cf4cd6591b247a34730af919", "price_changes": [{"asset_id": "40081275558852222228080198821361202017557872256707631666334039001378518619916", "price": "0.412", "size": "11323.8", "side": "BUY", "hash": "62b54e7b2887ac6263aa7f003c497a6d2073eb6b", "best_bid": "0.428", "best_ask": "0.429"}, {"asset_id": "78633590736077251574794513664747155551297291244492840448622550955320930591622", "price": "0.588", "size": "11323.8", "side": "SELL", "hash": "345d66f52efeea8d80799f38bcfdeef3c726f389", "best_bid": "0.571", "best_ask": "0.572"}], "timestamp": "1785163410609", "event_type": "price_change"}}
{"ts": 1785163410.61, "kind": "price_change", "data": {"market": "0x18b1c135d0a40c5894da9412e77311827d9caf16cf4cd6591b247a34730af919", "price_changes": [{"asset_id": "40081275558852222228080198821361202017557872256707631666334039001378518619916", "price": "0.411", "size": "36907.4", "side": "BUY", "hash": "2bf06828fc4ce0a1af2c95fd0561d5fb6e3f9c71", "best_bid": "0.428", "best_ask": "0.429"}, {"asset_id": "78633590736077251574794513664747155551297291244492840448622550955320930591622", "price": "0.589", "size": "36907.4", "side": "SELL", "hash": "3342bc6fab42af9bc76d59393ff6448684c7de97", "best_bid": "0.571", "best_ask": "0.572"}], "timestamp": "1785163410610", "event_type": "price_change"}}
{"ts": 1785163410.621, "kind": "price_change", "data": {"market": "0x18b1c135d0a40c5894da9412e77311827d9caf16cf4cd6591b247a34730af919", "price_changes": [{"asset_id": "78633590736077251574794513664747155551297291244492840448622550955320930591622", "price": "0.551", "size": "28706.16", "side": "BUY", "hash": "aa33eda0820b9da825bcbc87f09cd3b0b91ee948", "best_bid": "0.571", "best_ask": "0.572"}, {"asset_id": "40081275558852222228080198821361202017557872256707631666334039001378518619916", "price": "0.449", "size": "28706.16", "side": "SELL", "hash": "37d77d128de32c1443f927ec46edc0e2620ca7f3", "best_bid": "0.428", "best_ask": "0.429"}], "timestamp": "1785163410621", "event_type": "price_change"}}
{"ts": 1785163410.642, "kind": "price_change", "data": {"market": "0x18b1c135d0a40c5894da9412e77311827d9caf16cf4cd6591b247a34730af919", "price_changes": [{"asset_id": "78633590736077251574794513664747155551297291244492840448622550955320930591622", "price": "0.555", "size": "12364.59", "side": "BUY", "hash": "c21dcf0953b3bbc1fe7c35838754cfb1934bb467", "best_bid": "0.571", "best_ask": "0.572"}, {"asset_id": "40081275558852222228080198821361202017557872256707631666334039001378518619916", "price": "0.445", "size": "12364.59", "side": "SELL", "hash": "7a7bae89c117ed23e616c5903c53166dbbce30ca", "best_bid": "0.428", "best_ask": "0.429"}], "timestamp": "1785163410642", "event_type": "price_change"}}
{"ts": 1785163410.644, "kind": "price_change", "data": {"market": "0x18b1c135d0a40c5894da9412e77311827d9caf16cf4cd6591b247a34730af919", "price_changes": [{"asset_id": "78633590736077251574794513664747155551297291244492840448622550955320930591622", "price": "0.56", "size": "5894.39", "side": "BUY", "hash": "9674f11bfa426dac1833a8f962f6d8929f8c940e", "best_bid": "0.571", "best_ask": "0.572"}, {"asset_id": "40081275558852222228080198821361202017557872256707631666334039001378518619916", "price": "0.44", "size": "5894.39", "side": "SELL", "hash": "0aa54a87ba17cda84d7d0bd5182b00b56f53af08", "best_bid": "0.428", "best_ask": "0.429"}], "timestamp": "1785163410644", "event_type": "price_change"}}
{"ts": 1785163410.646, "kind": "price_change", "data": {"market": "0x18b1c135d0a40c5894da9412e77311827d9caf16cf4cd6591b247a34730af919", "price_changes": [{"asset_id": "40081275558852222228080198821361202017557872256707631666334039001378518619916", "price": "0.398", "size": "14592.5", "side": "BUY", "hash": "6cddc5b073cc44e91109bf979327e0d7bb8f7c50", "best_bid": "0.428", "best_ask": "0.429"}, {"asset_id": "78633590736077251574794513664747155551297291244492840448622550955320930591622", "price": "0.602", "size": "14592.5", "side": "SELL", "hash": "3db1b6ccd1a590c4aea3e81cb1a3c3b24bd65825", "best_bid": "0.571", "best_ask": "0.572"}], "timestamp": "1785163410646", "event_type": "price_change"}}
{"ts": 1785163410.648, "kind": "price_change", "data": {"market": "0x18b1c135d0a40c5894da9412e77311827d9caf16cf4cd6591b247a34730af919", "price_changes": [{"asset_id": "78633590736077251574794513664747155551297291244492840448622550955320930591622", "price": "0.561", "size": "12315.9", "side": "BUY", "hash": "727491aebc9d79e4b258ffb58d9cd94cdbc27bed", "best_bid": "0.571", "best_ask": "0.572"}, {"asset_id": "40081275558852222228080198821361202017557872256707631666334039001378518619916", "price": "0.439", "size": "12315.9", "side": "SELL", "hash": "90d019aadff83c7df9e5a41e265def4a5c8764e3", "best_bid": "0.428", "best_ask": "0.429"}], "timestamp": "1785163410648", "event_type": "price_change"}}
{"ts": 1785163410.649, "kind": "price_change", "data": {"market": "0x18b1c135d0a40c5894da9412e77311827d9caf16cf4cd6591b247a34730af919", "price_changes": [{"asset_id": "40081275558852222228080198821361202017557872256707631666334039001378518619916", "price": "0.397", "size": "50704", "side": "BUY", "hash": "493c021bad5be8f59848252a2a4704d1b3ff7631", "best_bid": "0.428", "best_ask": "0.429"}, {"asset_id": "78633590736077251574794513664747155551297291244492840448622550955320930591622", "price": "0.603", "size": "50704", "side": "SELL", "hash": "bcda17f8bc9e9a8dc01c05056809c48551205897", "best_bid": "0.571", "best_ask": "0.572"}], "timestamp": "1785163410649", "event_type": "price_change"}}
{"ts": 1785163410.649, "kind": "price_change", "data": {"market": "0x18b1c135d0a40c5894da9412e77311827d9caf16cf4cd6591b247a34730af919", "price_changes": [{"asset_id": "40081275558852222228080198821361202017557872256707631666334039001378518619916", "price": "0.399", "size": "10218.2", "side": "BUY", "hash": "e8b3b2c49b917c46ea50fc2809fbc2d17f345343", "best_bid": "0.428", "best_ask": "0.429"}, {"asset_id": "78633590736077251574794513664747155551297291244492840448622550955320930591622", "price": "0.601", "size": "10218.2", "side": "SELL", "hash": "8a9f4905be12c6f8575b57e46df41c7380ec803e", "best_bid": "0.571", "best_ask": "0.572"}], "timestamp": "1785163410649", "event_type": "price_change"}}
{"ts": 1785163410.65, "kind": "price_change", "data": {"market": "0x18b1c135d0a40c5894da9412e77311827d9caf16cf4cd6591b247a34730af919", "price_changes": [{"asset_id": "78633590736077251574794513664747155551297291244492840448622550955320930591622", "price": "0.55", "size": "30379.18", "side": "BUY", "hash": "36e8b1cc16ea158ee4ce4c0d757736d80ca9fed9", "best_bid": "0.571", "best_ask": "0.572"}, {"asset_id": "40081275558852222228080198821361202017557872256707631666334039001378518619916", "price": "0.45", "size": "30379.18", "side": "SELL", "hash": "202818e6b9a7482711c5621304d5d33af652a2c1", "best_bid": "0.428", "best_ask": "0.429"}], "timestamp": "1785163410650", "event_type": "price_change"}}
{"ts": 1785163411.066, "kind": "price_change", "data": {"market": "0x18b1c135d0a40c5894da9412e77311827d9caf16cf4cd6591b247a34730af919", "price_changes": [{"asset_id": "40081275558852222228080198821361202017557872256707631666334039001378518619916", "price": "0.41", "size": "2947.28", "side": "BUY", "hash": "c168b41b044cbf8125490b68cea08932bb356844", "best_bid": "0.428", "best_ask": "0.429"}, {"asset_id": "78633590736077251574794513664747155551297291244492840448622550955320930591622", "price": "0.59", "size": "2947.28", "side": "SELL", "hash": "9d33fa1f9c98217c94f457aff599644d8597d84d", "best_bid": "0.571", "best_ask": "0.572"}], "timestamp": "1785163411066", "event_type": "price_change"}}
{"ts": 1785163411.394, "kind": "price_change", "data": {"market": "0x0f49db97f71c68b1e42a6d16e3de93d85dbf7d4148e3f018eb79e88554be9f75", "price_changes": [{"asset_id": "54533043819946592547517511176940999955633860128497669742211153063842200957669", "price": "0.007", "size": "53571.42", "side": "BUY", "hash": "2e41b3a6170b893352a8605335855952b92d8da4", "best_bid": "0.194", "best_ask": "0.195"}, {"asset_id": "87854174148074652060467921081181402357467303721471806610111179101805869578687", "price": "0.993", "size": "53571.42", "side": "SELL", "hash": "705a4d8443a8a5d4deb76eaf713bd814edb7265a", "best_bid": "0.805", "best_ask": "0.806"}], "timestamp": "1785163411394", "event_type": "price_change"}}
{"ts": 1785163411.4, "kind": "price_change", "data": {"market": "0x0f49db97f71c68b1e42a6d16e3de93d85dbf7d4148e3f018eb79e88554be9f75", "price_changes": [{"asset_id": "54533043819946592547517511176940999955633860128497669742211153063842200957669", "price": "0.009", "size": "13888.88", "side": "BUY", "hash": "b0daa814bfd1d7b7864a18727e9fbae1186e48dd", "best_bid": "0.194", "best_ask": "0.195"}, {"asset_id": "87854174148074652060467921081181402357467303721471806610111179101805869578687", "price": "0.991", "size": "13888.88", "side": "SELL", "hash": "284080ae7dd6ad13a0971eda424bb0f14b294950", "best_bid": "0.805", "best_ask": "0.806"}], "timestamp": "1785163411400", "event_type": "price_change"}}
{"ts": 1785163412.112, "kind": "price_change", "data": {"market": "0x18b1c135d0a40c5894da9412e77311827d9caf16cf4cd6591b247a34730af919", "price_changes": [{"asset_id": "78633590736077251574794513664747155551297291244492840448622550955320930591622", "price": "0.57", "size": "3245.84", "side": "BUY", "hash": "6e27eaaccb67997adf8f20e1d7a82070a8b3a83c", "best_bid": "0.571", "best_ask": "0.572"}, {"asset_id": "40081275558852222228080198821361202017557872256707631666334039001378518619916", "price": "0.43", "size": "3245.84", "side": "SELL", "hash": "b58cac3ce881e55eba9913bae5ab5da9fd08238d", "best_bid": "0.428", "best_ask": "0.429"}], "timestamp": "1785163412112", "event_type": "price_change"}}
{"ts": 1785163412.112, "kind": "price_change", "data": {"market": "0x18b1c135d0a40c5894da9412e77311827d9caf16cf4cd6591b247a34730af919", "price_changes": [{"asset_id": "40081275558852222228080198821361202017557872256707631666334039001378518619916", "price": "0.427", "size": "7209.99", "side": "BUY", "hash": "b58cac3ce881e55eba9913bae5ab5da9fd08238d", "best_bid": "0.428", "best_ask": "0.429"}, {"asset_id": "78633590736077251574794513664747155551297291244492840448622550955320930591622", "price": "0.573", "size": "7209.99", "side": "SELL", "hash": "6e27eaaccb67997adf8f20e1d7a82070a8b3a83c", "best_bid": "0.571", "best_ask": "0.572"}], "timestamp": "1785163412112", "event_type": "price_change"}}
{"ts": 1785163412.159, "kind": "price_change", "data": {"market": "0x18b1c135d0a40c5894da9412e77311827d9caf16cf4cd6591b247a34730af919", "price_changes": [{"asset_id": "40081275558852222228080198821361202017557872256707631666334039001378518619916", "price": "0.506", "size": "0", "side": "SELL", "hash": "b39f9bb6b380bc2e00c92b3407a41e56963b6041", "best_bid": "0.428", "best_ask": "0.429"}, {"asset_id": "78633590736077251574794513664747155551297291244492840448622550955320930591622", "price": "0.494", "size": "0", "side": "BUY", "hash": "991537b58a5026bae3e2dea0118753bd546100dd", "best_bid": "0.571", "best_ask": "0.572"}], "timestamp": "1785163412159", "event_type": "price_change"}}
{"ts": 1785163412.198, "kind": "price_change", "data": {"market": "0x18b1c135d0a40c5894da9412e77311827d9caf16cf4cd6591b247a34730af919", "price_changes": [{"asset_id": "78633590736077251574794513664747155551297291244492840448622550955320930591622", "price": "0.549", "size": "0", "side": "BUY", "hash": "121b72c73d811640ad991834081d4fe057cf6689", "best_bid": "0.571", "best_ask": "0.572"}, {"asset_id": "40081275558852222228080198821361202017557872256707631666334039001378518619916", "price": "0.451", "size": "0", "side": "SELL", "hash": "4191738488ae7a17117c4190c7058ae091feb83a", "best_bid": "0.428", "best_ask": "0.429"}], "timestamp": "1785163412198", "event_type": "price_change"}}
{"ts": 1785163412.511, "kind": "price_change", "data": {"market": "0x18b1c135d0a40c5894da9412e77311827d9caf16cf4cd6591b247a34730af919", "price_changes": [{"asset_id": "40081275558852222228080198821361202017557872256707631666334039001378518619916", "price": "0.507", "size": "36.7", "side": "SELL", "hash": "7a07e8af7a70c594cdc051aef61433d734b95b09", "best_bid": "0.428", "best_ask": "0.429"}, {"asset_id": "78633590736077251574794513664747155551297291244492840448622550955320930591622", "price": "0.493", "size": "36.7", "side": "BUY", "hash": "92a6e5a5f40afd3138c697b8d16a51be8e2c5dae", "best_bid": "0.571", "best_ask": "0.572"}], "timestamp": "1785163412511", "event_type": "price_change"}}
{"ts": 1785163412.582, "kind": "price_change", "data": {"market": "0x18b1c135d0a40c5894da9412e77311827d9caf16cf4cd6591b247a34730af919", "price_changes": [{"asset_id": "78633590736077251574794513664747155551297291244492840448622550955320930591622", "price": "0.548", "size": "19.99", "side": "BUY", "hash": "d31ab8bf11c35087bc3e1ee8ee0b589039578be0", "best_bid": "0.571", "best_ask": "0.572"}, {"asset_id": "40081275558852222228080198821361202017557872256707631666334039001378518619916", "price": "0.452", "size": "19.99", "side": "SELL", "hash": "dfdd1eeba33ca6e72b09253ff68461d821117780", "best_bid": "0.428", "best_ask": "0.429"}], "timestamp": "1785163412582", "event_type": "price_change"}}
{"ts": 1785163413.003, "kind": "price_change", "data": {"market": "0x18b1c135d0a40c5894da9412e77311827d9caf16cf4cd6591b247a34730af919", "price_changes": [{"asset_id": "78633590736077251574794513664747155551297291244492840448622550955320930591622", "price": "0.561", "size": "11941.9", "side": "BUY", "hash": "53e247eef25d569b641bc24d842769d5e7abb806", "best_bid": "0.571", "best_ask": "0.572"}, {"asset_id": "40081275558852222228080198821361202017557872256707631666334039001378518619916", "price": "0.439", "size": "11941.9", "side": "SELL", "hash": "8d3c79e91d9c1a9c2fcf3e0871a5b30790573349", "best_bid": "0.428", "best_ask": "0.429"}], "timestamp": "1785163413003", "event_type": "price_change"}}
{"ts": 1785163415.836, "kind": "price_change", "data": {"market": "0x0f49db97f71c68b1e42a6d16e3de93d85dbf7d4148e3f018eb79e88554be9f75", "price_changes": [{"asset_id": "87854174148074652060467921081181402357467303721471806610111179101805869578687", "price": "0.805", "size": "1049.98", "side": "BUY", "hash": "9771914976e80ccd511110e039680dead76b1ada", "best_bid": "0.805", "best_ask": "0.806"}, {"asset_id": "54533043819946592547517511176940999955633860128497669742211153063842200957669", "price": "0.195", "size": "1049.98", "side": "SELL", "hash": "db1f62d959875c295adea1d548ac6fffee61cf32", "best_bid": "0.194", "best_ask": "0.195"}], "timestamp": "1785163415836", "event_type": "price_change"}}
{"ts": 1785163415.841, "kind": "price_change", "data": {"market": "0x0f49db97f71c68b1e42a6d16e3de93d85dbf7d4148e3f018eb79e88554be9f75", "price_changes": [{"asset_id": "54533043819946592547517511176940999955633860128497669742211153063842200957669", "price": "0.194", "size": "521.51", "side": "BUY", "hash": "7e61fc8ec5277f77f9f0f411926464a7f8779fcb", "best_bid": "0.194", "best_ask": "0.195"}, {"asset_id": "87854174148074652060467921081181402357467303721471806610111179101805869578687", "price": "0.806", "size": "521.51", "side": "SELL", "hash": "1f64a46be52c19dec5e26fbd63e3c792aca6478b", "best_bid": "0.805", "best_ask": "0.806"}], "timestamp": "1785163415841", "event_type": "price_change"}}
{"ts": 1785163416.367, "kind": "price_change", "data": {"market": "0x18b1c135d0a40c5894da9412e77311827d9caf16cf4cd6591b247a34730af919", "price_changes": [{"asset_id": "40081275558852222228080198821361202017557872256707631666334039001378518619916", "price": "0.41", "size": "2931.23", "side": "BUY", "hash": "2cb5ffde20960bea5c3fcc0790546c3133f28630", "best_bid": "0.428", "best_ask": "0.429"}, {"asset_id": "78633590736077251574794513664747155551297291244492840448622550955320930591622", "price": "0.59", "size": "2931.23", "side": "SELL", "hash": "6568ad82f86cd2538851246ee4e7185a240dc41b", "best_bid": "0.571", "best_ask": "0.572"}], "timestamp": "1785163416367", "event_type": "price_change"}}
{"ts": 1785163417.378, "kind": "price_change", "data": {"market": "0x0f49db97f71c68b1e42a6d16e3de93d85dbf7d4148e3f018eb79e88554be9f75", "price_changes": [{"asset_id": "87854174148074652060467921081181402357467303721471806610111179101805869578687", "price": "0.001", "size": "6148776.01", "side": "BUY", "hash": "85151f1c564324262d890987b7fdf34d797e3db7", "best_bid": "0.805", "best_ask": "0.806"}, {"asset_id": "54533043819946592547517511176940999955633860128497669742211153063842200957669", "price": "0.999", "size": "6148776.01", "side": "SELL", "hash": "2a657c21582e714e49af6445136cfd94325fe6b4", "best_bid": "0.194", "best_ask": "0.195"}], "timestamp": "1785163417378", "event_type": "price_change"}}
{"ts": 1785163417.38, "kind": "price_change", "data": {"market": "0x0f49db97f71c68b1e42a6d16e3de93d85dbf7d4148e3f018eb79e88554be9f75", "price_changes": [{"asset_id": "87854174148074652060467921081181402357467303721471806610111179101805869578687", "price": "0.001", "size": "6147766.01", "side": "BUY", "hash": "423a02c7cb5b41b5587a8ac3f00abaa154ce97bb", "best_bid": "0.805", "best_ask": "0.806"}, {"asset_id": "54533043819946592547517511176940999955633860128497669742211153063842200957669", "price": "0.999", "size": "6147766.01", "side": "SELL", "hash": "58797bae9b9ce2b72a2340412482302ac01aa6d4", "best_bid": "0.194", "best_ask": "0.195"}], "timestamp": "1785163417380", "event_type": "price_change"}}
{"ts": 1785163417.429, "kind": "price_change", "data": {"market": "0x0f49db97f71c68b1e42a6d16e3de93d85dbf7d4148e3f018eb79e88554be9f75", "price_changes": [{"asset_id": "54533043819946592547517511176940999955633860128497669742211153063842200957669", "price": "0.009", "size": "0", "side": "BUY", "hash": "7e028b87b34d27400669378d66067156ce9b28dc", "best_bid": "0.194", "best_ask": "0.195"}, {"asset_id": "87854174148074652060467921081181402357467303721471806610111179101805869578687", "price": "0.991", "size": "0", "side": "SELL", "hash": "d94ebf36125a4824e5827dfd7f827726e723eeb0", "best_bid": "0.805", "best_ask": "0.806"}], "timestamp": "1785163417429", "event_type": "price_change"}}
{"ts": 1785163417.429, "kind": "price_change", "data": {"market": "0x0f49db97f71c68b1e42a6d16e3de93d85dbf7d4148e3f018eb79e88554be9f75", "price_changes": [{"asset_id": "54533043819946592547517511176940999955633860128497669742211153063842200957669", "price": "0.007", "size": "0", "side": "BUY", "hash": "7e028b87b34d27400669378d66067156ce9b28dc", "best_bid": "0.194", "best_ask": "0.195"}, {"asset_id": "87854174148074652060467921081181402357467303721471806610111179101805869578687", "price": "0.993", "size": "0", "side": "SELL", "hash": "d94ebf36125a4824e5827dfd7f827726e723eeb0", "best_bid": "0.805", "best_ask": "0.806"}], "timestamp": "1785163417429", "event_type": "price_change"}}
{"ts": 1785163417.503, "kind": "price_change", "data": {"market": "0x0f49db97f71c68b1e42a6d16e3de93d85dbf7d4148e3f018eb79e88554be9f75", "price_changes": [{"asset_id": "54533043819946592547517511176940999955633860128497669742211153063842200957669", "price": "0.176", "size": "12210.93", "side": "BUY", "hash": "30db528476074ef3b31585e1df286f0254dd391b", "best_bid": "0.194", "best_ask": "0.195"}, {"asset_id": "87854174148074652060467921081181402357467303721471806610111179101805869578687", "price": "0.824", "size": "12210.93", "side": "SELL", "hash": "63441e628011300cd5c4abdb43f3259948d7731f", "best_bid": "0.805", "best_ask": "0.806"}], "timestamp": "1785163417503", "event_type": "price_change"}}
{"ts": 1785163421.471, "kind": "price_change", "data": {"market": "0x18b1c135d0a40c5894da9412e77311827d9caf16cf4cd6591b247a34730af919", "price_changes": [{"asset_id": "78633590736077251574794513664747155551297291244492840448622550955320930591622", "price": "0.475", "size": "2043", "side": "BUY", "hash": "13c85f26243dd31054813eeea40f2ab0ac80c844", "best_bid": "0.571", "best_ask": "0.572"}, {"asset_id": "40081275558852222228080198821361202017557872256707631666334039001378518619916", "price": "0.525", "size": "2043", "side": "SELL", "hash": "6db081b152c174942c8829eb38f8b66144335c86", "best_bid": "0.428", "best_ask": "0.429"}], "timestamp": "1785163421471", "event_type": "price_change"}}
{"ts": 1785163421.471, "kind": "price_change", "data": {"market": "0x18b1c135d0a40c5894da9412e77311827d9caf16cf4cd6591b247a34730af919", "price_changes": [{"asset_id": "78633590736077251574794513664747155551297291244492840448622550955320930591622", "price": "0.461", "size": "0", "side": "BUY", "hash": "13c85f26243dd31054813eeea40f2ab0ac80c844", "best_bid": "0.571", "best_ask": "0.572"}, {"asset_id": "40081275558852222228080198821361202017557872256707631666334039001378518619916", "price": "0.539", "size": "0", "side": "SELL", "hash": "6db081b152c174942c8829eb38f8b66144335c86", "best_bid": "0.428", "best_ask": "0.429"}], "timestamp": "1785163421471", "event_type": "price_change"}}
{"ts": 1785163421.471, "kind": "price_change", "data": {"market": "0x18b1c135d0a40c5894da9412e77311827d9caf16cf4cd6591b247a34730af919", "price_changes": [{"asset_id": "78633590736077251574794513664747155551297291244492840448622550955320930591622", "price": "0.434", "size": "5000", "side": "BUY", "hash": "13c85f26243dd31054813eeea40f2ab0ac80c844", "best_bid": "0.571", "best_ask": "0.572"}, {"asset_id": "40081275558852222228080198821361202017557872256707631666334039001378518619916", "price": "0.566", "size": "5000", "side": "SELL", "hash": "6db081b152c174942c8829eb38f8b66144335c86", "best_bid": "0.428", "best_ask": "0.429"}], "timestamp": "1785163421471", "event_type": "price_change"}}
{"ts": 1785163421.581, "kind": "price_change", "data": {"market": "0x18b1c135d0a40c5894da9412e77311827d9caf16cf4cd6591b247a34730af919", "price_changes": [{"asset_id": "78633590736077251574794513664747155551297291244492840448622550955320930591622", "price": "0.465", "size": "5050", "side": "BUY", "hash": "5a08d984ca55261c496ca52503040668f89c909d", "best_bid": "0.571", "best_ask": "0.572"}, {"asset_id": "40081275558852222228080198821361202017557872256707631666334039001378518619916", "price": "0.535", "size": "5050", "side": "SELL", "hash": "c36586c4335a42ef667e06d5bd7dd1be2b0a5c4c", "best_bid": "0.428", "best_ask": "0.429"}], "timestamp": "1785163421581", "event_type": "price_change"}}
{"ts": 1785163421.585, "kind": "price_change", "data": {"market": "0x18b1c135d0a40c5894da9412e77311827d9caf16cf4cd6591b247a34730af919", "price_changes": [{"asset_id": "78633590736077251574794513664747155551297291244492840448622550955320930591622", "price": "0.476", "size": "145", "side": "BUY", "hash": "57577135055b4427ffe5610de40543dc4e331208", "best_bid": "0.571", "best_ask": "0.572"}, {"asset_id": "40081275558852222228080198821361202017557872256707631666334039001378518619916", "price": "0.524", "size": "145", "side": "SELL", "hash": "4589424f2a990310fe5f39cd4706d04684153c25", "best_bid": "0.428", "best_ask": "0.429"}], "timestamp": "1785163421585", "event_type": "price_change"}}
{"ts": 1785163421.591, "kind": "price_change", "data": {"market": "0x18b1c135d0a40c5894da9412e77311827d9caf16cf4cd6591b247a34730af919", "price_changes": [{"asset_id": "78633590736077251574794513664747155551297291244492840448622550955320930591622", "price": "0.435", "size": "100", "side": "BUY", "hash": "e3ad3abb36ce587081ea8ca1981d4c005bdc8bbd", "best_bid": "0.571", "best_ask": "0.572"}, {"asset_id": "40081275558852222228080198821361202017557872256707631666334039001378518619916", "price": "0.565", "size": "100", "side": "SELL", "hash": "65d62521b23380660b89ea23deb5861cc825d202", "best_bid": "0.428", "best_ask": "0.429"}], "timestamp": "1785163421591", "event_type": "price_change"}}
{"ts": 1785163421.779757, "kind": "orders_out", "data": [{"token_id": "40081275558852222228080198821361202017557872256707631666334039001378518619916", "side": "BUY", "price": 0.387, "size": 7.75}, {"token_id": "78633590736077251574794513664747155551297291244492840448622550955320930591622", "side": "BUY", "price": 0.529, "size": 5.67}]}
{"ts": 1785163421.78, "kind": "price_change", "data": {"market": "0x18b1c135d0a40c5894da9412e77311827d9caf16cf4cd6591b247a34730af919", "price_changes": [{"asset_id": "40081275558852222228080198821361202017557872256707631666334039001378518619916", "price": "0.427", "size": "7659.99", "side": "BUY", "hash": "e8729f3f36e0db1a7c8c9e26f92b63ae15e32f60", "best_bid": "0.428", "best_ask": "0.429"}, {"asset_id": "78633590736077251574794513664747155551297291244492840448622550955320930591622", "price": "0.573", "size": "7659.99", "side": "SELL", "hash": "03936e9b6e6048135ef7667aec74349d4289263d", "best_bid": "0.571", "best_ask": "0.572"}], "timestamp": "1785163421780", "event_type": "price_change"}}
{"ts": 1785163421.923, "kind": "price_change", "data": {"market": "0x18b1c135d0a40c5894da9412e77311827d9caf16cf4cd6591b247a34730af919", "price_changes": [{"asset_id": "78633590736077251574794513664747155551297291244492840448622550955320930591622", "price": "0.57", "size": "3695.84", "side": "BUY", "hash": "07e37899645e138b5064cd4db40aea04812a75d5", "best_bid": "0.571", "best_ask": "0.572"}, {"asset_id": "40081275558852222228080198821361202017557872256707631666334039001378518619916", "price": "0.43", "size": "3695.84", "side": "SELL", "hash": "423849859c2798b3d8c6b1550fe599070d641700", "best_bid": "0.428", "best_ask": "0.429"}], "timestamp": "1785163421923", "event_type": "price_change"}}
{"ts": 1785163421.993, "kind": "price_change", "data": {"market": "0x18b1c135d0a40c5894da9412e77311827d9caf16cf4cd6591b247a34730af919", "price_changes": [{"asset_id": "78633590736077251574794513664747155551297291244492840448622550955320930591622", "price": "0.548", "size": "10", "side": "BUY", "hash": "9df1c130f61f10e890461200113d6f2af368ede7", "best_bid": "0.571", "best_ask": "0.572"}, {"asset_id": "40081275558852222228080198821361202017557872256707631666334039001378518619916", "price": "0.452", "size": "10", "side": "SELL", "hash": "71cb4e939eedf5e377023871bb6068ac4641abfb", "best_bid": "0.428", "best_ask": "0.429"}], "timestamp": "1785163421993", "event_type": "price_change"}}
{"ts": 1785163427.377, "kind": "price_change", "data": {"market": "0x18b1c135d0a40c5894da9412e77311827d9caf16cf4cd6591b247a34730af919", "price_changes": [{"asset_id": "78633590736077251574794513664747155551297291244492840448622550955320930591622", "price": "0.482", "size": "161.09", "side": "BUY", "hash": "d3f4acbdd6a5b842d5a2842fe6692042f704c9d5", "best_bid": "0.571", "best_ask": "0.572"}, {"asset_id": "40081275558852222228080198821361202017557872256707631666334039001378518619916", "price": "0.518", "size": "161.09", "side": "SELL", "hash": "ce493742816d49941eb102d9316d27d767174690", "best_bid": "0.428", "best_ask": "0.429"}], "timestamp": "1785163427377", "event_type": "price_change"}}
{"ts": 1785163427.43, "kind": "price_change", "data": {"market": "0x18b1c135d0a40c5894da9412e77311827d9caf16cf4cd6591b247a34730af919", "price_changes": [{"asset_id": "78633590736077251574794513664747155551297291244492840448622550955320930591622", "price": "0.486", "size": "10", "side": "BUY", "hash": "d97043f4fb2faf627837c9757c4b5c4dc09563a0", "best_bid": "0.571", "best_ask": "0.572"}, {"asset_id": "40081275558852222228080198821361202017557872256707631666334039001378518619916", "price": "0.514", "size": "10", "side": "SELL", "hash": "c06a2d980a69d8d215010f6342f575890bb91c49", "best_bid": "0.428", "best_ask": "0.429"}], "timestamp": "1785163427430", "event_type": "price_change"}}
{"ts": 1785163427.432, "kind": "price_change", "data": {"market": "0x18b1c135d0a40c5894da9412e77311827d9caf16cf4cd6591b247a34730af919", "price_changes": [{"asset_id": "78633590736077251574794513664747155551297291244492840448622550955320930591622", "price": "0.485", "size": "107", "side": "BUY", "hash": "d810a3349afa9741df9fae65ac811f062abad117", "best_bid": "0.571", "best_ask": "0.572"}, {"asset_id": "40081275558852222228080198821361202017557872256707631666334039001378518619916", "price": "0.515", "size": "107", "side": "SELL", "hash": "541cafefa7eceb70cd75488f1fe52b93ec77210d", "best_bid": "0.428", "best_ask": "0.429"}], "timestamp": "1785163427432", "event_type": "price_change"}}
{"ts": 1785163427.435, "kind": "price_change", "data": {"market": "0x18b1c135d0a40c5894da9412e77311827d9caf16cf4cd6591b247a34730af919", "price_changes": [{"asset_id": "78633590736077251574794513664747155551297291244492840448622550955320930591622", "price": "0.485", "size": "30", "side": "BUY", "hash": "4bda606216f1a10d631a82fe7812d5a663b9a894", "best_bid": "0.571", "best_ask": "0.572"}, {"asset_id": "40081275558852222228080198821361202017557872256707631666334039001378518619916", "price": "0.515", "size": "30", "side": "SELL", "hash": "ed5394ab5c6eb277d3baad12f306e52cf01db0ae", "best_bid": "0.428", "best_ask": "0.429"}], "timestamp": "1785163427435", "event_type": "price_change"}}
{"ts": 1785163427.435, "kind": "price_change", "data": {"market": "0x18b1c135d0a40c5894da9412e77311827d9caf16cf4cd6591b247a34730af919", "price_changes": [{"asset_id": "78633590736077251574794513664747155551297291244492840448622550955320930591622", "price": "0.482", "size": "0", "side": "BUY", "hash": "4bda606216f1a10d631a82fe7812d5a663b9a894", "best_bid": "0.571", "best_ask": "0.572"}, {"asset_id": "40081275558852222228080198821361202017557872256707631666334039001378518619916", "price": "0.518", "size": "0", "side": "SELL", "hash": "ed5394ab5c6eb277d3baad12f306e52cf01db0ae", "best_bid": "0.428", "best_ask": "0.429"}], "timestamp": "1785163427435", "event_type": "price_change"}}
{"ts": 1785163427.461, "kind": "price_change", "data": {"market": "0x18b1c135d0a40c5894da9412e77311827d9caf16cf4cd6591b247a34730af919", "price_changes": [{"asset_id": "78633590736077251574794513664747155551297291244492840448622550955320930591622", "price": "0.486", "size": "0", "side": "BUY", "hash": "70e7231b91d1a4f8ecae8ba35bb16c24aefae3af", "best_bid": "0.571", "best_ask": "0.572"}, {"asset_id": "40081275558852222228080198821361202017557872256707631666334039001378518619916", "price": "0.514", "size": "0", "side": "SELL", "hash": "067b0033bb86391fd2853deac9cf62c67c3cb35f", "best_bid": "0.428", "best_ask": "0.429"}], "timestamp": "1785163427461", "event_type": "price_change"}}
{"ts": 1785163427.461, "kind": "price_change", "data": {"market": "0x18b1c135d0a40c5894da9412e77311827d9caf16cf4cd6591b247a34730af919", "price_changes": [{"asset_id": "78633590736077251574794513664747155551297291244492840448622550955320930591622", "price": "0.485", "size": "0", "side": "BUY", "hash": "70e7231b91d1a4f8ecae8ba35bb16c24aefae3af", "best_bid": "0.571", "best_ask": "0.572"}, {"asset_id": "40081275558852222228080198821361202017557872256707631666334039001378518619916", "price": "0.515", "size": "0", "side": "SELL", "hash": "067b0033bb86391fd2853deac9cf62c67c3cb35f", "best_bid": "0.428", "best_ask": "0.429"}], "timestamp": "1785163427461", "event_type": "price_change"}}
{"ts": 1785163427.463, "kind": "price_change", "data": {"market": "0x18b1c135d0a40c5894da9412e77311827d9caf16cf4cd6591b247a34730af919", "price_changes": [{"asset_id": "78633590736077251574794513664747155551297291244492840448622550955320930591622", "price": "0.549", "size": "9.99", "side": "BUY", "hash": "c3aff0cdc15718fbddad5945caaeb5e3f3c8805a", "best_bid": "0.571", "best_ask": "0.572"}, {"asset_id": "40081275558852222228080198821361202017557872256707631666334039001378518619916", "price": "0.451", "size": "9.99", "side": "SELL", "hash": "5d7eaeaf35780779142843e16b579b9289f7eb6e", "best_bid": "0.428", "best_ask": "0.429"}], "timestamp": "1785163427463", "event_type": "price_change"}}
{"ts": 1785163427.492, "kind": "price_change", "data": {"market": "0x18b1c135d0a40c5894da9412e77311827d9caf16cf4cd6591b247a34730af919", "price_changes": [{"asset_id": "78633590736077251574794513664747155551297291244492840448622550955320930591622", "price": "0.482", "size": "30", "side": "BUY", "hash": "ed2c0d6208d000141eef5fe3062777187879c190", "best_bid": "0.571", "best_ask": "0.572"}, {"asset_id": "40081275558852222228080198821361202017557872256707631666334039001378518619916", "price": "0.518", "size": "30", "side": "SELL", "hash": "7da526e84399539281aad56d8fea53a597c2fd92", "best_bid": "0.428", "best_ask": "0.429"}], "timestamp": "1785163427492", "event_type": "price_change"}}
{"ts": 1785163427.494, "kind": "price_change", "data": {"market": "0x18b1c135d0a40c5894da9412e77311827d9caf16cf4cd6591b247a34730af919", "price_changes": [{"asset_id": "78633590736077251574794513664747155551297291244492840448622550955320930591622", "price": "0.482", "size": "40", "side": "BUY", "hash": "76d990d5fbeccac92b3559f682b6f5421fbb446b", "best_bid": "0.571", "best_ask": "0.572"}, {"asset_id": "40081275558852222228080198821361202017557872256707631666334039001378518619916", "price": "0.518", "size": "40", "side": "SELL", "hash": "c5c5ac53cec567f60fd7f901c771b600d020748c", "best_bid": "0.428", "best_ask": "0.429"}], "timestamp": "1785163427494", "event_type": "price_change"}}
{"ts": 1785163431.636, "kind": "price_change", "data": {"market": "0x18b1c135d0a40c5894da9412e77311827d9caf16cf4cd6591b247a34730af919", "price_changes": [{"asset_id": "40081275558852222228080198821361202017557872256707631666334039001378518619916", "price": "0.427", "size": "7259.99", "side": "BUY", "hash": "ac699dfdad70b1b32982ab55c47ad46d45f06ecd", "best_bid": "0.428", "best_ask": "0.429"}, {"asset_id": "78633590736077251574794513664747155551297291244492840448622550955320930591622", "price": "0.573", "size": "7259.99", "side": "SELL", "hash": "36c4e22632b03a0859b1920455776fca01d3e06f", "best_bid": "0.571", "best_ask": "0.572"}], "timestamp": "1785163431636", "event_type": "price_change"}}
{"ts": 1785163431.636, "kind": "price_change", "data": {"market": "0x18b1c135d0a40c5894da9412e77311827d9caf16cf4cd6591b247a34730af919", "price_changes": [{"asset_id": "78633590736077251574794513664747155551297291244492840448622550955320930591622", "price": "0.57", "size": "3295.84", "side": "BUY", "hash": "36c4e22632b03a0859b1920455776fca01d3e06f", "best_bid": "0.571", "best_ask": "0.572"}, {"asset_id": "40081275558852222228080198821361202017557872256707631666334039001378518619916", "price": "0.43", "size": "3295.84", "side": "SELL", "hash": "ac699dfdad70b1b32982ab55c47ad46d45f06ecd", "best_bid": "0.428", "best_ask": "0.429"}], "timestamp": "1785163431636", "event_type": "price_change"}}
{"ts": 1785163431.702, "kind": "price_change", "data": {"market": "0x18b1c135d0a40c5894da9412e77311827d9caf16cf4cd6591b247a34730af919", "price_changes": [{"asset_id": "78633590736077251574794513664747155551297291244492840448622550955320930591622", "price": "0.549", "size": "0", "side": "BUY", "hash": "23186ef55ef3d0236557002113c3e106e1b90a5e", "best_bid": "0.571", "best_ask": "0.572"}, {"asset_id": "40081275558852222228080198821361202017557872256707631666334039001378518619916", "price": "0.451", "size": "0", "side": "SELL", "hash": "bba4b3eee0c0b7505db7adf9ce0613f2e9713a31", "best_bid": "0.428", "best_ask": "0.429"}], "timestamp": "1785163431702", "event_type": "price_change"}}
{"ts": 1785163432.246, "kind": "price_change", "data": {"market": "0x18b1c135d0a40c5894da9412e77311827d9caf16cf4cd6591b247a34730af919", "price_changes": [{"asset_id": "78633590736077251574794513664747155551297291244492840448622550955320930591622", "price": "0.374", "size": "0", "side": "BUY", "hash": "01587787054a89eb8c176eb4da9f0b2c1359e7df", "best_bid": "0.571", "best_ask": "0.572"}, {"asset_id": "40081275558852222228080198821361202017557872256707631666334039001378518619916", "price": "0.626", "size": "0", "side": "SELL", "hash": "04d65b83e5238c38e47bac403efdb08956f9e607", "best_bid": "0.428", "best_ask": "0.429"}], "timestamp": "1785163432246", "event_type": "price_change"}}
{"ts": 1785163432.27, "kind": "price_change", "data": {"market": "0x18b1c135d0a40c5894da9412e77311827d9caf16cf4cd6591b247a34730af919", "price_changes": [{"asset_id": "78633590736077251574794513664747155551297291244492840448622550955320930591622", "price": "0.375", "size": "0", "side": "BUY", "hash": "5fe2e76d281b0e3edb416b87848a3145ee439ef9", "best_bid": "0.571", "best_ask": "0.572"}, {"asset_id": "40081275558852222228080198821361202017557872256707631666334039001378518619916", "price": "0.625", "size": "0", "side": "SELL", "hash": "87d053cfdbdb428bcc4d351051e18d6cabc84c65", "best_bid": "0.428", "best_ask": "0.429"}], "timestamp": "1785163432270", "event_type": "price_change"}}
{"ts": 1785163432.295, "kind": "price_change", "data": {"market": "0x18b1c135d0a40c5894da9412e77311827d9caf16cf4cd6591b247a34730af919", "price_changes": [{"asset_id": "78633590736077251574794513664747155551297291244492840448622550955320930591622", "price": "0.371", "size": "400", "side": "BUY", "hash": "5548034ff29494a99614f7752674ee576b140706", "best_bid": "0.571", "best_ask": "0.572"}, {"asset_id": "40081275558852222228080198821361202017557872256707631666334039001378518619916", "price": "0.629", "size": "400", "side": "SELL", "hash": "4ac306fb082d1c7fe43130927619dfeee3828691", "best_bid": "0.428", "best_ask": "0.429"}], "timestamp": "1785163432295", "event_type": "price_change"}}
{"ts": 1785163432.332, "kind": "price_change", "data": {"market": "0x18b1c135d0a40c5894da9412e77311827d9caf16cf4cd6591b247a34730af919", "price_changes": [{"asset_id": "78633590736077251574794513664747155551297291244492840448622550955320930591622", "price": "0.548", "size": "19.99", "side": "BUY", "hash": "94f80fafb6d1cef39fdf7fde673272140b2b5490", "best_bid": "0.571", "best_ask": "0.572"}, {"asset_id": "40081275558852222228080198821361202017557872256707631666334039001378518619916", "price": "0.452", "size": "19.99", "side": "SELL", "hash": "cf4a47c4a7bfc805b3b382049681cfdb6e1195e7", "best_bid": "0.428", "best_ask": "0.429"}], "timestamp": "1785163432332", "event_type": "price_change"}}
{"ts": 1785163433.003, "kind": "price_change", "data": {"market": "0x18b1c135d0a40c5894da9412e77311827d9caf16cf4cd6591b247a34730af919", "price_changes": [{"asset_id": "40081275558852222228080198821361202017557872256707631666334039001378518619916", "price": "0.171", "size": "0", "side": "BUY", "hash": "bd68270927062f86d675299ee56ff4ac2c19c25f", "best_bid": "0.428", "best_ask": "0.429"}, {"asset_id": "78633590736077251574794513664747155551297291244492840448622550955320930591622", "price": "0.829", "size": "0", "side": "SELL", "hash": "eae8cdc04cc906a1a993a8524d4694ac04b8e0b0", "best_bid": "0.571", "best_ask": "0.572"}], "timestamp": "1785163433003", "event_type": "price_change"}}
{"ts": 1785163433.004, "kind": "price_change", "data": {"market": "0x18b1c135d0a40c5894da9412e77311827d9caf16cf4cd6591b247a34730af919", "price_changes": [{"asset_id": "40081275558852222228080198821361202017557872256707631666334039001378518619916", "price": "0.171", "size": "0", "side": "BUY", "hash": "3f6bfea94016121789e51955d22d386d3341f09e", "best_bid": "0.428", "best_ask": "0.429"}, {"asset_id": "78633590736077251574794513664747155551297291244492840448622550955320930591622", "price": "0.829", "size": "0", "side": "SELL", "hash": "1980d1cb726a8ed69cc13088fc36b859c6e7fd62", "best_bid": "0.571", "best_ask": "0.572"}], "timestamp": "1785163433004", "event_type": "price_change"}}
{"ts": 1785163433.523, "kind": "price_change", "data": {"market": "0x18b1c135d0a40c5894da9412e77311827d9caf16cf4cd6591b247a34730af919", "price_changes": [{"asset_id": "40081275558852222228080198821361202017557872256707631666334039001378518619916", "price": "0.41", "size": "2947.28", "side": "BUY", "hash": "e5dd9cccd4d5a679360181bfe82139409c8d06dc", "best_bid": "0.428", "best_ask": "0.429"}, {"asset_id": "78633590736077251574794513664747155551297291244492840448622550955320930591622", "price": "0.59", "size": "2947.28", "side": "SELL", "hash": "dc5d0ce5bdd97a1c195187583a0e616d3dc9bb65", "best_bid": "0.571", "best_ask": "0.572"}], "timestamp": "1785163433523", "event_type": "price_change"}}
{"ts": 1785163433.915, "kind": "price_change", "data": {"market": "0x18b1c135d0a40c5894da9412e77311827d9caf16cf4cd6591b247a34730af919", "price_changes": [{"asset_id": "78633590736077251574794513664747155551297291244492840448622550955320930591622", "price": "0.482", "size": "201.09", "side": "BUY", "hash": "60721d9449c81fe5f51f9bb88c0f5baa3ae4230c", "best_bid": "0.571", "best_ask": "0.572"}, {"asset_id": "40081275558852222228080198821361202017557872256707631666334039001378518619916", "price": "0.518", "size": "201.09", "side": "SELL", "hash": "a150e0985148497fa1f197615d130cedb2870a69", "best_bid": "0.428", "best_ask": "0.429"}], "timestamp": "1785163433915", "event_type": "price_change"}}
{"ts": 1785163433.936, "kind": "price_change", "data": {"market": "0x18b1c135d0a40c5894da9412e77311827d9caf16cf4cd6591b247a34730af919", "price_changes": [{"asset_id": "78633590736077251574794513664747155551297291244492840448622550955320930591622", "price": "0.485", "size": "77", "side": "BUY", "hash": "5b61d8d640ada8deba198ba13fa8439f2a293dfc", "best_bid": "0.571", "best_ask": "0.572"}, {"asset_id": "40081275558852222228080198821361202017557872256707631666334039001378518619916", "price": "0.515", "size": "77", "side": "SELL", "hash": "a8b47e5c337d4a6878647e804fb8ada01c47bfad", "best_bid": "0.428", "best_ask": "0.429"}], "timestamp": "1785163433936", "event_type": "price_change"}}
{"ts": 1785163435.637, "kind": "price_change", "data": {"market": "0x18b1c135d0a40c5894da9412e77311827d9caf16cf4cd6591b247a34730af919", "price_changes": [{"asset_id": "40081275558852222228080198821361202017557872256707631666334039001378518619916", "price": "0.507", "size": "0", "side": "SELL", "hash": "215634c196bb07c32b46fb0d2550ed4c192b06a9", "best_bid": "0.428", "best_ask": "0.429"}, {"asset_id": "78633590736077251574794513664747155551297291244492840448622550955320930591622", "price": "0.493", "size": "0", "side": "BUY", "hash": "3b4fcf17e1cbdfa541058d669e36612d2b8a00a6", "best_bid": "0.571", "best_ask": "0.572"}], "timestamp": "1785163435637", "event_type": "price_change"}}
{"ts": 1785163436.715, "kind": "price_change", "data": {"market": "0x18b1c135d0a40c5894da9412e77311827d9caf16cf4cd6591b247a34730af919", "price_changes": [{"asset_id": "40081275558852222228080198821361202017557872256707631666334039001378518619916", "price": "0.506", "size": "36.7", "side": "SELL", "hash": "f0fb54d145c6cd4754029322d780bd584aaaf9f6", "best_bid": "0.428", "best_ask": "0.429"}, {"asset_id": "78633590736077251574794513664747155551297291244492840448622550955320930591622", "price": "0.494", "size": "36.7", "side": "BUY", "hash": "d333fe48b82e201016df0934ca93f285c18d0c60", "best_bid": "0.571", "best_ask": "0.572"}], "timestamp": "1785163436715", "event_type": "price_change"}}
{"ts": 1785163437.362, "kind": "price_change", "data": {"market": "0x18b1c135d0a40c5894da9412e77311827d9caf16cf4cd6591b247a34730af919", "price_changes": [{"asset_id": "40081275558852222228080198821361202017557872256707631666334039001378518619916", "price": "0.506", "size": "0", "side": "SELL", "hash": "fefa4e6c92dc0313573e22173dc002996467e97a", "best_bid": "0.428", "best_ask": "0.429"}, {"asset_id": "78633590736077251574794513664747155551297291244492840448622550955320930591622", "price": "0.494", "size": "0", "side": "BUY", "hash": "8c4ad28ae7227f82d855d12fd3bdf34bc7f9512c", "best_bid": "0.571", "best_ask": "0.572"}], "timestamp": "1785163437362", "event_type": "price_change"}}
{"ts": 1785163437.818, "kind": "price_change", "data": {"market": "0x18b1c135d0a40c5894da9412e77311827d9caf16cf4cd6591b247a34730af919", "price_changes": [{"asset_id": "40081275558852222228080198821361202017557872256707631666334039001378518619916", "price": "0.507", "size": "36.7", "side": "SELL", "hash": "2bf5b322bcede7d14ef23b4ceb032dbe4dfdd2f2", "best_bid": "0.428", "best_ask": "0.429"}, {"asset_id": "78633590736077251574794513664747155551297291244492840448622550955320930591622", "price": "0.493", "size": "36.7", "side": "BUY", "hash": "b893624d7041aba9c49505574b61d1d52e5accd8", "best_bid": "0.571", "best_ask": "0.572"}], "timestamp": "1785163437818", "event_type": "price_change"}}
{"ts": 1785163439.138, "kind": "price_change", "data": {"market": "0x18b1c135d0a40c5894da9412e77311827d9caf16cf4cd6591b247a34730af919", "price_changes": [{"asset_id": "78633590736077251574794513664747155551297291244492840448622550955320930591622", "price": "0.311", "size": "49.27", "side": "BUY", "hash": "72e031c33508757a3d33642afbee69ed98d64093", "best_bid": "0.571", "best_ask": "0.572"}, {"asset_id": "40081275558852222228080198821361202017557872256707631666334039001378518619916", "price": "0.689", "size": "49.27", "side": "SELL", "hash": "9e73b7c24732cd5c9f658d6d07c29658fb09424e", "best_bid": "0.428", "best_ask": "0.429"}], "timestamp": "1785163439138", "event_type": "price_change"}}
{"ts": 1785163441.203, "kind": "price_change", "data": {"market": "0x18b1c135d0a40c5894da9412e77311827d9caf16cf4cd6591b247a34730af919", "price_changes": [{"asset_id": "40081275558852222228080198821361202017557872256707631666334039001378518619916", "price": "0.427", "size": "7659.99", "side": "BUY", "hash": "0458f801124a077efa89d4930d4f239a9728d71a", "best_bid": "0.428", "best_ask": "0.429"}, {"asset_id": "78633590736077251574794513664747155551297291244492840448622550955320930591622", "price": "0.573", "size": "7659.99", "side": "SELL", "hash": "9cfbd54868bf4b2e777fb5b8fdc3f0f7e690f865", "best_bid": "0.571", "best_ask": "0.572"}], "timestamp": "1785163441203", "event_type": "price_change"}}
{"ts": 1785163441.386, "kind": "price_change", "data": {"market": "0x18b1c135d0a40c5894da9412e77311827d9caf16cf4cd6591b247a34730af919", "price_changes": [{"asset_id": "78633590736077251574794513664747155551297291244492840448622550955320930591622", "price": "0.57", "size": "3695.84", "side": "BUY", "hash": "08e6a6cbd5714bb29ad108441d55122229287449", "best_bid": "0.571", "best_ask": "0.572"}, {"asset_id": "40081275558852222228080198821361202017557872256707631666334039001378518619916", "price": "0.43", "size": "3695.84", "side": "SELL", "hash": "d420de0ca42de2de8067d8ad81eaa75aebe35ca9", "best_bid": "0.428", "best_ask": "0.429"}], "timestamp": "1785163441386", "event_type": "price_change"}}
{"ts": 1785163441.507379, "kind": "orders_out", "data": [{"token_id": "40081275558852222228080198821361202017557872256707631666334039001378518619916", "side": "BUY", "price": 0.387, "size": 7.75}, {"token_id": "78633590736077251574794513664747155551297291244492840448622550955320930591622", "side": "BUY", "price": 0.529, "size": 5.67}]}
{"ts": 1785163441.461, "kind": "price_change", "data": {"market": "0x18b1c135d0a40c5894da9412e77311827d9caf16cf4cd6591b247a34730af919", "price_changes": [{"asset_id": "78633590736077251574794513664747155551297291244492840448622550955320930591622", "price": "0.548", "size": "10", "side": "BUY", "hash": "1856dc65cb482f40fe7441466f4571b37dd360f8", "best_bid": "0.571", "best_ask": "0.572"}, {"asset_id": "40081275558852222228080198821361202017557872256707631666334039001378518619916", "price": "0.452", "size": "10", "side": "SELL", "hash": "3707753292d5c86728b5835a5a5db97f43b6ae81", "best_bid": "0.428", "best_ask": "0.429"}], "timestamp": "1785163441461", "event_type": "price_change"}}
{"ts": 1785163442.0, "kind": "price_change", "data": {"market": "0x18b1c135d0a40c5894da9412e77311827d9caf16cf4cd6591b247a34730af919", "price_changes": [{"asset_id": "78633590736077251574794513664747155551297291244492840448622550955320930591622", "price": "0.08", "size": "1875", "side": "BUY", "hash": "f51b9ea437df83ffea6747ef2ad3c15dd0cc9a21", "best_bid": "0.571", "best_ask": "0.572"}, {"asset_id": "40081275558852222228080198821361202017557872256707631666334039001378518619916", "price": "0.92", "size": "1875", "side": "SELL", "hash": "ef6b029b872988c2ab14f60561246011cc453ab7", "best_bid": "0.428", "best_ask": "0.429"}], "timestamp": "1785163442000", "event_type": "price_change"}}
{"ts": 1785163442.006, "kind": "price_change", "data": {"market": "0x18b1c135d0a40c5894da9412e77311827d9caf16cf4cd6591b247a34730af919", "price_changes": [{"asset_id": "40081275558852222228080198821361202017557872256707631666334039001378518619916", "price": "0.03", "size": "118750", "side": "BUY", "hash": "7a61f582c11e5706c8224c4333c39141dfd5d5be", "best_bid": "0.428", "best_ask": "0.429"}, {"asset_id": "78633590736077251574794513664747155551297291244492840448622550955320930591622", "price": "0.97", "size": "118750", "side": "SELL", "hash": "3ffe1ac9a4c362b31775e11b7580cb0378c44e5a", "best_bid": "0.571", "best_ask": "0.572"}], "timestamp": "1785163442006", "event_type": "price_change"}}
{"ts": 1785163442.151, "kind": "price_change", "data": {"market": "0x18b1c135d0a40c5894da9412e77311827d9caf16cf4cd6591b247a34730af919", "price_changes": [{"asset_id": "78633590736077251574794513664747155551297291244492840448622550955320930591622", "price": "0.549", "size": "9.99", "side": "BUY", "hash": "3a1c7cdd04fcf3d7bb4ccb9bdbe8ffdfaf8d655d", "best_bid": "0.571", "best_ask": "0.572"}, {"asset_id": "40081275558852222228080198821361202017557872256707631666334039001378518619916", "price": "0.451", "size": "9.99", "side": "SELL", "hash": "ff6c470163100a5d34f7e8730af4d77bd8e35a98", "best_bid": "0.428", "best_ask": "0.429"}], "timestamp": "1785163442151", "event_type": "price_change"}}
{"ts": 1785163445.0, "kind": "price_change", "data": {"market": "0x0f49db97f71c68b1e42a6d16e3de93d85dbf7d4148e3f018eb79e88554be9f75", "price_changes": [{"asset_id": "87854174148074652060467921081181402357467303721471806610111179101805869578687", "price": "0.803", "size": "12134.97", "side": "BUY", "hash": "a2135c938016f83faf9f839063472e5a71eaabd4", "best_bid": "0.805", "best_ask": "0.806"}, {"asset_id": "54533043819946592547517511176940999955633860128497669742211153063842200957669", "price": "0.197", "size": "12134.97", "side": "SELL", "hash": "530bf93eae605e6ae03b2636e3dfcf6e3d562e0b", "best_bid": "0.194", "best_ask": "0.195"}], "timestamp": "1785163445000", "event_type": "price_change"}}
{"ts": 1785163445.001, "kind": "price_change", "data": {"market": "0x0f49db97f71c68b1e42a6d16e3de93d85dbf7d4148e3f018eb79e88554be9f75", "price_changes": [{"asset_id": "54533043819946592547517511176940999955633860128497669742211153063842200957669", "price": "0.193", "size": "10687", "side": "BUY", "hash": "8955dc461975938a9ea089b716999556bf3704f0", "best_bid": "0.194", "best_ask": "0.195"}, {"asset_id": "87854174148074652060467921081181402357467303721471806610111179101805869578687", "price": "0.807", "size": "10687", "side": "SELL", "hash": "a2135c938016f83faf9f839063472e5a71eaabd4", "best_bid": "0.805", "best_ask": "0.806"}], "timestamp": "1785163445001", "event_type": "price_change"}}
{"ts": 1785163445.002, "kind": "price_change", "data": {"market": "0x0f49db97f71c68b1e42a6d16e3de93d85dbf7d4148e3f018eb79e88554be9f75", "price_changes": [{"asset_id": "54533043819946592547517511176940999955633860128497669742211153063842200957669", "price": "0.193", "size": "10687", "side": "BUY", "hash": "d0bd9d3fe7b8cd4603265af897e94d369abd1755", "best_bid": "0.194", "best_ask": "0.195"}, {"asset_id": "87854174148074652060467921081181402357467303721471806610111179101805869578687", "price": "0.807", "size": "10687", "side": "SELL", "hash": "92b74048c154ecb662c309ee15f660d4571f47a9", "best_bid": "0.805", "best_ask": "0.806"}], "timestamp": "1785163445002", "event_type": "price_change"}}
{"ts": 1785163445.002, "kind": "price_change", "data": {"market": "0x0f49db97f71c68b1e42a6d16e3de93d85dbf7d4148e3f018eb79e88554be9f75", "price_changes": [{"asset_id": "87854174148074652060467921081181402357467303721471806610111179101805869578687", "price": "0.37", "size": "0", "side": "BUY", "hash": "92b74048c154ecb662c309ee15f660d4571f47a9", "best_bid": "0.805", "best_ask": "0.806"}, {"asset_id": "54533043819946592547517511176940999955633860128497669742211153063842200957669", "price": "0.63", "size": "0", "side": "SELL", "hash": "d0bd9d3fe7b8cd4603265af897e94d369abd1755", "best_bid": "0.194", "best_ask": "0.195"}], "timestamp": "1785163445002", "event_type": "price_change"}}
{"ts": 1785163445.002, "kind": "price_change", "data": {"market": "0x0f49db97f71c68b1e42a6d16e3de93d85dbf7d4148e3f018eb79e88554be9f75", "price_changes": [{"asset_id": "87854174148074652060467921081181402357467303721471806610111179101805869578687", "price": "0.803", "size": "12134.97", "side": "BUY", "hash": "92b74048c154ecb662c309ee15f660d4571f47a9", "best_bid": "0.805", "best_ask": "0.806"}, {"asset_id": "54533043819946592547517511176940999955633860128497669742211153063842200957669", "price": "0.197", "size": "12134.97", "side": "SELL", "hash": "d0bd9d3fe7b8cd4603265af897e94d369abd1755", "best_bid": "0.194", "best_ask": "0.195"}], "timestamp": "1785163445002", "event_type": "price_change"}}
{"ts": 1785163445.037, "kind": "price_change", "data": {"market": "0x0f49db97f71c68b1e42a6d16e3de93d85dbf7d4148e3f018eb79e88554be9f75", "price_changes": [{"asset_id": "54533043819946592547517511176940999955633860128497669742211153063842200957669", "price": "0.193", "size": "10787", "side": "BUY", "hash": "1af730c125ac2ad5ba5444f0ba495e58b2fc6c5f", "best_bid": "0.194", "best_ask": "0.195"}, {"asset_id": "87854174148074652060467921081181402357467303721471806610111179101805869578687", "price": "0.807", "size": "10787", "side": "SELL", "hash": "e08e795ea2985f4fc4d62b86ec58a3448e7ed7ca", "best_bid": "0.805", "best_ask": "0.806"}], "timestamp": "1785163445037", "event_type": "price_change"}}
{"ts": 1785163445.038, "kind": "price_change", "data": {"market": "0x0f49db97f71c68b1e42a6d16e3de93d85dbf7d4148e3f018eb79e88554be9f75", "price_changes": [{"asset_id": "87854174148074652060467921081181402357467303721471806610111179101805869578687", "price": "0.803", "size": "12234.97", "side": "BUY", "hash": "b3de3ad2dbb1c9faa0fd7c08d3de3b3ef108359d", "best_bid": "0.805", "best_ask": "0.806"}, {"asset_id": "54533043819946592547517511176940999955633860128497669742211153063842200957669", "price": "0.197", "size": "12234.97", "side": "SELL", "hash": "f10197319ce10c590a78019a0a38612337b74ed2", "best_bid": "0.194", "best_ask": "0.195"}], "timestamp": "1785163445038", "event_type": "price_change"}}
{"ts": 1785163445.039, "kind": "price_change", "data": {"market": "0x0f49db97f71c68b1e42a6d16e3de93d85dbf7d4148e3f018eb79e88554be9f75", "price_changes": [{"asset_id": "54533043819946592547517511176940999955633860128497669742211153063842200957669", "price": "0.193", "size": "10887", "side": "BUY", "hash": "4610e32fb9ce24365073fccc9ff17706016da383", "best_bid": "0.194", "best_ask": "0.195"}, {"asset_id": "87854174148074652060467921081181402357467303721471806610111179101805869578687", "price": "0.807", "size": "10887", "side": "SELL", "hash": "dec06760852ff9b6c12631e4bb73a95a2bbacc5b", "best_bid": "0.805", "best_ask": "0.806"}], "timestamp": "1785163445039", "event_type": "price_change"}}
{"ts": 1785163445.056, "kind": "price_change", "data": {"market": "0x0f49db97f71c68b1e42a6d16e3de93d85dbf7d4148e3f018eb79e88554be9f75", "price_changes": [{"asset_id": "87854174148074652060467921081181402357467303721471806610111179101805869578687", "price": "0.803", "size": "12334.97", "side": "BUY", "hash": "3e2cbf5ce08013e43002ea89304b937e93258e1c", "best_bid": "0.805", "best_ask": "0.806"}, {"asset_id": "54533043819946592547517511176940999955633860128497669742211153063842200957669", "price": "0.197", "size": "12334.97", "side": "SELL", "hash": "eff132d69d97de51f911b211af68792f4436b0f5", "best_bid": "0.194", "best_ask": "0.195"}], "timestamp": "1785163445056", "event_type": "price_change"}}
{"ts": 1785163446.908, "kind": "price_change", "data": {"market": "0x18b1c135d0a40c5894da9412e77311827d9caf16cf4cd6591b247a34730af919", "price_changes": [{"asset_id": "40081275558852222228080198821361202017557872256707631666334039001378518619916", "price": "0.507", "size": "0", "side": "SELL", "hash": "a4aff9868851487f9d7fa6812e4736d549d47d80", "best_bid": "0.428", "best_ask": "0.429"}, {"asset_id": "78633590736077251574794513664747155551297291244492840448622550955320930591622", "price": "0.493", "size": "0", "side": "BUY", "hash": "bfb8fdd57913b8187ca842263c4cb13321f88909", "best_bid": "0.571", "best_ask": "0.572"}], "timestamp": "1785163446908", "event_type": "price_change"}}
{"ts": 1785163447.916, "kind": "price_change", "data": {"market": "0x18b1c135d0a40c5894da9412e77311827d9caf16cf4cd6591b247a34730af919", "price_changes": [{"asset_id": "40081275558852222228080198821361202017557872256707631666334039001378518619916", "price": "0.506", "size": "36.7", "side": "SELL", "hash": "132b2a35a5ef9ba22055f0a19f204d267add8756", "best_bid": "0.428", "best_ask": "0.429"}, {"asset_id": "78633590736077251574794513664747155551297291244492840448622550955320930591622", "price": "0.494", "size": "36.7", "side": "BUY", "hash": "6864c4aeff5df2fac0f735f80d8bf47c9d26044f", "best_bid": "0.571", "best_ask": "0.572"}], "timestamp": "1785163447916", "event_type": "price_change"}}
{"ts": 1785163448.896, "kind": "price_change", "data": {"market": "0x18b1c135d0a40c5894da9412e77311827d9caf16cf4cd6591b247a34730af919", "price_changes": [{"asset_id": "40081275558852222228080198821361202017557872256707631666334039001378518619916", "price": "0.506", "size": "0", "side": "SELL", "hash": "d0a28c36462772ab8e72e7fc9b862396a2edc61e", "best_bid": "0.428", "best_ask": "0.429"}, {"asset_id": "78633590736077251574794513664747155551297291244492840448622550955320930591622", "price": "0.494", "size": "0", "side": "BUY", "hash": "a15c28631e7c97f81eb8a8ded43332be0c93f93a", "best_bid": "0.571", "best_ask": "0.572"}], "timestamp": "1785163448896", "event_type": "price_change"}}
{"ts": 1785163449.216, "kind": "price_change", "data": {"market": "0x18b1c135d0a40c5894da9412e77311827d9caf16cf4cd6591b247a34730af919", "price_changes": [{"asset_id": "40081275558852222228080198821361202017557872256707631666334039001378518619916", "price": "0.507", "size": "36.7", "side": "SELL", "hash": "3b4e6e62d8f15be2f0acc77ece04a8143673a79e", "best_bid": "0.428", "best_ask": "0.429"}, {"asset_id": "78633590736077251574794513664747155551297291244492840448622550955320930591622", "price": "0.493", "size": "36.7", "side": "BUY", "hash": "1fedd32e8cc2c28360e30f87591f064c8a4a1b17", "best_bid": "0.571", "best_ask": "0.572"}], "timestamp": "1785163449216", "event_type": "price_change"}}
{"ts": 1785163449.868, "kind": "price_change", "data": {"market": "0x18b1c135d0a40c5894da9412e77311827d9caf16cf4cd6591b247a34730af919", "price_changes": [{"asset_id": "40081275558852222228080198821361202017557872256707631666334039001378518619916", "price": "0.03", "size": "158750", "side": "BUY", "hash": "07a2ea4a4dce5560791b0b798fde6f90f746ac90", "best_bid": "0.428", "best_ask": "0.429"}, {"asset_id": "78633590736077251574794513664747155551297291244492840448622550955320930591622", "price": "0.97", "size": "158750", "side": "SELL", "hash": "482337db2315ed58b17007fa669e57832da7d967", "best_bid": "0.571", "best_ask": "0.572"}], "timestamp": "1785163449868", "event_type": "price_change"}}
{"ts": 1785163449.869, "kind": "price_change", "data": {"market": "0x18b1c135d0a40c5894da9412e77311827d9caf16cf4cd6591b247a34730af919", "price_changes": [{"asset_id": "78633590736077251574794513664747155551297291244492840448622550955320930591622", "price": "0.08", "size": "16875", "side": "BUY", "hash": "a86ca466eae11884f7b625b74492ea0d681c6e13", "best_bid": "0.571", "best_ask": "0.572"}, {"asset_id": "40081275558852222228080198821361202017557872256707631666334039001378518619916", "price": "0.92", "size": "16875", "side": "SELL", "hash": "bb6e96f78fd245cb72963c2fa60a76f041391e39", "best_bid": "0.428", "best_ask": "0.429"}], "timestamp": "1785163449869", "event_type": "price_change"}}
{"ts": 1785163450.001, "kind": "price_change", "data": {"market": "0x18b1c135d0a40c5894da9412e77311827d9caf16cf4cd6591b247a34730af919", "price_changes": [{"asset_id": "40081275558852222228080198821361202017557872256707631666334039001378518619916", "price": "0.412", "size": "11123.8", "side": "BUY", "hash": "7733fc02967cd80cd5bae2efb70634713477528a", "best_bid": "0.428", "best_ask": "0.429"}, {"asset_id": "78633590736077251574794513664747155551297291244492840448622550955320930591622", "price": "0.588", "size": "11123.8", "side": "SELL", "hash": "a81da90ff484a0ee33e987a20c1f23f52306d22a", "best_bid": "0.571", "best_ask": "0.572"}], "timestamp": "1785163450001", "event_type": "price_change"}}
{"ts": 1785163450.002, "kind": "price_change", "data": {"market": "0x18b1c135d0a40c5894da9412e77311827d9caf16cf4cd6591b247a34730af919", "price_changes": [{"asset_id": "78633590736077251574794513664747155551297291244492840448622550955320930591622", "price": "0.55", "size": "30179.18", "side": "BUY", "hash": "cd48fde6eca780042e8523deab19835502fb5a45", "best_bid": "0.571", "best_ask": "0.572"}, {"asset_id": "40081275558852222228080198821361202017557872256707631666334039001378518619916", "price": "0.45", "size": "30179.18", "side": "SELL", "hash": "0af007ba0dc83931e63a4c544082b9c9eebb4b93", "best_bid": "0.428", "best_ask": "0.429"}], "timestamp": "1785163450002", "event_type": "price_change"}}
{"ts": 1785163450.002, "kind": "price_change", "data": {"market": "0x18b1c135d0a40c5894da9412e77311827d9caf16cf4cd6591b247a34730af919", "price_changes": [{"asset_id": "78633590736077251574794513664747155551297291244492840448622550955320930591622", "price": "0.551", "size": "28506.16", "side": "BUY", "hash": "cd48fde6eca780042e8523deab19835502fb5a45", "best_bid": "0.571", "best_ask": "0.572"}, {"asset_id": "40081275558852222228080198821361202017557872256707631666334039001378518619916", "price": "0.449", "size": "28506.16", "side": "SELL", "hash": "0af007ba0dc83931e63a4c544082b9c9eebb4b93", "best_bid": "0.428", "best_ask": "0.429"}], "timestamp": "1785163450002", "event_type": "price_change"}}
{"ts": 1785163450.039, "kind": "price_change", "data": {"market": "0x18b1c135d0a40c5894da9412e77311827d9caf16cf4cd6591b247a34730af919", "price_changes": [{"asset_id": "78633590736077251574794513664747155551297291244492840448622550955320930591622", "price": "0.551", "size": "28706.16", "side": "BUY", "hash": "347e2d0bb877932acc36a12e4eefe569d5046925", "best_bid": "0.571", "best_ask": "0.572"}, {"asset_id": "40081275558852222228080198821361202017557872256707631666334039001378518619916", "price": "0.449", "size": "28706.16", "side": "SELL", "hash": "186c09ba7622e762844d2a4023f5c0caf6725d82", "best_bid": "0.428", "best_ask": "0.429"}], "timestamp": "1785163450039", "event_type": "price_change"}}
{"ts": 1785163450.047, "kind": "price_change", "data": {"market": "0x18b1c135d0a40c5894da9412e77311827d9caf16cf4cd6591b247a34730af919", "price_changes": [{"asset_id": "78633590736077251574794513664747155551297291244492840448622550955320930591622", "price": "0.55", "size": "30379.18", "side": "BUY", "hash": "a2a5148dd23221b367656359e1a6f46d7afb9324", "best_bid": "0.571", "best_ask": "0.572"}, {"asset_id": "40081275558852222228080198821361202017557872256707631666334039001378518619916", "price": "0.45", "size": "30379.18", "side": "SELL", "hash": "668c5bd5a0a8a2ebf4c39c292289d085793b71b0", "best_bid": "0.428", "best_ask": "0.429"}], "timestamp": "1785163450047", "event_type": "price_change"}}
{"ts": 1785163450.055, "kind": "price_change", "data": {"market": "0x18b1c135d0a40c5894da9412e77311827d9caf16cf4cd6591b247a34730af919", "price_changes": [{"asset_id": "40081275558852222228080198821361202017557872256707631666334039001378518619916", "price": "0.412", "size": "11323.8", "side": "BUY", "hash": "3cb8368418b325702caf252771f9eaa127b83903", "best_bid": "0.428", "best_ask": "0.429"}, {"asset_id": "78633590736077251574794513664747155551297291244492840448622550955320930591622", "price": "0.588", "size": "11323.8", "side": "SELL", "hash": "e6c80b1041150373181252ebbe9d6b4022371059", "best_bid": "0.571", "best_ask": "0.572"}], "timestamp": "1785163450055", "event_type": "price_change"}}
{"ts": 1785163450.165, "kind": "price_change", "data": {"market": "0x18b1c135d0a40c5894da9412e77311827d9caf16cf4cd6591b247a34730af919", "price_changes": [{"asset_id": "40081275558852222228080198821361202017557872256707631666334039001378518619916", "price": "0.41", "size": "2931.23", "side": "BUY", "hash": "11443540fb45e536f6b06ec96ebe3fbd4e308f9e", "best_bid": "0.428", "best_ask": "0.429"}, {"asset_id": "78633590736077251574794513664747155551297291244492840448622550955320930591622", "price": "0.59", "size": "2931.23", "side": "SELL", "hash": "e4ed313fc8ecd5791a6a6c0e5fbe1069fac74dce", "best_bid": "0.571", "best_ask": "0.572"}], "timestamp": "1785163450165", "event_type": "price_change"}}
{"ts": 1785163450.897, "kind": "price_change", "data": {"market": "0x18b1c135d0a40c5894da9412e77311827d9caf16cf4cd6591b247a34730af919", "price_changes": [{"asset_id": "40081275558852222228080198821361202017557872256707631666334039001378518619916", "price": "0.41", "size": "2947.28", "side": "BUY", "hash": "33a4c425d353101af967fb8b62ed7b79000c96af", "best_bid": "0.428", "best_ask": "0.429"}, {"asset_id": "78633590736077251574794513664747155551297291244492840448622550955320930591622", "price": "0.59", "size": "2947.28", "side": "SELL", "hash": "6816d68dfec2265e872444a86d8f743602d4f988", "best_bid": "0.571", "best_ask": "0.572"}], "timestamp": "1785163450897", "event_type": "price_change"}}
{"ts": 1785163452.222, "kind": "price_change", "data": {"market": "0x0f49db97f71c68b1e42a6d16e3de93d85dbf7d4148e3f018eb79e88554be9f75", "price_changes": [{"asset_id": "87854174148074652060467921081181402357467303721471806610111179101805869578687", "price": "0.37", "size": "2702", "side": "BUY", "hash": "bb285c102fa1d39077213bdf4b318f256e7c11c8", "best_bid": "0.805", "best_ask": "0.806"}, {"asset_id": "54533043819946592547517511176940999955633860128497669742211153063842200957669", "price": "0.63", "size": "2702", "side": "SELL", "hash": "20d886c3a32676dd3961e29f02554cdb6106b2bf", "best_bid": "0.194", "best_ask": "0.195"}], "timestamp": "1785163452222", "event_type": "price_change"}}
{"ts": 1785163452.684939, "kind": "orders_out", "data": [{"token_id": "54533043819946592547517511176940999955633860128497669742211153063842200957669", "side": "BUY", "price": 0.153, "size": 19.61}]}
{"ts": 1785163453.003, "kind": "price_change", "data": {"market": "0x18b1c135d0a40c5894da9412e77311827d9caf16cf4cd6591b247a34730af919", "price_changes": [{"asset_id": "40081275558852222228080198821361202017557872256707631666334039001378518619916", "price": "0.28", "size": "0", "side": "BUY", "hash": "9b75e0ee8973d2f62ca92fa9dd50d00d13441db7", "best_bid": "0.428", "best_ask": "0.429"}, {"asset_id": "78633590736077251574794513664747155551297291244492840448622550955320930591622", "price": "0.72", "size": "0", "side": "SELL", "hash": "f05d94ed2946408348e5e3177e35b3e65d5db5da", "best_bid": "0.571", "best_ask": "0.572"}], "timestamp": "1785163453003", "event_type": "price_change"}}
{"ts": 1785163454.616, "kind": "price_change", "data": {"market": "0x0f49db97f71c68b1e42a6d16e3de93d85dbf7d4148e3f018eb79e88554be9f75", "price_changes": [{"asset_id": "87854174148074652060467921081181402357467303721471806610111179101805869578687", "price": "0.795", "size": "3127.98", "side": "BUY", "hash": "f5fe3e9ff10b4843016c0114f10561ff0814ad0f", "best_bid": "0.805", "best_ask": "0.806"}, {"asset_id": "54533043819946592547517511176940999955633860128497669742211153063842200957669", "price": "0.205", "size": "3127.98", "side": "SELL", "hash": "eaf0a3bfce70f6a27d06266412e58997d8bb5276", "best_bid": "0.194", "best_ask": "0.195"}], "timestamp": "1785163454616", "event_type": "price_change"}}
{"ts": 1785163454.708, "kind": "price_change", "data": {"market": "0x0f49db97f71c68b1e42a6d16e3de93d85dbf7d4148e3f018eb79e88554be9f75", "price_changes": [{"asset_id": "87854174148074652060467921081181402357467303721471806610111179101805869578687", "price": "0.795", "size": "3694.98", "side": "BUY", "hash": "e4fce9c8145868edc830d9604594c1a39724a66e", "best_bid": "0.805", "best_ask": "0.806"}, {"asset_id": "54533043819946592547517511176940999955633860128497669742211153063842200957669", "price": "0.205", "size": "3694.98", "side": "SELL", "hash": "6519d39b7c0a3b3fc5a729065d271bb457adf16d", "best_bid": "0.194", "best_ask": "0.195"}], "timestamp": "1785163454708", "event_type": "price_change"}}
{"ts": 1785163455.005, "kind": "price_change", "data": {"market": "0x18b1c135d0a40c5894da9412e77311827d9caf16cf4cd6591b247a34730af919", "price_changes": [{"asset_id": "40081275558852222228080198821361202017557872256707631666334039001378518619916", "price": "0.411", "size": "36707.4", "side": "BUY", "hash": "a31f60b108da6e2819b598c4ed11d96fec0fb598", "best_bid": "0.428", "best_ask": "0.429"}, {"asset_id": "78633590736077251574794513664747155551297291244492840448622550955320930591622", "price": "0.589", "size": "36707.4", "side": "SELL", "hash": "2e5c54c3198d7a2273c32192819039ed4a2ee133", "best_bid": "0.571", "best_ask": "0.572"}], "timestamp": "1785163455005", "event_type": "price_change"}}
{"ts": 1785163455.038, "kind": "price_change", "data": {"market": "0x18b1c135d0a40c5894da9412e77311827d9caf16cf4cd6591b247a34730af919", "price_changes": [{"asset_id": "40081275558852222228080198821361202017557872256707631666334039001378518619916", "price": "0.411", "size": "36907.4", "side": "BUY", "hash": "ca90d9a23c37d19c9298de751d1c1feaa5028c3b", "best_bid": "0.428", "best_ask": "0.429"}, {"asset_id": "78633590736077251574794513664747155551297291244492840448622550955320930591622", "price": "0.589", "size": "36907.4", "side": "SELL", "hash": "f50c9c81fd7046d5d7d82b063325039606167041", "best_bid": "0.571", "best_ask": "0.572"}], "timestamp": "1785163455038", "event_type": "price_change"}}
{"ts": 1785163455.387, "kind": "price_change", "data": {"market": "0x18b1c135d0a40c5894da9412e77311827d9caf16cf4cd6591b247a34730af919", "price_changes": [{"asset_id": "40081275558852222228080198821361202017557872256707631666334039001378518619916", "price": "0.418", "size": "5970.05", "side": "BUY", "hash": "fb05bc1c099df2c081b0e60bfda7a413416cd52d", "best_bid": "0.428", "best_ask": "0.429"}, {"asset_id": "78633590736077251574794513664747155551297291244492840448622550955320930591622", "price": "0.582", "size": "5970.05", "side": "SELL", "hash": "f69702b2b57d790081f819d49b70711cc2bfac90", "best_bid": "0.571", "best_ask": "0.572"}], "timestamp": "1785163455387", "event_type": "price_change"}}
{"ts": 1785163455.483, "kind": "price_change", "data": {"market": "0x18b1c135d0a40c5894da9412e77311827d9caf16cf4cd6591b247a34730af919", "price_changes": [{"asset_id": "40081275558852222228080198821361202017557872256707631666334039001378518619916", "price": "0.418", "size": "7048.05", "side": "BUY", "hash": "3a673b352a2a564e174d37c06f16d91b74466652", "best_bid": "0.428", "best_ask": "0.429"}, {"asset_id": "78633590736077251574794513664747155551297291244492840448622550955320930591622", "price": "0.582", "size": "7048.05", "side": "SELL", "hash": "ce7b99e6435fdaf90ec3b982422196054ec6ad69", "best_bid": "0.571", "best_ask": "0.572"}], "timestamp": "1785163455483", "event_type": "price_change"}}
{"ts": 1785163455.982, "kind": "price_change", "data": {"market": "0x18b1c135d0a40c5894da9412e77311827d9caf16cf4cd6591b247a34730af919", "price_changes": [{"asset_id": "40081275558852222228080198821361202017557872256707631666334039001378518619916", "price": "0.23", "size": "1086", "side": "BUY", "hash": "bab4448388e9118fb364ba3dc0e14efc10db9691", "best_bid": "0.428", "best_ask": "0.429"}, {"asset_id": "78633590736077251574794513664747155551297291244492840448622550955320930591622", "price": "0.77", "size": "1086", "side": "SELL", "hash": "a92fa83f9d93c1ea7bac19a162a92b284534ecfb", "best_bid": "0.571", "best_ask": "0.572"}], "timestamp": "1785163455982", "event_type": "price_change"}}
{"ts": 1785163456.003, "kind": "price_change", "data": {"market": "0x0f49db97f71c68b1e42a6d16e3de93d85dbf7d4148e3f018eb79e88554be9f75", "price_changes": [{"asset_id": "87854174148074652060467921081181402357467303721471806610111179101805869578687", "price": "0.02", "size": "13000", "side": "BUY", "hash": "9f6a371aa0c9a5bf3c8c44ae8f57dab009a19b37", "best_bid": "0.805", "best_ask": "0.806"}, {"asset_id": "54533043819946592547517511176940999955633860128497669742211153063842200957669", "price": "0.98", "size": "13000", "side": "SELL", "hash": "751b82a09e0e8a77ad59686c1bd8175dc5db3ff0", "best_bid": "0.194", "best_ask": "0.195"}], "timestamp": "1785163456003", "event_type": "price_change"}}
{"ts": 1785163456.003, "kind": "price_change", "data": {"market": "0x0f49db97f71c68b1e42a6d16e3de93d85dbf7d4148e3f018eb79e88554be9f75", "price_changes": [{"asset_id": "87854174148074652060467921081181402357467303721471806610111179101805869578687", "price": "0.02", "size": "13000", "side": "BUY", "hash": "9f6a371aa0c9a5bf3c8c44ae8f57dab009a19b37", "best_bid": "0.805", "best_ask": "0.806"}, {"asset_id": "54533043819946592547517511176940999955633860128497669742211153063842200957669", "price": "0.98", "size": "13000", "side": "SELL", "hash": "751b82a09e0e8a77ad59686c1bd8175dc5db3ff0", "best_bid": "0.194", "best_ask": "0.195"}], "timestamp": "1785163456003", "event_type": "price_change"}}
{"ts": 1785163456.005, "kind": "price_change", "data": {"market": "0x0f49db97f71c68b1e42a6d16e3de93d85dbf7d4148e3f018eb79e88554be9f75", "price_changes": [{"asset_id": "87854174148074652060467921081181402357467303721471806610111179101805869578687", "price": "0.02", "size": "13000", "side": "BUY", "hash": "232e386735774e75ef4ee0920c392a43ebcdbce0", "best_bid": "0.805", "best_ask": "0.806"}, {"asset_id": "54533043819946592547517511176940999955633860128497669742211153063842200957669", "price": "0.98", "size": "13000", "side": "SELL", "hash": "8cd8905d8219cc21ff6d15c9ea784766e7c9ee59", "best_bid": "0.194", "best_ask": "0.195"}], "timestamp": "1785163456005", "event_type": "price_change"}}
{"ts": 1785163463.058, "kind": "price_change", "data": {"market": "0x0f49db97f71c68b1e42a6d16e3de93d85dbf7d4148e3f018eb79e88554be9f75", "price_changes": [{"asset_id": "87854174148074652060467921081181402357467303721471806610111179101805869578687", "price": "0.02", "size": "73000", "side": "BUY", "hash": "d7a6b32bb6dac5d50d904b3c7c5d52ffee8622d1", "best_bid": "0.805", "best_ask": "0.806"}, {"asset_id": "54533043819946592547517511176940999955633860128497669742211153063842200957669", "price": "0.98", "size": "73000", "side": "SELL", "hash": "e3fb4005d23ffcbbc62d529de0bd1cf92936975d", "best_bid": "0.194", "best_ask": "0.195"}], "timestamp": "1785163463058", "event_type": "price_change"}}
{"ts": 1785163463.059, "kind": "price_change", "data": {"market": "0x0f49db97f71c68b1e42a6d16e3de93d85dbf7d4148e3f018eb79e88554be9f75", "price_changes": [{"asset_id": "87854174148074652060467921081181402357467303721471806610111179101805869578687", "price": "0.02", "size": "148000", "side": "BUY", "hash": "32f1af118a869c08c51983c2a86de3c63d3529b6", "best_bid": "0.805", "best_ask": "0.806"}, {"asset_id": "54533043819946592547517511176940999955633860128497669742211153063842200957669", "price": "0.98", "size": "148000", "side": "SELL", "hash": "31a6d530ba3a7a7c7f131df22d3e1d91ac15e8f6", "best_bid": "0.194", "best_ask": "0.195"}], "timestamp": "1785163463059", "event_type": "price_change"}}
{"ts": 1785163463.06, "kind": "price_change", "data": {"market": "0x0f49db97f71c68b1e42a6d16e3de93d85dbf7d4148e3f018eb79e88554be9f75", "price_changes": [{"asset_id": "87854174148074652060467921081181402357467303721471806610111179101805869578687", "price": "0.02", "size": "233000", "side": "BUY", "hash": "7aebc314f35feee78303181b540965f5974793aa", "best_bid": "0.805", "best_ask": "0.806"}, {"asset_id": "54533043819946592547517511176940999955633860128497669742211153063842200957669", "price": "0.98", "size": "233000", "side": "SELL", "hash": "d773f3f96aa9f3caf66987442f45bf28410f458d", "best_bid": "0.194", "best_ask": "0.195"}], "timestamp": "1785163463060", "event_type": "price_change"}}
{"ts": 1785163464.554, "kind": "price_change", "data": {"market": "0x0f49db97f71c68b1e42a6d16e3de93d85dbf7d4148e3f018eb79e88554be9f75", "price_changes": [{"asset_id": "87854174148074652060467921081181402357467303721471806610111179101805869578687", "price": "0.795", "size": "3128.98", "side": "BUY", "hash": "89243a7f4f9ed52af331586007e8dcfedebbd16e", "best_bid": "0.805", "best_ask": "0.806"}, {"asset_id": "54533043819946592547517511176940999955633860128497669742211153063842200957669", "price": "0.205", "size": "3128.98", "side": "SELL", "hash": "04eae71552c63c05864bf69ff68172b3046cbb99", "best_bid": "0.194", "best_ask": "0.195"}], "timestamp": "1785163464554", "event_type": "price_change"}}
{"ts": 1785163464.558, "kind": "price_change", "data": {"market": "0x0f49db97f71c68b1e42a6d16e3de93d85dbf7d4148e3f018eb79e88554be9f75", "price_changes": [{"asset_id": "54533043819946592547517511176940999955633860128497669742211153063842200957669", "price": "0.009", "size": "13888.88", "side": "BUY", "hash": "1a8c31e57c740eae8166260b5bd9b94ad345acda", "best_bid": "0.194", "best_ask": "0.195"}, {"asset_id": "87854174148074652060467921081181402357467303721471806610111179101805869578687", "price": "0.991", "size": "13888.88", "side": "SELL", "hash": "1d50210c9fe8d12870f8df06e5d5a83dfc67883a", "best_bid": "0.805", "best_ask": "0.806"}], "timestamp": "1785163464558", "event_type": "price_change"}}
{"ts": 1785163464.561, "kind": "price_change", "data": {"market": "0x0f49db97f71c68b1e42a6d16e3de93d85dbf7d4148e3f018eb79e88554be9f75", "price_changes": [{"asset_id": "54533043819946592547517511176940999955633860128497669742211153063842200957669", "price": "0.007", "size": "53571.42", "side": "BUY", "hash": "e996ea87ccd3becad82a0d9fb1fc4625b8a117ec", "best_bid": "0.194", "best_ask": "0.195"}, {"asset_id": "87854174148074652060467921081181402357467303721471806610111179101805869578687", "price": "0.993", "size": "53571.42", "side": "SELL", "hash": "f972aa54429a30294e5528b4cf4c0c093f09ba2d", "best_bid": "0.805", "best_ask": "0.806"}], "timestamp": "1785163464561", "event_type": "price_change"}}
{"ts": 1785163464.635, "kind": "price_change", "data": {"market": "0x0f49db97f71c68b1e42a6d16e3de93d85dbf7d4148e3f018eb79e88554be9f75", "price_changes": [{"asset_id": "54533043819946592547517511176940999955633860128497669742211153063842200957669", "price": "0.176", "size": "12220.93", "side": "BUY", "hash": "891413363a43a8716b276cd8b9e0577dfc181ab8", "best_bid": "0.194", "best_ask": "0.195"}, {"asset_id": "87854174148074652060467921081181402357467303721471806610111179101805869578687", "price": "0.824", "size": "12220.93", "side": "SELL", "hash": "100b6cab28800097f66248432d7394b39ee140ea", "best_bid": "0.805", "best_ask": "0.806"}], "timestamp": "1785163464635", "event_type": "price_change"}}
{"ts": 1785163464.636, "kind": "price_change", "data": {"market": "0x0f49db97f71c68b1e42a6d16e3de93d85dbf7d4148e3f018eb79e88554be9f75", "price_changes": [{"asset_id": "87854174148074652060467921081181402357467303721471806610111179101805869578687", "price": "0.795", "size": "3694.98", "side": "BUY", "hash": "8b24dd0fddbded9bc2d139f805fb90812a7fc3d4", "best_bid": "0.805", "best_ask": "0.806"}, {"asset_id": "54533043819946592547517511176940999955633860128497669742211153063842200957669", "price": "0.205", "size": "3694.98", "side": "SELL", "hash": "9c61bd0e7745e07b28734dce1b544edcaea059ac", "best_bid": "0.194", "best_ask": "0.195"}], "timestamp": "1785163464636", "event_type": "price_change"}}
{"ts": 1785163465.115, "kind": "price_change", "data": {"market": "0x18b1c135d0a40c5894da9412e77311827d9caf16cf4cd6591b247a34730af919", "price_changes": [{"asset_id": "40081275558852222228080198821361202017557872256707631666334039001378518619916", "price": "0.418", "size": "5972.05", "side": "BUY", "hash": "8c39435935901a94469255d775ca5543337da94c", "best_bid": "0.428", "best_ask": "0.429"}, {"asset_id": "78633590736077251574794513664747155551297291244492840448622550955320930591622", "price": "0.582", "size": "5972.05", "side": "SELL", "hash": "30655d0b3b360adb6127a714e7d55adf76658717", "best_bid": "0.571", "best_ask": "0.572"}], "timestamp": "1785163465115", "event_type": "price_change"}}
{"ts": 1785163465.178, "kind": "price_change", "data": {"market": "0x18b1c135d0a40c5894da9412e77311827d9caf16cf4cd6591b247a34730af919", "price_changes": [{"asset_id": "40081275558852222228080198821361202017557872256707631666334039001378518619916", "price": "0.418", "size": "7048.05", "side": "BUY", "hash": "c8e96e528dd2501739d0c14c0ec2f8ef0837d510", "best_bid": "0.428", "best_ask": "0.429"}, {"asset_id": "78633590736077251574794513664747155551297291244492840448622550955320930591622", "price": "0.582", "size": "7048.05", "side": "SELL", "hash": "7476436aef5f59a7415bb0e3255e8f70ba286b71", "best_bid": "0.571", "best_ask": "0.572"}], "timestamp": "1785163465178", "event_type": "price_change"}}
{"ts": 1785163465.420135, "kind": "orders_out", "data": [{"token_id": "40081275558852222228080198821361202017557872256707631666334039001378518619916", "side": "BUY", "price": 0.387, "size": 7.75}, {"token_id": "78633590736077251574794513664747155551297291244492840448622550955320930591622", "side": "BUY", "price": 0.529, "size": 5.67}]}
{"ts": 1785163466.054, "kind": "price_change", "data": {"market": "0x18b1c135d0a40c5894da9412e77311827d9caf16cf4cd6591b247a34730af919", "price_changes": [{"asset_id": "40081275558852222228080198821361202017557872256707631666334039001378518619916", "price": "0.507", "size": "0", "side": "SELL", "hash": "f0bb83aee696c26c55ecb587d1f9a67fa09edfb9", "best_bid": "0.428", "best_ask": "0.429"}, {"asset_id": "78633590736077251574794513664747155551297291244492840448622550955320930591622", "price": "0.493", "size": "0", "side": "BUY", "hash": "2d3dca8d42103fe29669190a11bb488edced79d3", "best_bid": "0.571", "best_ask": "0.572"}], "timestamp": "1785163466054", "event_type": "price_change"}}
{"ts": 1785163466.934, "kind": "price_change", "data": {"market": "0x18b1c135d0a40c5894da9412e77311827d9caf16cf4cd6591b247a34730af919", "price_changes": [{"asset_id": "40081275558852222228080198821361202017557872256707631666334039001378518619916", "price": "0.41", "size": "2931.23", "side": "BUY", "hash": "80306c44e5b598ff2fc6e056c62fa7226435e322", "best_bid": "0.428", "best_ask": "0.429"}, {"asset_id": "78633590736077251574794513664747155551297291244492840448622550955320930591622", "price": "0.59", "size": "2931.23", "side": "SELL", "hash": "49709759a75357fba9d962687a1835ab9cb4f17b", "best_bid": "0.571", "best_ask": "0.572"}], "timestamp": "1785163466934", "event_type": "price_change"}}
{"ts": 1785163467.198, "kind": "price_change", "data": {"market": "0x18b1c135d0a40c5894da9412e77311827d9caf16cf4cd6591b247a34730af919", "price_changes": [{"asset_id": "40081275558852222228080198821361202017557872256707631666334039001378518619916", "price": "0.506", "size": "36.7", "side": "SELL", "hash": "b8f4010bd239881b08b958556e1d3780003ff98d", "best_bid": "0.428", "best_ask": "0.429"}, {"asset_id": "78633590736077251574794513664747155551297291244492840448622550955320930591622", "price": "0.494", "size": "36.7", "side": "BUY", "hash": "87f36f391bfd3bfcba39f677c8a216c5da528f97", "best_bid": "0.571", "best_ask": "0.572"}], "timestamp": "1785163467198", "event_type": "price_change"}}
{"ts": 1785163467.409, "kind": "price_change", "data": {"market": "0x18b1c135d0a40c5894da9412e77311827d9caf16cf4cd6591b247a34730af919", "price_changes": [{"asset_id": "40081275558852222228080198821361202017557872256707631666334039001378518619916", "price": "0.41", "size": "2947.28", "side": "BUY", "hash": "04b6bf0411f2dd7b3a5b4b9c5e9e3f295bf720e5", "best_bid": "0.428", "best_ask": "0.429"}, {"asset_id": "78633590736077251574794513664747155551297291244492840448622550955320930591622", "price": "0.59", "size": "2947.28", "side": "SELL", "hash": "ee10036ff29bee40cb85c5e9e423caf0591e19d1", "best_bid": "0.571", "best_ask": "0.572"}], "timestamp": "1785163467409", "event_type": "price_change"}}
{"ts": 1785163469.267, "kind": "price_change", "data": {"market": "0x0f49db97f71c68b1e42a6d16e3de93d85dbf7d4148e3f018eb79e88554be9f75", "price_changes": [{"asset_id": "54533043819946592547517511176940999955633860128497669742211153063842200957669", "price": "0.007", "size": "0", "side": "BUY", "hash": "4821dd5676aec19deaf97e3a8cbf1a6cbb378611", "best_bid": "0.194", "best_ask": "0.195"}, {"asset_id": "87854174148074652060467921081181402357467303721471806610111179101805869578687", "price": "0.993", "size": "0", "side": "SELL", "hash": "9d36e31997280fa4edceef88207d03e8b0bc2ec9", "best_bid": "0.805", "best_ask": "0.806"}], "timestamp": "1785163469267", "event_type": "price_change"}}
{"ts": 1785163469.267, "kind": "price_change", "data": {"market": "0x0f49db97f71c68b1e42a6d16e3de93d85dbf7d4148e3f018eb79e88554be9f75", "price_changes": [{"asset_id": "54533043819946592547517511176940999955633860128497669742211153063842200957669", "price": "0.009", "size": "0", "side": "BUY", "hash": "4821dd5676aec19deaf97e3a8cbf1a6cbb378611", "best_bid": "0.194", "best_ask": "0.195"}, {"asset_id": "87854174148074652060467921081181402357467303721471806610111179101805869578687", "price": "0.991", "size": "0", "side": "SELL", "hash": "9d36e31997280fa4edceef88207d03e8b0bc2ec9", "best_bid": "0.805", "best_ask": "0.806"}], "timestamp": "1785163469267", "event_type": "price_change"}}
{"ts": 1785163469.298, "kind": "price_change", "data": {"market": "0x0f49db97f71c68b1e42a6d16e3de93d85dbf7d4148e3f018eb79e88554be9f75", "price_changes": [{"asset_id": "54533043819946592547517511176940999955633860128497669742211153063842200957669", "price": "0.174", "size": "11373", "side": "BUY", "hash": "2cfebb956043341825e9de30cb42a2f623396b9e", "best_bid": "0.194", "best_ask": "0.195"}, {"asset_id": "87854174148074652060467921081181402357467303721471806610111179101805869578687", "price": "0.826", "size": "11373", "side": "SELL", "hash": "679052d01e3d332743bdaeb74ebea79ceea30618", "best_bid": "0.805", "best_ask": "0.806"}], "timestamp": "1785163469298", "event_type": "price_change"}}
{"ts": 1785163469.3, "kind": "price_change", "data": {"market": "0x0f49db97f71c68b1e42a6d16e3de93d85dbf7d4148e3f018eb79e88554be9f75", "price_changes": [{"asset_id": "87854174148074652060467921081181402357467303721471806610111179101805869578687", "price": "0.785", "size": "2688", "side": "BUY", "hash": "804a16ced80d55ff5997b0646c03657a46b3d0b5", "best_bid": "0.805", "best_ask": "0.806"}, {"asset_id": "54533043819946592547517511176940999955633860128497669742211153063842200957669", "price": "0.215", "size": "2688", "side": "SELL", "hash": "26e46c193e6ef82df8c2f59c0d7d84ecd7cc9bf7", "best_bid": "0.194", "best_ask": "0.195"}], "timestamp": "1785163469300", "event_type": "price_change"}}
{"ts": 1785163469.328, "kind": "price_change", "data": {"market": "0x0f49db97f71c68b1e42a6d16e3de93d85dbf7d4148e3f018eb79e88554be9f75", "price_changes": [{"asset_id": "54533043819946592547517511176940999955633860128497669742211153063842200957669", "price": "0.176", "size": "12210.93", "side": "BUY", "hash": "06e90ba12eaca3b6b22632f25b270674f481fb8b", "best_bid": "0.194", "best_ask": "0.195"}, {"asset_id": "87854174148074652060467921081181402357467303721471806610111179101805869578687", "price": "0.824", "size": "12210.93", "side": "SELL", "hash": "5acb89101ce4d100512589df7c08d5e462acd935", "best_bid": "0.805", "best_ask": "0.806"}], "timestamp": "1785163469328", "event_type": "price_change"}}
{"ts": 1785163469.504, "kind": "price_change", "data": {"market": "0x0f49db97f71c68b1e42a6d16e3de93d85dbf7d4148e3f018eb79e88554be9f75", "price_changes": [{"asset_id": "87854174148074652060467921081181402357467303721471806610111179101805869578687", "price": "0.78", "size": "923", "side": "BUY", "hash": "c46f30473329dfcedc41246085fc2b4b0b713e92", "best_bid": "0.805", "best_ask": "0.806"}, {"asset_id": "54533043819946592547517511176940999955633860128497669742211153063842200957669", "price": "0.22", "size": "923", "side": "SELL", "hash": "d1349a67429a200b53f844cc5317d713d90d2468", "best_bid": "0.194", "best_ask": "0.195"}], "timestamp": "1785163469504", "event_type": "price_change"}}
{"ts": 1785163471.006, "kind": "price_change", "data": {"market": "0x0f49db97f71c68b1e42a6d16e3de93d85dbf7d4148e3f018eb79e88554be9f75", "price_changes": [{"asset_id": "87854174148074652060467921081181402357467303721471806610111179101805869578687", "price": "0.004", "size": "0", "side": "BUY", "hash": "478a42b15c5d34e640e6e06ea4f745c586314b3b", "best_bid": "0.805", "best_ask": "0.806"}, {"asset_id": "54533043819946592547517511176940999955633860128497669742211153063842200957669", "price": "0.996", "size": "0", "side": "SELL", "hash": "8ea9f569e19ba6cb0a7664e836543b63937b6b5d", "best_bid": "0.194", "best_ask": "0.195"}], "timestamp": "1785163471006", "event_type": "price_change"}}
{"ts": 1785163474.439, "kind": "price_change", "data": {"market": "0x18b1c135d0a40c5894da9412e77311827d9caf16cf4cd6591b247a34730af919", "price_changes": [{"asset_id": "40081275558852222228080198821361202017557872256707631666334039001378518619916", "price": "0.506", "size": "0", "side": "SELL", "hash": "2797987aec6de4ea2b7479ab106b13655cbc2d5d", "best_bid": "0.428", "best_ask": "0.429"}, {"asset_id": "78633590736077251574794513664747155551297291244492840448622550955320930591622", "price": "0.494", "size": "0", "side": "BUY", "hash": "0ccf33fea76ca2009fac9a5efdff7c50088c0a2d", "best_bid": "0.571", "best_ask": "0.572"}], "timestamp": "1785163474439", "event_type": "price_change"}}
{"ts": 1785163475.45, "kind": "price_change", "data": {"market": "0x18b1c135d0a40c5894da9412e77311827d9caf16cf4cd6591b247a34730af919", "price_changes": [{"asset_id": "40081275558852222228080198821361202017557872256707631666334039001378518619916", "price": "0.506", "size": "36.7", "side": "SELL", "hash": "8ee923357442942468c10857047f968a8d36e24e", "best_bid": "0.428", "best_ask": "0.429"}, {"asset_id": "78633590736077251574794513664747155551297291244492840448622550955320930591622", "price": "0.494", "size": "36.7", "side": "BUY", "hash": "96a7b57ff5669e3f994074e94a024baae4c56db4", "best_bid": "0.571", "best_ask": "0.572"}], "timestamp": "1785163475450", "event_type": "price_change"}}
{"ts": 1785163476.662, "kind": "price_change", "data": {"market": "0x18b1c135d0a40c5894da9412e77311827d9caf16cf4cd6591b247a34730af919", "price_changes": [{"asset_id": "40081275558852222228080198821361202017557872256707631666334039001378518619916", "price": "0.506", "size": "0", "side": "SELL", "hash": "90f4d35e58c78ccf384f679e7494f30ef5a863be", "best_bid": "0.428", "best_ask": "0.429"}, {"asset_id": "78633590736077251574794513664747155551297291244492840448622550955320930591622", "price": "0.494", "size": "0", "side": "BUY", "hash": "eed47a361badbb5887a00498f3ff3eedca3849e2", "best_bid": "0.571", "best_ask": "0.572"}], "timestamp": "1785163476662", "event_type": "price_change"}}
{"ts": 1785163476.992, "kind": "price_change", "data": {"market": "0x18b1c135d0a40c5894da9412e77311827d9caf16cf4cd6591b247a34730af919", "price_changes": [{"asset_id": "40081275558852222228080198821361202017557872256707631666334039001378518619916", "price": "0.507", "size": "36.7", "side": "SELL", "hash": "68157a1867b1eb709a6d4985bf46ff9f7ec683ec", "best_bid": "0.428", "best_ask": "0.429"}, {"asset_id": "78633590736077251574794513664747155551297291244492840448622550955320930591622", "price": "0.493", "size": "36.7", "side": "BUY", "hash": "388d839bdacfa9f6ad076fe49d82323799bc676e", "best_bid": "0.571", "best_ask": "0.572"}], "timestamp": "1785163476992", "event_type": "price_change"}}
{"ts": 1785163477.378, "kind": "price_change", "data": {"market": "0x0f49db97f71c68b1e42a6d16e3de93d85dbf7d4148e3f018eb79e88554be9f75", "price_changes": [{"asset_id": "87854174148074652060467921081181402357467303721471806610111179101805869578687", "price": "0.001", "size": "6146756.01", "side": "BUY", "hash": "1dfbab0de8b510fb5bdb3dcf8629724a6990dc6b", "best_bid": "0.805", "best_ask": "0.806"}, {"asset_id": "54533043819946592547517511176940999955633860128497669742211153063842200957669", "price": "0.999", "size": "6146756.01", "side": "SELL", "hash": "57ab40a481160952c7ef64ca4bea0c28af8e7f73", "best_bid": "0.194", "best_ask": "0.195"}], "timestamp": "1785163477378", "event_type": "price_change"}}
{"ts": 1785163477.379, "kind": "price_change", "data": {"market": "0x0f49db97f71c68b1e42a6d16e3de93d85dbf7d4148e3f018eb79e88554be9f75", "price_changes": [{"asset_id": "87854174148074652060467921081181402357467303721471806610111179101805869578687", "price": "0.001", "size": "6147766.01", "side": "BUY", "hash": "969b1ca70a8bc665cf5bacd510b7b7d5e65d821c", "best_bid": "0.805", "best_ask": "0.806"}, {"asset_id": "54533043819946592547517511176940999955633860128497669742211153063842200957669", "price": "0.999", "size": "6147766.01", "side": "SELL", "hash": "e83b21004e87b1dd824e9559a75619b3cb22e53d", "best_bid": "0.194", "best_ask": "0.195"}], "timestamp": "1785163477379", "event_type": "price_change"}}
{"ts": 1785163478.473, "kind": "price_change", "data": {"market": "0x0f49db97f71c68b1e42a6d16e3de93d85dbf7d4148e3f018eb79e88554be9f75", "price_changes": [{"asset_id": "87854174148074652060467921081181402357467303721471806610111179101805869578687", "price": "0.02", "size": "220500", "side": "BUY", "hash": "698787d6b5f4c078572d50a5bd529e46043bb990", "best_bid": "0.805", "best_ask": "0.806"}, {"asset_id": "54533043819946592547517511176940999955633860128497669742211153063842200957669", "price": "0.98", "size": "220500", "side": "SELL", "hash": "229856d4734136f3fcde8f83ab64155f7ac92823", "best_bid": "0.194", "best_ask": "0.195"}], "timestamp": "1785163478473", "event_type": "price_change"}}
{"ts": 1785163478.478, "kind": "price_change", "data": {"market": "0x0f49db97f71c68b1e42a6d16e3de93d85dbf7d4148e3f018eb79e88554be9f75", "price_changes": [{"asset_id": "54533043819946592547517511176940999955633860128497669742211153063842200957669", "price": "0.04", "size": "4050", "side": "BUY", "hash": "e3be8aaaeae7785417008e6fd07e592a6bc1d071", "best_bid": "0.194", "best_ask": "0.195"}, {"asset_id": "87854174148074652060467921081181402357467303721471806610111179101805869578687", "price": "0.96", "size": "4050", "side": "SELL", "hash": "432a8eb282c252ff0f4e86b1f3d8179b57a2bc2c", "best_bid": "0.805", "best_ask": "0.806"}], "timestamp": "1785163478478", "event_type": "price_change"}}
{"ts": 1785163480.058, "kind": "price_change", "data": {"market": "0x0f49db97f71c68b1e42a6d16e3de93d85dbf7d4148e3f018eb79e88554be9f75", "price_changes": [{"asset_id": "87854174148074652060467921081181402357467303721471806610111179101805869578687", "price": "0.004", "size": "12500", "side": "BUY", "hash": "d037faec285253a80a66d4d3af2be9fe6fbb1156", "best_bid": "0.805", "best_ask": "0.806"}, {"asset_id": "54533043819946592547517511176940999955633860128497669742211153063842200957669", "price": "0.996", "size": "12500", "side": "SELL", "hash": "b48236db3030e3139c4e91c91d3d60b92d3e981b", "best_bid": "0.194", "best_ask": "0.195"}], "timestamp": "1785163480058", "event_type": "price_change"}}
{"ts": 1785163482.0, "kind": "price_change", "data": {"market": "0x0f49db97f71c68b1e42a6d16e3de93d85dbf7d4148e3f018eb79e88554be9f75", "price_changes": [{"asset_id": "54533043819946592547517511176940999955633860128497669742211153063842200957669", "price": "0.17", "size": "5889.88", "side": "BUY", "hash": "e760d967de0aedfe24b0bbfbedadc7b538e09af0", "best_bid": "0.194", "best_ask": "0.195"}, {"asset_id": "87854174148074652060467921081181402357467303721471806610111179101805869578687", "price": "0.83", "size": "5889.88", "side": "SELL", "hash": "0de6a29434c8887f5e434c92c7f8cc269d43ef73", "best_bid": "0.805", "best_ask": "0.806"}], "timestamp": "1785163482000", "event_type": "price_change"}}
{"ts": 1785163482.0, "kind": "price_change", "data": {"market": "0x0f49db97f71c68b1e42a6d16e3de93d85dbf7d4148e3f018eb79e88554be9f75", "price_changes": [{"asset_id": "54533043819946592547517511176940999955633860128497669742211153063842200957669", "price": "0.16", "size": "2750", "side": "BUY", "hash": "e760d967de0aedfe24b0bbfbedadc7b538e09af0", "best_bid": "0.194", "best_ask": "0.195"}, {"asset_id": "87854174148074652060467921081181402357467303721471806610111179101805869578687", "price": "0.84", "size": "2750", "side": "SELL", "hash": "0de6a29434c8887f5e434c92c7f8cc269d43ef73", "best_bid": "0.805", "best_ask": "0.806"}], "timestamp": "1785163482000", "event_type": "price_change"}}
{"ts": 1785163486.271, "kind": "price_change", "data": {"market": "0x18b1c135d0a40c5894da9412e77311827d9caf16cf4cd6591b247a34730af919", "price_changes": [{"asset_id": "40081275558852222228080198821361202017557872256707631666334039001378518619916", "price": "0.41", "size": "2931.23", "side": "BUY", "hash": "c9d5e56ccad7dfd1bf0b3a4372e7d8a769ab0839", "best_bid": "0.428", "best_ask": "0.429"}, {"asset_id": "78633590736077251574794513664747155551297291244492840448622550955320930591622", "price": "0.59", "size": "2931.23", "side": "SELL", "hash": "4424ef8321ec101d9bcb8566b5159629316e8bc3", "best_bid": "0.571", "best_ask": "0.572"}], "timestamp": "1785163486271", "event_type": "price_change"}}
{"ts": 1785163486.578089, "kind": "orders_out", "data": [{"token_id": "40081275558852222228080198821361202017557872256707631666334039001378518619916", "side": "BUY", "price": 0.387, "size": 7.75}, {"token_id": "78633590736077251574794513664747155551297291244492840448622550955320930591622", "side": "BUY", "price": 0.529, "size": 5.67}]}
{"ts": 1785163486.859, "kind": "price_change", "data": {"market": "0x18b1c135d0a40c5894da9412e77311827d9caf16cf4cd6591b247a34730af919", "price_changes": [{"asset_id": "40081275558852222228080198821361202017557872256707631666334039001378518619916", "price": "0.41", "size": "2947.28", "side": "BUY", "hash": "58d5c0c75feab4bd7bd554b10f71ef3e1ef38937", "best_bid": "0.428", "best_ask": "0.429"}, {"asset_id": "78633590736077251574794513664747155551297291244492840448622550955320930591622", "price": "0.59", "size": "2947.28", "side": "SELL", "hash": "723dc5c88eb20c2c270d32160120ada56bda7357", "best_bid": "0.571", "best_ask": "0.572"}], "timestamp": "1785163486859", "event_type": "price_change"}}
{"ts": 1785163488.164, "kind": "price_change", "data": {"market": "0x0f49db97f71c68b1e42a6d16e3de93d85dbf7d4148e3f018eb79e88554be9f75", "price_changes": [{"asset_id": "54533043819946592547517511176940999955633860128497669742211153063842200957669", "price": "0.187", "size": "36.49", "side": "BUY", "hash": "fa925e468a5a952c2b194578707627be44d28e6f", "best_bid": "0.194", "best_ask": "0.195"}, {"asset_id": "87854174148074652060467921081181402357467303721471806610111179101805869578687", "price": "0.813", "size": "36.49", "side": "SELL", "hash": "b45afa4cd2b3e3b0a32a1d1d1ce128467e75a8d3", "best_bid": "0.805", "best_ask": "0.806"}], "timestamp": "1785163488164", "event_type": "price_change"}}
{"ts": 1785163488.164, "kind": "price_change", "data": {"market": "0x0f49db97f71c68b1e42a6d16e3de93d85dbf7d4148e3f018eb79e88554be9f75", "price_changes": [{"asset_id": "54533043819946592547517511176940999955633860128497669742211153063842200957669", "price": "0.184", "size": "1546", "side": "BUY", "hash": "fa925e468a5a952c2b194578707627be44d28e6f", "best_bid": "0.194", "best_ask": "0.195"}, {"asset_id": "87854174148074652060467921081181402357467303721471806610111179101805869578687", "price": "0.816", "size": "1546", "side": "SELL", "hash": "b45afa4cd2b3e3b0a32a1d1d1ce128467e75a8d3", "best_bid": "0.805", "best_ask": "0.806"}], "timestamp": "1785163488164", "event_type": "price_change"}}
{"ts": 1785163488.164, "kind": "price_change", "data": {"market": "0x0f49db97f71c68b1e42a6d16e3de93d85dbf7d4148e3f018eb79e88554be9f75", "price_changes": [{"asset_id": "87854174148074652060467921081181402357467303721471806610111179101805869578687", "price": "0.798", "size": "2046.41", "side": "BUY", "hash": "b45afa4cd2b3e3b0a32a1d1d1ce128467e75a8d3", "best_bid": "0.805", "best_ask": "0.806"}, {"asset_id": "54533043819946592547517511176940999955633860128497669742211153063842200957669", "price": "0.202", "size": "2046.41", "side": "SELL", "hash": "fa925e468a5a952c2b194578707627be44d28e6f", "best_bid": "0.194", "best_ask": "0.195"}], "timestamp": "1785163488164", "event_type": "price_change"}}
{"ts": 1785163488.164, "kind": "price_change", "data": {"market": "0x0f49db97f71c68b1e42a6d16e3de93d85dbf7d4148e3f018eb79e88554be9f75", "price_changes": [{"asset_id": "87854174148074652060467921081181402357467303721471806610111179101805869578687", "price": "0.795", "size": "3474.98", "side": "BUY", "hash": "b45afa4cd2b3e3b0a32a1d1d1ce128467e75a8d3", "best_bid": "0.805", "best_ask": "0.806"}, {"asset_id": "54533043819946592547517511176940999955633860128497669742211153063842200957669", "price": "0.205", "size": "3474.98", "side": "SELL", "hash": "fa925e468a5a952c2b194578707627be44d28e6f", "best_bid": "0.194", "best_ask": "0.195"}], "timestamp": "1785163488164", "event_type": "price_change"}}
{"ts": 1785163488.278, "kind": "price_change", "data": {"market": "0x0f49db97f71c68b1e42a6d16e3de93d85dbf7d4148e3f018eb79e88554be9f75", "price_changes": [{"asset_id": "54533043819946592547517511176940999955633860128497669742211153063842200957669", "price": "0.187", "size": "256.49", "side": "BUY", "hash": "1aec01f2c15e94b35ad6f844885850da4fc74cab", "best_bid": "0.194", "best_ask": "0.195"}, {"asset_id": "87854174148074652060467921081181402357467303721471806610111179101805869578687", "price": "0.813", "size": "256.49", "side": "SELL", "hash": "eaf35a64ac2d057cae4d5e76acae98e3eeda6b51", "best_bid": "0.805", "best_ask": "0.806"}], "timestamp": "1785163488278", "event_type": "price_change"}}
{"ts": 1785163488.281, "kind": "price_change", "data": {"market": "0x0f49db97f71c68b1e42a6d16e3de93d85dbf7d4148e3f018eb79e88554be9f75", "price_changes": [{"asset_id": "87854174148074652060467921081181402357467303721471806610111179101805869578687", "price": "0.795", "size": "3694.98", "side": "BUY", "hash": "9ee0ec7a5e88a19012587fb4f5534ac094a382c4", "best_bid": "0.805", "best_ask": "0.806"}, {"asset_id": "54533043819946592547517511176940999955633860128497669742211153063842200957669", "price": "0.205", "size": "3694.98", "side": "SELL", "hash": "a6678c016a58150b81aa2da4f4b40bd433ed0693", "best_bid": "0.194", "best_ask": "0.195"}], "timestamp": "1785163488281", "event_type": "price_change"}}
{"ts": 1785163488.282, "kind": "price_change", "data": {"market": "0x0f49db97f71c68b1e42a6d16e3de93d85dbf7d4148e3f018eb79e88554be9f75", "price_changes": [{"asset_id": "54533043819946592547517511176940999955633860128497669742211153063842200957669", "price": "0.184", "size": "1766", "side": "BUY", "hash": "e15bae4396b8b2e08099c0c44034007010a4b6a7", "best_bid": "0.194", "best_ask": "0.195"}, {"asset_id": "87854174148074652060467921081181402357467303721471806610111179101805869578687", "price": "0.816", "size": "1766", "side": "SELL", "hash": "72bc8da963f5f0936c0a46d22f3c7b7eec87a5e9", "best_bid": "0.805", "best_ask": "0.806"}], "timestamp": "1785163488282", "event_type": "price_change"}}
{"ts": 1785163488.284, "kind": "price_change", "data": {"market": "0x0f49db97f71c68b1e42a6d16e3de93d85dbf7d4148e3f018eb79e88554be9f75", "price_changes": [{"asset_id": "87854174148074652060467921081181402357467303721471806610111179101805869578687", "price": "0.798", "size": "2266.41", "side": "BUY", "hash": "eaaa1e0cb9939c53275695860d6484b74c408d23", "best_bid": "0.805", "best_ask": "0.806"}, {"asset_id": "54533043819946592547517511176940999955633860128497669742211153063842200957669", "price": "0.202", "size": "2266.41", "side": "SELL", "hash": "2cc952438f2488a9228894626331b6e9fa72e2be", "best_bid": "0.194", "best_ask": "0.195"}], "timestamp": "1785163488284", "event_type": "price_change"}}
{"ts": 1785163488.357, "kind": "price_change", "data": {"market": "0x0f49db97f71c68b1e42a6d16e3de93d85dbf7d4148e3f018eb79e88554be9f75", "price_changes": [{"asset_id": "54533043819946592547517511176940999955633860128497669742211153063842200957669", "price": "0.176", "size": "12220.93", "side": "BUY", "hash": "45277e370d6e0944be388bc4c1f8790d678ef427", "best_bid": "0.194", "best_ask": "0.195"}, {"asset_id": "87854174148074652060467921081181402357467303721471806610111179101805869578687", "price": "0.824", "size": "12220.93", "side": "SELL", "hash": "05ba6a15e9c7a62114656033db4ee223ff9e2b9b", "best_bid": "0.805", "best_ask": "0.806"}], "timestamp": "1785163488357", "event_type": "price_change"}}
{"ts": 1785163488.473183, "kind": "orders_out", "data": [{"token_id": "54533043819946592547517511176940999955633860128497669742211153063842200957669", "side": "BUY", "price": 0.153, "size": 19.61}]}
{"ts": 1785163489.001, "kind": "price_change", "data": {"market": "0x0f49db97f71c68b1e42a6d16e3de93d85dbf7d4148e3f018eb79e88554be9f75", "price_changes": [{"asset_id": "54533043819946592547517511176940999955633860128497669742211153063842200957669", "price": "0.179", "size": "80959.56", "side": "BUY", "hash": "5d57bc6fb73efca5d6fdb0be5bd82b5b685a5fb7", "best_bid": "0.194", "best_ask": "0.195"}, {"asset_id": "87854174148074652060467921081181402357467303721471806610111179101805869578687", "price": "0.821", "size": "80959.56", "side": "SELL", "hash": "ea44aba8370473d8b20cfe7f7d3226f07512c74e", "best_bid": "0.805", "best_ask": "0.806"}], "timestamp": "1785163489001", "event_type": "price_change"}}
{"ts": 1785163493.949, "kind": "price_change", "data": {"market": "0x18b1c135d0a40c5894da9412e77311827d9caf16cf4cd6591b247a34730af919", "price_changes": [{"asset_id": "78633590736077251574794513664747155551297291244492840448622550955320930591622", "price": "0.482", "size": "161.09", "side": "BUY", "hash": "15627e044e42e1ebfc65e86160fae4e9d7783b69", "best_bid": "0.571", "best_ask": "0.572"}, {"asset_id": "40081275558852222228080198821361202017557872256707631666334039001378518619916", "price": "0.518", "size": "161.09", "side": "SELL", "hash": "ccb2ee1fa37fa688952098c72264f745949cf2b4", "best_bid": "0.428", "best_ask": "0.429"}], "timestamp": "1785163493949", "event_type": "price_change"}}
{"ts": 1785163493.982, "kind": "price_change", "data": {"market": "0x18b1c135d0a40c5894da9412e77311827d9caf16cf4cd6591b247a34730af919", "price_changes": [{"asset_id": "78633590736077251574794513664747155551297291244492840448622550955320930591622", "price": "0.485", "size": "107", "side": "BUY", "hash": "64ec549282cddd673ff75b6d1906bb3d076f1a11", "best_bid": "0.571", "best_ask": "0.572"}, {"asset_id": "40081275558852222228080198821361202017557872256707631666334039001378518619916", "price": "0.515", "size": "107", "side": "SELL", "hash": "d9962211e0a97fab612e357d331d5173194b102e", "best_bid": "0.428", "best_ask": "0.429"}], "timestamp": "1785163493982", "event_type": "price_change"}}
{"ts": 1785163493.985, "kind": "price_change", "data": {"market": "0x18b1c135d0a40c5894da9412e77311827d9caf16cf4cd6591b247a34730af919", "price_changes": [{"asset_id": "78633590736077251574794513664747155551297291244492840448622550955320930591622", "price": "0.486", "size": "10", "side": "BUY", "hash": "bcf180551c48df13037297289fb7427aba824156", "best_bid": "0.571", "best_ask": "0.572"}, {"asset_id": "40081275558852222228080198821361202017557872256707631666334039001378518619916", "price": "0.514", "size": "10", "side": "SELL", "hash": "930605d9e23af13bdd3b21636efa532299344d72", "best_bid": "0.428", "best_ask": "0.429"}], "timestamp": "1785163493985", "event_type": "price_change"}}
{"ts": 1785163494.005, "kind": "price_change", "data": {"market": "0x0f49db97f71c68b1e42a6d16e3de93d85dbf7d4148e3f018eb79e88554be9f75", "price_changes": [{"asset_id": "54533043819946592547517511176940999955633860128497669742211153063842200957669", "price": "0.177", "size": "155", "side": "BUY", "hash": "e3fb59bbcc22dc97674fc15396b75c2cb8dfe941", "best_bid": "0.194", "best_ask": "0.195"}, {"asset_id": "87854174148074652060467921081181402357467303721471806610111179101805869578687", "price": "0.823", "size": "155", "side": "SELL", "hash": "f69c2824719b9216f195c11298b41a95dbd3440b", "best_bid": "0.805", "best_ask": "0.806"}], "timestamp": "1785163494005", "event_type": "price_change"}}
{"ts": 1785163494.009, "kind": "price_change", "data": {"market": "0x18b1c135d0a40c5894da9412e77311827d9caf16cf4cd6591b247a34730af919", "price_changes": [{"asset_id": "78633590736077251574794513664747155551297291244492840448622550955320930591622", "price": "0.485", "size": "30", "side": "BUY", "hash": "82f023acaccf823c2b67927c43d57e7d8c6803f5", "best_bid": "0.571", "best_ask": "0.572"}, {"asset_id": "40081275558852222228080198821361202017557872256707631666334039001378518619916", "price": "0.515", "size": "30", "side": "SELL", "hash": "027d734765c0f3a9b5ad2573691ab38e646983f5", "best_bid": "0.428", "best_ask": "0.429"}], "timestamp": "1785163494009", "event_type": "price_change"}}
{"ts": 1785163494.009, "kind": "price_change", "data": {"market": "0x18b1c135d0a40c5894da9412e77311827d9caf16cf4cd6591b247a34730af919", "price_changes": [{"asset_id": "78633590736077251574794513664747155551297291244492840448622550955320930591622", "price": "0.482", "size": "0", "side": "BUY", "hash": "82f023acaccf823c2b67927c43d57e7d8c6803f5", "best_bid": "0.571", "best_ask": "0.572"}, {"asset_id": "40081275558852222228080198821361202017557872256707631666334039001378518619916", "price": "0.518", "size": "0", "side": "SELL", "hash": "027d734765c0f3a9b5ad2573691ab38e646983f5", "best_bid": "0.428", "best_ask": "0.429"}], "timestamp": "1785163494009", "event_type": "price_change"}}
{"ts": 1785163494.032, "kind": "price_change", "data": {"market": "0x18b1c135d0a40c5894da9412e77311827d9caf16cf4cd6591b247a34730af919", "price_changes": [{"asset_id": "78633590736077251574794513664747155551297291244492840448622550955320930591622", "price": "0.486", "size": "0", "side": "BUY", "hash": "1ea65f8ed055a61e10f5e215e9913ee1302944a2", "best_bid": "0.571", "best_ask": "0.572"}, {"asset_id": "40081275558852222228080198821361202017557872256707631666334039001378518619916", "price": "0.514", "size": "0", "side": "SELL", "hash": "e8759fa8ab457d563be99edd0897e5b8acf120b7", "best_bid": "0.428", "best_ask": "0.429"}], "timestamp": "1785163494032", "event_type": "price_change"}}
{"ts": 1785163494.032, "kind": "price_change", "data": {"market": "0x18b1c135d0a40c5894da9412e77311827d9caf16cf4cd6591b247a34730af919", "price_changes": [{"asset_id": "78633590736077251574794513664747155551297291244492840448622550955320930591622", "price": "0.485", "size": "0", "side": "BUY", "hash": "1ea65f8ed055a61e10f5e215e9913ee1302944a2", "best_bid": "0.571", "best_ask": "0.572"}, {"asset_id": "40081275558852222228080198821361202017557872256707631666334039001378518619916", "price": "0.515", "size": "0", "side": "SELL", "hash": "e8759fa8ab457d563be99edd0897e5b8acf120b7", "best_bid": "0.428", "best_ask": "0.429"}], "timestamp": "1785163494032", "event_type": "price_change"}}
{"ts": 1785163494.082, "kind": "price_change", "data": {"market": "0x18b1c135d0a40c5894da9412e77311827d9caf16cf4cd6591b247a34730af919", "price_changes": [{"asset_id": "78633590736077251574794513664747155551297291244492840448622550955320930591622", "price": "0.482", "size": "30", "side": "BUY", "hash": "384a40ce8c7f4a06c47e9f0e0e53331eb8c019ea", "best_bid": "0.571", "best_ask": "0.572"}, {"asset_id": "40081275558852222228080198821361202017557872256707631666334039001378518619916", "price": "0.518", "size": "30", "side": "SELL", "hash": "de55333f7ed7e1117b930054d72617c6d2e53286", "best_bid": "0.428", "best_ask": "0.429"}], "timestamp": "1785163494082", "event_type": "price_change"}}
{"ts": 1785163494.091, "kind": "price_change", "data": {"market": "0x18b1c135d0a40c5894da9412e77311827d9caf16cf4cd6591b247a34730af919", "price_changes": [{"asset_id": "78633590736077251574794513664747155551297291244492840448622550955320930591622", "price": "0.482", "size": "40", "side": "BUY", "hash": "096dff1aeea6a7998aa7f1f0e79bb4410b2d357c", "best_bid": "0.571", "best_ask": "0.572"}, {"asset_id": "40081275558852222228080198821361202017557872256707631666334039001378518619916", "price": "0.518", "size": "40", "side": "SELL", "hash": "405862063028c17d3446f44e9b6df504e95090a4", "best_bid": "0.428", "best_ask": "0.429"}], "timestamp": "1785163494091", "event_type": "price_change"}}
{"ts": 1785163494.106, "kind": "price_change", "data": {"market": "0x18b1c135d0a40c5894da9412e77311827d9caf16cf4cd6591b247a34730af919", "price_changes": [{"asset_id": "78633590736077251574794513664747155551297291244492840448622550955320930591622", "price": "0.549", "size": "0", "side": "BUY", "hash": "ca4b5369182be90fe3882c7c44fd1a97f999e6e7", "best_bid": "0.571", "best_ask": "0.572"}, {"asset_id": "40081275558852222228080198821361202017557872256707631666334039001378518619916", "price": "0.451", "size": "0", "side": "SELL", "hash": "721fa7440b565d1b3232704f9af868512dff53fe", "best_bid": "0.428", "best_ask": "0.429"}], "timestamp": "1785163494106", "event_type": "price_change"}}
{"ts": 1785163495.012, "kind": "price_change", "data": {"market": "0x18b1c135d0a40c5894da9412e77311827d9caf16cf4cd6591b247a34730af919", "price_changes": [{"asset_id": "78633590736077251574794513664747155551297291244492840448622550955320930591622", "price": "0.02", "size": "750", "side": "BUY", "hash": "f6ae3841dc436ac475482c9838e3021e75f32621", "best_bid": "0.571", "best_ask": "0.572"}, {"asset_id": "40081275558852222228080198821361202017557872256707631666334039001378518619916", "price": "0.98", "size": "750", "side": "SELL", "hash": "5708fcfded7b4787d78a82e638545fcd0a09c784", "best_bid": "0.428", "best_ask": "0.429"}], "timestamp": "1785163495012", "event_type": "price_change"}}
{"ts": 1785163499.008, "kind": "price_change", "data": {"market": "0x0f49db97f71c68b1e42a6d16e3de93d85dbf7d4148e3f018eb79e88554be9f75", "price_changes": [{"asset_id": "87854174148074652060467921081181402357467303721471806610111179101805869578687", "price": "0.795", "size": "3457.98", "side": "BUY", "hash": "8489f77a239b4bbab5648efff00f72fdb9b82f87", "best_bid": "0.805", "best_ask": "0.806"}, {"asset_id": "54533043819946592547517511176940999955633860128497669742211153063842200957669", "price": "0.205", "size": "3457.98", "side": "SELL", "hash": "9072ba0a3b0bdce8ec98b86c420c2cee5627156e", "best_bid": "0.194", "best_ask": "0.195"}], "timestamp": "1785163499008", "event_type": "price_change"}}
{"ts": 1785163503.106, "kind": "price_change", "data": {"market": "0x18b1c135d0a40c5894da9412e77311827d9caf16cf4cd6591b247a34730af919", "price_changes": [{"asset_id": "78633590736077251574794513664747155551297291244492840448622550955320930591622", "price": "0.02", "size": "75750", "side": "BUY", "hash": "02283dff016069e57454490e40df5d4fc17d6906", "best_bid": "0.571", "best_ask": "0.572"}, {"asset_id": "40081275558852222228080198821361202017557872256707631666334039001378518619916", "price": "0.98", "size": "75750", "side": "SELL", "hash": "2a906ae42c763a1a82b5d12df08782aadce548ee", "best_bid": "0.428", "best_ask": "0.429"}], "timestamp": "1785163503106", "event_type": "price_change"}}
{"ts": 1785163503.676, "kind": "price_change", "data": {"market": "0x18b1c135d0a40c5894da9412e77311827d9caf16cf4cd6591b247a34730af919", "price_changes": [{"asset_id": "40081275558852222228080198821361202017557872256707631666334039001378518619916", "price": "0.41", "size": "2931.23", "side": "BUY", "hash": "64239e6dcbe017c7c613c7d9d6ae025fcdf63172", "best_bid": "0.428", "best_ask": "0.429"}, {"asset_id": "78633590736077251574794513664747155551297291244492840448622550955320930591622", "price": "0.59", "size": "2931.23", "side": "SELL", "hash": "872511b51768ec94bd9a8f6590e3c92928477ac9", "best_bid": "0.571", "best_ask": "0.572"}], "timestamp": "1785163503676", "event_type": "price_change"}}
{"ts": 1785163504.386, "kind": "price_change", "data": {"market": "0x18b1c135d0a40c5894da9412e77311827d9caf16cf4cd6591b247a34730af919", "price_changes": [{"asset_id": "40081275558852222228080198821361202017557872256707631666334039001378518619916", "price": "0.41", "size": "2947.28", "side": "BUY", "hash": "f12ef09981afb16cb6da37f14c9d89abfb590c4f", "best_bid": "0.428", "best_ask": "0.429"}, {"asset_id": "78633590736077251574794513664747155551297291244492840448622550955320930591622", "price": "0.59", "size": "2947.28", "side": "SELL", "hash": "69b2924c3d23b1d9eb8b510b2b4743ab4e791705", "best_bid": "0.571", "best_ask": "0.572"}], "timestamp": "1785163504386", "event_type": "price_change"}}
{"ts": 1785163506.711, "kind": "price_change", "data": {"market": "0x0f49db97f71c68b1e42a6d16e3de93d85dbf7d4148e3f018eb79e88554be9f75", "price_changes": [{"asset_id": "87854174148074652060467921081181402357467303721471806610111179101805869578687", "price": "0.804", "size": "968.01", "side": "BUY", "hash": "ecdbb10c9810bd35222301b8e500d7a06b57ce34", "best_bid": "0.805", "best_ask": "0.806"}, {"asset_id": "54533043819946592547517511176940999955633860128497669742211153063842200957669", "price": "0.196", "size": "968.01", "side": "SELL", "hash": "b580cc5a008089e47149d3a79d7509440005f67e", "best_bid": "0.194", "best_ask": "0.195"}], "timestamp": "1785163506711", "event_type": "price_change"}}
{"ts": 1785163506.975, "kind": "price_change", "data": {"market": "0x0f49db97f71c68b1e42a6d16e3de93d85dbf7d4148e3f018eb79e88554be9f75", "price_changes": [{"asset_id": "54533043819946592547517511176940999955633860128497669742211153063842200957669", "price": "0.193", "size": "10987", "side": "BUY", "hash": "f01bf5c87b2ad9a4d214bccb9c7742a4ebf75ee6", "best_bid": "0.194", "best_ask": "0.195"}, {"asset_id": "87854174148074652060467921081181402357467303721471806610111179101805869578687", "price": "0.807", "size": "10987", "side": "SELL", "hash": "abcf51ad52b662e7ec58210407971d0080eca47e", "best_bid": "0.805", "best_ask": "0.806"}], "timestamp": "1785163506975", "event_type": "price_change"}}
{"ts": 1785163507.030608, "kind": "orders_out", "data": [{"token_id": "54533043819946592547517511176940999955633860128497669742211153063842200957669", "side": "BUY", "price": 0.153, "size": 19.61}]}
{"ts": 1785163507.0, "kind": "price_change", "data": {"market": "0x18b1c135d0a40c5894da9412e77311827d9caf16cf4cd6591b247a34730af919", "price_changes": [{"asset_id": "40081275558852222228080198821361202017557872256707631666334039001378518619916", "price": "0.05", "size": "0", "side": "BUY", "hash": "14986bbd7860b13a1d5749476bd2762ad7d841c3", "best_bid": "0.428", "best_ask": "0.429"}, {"asset_id": "78633590736077251574794513664747155551297291244492840448622550955320930591622", "price": "0.95", "size": "0", "side": "SELL", "hash": "b25de9c5c6c811e8032df075cb0b10fe0fbf3f9b", "best_bid": "0.571", "best_ask": "0.572"}], "timestamp": "1785163507000", "event_type": "price_change"}}
{"ts": 1785163507.315037, "kind": "orders_out", "data": [{"token_id": "40081275558852222228080198821361202017557872256707631666334039001378518619916", "side": "BUY", "price": 0.387, "size": 7.75}, {"token_id": "78633590736077251574794513664747155551297291244492840448622550955320930591622", "side": "BUY", "price": 0.529, "size": 5.67}]}
{"ts": 1785163507.885, "kind": "price_change", "data": {"market": "0x18b1c135d0a40c5894da9412e77311827d9caf16cf4cd6591b247a34730af919", "price_changes": [{"asset_id": "40081275558852222228080198821361202017557872256707631666334039001378518619916", "price": "0.507", "size": "0", "side": "SELL", "hash": "a8b4e6691e06e8cad07d9ab389893ac30151d36a", "best_bid": "0.428", "best_ask": "0.429"}, {"asset_id": "78633590736077251574794513664747155551297291244492840448622550955320930591622", "price": "0.493", "size": "0", "side": "BUY", "hash": "2cc6e43cfea726630b4ac1dcd62ba779ad063bb5", "best_bid": "0.571", "best_ask": "0.572"}], "timestamp": "1785163507885", "event_type": "price_change"}}
{"ts": 1785163509.013, "kind": "price_change", "data": {"market": "0x18b1c135d0a40c5894da9412e77311827d9caf16cf4cd6591b247a34730af919", "price_changes": [{"asset_id": "78633590736077251574794513664747155551297291244492840448622550955320930591622", "price": "0.551", "size": "28506.16", "side": "BUY", "hash": "705c04000d3309a4d63cfb884ec8d3b09b6c2aed", "best_bid": "0.571", "best_ask": "0.572"}, {"asset_id": "40081275558852222228080198821361202017557872256707631666334039001378518619916", "price": "0.449", "size": "28506.16", "side": "SELL", "hash": "73fb556848cd8c7d7bfbe8a3531e10d3b98e03c0", "best_bid": "0.428", "best_ask": "0.429"}], "timestamp": "1785163509013", "event_type": "price_change"}}
{"ts": 1785163509.599, "kind": "price_change", "data": {"market": "0x18b1c135d0a40c5894da9412e77311827d9caf16cf4cd6591b247a34730af919", "price_changes": [{"asset_id": "78633590736077251574794513664747155551297291244492840448622550955320930591622", "price": "0.551", "size": "28706.16", "side": "BUY", "hash": "b41332b5212e72178470a8bdc666d2693bc295e0", "best_bid": "0.571", "best_ask": "0.572"}, {"asset_id": "40081275558852222228080198821361202017557872256707631666334039001378518619916", "price": "0.449", "size": "28706.16", "side": "SELL", "hash": "f3a3d9e5a6c960d4c5291c0a09a5a63a02c41c9b", "best_bid": "0.428", "best_ask": "0.429"}], "timestamp": "1785163509599", "event_type": "price_change"}}
{"ts": 1785163509.756, "kind": "price_change", "data": {"market": "0x18b1c135d0a40c5894da9412e77311827d9caf16cf4cd6591b247a34730af919", "price_changes": [{"asset_id": "40081275558852222228080198821361202017557872256707631666334039001378518619916", "price": "0.506", "size": "36.7", "side": "SELL", "hash": "e6465fa6eebe572b32bf9a305085cc8bf5730708", "best_bid": "0.428", "best_ask": "0.429"}, {"asset_id": "78633590736077251574794513664747155551297291244492840448622550955320930591622", "price": "0.494", "size": "36.7", "side": "BUY", "hash": "915fe502b662a7954e91b823fa497d5f85b15261", "best_bid": "0.571", "best_ask": "0.572"}], "timestamp": "1785163509756", "event_type": "price_change"}}
{"ts": 1785163511.022, "kind": "price_change", "data": {"market": "0x0f49db97f71c68b1e42a6d16e3de93d85dbf7d4148e3f018eb79e88554be9f75", "price_changes": [{"asset_id": "54533043819946592547517511176940999955633860128497669742211153063842200957669", "price": "0.003", "size": "11073", "side": "BUY", "hash": "15c9fbd7e2fbcf283240417ead1dd128eb7c644a", "best_bid": "0.194", "best_ask": "0.195"}, {"asset_id": "87854174148074652060467921081181402357467303721471806610111179101805869578687", "price": "0.997", "size": "11073", "side": "SELL", "hash": "d102b0bda0437526de08651ac19e5459ed18955d", "best_bid": "0.805", "best_ask": "0.806"}], "timestamp": "1785163511022", "event_type": "price_change"}}
{"ts": 1785163511.134, "kind": "price_change", "data": {"market": "0x18b1c135d0a40c5894da9412e77311827d9caf16cf4cd6591b247a34730af919", "price_changes": [{"asset_id": "78633590736077251574794513664747155551297291244492840448622550955320930591622", "price": "0.08", "size": "29375", "side": "BUY", "hash": "f5caf6e011d57689cf382c6711220efd3c00d9ca", "best_bid": "0.571", "best_ask": "0.572"}, {"asset_id": "40081275558852222228080198821361202017557872256707631666334039001378518619916", "price": "0.92", "size": "29375", "side": "SELL", "hash": "bcb6b6f671fccd3aa3bbeddb2bff53bda3f0abaa", "best_bid": "0.428", "best_ask": "0.429"}], "timestamp": "1785163511134", "event_type": "price_change"}}
{"ts": 1785163511.3391201, "kind": "orders_out", "data": [{"token_id": "54533043819946592547517511176940999955633860128497669742211153063842200957669", "side": "BUY", "price": 0.144, "size": 10.42}]}
{"ts": 1785163512.309, "kind": "price_change", "data": {"market": "0x0f49db97f71c68b1e42a6d16e3de93d85dbf7d4148e3f018eb79e88554be9f75", "price_changes": [{"asset_id": "54533043819946592547517511176940999955633860128497669742211153063842200957669", "price": "0.009", "size": "13888.88", "side": "BUY", "hash": "4c6525b76d263e6a5b101d598dc9dd8629825ee6", "best_bid": "0.194", "best_ask": "0.195"}, {"asset_id": "87854174148074652060467921081181402357467303721471806610111179101805869578687", "price": "0.991", "size": "13888.88", "side": "SELL", "hash": "dc747e8e3f34c4c9b352ffb2c1c04338e40f6239", "best_bid": "0.805", "best_ask": "0.806"}], "timestamp": "1785163512309", "event_type": "price_change"}}
{"ts": 1785163512.314, "kind": "price_change", "data": {"market": "0x0f49db97f71c68b1e42a6d16e3de93d85dbf7d4148e3f018eb79e88554be9f75", "price_changes": [{"asset_id": "54533043819946592547517511176940999955633860128497669742211153063842200957669", "price": "0.007", "size": "53571.42", "side": "BUY", "hash": "5ada2ca158a0f244397b6b09c5cf03f8c043fe8f", "best_bid": "0.194", "best_ask": "0.195"}, {"asset_id": "87854174148074652060467921081181402357467303721471806610111179101805869578687", "price": "0.993", "size": "53571.42", "side": "SELL", "hash": "cf49b8c85f15d03a9fd71650934a0f53fa4ace5a", "best_bid": "0.805", "best_ask": "0.806"}], "timestamp": "1785163512314", "event_type": "price_change"}}
{"ts": 1785163512.762, "kind": "price_change", "data": {"market": "0x18b1c135d0a40c5894da9412e77311827d9caf16cf4cd6591b247a34730af919", "price_changes": [{"asset_id": "40081275558852222228080198821361202017557872256707631666334039001378518619916", "price": "0.171", "size": "1023.39", "side": "BUY", "hash": "f943ecf619d0c4da91a5a8be71d1328cc5549dc7", "best_bid": "0.428", "best_ask": "0.429"}, {"asset_id": "78633590736077251574794513664747155551297291244492840448622550955320930591622", "price": "0.829", "size": "1023.39", "side": "SELL", "hash": "e2e8ffbae98a8a2865dca440de854c34faea2c4e", "best_bid": "0.571", "best_ask": "0.572"}], "timestamp": "1785163512762", "event_type": "price_change"}}
{"ts": 1785163512.767, "kind": "price_change", "data": {"market": "0x18b1c135d0a40c5894da9412e77311827d9caf16cf4cd6591b247a34730af919", "price_changes": [{"asset_id": "40081275558852222228080198821361202017557872256707631666334039001378518619916", "price": "0.171", "size": "2970.75", "side": "BUY", "hash": "6623ddc99889442f4467da4dae66521ad03276fb", "best_bid": "0.428", "best_ask": "0.429"}, {"asset_id": "78633590736077251574794513664747155551297291244492840448622550955320930591622", "price": "0.829", "size": "2970.75", "side": "SELL", "hash": "6fa0c51a1a136f658b998741cd0f17378bb63328", "best_bid": "0.571", "best_ask": "0.572"}], "timestamp": "1785163512767", "event_type": "price_change"}}
{"ts": 1785163514.96, "kind": "price_change", "data": {"market": "0x0f49db97f71c68b1e42a6d16e3de93d85dbf7d4148e3f018eb79e88554be9f75", "price_changes": [{"asset_id": "87854174148074652060467921081181402357467303721471806610111179101805869578687", "price": "0.795", "size": "2890.98", "side": "BUY", "hash": "8c784cd77cd154aebf3fa8c4e5608935864426f3", "best_bid": "0.805", "best_ask": "0.806"}, {"asset_id": "54533043819946592547517511176940999955633860128497669742211153063842200957669", "price": "0.205", "size": "2890.98", "side": "SELL", "hash": "6dcc9707182b8ba4b6bbb7b95360a0e3d4b67d76", "best_bid": "0.194", "best_ask": "0.195"}], "timestamp": "1785163514960", "event_type": "price_change"}}
{"ts": 1785163515.056, "kind": "price_change", "data": {"market": "0x0f49db97f71c68b1e42a6d16e3de93d85dbf7d4148e3f018eb79e88554be9f75", "price_changes": [{"asset_id": "87854174148074652060467921081181402357467303721471806610111179101805869578687", "price": "0.795", "size": "3457.98", "side": "BUY", "hash": "d3cade3660e106bfeb181bad9b230bc3bc3abe99", "best_bid": "0.805", "best_ask": "0.806"}, {"asset_id": "54533043819946592547517511176940999955633860128497669742211153063842200957669", "price": "0.205", "size": "3457.98", "side": "SELL", "hash": "ef4144820488ece7eeee431120d0001997d92564", "best_bid": "0.194", "best_ask": "0.195"}], "timestamp": "1785163515056", "event_type": "price_change"}}
{"ts": 1785163515.633, "kind": "price_change", "data": {"market": "0x18b1c135d0a40c5894da9412e77311827d9caf16cf4cd6591b247a34730af919", "price_changes": [{"asset_id": "40081275558852222228080198821361202017557872256707631666334039001378518619916", "price": "0.418", "size": "5970.05", "side": "BUY", "hash": "3280e9c290cafe6c6cfc2d42c37791a331f045dd", "best_bid": "0.428", "best_ask": "0.429"}, {"asset_id": "78633590736077251574794513664747155551297291244492840448622550955320930591622", "price": "0.582", "size": "5970.05", "side": "SELL", "hash": "66fea2f6c4c548e0c6c67f1a7e4bde1f38069468", "best_bid": "0.571", "best_ask": "0.572"}], "timestamp": "1785163515633", "event_type": "price_change"}}
{"ts": 1785163515.718, "kind": "price_change", "data": {"market": "0x18b1c135d0a40c5894da9412e77311827d9caf16cf4cd6591b247a34730af919", "price_changes": [{"asset_id": "40081275558852222228080198821361202017557872256707631666334039001378518619916", "price": "0.418", "size": "7048.05", "side": "BUY", "hash": "d4d6d56accae18b418badc9da12fcd6ac37548d3", "best_bid": "0.428", "best_ask": "0.429"}, {"asset_id": "78633590736077251574794513664747155551297291244492840448622550955320930591622", "price": "0.582", "size": "7048.05", "side": "SELL", "hash": "511abf02c12e311b8a24499a1136d7594a63d9c0", "best_bid": "0.571", "best_ask": "0.572"}], "timestamp": "1785163515718", "event_type": "price_change"}}
{"ts": 1785163516.644, "kind": "price_change", "data": {"market": "0x0f49db97f71c68b1e42a6d16e3de93d85dbf7d4148e3f018eb79e88554be9f75", "price_changes": [{"asset_id": "54533043819946592547517511176940999955633860128497669742211153063842200957669", "price": "0.007", "size": "0", "side": "BUY", "hash": "6ba2b0b8c76cd3404a7d538bc20a8cd8c04f2ca0", "best_bid": "0.194", "best_ask": "0.195"}, {"asset_id": "87854174148074652060467921081181402357467303721471806610111179101805869578687", "price": "0.993", "size": "0", "side": "SELL", "hash": "b4fea080e485afc5cffb40960cea4fa691b3c512", "best_bid": "0.805", "best_ask": "0.806"}], "timestamp": "1785163516644", "event_type": "price_change"}}
{"ts": 1785163516.644, "kind": "price_change", "data": {"market": "0x0f49db97f71c68b1e42a6d16e3de93d85dbf7d4148e3f018eb79e88554be9f75", "price_changes": [{"asset_id": "54533043819946592547517511176940999955633860128497669742211153063842200957669", "price": "0.009", "size": "0", "side": "BUY", "hash": "6ba2b0b8c76cd3404a7d538bc20a8cd8c04f2ca0", "best_bid": "0.194", "best_ask": "0.195"}, {"asset_id": "87854174148074652060467921081181402357467303721471806610111179101805869578687", "price": "0.991", "size": "0", "side": "SELL", "hash": "b4fea080e485afc5cffb40960cea4fa691b3c512", "best_bid": "0.805", "best_ask": "0.806"}], "timestamp": "1785163516644", "event_type": "price_change"}}
{"ts": 1785163516.707, "kind": "price_change", "data": {"market": "0x0f49db97f71c68b1e42a6d16e3de93d85dbf7d4148e3f018eb79e88554be9f75", "price_changes": [{"asset_id": "54533043819946592547517511176940999955633860128497669742211153063842200957669", "price": "0.176", "size": "12210.93", "side": "BUY", "hash": "772586b78e92c4f6307ba0b4fb2086b4484e69a8", "best_bid": "0.194", "best_ask": "0.195"}, {"asset_id": "87854174148074652060467921081181402357467303721471806610111179101805869578687", "price": "0.824", "size": "12210.93", "side": "SELL", "hash": "31e9c1ccffab8d36876aefbb28c20a89e92c49b8", "best_bid": "0.805", "best_ask": "0.806"}], "timestamp": "1785163516707", "event_type": "price_change"}}
{"ts": 1785163518.348, "kind": "price_change", "data": {"market": "0x0f49db97f71c68b1e42a6d16e3de93d85dbf7d4148e3f018eb79e88554be9f75", "price_changes": [{"asset_id": "54533043819946592547517511176940999955633860128497669742211153063842200957669", "price": "0.003", "size": "14406.33", "side": "BUY", "hash": "f36037e2ac1c93add3de7df5f9dba41428a08504", "best_bid": "0.194", "best_ask": "0.195"}, {"asset_id": "87854174148074652060467921081181402357467303721471806610111179101805869578687", "price": "0.997", "size": "14406.33", "side": "SELL", "hash": "3b2da17c7181e8e6cef87e69c533a2bf5a8d8cdf", "best_bid": "0.805", "best_ask": "0.806"}], "timestamp": "1785163518348", "event_type": "price_change"}}
{"ts": 1785163518.653527, "kind": "orders_out", "data": [{"token_id": "54533043819946592547517511176940999955633860128497669742211153063842200957669", "side": "BUY", "price": 0.153, "size": 19.61}]}
{"ts": 1785163520.592, "kind": "price_change", "data": {"market": "0x18b1c135d0a40c5894da9412e77311827d9caf16cf4cd6591b247a34730af919", "price_changes": [{"asset_id": "40081275558852222228080198821361202017557872256707631666334039001378518619916", "price": "0.41", "size": "2931.23", "side": "BUY", "hash": "1476b316c755b82846714fec4161ebf37b733634", "best_bid": "0.428", "best_ask": "0.429"}, {"asset_id": "78633590736077251574794513664747155551297291244492840448622550955320930591622", "price": "0.59", "size": "2931.23", "side": "SELL", "hash": "47beaafbb38cfcf0a7bd974721d5a4586932b756", "best_bid": "0.571", "best_ask": "0.572"}], "timestamp": "1785163520592", "event_type": "price_change"}}
{"ts": 1785163521.637, "kind": "price_change", "data": {"market": "0x18b1c135d0a40c5894da9412e77311827d9caf16cf4cd6591b247a34730af919", "price_changes": [{"asset_id": "40081275558852222228080198821361202017557872256707631666334039001378518619916", "price": "0.41", "size": "2947.28", "side": "BUY", "hash": "102688a3e4a84a820c5fb3ae986f508e6b77a639", "best_bid": "0.428", "best_ask": "0.429"}, {"asset_id": "78633590736077251574794513664747155551297291244492840448622550955320930591622", "price": "0.59", "size": "2947.28", "side": "SELL", "hash": "de955e25e461374cd7eeb5c4a7f9bc91535ad631", "best_bid": "0.571", "best_ask": "0.572"}], "timestamp": "1785163521637", "event_type": "price_change"}}
{"ts": 1785163525.197, "kind": "price_change", "data": {"market": "0x0f49db97f71c68b1e42a6d16e3de93d85dbf7d4148e3f018eb79e88554be9f75", "price_changes": [{"asset_id": "87854174148074652060467921081181402357467303721471806610111179101805869578687", "price": "0.795", "size": "2891.98", "side": "BUY", "hash": "29ce070ca72064a2900ac0c4a1ae4909c3f944fc", "best_bid": "0.805", "best_ask": "0.806"}, {"asset_id": "54533043819946592547517511176940999955633860128497669742211153063842200957669", "price": "0.205", "size": "2891.98", "side": "SELL", "hash": "ed6893865389e784c8ec7fa4d3129f824c4efe3f", "best_bid": "0.194", "best_ask": "0.195"}], "timestamp": "1785163525197", "event_type": "price_change"}}
{"ts": 1785163525.295, "kind": "price_change", "data": {"market": "0x0f49db97f71c68b1e42a6d16e3de93d85dbf7d4148e3f018eb79e88554be9f75", "price_changes": [{"asset_id": "87854174148074652060467921081181402357467303721471806610111179101805869578687", "price": "0.795", "size": "3457.98", "side": "BUY", "hash": "b20a398bd4fc6af2b94cf0de1efc68447163d212", "best_bid": "0.805", "best_ask": "0.806"}, {"asset_id": "54533043819946592547517511176940999955633860128497669742211153063842200957669", "price": "0.205", "size": "3457.98", "side": "SELL", "hash": "a02850288b19ba93429c8f69f8b34f776b021927", "best_bid": "0.194", "best_ask": "0.195"}], "timestamp": "1785163525295", "event_type": "price_change"}}
{"ts": 1785163526.068, "kind": "price_change", "data": {"market": "0x18b1c135d0a40c5894da9412e77311827d9caf16cf4cd6591b247a34730af919", "price_changes": [{"asset_id": "40081275558852222228080198821361202017557872256707631666334039001378518619916", "price": "0.418", "size": "5972.05", "side": "BUY", "hash": "fb3f3383907aa518fecdcb88254adb6c7b41e7a6", "best_bid": "0.428", "best_ask": "0.429"}, {"asset_id": "78633590736077251574794513664747155551297291244492840448622550955320930591622", "price": "0.582", "size": "5972.05", "side": "SELL", "hash": "05d69a21965879d0da9dc02500bc93b24da29de4", "best_bid": "0.571", "best_ask": "0.572"}], "timestamp": "1785163526068", "event_type": "price_change"}}
{"ts": 1785163526.136, "kind": "price_change", "data": {"market": "0x18b1c135d0a40c5894da9412e77311827d9caf16cf4cd6591b247a34730af919", "price_changes": [{"asset_id": "40081275558852222228080198821361202017557872256707631666334039001378518619916", "price": "0.418", "size": "7048.05", "side": "BUY", "hash": "7c756093522fb93bf176940b355e555165638b0f", "best_bid": "0.428", "best_ask": "0.429"}, {"asset_id": "78633590736077251574794513664747155551297291244492840448622550955320930591622", "price": "0.582", "size": "7048.05", "side": "SELL", "hash": "2e6f9837a22090e71ab5298635995e7b489a0581", "best_bid": "0.571", "best_ask": "0.572"}], "timestamp": "1785163526136", "event_type": "price_change"}}
{"ts": 1785163526.693, "kind": "price_change", "data": {"market": "0x18b1c135d0a40c5894da9412e77311827d9caf16cf4cd6591b247a34730af919", "price_changes": [{"asset_id": "40081275558852222228080198821361202017557872256707631666334039001378518619916", "price": "0.221", "size": "0", "side": "BUY", "hash": "3ce9656610e5e7083d5c382dad55b6df0bb4cb2c", "best_bid": "0.428", "best_ask": "0.429"}, {"asset_id": "78633590736077251574794513664747155551297291244492840448622550955320930591622", "price": "0.779", "size": "0", "side": "SELL", "hash": "e99424d13c014cb3766aadb98218f1584a0aedde", "best_bid": "0.571", "best_ask": "0.572"}], "timestamp": "1785163526693", "event_type": "price_change"}}
{"ts": 1785163526.693, "kind": "price_change", "data": {"market": "0x18b1c135d0a40c5894da9412e77311827d9caf16cf4cd6591b247a34730af919", "price_changes": [{"asset_id": "78633590736077251574794513664747155551297291244492840448622550955320930591622", "price": "0.311", "size": "0", "side": "BUY", "hash": "e99424d13c014cb3766aadb98218f1584a0aedde", "best_bid": "0.571", "best_ask": "0.572"}, {"asset_id": "40081275558852222228080198821361202017557872256707631666334039001378518619916", "price": "0.689", "size": "0", "side": "SELL", "hash": "3ce9656610e5e7083d5c382dad55b6df0bb4cb2c", "best_bid": "0.428", "best_ask": "0.429"}], "timestamp": "1785163526693", "event_type": "price_change"}}
{"ts": 1785163529.057, "kind": "price_change", "data": {"market": "0x0f49db97f71c68b1e42a6d16e3de93d85dbf7d4148e3f018eb79e88554be9f75", "price_changes": [{"asset_id": "54533043819946592547517511176940999955633860128497669742211153063842200957669", "price": "0.194", "size": "421.51", "side": "BUY", "hash": "e26db1dadb624e7d7688b4422aa978a7633e5162", "best_bid": "0.194", "best_ask": "0.195"}, {"asset_id": "87854174148074652060467921081181402357467303721471806610111179101805869578687", "price": "0.806", "size": "421.51", "side": "SELL", "hash": "b3591e59efe5ce437b73c3bb0696376453089451", "best_bid": "0.805", "best_ask": "0.806"}], "timestamp": "1785163529057", "event_type": "price_change"}}
{"ts": 1785163529.057, "kind": "price_change", "data": {"market": "0x0f49db97f71c68b1e42a6d16e3de93d85dbf7d4148e3f018eb79e88554be9f75", "price_changes": [{"asset_id": "87854174148074652060467921081181402357467303721471806610111179101805869578687", "price": "0.805", "size": "949.98", "side": "BUY", "hash": "b3591e59efe5ce437b73c3bb0696376453089451", "best_bid": "0.805", "best_ask": "0.806"}, {"asset_id": "54533043819946592547517511176940999955633860128497669742211153063842200957669", "price": "0.195", "size": "949.98", "side": "SELL", "hash": "e26db1dadb624e7d7688b4422aa978a7633e5162", "best_bid": "0.194", "best_ask": "0.195"}], "timestamp": "1785163529057", "event_type": "price_change"}}
{"ts": 1785163530.657, "kind": "price_change", "data": {"market": "0x18b1c135d0a40c5894da9412e77311827d9caf16cf4cd6591b247a34730af919", "price_changes": [{"asset_id": "40081275558852222228080198821361202017557872256707631666334039001378518619916", "price": "0.231", "size": "48.28", "side": "BUY", "hash": "c097e880746102241902eb05acefc13e0f48a1d3", "best_bid": "0.428", "best_ask": "0.429"}, {"asset_id": "78633590736077251574794513664747155551297291244492840448622550955320930591622", "price": "0.769", "size": "48.28", "side": "SELL", "hash": "59c792411e47434c1dede96575aaade5f1f4a430", "best_bid": "0.571", "best_ask": "0.572"}], "timestamp": "1785163530657", "event_type": "price_change"}}
{"ts": 1785163530.674, "kind": "price_change", "data": {"market": "0x18b1c135d0a40c5894da9412e77311827d9caf16cf4cd6591b247a34730af919", "price_changes": [{"asset_id": "78633590736077251574794513664747155551297291244492840448622550955320930591622", "price": "0.372", "size": "48.28", "side": "BUY", "hash": "35ffa3ad661dafb031eb437736127fff985ebb02", "best_bid": "0.571", "best_ask": "0.572"}, {"asset_id": "40081275558852222228080198821361202017557872256707631666334039001378518619916", "price": "0.628", "size": "48.28", "side": "SELL", "hash": "865dc189b98c0cf8e28a3e47df7ff74aaae35582", "best_bid": "0.428", "best_ask": "0.429"}], "timestamp": "1785163530674", "event_type": "price_change"}}
{"ts": 1785163530.96098, "kind": "orders_out", "data": [{"token_id": "40081275558852222228080198821361202017557872256707631666334039001378518619916", "side": "BUY", "price": 0.387, "size": 7.75}, {"token_id": "78633590736077251574794513664747155551297291244492840448622550955320930591622", "side": "BUY", "price": 0.529, "size": 5.67}]}
{"ts": 1785163533.018, "kind": "price_change", "data": {"market": "0x0f49db97f71c68b1e42a6d16e3de93d85dbf7d4148e3f018eb79e88554be9f75", "price_changes": [{"asset_id": "87854174148074652060467921081181402357467303721471806610111179101805869578687", "price": "0.803", "size": "12234.97", "side": "BUY", "hash": "d18a9b26620e2257485738aaf3d15a7076748c1a", "best_bid": "0.805", "best_ask": "0.806"}, {"asset_id": "54533043819946592547517511176940999955633860128497669742211153063842200957669", "price": "0.197", "size": "12234.97", "side": "SELL", "hash": "d455d97a43f2f23b377294296e8c408aa1554730", "best_bid": "0.194", "best_ask": "0.195"}], "timestamp": "1785163533018", "event_type": "price_change"}}
{"ts": 1785163533.018, "kind": "price_change", "data": {"market": "0x0f49db97f71c68b1e42a6d16e3de93d85dbf7d4148e3f018eb79e88554be9f75", "price_changes": [{"asset_id": "54533043819946592547517511176940999955633860128497669742211153063842200957669", "price": "0.193", "size": "10887", "side": "BUY", "hash": "d455d97a43f2f23b377294296e8c408aa1554730", "best_bid": "0.194", "best_ask": "0.195"}, {"asset_id": "87854174148074652060467921081181402357467303721471806610111179101805869578687", "price": "0.807", "size": "10887", "side": "SELL", "hash": "d18a9b26620e2257485738aaf3d15a7076748c1a", "best_bid": "0.805", "best_ask": "0.806"}], "timestamp": "1785163533018", "event_type": "price_change"}}
{"ts": 1785163533.32364, "kind": "orders_out", "data": [{"token_id": "54533043819946592547517511176940999955633860128497669742211153063842200957669", "side": "BUY", "price": 0.144, "size": 10.42}]}
{"ts": 1785163533.409, "kind": "price_change", "data": {"market": "0x0f49db97f71c68b1e42a6d16e3de93d85dbf7d4148e3f018eb79e88554be9f75", "price_changes": [{"asset_id": "54533043819946592547517511176940999955633860128497669742211153063842200957669", "price": "0.193", "size": "10987", "side": "BUY", "hash": "49a931031f217f4dbf4860c512ffdcbaa1988556", "best_bid": "0.194", "best_ask": "0.195"}, {"asset_id": "87854174148074652060467921081181402357467303721471806610111179101805869578687", "price": "0.807", "size": "10987", "side": "SELL", "hash": "a10d5a875a44431fcf77bad06277a2f5bd376b7b", "best_bid": "0.805", "best_ask": "0.806"}], "timestamp": "1785163533409", "event_type": "price_change"}}
{"ts": 1785163533.413, "kind": "price_change", "data": {"market": "0x0f49db97f71c68b1e42a6d16e3de93d85dbf7d4148e3f018eb79e88554be9f75", "price_changes": [{"asset_id": "87854174148074652060467921081181402357467303721471806610111179101805869578687", "price": "0.803", "size": "12334.97", "side": "BUY", "hash": "d312445706034df55ab4fd6da5157215d0416ae6", "best_bid": "0.805", "best_ask": "0.806"}, {"asset_id": "54533043819946592547517511176940999955633860128497669742211153063842200957669", "price": "0.197", "size": "12334.97", "side": "SELL", "hash": "2efa2afb55925ff6f8579acb497d17c5d1cba873", "best_bid": "0.194", "best_ask": "0.195"}], "timestamp": "1785163533413", "event_type": "price_change"}}
{"ts": 1785163533.489, "kind": "price_change", "data": {"market": "0x0f49db97f71c68b1e42a6d16e3de93d85dbf7d4148e3f018eb79e88554be9f75", "price_changes": [{"asset_id": "54533043819946592547517511176940999955633860128497669742211153063842200957669", "price": "0.176", "size": "12220.93", "side": "BUY", "hash": "f597a3eb0d5a24461cbf034669c4c1c730e1ff81", "best_bid": "0.194", "best_ask": "0.195"}, {"asset_id": "87854174148074652060467921081181402357467303721471806610111179101805869578687", "price": "0.824", "size": "12220.93", "side": "SELL", "hash": "61407167688ce1961c64e55957426cf0cb2d74d0", "best_bid": "0.805", "best_ask": "0.806"}], "timestamp": "1785163533489", "event_type": "price_change"}}
{"ts": 1785163535.77, "kind": "price_change", "data": {"market": "0x18b1c135d0a40c5894da9412e77311827d9caf16cf4cd6591b247a34730af919", "price_changes": [{"asset_id": "78633590736077251574794513664747155551297291244492840448622550955320930591622", "price": "0.445", "size": "0", "side": "BUY", "hash": "515256847a124022e3d1ffd19e8acd1981978aaf", "best_bid": "0.571", "best_ask": "0.572"}, {"asset_id": "40081275558852222228080198821361202017557872256707631666334039001378518619916", "price": "0.555", "size": "0", "side": "SELL", "hash": "3b815e11b3184535fa1c14420bc796ef1046a970", "best_bid": "0.428", "best_ask": "0.429"}], "timestamp": "1785163535770", "event_type": "price_change"}}
{"ts": 1785163535.86, "kind": "price_change", "data": {"market": "0x18b1c135d0a40c5894da9412e77311827d9caf16cf4cd6591b247a34730af919", "price_changes": [{"asset_id": "78633590736077251574794513664747155551297291244492840448622550955320930591622", "price": "0.445", "size": "100", "side": "BUY", "hash": "032cce9cc63149ff063ea3ea032f40e0fcb8da01", "best_bid": "0.571", "best_ask": "0.572"}, {"asset_id": "40081275558852222228080198821361202017557872256707631666334039001378518619916", "price": "0.555", "size": "100", "side": "SELL", "hash": "ec8d18c68e0d772df7329c5a902782008c625fa8", "best_bid": "0.428", "best_ask": "0.429"}], "timestamp": "1785163535860", "event_type": "price_change"}}
{"ts": 1785163537.382, "kind": "price_change", "data": {"market": "0x0f49db97f71c68b1e42a6d16e3de93d85dbf7d4148e3f018eb79e88554be9f75", "price_changes": [{"asset_id": "87854174148074652060467921081181402357467303721471806610111179101805869578687", "price": "0.001", "size": "6146756.01", "side": "BUY", "hash": "98c0a5b31a1ff21ce9116b2956bd0070f1e1f0b8", "best_bid": "0.805", "best_ask": "0.806"}, {"asset_id": "54533043819946592547517511176940999955633860128497669742211153063842200957669", "price": "0.999", "size": "6146756.01", "side": "SELL", "hash": "658ccd3f42360ca442ba44b29c35888d8a3f0983", "best_bid": "0.194", "best_ask": "0.195"}], "timestamp": "1785163537382", "event_type": "price_change"}}
{"ts": 1785163537.395, "kind": "price_change", "data": {"market": "0x0f49db97f71c68b1e42a6d16e3de93d85dbf7d4148e3f018eb79e88554be9f75", "price_changes": [{"asset_id": "87854174148074652060467921081181402357467303721471806610111179101805869578687", "price": "0.001", "size": "6147766.01", "side": "BUY", "hash": "45a0f2eda5b4823f4450e4bb01c3d8064d8ee5bb", "best_bid": "0.805", "best_ask": "0.806"}, {"asset_id": "54533043819946592547517511176940999955633860128497669742211153063842200957669", "price": "0.999", "size": "6147766.01", "side": "SELL", "hash": "751b8a44b7cc79a31788fd6cda6ad7b04b2dcbde", "best_bid": "0.194", "best_ask": "0.195"}], "timestamp": "1785163537395", "event_type": "price_change"}}
{"ts": 1785163538.899, "kind": "price_change", "data": {"market": "0x18b1c135d0a40c5894da9412e77311827d9caf16cf4cd6591b247a34730af919", "price_changes": [{"asset_id": "40081275558852222228080198821361202017557872256707631666334039001378518619916", "price": "0.506", "size": "0", "side": "SELL", "hash": "aa871196f0a6b4674f46088e43de2809ad85af5d", "best_bid": "0.428", "best_ask": "0.429"}, {"asset_id": "78633590736077251574794513664747155551297291244492840448622550955320930591622", "price": "0.494", "size": "0", "side": "BUY", "hash": "ba3ce2340beb3db505076b041e1786852b41827c", "best_bid": "0.571", "best_ask": "0.572"}], "timestamp": "1785163538899", "event_type": "price_change"}}
{"ts": 1785163539.043, "kind": "price_change", "data": {"market": "0x18b1c135d0a40c5894da9412e77311827d9caf16cf4cd6591b247a34730af919", "price_changes": [{"asset_id": "40081275558852222228080198821361202017557872256707631666334039001378518619916", "price": "0.41", "size": "2931.23", "side": "BUY", "hash": "02285af3a341bc347ac4597dbbc834bdf497214c", "best_bid": "0.428", "best_ask": "0.429"}, {"asset_id": "78633590736077251574794513664747155551297291244492840448622550955320930591622", "price": "0.59", "size": "2931.23", "side": "SELL", "hash": "601d0cae442de764893ad5833893f444d7be9ee0", "best_bid": "0.571", "best_ask": "0.572"}], "timestamp": "1785163539043", "event_type": "price_change"}}
